{"local_receipt_timestamp_ns":1704067200000000011,"raw_payload":"{\"stream\":\"btcusdt@depth@100ms\",\"data\":{\"e\":\"depthUpdate\",\"E\":1704067200001,\"U\":1,\"u\":1,\"b\":[[\"50000.00\",\"1.00000000\"]],\"a\":[]}}"}
{"local_receipt_timestamp_ns":1704067200000000021,"raw_payload":"{\"stream\":\"btcusdt@depth@100ms\",\"data\":{\"e\":\"depthUpdate\",\"E\":1704067200002,\"U\":2,\"u\":2,\"b\":[],\"a\":[[\"50001.00\",\"1.00000000\"]]}}"}
{"local_receipt_timestamp_ns":1704067200000000031,"raw_payload":"{\"stream\":\"btcusdt@depth@100ms\",\"data\":{\"e\":\"depthUpdate\",\"E\":1704067200003,\"U\":3,\"u\":3,\"b\":[[\"50000.00\",\"1.00000000\"]],\"a\":[]}}"}
{"local_receipt_timestamp_ns":1704067200000000041,"raw_payload":"{\"stream\":\"btcusdt@depth@100ms\",\"data\":{\"e\":\"depthUpdate\",\"E\":1704067200004,\"U\":4,\"u\":4,\"b\":[],\"a\":[[\"50001.00\",\"1.00000000\"]]}}"}
{"local_receipt_timestamp_ns":1704067200000000051,"raw_payload":"{\"stream\":\"btcusdt@depth@100ms\",\"data\":{\"e\":\"depthUpdate\",\"E\":1704067200005,\"U\":5,\"u\":5,\"b\":[[\"50000.00\",\"1.00000000\"]],\"a\":[]}}"}
{"local_receipt_timestamp_ns":1704067200000000061,"raw_payload":"{\"stream\":\"btcusdt@depth@100ms\",\"data\":{\"e\":\"depthUpdate\",\"E\":1704067200006,\"U\":6,\"u\":6,\"b\":[],\"a\":[[\"50001.00\",\"1.00000000\"]]}}"}
{"local_receipt_timestamp_ns":1704067200000000071,"raw_payload":"{\"stream\":\"btcusdt@depth@100ms\",\"data\":{\"e\":\"depthUpdate\",\"E\":1704067200007,\"U\":7,\"u\":7,\"b\":[[\"50000.00\",\"1.00000000\"]],\"a\":[]}}"}
{"local_receipt_timestamp_ns":1704067200000000081,"raw_payload":"{\"stream\":\"btcusdt@depth@100ms\",\"data\":{\"e\":\"depthUpdate\",\"E\":1704067200008,\"U\":8,\"u\":8,\"b\":[],\"a\":[[\"50001.00\",\"1.00000000\"]]}}"}
{"local_receipt_timestamp_ns":1704067200000000091,"raw_payload":"{\"stream\":\"btcusdt@depth@100ms\",\"data\":{\"e\":\"depthUpdate\",\"E\":1704067200009,\"U\":9,\"u\":9,\"b\":[[\"50000.00\",\"1.00000000\"]],\"a\":[]}}"}
{"local_receipt_timestamp_ns":1704067200000000101,"raw_payload":"{\"stream\":\"btcusdt@depth@100ms\",\"data\":{\"e\":\"depthUpdate\",\"E\":1704067200010,\"U\":10,\"u\":10,\"b\":[],\"a\":[[\"50001.00\",\"1.00000000\"]]}}"}
{"local_receipt_timestamp_ns":1704067200000000111,"raw_payload":"{\"stream\":\"btcusdt@depth@100ms\",\"data\":{\"e\":\"depthUpdate\",\"E\":1704067200011,\"U\":11,\"u\":11,\"b\":[[\"50000.00\",\"1.00000000\"]],\"a\":[]}}"}
{"local_receipt_timestamp_ns":1704067200000000121,"raw_payload":"{\"stream\":\"btcusdt@depth@100ms\",\"data\":{\"e\":\"depthUpdate\",\"E\":1704067200012,\"U\":12,\"u\":12,\"b\":[],\"a\":[[\"50001.00\",\"1.00000000\"]]}}"}
{"local_receipt_timestamp_ns":1704067200000000131,"raw_payload":"{\"stream\":\"btcusdt@depth@100ms\",\"data\":{\"e\":\"depthUpdate\",\"E\":1704067200013,\"U\":13,\"u\":13,\"b\":[[\"50000.00\",\"1.00000000\"]],\"a\":[]}}"}
{"local_receipt_timestamp_ns":1704067200000000141,"raw_payload":"{\"stream\":\"btcusdt@depth@100ms\",\"data\":{\"e\":\"depthUpdate\",\"E\":1704067200014,\"U\":14,\"u\":14,\"b\":[],\"a\":[[\"50001.00\",\"1.00000000\"]]}}"}
{"local_receipt_timestamp_ns":1704067200000000151,"raw_payload":"{\"stream\":\"btcusdt@depth@100ms\",\"data\":{\"e\":\"depthUpdate\",\"E\":1704067200015,\"U\":15,\"u\":15,\"b\":[[\"50000.00\",\"1.00000000\"]],\"a\":[]}}"}
{"local_receipt_timestamp_ns":1704067200000000161,"raw_payload":"{\"stream\":\"btcusdt@depth@100ms\",\"data\":{\"e\":\"depthUpdate\",\"E\":1704067200016,\"U\":16,\"u\":16,\"b\":[],\"a\":[[\"50001.00\",\"1.00000000\"]]}}"}
{"local_receipt_timestamp_ns":1704067200000000171,"raw_payload":"{\"stream\":\"btcusdt@depth@100ms\",\"data\":{\"e\":\"depthUpdate\",\"E\":1704067200017,\"U\":17,\"u\":17,\"b\":[[\"50000.00\",\"1.00000000\"]],\"a\":[]}}"}
{"local_receipt_timestamp_ns":1704067200000000181,"raw_payload":"{\"stream\":\"btcusdt@depth@100ms\",\"data\":{\"e\":\"depthUpdate\",\"E\":1704067200018,\"U\":18,\"u\":18,\"b\":[],\"a\":[[\"50001.00\",\"1.00000000\"]]}}"}
{"local_receipt_timestamp_ns":1704067200000000191,"raw_payload":"{\"stream\":\"btcusdt@depth@100ms\",\"data\":{\"e\":\"depthUpdate\",\"E\":1704067200019,\"U\":19,\"u\":19,\"b\":[[\"50000.00\",\"1.00000000\"]],\"a\":[]}}"}
{"local_receipt_timestamp_ns":1704067200000000201,"raw_payload":"{\"stream\":\"btcusdt@depth@100ms\",\"data\":{\"e\":\"depthUpdate\",\"E\":1704067200020,\"U\":20,\"u\":20,\"b\":[],\"a\":[[\"50001.00\",\"1.00000000\"]]}}"}
{"local_receipt_timestamp_ns":1704067200000000211,"raw_payload":"{\"stream\":\"btcusdt@depth@100ms\",\"data\":{\"e\":\"depthUpdate\",\"E\":1704067200021,\"U\":21,\"u\":21,\"b\":[[\"50000.00\",\"1.00000000\"]],\"a\":[]}}"}
{"local_receipt_timestamp_ns":1704067200000000221,"raw_payload":"{\"stream\":\"btcusdt@depth@100ms\",\"data\":{\"e\":\"depthUpdate\",\"E\":1704067200022,\"U\":22,\"u\":22,\"b\":[],\"a\":[[\"50001.00\",\"1.00000000\"]]}}"}
{"local_receipt_timestamp_ns":1704067200000000231,"raw_payload":"{\"stream\":\"btcusdt@depth@100ms\",\"data\":{\"e\":\"depthUpdate\",\"E\":1704067200023,\"U\":23,\"u\":23,\"b\":[[\"50000.00\",\"1.00000000\"]],\"a\":[]}}"}
{"local_receipt_timestamp_ns":1704067200000000241,"raw_payload":"{\"stream\":\"btcusdt@depth@100ms\",\"data\":{\"e\":\"depthUpdate\",\"E\":1704067200024,\"U\":24,\"u\":24,\"b\":[],\"a\":[[\"50001.00\",\"1.00000000\"]]}}"}
{"local_receipt_timestamp_ns":1704067200000000251,"raw_payload":"{\"stream\":\"btcusdt@depth@100ms\",\"data\":{\"e\":\"depthUpdate\",\"E\":1704067200025,\"U\":25,\"u\":25,\"b\":[[\"50000.00\",\"1.00000000\"]],\"a\":[]}}"}
{"local_receipt_timestamp_ns":1704067200000000261,"raw_payload":"{\"stream\":\"btcusdt@depth@100ms\",\"data\":{\"e\":\"depthUpdate\",\"E\":1704067200026,\"U\":26,\"u\":26,\"b\":[],\"a\":[[\"50001.00\",\"1.00000000\"]]}}"}
{"local_receipt_timestamp_ns":1704067200000000271,"raw_payload":"{\"stream\":\"btcusdt@depth@100ms\",\"data\":{\"e\":\"depthUpdate\",\"E\":1704067200027,\"U\":27,\"u\":27,\"b\":[[\"50000.00\",\"1.00000000\"]],\"a\":[]}}"}
{"local_receipt_timestamp_ns":1704067200000000281,"raw_payload":"{\"stream\":\"btcusdt@depth@100ms\",\"data\":{\"e\":\"depthUpdate\",\"E\":1704067200028,\"U\":28,\"u\":28,\"b\":[],\"a\":[[\"50001.00\",\"1.00000000\"]]}}"}
{"local_receipt_timestamp_ns":1704067200000000291,"raw_payload":"{\"stream\":\"btcusdt@depth@100ms\",\"data\":{\"e\":\"depthUpdate\",\"E\":1704067200029,\"U\":29,\"u\":29,\"b\":[[\"50000.00\",\"1.00000000\"]],\"a\":[]}}"}
{"local_receipt_timestamp_ns":1704067200000000301,"raw_payload":"{\"stream\":\"btcusdt@depth@100ms\",\"data\":{\"e\":\"depthUpdate\",\"E\":1704067200030,\"U\":30,\"u\":30,\"b\":[],\"a\":[[\"50001.00\",\"1.00000000\"]]}}"}
{"local_receipt_timestamp_ns":1704067200000000311,"raw_payload":"{\"stream\":\"btcusdt@depth@100ms\",\"data\":{\"e\":\"depthUpdate\",\"E\":1704067200031,\"U\":31,\"u\":31,\"b\":[[\"50000.00\",\"1.00000000\"]],\"a\":[]}}"}
{"local_receipt_timestamp_ns":1704067200000000321,"raw_payload":"{\"stream\":\"btcusdt@depth@100ms\",\"data\":{\"e\":\"depthUpdate\",\"E\":1704067200032,\"U\":32,\"u\":32,\"b\":[],\"a\":[[\"50001.00\",\"1.00000000\"]]}}"}
{"local_receipt_timestamp_ns":1704067200000000331,"raw_payload":"{\"stream\":\"btcusdt@depth@100ms\",\"data\":{\"e\":\"depthUpdate\",\"E\":1704067200033,\"U\":33,\"u\":33,\"b\":[[\"50000.00\",\"1.00000000\"]],\"a\":[]}}"}
{"local_receipt_timestamp_ns":1704067200000000341,"raw_payload":"{\"stream\":\"btcusdt@depth@100ms\",\"data\":{\"e\":\"depthUpdate\",\"E\":1704067200034,\"U\":34,\"u\":34,\"b\":[],\"a\":[[\"50001.00\",\"1.00000000\"]]}}"}
{"local_receipt_timestamp_ns":1704067200000000351,"raw_payload":"{\"stream\":\"btcusdt@depth@100ms\",\"data\":{\"e\":\"depthUpdate\",\"E\":1704067200035,\"U\":35,\"u\":35,\"b\":[[\"50000.00\",\"1.00000000\"]],\"a\":[]}}"}
{"local_receipt_timestamp_ns":1704067200000000361,"raw_payload":"{\"stream\":\"btcusdt@depth@100ms\",\"data\":{\"e\":\"depthUpdate\",\"E\":1704067200036,\"U\":36,\"u\":36,\"b\":[],\"a\":[[\"50001.00\",\"1.00000000\"]]}}"}
{"local_receipt_timestamp_ns":1704067200000000371,"raw_payload":"{\"stream\":\"btcusdt@depth@100ms\",\"data\":{\"e\":\"depthUpdate\",\"E\":1704067200037,\"U\":37,\"u\":37,\"b\":[[\"50000.00\",\"1.00000000\"]],\"a\":[]}}"}
{"local_receipt_timestamp_ns":1704067200000000381,"raw_payload":"{\"stream\":\"btcusdt@depth@100ms\",\"data\":{\"e\":\"depthUpdate\",\"E\":1704067200038,\"U\":38,\"u\":38,\"b\":[],\"a\":[[\"50001.00\",\"1.00000000\"]]}}"}
{"local_receipt_timestamp_ns":1704067200000000391,"raw_payload":"{\"stream\":\"btcusdt@depth@100ms\",\"data\":{\"e\":\"depthUpdate\",\"E\":1704067200039,\"U\":39,\"u\":39,\"b\":[[\"50000.00\",\"1.00000000\"]],\"a\":[]}}"}
{"local_receipt_timestamp_ns":1704067200000000401,"raw_payload":"{\"stream\":\"btcusdt@depth@100ms\",\"data\":{\"e\":\"depthUpdate\",\"E\":1704067200040,\"U\":40,\"u\":40,\"b\":[],\"a\":[[\"50001.00\",\"1.00000000\"]]}}"}
{"local_receipt_timestamp_ns":1704067200000000411,"raw_payload":"{\"stream\":\"btcusdt@depth@100ms\",\"data\":{\"e\":\"depthUpdate\",\"E\":1704067200041,\"U\":41,\"u\":41,\"b\":[[\"50000.00\",\"1.00000000\"]],\"a\":[]}}"}
{"local_receipt_timestamp_ns":1704067200000000421,"raw_payload":"{\"stream\":\"btcusdt@depth@100ms\",\"data\":{\"e\":\"depthUpdate\",\"E\":1704067200042,\"U\":42,\"u\":42,\"b\":[],\"a\":[[\"50001.00\",\"1.00000000\"]]}}"}
{"local_receipt_timestamp_ns":1704067200000000431,"raw_payload":"{\"stream\":\"btcusdt@depth@100ms\",\"data\":{\"e\":\"depthUpdate\",\"E\":1704067200043,\"U\":43,\"u\":43,\"b\":[[\"50000.00\",\"1.00000000\"]],\"a\":[]}}"}
{"local_receipt_timestamp_ns":1704067200000000441,"raw_payload":"{\"stream\":\"btcusdt@depth@100ms\",\"data\":{\"e\":\"depthUpdate\",\"E\":1704067200044,\"U\":44,\"u\":44,\"b\":[],\"a\":[[\"50001.00\",\"1.00000000\"]]}}"}
{"local_receipt_timestamp_ns":1704067200000000451,"raw_payload":"{\"stream\":\"btcusdt@depth@100ms\",\"data\":{\"e\":\"depthUpdate\",\"E\":1704067200045,\"U\":45,\"u\":45,\"b\":[[\"50000.00\",\"1.00000000\"]],\"a\":[]}}"}
{"local_receipt_timestamp_ns":1704067200000000461,"raw_payload":"{\"stream\":\"btcusdt@depth@100ms\",\"data\":{\"e\":\"depthUpdate\",\"E\":1704067200046,\"U\":46,\"u\":46,\"b\":[],\"a\":[[\"50001.00\",\"1.00000000\"]]}}"}
{"local_receipt_timestamp_ns":1704067200000000471,"raw_payload":"{\"stream\":\"btcusdt@depth@100ms\",\"data\":{\"e\":\"depthUpdate\",\"E\":1704067200047,\"U\":47,\"u\":47,\"b\":[[\"50000.00\",\"1.00000000\"]],\"a\":[]}}"}
{"local_receipt_timestamp_ns":1704067200000000481,"raw_payload":"{\"stream\":\"btcusdt@depth@100ms\",\"data\":{\"e\":\"depthUpdate\",\"E\":1704067200048,\"U\":48,\"u\":48,\"b\":[],\"a\":[[\"50001.00\",\"1.00000000\"]]}}"}
{"local_receipt_timestamp_ns":1704067200000000491,"raw_payload":"{\"stream\":\"btcusdt@depth@100ms\",\"data\":{\"e\":\"depthUpdate\",\"E\":1704067200049,\"U\":49,\"u\":49,\"b\":[[\"50000.00\",\"1.00000000\"]],\"a\":[]}}"}
{"local_receipt_timestamp_ns":1704067200000000501,"raw_payload":"{\"stream\":\"btcusdt@depth@100ms\",\"data\":{\"e\":\"depthUpdate\",\"E\":1704067200050,\"U\":50,\"u\":50,\"b\":[],\"a\":[[\"50001.00\",\"1.00000000\"]]}}"}
{"local_receipt_timestamp_ns":1704067200000000511,"raw_payload":"{\"stream\":\"btcusdt@depth@100ms\",\"data\":{\"e\":\"depthUpdate\",\"E\":1704067200051,\"U\":51,\"u\":51,\"b\":[[\"50000.00\",\"1.00000000\"]],\"a\":[]}}"}
{"local_receipt_timestamp_ns":1704067200000000521,"raw_payload":"{\"stream\":\"btcusdt@depth@100ms\",\"data\":{\"e\":\"depthUpdate\",\"E\":1704067200052,\"U\":52,\"u\":52,\"b\":[],\"a\":[[\"50001.00\",\"1.00000000\"]]}}"}
{"local_receipt_timestamp_ns":1704067200000000531,"raw_payload":"{\"stream\":\"btcusdt@depth@100ms\",\"data\":{\"e\":\"depthUpdate\",\"E\":1704067200053,\"U\":53,\"u\":53,\"b\":[[\"50000.00\",\"1.00000000\"]],\"a\":[]}}"}
{"local_receipt_timestamp_ns":1704067200000000541,"raw_payload":"{\"stream\":\"btcusdt@depth@100ms\",\"data\":{\"e\":\"depthUpdate\",\"E\":1704067200054,\"U\":54,\"u\":54,\"b\":[],\"a\":[[\"50001.00\",\"1.00000000\"]]}}"}
{"local_receipt_timestamp_ns":1704067200000000551,"raw_payload":"{\"stream\":\"btcusdt@depth@100ms\",\"data\":{\"e\":\"depthUpdate\",\"E\":1704067200055,\"U\":55,\"u\":55,\"b\":[[\"50000.00\",\"1.00000000\"]],\"a\":[]}}"}
{"local_receipt_timestamp_ns":1704067200000000561,"raw_payload":"{\"stream\":\"btcusdt@depth@100ms\",\"data\":{\"e\":\"depthUpdate\",\"E\":1704067200056,\"U\":56,\"u\":56,\"b\":[],\"a\":[[\"50001.00\",\"1.00000000\"]]}}"}
{"local_receipt_timestamp_ns":1704067200000000571,"raw_payload":"{\"stream\":\"btcusdt@depth@100ms\",\"data\":{\"e\":\"depthUpdate\",\"E\":1704067200057,\"U\":57,\"u\":57,\"b\":[[\"50000.00\",\"1.00000000\"]],\"a\":[]}}"}
{"local_receipt_timestamp_ns":1704067200000000581,"raw_payload":"{\"stream\":\"btcusdt@depth@100ms\",\"data\":{\"e\":\"depthUpdate\",\"E\":1704067200058,\"U\":58,\"u\":58,\"b\":[],\"a\":[[\"50001.00\",\"1.00000000\"]]}}"}
{"local_receipt_timestamp_ns":1704067200000000591,"raw_payload":"{\"stream\":\"btcusdt@depth@100ms\",\"data\":{\"e\":\"depthUpdate\",\"E\":1704067200059,\"U\":59,\"u\":59,\"b\":[[\"50000.00\",\"1.00000000\"]],\"a\":[]}}"}
{"local_receipt_timestamp_ns":1704067200000000601,"raw_payload":"{\"stream\":\"btcusdt@depth@100ms\",\"data\":{\"e\":\"depthUpdate\",\"E\":1704067200060,\"U\":60,\"u\":60,\"b\":[],\"a\":[[\"50001.00\",\"1.00000000\"]]}}"}
{"local_receipt_timestamp_ns":1704067200000000611,"raw_payload":"{\"stream\":\"btcusdt@depth@100ms\",\"data\":{\"e\":\"depthUpdate\",\"E\":1704067200061,\"U\":61,\"u\":61,\"b\":[[\"50000.00\",\"1.00000000\"]],\"a\":[]}}"}
{"local_receipt_timestamp_ns":1704067200000000621,"raw_payload":"{\"stream\":\"btcusdt@depth@100ms\",\"data\":{\"e\":\"depthUpdate\",\"E\":1704067200062,\"U\":62,\"u\":62,\"b\":[],\"a\":[[\"50001.00\",\"1.00000000\"]]}}"}
{"local_receipt_timestamp_ns":1704067200000000631,"raw_payload":"{\"stream\":\"btcusdt@depth@100ms\",\"data\":{\"e\":\"depthUpdate\",\"E\":1704067200063,\"U\":63,\"u\":63,\"b\":[[\"50000.00\",\"1.00000000\"]],\"a\":[]}}"}
{"local_receipt_timestamp_ns":1704067200000000641,"raw_payload":"{\"stream\":\"btcusdt@depth@100ms\",\"data\":{\"e\":\"depthUpdate\",\"E\":1704067200064,\"U\":64,\"u\":64,\"b\":[],\"a\":[[\"50001.00\",\"1.00000000\"]]}}"}
{"local_receipt_timestamp_ns":1704067200000000651,"raw_payload":"{\"stream\":\"btcusdt@depth@100ms\",\"data\":{\"e\":\"depthUpdate\",\"E\":1704067200065,\"U\":65,\"u\":65,\"b\":[[\"50000.00\",\"1.00000000\"]],\"a\":[]}}"}
{"local_receipt_timestamp_ns":1704067200000000661,"raw_payload":"{\"stream\":\"btcusdt@depth@100ms\",\"data\":{\"e\":\"depthUpdate\",\"E\":1704067200066,\"U\":66,\"u\":66,\"b\":[],\"a\":[[\"50001.00\",\"1.00000000\"]]}}"}
{"local_receipt_timestamp_ns":1704067200000000671,"raw_payload":"{\"stream\":\"btcusdt@depth@100ms\",\"data\":{\"e\":\"depthUpdate\",\"E\":1704067200067,\"U\":67,\"u\":67,\"b\":[[\"50000.00\",\"1.00000000\"]],\"a\":[]}}"}
{"local_receipt_timestamp_ns":1704067200000000681,"raw_payload":"{\"stream\":\"btcusdt@depth@100ms\",\"data\":{\"e\":\"depthUpdate\",\"E\":1704067200068,\"U\":68,\"u\":68,\"b\":[],\"a\":[[\"50001.00\",\"1.00000000\"]]}}"}
{"local_receipt_timestamp_ns":1704067200000000691,"raw_payload":"{\"stream\":\"btcusdt@depth@100ms\",\"data\":{\"e\":\"depthUpdate\",\"E\":1704067200069,\"U\":69,\"u\":69,\"b\":[[\"50000.00\",\"1.00000000\"]],\"a\":[]}}"}
{"local_receipt_timestamp_ns":1704067200000000701,"raw_payload":"{\"stream\":\"btcusdt@depth@100ms\",\"data\":{\"e\":\"depthUpdate\",\"E\":1704067200070,\"U\":70,\"u\":70,\"b\":[],\"a\":[[\"50001.00\",\"1.00000000\"]]}}"}
{"local_receipt_timestamp_ns":1704067200000000711,"raw_payload":"{\"stream\":\"btcusdt@depth@100ms\",\"data\":{\"e\":\"depthUpdate\",\"E\":1704067200071,\"U\":71,\"u\":71,\"b\":[[\"50000.00\",\"1.00000000\"]],\"a\":[]}}"}
{"local_receipt_timestamp_ns":1704067200000000721,"raw_payload":"{\"stream\":\"btcusdt@depth@100ms\",\"data\":{\"e\":\"depthUpdate\",\"E\":1704067200072,\"U\":72,\"u\":72,\"b\":[],\"a\":[[\"50001.00\",\"1.00000000\"]]}}"}
{"local_receipt_timestamp_ns":1704067200000000731,"raw_payload":"{\"stream\":\"btcusdt@depth@100ms\",\"data\":{\"e\":\"depthUpdate\",\"E\":1704067200073,\"U\":73,\"u\":73,\"b\":[[\"50000.00\",\"1.00000000\"]],\"a\":[]}}"}
{"local_receipt_timestamp_ns":1704067200000000741,"raw_payload":"{\"stream\":\"btcusdt@depth@100ms\",\"data\":{\"e\":\"depthUpdate\",\"E\":1704067200074,\"U\":74,\"u\":74,\"b\":[],\"a\":[[\"50001.00\",\"1.00000000\"]]}}"}
{"local_receipt_timestamp_ns":1704067200000000751,"raw_payload":"{\"stream\":\"btcusdt@depth@100ms\",\"data\":{\"e\":\"depthUpdate\",\"E\":1704067200075,\"U\":75,\"u\":75,\"b\":[[\"50000.00\",\"1.00000000\"]],\"a\":[]}}"}
{"local_receipt_timestamp_ns":1704067200000000761,"raw_payload":"{\"stream\":\"btcusdt@depth@100ms\",\"data\":{\"e\":\"depthUpdate\",\"E\":1704067200076,\"U\":76,\"u\":76,\"b\":[],\"a\":[[\"50001.00\",\"1.00000000\"]]}}"}
{"local_receipt_timestamp_ns":1704067200000000771,"raw_payload":"{\"stream\":\"btcusdt@depth@100ms\",\"data\":{\"e\":\"depthUpdate\",\"E\":1704067200077,\"U\":77,\"u\":77,\"b\":[[\"50000.00\",\"1.00000000\"]],\"a\":[]}}"}
{"local_receipt_timestamp_ns":1704067200000000781,"raw_payload":"{\"stream\":\"btcusdt@depth@100ms\",\"data\":{\"e\":\"depthUpdate\",\"E\":1704067200078,\"U\":78,\"u\":78,\"b\":[],\"a\":[[\"50001.00\",\"1.00000000\"]]}}"}
{"local_receipt_timestamp_ns":1704067200000000791,"raw_payload":"{\"stream\":\"btcusdt@depth@100ms\",\"data\":{\"e\":\"depthUpdate\",\"E\":1704067200079,\"U\":79,\"u\":79,\"b\":[[\"50000.00\",\"1.00000000\"]],\"a\":[]}}"}
{"local_receipt_timestamp_ns":1704067200000000801,"raw_payload":"{\"stream\":\"btcusdt@depth@100ms\",\"data\":{\"e\":\"depthUpdate\",\"E\":1704067200080,\"U\":80,\"u\":80,\"b\":[],\"a\":[[\"50001.00\",\"1.00000000\"]]}}"}
{"local_receipt_timestamp_ns":1704067200000000811,"raw_payload":"{\"stream\":\"btcusdt@depth@100ms\",\"data\":{\"e\":\"depthUpdate\",\"E\":1704067200081,\"U\":81,\"u\":81,\"b\":[[\"50000.00\",\"1.00000000\"]],\"a\":[]}}"}
{"local_receipt_timestamp_ns":1704067200000000821,"raw_payload":"{\"stream\":\"btcusdt@depth@100ms\",\"data\":{\"e\":\"depthUpdate\",\"E\":1704067200082,\"U\":82,\"u\":82,\"b\":[],\"a\":[[\"50001.00\",\"1.00000000\"]]}}"}
{"local_receipt_timestamp_ns":1704067200000000831,"raw_payload":"{\"stream\":\"btcusdt@depth@100ms\",\"data\":{\"e\":\"depthUpdate\",\"E\":1704067200083,\"U\":83,\"u\":83,\"b\":[[\"50000.00\",\"1.00000000\"]],\"a\":[]}}"}
{"local_receipt_timestamp_ns":1704067200000000841,"raw_payload":"{\"stream\":\"btcusdt@depth@100ms\",\"data\":{\"e\":\"depthUpdate\",\"E\":1704067200084,\"U\":84,\"u\":84,\"b\":[],\"a\":[[\"50001.00\",\"1.00000000\"]]}}"}
{"local_receipt_timestamp_ns":1704067200000000851,"raw_payload":"{\"stream\":\"btcusdt@depth@100ms\",\"data\":{\"e\":\"depthUpdate\",\"E\":1704067200085,\"U\":85,\"u\":85,\"b\":[[\"50000.00\",\"1.00000000\"]],\"a\":[]}}"}
{"local_receipt_timestamp_ns":1704067200000000861,"raw_payload":"{\"stream\":\"btcusdt@depth@100ms\",\"data\":{\"e\":\"depthUpdate\",\"E\":1704067200086,\"U\":86,\"u\":86,\"b\":[],\"a\":[[\"50001.00\",\"1.00000000\"]]}}"}
{"local_receipt_timestamp_ns":1704067200000000871,"raw_payload":"{\"stream\":\"btcusdt@depth@100ms\",\"data\":{\"e\":\"depthUpdate\",\"E\":1704067200087,\"U\":87,\"u\":87,\"b\":[[\"50000.00\",\"1.00000000\"]],\"a\":[]}}"}
{"local_receipt_timestamp_ns":1704067200000000881,"raw_payload":"{\"stream\":\"btcusdt@depth@100ms\",\"data\":{\"e\":\"depthUpdate\",\"E\":1704067200088,\"U\":88,\"u\":88,\"b\":[],\"a\":[[\"50001.00\",\"1.00000000\"]]}}"}
{"local_receipt_timestamp_ns":1704067200000000891,"raw_payload":"{\"stream\":\"btcusdt@depth@100ms\",\"data\":{\"e\":\"depthUpdate\",\"E\":1704067200089,\"U\":89,\"u\":89,\"b\":[[\"50000.00\",\"1.00000000\"]],\"a\":[]}}"}
{"local_receipt_timestamp_ns":1704067200000000901,"raw_payload":"{\"stream\":\"btcusdt@depth@100ms\",\"data\":{\"e\":\"depthUpdate\",\"E\":1704067200090,\"U\":90,\"u\":90,\"b\":[],\"a\":[[\"50001.00\",\"1.00000000\"]]}}"}
{"local_receipt_timestamp_ns":1704067200000000911,"raw_payload":"{\"stream\":\"btcusdt@depth@100ms\",\"data\":{\"e\":\"depthUpdate\",\"E\":1704067200091,\"U\":91,\"u\":91,\"b\":[[\"50000.00\",\"1.00000000\"]],\"a\":[]}}"}
{"local_receipt_timestamp_ns":1704067200000000921,"raw_payload":"{\"stream\":\"btcusdt@depth@100ms\",\"data\":{\"e\":\"depthUpdate\",\"E\":1704067200092,\"U\":92,\"u\":92,\"b\":[],\"a\":[[\"50001.00\",\"1.00000000\"]]}}"}
{"local_receipt_timestamp_ns":1704067200000000931,"raw_payload":"{\"stream\":\"btcusdt@depth@100ms\",\"data\":{\"e\":\"depthUpdate\",\"E\":1704067200093,\"U\":93,\"u\":93,\"b\":[[\"50000.00\",\"1.00000000\"]],\"a\":[]}}"}
{"local_receipt_timestamp_ns":1704067200000000941,"raw_payload":"{\"stream\":\"btcusdt@depth@100ms\",\"data\":{\"e\":\"depthUpdate\",\"E\":1704067200094,\"U\":94,\"u\":94,\"b\":[],\"a\":[[\"50001.00\",\"1.00000000\"]]}}"}
{"local_receipt_timestamp_ns":1704067200000000951,"raw_payload":"{\"stream\":\"btcusdt@depth@100ms\",\"data\":{\"e\":\"depthUpdate\",\"E\":1704067200095,\"U\":95,\"u\":95,\"b\":[[\"50000.00\",\"1.00000000\"]],\"a\":[]}}"}
{"local_receipt_timestamp_ns":1704067200000000961,"raw_payload":"{\"stream\":\"btcusdt@depth@100ms\",\"data\":{\"e\":\"depthUpdate\",\"E\":1704067200096,\"U\":96,\"u\":96,\"b\":[],\"a\":[[\"50001.00\",\"1.00000000\"]]}}"}
{"local_receipt_timestamp_ns":1704067200000000971,"raw_payload":"{\"stream\":\"btcusdt@depth@100ms\",\"data\":{\"e\":\"depthUpdate\",\"E\":1704067200097,\"U\":97,\"u\":97,\"b\":[[\"50000.00\",\"1.00000000\"]],\"a\":[]}}"}
{"local_receipt_timestamp_ns":1704067200000000981,"raw_payload":"{\"stream\":\"btcusdt@depth@100ms\",\"data\":{\"e\":\"depthUpdate\",\"E\":1704067200098,\"U\":98,\"u\":98,\"b\":[],\"a\":[[\"50001.00\",\"1.00000000\"]]}}"}
{"local_receipt_timestamp_ns":1704067200000000991,"raw_payload":"{\"stream\":\"btcusdt@depth@100ms\",\"data\":{\"e\":\"depthUpdate\",\"E\":1704067200099,\"U\":99,\"u\":99,\"b\":[[\"50000.00\",\"1.00000000\"]],\"a\":[]}}"}
{"local_receipt_timestamp_ns":1704067200000001001,"raw_payload":"{\"stream\":\"btcusdt@depth@100ms\",\"data\":{\"e\":\"depthUpdate\",\"E\":1704067200100,\"U\":100,\"u\":100,\"b\":[],\"a\":[[\"50001.00\",\"1.00000000\"]]}}"}
{"local_receipt_timestamp_ns":1704067200000001011,"raw_payload":"{\"stream\":\"btcusdt@depth@100ms\",\"data\":{\"e\":\"depthUpdate\",\"E\":1704067200101,\"U\":101,\"u\":101,\"b\":[[\"50000.00\",\"1.00000000\"]],\"a\":[]}}"}
{"local_receipt_timestamp_ns":1704067200000001021,"raw_payload":"{\"stream\":\"btcusdt@depth@100ms\",\"data\":{\"e\":\"depthUpdate\",\"E\":1704067200102,\"U\":102,\"u\":102,\"b\":[],\"a\":[[\"50001.00\",\"1.00000000\"]]}}"}
{"local_receipt_timestamp_ns":1704067200000001031,"raw_payload":"{\"stream\":\"btcusdt@depth@100ms\",\"data\":{\"e\":\"depthUpdate\",\"E\":1704067200103,\"U\":103,\"u\":103,\"b\":[[\"50000.00\",\"1.00000000\"]],\"a\":[]}}"}
{"local_receipt_timestamp_ns":1704067200000001041,"raw_payload":"{\"stream\":\"btcusdt@depth@100ms\",\"data\":{\"e\":\"depthUpdate\",\"E\":1704067200104,\"U\":104,\"u\":104,\"b\":[],\"a\":[[\"50001.00\",\"1.00000000\"]]}}"}
{"local_receipt_timestamp_ns":1704067200000001051,"raw_payload":"{\"stream\":\"btcusdt@depth@100ms\",\"data\":{\"e\":\"depthUpdate\",\"E\":1704067200105,\"U\":105,\"u\":105,\"b\":[[\"50000.00\",\"1.00000000\"]],\"a\":[]}}"}
{"local_receipt_timestamp_ns":1704067200000001061,"raw_payload":"{\"stream\":\"btcusdt@depth@100ms\",\"data\":{\"e\":\"depthUpdate\",\"E\":1704067200106,\"U\":106,\"u\":106,\"b\":[],\"a\":[[\"50001.00\",\"1.00000000\"]]}}"}
{"local_receipt_timestamp_ns":1704067200000001071,"raw_payload":"{\"stream\":\"btcusdt@depth@100ms\",\"data\":{\"e\":\"depthUpdate\",\"E\":1704067200107,\"U\":107,\"u\":107,\"b\":[[\"50000.00\",\"1.00000000\"]],\"a\":[]}}"}
{"local_receipt_timestamp_ns":1704067200000001081,"raw_payload":"{\"stream\":\"btcusdt@depth@100ms\",\"data\":{\"e\":\"depthUpdate\",\"E\":1704067200108,\"U\":108,\"u\":108,\"b\":[],\"a\":[[\"50001.00\",\"1.00000000\"]]}}"}
{"local_receipt_timestamp_ns":1704067200000001091,"raw_payload":"{\"stream\":\"btcusdt@depth@100ms\",\"data\":{\"e\":\"depthUpdate\",\"E\":1704067200109,\"U\":109,\"u\":109,\"b\":[[\"50000.00\",\"1.00000000\"]],\"a\":[]}}"}
{"local_receipt_timestamp_ns":1704067200000001101,"raw_payload":"{\"stream\":\"btcusdt@depth@100ms\",\"data\":{\"e\":\"depthUpdate\",\"E\":1704067200110,\"U\":110,\"u\":110,\"b\":[],\"a\":[[\"50001.00\",\"1.00000000\"]]}}"}
{"local_receipt_timestamp_ns":1704067200000001111,"raw_payload":"{\"stream\":\"btcusdt@depth@100ms\",\"data\":{\"e\":\"depthUpdate\",\"E\":1704067200111,\"U\":111,\"u\":111,\"b\":[[\"50000.00\",\"1.00000000\"]],\"a\":[]}}"}
{"local_receipt_timestamp_ns":1704067200000001121,"raw_payload":"{\"stream\":\"btcusdt@depth@100ms\",\"data\":{\"e\":\"depthUpdate\",\"E\":1704067200112,\"U\":112,\"u\":112,\"b\":[],\"a\":[[\"50001.00\",\"1.00000000\"]]}}"}
{"local_receipt_timestamp_ns":1704067200000001131,"raw_payload":"{\"stream\":\"btcusdt@depth@100ms\",\"data\":{\"e\":\"depthUpdate\",\"E\":1704067200113,\"U\":113,\"u\":113,\"b\":[[\"50000.00\",\"1.00000000\"]],\"a\":[]}}"}
{"local_receipt_timestamp_ns":1704067200000001141,"raw_payload":"{\"stream\":\"btcusdt@depth@100ms\",\"data\":{\"e\":\"depthUpdate\",\"E\":1704067200114,\"U\":114,\"u\":114,\"b\":[],\"a\":[[\"50001.00\",\"1.00000000\"]]}}"}
{"local_receipt_timestamp_ns":1704067200000001151,"raw_payload":"{\"stream\":\"btcusdt@depth@100ms\",\"data\":{\"e\":\"depthUpdate\",\"E\":1704067200115,\"U\":115,\"u\":115,\"b\":[[\"50000.00\",\"1.00000000\"]],\"a\":[]}}"}
{"local_receipt_timestamp_ns":1704067200000001161,"raw_payload":"{\"stream\":\"btcusdt@depth@100ms\",\"data\":{\"e\":\"depthUpdate\",\"E\":1704067200116,\"U\":116,\"u\":116,\"b\":[],\"a\":[[\"50001.00\",\"1.00000000\"]]}}"}
{"local_receipt_timestamp_ns":1704067200000001171,"raw_payload":"{\"stream\":\"btcusdt@depth@100ms\",\"data\":{\"e\":\"depthUpdate\",\"E\":1704067200117,\"U\":117,\"u\":117,\"b\":[[\"50000.00\",\"1.00000000\"]],\"a\":[]}}"}
{"local_receipt_timestamp_ns":1704067200000001181,"raw_payload":"{\"stream\":\"btcusdt@depth@100ms\",\"data\":{\"e\":\"depthUpdate\",\"E\":1704067200118,\"U\":118,\"u\":118,\"b\":[],\"a\":[[\"50001.00\",\"1.00000000\"]]}}"}
{"local_receipt_timestamp_ns":1704067200000001191,"raw_payload":"{\"stream\":\"btcusdt@depth@100ms\",\"data\":{\"e\":\"depthUpdate\",\"E\":1704067200119,\"U\":119,\"u\":119,\"b\":[[\"50000.00\",\"1.00000000\"]],\"a\":[]}}"}
{"local_receipt_timestamp_ns":1704067200000001201,"raw_payload":"{\"stream\":\"btcusdt@depth@100ms\",\"data\":{\"e\":\"depthUpdate\",\"E\":1704067200120,\"U\":120,\"u\":120,\"b\":[],\"a\":[[\"50001.00\",\"1.00000000\"]]}}"}
{"local_receipt_timestamp_ns":1704067200000001211,"raw_payload":"{\"stream\":\"btcusdt@depth@100ms\",\"data\":{\"e\":\"depthUpdate\",\"E\":1704067200121,\"U\":121,\"u\":121,\"b\":[[\"50000.00\",\"1.00000000\"]],\"a\":[]}}"}
{"local_receipt_timestamp_ns":1704067200000001221,"raw_payload":"{\"stream\":\"btcusdt@depth@100ms\",\"data\":{\"e\":\"depthUpdate\",\"E\":1704067200122,\"U\":122,\"u\":122,\"b\":[],\"a\":[[\"50001.00\",\"1.00000000\"]]}}"}
{"local_receipt_timestamp_ns":1704067200000001231,"raw_payload":"{\"stream\":\"btcusdt@depth@100ms\",\"data\":{\"e\":\"depthUpdate\",\"E\":1704067200123,\"U\":123,\"u\":123,\"b\":[[\"50000.00\",\"1.00000000\"]],\"a\":[]}}"}
{"local_receipt_timestamp_ns":1704067200000001241,"raw_payload":"{\"stream\":\"btcusdt@depth@100ms\",\"data\":{\"e\":\"depthUpdate\",\"E\":1704067200124,\"U\":124,\"u\":124,\"b\":[],\"a\":[[\"50001.00\",\"1.00000000\"]]}}"}
{"local_receipt_timestamp_ns":1704067200000001251,"raw_payload":"{\"stream\":\"btcusdt@depth@100ms\",\"data\":{\"e\":\"depthUpdate\",\"E\":1704067200125,\"U\":125,\"u\":125,\"b\":[[\"50000.00\",\"1.00000000\"]],\"a\":[]}}"}
{"local_receipt_timestamp_ns":1704067200000001261,"raw_payload":"{\"stream\":\"btcusdt@depth@100ms\",\"data\":{\"e\":\"depthUpdate\",\"E\":1704067200126,\"U\":126,\"u\":126,\"b\":[],\"a\":[[\"50001.00\",\"1.00000000\"]]}}"}
{"local_receipt_timestamp_ns":1704067200000001271,"raw_payload":"{\"stream\":\"btcusdt@depth@100ms\",\"data\":{\"e\":\"depthUpdate\",\"E\":1704067200127,\"U\":127,\"u\":127,\"b\":[[\"50000.00\",\"1.00000000\"]],\"a\":[]}}"}
{"local_receipt_timestamp_ns":1704067200000001281,"raw_payload":"{\"stream\":\"btcusdt@depth@100ms\",\"data\":{\"e\":\"depthUpdate\",\"E\":1704067200128,\"U\":128,\"u\":128,\"b\":[],\"a\":[[\"50001.00\",\"1.00000000\"]]}}"}
{"local_receipt_timestamp_ns":1704067200000001291,"raw_payload":"{\"stream\":\"btcusdt@depth@100ms\",\"data\":{\"e\":\"depthUpdate\",\"E\":1704067200129,\"U\":129,\"u\":129,\"b\":[[\"50000.00\",\"1.00000000\"]],\"a\":[]}}"}
{"local_receipt_timestamp_ns":1704067200000001301,"raw_payload":"{\"stream\":\"btcusdt@depth@100ms\",\"data\":{\"e\":\"depthUpdate\",\"E\":1704067200130,\"U\":130,\"u\":130,\"b\":[],\"a\":[[\"50001.00\",\"1.00000000\"]]}}"}
{"local_receipt_timestamp_ns":1704067200000001311,"raw_payload":"{\"stream\":\"btcusdt@depth@100ms\",\"data\":{\"e\":\"depthUpdate\",\"E\":1704067200131,\"U\":131,\"u\":131,\"b\":[[\"50000.00\",\"1.00000000\"]],\"a\":[]}}"}
{"local_receipt_timestamp_ns":1704067200000001321,"raw_payload":"{\"stream\":\"btcusdt@depth@100ms\",\"data\":{\"e\":\"depthUpdate\",\"E\":1704067200132,\"U\":132,\"u\":132,\"b\":[],\"a\":[[\"50001.00\",\"1.00000000\"]]}}"}
{"local_receipt_timestamp_ns":1704067200000001331,"raw_payload":"{\"stream\":\"btcusdt@depth@100ms\",\"data\":{\"e\":\"depthUpdate\",\"E\":1704067200133,\"U\":133,\"u\":133,\"b\":[[\"50000.00\",\"1.00000000\"]],\"a\":[]}}"}
{"local_receipt_timestamp_ns":1704067200000001341,"raw_payload":"{\"stream\":\"btcusdt@depth@100ms\",\"data\":{\"e\":\"depthUpdate\",\"E\":1704067200134,\"U\":134,\"u\":134,\"b\":[],\"a\":[[\"50001.00\",\"1.00000000\"]]}}"}
{"local_receipt_timestamp_ns":1704067200000001351,"raw_payload":"{\"stream\":\"btcusdt@depth@100ms\",\"data\":{\"e\":\"depthUpdate\",\"E\":1704067200135,\"U\":135,\"u\":135,\"b\":[[\"50000.00\",\"1.00000000\"]],\"a\":[]}}"}
{"local_receipt_timestamp_ns":1704067200000001361,"raw_payload":"{\"stream\":\"btcusdt@depth@100ms\",\"data\":{\"e\":\"depthUpdate\",\"E\":1704067200136,\"U\":136,\"u\":136,\"b\":[],\"a\":[[\"50001.00\",\"1.00000000\"]]}}"}
{"local_receipt_timestamp_ns":1704067200000001371,"raw_payload":"{\"stream\":\"btcusdt@depth@100ms\",\"data\":{\"e\":\"depthUpdate\",\"E\":1704067200137,\"U\":137,\"u\":137,\"b\":[[\"50000.00\",\"1.00000000\"]],\"a\":[]}}"}
{"local_receipt_timestamp_ns":1704067200000001381,"raw_payload":"{\"stream\":\"btcusdt@depth@100ms\",\"data\":{\"e\":\"depthUpdate\",\"E\":1704067200138,\"U\":138,\"u\":138,\"b\":[],\"a\":[[\"50001.00\",\"1.00000000\"]]}}"}
{"local_receipt_timestamp_ns":1704067200000001391,"raw_payload":"{\"stream\":\"btcusdt@depth@100ms\",\"data\":{\"e\":\"depthUpdate\",\"E\":1704067200139,\"U\":139,\"u\":139,\"b\":[[\"50000.00\",\"1.00000000\"]],\"a\":[]}}"}
{"local_receipt_timestamp_ns":1704067200000001401,"raw_payload":"{\"stream\":\"btcusdt@depth@100ms\",\"data\":{\"e\":\"depthUpdate\",\"E\":1704067200140,\"U\":140,\"u\":140,\"b\":[],\"a\":[[\"50001.00\",\"1.00000000\"]]}}"}
{"local_receipt_timestamp_ns":1704067200000001411,"raw_payload":"{\"stream\":\"btcusdt@depth@100ms\",\"data\":{\"e\":\"depthUpdate\",\"E\":1704067200141,\"U\":141,\"u\":141,\"b\":[[\"50000.00\",\"1.00000000\"]],\"a\":[]}}"}
{"local_receipt_timestamp_ns":1704067200000001421,"raw_payload":"{\"stream\":\"btcusdt@depth@100ms\",\"data\":{\"e\":\"depthUpdate\",\"E\":1704067200142,\"U\":142,\"u\":142,\"b\":[],\"a\":[[\"50001.00\",\"1.00000000\"]]}}"}
{"local_receipt_timestamp_ns":1704067200000001431,"raw_payload":"{\"stream\":\"btcusdt@depth@100ms\",\"data\":{\"e\":\"depthUpdate\",\"E\":1704067200143,\"U\":143,\"u\":143,\"b\":[[\"50000.00\",\"1.00000000\"]],\"a\":[]}}"}
{"local_receipt_timestamp_ns":1704067200000001441,"raw_payload":"{\"stream\":\"btcusdt@depth@100ms\",\"data\":{\"e\":\"depthUpdate\",\"E\":1704067200144,\"U\":144,\"u\":144,\"b\":[],\"a\":[[\"50001.00\",\"1.00000000\"]]}}"}
{"local_receipt_timestamp_ns":1704067200000001451,"raw_payload":"{\"stream\":\"btcusdt@depth@100ms\",\"data\":{\"e\":\"depthUpdate\",\"E\":1704067200145,\"U\":145,\"u\":145,\"b\":[[\"50000.00\",\"1.00000000\"]],\"a\":[]}}"}
{"local_receipt_timestamp_ns":1704067200000001461,"raw_payload":"{\"stream\":\"btcusdt@depth@100ms\",\"data\":{\"e\":\"depthUpdate\",\"E\":1704067200146,\"U\":146,\"u\":146,\"b\":[],\"a\":[[\"50001.00\",\"1.00000000\"]]}}"}
{"local_receipt_timestamp_ns":1704067200000001471,"raw_payload":"{\"stream\":\"btcusdt@depth@100ms\",\"data\":{\"e\":\"depthUpdate\",\"E\":1704067200147,\"U\":147,\"u\":147,\"b\":[[\"50000.00\",\"1.00000000\"]],\"a\":[]}}"}
{"local_receipt_timestamp_ns":1704067200000001481,"raw_payload":"{\"stream\":\"btcusdt@depth@100ms\",\"data\":{\"e\":\"depthUpdate\",\"E\":1704067200148,\"U\":148,\"u\":148,\"b\":[],\"a\":[[\"50001.00\",\"1.00000000\"]]}}"}
{"local_receipt_timestamp_ns":1704067200000001491,"raw_payload":"{\"stream\":\"btcusdt@depth@100ms\",\"data\":{\"e\":\"depthUpdate\",\"E\":1704067200149,\"U\":149,\"u\":149,\"b\":[[\"50000.00\",\"1.00000000\"]],\"a\":[]}}"}
{"local_receipt_timestamp_ns":1704067200000001501,"raw_payload":"{\"stream\":\"btcusdt@depth@100ms\",\"data\":{\"e\":\"depthUpdate\",\"E\":1704067200150,\"U\":150,\"u\":150,\"b\":[],\"a\":[[\"50001.00\",\"1.00000000\"]]}}"}
{"local_receipt_timestamp_ns":1704067200000001511,"raw_payload":"{\"stream\":\"btcusdt@depth@100ms\",\"data\":{\"e\":\"depthUpdate\",\"E\":1704067200151,\"U\":151,\"u\":151,\"b\":[[\"50000.00\",\"1.00000000\"]],\"a\":[]}}"}
{"local_receipt_timestamp_ns":1704067200000001521,"raw_payload":"{\"stream\":\"btcusdt@depth@100ms\",\"data\":{\"e\":\"depthUpdate\",\"E\":1704067200152,\"U\":152,\"u\":152,\"b\":[],\"a\":[[\"50001.00\",\"1.00000000\"]]}}"}
{"local_receipt_timestamp_ns":1704067200000001531,"raw_payload":"{\"stream\":\"btcusdt@depth@100ms\",\"data\":{\"e\":\"depthUpdate\",\"E\":1704067200153,\"U\":153,\"u\":153,\"b\":[[\"50000.00\",\"1.00000000\"]],\"a\":[]}}"}
{"local_receipt_timestamp_ns":1704067200000001541,"raw_payload":"{\"stream\":\"btcusdt@depth@100ms\",\"data\":{\"e\":\"depthUpdate\",\"E\":1704067200154,\"U\":154,\"u\":154,\"b\":[],\"a\":[[\"50001.00\",\"1.00000000\"]]}}"}
{"local_receipt_timestamp_ns":1704067200000001551,"raw_payload":"{\"stream\":\"btcusdt@depth@100ms\",\"data\":{\"e\":\"depthUpdate\",\"E\":1704067200155,\"U\":155,\"u\":155,\"b\":[[\"50000.00\",\"1.00000000\"]],\"a\":[]}}"}
{"local_receipt_timestamp_ns":1704067200000001561,"raw_payload":"{\"stream\":\"btcusdt@depth@100ms\",\"data\":{\"e\":\"depthUpdate\",\"E\":1704067200156,\"U\":156,\"u\":156,\"b\":[],\"a\":[[\"50001.00\",\"1.00000000\"]]}}"}
{"local_receipt_timestamp_ns":1704067200000001571,"raw_payload":"{\"stream\":\"btcusdt@depth@100ms\",\"data\":{\"e\":\"depthUpdate\",\"E\":1704067200157,\"U\":157,\"u\":157,\"b\":[[\"50000.00\",\"1.00000000\"]],\"a\":[]}}"}
{"local_receipt_timestamp_ns":1704067200000001581,"raw_payload":"{\"stream\":\"btcusdt@depth@100ms\",\"data\":{\"e\":\"depthUpdate\",\"E\":1704067200158,\"U\":158,\"u\":158,\"b\":[],\"a\":[[\"50001.00\",\"1.00000000\"]]}}"}
{"local_receipt_timestamp_ns":1704067200000001591,"raw_payload":"{\"stream\":\"btcusdt@depth@100ms\",\"data\":{\"e\":\"depthUpdate\",\"E\":1704067200159,\"U\":159,\"u\":159,\"b\":[[\"50000.00\",\"1.00000000\"]],\"a\":[]}}"}
{"local_receipt_timestamp_ns":1704067200000001601,"raw_payload":"{\"stream\":\"btcusdt@depth@100ms\",\"data\":{\"e\":\"depthUpdate\",\"E\":1704067200160,\"U\":160,\"u\":160,\"b\":[],\"a\":[[\"50001.00\",\"1.00000000\"]]}}"}
{"local_receipt_timestamp_ns":1704067200000001611,"raw_payload":"{\"stream\":\"btcusdt@depth@100ms\",\"data\":{\"e\":\"depthUpdate\",\"E\":1704067200161,\"U\":161,\"u\":161,\"b\":[[\"50000.00\",\"1.00000000\"]],\"a\":[]}}"}
{"local_receipt_timestamp_ns":1704067200000001621,"raw_payload":"{\"stream\":\"btcusdt@depth@100ms\",\"data\":{\"e\":\"depthUpdate\",\"E\":1704067200162,\"U\":162,\"u\":162,\"b\":[],\"a\":[[\"50001.00\",\"1.00000000\"]]}}"}
{"local_receipt_timestamp_ns":1704067200000001631,"raw_payload":"{\"stream\":\"btcusdt@depth@100ms\",\"data\":{\"e\":\"depthUpdate\",\"E\":1704067200163,\"U\":163,\"u\":163,\"b\":[[\"50000.00\",\"1.00000000\"]],\"a\":[]}}"}
{"local_receipt_timestamp_ns":1704067200000001641,"raw_payload":"{\"stream\":\"btcusdt@depth@100ms\",\"data\":{\"e\":\"depthUpdate\",\"E\":1704067200164,\"U\":164,\"u\":164,\"b\":[],\"a\":[[\"50001.00\",\"1.00000000\"]]}}"}
{"local_receipt_timestamp_ns":1704067200000001651,"raw_payload":"{\"stream\":\"btcusdt@depth@100ms\",\"data\":{\"e\":\"depthUpdate\",\"E\":1704067200165,\"U\":165,\"u\":165,\"b\":[[\"50000.00\",\"1.00000000\"]],\"a\":[]}}"}
{"local_receipt_timestamp_ns":1704067200000001661,"raw_payload":"{\"stream\":\"btcusdt@depth@100ms\",\"data\":{\"e\":\"depthUpdate\",\"E\":1704067200166,\"U\":166,\"u\":166,\"b\":[],\"a\":[[\"50001.00\",\"1.00000000\"]]}}"}
{"local_receipt_timestamp_ns":1704067200000001671,"raw_payload":"{\"stream\":\"btcusdt@depth@100ms\",\"data\":{\"e\":\"depthUpdate\",\"E\":1704067200167,\"U\":167,\"u\":167,\"b\":[[\"50000.00\",\"1.00000000\"]],\"a\":[]}}"}
{"local_receipt_timestamp_ns":1704067200000001681,"raw_payload":"{\"stream\":\"btcusdt@depth@100ms\",\"data\":{\"e\":\"depthUpdate\",\"E\":1704067200168,\"U\":168,\"u\":168,\"b\":[],\"a\":[[\"50001.00\",\"1.00000000\"]]}}"}
{"local_receipt_timestamp_ns":1704067200000001691,"raw_payload":"{\"stream\":\"btcusdt@depth@100ms\",\"data\":{\"e\":\"depthUpdate\",\"E\":1704067200169,\"U\":169,\"u\":169,\"b\":[[\"50000.00\",\"1.00000000\"]],\"a\":[]}}"}
{"local_receipt_timestamp_ns":1704067200000001701,"raw_payload":"{\"stream\":\"btcusdt@depth@100ms\",\"data\":{\"e\":\"depthUpdate\",\"E\":1704067200170,\"U\":170,\"u\":170,\"b\":[],\"a\":[[\"50001.00\",\"1.00000000\"]]}}"}
{"local_receipt_timestamp_ns":1704067200000001711,"raw_payload":"{\"stream\":\"btcusdt@depth@100ms\",\"data\":{\"e\":\"depthUpdate\",\"E\":1704067200171,\"U\":171,\"u\":171,\"b\":[[\"50000.00\",\"1.00000000\"]],\"a\":[]}}"}
{"local_receipt_timestamp_ns":1704067200000001721,"raw_payload":"{\"stream\":\"btcusdt@depth@100ms\",\"data\":{\"e\":\"depthUpdate\",\"E\":1704067200172,\"U\":172,\"u\":172,\"b\":[],\"a\":[[\"50001.00\",\"1.00000000\"]]}}"}
{"local_receipt_timestamp_ns":1704067200000001731,"raw_payload":"{\"stream\":\"btcusdt@depth@100ms\",\"data\":{\"e\":\"depthUpdate\",\"E\":1704067200173,\"U\":173,\"u\":173,\"b\":[[\"50000.00\",\"1.00000000\"]],\"a\":[]}}"}
{"local_receipt_timestamp_ns":1704067200000001741,"raw_payload":"{\"stream\":\"btcusdt@depth@100ms\",\"data\":{\"e\":\"depthUpdate\",\"E\":1704067200174,\"U\":174,\"u\":174,\"b\":[],\"a\":[[\"50001.00\",\"1.00000000\"]]}}"}
{"local_receipt_timestamp_ns":1704067200000001751,"raw_payload":"{\"stream\":\"btcusdt@depth@100ms\",\"data\":{\"e\":\"depthUpdate\",\"E\":1704067200175,\"U\":175,\"u\":175,\"b\":[[\"50000.00\",\"1.00000000\"]],\"a\":[]}}"}
{"local_receipt_timestamp_ns":1704067200000001761,"raw_payload":"{\"stream\":\"btcusdt@depth@100ms\",\"data\":{\"e\":\"depthUpdate\",\"E\":1704067200176,\"U\":176,\"u\":176,\"b\":[],\"a\":[[\"50001.00\",\"1.00000000\"]]}}"}
{"local_receipt_timestamp_ns":1704067200000001771,"raw_payload":"{\"stream\":\"btcusdt@depth@100ms\",\"data\":{\"e\":\"depthUpdate\",\"E\":1704067200177,\"U\":177,\"u\":177,\"b\":[[\"50000.00\",\"1.00000000\"]],\"a\":[]}}"}
{"local_receipt_timestamp_ns":1704067200000001781,"raw_payload":"{\"stream\":\"btcusdt@depth@100ms\",\"data\":{\"e\":\"depthUpdate\",\"E\":1704067200178,\"U\":178,\"u\":178,\"b\":[],\"a\":[[\"50001.00\",\"1.00000000\"]]}}"}
{"local_receipt_timestamp_ns":1704067200000001791,"raw_payload":"{\"stream\":\"btcusdt@depth@100ms\",\"data\":{\"e\":\"depthUpdate\",\"E\":1704067200179,\"U\":179,\"u\":179,\"b\":[[\"50000.00\",\"1.00000000\"]],\"a\":[]}}"}
{"local_receipt_timestamp_ns":1704067200000001801,"raw_payload":"{\"stream\":\"btcusdt@depth@100ms\",\"data\":{\"e\":\"depthUpdate\",\"E\":1704067200180,\"U\":180,\"u\":180,\"b\":[],\"a\":[[\"50001.00\",\"1.00000000\"]]}}"}
{"local_receipt_timestamp_ns":1704067200000001811,"raw_payload":"{\"stream\":\"btcusdt@depth@100ms\",\"data\":{\"e\":\"depthUpdate\",\"E\":1704067200181,\"U\":181,\"u\":181,\"b\":[[\"50000.00\",\"1.00000000\"]],\"a\":[]}}"}
{"local_receipt_timestamp_ns":1704067200000001821,"raw_payload":"{\"stream\":\"btcusdt@depth@100ms\",\"data\":{\"e\":\"depthUpdate\",\"E\":1704067200182,\"U\":182,\"u\":182,\"b\":[],\"a\":[[\"50001.00\",\"1.00000000\"]]}}"}
{"local_receipt_timestamp_ns":1704067200000001831,"raw_payload":"{\"stream\":\"btcusdt@depth@100ms\",\"data\":{\"e\":\"depthUpdate\",\"E\":1704067200183,\"U\":183,\"u\":183,\"b\":[[\"50000.00\",\"1.00000000\"]],\"a\":[]}}"}
{"local_receipt_timestamp_ns":1704067200000001841,"raw_payload":"{\"stream\":\"btcusdt@depth@100ms\",\"data\":{\"e\":\"depthUpdate\",\"E\":1704067200184,\"U\":184,\"u\":184,\"b\":[],\"a\":[[\"50001.00\",\"1.00000000\"]]}}"}
{"local_receipt_timestamp_ns":1704067200000001851,"raw_payload":"{\"stream\":\"btcusdt@depth@100ms\",\"data\":{\"e\":\"depthUpdate\",\"E\":1704067200185,\"U\":185,\"u\":185,\"b\":[[\"50000.00\",\"1.00000000\"]],\"a\":[]}}"}
{"local_receipt_timestamp_ns":1704067200000001861,"raw_payload":"{\"stream\":\"btcusdt@depth@100ms\",\"data\":{\"e\":\"depthUpdate\",\"E\":1704067200186,\"U\":186,\"u\":186,\"b\":[],\"a\":[[\"50001.00\",\"1.00000000\"]]}}"}
{"local_receipt_timestamp_ns":1704067200000001871,"raw_payload":"{\"stream\":\"btcusdt@depth@100ms\",\"data\":{\"e\":\"depthUpdate\",\"E\":1704067200187,\"U\":187,\"u\":187,\"b\":[[\"50000.00\",\"1.00000000\"]],\"a\":[]}}"}
{"local_receipt_timestamp_ns":1704067200000001881,"raw_payload":"{\"stream\":\"btcusdt@depth@100ms\",\"data\":{\"e\":\"depthUpdate\",\"E\":1704067200188,\"U\":188,\"u\":188,\"b\":[],\"a\":[[\"50001.00\",\"1.00000000\"]]}}"}
{"local_receipt_timestamp_ns":1704067200000001891,"raw_payload":"{\"stream\":\"btcusdt@depth@100ms\",\"data\":{\"e\":\"depthUpdate\",\"E\":1704067200189,\"U\":189,\"u\":189,\"b\":[[\"50000.00\",\"1.00000000\"]],\"a\":[]}}"}
{"local_receipt_timestamp_ns":1704067200000001901,"raw_payload":"{\"stream\":\"btcusdt@depth@100ms\",\"data\":{\"e\":\"depthUpdate\",\"E\":1704067200190,\"U\":190,\"u\":190,\"b\":[],\"a\":[[\"50001.00\",\"1.00000000\"]]}}"}
{"local_receipt_timestamp_ns":1704067200000001911,"raw_payload":"{\"stream\":\"btcusdt@depth@100ms\",\"data\":{\"e\":\"depthUpdate\",\"E\":1704067200191,\"U\":191,\"u\":191,\"b\":[[\"50000.00\",\"1.00000000\"]],\"a\":[]}}"}
{"local_receipt_timestamp_ns":1704067200000001921,"raw_payload":"{\"stream\":\"btcusdt@depth@100ms\",\"data\":{\"e\":\"depthUpdate\",\"E\":1704067200192,\"U\":192,\"u\":192,\"b\":[],\"a\":[[\"50001.00\",\"1.00000000\"]]}}"}
{"local_receipt_timestamp_ns":1704067200000001931,"raw_payload":"{\"stream\":\"btcusdt@depth@100ms\",\"data\":{\"e\":\"depthUpdate\",\"E\":1704067200193,\"U\":193,\"u\":193,\"b\":[[\"50000.00\",\"1.00000000\"]],\"a\":[]}}"}
{"local_receipt_timestamp_ns":1704067200000001941,"raw_payload":"{\"stream\":\"btcusdt@depth@100ms\",\"data\":{\"e\":\"depthUpdate\",\"E\":1704067200194,\"U\":194,\"u\":194,\"b\":[],\"a\":[[\"50001.00\",\"1.00000000\"]]}}"}
{"local_receipt_timestamp_ns":1704067200000001951,"raw_payload":"{\"stream\":\"btcusdt@depth@100ms\",\"data\":{\"e\":\"depthUpdate\",\"E\":1704067200195,\"U\":195,\"u\":195,\"b\":[[\"50000.00\",\"1.00000000\"]],\"a\":[]}}"}
{"local_receipt_timestamp_ns":1704067200000001961,"raw_payload":"{\"stream\":\"btcusdt@depth@100ms\",\"data\":{\"e\":\"depthUpdate\",\"E\":1704067200196,\"U\":196,\"u\":196,\"b\":[],\"a\":[[\"50001.00\",\"1.00000000\"]]}}"}
{"local_receipt_timestamp_ns":1704067200000001971,"raw_payload":"{\"stream\":\"btcusdt@depth@100ms\",\"data\":{\"e\":\"depthUpdate\",\"E\":1704067200197,\"U\":197,\"u\":197,\"b\":[[\"50000.00\",\"1.00000000\"]],\"a\":[]}}"}
{"local_receipt_timestamp_ns":1704067200000001981,"raw_payload":"{\"stream\":\"btcusdt@depth@100ms\",\"data\":{\"e\":\"depthUpdate\",\"E\":1704067200198,\"U\":198,\"u\":198,\"b\":[],\"a\":[[\"50001.00\",\"1.00000000\"]]}}"}
{"local_receipt_timestamp_ns":1704067200000001991,"raw_payload":"{\"stream\":\"btcusdt@depth@100ms\",\"data\":{\"e\":\"depthUpdate\",\"E\":1704067200199,\"U\":199,\"u\":199,\"b\":[[\"50000.00\",\"1.00000000\"]],\"a\":[]}}"}
{"local_receipt_timestamp_ns":1704067200000002001,"raw_payload":"{\"stream\":\"btcusdt@depth@100ms\",\"data\":{\"e\":\"depthUpdate\",\"E\":1704067200200,\"U\":200,\"u\":200,\"b\":[],\"a\":[[\"50001.00\",\"1.00000000\"]]}}"}
{"local_receipt_timestamp_ns":1704067200000002011,"raw_payload":"{\"stream\":\"btcusdt@depth@100ms\",\"data\":{\"e\":\"depthUpdate\",\"E\":1704067200201,\"U\":201,\"u\":201,\"b\":[[\"50000.00\",\"1.00000000\"]],\"a\":[]}}"}
{"local_receipt_timestamp_ns":1704067200000002021,"raw_payload":"{\"stream\":\"btcusdt@depth@100ms\",\"data\":{\"e\":\"depthUpdate\",\"E\":1704067200202,\"U\":202,\"u\":202,\"b\":[],\"a\":[[\"50001.00\",\"1.00000000\"]]}}"}
{"local_receipt_timestamp_ns":1704067200000002031,"raw_payload":"{\"stream\":\"btcusdt@depth@100ms\",\"data\":{\"e\":\"depthUpdate\",\"E\":1704067200203,\"U\":203,\"u\":203,\"b\":[[\"50000.00\",\"1.00000000\"]],\"a\":[]}}"}
{"local_receipt_timestamp_ns":1704067200000002041,"raw_payload":"{\"stream\":\"btcusdt@depth@100ms\",\"data\":{\"e\":\"depthUpdate\",\"E\":1704067200204,\"U\":204,\"u\":204,\"b\":[],\"a\":[[\"50001.00\",\"1.00000000\"]]}}"}
{"local_receipt_timestamp_ns":1704067200000002051,"raw_payload":"{\"stream\":\"btcusdt@depth@100ms\",\"data\":{\"e\":\"depthUpdate\",\"E\":1704067200205,\"U\":205,\"u\":205,\"b\":[[\"50000.00\",\"1.00000000\"]],\"a\":[]}}"}
{"local_receipt_timestamp_ns":1704067200000002061,"raw_payload":"{\"stream\":\"btcusdt@depth@100ms\",\"data\":{\"e\":\"depthUpdate\",\"E\":1704067200206,\"U\":206,\"u\":206,\"b\":[],\"a\":[[\"50001.00\",\"1.00000000\"]]}}"}
{"local_receipt_timestamp_ns":1704067200000002071,"raw_payload":"{\"stream\":\"btcusdt@depth@100ms\",\"data\":{\"e\":\"depthUpdate\",\"E\":1704067200207,\"U\":207,\"u\":207,\"b\":[[\"50000.00\",\"1.00000000\"]],\"a\":[]}}"}
{"local_receipt_timestamp_ns":1704067200000002081,"raw_payload":"{\"stream\":\"btcusdt@depth@100ms\",\"data\":{\"e\":\"depthUpdate\",\"E\":1704067200208,\"U\":208,\"u\":208,\"b\":[],\"a\":[[\"50001.00\",\"1.00000000\"]]}}"}
{"local_receipt_timestamp_ns":1704067200000002091,"raw_payload":"{\"stream\":\"btcusdt@depth@100ms\",\"data\":{\"e\":\"depthUpdate\",\"E\":1704067200209,\"U\":209,\"u\":209,\"b\":[[\"50000.00\",\"1.00000000\"]],\"a\":[]}}"}
{"local_receipt_timestamp_ns":1704067200000002101,"raw_payload":"{\"stream\":\"btcusdt@depth@100ms\",\"data\":{\"e\":\"depthUpdate\",\"E\":1704067200210,\"U\":210,\"u\":210,\"b\":[],\"a\":[[\"50001.00\",\"1.00000000\"]]}}"}
{"local_receipt_timestamp_ns":1704067200000002111,"raw_payload":"{\"stream\":\"btcusdt@depth@100ms\",\"data\":{\"e\":\"depthUpdate\",\"E\":1704067200211,\"U\":211,\"u\":211,\"b\":[[\"50000.00\",\"1.00000000\"]],\"a\":[]}}"}
{"local_receipt_timestamp_ns":1704067200000002121,"raw_payload":"{\"stream\":\"btcusdt@depth@100ms\",\"data\":{\"e\":\"depthUpdate\",\"E\":1704067200212,\"U\":212,\"u\":212,\"b\":[],\"a\":[[\"50001.00\",\"1.00000000\"]]}}"}
{"local_receipt_timestamp_ns":1704067200000002131,"raw_payload":"{\"stream\":\"btcusdt@depth@100ms\",\"data\":{\"e\":\"depthUpdate\",\"E\":1704067200213,\"U\":213,\"u\":213,\"b\":[[\"50000.00\",\"1.00000000\"]],\"a\":[]}}"}
{"local_receipt_timestamp_ns":1704067200000002141,"raw_payload":"{\"stream\":\"btcusdt@depth@100ms\",\"data\":{\"e\":\"depthUpdate\",\"E\":1704067200214,\"U\":214,\"u\":214,\"b\":[],\"a\":[[\"50001.00\",\"1.00000000\"]]}}"}
{"local_receipt_timestamp_ns":1704067200000002151,"raw_payload":"{\"stream\":\"btcusdt@depth@100ms\",\"data\":{\"e\":\"depthUpdate\",\"E\":1704067200215,\"U\":215,\"u\":215,\"b\":[[\"50000.00\",\"1.00000000\"]],\"a\":[]}}"}
{"local_receipt_timestamp_ns":1704067200000002161,"raw_payload":"{\"stream\":\"btcusdt@depth@100ms\",\"data\":{\"e\":\"depthUpdate\",\"E\":1704067200216,\"U\":216,\"u\":216,\"b\":[],\"a\":[[\"50001.00\",\"1.00000000\"]]}}"}
{"local_receipt_timestamp_ns":1704067200000002171,"raw_payload":"{\"stream\":\"btcusdt@depth@100ms\",\"data\":{\"e\":\"depthUpdate\",\"E\":1704067200217,\"U\":217,\"u\":217,\"b\":[[\"50000.00\",\"1.00000000\"]],\"a\":[]}}"}
{"local_receipt_timestamp_ns":1704067200000002181,"raw_payload":"{\"stream\":\"btcusdt@depth@100ms\",\"data\":{\"e\":\"depthUpdate\",\"E\":1704067200218,\"U\":218,\"u\":218,\"b\":[],\"a\":[[\"50001.00\",\"1.00000000\"]]}}"}
{"local_receipt_timestamp_ns":1704067200000002191,"raw_payload":"{\"stream\":\"btcusdt@depth@100ms\",\"data\":{\"e\":\"depthUpdate\",\"E\":1704067200219,\"U\":219,\"u\":219,\"b\":[[\"50000.00\",\"1.00000000\"]],\"a\":[]}}"}
{"local_receipt_timestamp_ns":1704067200000002201,"raw_payload":"{\"stream\":\"btcusdt@depth@100ms\",\"data\":{\"e\":\"depthUpdate\",\"E\":1704067200220,\"U\":220,\"u\":220,\"b\":[],\"a\":[[\"50001.00\",\"1.00000000\"]]}}"}
{"local_receipt_timestamp_ns":1704067200000002211,"raw_payload":"{\"stream\":\"btcusdt@depth@100ms\",\"data\":{\"e\":\"depthUpdate\",\"E\":1704067200221,\"U\":221,\"u\":221,\"b\":[[\"50000.00\",\"1.00000000\"]],\"a\":[]}}"}
{"local_receipt_timestamp_ns":1704067200000002221,"raw_payload":"{\"stream\":\"btcusdt@depth@100ms\",\"data\":{\"e\":\"depthUpdate\",\"E\":1704067200222,\"U\":222,\"u\":222,\"b\":[],\"a\":[[\"50001.00\",\"1.00000000\"]]}}"}
{"local_receipt_timestamp_ns":1704067200000002231,"raw_payload":"{\"stream\":\"btcusdt@depth@100ms\",\"data\":{\"e\":\"depthUpdate\",\"E\":1704067200223,\"U\":223,\"u\":223,\"b\":[[\"50000.00\",\"1.00000000\"]],\"a\":[]}}"}
{"local_receipt_timestamp_ns":1704067200000002241,"raw_payload":"{\"stream\":\"btcusdt@depth@100ms\",\"data\":{\"e\":\"depthUpdate\",\"E\":1704067200224,\"U\":224,\"u\":224,\"b\":[],\"a\":[[\"50001.00\",\"1.00000000\"]]}}"}
{"local_receipt_timestamp_ns":1704067200000002251,"raw_payload":"{\"stream\":\"btcusdt@depth@100ms\",\"data\":{\"e\":\"depthUpdate\",\"E\":1704067200225,\"U\":225,\"u\":225,\"b\":[[\"50000.00\",\"1.00000000\"]],\"a\":[]}}"}
{"local_receipt_timestamp_ns":1704067200000002261,"raw_payload":"{\"stream\":\"btcusdt@depth@100ms\",\"data\":{\"e\":\"depthUpdate\",\"E\":1704067200226,\"U\":226,\"u\":226,\"b\":[],\"a\":[[\"50001.00\",\"1.00000000\"]]}}"}
{"local_receipt_timestamp_ns":1704067200000002271,"raw_payload":"{\"stream\":\"btcusdt@depth@100ms\",\"data\":{\"e\":\"depthUpdate\",\"E\":1704067200227,\"U\":227,\"u\":227,\"b\":[[\"50000.00\",\"1.00000000\"]],\"a\":[]}}"}
{"local_receipt_timestamp_ns":1704067200000002281,"raw_payload":"{\"stream\":\"btcusdt@depth@100ms\",\"data\":{\"e\":\"depthUpdate\",\"E\":1704067200228,\"U\":228,\"u\":228,\"b\":[],\"a\":[[\"50001.00\",\"1.00000000\"]]}}"}
{"local_receipt_timestamp_ns":1704067200000002291,"raw_payload":"{\"stream\":\"btcusdt@depth@100ms\",\"data\":{\"e\":\"depthUpdate\",\"E\":1704067200229,\"U\":229,\"u\":229,\"b\":[[\"50000.00\",\"1.00000000\"]],\"a\":[]}}"}
{"local_receipt_timestamp_ns":1704067200000002301,"raw_payload":"{\"stream\":\"btcusdt@depth@100ms\",\"data\":{\"e\":\"depthUpdate\",\"E\":1704067200230,\"U\":230,\"u\":230,\"b\":[],\"a\":[[\"50001.00\",\"1.00000000\"]]}}"}
{"local_receipt_timestamp_ns":1704067200000002311,"raw_payload":"{\"stream\":\"btcusdt@depth@100ms\",\"data\":{\"e\":\"depthUpdate\",\"E\":1704067200231,\"U\":231,\"u\":231,\"b\":[[\"50000.00\",\"1.00000000\"]],\"a\":[]}}"}
{"local_receipt_timestamp_ns":1704067200000002321,"raw_payload":"{\"stream\":\"btcusdt@depth@100ms\",\"data\":{\"e\":\"depthUpdate\",\"E\":1704067200232,\"U\":232,\"u\":232,\"b\":[],\"a\":[[\"50001.00\",\"1.00000000\"]]}}"}
{"local_receipt_timestamp_ns":1704067200000002331,"raw_payload":"{\"stream\":\"btcusdt@depth@100ms\",\"data\":{\"e\":\"depthUpdate\",\"E\":1704067200233,\"U\":233,\"u\":233,\"b\":[[\"50000.00\",\"1.00000000\"]],\"a\":[]}}"}
{"local_receipt_timestamp_ns":1704067200000002341,"raw_payload":"{\"stream\":\"btcusdt@depth@100ms\",\"data\":{\"e\":\"depthUpdate\",\"E\":1704067200234,\"U\":234,\"u\":234,\"b\":[],\"a\":[[\"50001.00\",\"1.00000000\"]]}}"}
{"local_receipt_timestamp_ns":1704067200000002351,"raw_payload":"{\"stream\":\"btcusdt@depth@100ms\",\"data\":{\"e\":\"depthUpdate\",\"E\":1704067200235,\"U\":235,\"u\":235,\"b\":[[\"50000.00\",\"1.00000000\"]],\"a\":[]}}"}
{"local_receipt_timestamp_ns":1704067200000002361,"raw_payload":"{\"stream\":\"btcusdt@depth@100ms\",\"data\":{\"e\":\"depthUpdate\",\"E\":1704067200236,\"U\":236,\"u\":236,\"b\":[],\"a\":[[\"50001.00\",\"1.00000000\"]]}}"}
{"local_receipt_timestamp_ns":1704067200000002371,"raw_payload":"{\"stream\":\"btcusdt@depth@100ms\",\"data\":{\"e\":\"depthUpdate\",\"E\":1704067200237,\"U\":237,\"u\":237,\"b\":[[\"50000.00\",\"1.00000000\"]],\"a\":[]}}"}
{"local_receipt_timestamp_ns":1704067200000002381,"raw_payload":"{\"stream\":\"btcusdt@depth@100ms\",\"data\":{\"e\":\"depthUpdate\",\"E\":1704067200238,\"U\":238,\"u\":238,\"b\":[],\"a\":[[\"50001.00\",\"1.00000000\"]]}}"}
{"local_receipt_timestamp_ns":1704067200000002391,"raw_payload":"{\"stream\":\"btcusdt@depth@100ms\",\"data\":{\"e\":\"depthUpdate\",\"E\":1704067200239,\"U\":239,\"u\":239,\"b\":[[\"50000.00\",\"1.00000000\"]],\"a\":[]}}"}
{"local_receipt_timestamp_ns":1704067200000002401,"raw_payload":"{\"stream\":\"btcusdt@depth@100ms\",\"data\":{\"e\":\"depthUpdate\",\"E\":1704067200240,\"U\":240,\"u\":240,\"b\":[],\"a\":[[\"50001.00\",\"1.00000000\"]]}}"}
{"local_receipt_timestamp_ns":1704067200000002411,"raw_payload":"{\"stream\":\"btcusdt@depth@100ms\",\"data\":{\"e\":\"depthUpdate\",\"E\":1704067200241,\"U\":241,\"u\":241,\"b\":[[\"50000.00\",\"1.00000000\"]],\"a\":[]}}"}
{"local_receipt_timestamp_ns":1704067200000002421,"raw_payload":"{\"stream\":\"btcusdt@depth@100ms\",\"data\":{\"e\":\"depthUpdate\",\"E\":1704067200242,\"U\":242,\"u\":242,\"b\":[],\"a\":[[\"50001.00\",\"1.00000000\"]]}}"}
{"local_receipt_timestamp_ns":1704067200000002431,"raw_payload":"{\"stream\":\"btcusdt@depth@100ms\",\"data\":{\"e\":\"depthUpdate\",\"E\":1704067200243,\"U\":243,\"u\":243,\"b\":[[\"50000.00\",\"1.00000000\"]],\"a\":[]}}"}
{"local_receipt_timestamp_ns":1704067200000002441,"raw_payload":"{\"stream\":\"btcusdt@depth@100ms\",\"data\":{\"e\":\"depthUpdate\",\"E\":1704067200244,\"U\":244,\"u\":244,\"b\":[],\"a\":[[\"50001.00\",\"1.00000000\"]]}}"}
{"local_receipt_timestamp_ns":1704067200000002451,"raw_payload":"{\"stream\":\"btcusdt@depth@100ms\",\"data\":{\"e\":\"depthUpdate\",\"E\":1704067200245,\"U\":245,\"u\":245,\"b\":[[\"50000.00\",\"1.00000000\"]],\"a\":[]}}"}
{"local_receipt_timestamp_ns":1704067200000002461,"raw_payload":"{\"stream\":\"btcusdt@depth@100ms\",\"data\":{\"e\":\"depthUpdate\",\"E\":1704067200246,\"U\":246,\"u\":246,\"b\":[],\"a\":[[\"50001.00\",\"1.00000000\"]]}}"}
{"local_receipt_timestamp_ns":1704067200000002471,"raw_payload":"{\"stream\":\"btcusdt@depth@100ms\",\"data\":{\"e\":\"depthUpdate\",\"E\":1704067200247,\"U\":247,\"u\":247,\"b\":[[\"50000.00\",\"1.00000000\"]],\"a\":[]}}"}
{"local_receipt_timestamp_ns":1704067200000002481,"raw_payload":"{\"stream\":\"btcusdt@depth@100ms\",\"data\":{\"e\":\"depthUpdate\",\"E\":1704067200248,\"U\":248,\"u\":248,\"b\":[],\"a\":[[\"50001.00\",\"1.00000000\"]]}}"}
{"local_receipt_timestamp_ns":1704067200000002491,"raw_payload":"{\"stream\":\"btcusdt@depth@100ms\",\"data\":{\"e\":\"depthUpdate\",\"E\":1704067200249,\"U\":249,\"u\":249,\"b\":[[\"50000.00\",\"1.00000000\"]],\"a\":[]}}"}
{"local_receipt_timestamp_ns":1704067200000002501,"raw_payload":"{\"stream\":\"btcusdt@depth@100ms\",\"data\":{\"e\":\"depthUpdate\",\"E\":1704067200250,\"U\":250,\"u\":250,\"b\":[],\"a\":[[\"50001.00\",\"1.00000000\"]]}}"}
{"local_receipt_timestamp_ns":1704067200000002511,"raw_payload":"{\"stream\":\"btcusdt@depth@100ms\",\"data\":{\"e\":\"depthUpdate\",\"E\":1704067200251,\"U\":250,\"u\":250,\"b\":[],\"a\":[[\"50001.00\",\"1.00000000\"]]}}"}
{"local_receipt_timestamp_ns":1704067200000002521,"raw_payload":"{\"stream\":\"btcusdt@depth@100ms\",\"data\":{\"e\":\"depthUpdate\",\"E\":1704067200252,\"U\":249,\"u\":249,\"b\":[[\"50000.00\",\"1.00000000\"]],\"a\":[]}}"}
{"local_receipt_timestamp_ns":1704067200000002531,"raw_payload":"{\"stream\":\"btcusdt@depth@100ms\",\"data\":{\"e\":\"depthUpdate\",\"E\":1704067200253,\"U\":252,\"u\":252,\"b\":[],\"a\":[[\"50001.00\",\"1.00000000\"]]}}"}
{"local_receipt_timestamp_ns":1704067200000002541,"raw_payload":"{\"stream\":\"btcusdt@depth@100ms\",\"data\":{\"e\":\"depthUpdate\",\"E\":1704067200254,\"U\":253,\"u\":253,\"b\":[[\"50000.00\",\"1.00000000\"]],\"a\":[]}}"}
{"local_receipt_timestamp_ns":1704067200000002551,"raw_payload":"{\"stream\":\"btcusdt@depth@100ms\",\"data\":{\"e\":\"depthUpdate\",\"E\":1704067200255,\"U\":254,\"u\":254,\"b\":[],\"a\":[[\"50001.00\",\"1.00000000\"]]}}"}
{"local_receipt_timestamp_ns":1704067200000002561,"raw_payload":"{\"stream\":\"btcusdt@depth@100ms\",\"data\":{\"e\":\"depthUpdate\",\"E\":1704067200256,\"U\":255,\"u\":255,\"b\":[[\"50000.00\",\"1.00000000\"]],\"a\":[]}}"}
{"local_receipt_timestamp_ns":1704067200000002571,"raw_payload":"{\"stream\":\"btcusdt@depth@100ms\",\"data\":{\"e\":\"depthUpdate\",\"E\":1704067200257,\"U\":256,\"u\":256,\"b\":[],\"a\":[[\"50001.00\",\"1.00000000\"]]}}"}
{"local_receipt_timestamp_ns":1704067200000002581,"raw_payload":"{\"stream\":\"btcusdt@depth@100ms\",\"data\":{\"e\":\"depthUpdate\",\"E\":1704067200258,\"U\":257,\"u\":257,\"b\":[[\"50000.00\",\"1.00000000\"]],\"a\":[]}}"}
{"local_receipt_timestamp_ns":1704067200000002591,"raw_payload":"{\"stream\":\"btcusdt@depth@100ms\",\"data\":{\"e\":\"depthUpdate\",\"E\":1704067200259,\"U\":258,\"u\":258,\"b\":[],\"a\":[[\"50001.00\",\"1.00000000\"]]}}"}
{"local_receipt_timestamp_ns":1704067200000002601,"raw_payload":"{\"stream\":\"btcusdt@depth@100ms\",\"data\":{\"e\":\"depthUpdate\",\"E\":1704067200260,\"U\":259,\"u\":259,\"b\":[[\"50000.00\",\"1.00000000\"]],\"a\":[]}}"}
{"local_receipt_timestamp_ns":1704067200000002611,"raw_payload":"{\"stream\":\"btcusdt@depth@100ms\",\"data\":{\"e\":\"depthUpdate\",\"E\":1704067200261,\"U\":260,\"u\":260,\"b\":[],\"a\":[[\"50001.00\",\"1.00000000\"]]}}"}
{"local_receipt_timestamp_ns":1704067200000002621,"raw_payload":"{\"stream\":\"btcusdt@depth@100ms\",\"data\":{\"e\":\"depthUpdate\",\"E\":1704067200262,\"U\":261,\"u\":261,\"b\":[[\"50000.00\",\"1.00000000\"]],\"a\":[]}}"}
{"local_receipt_timestamp_ns":1704067200000002631,"raw_payload":"{\"stream\":\"btcusdt@depth@100ms\",\"data\":{\"e\":\"depthUpdate\",\"E\":1704067200263,\"U\":262,\"u\":262,\"b\":[],\"a\":[[\"50001.00\",\"1.00000000\"]]}}"}
{"local_receipt_timestamp_ns":1704067200000002641,"raw_payload":"{\"stream\":\"btcusdt@depth@100ms\",\"data\":{\"e\":\"depthUpdate\",\"E\":1704067200264,\"U\":263,\"u\":263,\"b\":[[\"50000.00\",\"1.00000000\"]],\"a\":[]}}"}
{"local_receipt_timestamp_ns":1704067200000002651,"raw_payload":"{\"stream\":\"btcusdt@depth@100ms\",\"data\":{\"e\":\"depthUpdate\",\"E\":1704067200265,\"U\":264,\"u\":264,\"b\":[],\"a\":[[\"50001.00\",\"1.00000000\"]]}}"}
{"local_receipt_timestamp_ns":1704067200000002661,"raw_payload":"{\"stream\":\"btcusdt@depth@100ms\",\"data\":{\"e\":\"depthUpdate\",\"E\":1704067200266,\"U\":265,\"u\":265,\"b\":[[\"50000.00\",\"1.00000000\"]],\"a\":[]}}"}
{"local_receipt_timestamp_ns":1704067200000002671,"raw_payload":"{\"stream\":\"btcusdt@depth@100ms\",\"data\":{\"e\":\"depthUpdate\",\"E\":1704067200267,\"U\":266,\"u\":266,\"b\":[],\"a\":[[\"50001.00\",\"1.00000000\"]]}}"}
{"local_receipt_timestamp_ns":1704067200000002681,"raw_payload":"{\"stream\":\"btcusdt@depth@100ms\",\"data\":{\"e\":\"depthUpdate\",\"E\":1704067200268,\"U\":267,\"u\":267,\"b\":[[\"50000.00\",\"1.00000000\"]],\"a\":[]}}"}
{"local_receipt_timestamp_ns":1704067200000002691,"raw_payload":"{\"stream\":\"btcusdt@depth@100ms\",\"data\":{\"e\":\"depthUpdate\",\"E\":1704067200269,\"U\":268,\"u\":268,\"b\":[],\"a\":[[\"50001.00\",\"1.00000000\"]]}}"}
{"local_receipt_timestamp_ns":1704067200000002701,"raw_payload":"{\"stream\":\"btcusdt@depth@100ms\",\"data\":{\"e\":\"depthUpdate\",\"E\":1704067200270,\"U\":269,\"u\":269,\"b\":[[\"50000.00\",\"1.00000000\"]],\"a\":[]}}"}
{"local_receipt_timestamp_ns":1704067200000002711,"raw_payload":"{\"stream\":\"btcusdt@depth@100ms\",\"data\":{\"e\":\"depthUpdate\",\"E\":1704067200271,\"U\":270,\"u\":270,\"b\":[],\"a\":[[\"50001.00\",\"1.00000000\"]]}}"}
{"local_receipt_timestamp_ns":1704067200000002721,"raw_payload":"{\"stream\":\"btcusdt@depth@100ms\",\"data\":{\"e\":\"depthUpdate\",\"E\":1704067200272,\"U\":271,\"u\":271,\"b\":[[\"50000.00\",\"1.00000000\"]],\"a\":[]}}"}
{"local_receipt_timestamp_ns":1704067200000002731,"raw_payload":"{\"stream\":\"btcusdt@depth@100ms\",\"data\":{\"e\":\"depthUpdate\",\"E\":1704067200273,\"U\":272,\"u\":272,\"b\":[],\"a\":[[\"50001.00\",\"1.00000000\"]]}}"}
{"local_receipt_timestamp_ns":1704067200000002741,"raw_payload":"{\"stream\":\"btcusdt@depth@100ms\",\"data\":{\"e\":\"depthUpdate\",\"E\":1704067200274,\"U\":273,\"u\":273,\"b\":[[\"50000.00\",\"1.00000000\"]],\"a\":[]}}"}
{"local_receipt_timestamp_ns":1704067200000002751,"raw_payload":"{\"stream\":\"btcusdt@depth@100ms\",\"data\":{\"e\":\"depthUpdate\",\"E\":1704067200275,\"U\":274,\"u\":274,\"b\":[],\"a\":[[\"50001.00\",\"1.00000000\"]]}}"}
{"local_receipt_timestamp_ns":1704067200000002761,"raw_payload":"{\"stream\":\"btcusdt@depth@100ms\",\"data\":{\"e\":\"depthUpdate\",\"E\":1704067200276,\"U\":275,\"u\":275,\"b\":[[\"50000.00\",\"1.00000000\"]],\"a\":[]}}"}
{"local_receipt_timestamp_ns":1704067200000002771,"raw_payload":"{\"stream\":\"btcusdt@depth@100ms\",\"data\":{\"e\":\"depthUpdate\",\"E\":1704067200277,\"U\":276,\"u\":276,\"b\":[],\"a\":[[\"50001.00\",\"1.00000000\"]]}}"}
{"local_receipt_timestamp_ns":1704067200000002781,"raw_payload":"{\"stream\":\"btcusdt@depth@100ms\",\"data\":{\"e\":\"depthUpdate\",\"E\":1704067200278,\"U\":277,\"u\":277,\"b\":[[\"50000.00\",\"1.00000000\"]],\"a\":[]}}"}
{"local_receipt_timestamp_ns":1704067200000002791,"raw_payload":"{\"stream\":\"btcusdt@depth@100ms\",\"data\":{\"e\":\"depthUpdate\",\"E\":1704067200279,\"U\":278,\"u\":278,\"b\":[],\"a\":[[\"50001.00\",\"1.00000000\"]]}}"}
{"local_receipt_timestamp_ns":1704067200000002801,"raw_payload":"{\"stream\":\"btcusdt@depth@100ms\",\"data\":{\"e\":\"depthUpdate\",\"E\":1704067200280,\"U\":279,\"u\":279,\"b\":[[\"50000.00\",\"1.00000000\"]],\"a\":[]}}"}
{"local_receipt_timestamp_ns":1704067200000002811,"raw_payload":"{\"stream\":\"btcusdt@depth@100ms\",\"data\":{\"e\":\"depthUpdate\",\"E\":1704067200281,\"U\":280,\"u\":280,\"b\":[],\"a\":[[\"50001.00\",\"1.00000000\"]]}}"}
{"local_receipt_timestamp_ns":1704067200000002821,"raw_payload":"{\"stream\":\"btcusdt@depth@100ms\",\"data\":{\"e\":\"depthUpdate\",\"E\":1704067200282,\"U\":281,\"u\":281,\"b\":[[\"50000.00\",\"1.00000000\"]],\"a\":[]}}"}
{"local_receipt_timestamp_ns":1704067200000002831,"raw_payload":"{\"stream\":\"btcusdt@depth@100ms\",\"data\":{\"e\":\"depthUpdate\",\"E\":1704067200283,\"U\":282,\"u\":282,\"b\":[],\"a\":[[\"50001.00\",\"1.00000000\"]]}}"}
{"local_receipt_timestamp_ns":1704067200000002841,"raw_payload":"{\"stream\":\"btcusdt@depth@100ms\",\"data\":{\"e\":\"depthUpdate\",\"E\":1704067200284,\"U\":283,\"u\":283,\"b\":[[\"50000.00\",\"1.00000000\"]],\"a\":[]}}"}
{"local_receipt_timestamp_ns":1704067200000002851,"raw_payload":"{\"stream\":\"btcusdt@depth@100ms\",\"data\":{\"e\":\"depthUpdate\",\"E\":1704067200285,\"U\":284,\"u\":284,\"b\":[],\"a\":[[\"50001.00\",\"1.00000000\"]]}}"}
{"local_receipt_timestamp_ns":1704067200000002861,"raw_payload":"{\"stream\":\"btcusdt@depth@100ms\",\"data\":{\"e\":\"depthUpdate\",\"E\":1704067200286,\"U\":285,\"u\":285,\"b\":[[\"50000.00\",\"1.00000000\"]],\"a\":[]}}"}
{"local_receipt_timestamp_ns":1704067200000002871,"raw_payload":"{\"stream\":\"btcusdt@depth@100ms\",\"data\":{\"e\":\"depthUpdate\",\"E\":1704067200287,\"U\":286,\"u\":286,\"b\":[],\"a\":[[\"50001.00\",\"1.00000000\"]]}}"}
{"local_receipt_timestamp_ns":1704067200000002881,"raw_payload":"{\"stream\":\"btcusdt@depth@100ms\",\"data\":{\"e\":\"depthUpdate\",\"E\":1704067200288,\"U\":287,\"u\":287,\"b\":[[\"50000.00\",\"1.00000000\"]],\"a\":[]}}"}
{"local_receipt_timestamp_ns":1704067200000002891,"raw_payload":"{\"stream\":\"btcusdt@depth@100ms\",\"data\":{\"e\":\"depthUpdate\",\"E\":1704067200289,\"U\":288,\"u\":288,\"b\":[],\"a\":[[\"50001.00\",\"1.00000000\"]]}}"}
{"local_receipt_timestamp_ns":1704067200000002901,"raw_payload":"{\"stream\":\"btcusdt@depth@100ms\",\"data\":{\"e\":\"depthUpdate\",\"E\":1704067200290,\"U\":289,\"u\":289,\"b\":[[\"50000.00\",\"1.00000000\"]],\"a\":[]}}"}
{"local_receipt_timestamp_ns":1704067200000002911,"raw_payload":"{\"stream\":\"btcusdt@depth@100ms\",\"data\":{\"e\":\"depthUpdate\",\"E\":1704067200291,\"U\":290,\"u\":290,\"b\":[],\"a\":[[\"50001.00\",\"1.00000000\"]]}}"}
{"local_receipt_timestamp_ns":1704067200000002921,"raw_payload":"{\"stream\":\"btcusdt@depth@100ms\",\"data\":{\"e\":\"depthUpdate\",\"E\":1704067200292,\"U\":291,\"u\":291,\"b\":[[\"50000.00\",\"1.00000000\"]],\"a\":[]}}"}
{"local_receipt_timestamp_ns":1704067200000002931,"raw_payload":"{\"stream\":\"btcusdt@depth@100ms\",\"data\":{\"e\":\"depthUpdate\",\"E\":1704067200293,\"U\":292,\"u\":292,\"b\":[],\"a\":[[\"50001.00\",\"1.00000000\"]]}}"}
{"local_receipt_timestamp_ns":1704067200000002941,"raw_payload":"{\"stream\":\"btcusdt@depth@100ms\",\"data\":{\"e\":\"depthUpdate\",\"E\":1704067200294,\"U\":293,\"u\":293,\"b\":[[\"50000.00\",\"1.00000000\"]],\"a\":[]}}"}
{"local_receipt_timestamp_ns":1704067200000002951,"raw_payload":"{\"stream\":\"btcusdt@depth@100ms\",\"data\":{\"e\":\"depthUpdate\",\"E\":1704067200295,\"U\":294,\"u\":294,\"b\":[],\"a\":[[\"50001.00\",\"1.00000000\"]]}}"}
{"local_receipt_timestamp_ns":1704067200000002961,"raw_payload":"{\"stream\":\"btcusdt@depth@100ms\",\"data\":{\"e\":\"depthUpdate\",\"E\":1704067200296,\"U\":295,\"u\":295,\"b\":[[\"50000.00\",\"1.00000000\"]],\"a\":[]}}"}
{"local_receipt_timestamp_ns":1704067200000002971,"raw_payload":"{\"stream\":\"btcusdt@depth@100ms\",\"data\":{\"e\":\"depthUpdate\",\"E\":1704067200297,\"U\":296,\"u\":296,\"b\":[],\"a\":[[\"50001.00\",\"1.00000000\"]]}}"}
{"local_receipt_timestamp_ns":1704067200000002981,"raw_payload":"{\"stream\":\"btcusdt@depth@100ms\",\"data\":{\"e\":\"depthUpdate\",\"E\":1704067200298,\"U\":297,\"u\":297,\"b\":[[\"50000.00\",\"1.00000000\"]],\"a\":[]}}"}
{"local_receipt_timestamp_ns":1704067200000002991,"raw_payload":"{\"stream\":\"btcusdt@depth@100ms\",\"data\":{\"e\":\"depthUpdate\",\"E\":1704067200299,\"U\":298,\"u\":298,\"b\":[],\"a\":[[\"50001.00\",\"1.00000000\"]]}}"}
{"local_receipt_timestamp_ns":1704067200000003001,"raw_payload":"{\"stream\":\"btcusdt@depth@100ms\",\"data\":{\"e\":\"depthUpdate\",\"E\":1704067200300,\"U\":299,\"u\":299,\"b\":[[\"50000.00\",\"1.00000000\"]],\"a\":[]}}"}
{"local_receipt_timestamp_ns":1704067200000003011,"raw_payload":"{\"stream\":\"btcusdt@depth@100ms\",\"data\":{\"e\":\"depthUpdate\",\"E\":1704067200301,\"U\":300,\"u\":300,\"b\":[],\"a\":[[\"50001.00\",\"1.00000000\"]]}}"}
{"local_receipt_timestamp_ns":1704067200000003021,"raw_payload":"{\"stream\":\"btcusdt@depth@100ms\",\"data\":{\"e\":\"depthUpdate\",\"E\":1704067200302,\"U\":301,\"u\":301,\"b\":[[\"50000.00\",\"1.00000000\"]],\"a\":[]}}"}
{"local_receipt_timestamp_ns":1704067200000003031,"raw_payload":"{\"stream\":\"btcusdt@depth@100ms\",\"data\":{\"e\":\"depthUpdate\",\"E\":1704067200303,\"U\":302,\"u\":302,\"b\":[],\"a\":[[\"50001.00\",\"1.00000000\"]]}}"}
{"local_receipt_timestamp_ns":1704067200000003041,"raw_payload":"{\"stream\":\"btcusdt@depth@100ms\",\"data\":{\"e\":\"depthUpdate\",\"E\":1704067200304,\"U\":303,\"u\":303,\"b\":[[\"50000.00\",\"1.00000000\"]],\"a\":[]}}"}
{"local_receipt_timestamp_ns":1704067200000003051,"raw_payload":"{\"stream\":\"btcusdt@depth@100ms\",\"data\":{\"e\":\"depthUpdate\",\"E\":1704067200305,\"U\":304,\"u\":304,\"b\":[],\"a\":[[\"50001.00\",\"1.00000000\"]]}}"}
{"local_receipt_timestamp_ns":1704067200000003061,"raw_payload":"{\"stream\":\"btcusdt@depth@100ms\",\"data\":{\"e\":\"depthUpdate\",\"E\":1704067200306,\"U\":305,\"u\":305,\"b\":[[\"50000.00\",\"1.00000000\"]],\"a\":[]}}"}
{"local_receipt_timestamp_ns":1704067200000003071,"raw_payload":"{\"stream\":\"btcusdt@depth@100ms\",\"data\":{\"e\":\"depthUpdate\",\"E\":1704067200307,\"U\":306,\"u\":306,\"b\":[],\"a\":[[\"50001.00\",\"1.00000000\"]]}}"}
{"local_receipt_timestamp_ns":1704067200000003081,"raw_payload":"{\"stream\":\"btcusdt@depth@100ms\",\"data\":{\"e\":\"depthUpdate\",\"E\":1704067200308,\"U\":307,\"u\":307,\"b\":[[\"50000.00\",\"1.00000000\"]],\"a\":[]}}"}
{"local_receipt_timestamp_ns":1704067200000003091,"raw_payload":"{\"stream\":\"btcusdt@depth@100ms\",\"data\":{\"e\":\"depthUpdate\",\"E\":1704067200309,\"U\":308,\"u\":308,\"b\":[],\"a\":[[\"50001.00\",\"1.00000000\"]]}}"}
{"local_receipt_timestamp_ns":1704067200000003101,"raw_payload":"{\"stream\":\"btcusdt@depth@100ms\",\"data\":{\"e\":\"depthUpdate\",\"E\":1704067200310,\"U\":309,\"u\":309,\"b\":[[\"50000.00\",\"1.00000000\"]],\"a\":[]}}"}
{"local_receipt_timestamp_ns":1704067200000003111,"raw_payload":"{\"stream\":\"btcusdt@depth@100ms\",\"data\":{\"e\":\"depthUpdate\",\"E\":1704067200311,\"U\":310,\"u\":310,\"b\":[],\"a\":[[\"50001.00\",\"1.00000000\"]]}}"}
{"local_receipt_timestamp_ns":1704067200000003121,"raw_payload":"{\"stream\":\"btcusdt@depth@100ms\",\"data\":{\"e\":\"depthUpdate\",\"E\":1704067200312,\"U\":311,\"u\":311,\"b\":[[\"50000.00\",\"1.00000000\"]],\"a\":[]}}"}
{"local_receipt_timestamp_ns":1704067200000003131,"raw_payload":"{\"stream\":\"btcusdt@depth@100ms\",\"data\":{\"e\":\"depthUpdate\",\"E\":1704067200313,\"U\":312,\"u\":312,\"b\":[],\"a\":[[\"50001.00\",\"1.00000000\"]]}}"}
{"local_receipt_timestamp_ns":1704067200000003141,"raw_payload":"{\"stream\":\"btcusdt@depth@100ms\",\"data\":{\"e\":\"depthUpdate\",\"E\":1704067200314,\"U\":313,\"u\":313,\"b\":[[\"50000.00\",\"1.00000000\"]],\"a\":[]}}"}
{"local_receipt_timestamp_ns":1704067200000003151,"raw_payload":"{\"stream\":\"btcusdt@depth@100ms\",\"data\":{\"e\":\"depthUpdate\",\"E\":1704067200315,\"U\":314,\"u\":314,\"b\":[],\"a\":[[\"50001.00\",\"1.00000000\"]]}}"}
{"local_receipt_timestamp_ns":1704067200000003161,"raw_payload":"{\"stream\":\"btcusdt@depth@100ms\",\"data\":{\"e\":\"depthUpdate\",\"E\":1704067200316,\"U\":315,\"u\":315,\"b\":[[\"50000.00\",\"1.00000000\"]],\"a\":[]}}"}
{"local_receipt_timestamp_ns":1704067200000003171,"raw_payload":"{\"stream\":\"btcusdt@depth@100ms\",\"data\":{\"e\":\"depthUpdate\",\"E\":1704067200317,\"U\":316,\"u\":316,\"b\":[],\"a\":[[\"50001.00\",\"1.00000000\"]]}}"}
{"local_receipt_timestamp_ns":1704067200000003181,"raw_payload":"{\"stream\":\"btcusdt@depth@100ms\",\"data\":{\"e\":\"depthUpdate\",\"E\":1704067200318,\"U\":317,\"u\":317,\"b\":[[\"50000.00\",\"1.00000000\"]],\"a\":[]}}"}
{"local_receipt_timestamp_ns":1704067200000003191,"raw_payload":"{\"stream\":\"btcusdt@depth@100ms\",\"data\":{\"e\":\"depthUpdate\",\"E\":1704067200319,\"U\":318,\"u\":318,\"b\":[],\"a\":[[\"50001.00\",\"1.00000000\"]]}}"}
{"local_receipt_timestamp_ns":1704067200000003201,"raw_payload":"{\"stream\":\"btcusdt@depth@100ms\",\"data\":{\"e\":\"depthUpdate\",\"E\":1704067200320,\"U\":319,\"u\":319,\"b\":[[\"50000.00\",\"1.00000000\"]],\"a\":[]}}"}
{"local_receipt_timestamp_ns":1704067200000003211,"raw_payload":"{\"stream\":\"btcusdt@depth@100ms\",\"data\":{\"e\":\"depthUpdate\",\"E\":1704067200321,\"U\":320,\"u\":320,\"b\":[],\"a\":[[\"50001.00\",\"1.00000000\"]]}}"}
{"local_receipt_timestamp_ns":1704067200000003221,"raw_payload":"{\"stream\":\"btcusdt@depth@100ms\",\"data\":{\"e\":\"depthUpdate\",\"E\":1704067200322,\"U\":321,\"u\":321,\"b\":[[\"50000.00\",\"1.00000000\"]],\"a\":[]}}"}
{"local_receipt_timestamp_ns":1704067200000003231,"raw_payload":"{\"stream\":\"btcusdt@depth@100ms\",\"data\":{\"e\":\"depthUpdate\",\"E\":1704067200323,\"U\":322,\"u\":322,\"b\":[],\"a\":[[\"50001.00\",\"1.00000000\"]]}}"}
{"local_receipt_timestamp_ns":1704067200000003241,"raw_payload":"{\"stream\":\"btcusdt@depth@100ms\",\"data\":{\"e\":\"depthUpdate\",\"E\":1704067200324,\"U\":323,\"u\":323,\"b\":[[\"50000.00\",\"1.00000000\"]],\"a\":[]}}"}
{"local_receipt_timestamp_ns":1704067200000003251,"raw_payload":"{\"stream\":\"btcusdt@depth@100ms\",\"data\":{\"e\":\"depthUpdate\",\"E\":1704067200325,\"U\":324,\"u\":324,\"b\":[],\"a\":[[\"50001.00\",\"1.00000000\"]]}}"}
{"local_receipt_timestamp_ns":1704067200000003261,"raw_payload":"{\"stream\":\"btcusdt@depth@100ms\",\"data\":{\"e\":\"depthUpdate\",\"E\":1704067200326,\"U\":325,\"u\":325,\"b\":[[\"50000.00\",\"1.00000000\"]],\"a\":[]}}"}
{"local_receipt_timestamp_ns":1704067200000003271,"raw_payload":"{\"stream\":\"btcusdt@depth@100ms\",\"data\":{\"e\":\"depthUpdate\",\"E\":1704067200327,\"U\":326,\"u\":326,\"b\":[],\"a\":[[\"50001.00\",\"1.00000000\"]]}}"}
{"local_receipt_timestamp_ns":1704067200000003281,"raw_payload":"{\"stream\":\"btcusdt@depth@100ms\",\"data\":{\"e\":\"depthUpdate\",\"E\":1704067200328,\"U\":327,\"u\":327,\"b\":[[\"50000.00\",\"1.00000000\"]],\"a\":[]}}"}
{"local_receipt_timestamp_ns":1704067200000003291,"raw_payload":"{\"stream\":\"btcusdt@depth@100ms\",\"data\":{\"e\":\"depthUpdate\",\"E\":1704067200329,\"U\":328,\"u\":328,\"b\":[],\"a\":[[\"50001.00\",\"1.00000000\"]]}}"}
{"local_receipt_timestamp_ns":1704067200000003301,"raw_payload":"{\"stream\":\"btcusdt@depth@100ms\",\"data\":{\"e\":\"depthUpdate\",\"E\":1704067200330,\"U\":329,\"u\":329,\"b\":[[\"50000.00\",\"1.00000000\"]],\"a\":[]}}"}
{"local_receipt_timestamp_ns":1704067200000003311,"raw_payload":"{\"stream\":\"btcusdt@depth@100ms\",\"data\":{\"e\":\"depthUpdate\",\"E\":1704067200331,\"U\":330,\"u\":330,\"b\":[],\"a\":[[\"50001.00\",\"1.00000000\"]]}}"}
{"local_receipt_timestamp_ns":1704067200000003321,"raw_payload":"{\"stream\":\"btcusdt@depth@100ms\",\"data\":{\"e\":\"depthUpdate\",\"E\":1704067200332,\"U\":331,\"u\":331,\"b\":[[\"50000.00\",\"1.00000000\"]],\"a\":[]}}"}
{"local_receipt_timestamp_ns":1704067200000003331,"raw_payload":"{\"stream\":\"btcusdt@depth@100ms\",\"data\":{\"e\":\"depthUpdate\",\"E\":1704067200333,\"U\":332,\"u\":332,\"b\":[],\"a\":[[\"50001.00\",\"1.00000000\"]]}}"}
{"local_receipt_timestamp_ns":1704067200000003341,"raw_payload":"{\"stream\":\"btcusdt@depth@100ms\",\"data\":{\"e\":\"depthUpdate\",\"E\":1704067200334,\"U\":333,\"u\":333,\"b\":[[\"50000.00\",\"1.00000000\"]],\"a\":[]}}"}
{"local_receipt_timestamp_ns":1704067200000003351,"raw_payload":"{\"stream\":\"btcusdt@depth@100ms\",\"data\":{\"e\":\"depthUpdate\",\"E\":1704067200335,\"U\":334,\"u\":334,\"b\":[],\"a\":[[\"50001.00\",\"1.00000000\"]]}}"}
{"local_receipt_timestamp_ns":1704067200000003361,"raw_payload":"{\"stream\":\"btcusdt@depth@100ms\",\"data\":{\"e\":\"depthUpdate\",\"E\":1704067200336,\"U\":335,\"u\":335,\"b\":[[\"50000.00\",\"1.00000000\"]],\"a\":[]}}"}
{"local_receipt_timestamp_ns":1704067200000003371,"raw_payload":"{\"stream\":\"btcusdt@depth@100ms\",\"data\":{\"e\":\"depthUpdate\",\"E\":1704067200337,\"U\":336,\"u\":336,\"b\":[],\"a\":[[\"50001.00\",\"1.00000000\"]]}}"}
{"local_receipt_timestamp_ns":1704067200000003381,"raw_payload":"{\"stream\":\"btcusdt@depth@100ms\",\"data\":{\"e\":\"depthUpdate\",\"E\":1704067200338,\"U\":337,\"u\":337,\"b\":[[\"50000.00\",\"1.00000000\"]],\"a\":[]}}"}
{"local_receipt_timestamp_ns":1704067200000003391,"raw_payload":"{\"stream\":\"btcusdt@depth@100ms\",\"data\":{\"e\":\"depthUpdate\",\"E\":1704067200339,\"U\":338,\"u\":338,\"b\":[],\"a\":[[\"50001.00\",\"1.00000000\"]]}}"}
{"local_receipt_timestamp_ns":1704067200000003401,"raw_payload":"{\"stream\":\"btcusdt@depth@100ms\",\"data\":{\"e\":\"depthUpdate\",\"E\":1704067200340,\"U\":339,\"u\":339,\"b\":[[\"50000.00\",\"1.00000000\"]],\"a\":[]}}"}
{"local_receipt_timestamp_ns":1704067200000003411,"raw_payload":"{\"stream\":\"btcusdt@depth@100ms\",\"data\":{\"e\":\"depthUpdate\",\"E\":1704067200341,\"U\":340,\"u\":340,\"b\":[],\"a\":[[\"50001.00\",\"1.00000000\"]]}}"}
{"local_receipt_timestamp_ns":1704067200000003421,"raw_payload":"{\"stream\":\"btcusdt@depth@100ms\",\"data\":{\"e\":\"depthUpdate\",\"E\":1704067200342,\"U\":341,\"u\":341,\"b\":[[\"50000.00\",\"1.00000000\"]],\"a\":[]}}"}
{"local_receipt_timestamp_ns":1704067200000003431,"raw_payload":"{\"stream\":\"btcusdt@depth@100ms\",\"data\":{\"e\":\"depthUpdate\",\"E\":1704067200343,\"U\":342,\"u\":342,\"b\":[],\"a\":[[\"50001.00\",\"1.00000000\"]]}}"}
{"local_receipt_timestamp_ns":1704067200000003441,"raw_payload":"{\"stream\":\"btcusdt@depth@100ms\",\"data\":{\"e\":\"depthUpdate\",\"E\":1704067200344,\"U\":343,\"u\":343,\"b\":[[\"50000.00\",\"1.00000000\"]],\"a\":[]}}"}
{"local_receipt_timestamp_ns":1704067200000003451,"raw_payload":"{\"stream\":\"btcusdt@depth@100ms\",\"data\":{\"e\":\"depthUpdate\",\"E\":1704067200345,\"U\":344,\"u\":344,\"b\":[],\"a\":[[\"50001.00\",\"1.00000000\"]]}}"}
{"local_receipt_timestamp_ns":1704067200000003461,"raw_payload":"{\"stream\":\"btcusdt@depth@100ms\",\"data\":{\"e\":\"depthUpdate\",\"E\":1704067200346,\"U\":345,\"u\":345,\"b\":[[\"50000.00\",\"1.00000000\"]],\"a\":[]}}"}
{"local_receipt_timestamp_ns":1704067200000003471,"raw_payload":"{\"stream\":\"btcusdt@depth@100ms\",\"data\":{\"e\":\"depthUpdate\",\"E\":1704067200347,\"U\":346,\"u\":346,\"b\":[],\"a\":[[\"50001.00\",\"1.00000000\"]]}}"}
{"local_receipt_timestamp_ns":1704067200000003481,"raw_payload":"{\"stream\":\"btcusdt@depth@100ms\",\"data\":{\"e\":\"depthUpdate\",\"E\":1704067200348,\"U\":347,\"u\":347,\"b\":[[\"50000.00\",\"1.00000000\"]],\"a\":[]}}"}
{"local_receipt_timestamp_ns":1704067200000003491,"raw_payload":"{\"stream\":\"btcusdt@depth@100ms\",\"data\":{\"e\":\"depthUpdate\",\"E\":1704067200349,\"U\":348,\"u\":348,\"b\":[],\"a\":[[\"50001.00\",\"1.00000000\"]]}}"}
{"local_receipt_timestamp_ns":1704067200000003501,"raw_payload":"{\"stream\":\"btcusdt@depth@100ms\",\"data\":{\"e\":\"depthUpdate\",\"E\":1704067200350,\"U\":349,\"u\":349,\"b\":[[\"50000.00\",\"1.00000000\"]],\"a\":[]}}"}
{"local_receipt_timestamp_ns":1704067200000003511,"raw_payload":"{\"stream\":\"btcusdt@depth@100ms\",\"data\":{\"e\":\"depthUpdate\",\"E\":1704067200351,\"U\":350,\"u\":350,\"b\":[],\"a\":[[\"50001.00\",\"1.00000000\"]]}}"}
{"local_receipt_timestamp_ns":1704067200000003521,"raw_payload":"{\"stream\":\"btcusdt@depth@100ms\",\"data\":{\"e\":\"depthUpdate\",\"E\":1704067200352,\"U\":351,\"u\":351,\"b\":[[\"50000.00\",\"1.00000000\"]],\"a\":[]}}"}
{"local_receipt_timestamp_ns":1704067200000003531,"raw_payload":"{\"stream\":\"btcusdt@depth@100ms\",\"data\":{\"e\":\"depthUpdate\",\"E\":1704067200353,\"U\":352,\"u\":352,\"b\":[],\"a\":[[\"50001.00\",\"1.00000000\"]]}}"}
{"local_receipt_timestamp_ns":1704067200000003541,"raw_payload":"{\"stream\":\"btcusdt@depth@100ms\",\"data\":{\"e\":\"depthUpdate\",\"E\":1704067200354,\"U\":353,\"u\":353,\"b\":[[\"50000.00\",\"1.00000000\"]],\"a\":[]}}"}
{"local_receipt_timestamp_ns":1704067200000003551,"raw_payload":"{\"stream\":\"btcusdt@depth@100ms\",\"data\":{\"e\":\"depthUpdate\",\"E\":1704067200355,\"U\":354,\"u\":354,\"b\":[],\"a\":[[\"50001.00\",\"1.00000000\"]]}}"}
{"local_receipt_timestamp_ns":1704067200000003561,"raw_payload":"{\"stream\":\"btcusdt@depth@100ms\",\"data\":{\"e\":\"depthUpdate\",\"E\":1704067200356,\"U\":355,\"u\":355,\"b\":[[\"50000.00\",\"1.00000000\"]],\"a\":[]}}"}
{"local_receipt_timestamp_ns":1704067200000003571,"raw_payload":"{\"stream\":\"btcusdt@depth@100ms\",\"data\":{\"e\":\"depthUpdate\",\"E\":1704067200357,\"U\":356,\"u\":356,\"b\":[],\"a\":[[\"50001.00\",\"1.00000000\"]]}}"}
{"local_receipt_timestamp_ns":1704067200000003581,"raw_payload":"{\"stream\":\"btcusdt@depth@100ms\",\"data\":{\"e\":\"depthUpdate\",\"E\":1704067200358,\"U\":357,\"u\":357,\"b\":[[\"50000.00\",\"1.00000000\"]],\"a\":[]}}"}
{"local_receipt_timestamp_ns":1704067200000003591,"raw_payload":"{\"stream\":\"btcusdt@depth@100ms\",\"data\":{\"e\":\"depthUpdate\",\"E\":1704067200359,\"U\":358,\"u\":358,\"b\":[],\"a\":[[\"50001.00\",\"1.00000000\"]]}}"}
{"local_receipt_timestamp_ns":1704067200000003601,"raw_payload":"{\"stream\":\"btcusdt@depth@100ms\",\"data\":{\"e\":\"depthUpdate\",\"E\":1704067200360,\"U\":359,\"u\":359,\"b\":[[\"50000.00\",\"1.00000000\"]],\"a\":[]}}"}
{"local_receipt_timestamp_ns":1704067200000003611,"raw_payload":"{\"stream\":\"btcusdt@depth@100ms\",\"data\":{\"e\":\"depthUpdate\",\"E\":1704067200361,\"U\":360,\"u\":360,\"b\":[],\"a\":[[\"50001.00\",\"1.00000000\"]]}}"}
{"local_receipt_timestamp_ns":1704067200000003621,"raw_payload":"{\"stream\":\"btcusdt@depth@100ms\",\"data\":{\"e\":\"depthUpdate\",\"E\":1704067200362,\"U\":361,\"u\":361,\"b\":[[\"50000.00\",\"1.00000000\"]],\"a\":[]}}"}
{"local_receipt_timestamp_ns":1704067200000003631,"raw_payload":"{\"stream\":\"btcusdt@depth@100ms\",\"data\":{\"e\":\"depthUpdate\",\"E\":1704067200363,\"U\":362,\"u\":362,\"b\":[],\"a\":[[\"50001.00\",\"1.00000000\"]]}}"}
{"local_receipt_timestamp_ns":1704067200000003641,"raw_payload":"{\"stream\":\"btcusdt@depth@100ms\",\"data\":{\"e\":\"depthUpdate\",\"E\":1704067200364,\"U\":363,\"u\":363,\"b\":[[\"50000.00\",\"1.00000000\"]],\"a\":[]}}"}
{"local_receipt_timestamp_ns":1704067200000003651,"raw_payload":"{\"stream\":\"btcusdt@depth@100ms\",\"data\":{\"e\":\"depthUpdate\",\"E\":1704067200365,\"U\":364,\"u\":364,\"b\":[],\"a\":[[\"50001.00\",\"1.00000000\"]]}}"}
{"local_receipt_timestamp_ns":1704067200000003661,"raw_payload":"{\"stream\":\"btcusdt@depth@100ms\",\"data\":{\"e\":\"depthUpdate\",\"E\":1704067200366,\"U\":365,\"u\":365,\"b\":[[\"50000.00\",\"1.00000000\"]],\"a\":[]}}"}
{"local_receipt_timestamp_ns":1704067200000003671,"raw_payload":"{\"stream\":\"btcusdt@depth@100ms\",\"data\":{\"e\":\"depthUpdate\",\"E\":1704067200367,\"U\":366,\"u\":366,\"b\":[],\"a\":[[\"50001.00\",\"1.00000000\"]]}}"}
{"local_receipt_timestamp_ns":1704067200000003681,"raw_payload":"{\"stream\":\"btcusdt@depth@100ms\",\"data\":{\"e\":\"depthUpdate\",\"E\":1704067200368,\"U\":367,\"u\":367,\"b\":[[\"50000.00\",\"1.00000000\"]],\"a\":[]}}"}
{"local_receipt_timestamp_ns":1704067200000003691,"raw_payload":"{\"stream\":\"btcusdt@depth@100ms\",\"data\":{\"e\":\"depthUpdate\",\"E\":1704067200369,\"U\":368,\"u\":368,\"b\":[],\"a\":[[\"50001.00\",\"1.00000000\"]]}}"}
{"local_receipt_timestamp_ns":1704067200000003701,"raw_payload":"{\"stream\":\"btcusdt@depth@100ms\",\"data\":{\"e\":\"depthUpdate\",\"E\":1704067200370,\"U\":369,\"u\":369,\"b\":[[\"50000.00\",\"1.00000000\"]],\"a\":[]}}"}
{"local_receipt_timestamp_ns":1704067200000003711,"raw_payload":"{\"stream\":\"btcusdt@depth@100ms\",\"data\":{\"e\":\"depthUpdate\",\"E\":1704067200371,\"U\":370,\"u\":370,\"b\":[],\"a\":[[\"50001.00\",\"1.00000000\"]]}}"}
{"local_receipt_timestamp_ns":1704067200000003721,"raw_payload":"{\"stream\":\"btcusdt@depth@100ms\",\"data\":{\"e\":\"depthUpdate\",\"E\":1704067200372,\"U\":371,\"u\":371,\"b\":[[\"50000.00\",\"1.00000000\"]],\"a\":[]}}"}
{"local_receipt_timestamp_ns":1704067200000003731,"raw_payload":"{\"stream\":\"btcusdt@depth@100ms\",\"data\":{\"e\":\"depthUpdate\",\"E\":1704067200373,\"U\":372,\"u\":372,\"b\":[],\"a\":[[\"50001.00\",\"1.00000000\"]]}}"}
{"local_receipt_timestamp_ns":1704067200000003741,"raw_payload":"{\"stream\":\"btcusdt@depth@100ms\",\"data\":{\"e\":\"depthUpdate\",\"E\":1704067200374,\"U\":373,\"u\":373,\"b\":[[\"50000.00\",\"1.00000000\"]],\"a\":[]}}"}
{"local_receipt_timestamp_ns":1704067200000003751,"raw_payload":"{\"stream\":\"btcusdt@depth@100ms\",\"data\":{\"e\":\"depthUpdate\",\"E\":1704067200375,\"U\":374,\"u\":374,\"b\":[],\"a\":[[\"50001.00\",\"1.00000000\"]]}}"}
{"local_receipt_timestamp_ns":1704067200000003761,"raw_payload":"{\"stream\":\"btcusdt@depth@100ms\",\"data\":{\"e\":\"depthUpdate\",\"E\":1704067200376,\"U\":375,\"u\":375,\"b\":[[\"50000.00\",\"1.00000000\"]],\"a\":[]}}"}
{"local_receipt_timestamp_ns":1704067200000003771,"raw_payload":"{\"stream\":\"btcusdt@depth@100ms\",\"data\":{\"e\":\"depthUpdate\",\"E\":1704067200377,\"U\":376,\"u\":376,\"b\":[],\"a\":[[\"50001.00\",\"1.00000000\"]]}}"}
{"local_receipt_timestamp_ns":1704067200000003781,"raw_payload":"{\"stream\":\"btcusdt@depth@100ms\",\"data\":{\"e\":\"depthUpdate\",\"E\":1704067200378,\"U\":377,\"u\":377,\"b\":[[\"50000.00\",\"1.00000000\"]],\"a\":[]}}"}
{"local_receipt_timestamp_ns":1704067200000003791,"raw_payload":"{\"stream\":\"btcusdt@depth@100ms\",\"data\":{\"e\":\"depthUpdate\",\"E\":1704067200379,\"U\":378,\"u\":378,\"b\":[],\"a\":[[\"50001.00\",\"1.00000000\"]]}}"}
{"local_receipt_timestamp_ns":1704067200000003801,"raw_payload":"{\"stream\":\"btcusdt@depth@100ms\",\"data\":{\"e\":\"depthUpdate\",\"E\":1704067200380,\"U\":379,\"u\":379,\"b\":[[\"50000.00\",\"1.00000000\"]],\"a\":[]}}"}
{"local_receipt_timestamp_ns":1704067200000003811,"raw_payload":"{\"stream\":\"btcusdt@depth@100ms\",\"data\":{\"e\":\"depthUpdate\",\"E\":1704067200381,\"U\":380,\"u\":380,\"b\":[],\"a\":[[\"50001.00\",\"1.00000000\"]]}}"}
{"local_receipt_timestamp_ns":1704067200000003821,"raw_payload":"{\"stream\":\"btcusdt@depth@100ms\",\"data\":{\"e\":\"depthUpdate\",\"E\":1704067200382,\"U\":381,\"u\":381,\"b\":[[\"50000.00\",\"1.00000000\"]],\"a\":[]}}"}
{"local_receipt_timestamp_ns":1704067200000003831,"raw_payload":"{\"stream\":\"btcusdt@depth@100ms\",\"data\":{\"e\":\"depthUpdate\",\"E\":1704067200383,\"U\":382,\"u\":382,\"b\":[],\"a\":[[\"50001.00\",\"1.00000000\"]]}}"}
{"local_receipt_timestamp_ns":1704067200000003841,"raw_payload":"{\"stream\":\"btcusdt@depth@100ms\",\"data\":{\"e\":\"depthUpdate\",\"E\":1704067200384,\"U\":383,\"u\":383,\"b\":[[\"50000.00\",\"1.00000000\"]],\"a\":[]}}"}
{"local_receipt_timestamp_ns":1704067200000003851,"raw_payload":"{\"stream\":\"btcusdt@depth@100ms\",\"data\":{\"e\":\"depthUpdate\",\"E\":1704067200385,\"U\":384,\"u\":384,\"b\":[],\"a\":[[\"50001.00\",\"1.00000000\"]]}}"}
{"local_receipt_timestamp_ns":1704067200000003861,"raw_payload":"{\"stream\":\"btcusdt@depth@100ms\",\"data\":{\"e\":\"depthUpdate\",\"E\":1704067200386,\"U\":385,\"u\":385,\"b\":[[\"50000.00\",\"1.00000000\"]],\"a\":[]}}"}
{"local_receipt_timestamp_ns":1704067200000003871,"raw_payload":"{\"stream\":\"btcusdt@depth@100ms\",\"data\":{\"e\":\"depthUpdate\",\"E\":1704067200387,\"U\":386,\"u\":386,\"b\":[],\"a\":[[\"50001.00\",\"1.00000000\"]]}}"}
{"local_receipt_timestamp_ns":1704067200000003881,"raw_payload":"{\"stream\":\"btcusdt@depth@100ms\",\"data\":{\"e\":\"depthUpdate\",\"E\":1704067200388,\"U\":387,\"u\":387,\"b\":[[\"50000.00\",\"1.00000000\"]],\"a\":[]}}"}
{"local_receipt_timestamp_ns":1704067200000003891,"raw_payload":"{\"stream\":\"btcusdt@depth@100ms\",\"data\":{\"e\":\"depthUpdate\",\"E\":1704067200389,\"U\":388,\"u\":388,\"b\":[],\"a\":[[\"50001.00\",\"1.00000000\"]]}}"}
{"local_receipt_timestamp_ns":1704067200000003901,"raw_payload":"{\"stream\":\"btcusdt@depth@100ms\",\"data\":{\"e\":\"depthUpdate\",\"E\":1704067200390,\"U\":389,\"u\":389,\"b\":[[\"50000.00\",\"1.00000000\"]],\"a\":[]}}"}
{"local_receipt_timestamp_ns":1704067200000003911,"raw_payload":"{\"stream\":\"btcusdt@depth@100ms\",\"data\":{\"e\":\"depthUpdate\",\"E\":1704067200391,\"U\":390,\"u\":390,\"b\":[],\"a\":[[\"50001.00\",\"1.00000000\"]]}}"}
{"local_receipt_timestamp_ns":1704067200000003921,"raw_payload":"{\"stream\":\"btcusdt@depth@100ms\",\"data\":{\"e\":\"depthUpdate\",\"E\":1704067200392,\"U\":391,\"u\":391,\"b\":[[\"50000.00\",\"1.00000000\"]],\"a\":[]}}"}
{"local_receipt_timestamp_ns":1704067200000003931,"raw_payload":"{\"stream\":\"btcusdt@depth@100ms\",\"data\":{\"e\":\"depthUpdate\",\"E\":1704067200393,\"U\":392,\"u\":392,\"b\":[],\"a\":[[\"50001.00\",\"1.00000000\"]]}}"}
{"local_receipt_timestamp_ns":1704067200000003941,"raw_payload":"{\"stream\":\"btcusdt@depth@100ms\",\"data\":{\"e\":\"depthUpdate\",\"E\":1704067200394,\"U\":393,\"u\":393,\"b\":[[\"50000.00\",\"1.00000000\"]],\"a\":[]}}"}
{"local_receipt_timestamp_ns":1704067200000003951,"raw_payload":"{\"stream\":\"btcusdt@depth@100ms\",\"data\":{\"e\":\"depthUpdate\",\"E\":1704067200395,\"U\":394,\"u\":394,\"b\":[],\"a\":[[\"50001.00\",\"1.00000000\"]]}}"}
{"local_receipt_timestamp_ns":1704067200000003961,"raw_payload":"{\"stream\":\"btcusdt@depth@100ms\",\"data\":{\"e\":\"depthUpdate\",\"E\":1704067200396,\"U\":395,\"u\":395,\"b\":[[\"50000.00\",\"1.00000000\"]],\"a\":[]}}"}
{"local_receipt_timestamp_ns":1704067200000003971,"raw_payload":"{\"stream\":\"btcusdt@depth@100ms\",\"data\":{\"e\":\"depthUpdate\",\"E\":1704067200397,\"U\":396,\"u\":396,\"b\":[],\"a\":[[\"50001.00\",\"1.00000000\"]]}}"}
{"local_receipt_timestamp_ns":1704067200000003981,"raw_payload":"{\"stream\":\"btcusdt@depth@100ms\",\"data\":{\"e\":\"depthUpdate\",\"E\":1704067200398,\"U\":397,\"u\":397,\"b\":[[\"50000.00\",\"1.00000000\"]],\"a\":[]}}"}
{"local_receipt_timestamp_ns":1704067200000003991,"raw_payload":"{\"stream\":\"btcusdt@depth@100ms\",\"data\":{\"e\":\"depthUpdate\",\"E\":1704067200399,\"U\":398,\"u\":398,\"b\":[],\"a\":[[\"50001.00\",\"1.00000000\"]]}}"}
{"local_receipt_timestamp_ns":1704067200000004001,"raw_payload":"{\"stream\":\"btcusdt@depth@100ms\",\"data\":{\"e\":\"depthUpdate\",\"E\":1704067200400,\"U\":399,\"u\":399,\"b\":[[\"50000.00\",\"1.00000000\"]],\"a\":[]}}"}
{"local_receipt_timestamp_ns":1704067200000004011,"raw_payload":"{\"stream\":\"btcusdt@depth@100ms\",\"data\":{\"e\":\"depthUpdate\",\"E\":1704067200401,\"U\":400,\"u\":400,\"b\":[],\"a\":[[\"50001.00\",\"1.00000000\"]]}}"}
{"local_receipt_timestamp_ns":1704067200000004021,"raw_payload":"{\"stream\":\"btcusdt@depth@100ms\",\"data\":{\"e\":\"depthUpdate\",\"E\":1704067200402,\"U\":401,\"u\":401,\"b\":[[\"50000.00\",\"1.00000000\"]],\"a\":[]}}"}
{"local_receipt_timestamp_ns":1704067200000004031,"raw_payload":"{\"stream\":\"btcusdt@depth@100ms\",\"data\":{\"e\":\"depthUpdate\",\"E\":1704067200403,\"U\":402,\"u\":402,\"b\":[],\"a\":[[\"50001.00\",\"1.00000000\"]]}}"}
{"local_receipt_timestamp_ns":1704067200000004041,"raw_payload":"{\"stream\":\"btcusdt@depth@100ms\",\"data\":{\"e\":\"depthUpdate\",\"E\":1704067200404,\"U\":403,\"u\":403,\"b\":[[\"50000.00\",\"1.00000000\"]],\"a\":[]}}"}
{"local_receipt_timestamp_ns":1704067200000004051,"raw_payload":"{\"stream\":\"btcusdt@depth@100ms\",\"data\":{\"e\":\"depthUpdate\",\"E\":1704067200405,\"U\":404,\"u\":404,\"b\":[],\"a\":[[\"50001.00\",\"1.00000000\"]]}}"}
{"local_receipt_timestamp_ns":1704067200000004061,"raw_payload":"{\"stream\":\"btcusdt@depth@100ms\",\"data\":{\"e\":\"depthUpdate\",\"E\":1704067200406,\"U\":405,\"u\":405,\"b\":[[\"50000.00\",\"1.00000000\"]],\"a\":[]}}"}
{"local_receipt_timestamp_ns":1704067200000004071,"raw_payload":"{\"stream\":\"btcusdt@depth@100ms\",\"data\":{\"e\":\"depthUpdate\",\"E\":1704067200407,\"U\":406,\"u\":406,\"b\":[],\"a\":[[\"50001.00\",\"1.00000000\"]]}}"}
{"local_receipt_timestamp_ns":1704067200000004081,"raw_payload":"{\"stream\":\"btcusdt@depth@100ms\",\"data\":{\"e\":\"depthUpdate\",\"E\":1704067200408,\"U\":407,\"u\":407,\"b\":[[\"50000.00\",\"1.00000000\"]],\"a\":[]}}"}
{"local_receipt_timestamp_ns":1704067200000004091,"raw_payload":"{\"stream\":\"btcusdt@depth@100ms\",\"data\":{\"e\":\"depthUpdate\",\"E\":1704067200409,\"U\":408,\"u\":408,\"b\":[],\"a\":[[\"50001.00\",\"1.00000000\"]]}}"}
{"local_receipt_timestamp_ns":1704067200000004101,"raw_payload":"{\"stream\":\"btcusdt@depth@100ms\",\"data\":{\"e\":\"depthUpdate\",\"E\":1704067200410,\"U\":409,\"u\":409,\"b\":[[\"50000.00\",\"1.00000000\"]],\"a\":[]}}"}
{"local_receipt_timestamp_ns":1704067200000004111,"raw_payload":"{\"stream\":\"btcusdt@depth@100ms\",\"data\":{\"e\":\"depthUpdate\",\"E\":1704067200411,\"U\":410,\"u\":410,\"b\":[],\"a\":[[\"50001.00\",\"1.00000000\"]]}}"}
{"local_receipt_timestamp_ns":1704067200000004121,"raw_payload":"{\"stream\":\"btcusdt@depth@100ms\",\"data\":{\"e\":\"depthUpdate\",\"E\":1704067200412,\"U\":411,\"u\":411,\"b\":[[\"50000.00\",\"1.00000000\"]],\"a\":[]}}"}
{"local_receipt_timestamp_ns":1704067200000004131,"raw_payload":"{\"stream\":\"btcusdt@depth@100ms\",\"data\":{\"e\":\"depthUpdate\",\"E\":1704067200413,\"U\":412,\"u\":412,\"b\":[],\"a\":[[\"50001.00\",\"1.00000000\"]]}}"}
{"local_receipt_timestamp_ns":1704067200000004141,"raw_payload":"{\"stream\":\"btcusdt@depth@100ms\",\"data\":{\"e\":\"depthUpdate\",\"E\":1704067200414,\"U\":413,\"u\":413,\"b\":[[\"50000.00\",\"1.00000000\"]],\"a\":[]}}"}
{"local_receipt_timestamp_ns":1704067200000004151,"raw_payload":"{\"stream\":\"btcusdt@depth@100ms\",\"data\":{\"e\":\"depthUpdate\",\"E\":1704067200415,\"U\":414,\"u\":414,\"b\":[],\"a\":[[\"50001.00\",\"1.00000000\"]]}}"}
{"local_receipt_timestamp_ns":1704067200000004161,"raw_payload":"{\"stream\":\"btcusdt@depth@100ms\",\"data\":{\"e\":\"depthUpdate\",\"E\":1704067200416,\"U\":415,\"u\":415,\"b\":[[\"50000.00\",\"1.00000000\"]],\"a\":[]}}"}
{"local_receipt_timestamp_ns":1704067200000004171,"raw_payload":"{\"stream\":\"btcusdt@depth@100ms\",\"data\":{\"e\":\"depthUpdate\",\"E\":1704067200417,\"U\":416,\"u\":416,\"b\":[],\"a\":[[\"50001.00\",\"1.00000000\"]]}}"}
{"local_receipt_timestamp_ns":1704067200000004181,"raw_payload":"{\"stream\":\"btcusdt@depth@100ms\",\"data\":{\"e\":\"depthUpdate\",\"E\":1704067200418,\"U\":417,\"u\":417,\"b\":[[\"50000.00\",\"1.00000000\"]],\"a\":[]}}"}
{"local_receipt_timestamp_ns":1704067200000004191,"raw_payload":"{\"stream\":\"btcusdt@depth@100ms\",\"data\":{\"e\":\"depthUpdate\",\"E\":1704067200419,\"U\":418,\"u\":418,\"b\":[],\"a\":[[\"50001.00\",\"1.00000000\"]]}}"}
{"local_receipt_timestamp_ns":1704067200000004201,"raw_payload":"{\"stream\":\"btcusdt@depth@100ms\",\"data\":{\"e\":\"depthUpdate\",\"E\":1704067200420,\"U\":419,\"u\":419,\"b\":[[\"50000.00\",\"1.00000000\"]],\"a\":[]}}"}
{"local_receipt_timestamp_ns":1704067200000004211,"raw_payload":"{\"stream\":\"btcusdt@depth@100ms\",\"data\":{\"e\":\"depthUpdate\",\"E\":1704067200421,\"U\":420,\"u\":420,\"b\":[],\"a\":[[\"50001.00\",\"1.00000000\"]]}}"}
{"local_receipt_timestamp_ns":1704067200000004221,"raw_payload":"{\"stream\":\"btcusdt@depth@100ms\",\"data\":{\"e\":\"depthUpdate\",\"E\":1704067200422,\"U\":421,\"u\":421,\"b\":[[\"50000.00\",\"1.00000000\"]],\"a\":[]}}"}
{"local_receipt_timestamp_ns":1704067200000004231,"raw_payload":"{\"stream\":\"btcusdt@depth@100ms\",\"data\":{\"e\":\"depthUpdate\",\"E\":1704067200423,\"U\":422,\"u\":422,\"b\":[],\"a\":[[\"50001.00\",\"1.00000000\"]]}}"}
{"local_receipt_timestamp_ns":1704067200000004241,"raw_payload":"{\"stream\":\"btcusdt@depth@100ms\",\"data\":{\"e\":\"depthUpdate\",\"E\":1704067200424,\"U\":423,\"u\":423,\"b\":[[\"50000.00\",\"1.00000000\"]],\"a\":[]}}"}
{"local_receipt_timestamp_ns":1704067200000004251,"raw_payload":"{\"stream\":\"btcusdt@depth@100ms\",\"data\":{\"e\":\"depthUpdate\",\"E\":1704067200425,\"U\":424,\"u\":424,\"b\":[],\"a\":[[\"50001.00\",\"1.00000000\"]]}}"}
{"local_receipt_timestamp_ns":1704067200000004261,"raw_payload":"{\"stream\":\"btcusdt@depth@100ms\",\"data\":{\"e\":\"depthUpdate\",\"E\":1704067200426,\"U\":425,\"u\":425,\"b\":[[\"50000.00\",\"1.00000000\"]],\"a\":[]}}"}
{"local_receipt_timestamp_ns":1704067200000004271,"raw_payload":"{\"stream\":\"btcusdt@depth@100ms\",\"data\":{\"e\":\"depthUpdate\",\"E\":1704067200427,\"U\":426,\"u\":426,\"b\":[],\"a\":[[\"50001.00\",\"1.00000000\"]]}}"}
{"local_receipt_timestamp_ns":1704067200000004281,"raw_payload":"{\"stream\":\"btcusdt@depth@100ms\",\"data\":{\"e\":\"depthUpdate\",\"E\":1704067200428,\"U\":427,\"u\":427,\"b\":[[\"50000.00\",\"1.00000000\"]],\"a\":[]}}"}
{"local_receipt_timestamp_ns":1704067200000004291,"raw_payload":"{\"stream\":\"btcusdt@depth@100ms\",\"data\":{\"e\":\"depthUpdate\",\"E\":1704067200429,\"U\":428,\"u\":428,\"b\":[],\"a\":[[\"50001.00\",\"1.00000000\"]]}}"}
{"local_receipt_timestamp_ns":1704067200000004301,"raw_payload":"{\"stream\":\"btcusdt@depth@100ms\",\"data\":{\"e\":\"depthUpdate\",\"E\":1704067200430,\"U\":429,\"u\":429,\"b\":[[\"50000.00\",\"1.00000000\"]],\"a\":[]}}"}
{"local_receipt_timestamp_ns":1704067200000004311,"raw_payload":"{\"stream\":\"btcusdt@depth@100ms\",\"data\":{\"e\":\"depthUpdate\",\"E\":1704067200431,\"U\":430,\"u\":430,\"b\":[],\"a\":[[\"50001.00\",\"1.00000000\"]]}}"}
{"local_receipt_timestamp_ns":1704067200000004321,"raw_payload":"{\"stream\":\"btcusdt@depth@100ms\",\"data\":{\"e\":\"depthUpdate\",\"E\":1704067200432,\"U\":431,\"u\":431,\"b\":[[\"50000.00\",\"1.00000000\"]],\"a\":[]}}"}
{"local_receipt_timestamp_ns":1704067200000004331,"raw_payload":"{\"stream\":\"btcusdt@depth@100ms\",\"data\":{\"e\":\"depthUpdate\",\"E\":1704067200433,\"U\":432,\"u\":432,\"b\":[],\"a\":[[\"50001.00\",\"1.00000000\"]]}}"}
{"local_receipt_timestamp_ns":1704067200000004341,"raw_payload":"{\"stream\":\"btcusdt@depth@100ms\",\"data\":{\"e\":\"depthUpdate\",\"E\":1704067200434,\"U\":433,\"u\":433,\"b\":[[\"50000.00\",\"1.00000000\"]],\"a\":[]}}"}
{"local_receipt_timestamp_ns":1704067200000004351,"raw_payload":"{\"stream\":\"btcusdt@depth@100ms\",\"data\":{\"e\":\"depthUpdate\",\"E\":1704067200435,\"U\":434,\"u\":434,\"b\":[],\"a\":[[\"50001.00\",\"1.00000000\"]]}}"}
{"local_receipt_timestamp_ns":1704067200000004361,"raw_payload":"{\"stream\":\"btcusdt@depth@100ms\",\"data\":{\"e\":\"depthUpdate\",\"E\":1704067200436,\"U\":435,\"u\":435,\"b\":[[\"50000.00\",\"1.00000000\"]],\"a\":[]}}"}
{"local_receipt_timestamp_ns":1704067200000004371,"raw_payload":"{\"stream\":\"btcusdt@depth@100ms\",\"data\":{\"e\":\"depthUpdate\",\"E\":1704067200437,\"U\":436,\"u\":436,\"b\":[],\"a\":[[\"50001.00\",\"1.00000000\"]]}}"}
{"local_receipt_timestamp_ns":1704067200000004381,"raw_payload":"{\"stream\":\"btcusdt@depth@100ms\",\"data\":{\"e\":\"depthUpdate\",\"E\":1704067200438,\"U\":437,\"u\":437,\"b\":[[\"50000.00\",\"1.00000000\"]],\"a\":[]}}"}
{"local_receipt_timestamp_ns":1704067200000004391,"raw_payload":"{\"stream\":\"btcusdt@depth@100ms\",\"data\":{\"e\":\"depthUpdate\",\"E\":1704067200439,\"U\":438,\"u\":438,\"b\":[],\"a\":[[\"50001.00\",\"1.00000000\"]]}}"}
{"local_receipt_timestamp_ns":1704067200000004401,"raw_payload":"{\"stream\":\"btcusdt@depth@100ms\",\"data\":{\"e\":\"depthUpdate\",\"E\":1704067200440,\"U\":439,\"u\":439,\"b\":[[\"50000.00\",\"1.00000000\"]],\"a\":[]}}"}
{"local_receipt_timestamp_ns":1704067200000004411,"raw_payload":"{\"stream\":\"btcusdt@depth@100ms\",\"data\":{\"e\":\"depthUpdate\",\"E\":1704067200441,\"U\":440,\"u\":440,\"b\":[],\"a\":[[\"50001.00\",\"1.00000000\"]]}}"}
{"local_receipt_timestamp_ns":1704067200000004421,"raw_payload":"{\"stream\":\"btcusdt@depth@100ms\",\"data\":{\"e\":\"depthUpdate\",\"E\":1704067200442,\"U\":441,\"u\":441,\"b\":[[\"50000.00\",\"1.00000000\"]],\"a\":[]}}"}
{"local_receipt_timestamp_ns":1704067200000004431,"raw_payload":"{\"stream\":\"btcusdt@depth@100ms\",\"data\":{\"e\":\"depthUpdate\",\"E\":1704067200443,\"U\":442,\"u\":442,\"b\":[],\"a\":[[\"50001.00\",\"1.00000000\"]]}}"}
{"local_receipt_timestamp_ns":1704067200000004441,"raw_payload":"{\"stream\":\"btcusdt@depth@100ms\",\"data\":{\"e\":\"depthUpdate\",\"E\":1704067200444,\"U\":443,\"u\":443,\"b\":[[\"50000.00\",\"1.00000000\"]],\"a\":[]}}"}
{"local_receipt_timestamp_ns":1704067200000004451,"raw_payload":"{\"stream\":\"btcusdt@depth@100ms\",\"data\":{\"e\":\"depthUpdate\",\"E\":1704067200445,\"U\":444,\"u\":444,\"b\":[],\"a\":[[\"50001.00\",\"1.00000000\"]]}}"}
{"local_receipt_timestamp_ns":1704067200000004461,"raw_payload":"{\"stream\":\"btcusdt@depth@100ms\",\"data\":{\"e\":\"depthUpdate\",\"E\":1704067200446,\"U\":445,\"u\":445,\"b\":[[\"50000.00\",\"1.00000000\"]],\"a\":[]}}"}
{"local_receipt_timestamp_ns":1704067200000004471,"raw_payload":"{\"stream\":\"btcusdt@depth@100ms\",\"data\":{\"e\":\"depthUpdate\",\"E\":1704067200447,\"U\":446,\"u\":446,\"b\":[],\"a\":[[\"50001.00\",\"1.00000000\"]]}}"}
{"local_receipt_timestamp_ns":1704067200000004481,"raw_payload":"{\"stream\":\"btcusdt@depth@100ms\",\"data\":{\"e\":\"depthUpdate\",\"E\":1704067200448,\"U\":447,\"u\":447,\"b\":[[\"50000.00\",\"1.00000000\"]],\"a\":[]}}"}
{"local_receipt_timestamp_ns":1704067200000004491,"raw_payload":"{\"stream\":\"btcusdt@depth@100ms\",\"data\":{\"e\":\"depthUpdate\",\"E\":1704067200449,\"U\":448,\"u\":448,\"b\":[],\"a\":[[\"50001.00\",\"1.00000000\"]]}}"}
{"local_receipt_timestamp_ns":1704067200000004501,"raw_payload":"{\"stream\":\"btcusdt@depth@100ms\",\"data\":{\"e\":\"depthUpdate\",\"E\":1704067200450,\"U\":449,\"u\":449,\"b\":[[\"50000.00\",\"1.00000000\"]],\"a\":[]}}"}
{"local_receipt_timestamp_ns":1704067200000004511,"raw_payload":"{\"stream\":\"btcusdt@depth@100ms\",\"data\":{\"e\":\"depthUpdate\",\"E\":1704067200451,\"U\":450,\"u\":450,\"b\":[],\"a\":[[\"50001.00\",\"1.00000000\"]]}}"}
{"local_receipt_timestamp_ns":1704067200000004521,"raw_payload":"{\"stream\":\"btcusdt@depth@100ms\",\"data\":{\"e\":\"depthUpdate\",\"E\":1704067200452,\"U\":451,\"u\":451,\"b\":[[\"50000.00\",\"1.00000000\"]],\"a\":[]}}"}
{"local_receipt_timestamp_ns":1704067200000004531,"raw_payload":"{\"stream\":\"btcusdt@depth@100ms\",\"data\":{\"e\":\"depthUpdate\",\"E\":1704067200453,\"U\":452,\"u\":452,\"b\":[],\"a\":[[\"50001.00\",\"1.00000000\"]]}}"}
{"local_receipt_timestamp_ns":1704067200000004541,"raw_payload":"{\"stream\":\"btcusdt@depth@100ms\",\"data\":{\"e\":\"depthUpdate\",\"E\":1704067200454,\"U\":453,\"u\":453,\"b\":[[\"50000.00\",\"1.00000000\"]],\"a\":[]}}"}
{"local_receipt_timestamp_ns":1704067200000004551,"raw_payload":"{\"stream\":\"btcusdt@depth@100ms\",\"data\":{\"e\":\"depthUpdate\",\"E\":1704067200455,\"U\":454,\"u\":454,\"b\":[],\"a\":[[\"50001.00\",\"1.00000000\"]]}}"}
{"local_receipt_timestamp_ns":1704067200000004561,"raw_payload":"{\"stream\":\"btcusdt@depth@100ms\",\"data\":{\"e\":\"depthUpdate\",\"E\":1704067200456,\"U\":455,\"u\":455,\"b\":[[\"50000.00\",\"1.00000000\"]],\"a\":[]}}"}
{"local_receipt_timestamp_ns":1704067200000004571,"raw_payload":"{\"stream\":\"btcusdt@depth@100ms\",\"data\":{\"e\":\"depthUpdate\",\"E\":1704067200457,\"U\":456,\"u\":456,\"b\":[],\"a\":[[\"50001.00\",\"1.00000000\"]]}}"}
{"local_receipt_timestamp_ns":1704067200000004581,"raw_payload":"{\"stream\":\"btcusdt@depth@100ms\",\"data\":{\"e\":\"depthUpdate\",\"E\":1704067200458,\"U\":457,\"u\":457,\"b\":[[\"50000.00\",\"1.00000000\"]],\"a\":[]}}"}
{"local_receipt_timestamp_ns":1704067200000004591,"raw_payload":"{\"stream\":\"btcusdt@depth@100ms\",\"data\":{\"e\":\"depthUpdate\",\"E\":1704067200459,\"U\":458,\"u\":458,\"b\":[],\"a\":[[\"50001.00\",\"1.00000000\"]]}}"}
{"local_receipt_timestamp_ns":1704067200000004601,"raw_payload":"{\"stream\":\"btcusdt@depth@100ms\",\"data\":{\"e\":\"depthUpdate\",\"E\":1704067200460,\"U\":459,\"u\":459,\"b\":[[\"50000.00\",\"1.00000000\"]],\"a\":[]}}"}
{"local_receipt_timestamp_ns":1704067200000004611,"raw_payload":"{\"stream\":\"btcusdt@depth@100ms\",\"data\":{\"e\":\"depthUpdate\",\"E\":1704067200461,\"U\":460,\"u\":460,\"b\":[],\"a\":[[\"50001.00\",\"1.00000000\"]]}}"}
{"local_receipt_timestamp_ns":1704067200000004621,"raw_payload":"{\"stream\":\"btcusdt@depth@100ms\",\"data\":{\"e\":\"depthUpdate\",\"E\":1704067200462,\"U\":461,\"u\":461,\"b\":[[\"50000.00\",\"1.00000000\"]],\"a\":[]}}"}
{"local_receipt_timestamp_ns":1704067200000004631,"raw_payload":"{\"stream\":\"btcusdt@depth@100ms\",\"data\":{\"e\":\"depthUpdate\",\"E\":1704067200463,\"U\":462,\"u\":462,\"b\":[],\"a\":[[\"50001.00\",\"1.00000000\"]]}}"}
{"local_receipt_timestamp_ns":1704067200000004641,"raw_payload":"{\"stream\":\"btcusdt@depth@100ms\",\"data\":{\"e\":\"depthUpdate\",\"E\":1704067200464,\"U\":463,\"u\":463,\"b\":[[\"50000.00\",\"1.00000000\"]],\"a\":[]}}"}
{"local_receipt_timestamp_ns":1704067200000004651,"raw_payload":"{\"stream\":\"btcusdt@depth@100ms\",\"data\":{\"e\":\"depthUpdate\",\"E\":1704067200465,\"U\":464,\"u\":464,\"b\":[],\"a\":[[\"50001.00\",\"1.00000000\"]]}}"}
{"local_receipt_timestamp_ns":1704067200000004661,"raw_payload":"{\"stream\":\"btcusdt@depth@100ms\",\"data\":{\"e\":\"depthUpdate\",\"E\":1704067200466,\"U\":465,\"u\":465,\"b\":[[\"50000.00\",\"1.00000000\"]],\"a\":[]}}"}
{"local_receipt_timestamp_ns":1704067200000004671,"raw_payload":"{\"stream\":\"btcusdt@depth@100ms\",\"data\":{\"e\":\"depthUpdate\",\"E\":1704067200467,\"U\":466,\"u\":466,\"b\":[],\"a\":[[\"50001.00\",\"1.00000000\"]]}}"}
{"local_receipt_timestamp_ns":1704067200000004681,"raw_payload":"{\"stream\":\"btcusdt@depth@100ms\",\"data\":{\"e\":\"depthUpdate\",\"E\":1704067200468,\"U\":467,\"u\":467,\"b\":[[\"50000.00\",\"1.00000000\"]],\"a\":[]}}"}
{"local_receipt_timestamp_ns":1704067200000004691,"raw_payload":"{\"stream\":\"btcusdt@depth@100ms\",\"data\":{\"e\":\"depthUpdate\",\"E\":1704067200469,\"U\":468,\"u\":468,\"b\":[],\"a\":[[\"50001.00\",\"1.00000000\"]]}}"}
{"local_receipt_timestamp_ns":1704067200000004701,"raw_payload":"{\"stream\":\"btcusdt@depth@100ms\",\"data\":{\"e\":\"depthUpdate\",\"E\":1704067200470,\"U\":469,\"u\":469,\"b\":[[\"50000.00\",\"1.00000000\"]],\"a\":[]}}"}
{"local_receipt_timestamp_ns":1704067200000004711,"raw_payload":"{\"stream\":\"btcusdt@depth@100ms\",\"data\":{\"e\":\"depthUpdate\",\"E\":1704067200471,\"U\":470,\"u\":470,\"b\":[],\"a\":[[\"50001.00\",\"1.00000000\"]]}}"}
{"local_receipt_timestamp_ns":1704067200000004721,"raw_payload":"{\"stream\":\"btcusdt@depth@100ms\",\"data\":{\"e\":\"depthUpdate\",\"E\":1704067200472,\"U\":471,\"u\":471,\"b\":[[\"50000.00\",\"1.00000000\"]],\"a\":[]}}"}
{"local_receipt_timestamp_ns":1704067200000004731,"raw_payload":"{\"stream\":\"btcusdt@depth@100ms\",\"data\":{\"e\":\"depthUpdate\",\"E\":1704067200473,\"U\":472,\"u\":472,\"b\":[],\"a\":[[\"50001.00\",\"1.00000000\"]]}}"}
{"local_receipt_timestamp_ns":1704067200000004741,"raw_payload":"{\"stream\":\"btcusdt@depth@100ms\",\"data\":{\"e\":\"depthUpdate\",\"E\":1704067200474,\"U\":473,\"u\":473,\"b\":[[\"50000.00\",\"1.00000000\"]],\"a\":[]}}"}
{"local_receipt_timestamp_ns":1704067200000004751,"raw_payload":"{\"stream\":\"btcusdt@depth@100ms\",\"data\":{\"e\":\"depthUpdate\",\"E\":1704067200475,\"U\":474,\"u\":474,\"b\":[],\"a\":[[\"50001.00\",\"1.00000000\"]]}}"}
{"local_receipt_timestamp_ns":1704067200000004761,"raw_payload":"{\"stream\":\"btcusdt@depth@100ms\",\"data\":{\"e\":\"depthUpdate\",\"E\":1704067200476,\"U\":475,\"u\":475,\"b\":[[\"50000.00\",\"1.00000000\"]],\"a\":[]}}"}
{"local_receipt_timestamp_ns":1704067200000004771,"raw_payload":"{\"stream\":\"btcusdt@depth@100ms\",\"data\":{\"e\":\"depthUpdate\",\"E\":1704067200477,\"U\":476,\"u\":476,\"b\":[],\"a\":[[\"50001.00\",\"1.00000000\"]]}}"}
{"local_receipt_timestamp_ns":1704067200000004781,"raw_payload":"{\"stream\":\"btcusdt@depth@100ms\",\"data\":{\"e\":\"depthUpdate\",\"E\":1704067200478,\"U\":477,\"u\":477,\"b\":[[\"50000.00\",\"1.00000000\"]],\"a\":[]}}"}
{"local_receipt_timestamp_ns":1704067200000004791,"raw_payload":"{\"stream\":\"btcusdt@depth@100ms\",\"data\":{\"e\":\"depthUpdate\",\"E\":1704067200479,\"U\":478,\"u\":478,\"b\":[],\"a\":[[\"50001.00\",\"1.00000000\"]]}}"}
{"local_receipt_timestamp_ns":1704067200000004801,"raw_payload":"{\"stream\":\"btcusdt@depth@100ms\",\"data\":{\"e\":\"depthUpdate\",\"E\":1704067200480,\"U\":479,\"u\":479,\"b\":[[\"50000.00\",\"1.00000000\"]],\"a\":[]}}"}
{"local_receipt_timestamp_ns":1704067200000004811,"raw_payload":"{\"stream\":\"btcusdt@depth@100ms\",\"data\":{\"e\":\"depthUpdate\",\"E\":1704067200481,\"U\":480,\"u\":480,\"b\":[],\"a\":[[\"50001.00\",\"1.00000000\"]]}}"}
{"local_receipt_timestamp_ns":1704067200000004821,"raw_payload":"{\"stream\":\"btcusdt@depth@100ms\",\"data\":{\"e\":\"depthUpdate\",\"E\":1704067200482,\"U\":481,\"u\":481,\"b\":[[\"50000.00\",\"1.00000000\"]],\"a\":[]}}"}
{"local_receipt_timestamp_ns":1704067200000004831,"raw_payload":"{\"stream\":\"btcusdt@depth@100ms\",\"data\":{\"e\":\"depthUpdate\",\"E\":1704067200483,\"U\":482,\"u\":482,\"b\":[],\"a\":[[\"50001.00\",\"1.00000000\"]]}}"}
{"local_receipt_timestamp_ns":1704067200000004841,"raw_payload":"{\"stream\":\"btcusdt@depth@100ms\",\"data\":{\"e\":\"depthUpdate\",\"E\":1704067200484,\"U\":483,\"u\":483,\"b\":[[\"50000.00\",\"1.00000000\"]],\"a\":[]}}"}
{"local_receipt_timestamp_ns":1704067200000004851,"raw_payload":"{\"stream\":\"btcusdt@depth@100ms\",\"data\":{\"e\":\"depthUpdate\",\"E\":1704067200485,\"U\":484,\"u\":484,\"b\":[],\"a\":[[\"50001.00\",\"1.00000000\"]]}}"}
{"local_receipt_timestamp_ns":1704067200000004861,"raw_payload":"{\"stream\":\"btcusdt@depth@100ms\",\"data\":{\"e\":\"depthUpdate\",\"E\":1704067200486,\"U\":485,\"u\":485,\"b\":[[\"50000.00\",\"1.00000000\"]],\"a\":[]}}"}
{"local_receipt_timestamp_ns":1704067200000004871,"raw_payload":"{\"stream\":\"btcusdt@depth@100ms\",\"data\":{\"e\":\"depthUpdate\",\"E\":1704067200487,\"U\":486,\"u\":486,\"b\":[],\"a\":[[\"50001.00\",\"1.00000000\"]]}}"}
{"local_receipt_timestamp_ns":1704067200000004881,"raw_payload":"{\"stream\":\"btcusdt@depth@100ms\",\"data\":{\"e\":\"depthUpdate\",\"E\":1704067200488,\"U\":487,\"u\":487,\"b\":[[\"50000.00\",\"1.00000000\"]],\"a\":[]}}"}
{"local_receipt_timestamp_ns":1704067200000004891,"raw_payload":"{\"stream\":\"btcusdt@depth@100ms\",\"data\":{\"e\":\"depthUpdate\",\"E\":1704067200489,\"U\":488,\"u\":488,\"b\":[],\"a\":[[\"50001.00\",\"1.00000000\"]]}}"}
{"local_receipt_timestamp_ns":1704067200000004901,"raw_payload":"{\"stream\":\"btcusdt@depth@100ms\",\"data\":{\"e\":\"depthUpdate\",\"E\":1704067200490,\"U\":489,\"u\":489,\"b\":[[\"50000.00\",\"1.00000000\"]],\"a\":[]}}"}
{"local_receipt_timestamp_ns":1704067200000004911,"raw_payload":"{\"stream\":\"btcusdt@depth@100ms\",\"data\":{\"e\":\"depthUpdate\",\"E\":1704067200491,\"U\":490,\"u\":490,\"b\":[],\"a\":[[\"50001.00\",\"1.00000000\"]]}}"}
{"local_receipt_timestamp_ns":1704067200000004921,"raw_payload":"{\"stream\":\"btcusdt@depth@100ms\",\"data\":{\"e\":\"depthUpdate\",\"E\":1704067200492,\"U\":491,\"u\":491,\"b\":[[\"50000.00\",\"1.00000000\"]],\"a\":[]}}"}
{"local_receipt_timestamp_ns":1704067200000004931,"raw_payload":"{\"stream\":\"btcusdt@depth@100ms\",\"data\":{\"e\":\"depthUpdate\",\"E\":1704067200493,\"U\":492,\"u\":492,\"b\":[],\"a\":[[\"50001.00\",\"1.00000000\"]]}}"}
{"local_receipt_timestamp_ns":1704067200000004941,"raw_payload":"{\"stream\":\"btcusdt@depth@100ms\",\"data\":{\"e\":\"depthUpdate\",\"E\":1704067200494,\"U\":493,\"u\":493,\"b\":[[\"50000.00\",\"1.00000000\"]],\"a\":[]}}"}
{"local_receipt_timestamp_ns":1704067200000004951,"raw_payload":"{\"stream\":\"btcusdt@depth@100ms\",\"data\":{\"e\":\"depthUpdate\",\"E\":1704067200495,\"U\":494,\"u\":494,\"b\":[],\"a\":[[\"50001.00\",\"1.00000000\"]]}}"}
{"local_receipt_timestamp_ns":1704067200000004961,"raw_payload":"{\"stream\":\"btcusdt@depth@100ms\",\"data\":{\"e\":\"depthUpdate\",\"E\":1704067200496,\"U\":495,\"u\":495,\"b\":[[\"50000.00\",\"1.00000000\"]],\"a\":[]}}"}
{"local_receipt_timestamp_ns":1704067200000004971,"raw_payload":"{\"stream\":\"btcusdt@depth@100ms\",\"data\":{\"e\":\"depthUpdate\",\"E\":1704067200497,\"U\":496,\"u\":496,\"b\":[],\"a\":[[\"50001.00\",\"1.00000000\"]]}}"}
{"local_receipt_timestamp_ns":1704067200000004981,"raw_payload":"{\"stream\":\"btcusdt@depth@100ms\",\"data\":{\"e\":\"depthUpdate\",\"E\":1704067200498,\"U\":497,\"u\":497,\"b\":[[\"50000.00\",\"1.00000000\"]],\"a\":[]}}"}
{"local_receipt_timestamp_ns":1704067200000004991,"raw_payload":"{\"stream\":\"btcusdt@depth@100ms\",\"data\":{\"e\":\"depthUpdate\",\"E\":1704067200499,\"U\":498,\"u\":498,\"b\":[],\"a\":[[\"50001.00\",\"1.00000000\"]]}}"}
{"local_receipt_timestamp_ns":1704067200000005001,"raw_payload":"{\"stream\":\"btcusdt@depth@100ms\",\"data\":{\"e\":\"depthUpdate\",\"E\":1704067200500,\"U\":499,\"u\":499,\"b\":[[\"50000.00\",\"1.00000000\"]],\"a\":[]}}"}
{"local_receipt_timestamp_ns":1704067200000005011,"raw_payload":"{\"stream\":\"btcusdt@depth@100ms\",\"data\":{\"e\":\"depthUpdate\",\"E\":1704067200501,\"U\":500,\"u\":500,\"b\":[],\"a\":[[\"50001.00\",\"1.00000000\"]]}}"}
{"local_receipt_timestamp_ns":1704067200000005021,"raw_payload":"{\"stream\":\"btcusdt@depth@100ms\",\"data\":{\"e\":\"depthUpdate\",\"E\":1704067200502,\"U\":501,\"u\":501,\"b\":[[\"50000.00\",\"1.00000000\"]],\"a\":[]}}"}
{"local_receipt_timestamp_ns":1704067200000005031,"raw_payload":"{\"stream\":\"btcusdt@depth@100ms\",\"data\":{\"e\":\"depthUpdate\",\"E\":1704067200503,\"U\":502,\"u\":502,\"b\":[],\"a\":[[\"50001.00\",\"1.00000000\"]]}}"}
{"local_receipt_timestamp_ns":1704067200000005041,"raw_payload":"{\"stream\":\"btcusdt@depth@100ms\",\"data\":{\"e\":\"depthUpdate\",\"E\":1704067200504,\"U\":503,\"u\":503,\"b\":[[\"50000.00\",\"1.00000000\"]],\"a\":[]}}"}
{"local_receipt_timestamp_ns":1704067200000005051,"raw_payload":"{\"stream\":\"btcusdt@depth@100ms\",\"data\":{\"e\":\"depthUpdate\",\"E\":1704067200505,\"U\":504,\"u\":504,\"b\":[],\"a\":[[\"50001.00\",\"1.00000000\"]]}}"}
{"local_receipt_timestamp_ns":1704067200000005061,"raw_payload":"{\"stream\":\"btcusdt@depth@100ms\",\"data\":{\"e\":\"depthUpdate\",\"E\":1704067200506,\"U\":505,\"u\":505,\"b\":[[\"50000.00\",\"1.00000000\"]],\"a\":[]}}"}
{"local_receipt_timestamp_ns":1704067200000005071,"raw_payload":"{\"stream\":\"btcusdt@depth@100ms\",\"data\":{\"e\":\"depthUpdate\",\"E\":1704067200507,\"U\":506,\"u\":506,\"b\":[],\"a\":[[\"50001.00\",\"1.00000000\"]]}}"}
{"local_receipt_timestamp_ns":1704067200000005081,"raw_payload":"{\"stream\":\"btcusdt@depth@100ms\",\"data\":{\"e\":\"depthUpdate\",\"E\":1704067200508,\"U\":507,\"u\":507,\"b\":[[\"50000.00\",\"1.00000000\"]],\"a\":[]}}"}
{"local_receipt_timestamp_ns":1704067200000005091,"raw_payload":"{\"stream\":\"btcusdt@depth@100ms\",\"data\":{\"e\":\"depthUpdate\",\"E\":1704067200509,\"U\":508,\"u\":508,\"b\":[],\"a\":[[\"50001.00\",\"1.00000000\"]]}}"}
{"local_receipt_timestamp_ns":1704067200000005101,"raw_payload":"{\"stream\":\"btcusdt@depth@100ms\",\"data\":{\"e\":\"depthUpdate\",\"E\":1704067200510,\"U\":509,\"u\":509,\"b\":[[\"50000.00\",\"1.00000000\"]],\"a\":[]}}"}
{"local_receipt_timestamp_ns":1704067200000005111,"raw_payload":"{\"stream\":\"btcusdt@depth@100ms\",\"data\":{\"e\":\"depthUpdate\",\"E\":1704067200511,\"U\":510,\"u\":510,\"b\":[],\"a\":[[\"50001.00\",\"1.00000000\"]]}}"}
{"local_receipt_timestamp_ns":1704067200000005121,"raw_payload":"{\"stream\":\"btcusdt@depth@100ms\",\"data\":{\"e\":\"depthUpdate\",\"E\":1704067200512,\"U\":511,\"u\":511,\"b\":[[\"50000.00\",\"1.00000000\"]],\"a\":[]}}"}
{"local_receipt_timestamp_ns":1704067200000005131,"raw_payload":"{\"stream\":\"btcusdt@depth@100ms\",\"data\":{\"e\":\"depthUpdate\",\"E\":1704067200513,\"U\":512,\"u\":512,\"b\":[],\"a\":[[\"50001.00\",\"1.00000000\"]]}}"}
{"local_receipt_timestamp_ns":1704067200000005141,"raw_payload":"{\"stream\":\"btcusdt@depth@100ms\",\"data\":{\"e\":\"depthUpdate\",\"E\":1704067200514,\"U\":513,\"u\":513,\"b\":[[\"50000.00\",\"1.00000000\"]],\"a\":[]}}"}
{"local_receipt_timestamp_ns":1704067200000005151,"raw_payload":"{\"stream\":\"btcusdt@depth@100ms\",\"data\":{\"e\":\"depthUpdate\",\"E\":1704067200515,\"U\":514,\"u\":514,\"b\":[],\"a\":[[\"50001.00\",\"1.00000000\"]]}}"}
{"local_receipt_timestamp_ns":1704067200000005161,"raw_payload":"{\"stream\":\"btcusdt@depth@100ms\",\"data\":{\"e\":\"depthUpdate\",\"E\":1704067200516,\"U\":515,\"u\":515,\"b\":[[\"50000.00\",\"1.00000000\"]],\"a\":[]}}"}
{"local_receipt_timestamp_ns":1704067200000005171,"raw_payload":"{\"stream\":\"btcusdt@depth@100ms\",\"data\":{\"e\":\"depthUpdate\",\"E\":1704067200517,\"U\":516,\"u\":516,\"b\":[],\"a\":[[\"50001.00\",\"1.00000000\"]]}}"}
{"local_receipt_timestamp_ns":1704067200000005181,"raw_payload":"{\"stream\":\"btcusdt@depth@100ms\",\"data\":{\"e\":\"depthUpdate\",\"E\":1704067200518,\"U\":517,\"u\":517,\"b\":[[\"50000.00\",\"1.00000000\"]],\"a\":[]}}"}
{"local_receipt_timestamp_ns":1704067200000005191,"raw_payload":"{\"stream\":\"btcusdt@depth@100ms\",\"data\":{\"e\":\"depthUpdate\",\"E\":1704067200519,\"U\":518,\"u\":518,\"b\":[],\"a\":[[\"50001.00\",\"1.00000000\"]]}}"}
{"local_receipt_timestamp_ns":1704067200000005201,"raw_payload":"{\"stream\":\"btcusdt@depth@100ms\",\"data\":{\"e\":\"depthUpdate\",\"E\":1704067200520,\"U\":519,\"u\":519,\"b\":[[\"50000.00\",\"1.00000000\"]],\"a\":[]}}"}
{"local_receipt_timestamp_ns":1704067200000005211,"raw_payload":"{\"stream\":\"btcusdt@depth@100ms\",\"data\":{\"e\":\"depthUpdate\",\"E\":1704067200521,\"U\":520,\"u\":520,\"b\":[],\"a\":[[\"50001.00\",\"1.00000000\"]]}}"}
{"local_receipt_timestamp_ns":1704067200000005221,"raw_payload":"{\"stream\":\"btcusdt@depth@100ms\",\"data\":{\"e\":\"depthUpdate\",\"E\":1704067200522,\"U\":521,\"u\":521,\"b\":[[\"50000.00\",\"1.00000000\"]],\"a\":[]}}"}
{"local_receipt_timestamp_ns":1704067200000005231,"raw_payload":"{\"stream\":\"btcusdt@depth@100ms\",\"data\":{\"e\":\"depthUpdate\",\"E\":1704067200523,\"U\":522,\"u\":522,\"b\":[],\"a\":[[\"50001.00\",\"1.00000000\"]]}}"}
{"local_receipt_timestamp_ns":1704067200000005241,"raw_payload":"{\"stream\":\"btcusdt@depth@100ms\",\"data\":{\"e\":\"depthUpdate\",\"E\":1704067200524,\"U\":523,\"u\":523,\"b\":[[\"50000.00\",\"1.00000000\"]],\"a\":[]}}"}
{"local_receipt_timestamp_ns":1704067200000005251,"raw_payload":"{\"stream\":\"btcusdt@depth@100ms\",\"data\":{\"e\":\"depthUpdate\",\"E\":1704067200525,\"U\":524,\"u\":524,\"b\":[],\"a\":[[\"50001.00\",\"1.00000000\"]]}}"}
{"local_receipt_timestamp_ns":1704067200000005261,"raw_payload":"{\"stream\":\"btcusdt@depth@100ms\",\"data\":{\"e\":\"depthUpdate\",\"E\":1704067200526,\"U\":525,\"u\":525,\"b\":[[\"50000.00\",\"1.00000000\"]],\"a\":[]}}"}
{"local_receipt_timestamp_ns":1704067200000005271,"raw_payload":"{\"stream\":\"btcusdt@depth@100ms\",\"data\":{\"e\":\"depthUpdate\",\"E\":1704067200527,\"U\":526,\"u\":526,\"b\":[],\"a\":[[\"50001.00\",\"1.00000000\"]]}}"}
{"local_receipt_timestamp_ns":1704067200000005281,"raw_payload":"{\"stream\":\"btcusdt@depth@100ms\",\"data\":{\"e\":\"depthUpdate\",\"E\":1704067200528,\"U\":527,\"u\":527,\"b\":[[\"50000.00\",\"1.00000000\"]],\"a\":[]}}"}
{"local_receipt_timestamp_ns":1704067200000005291,"raw_payload":"{\"stream\":\"btcusdt@depth@100ms\",\"data\":{\"e\":\"depthUpdate\",\"E\":1704067200529,\"U\":528,\"u\":528,\"b\":[],\"a\":[[\"50001.00\",\"1.00000000\"]]}}"}
{"local_receipt_timestamp_ns":1704067200000005301,"raw_payload":"{\"stream\":\"btcusdt@depth@100ms\",\"data\":{\"e\":\"depthUpdate\",\"E\":1704067200530,\"U\":529,\"u\":529,\"b\":[[\"50000.00\",\"1.00000000\"]],\"a\":[]}}"}
{"local_receipt_timestamp_ns":1704067200000005311,"raw_payload":"{\"stream\":\"btcusdt@depth@100ms\",\"data\":{\"e\":\"depthUpdate\",\"E\":1704067200531,\"U\":530,\"u\":530,\"b\":[],\"a\":[[\"50001.00\",\"1.00000000\"]]}}"}
{"local_receipt_timestamp_ns":1704067200000005321,"raw_payload":"{\"stream\":\"btcusdt@depth@100ms\",\"data\":{\"e\":\"depthUpdate\",\"E\":1704067200532,\"U\":531,\"u\":531,\"b\":[[\"50000.00\",\"1.00000000\"]],\"a\":[]}}"}
{"local_receipt_timestamp_ns":1704067200000005331,"raw_payload":"{\"stream\":\"btcusdt@depth@100ms\",\"data\":{\"e\":\"depthUpdate\",\"E\":1704067200533,\"U\":532,\"u\":532,\"b\":[],\"a\":[[\"50001.00\",\"1.00000000\"]]}}"}
{"local_receipt_timestamp_ns":1704067200000005341,"raw_payload":"{\"stream\":\"btcusdt@depth@100ms\",\"data\":{\"e\":\"depthUpdate\",\"E\":1704067200534,\"U\":533,\"u\":533,\"b\":[[\"50000.00\",\"1.00000000\"]],\"a\":[]}}"}
{"local_receipt_timestamp_ns":1704067200000005351,"raw_payload":"{\"stream\":\"btcusdt@depth@100ms\",\"data\":{\"e\":\"depthUpdate\",\"E\":1704067200535,\"U\":534,\"u\":534,\"b\":[],\"a\":[[\"50001.00\",\"1.00000000\"]]}}"}
{"local_receipt_timestamp_ns":1704067200000005361,"raw_payload":"{\"stream\":\"btcusdt@depth@100ms\",\"data\":{\"e\":\"depthUpdate\",\"E\":1704067200536,\"U\":535,\"u\":535,\"b\":[[\"50000.00\",\"1.00000000\"]],\"a\":[]}}"}
{"local_receipt_timestamp_ns":1704067200000005371,"raw_payload":"{\"stream\":\"btcusdt@depth@100ms\",\"data\":{\"e\":\"depthUpdate\",\"E\":1704067200537,\"U\":536,\"u\":536,\"b\":[],\"a\":[[\"50001.00\",\"1.00000000\"]]}}"}
{"local_receipt_timestamp_ns":1704067200000005381,"raw_payload":"{\"stream\":\"btcusdt@depth@100ms\",\"data\":{\"e\":\"depthUpdate\",\"E\":1704067200538,\"U\":537,\"u\":537,\"b\":[[\"50000.00\",\"1.00000000\"]],\"a\":[]}}"}
{"local_receipt_timestamp_ns":1704067200000005391,"raw_payload":"{\"stream\":\"btcusdt@depth@100ms\",\"data\":{\"e\":\"depthUpdate\",\"E\":1704067200539,\"U\":538,\"u\":538,\"b\":[],\"a\":[[\"50001.00\",\"1.00000000\"]]}}"}
{"local_receipt_timestamp_ns":1704067200000005401,"raw_payload":"{\"stream\":\"btcusdt@depth@100ms\",\"data\":{\"e\":\"depthUpdate\",\"E\":1704067200540,\"U\":539,\"u\":539,\"b\":[[\"50000.00\",\"1.00000000\"]],\"a\":[]}}"}
{"local_receipt_timestamp_ns":1704067200000005411,"raw_payload":"{\"stream\":\"btcusdt@depth@100ms\",\"data\":{\"e\":\"depthUpdate\",\"E\":1704067200541,\"U\":540,\"u\":540,\"b\":[],\"a\":[[\"50001.00\",\"1.00000000\"]]}}"}
{"local_receipt_timestamp_ns":1704067200000005421,"raw_payload":"{\"stream\":\"btcusdt@depth@100ms\",\"data\":{\"e\":\"depthUpdate\",\"E\":1704067200542,\"U\":541,\"u\":541,\"b\":[[\"50000.00\",\"1.00000000\"]],\"a\":[]}}"}
{"local_receipt_timestamp_ns":1704067200000005431,"raw_payload":"{\"stream\":\"btcusdt@depth@100ms\",\"data\":{\"e\":\"depthUpdate\",\"E\":1704067200543,\"U\":542,\"u\":542,\"b\":[],\"a\":[[\"50001.00\",\"1.00000000\"]]}}"}
{"local_receipt_timestamp_ns":1704067200000005441,"raw_payload":"{\"stream\":\"btcusdt@depth@100ms\",\"data\":{\"e\":\"depthUpdate\",\"E\":1704067200544,\"U\":543,\"u\":543,\"b\":[[\"50000.00\",\"1.00000000\"]],\"a\":[]}}"}
{"local_receipt_timestamp_ns":1704067200000005451,"raw_payload":"{\"stream\":\"btcusdt@depth@100ms\",\"data\":{\"e\":\"depthUpdate\",\"E\":1704067200545,\"U\":544,\"u\":544,\"b\":[],\"a\":[[\"50001.00\",\"1.00000000\"]]}}"}
{"local_receipt_timestamp_ns":1704067200000005461,"raw_payload":"{\"stream\":\"btcusdt@depth@100ms\",\"data\":{\"e\":\"depthUpdate\",\"E\":1704067200546,\"U\":545,\"u\":545,\"b\":[[\"50000.00\",\"1.00000000\"]],\"a\":[]}}"}
{"local_receipt_timestamp_ns":1704067200000005471,"raw_payload":"{\"stream\":\"btcusdt@depth@100ms\",\"data\":{\"e\":\"depthUpdate\",\"E\":1704067200547,\"U\":546,\"u\":546,\"b\":[],\"a\":[[\"50001.00\",\"1.00000000\"]]}}"}
{"local_receipt_timestamp_ns":1704067200000005481,"raw_payload":"{\"stream\":\"btcusdt@depth@100ms\",\"data\":{\"e\":\"depthUpdate\",\"E\":1704067200548,\"U\":547,\"u\":547,\"b\":[[\"50000.00\",\"1.00000000\"]],\"a\":[]}}"}
{"local_receipt_timestamp_ns":1704067200000005491,"raw_payload":"{\"stream\":\"btcusdt@depth@100ms\",\"data\":{\"e\":\"depthUpdate\",\"E\":1704067200549,\"U\":548,\"u\":548,\"b\":[],\"a\":[[\"50001.00\",\"1.00000000\"]]}}"}
{"local_receipt_timestamp_ns":1704067200000005501,"raw_payload":"{\"stream\":\"btcusdt@depth@100ms\",\"data\":{\"e\":\"depthUpdate\",\"E\":1704067200550,\"U\":549,\"u\":549,\"b\":[[\"50000.00\",\"1.00000000\"]],\"a\":[]}}"}
{"local_receipt_timestamp_ns":1704067200000005511,"raw_payload":"{\"stream\":\"btcusdt@depth@100ms\",\"data\":{\"e\":\"depthUpdate\",\"E\":1704067200551,\"U\":550,\"u\":550,\"b\":[],\"a\":[[\"50001.00\",\"1.00000000\"]]}}"}
{"local_receipt_timestamp_ns":1704067200000005521,"raw_payload":"{\"stream\":\"btcusdt@depth@100ms\",\"data\":{\"e\":\"depthUpdate\",\"E\":1704067200552,\"U\":551,\"u\":551,\"b\":[[\"50000.00\",\"1.00000000\"]],\"a\":[]}}"}
{"local_receipt_timestamp_ns":1704067200000005531,"raw_payload":"{\"stream\":\"btcusdt@depth@100ms\",\"data\":{\"e\":\"depthUpdate\",\"E\":1704067200553,\"U\":552,\"u\":552,\"b\":[],\"a\":[[\"50001.00\",\"1.00000000\"]]}}"}
{"local_receipt_timestamp_ns":1704067200000005541,"raw_payload":"{\"stream\":\"btcusdt@depth@100ms\",\"data\":{\"e\":\"depthUpdate\",\"E\":1704067200554,\"U\":553,\"u\":553,\"b\":[[\"50000.00\",\"1.00000000\"]],\"a\":[]}}"}
{"local_receipt_timestamp_ns":1704067200000005551,"raw_payload":"{\"stream\":\"btcusdt@depth@100ms\",\"data\":{\"e\":\"depthUpdate\",\"E\":1704067200555,\"U\":554,\"u\":554,\"b\":[],\"a\":[[\"50001.00\",\"1.00000000\"]]}}"}
{"local_receipt_timestamp_ns":1704067200000005561,"raw_payload":"{\"stream\":\"btcusdt@depth@100ms\",\"data\":{\"e\":\"depthUpdate\",\"E\":1704067200556,\"U\":555,\"u\":555,\"b\":[[\"50000.00\",\"1.00000000\"]],\"a\":[]}}"}
{"local_receipt_timestamp_ns":1704067200000005571,"raw_payload":"{\"stream\":\"btcusdt@depth@100ms\",\"data\":{\"e\":\"depthUpdate\",\"E\":1704067200557,\"U\":556,\"u\":556,\"b\":[],\"a\":[[\"50001.00\",\"1.00000000\"]]}}"}
{"local_receipt_timestamp_ns":1704067200000005581,"raw_payload":"{\"stream\":\"btcusdt@depth@100ms\",\"data\":{\"e\":\"depthUpdate\",\"E\":1704067200558,\"U\":557,\"u\":557,\"b\":[[\"50000.00\",\"1.00000000\"]],\"a\":[]}}"}
{"local_receipt_timestamp_ns":1704067200000005591,"raw_payload":"{\"stream\":\"btcusdt@depth@100ms\",\"data\":{\"e\":\"depthUpdate\",\"E\":1704067200559,\"U\":558,\"u\":558,\"b\":[],\"a\":[[\"50001.00\",\"1.00000000\"]]}}"}
{"local_receipt_timestamp_ns":1704067200000005601,"raw_payload":"{\"stream\":\"btcusdt@depth@100ms\",\"data\":{\"e\":\"depthUpdate\",\"E\":1704067200560,\"U\":559,\"u\":559,\"b\":[[\"50000.00\",\"1.00000000\"]],\"a\":[]}}"}
{"local_receipt_timestamp_ns":1704067200000005611,"raw_payload":"{\"stream\":\"btcusdt@depth@100ms\",\"data\":{\"e\":\"depthUpdate\",\"E\":1704067200561,\"U\":560,\"u\":560,\"b\":[],\"a\":[[\"50001.00\",\"1.00000000\"]]}}"}
{"local_receipt_timestamp_ns":1704067200000005621,"raw_payload":"{\"stream\":\"btcusdt@depth@100ms\",\"data\":{\"e\":\"depthUpdate\",\"E\":1704067200562,\"U\":561,\"u\":561,\"b\":[[\"50000.00\",\"1.00000000\"]],\"a\":[]}}"}
{"local_receipt_timestamp_ns":1704067200000005631,"raw_payload":"{\"stream\":\"btcusdt@depth@100ms\",\"data\":{\"e\":\"depthUpdate\",\"E\":1704067200563,\"U\":562,\"u\":562,\"b\":[],\"a\":[[\"50001.00\",\"1.00000000\"]]}}"}
{"local_receipt_timestamp_ns":1704067200000005641,"raw_payload":"{\"stream\":\"btcusdt@depth@100ms\",\"data\":{\"e\":\"depthUpdate\",\"E\":1704067200564,\"U\":563,\"u\":563,\"b\":[[\"50000.00\",\"1.00000000\"]],\"a\":[]}}"}
{"local_receipt_timestamp_ns":1704067200000005651,"raw_payload":"{\"stream\":\"btcusdt@depth@100ms\",\"data\":{\"e\":\"depthUpdate\",\"E\":1704067200565,\"U\":564,\"u\":564,\"b\":[],\"a\":[[\"50001.00\",\"1.00000000\"]]}}"}
{"local_receipt_timestamp_ns":1704067200000005661,"raw_payload":"{\"stream\":\"btcusdt@depth@100ms\",\"data\":{\"e\":\"depthUpdate\",\"E\":1704067200566,\"U\":565,\"u\":565,\"b\":[[\"50000.00\",\"1.00000000\"]],\"a\":[]}}"}
{"local_receipt_timestamp_ns":1704067200000005671,"raw_payload":"{\"stream\":\"btcusdt@depth@100ms\",\"data\":{\"e\":\"depthUpdate\",\"E\":1704067200567,\"U\":566,\"u\":566,\"b\":[],\"a\":[[\"50001.00\",\"1.00000000\"]]}}"}
{"local_receipt_timestamp_ns":1704067200000005681,"raw_payload":"{\"stream\":\"btcusdt@depth@100ms\",\"data\":{\"e\":\"depthUpdate\",\"E\":1704067200568,\"U\":567,\"u\":567,\"b\":[[\"50000.00\",\"1.00000000\"]],\"a\":[]}}"}
{"local_receipt_timestamp_ns":1704067200000005691,"raw_payload":"{\"stream\":\"btcusdt@depth@100ms\",\"data\":{\"e\":\"depthUpdate\",\"E\":1704067200569,\"U\":568,\"u\":568,\"b\":[],\"a\":[[\"50001.00\",\"1.00000000\"]]}}"}
{"local_receipt_timestamp_ns":1704067200000005701,"raw_payload":"{\"stream\":\"btcusdt@depth@100ms\",\"data\":{\"e\":\"depthUpdate\",\"E\":1704067200570,\"U\":569,\"u\":569,\"b\":[[\"50000.00\",\"1.00000000\"]],\"a\":[]}}"}
{"local_receipt_timestamp_ns":1704067200000005711,"raw_payload":"{\"stream\":\"btcusdt@depth@100ms\",\"data\":{\"e\":\"depthUpdate\",\"E\":1704067200571,\"U\":570,\"u\":570,\"b\":[],\"a\":[[\"50001.00\",\"1.00000000\"]]}}"}
{"local_receipt_timestamp_ns":1704067200000005721,"raw_payload":"{\"stream\":\"btcusdt@depth@100ms\",\"data\":{\"e\":\"depthUpdate\",\"E\":1704067200572,\"U\":571,\"u\":571,\"b\":[[\"50000.00\",\"1.00000000\"]],\"a\":[]}}"}
{"local_receipt_timestamp_ns":1704067200000005731,"raw_payload":"{\"stream\":\"btcusdt@depth@100ms\",\"data\":{\"e\":\"depthUpdate\",\"E\":1704067200573,\"U\":572,\"u\":572,\"b\":[],\"a\":[[\"50001.00\",\"1.00000000\"]]}}"}
{"local_receipt_timestamp_ns":1704067200000005741,"raw_payload":"{\"stream\":\"btcusdt@depth@100ms\",\"data\":{\"e\":\"depthUpdate\",\"E\":1704067200574,\"U\":573,\"u\":573,\"b\":[[\"50000.00\",\"1.00000000\"]],\"a\":[]}}"}
{"local_receipt_timestamp_ns":1704067200000005751,"raw_payload":"{\"stream\":\"btcusdt@depth@100ms\",\"data\":{\"e\":\"depthUpdate\",\"E\":1704067200575,\"U\":574,\"u\":574,\"b\":[],\"a\":[[\"50001.00\",\"1.00000000\"]]}}"}
{"local_receipt_timestamp_ns":1704067200000005761,"raw_payload":"{\"stream\":\"btcusdt@depth@100ms\",\"data\":{\"e\":\"depthUpdate\",\"E\":1704067200576,\"U\":575,\"u\":575,\"b\":[[\"50000.00\",\"1.00000000\"]],\"a\":[]}}"}
{"local_receipt_timestamp_ns":1704067200000005771,"raw_payload":"{\"stream\":\"btcusdt@depth@100ms\",\"data\":{\"e\":\"depthUpdate\",\"E\":1704067200577,\"U\":576,\"u\":576,\"b\":[],\"a\":[[\"50001.00\",\"1.00000000\"]]}}"}
{"local_receipt_timestamp_ns":1704067200000005781,"raw_payload":"{\"stream\":\"btcusdt@depth@100ms\",\"data\":{\"e\":\"depthUpdate\",\"E\":1704067200578,\"U\":577,\"u\":577,\"b\":[[\"50000.00\",\"1.00000000\"]],\"a\":[]}}"}
{"local_receipt_timestamp_ns":1704067200000005791,"raw_payload":"{\"stream\":\"btcusdt@depth@100ms\",\"data\":{\"e\":\"depthUpdate\",\"E\":1704067200579,\"U\":578,\"u\":578,\"b\":[],\"a\":[[\"50001.00\",\"1.00000000\"]]}}"}
{"local_receipt_timestamp_ns":1704067200000005801,"raw_payload":"{\"stream\":\"btcusdt@depth@100ms\",\"data\":{\"e\":\"depthUpdate\",\"E\":1704067200580,\"U\":579,\"u\":579,\"b\":[[\"50000.00\",\"1.00000000\"]],\"a\":[]}}"}
{"local_receipt_timestamp_ns":1704067200000005811,"raw_payload":"{\"stream\":\"btcusdt@depth@100ms\",\"data\":{\"e\":\"depthUpdate\",\"E\":1704067200581,\"U\":580,\"u\":580,\"b\":[],\"a\":[[\"50001.00\",\"1.00000000\"]]}}"}
{"local_receipt_timestamp_ns":1704067200000005821,"raw_payload":"{\"stream\":\"btcusdt@depth@100ms\",\"data\":{\"e\":\"depthUpdate\",\"E\":1704067200582,\"U\":581,\"u\":581,\"b\":[[\"50000.00\",\"1.00000000\"]],\"a\":[]}}"}
{"local_receipt_timestamp_ns":1704067200000005831,"raw_payload":"{\"stream\":\"btcusdt@depth@100ms\",\"data\":{\"e\":\"depthUpdate\",\"E\":1704067200583,\"U\":582,\"u\":582,\"b\":[],\"a\":[[\"50001.00\",\"1.00000000\"]]}}"}
{"local_receipt_timestamp_ns":1704067200000005841,"raw_payload":"{\"stream\":\"btcusdt@depth@100ms\",\"data\":{\"e\":\"depthUpdate\",\"E\":1704067200584,\"U\":583,\"u\":583,\"b\":[[\"50000.00\",\"1.00000000\"]],\"a\":[]}}"}
{"local_receipt_timestamp_ns":1704067200000005851,"raw_payload":"{\"stream\":\"btcusdt@depth@100ms\",\"data\":{\"e\":\"depthUpdate\",\"E\":1704067200585,\"U\":584,\"u\":584,\"b\":[],\"a\":[[\"50001.00\",\"1.00000000\"]]}}"}
{"local_receipt_timestamp_ns":1704067200000005861,"raw_payload":"{\"stream\":\"btcusdt@depth@100ms\",\"data\":{\"e\":\"depthUpdate\",\"E\":1704067200586,\"U\":585,\"u\":585,\"b\":[[\"50000.00\",\"1.00000000\"]],\"a\":[]}}"}
{"local_receipt_timestamp_ns":1704067200000005871,"raw_payload":"{\"stream\":\"btcusdt@depth@100ms\",\"data\":{\"e\":\"depthUpdate\",\"E\":1704067200587,\"U\":586,\"u\":586,\"b\":[],\"a\":[[\"50001.00\",\"1.00000000\"]]}}"}
{"local_receipt_timestamp_ns":1704067200000005881,"raw_payload":"{\"stream\":\"btcusdt@depth@100ms\",\"data\":{\"e\":\"depthUpdate\",\"E\":1704067200588,\"U\":587,\"u\":587,\"b\":[[\"50000.00\",\"1.00000000\"]],\"a\":[]}}"}
{"local_receipt_timestamp_ns":1704067200000005891,"raw_payload":"{\"stream\":\"btcusdt@depth@100ms\",\"data\":{\"e\":\"depthUpdate\",\"E\":1704067200589,\"U\":588,\"u\":588,\"b\":[],\"a\":[[\"50001.00\",\"1.00000000\"]]}}"}
{"local_receipt_timestamp_ns":1704067200000005901,"raw_payload":"{\"stream\":\"btcusdt@depth@100ms\",\"data\":{\"e\":\"depthUpdate\",\"E\":1704067200590,\"U\":589,\"u\":589,\"b\":[[\"50000.00\",\"1.00000000\"]],\"a\":[]}}"}
{"local_receipt_timestamp_ns":1704067200000005911,"raw_payload":"{\"stream\":\"btcusdt@depth@100ms\",\"data\":{\"e\":\"depthUpdate\",\"E\":1704067200591,\"U\":590,\"u\":590,\"b\":[],\"a\":[[\"50001.00\",\"1.00000000\"]]}}"}
{"local_receipt_timestamp_ns":1704067200000005921,"raw_payload":"{\"stream\":\"btcusdt@depth@100ms\",\"data\":{\"e\":\"depthUpdate\",\"E\":1704067200592,\"U\":591,\"u\":591,\"b\":[[\"50000.00\",\"1.00000000\"]],\"a\":[]}}"}
{"local_receipt_timestamp_ns":1704067200000005931,"raw_payload":"{\"stream\":\"btcusdt@depth@100ms\",\"data\":{\"e\":\"depthUpdate\",\"E\":1704067200593,\"U\":592,\"u\":592,\"b\":[],\"a\":[[\"50001.00\",\"1.00000000\"]]}}"}
{"local_receipt_timestamp_ns":1704067200000005941,"raw_payload":"{\"stream\":\"btcusdt@depth@100ms\",\"data\":{\"e\":\"depthUpdate\",\"E\":1704067200594,\"U\":593,\"u\":593,\"b\":[[\"50000.00\",\"1.00000000\"]],\"a\":[]}}"}
{"local_receipt_timestamp_ns":1704067200000005951,"raw_payload":"{\"stream\":\"btcusdt@depth@100ms\",\"data\":{\"e\":\"depthUpdate\",\"E\":1704067200595,\"U\":594,\"u\":594,\"b\":[],\"a\":[[\"50001.00\",\"1.00000000\"]]}}"}
{"local_receipt_timestamp_ns":1704067200000005961,"raw_payload":"{\"stream\":\"btcusdt@depth@100ms\",\"data\":{\"e\":\"depthUpdate\",\"E\":1704067200596,\"U\":595,\"u\":595,\"b\":[[\"50000.00\",\"1.00000000\"]],\"a\":[]}}"}
{"local_receipt_timestamp_ns":1704067200000005971,"raw_payload":"{\"stream\":\"btcusdt@depth@100ms\",\"data\":{\"e\":\"depthUpdate\",\"E\":1704067200597,\"U\":596,\"u\":596,\"b\":[],\"a\":[[\"50001.00\",\"1.00000000\"]]}}"}
{"local_receipt_timestamp_ns":1704067200000005981,"raw_payload":"{\"stream\":\"btcusdt@depth@100ms\",\"data\":{\"e\":\"depthUpdate\",\"E\":1704067200598,\"U\":597,\"u\":597,\"b\":[[\"50000.00\",\"1.00000000\"]],\"a\":[]}}"}
{"local_receipt_timestamp_ns":1704067200000005991,"raw_payload":"{\"stream\":\"btcusdt@depth@100ms\",\"data\":{\"e\":\"depthUpdate\",\"E\":1704067200599,\"U\":598,\"u\":598,\"b\":[],\"a\":[[\"50001.00\",\"1.00000000\"]]}}"}
{"local_receipt_timestamp_ns":1704067200000006001,"raw_payload":"{\"stream\":\"btcusdt@depth@100ms\",\"data\":{\"e\":\"depthUpdate\",\"E\":1704067200600,\"U\":599,\"u\":599,\"b\":[[\"50000.00\",\"1.00000000\"]],\"a\":[]}}"}
{"local_receipt_timestamp_ns":1704067200000006011,"raw_payload":"{\"stream\":\"btcusdt@depth@100ms\",\"data\":{\"e\":\"depthUpdate\",\"E\":1704067200601,\"U\":600,\"u\":600,\"b\":[],\"a\":[[\"50001.00\",\"1.00000000\"]]}}"}
{"local_receipt_timestamp_ns":1704067200000006021,"raw_payload":"{\"stream\":\"btcusdt@depth@100ms\",\"data\":{\"e\":\"depthUpdate\",\"E\":1704067200602,\"U\":601,\"u\":601,\"b\":[[\"50000.00\",\"1.00000000\"]],\"a\":[]}}"}
{"local_receipt_timestamp_ns":1704067200000006031,"raw_payload":"{\"stream\":\"btcusdt@depth@100ms\",\"data\":{\"e\":\"depthUpdate\",\"E\":1704067200603,\"U\":602,\"u\":602,\"b\":[],\"a\":[[\"50001.00\",\"1.00000000\"]]}}"}
{"local_receipt_timestamp_ns":1704067200000006041,"raw_payload":"{\"stream\":\"btcusdt@depth@100ms\",\"data\":{\"e\":\"depthUpdate\",\"E\":1704067200604,\"U\":603,\"u\":603,\"b\":[[\"50000.00\",\"1.00000000\"]],\"a\":[]}}"}
{"local_receipt_timestamp_ns":1704067200000006051,"raw_payload":"{\"stream\":\"btcusdt@depth@100ms\",\"data\":{\"e\":\"depthUpdate\",\"E\":1704067200605,\"U\":604,\"u\":604,\"b\":[],\"a\":[[\"50001.00\",\"1.00000000\"]]}}"}
{"local_receipt_timestamp_ns":1704067200000006061,"raw_payload":"{\"stream\":\"btcusdt@depth@100ms\",\"data\":{\"e\":\"depthUpdate\",\"E\":1704067200606,\"U\":605,\"u\":605,\"b\":[[\"50000.00\",\"1.00000000\"]],\"a\":[]}}"}
{"local_receipt_timestamp_ns":1704067200000006071,"raw_payload":"{\"stream\":\"btcusdt@depth@100ms\",\"data\":{\"e\":\"depthUpdate\",\"E\":1704067200607,\"U\":606,\"u\":606,\"b\":[],\"a\":[[\"50001.00\",\"1.00000000\"]]}}"}
{"local_receipt_timestamp_ns":1704067200000006081,"raw_payload":"{\"stream\":\"btcusdt@depth@100ms\",\"data\":{\"e\":\"depthUpdate\",\"E\":1704067200608,\"U\":607,\"u\":607,\"b\":[[\"50000.00\",\"1.00000000\"]],\"a\":[]}}"}
{"local_receipt_timestamp_ns":1704067200000006091,"raw_payload":"{\"stream\":\"btcusdt@depth@100ms\",\"data\":{\"e\":\"depthUpdate\",\"E\":1704067200609,\"U\":608,\"u\":608,\"b\":[],\"a\":[[\"50001.00\",\"1.00000000\"]]}}"}
{"local_receipt_timestamp_ns":1704067200000006101,"raw_payload":"{\"stream\":\"btcusdt@depth@100ms\",\"data\":{\"e\":\"depthUpdate\",\"E\":1704067200610,\"U\":609,\"u\":609,\"b\":[[\"50000.00\",\"1.00000000\"]],\"a\":[]}}"}
{"local_receipt_timestamp_ns":1704067200000006111,"raw_payload":"{\"stream\":\"btcusdt@depth@100ms\",\"data\":{\"e\":\"depthUpdate\",\"E\":1704067200611,\"U\":610,\"u\":610,\"b\":[],\"a\":[[\"50001.00\",\"1.00000000\"]]}}"}
{"local_receipt_timestamp_ns":1704067200000006121,"raw_payload":"{\"stream\":\"btcusdt@depth@100ms\",\"data\":{\"e\":\"depthUpdate\",\"E\":1704067200612,\"U\":611,\"u\":611,\"b\":[[\"50000.00\",\"1.00000000\"]],\"a\":[]}}"}
{"local_receipt_timestamp_ns":1704067200000006131,"raw_payload":"{\"stream\":\"btcusdt@depth@100ms\",\"data\":{\"e\":\"depthUpdate\",\"E\":1704067200613,\"U\":612,\"u\":612,\"b\":[],\"a\":[[\"50001.00\",\"1.00000000\"]]}}"}
{"local_receipt_timestamp_ns":1704067200000006141,"raw_payload":"{\"stream\":\"btcusdt@depth@100ms\",\"data\":{\"e\":\"depthUpdate\",\"E\":1704067200614,\"U\":613,\"u\":613,\"b\":[[\"50000.00\",\"1.00000000\"]],\"a\":[]}}"}
{"local_receipt_timestamp_ns":1704067200000006151,"raw_payload":"{\"stream\":\"btcusdt@depth@100ms\",\"data\":{\"e\":\"depthUpdate\",\"E\":1704067200615,\"U\":614,\"u\":614,\"b\":[],\"a\":[[\"50001.00\",\"1.00000000\"]]}}"}
{"local_receipt_timestamp_ns":1704067200000006161,"raw_payload":"{\"stream\":\"btcusdt@depth@100ms\",\"data\":{\"e\":\"depthUpdate\",\"E\":1704067200616,\"U\":615,\"u\":615,\"b\":[[\"50000.00\",\"1.00000000\"]],\"a\":[]}}"}
{"local_receipt_timestamp_ns":1704067200000006171,"raw_payload":"{\"stream\":\"btcusdt@depth@100ms\",\"data\":{\"e\":\"depthUpdate\",\"E\":1704067200617,\"U\":616,\"u\":616,\"b\":[],\"a\":[[\"50001.00\",\"1.00000000\"]]}}"}
{"local_receipt_timestamp_ns":1704067200000006181,"raw_payload":"{\"stream\":\"btcusdt@depth@100ms\",\"data\":{\"e\":\"depthUpdate\",\"E\":1704067200618,\"U\":617,\"u\":617,\"b\":[[\"50000.00\",\"1.00000000\"]],\"a\":[]}}"}
{"local_receipt_timestamp_ns":1704067200000006191,"raw_payload":"{\"stream\":\"btcusdt@depth@100ms\",\"data\":{\"e\":\"depthUpdate\",\"E\":1704067200619,\"U\":618,\"u\":618,\"b\":[],\"a\":[[\"50001.00\",\"1.00000000\"]]}}"}
{"local_receipt_timestamp_ns":1704067200000006201,"raw_payload":"{\"stream\":\"btcusdt@depth@100ms\",\"data\":{\"e\":\"depthUpdate\",\"E\":1704067200620,\"U\":619,\"u\":619,\"b\":[[\"50000.00\",\"1.00000000\"]],\"a\":[]}}"}
{"local_receipt_timestamp_ns":1704067200000006211,"raw_payload":"{\"stream\":\"btcusdt@depth@100ms\",\"data\":{\"e\":\"depthUpdate\",\"E\":1704067200621,\"U\":620,\"u\":620,\"b\":[],\"a\":[[\"50001.00\",\"1.00000000\"]]}}"}
{"local_receipt_timestamp_ns":1704067200000006221,"raw_payload":"{\"stream\":\"btcusdt@depth@100ms\",\"data\":{\"e\":\"depthUpdate\",\"E\":1704067200622,\"U\":621,\"u\":621,\"b\":[[\"50000.00\",\"1.00000000\"]],\"a\":[]}}"}
{"local_receipt_timestamp_ns":1704067200000006231,"raw_payload":"{\"stream\":\"btcusdt@depth@100ms\",\"data\":{\"e\":\"depthUpdate\",\"E\":1704067200623,\"U\":622,\"u\":622,\"b\":[],\"a\":[[\"50001.00\",\"1.00000000\"]]}}"}
{"local_receipt_timestamp_ns":1704067200000006241,"raw_payload":"{\"stream\":\"btcusdt@depth@100ms\",\"data\":{\"e\":\"depthUpdate\",\"E\":1704067200624,\"U\":623,\"u\":623,\"b\":[[\"50000.00\",\"1.00000000\"]],\"a\":[]}}"}
{"local_receipt_timestamp_ns":1704067200000006251,"raw_payload":"{\"stream\":\"btcusdt@depth@100ms\",\"data\":{\"e\":\"depthUpdate\",\"E\":1704067200625,\"U\":624,\"u\":624,\"b\":[],\"a\":[[\"50001.00\",\"1.00000000\"]]}}"}
{"local_receipt_timestamp_ns":1704067200000006261,"raw_payload":"{\"stream\":\"btcusdt@depth@100ms\",\"data\":{\"e\":\"depthUpdate\",\"E\":1704067200626,\"U\":625,\"u\":625,\"b\":[[\"50000.00\",\"1.00000000\"]],\"a\":[]}}"}
{"local_receipt_timestamp_ns":1704067200000006271,"raw_payload":"{\"stream\":\"btcusdt@depth@100ms\",\"data\":{\"e\":\"depthUpdate\",\"E\":1704067200627,\"U\":626,\"u\":626,\"b\":[],\"a\":[[\"50001.00\",\"1.00000000\"]]}}"}
{"local_receipt_timestamp_ns":1704067200000006281,"raw_payload":"{\"stream\":\"btcusdt@depth@100ms\",\"data\":{\"e\":\"depthUpdate\",\"E\":1704067200628,\"U\":627,\"u\":627,\"b\":[[\"50000.00\",\"1.00000000\"]],\"a\":[]}}"}
{"local_receipt_timestamp_ns":1704067200000006291,"raw_payload":"{\"stream\":\"btcusdt@depth@100ms\",\"data\":{\"e\":\"depthUpdate\",\"E\":1704067200629,\"U\":628,\"u\":628,\"b\":[],\"a\":[[\"50001.00\",\"1.00000000\"]]}}"}
{"local_receipt_timestamp_ns":1704067200000006301,"raw_payload":"{\"stream\":\"btcusdt@depth@100ms\",\"data\":{\"e\":\"depthUpdate\",\"E\":1704067200630,\"U\":629,\"u\":629,\"b\":[[\"50000.00\",\"1.00000000\"]],\"a\":[]}}"}
{"local_receipt_timestamp_ns":1704067200000006311,"raw_payload":"{\"stream\":\"btcusdt@depth@100ms\",\"data\":{\"e\":\"depthUpdate\",\"E\":1704067200631,\"U\":630,\"u\":630,\"b\":[],\"a\":[[\"50001.00\",\"1.00000000\"]]}}"}
{"local_receipt_timestamp_ns":1704067200000006321,"raw_payload":"{\"stream\":\"btcusdt@depth@100ms\",\"data\":{\"e\":\"depthUpdate\",\"E\":1704067200632,\"U\":631,\"u\":631,\"b\":[[\"50000.00\",\"1.00000000\"]],\"a\":[]}}"}
{"local_receipt_timestamp_ns":1704067200000006331,"raw_payload":"{\"stream\":\"btcusdt@depth@100ms\",\"data\":{\"e\":\"depthUpdate\",\"E\":1704067200633,\"U\":632,\"u\":632,\"b\":[],\"a\":[[\"50001.00\",\"1.00000000\"]]}}"}
{"local_receipt_timestamp_ns":1704067200000006341,"raw_payload":"{\"stream\":\"btcusdt@depth@100ms\",\"data\":{\"e\":\"depthUpdate\",\"E\":1704067200634,\"U\":633,\"u\":633,\"b\":[[\"50000.00\",\"1.00000000\"]],\"a\":[]}}"}
{"local_receipt_timestamp_ns":1704067200000006351,"raw_payload":"{\"stream\":\"btcusdt@depth@100ms\",\"data\":{\"e\":\"depthUpdate\",\"E\":1704067200635,\"U\":634,\"u\":634,\"b\":[],\"a\":[[\"50001.00\",\"1.00000000\"]]}}"}
{"local_receipt_timestamp_ns":1704067200000006361,"raw_payload":"{\"stream\":\"btcusdt@depth@100ms\",\"data\":{\"e\":\"depthUpdate\",\"E\":1704067200636,\"U\":635,\"u\":635,\"b\":[[\"50000.00\",\"1.00000000\"]],\"a\":[]}}"}
{"local_receipt_timestamp_ns":1704067200000006371,"raw_payload":"{\"stream\":\"btcusdt@depth@100ms\",\"data\":{\"e\":\"depthUpdate\",\"E\":1704067200637,\"U\":636,\"u\":636,\"b\":[],\"a\":[[\"50001.00\",\"1.00000000\"]]}}"}
{"local_receipt_timestamp_ns":1704067200000006381,"raw_payload":"{\"stream\":\"btcusdt@depth@100ms\",\"data\":{\"e\":\"depthUpdate\",\"E\":1704067200638,\"U\":637,\"u\":637,\"b\":[[\"50000.00\",\"1.00000000\"]],\"a\":[]}}"}
{"local_receipt_timestamp_ns":1704067200000006391,"raw_payload":"{\"stream\":\"btcusdt@depth@100ms\",\"data\":{\"e\":\"depthUpdate\",\"E\":1704067200639,\"U\":638,\"u\":638,\"b\":[],\"a\":[[\"50001.00\",\"1.00000000\"]]}}"}
{"local_receipt_timestamp_ns":1704067200000006401,"raw_payload":"{\"stream\":\"btcusdt@depth@100ms\",\"data\":{\"e\":\"depthUpdate\",\"E\":1704067200640,\"U\":639,\"u\":639,\"b\":[[\"50000.00\",\"1.00000000\"]],\"a\":[]}}"}
{"local_receipt_timestamp_ns":1704067200000006411,"raw_payload":"{\"stream\":\"btcusdt@depth@100ms\",\"data\":{\"e\":\"depthUpdate\",\"E\":1704067200641,\"U\":640,\"u\":640,\"b\":[],\"a\":[[\"50001.00\",\"1.00000000\"]]}}"}
{"local_receipt_timestamp_ns":1704067200000006421,"raw_payload":"{\"stream\":\"btcusdt@depth@100ms\",\"data\":{\"e\":\"depthUpdate\",\"E\":1704067200642,\"U\":641,\"u\":641,\"b\":[[\"50000.00\",\"1.00000000\"]],\"a\":[]}}"}
{"local_receipt_timestamp_ns":1704067200000006431,"raw_payload":"{\"stream\":\"btcusdt@depth@100ms\",\"data\":{\"e\":\"depthUpdate\",\"E\":1704067200643,\"U\":642,\"u\":642,\"b\":[],\"a\":[[\"50001.00\",\"1.00000000\"]]}}"}
{"local_receipt_timestamp_ns":1704067200000006441,"raw_payload":"{\"stream\":\"btcusdt@depth@100ms\",\"data\":{\"e\":\"depthUpdate\",\"E\":1704067200644,\"U\":643,\"u\":643,\"b\":[[\"50000.00\",\"1.00000000\"]],\"a\":[]}}"}
{"local_receipt_timestamp_ns":1704067200000006451,"raw_payload":"{\"stream\":\"btcusdt@depth@100ms\",\"data\":{\"e\":\"depthUpdate\",\"E\":1704067200645,\"U\":644,\"u\":644,\"b\":[],\"a\":[[\"50001.00\",\"1.00000000\"]]}}"}
{"local_receipt_timestamp_ns":1704067200000006461,"raw_payload":"{\"stream\":\"btcusdt@depth@100ms\",\"data\":{\"e\":\"depthUpdate\",\"E\":1704067200646,\"U\":645,\"u\":645,\"b\":[[\"50000.00\",\"1.00000000\"]],\"a\":[]}}"}
{"local_receipt_timestamp_ns":1704067200000006471,"raw_payload":"{\"stream\":\"btcusdt@depth@100ms\",\"data\":{\"e\":\"depthUpdate\",\"E\":1704067200647,\"U\":646,\"u\":646,\"b\":[],\"a\":[[\"50001.00\",\"1.00000000\"]]}}"}
{"local_receipt_timestamp_ns":1704067200000006481,"raw_payload":"{\"stream\":\"btcusdt@depth@100ms\",\"data\":{\"e\":\"depthUpdate\",\"E\":1704067200648,\"U\":647,\"u\":647,\"b\":[[\"50000.00\",\"1.00000000\"]],\"a\":[]}}"}
{"local_receipt_timestamp_ns":1704067200000006491,"raw_payload":"{\"stream\":\"btcusdt@depth@100ms\",\"data\":{\"e\":\"depthUpdate\",\"E\":1704067200649,\"U\":648,\"u\":648,\"b\":[],\"a\":[[\"50001.00\",\"1.00000000\"]]}}"}
{"local_receipt_timestamp_ns":1704067200000006501,"raw_payload":"{\"stream\":\"btcusdt@depth@100ms\",\"data\":{\"e\":\"depthUpdate\",\"E\":1704067200650,\"U\":649,\"u\":649,\"b\":[[\"50000.00\",\"1.00000000\"]],\"a\":[]}}"}
{"local_receipt_timestamp_ns":1704067200000006511,"raw_payload":"{\"stream\":\"btcusdt@depth@100ms\",\"data\":{\"e\":\"depthUpdate\",\"E\":1704067200651,\"U\":650,\"u\":650,\"b\":[],\"a\":[[\"50001.00\",\"1.00000000\"]]}}"}
{"local_receipt_timestamp_ns":1704067200000006521,"raw_payload":"{\"stream\":\"btcusdt@depth@100ms\",\"data\":{\"e\":\"depthUpdate\",\"E\":1704067200652,\"U\":651,\"u\":651,\"b\":[[\"50000.00\",\"1.00000000\"]],\"a\":[]}}"}
{"local_receipt_timestamp_ns":1704067200000006531,"raw_payload":"{\"stream\":\"btcusdt@depth@100ms\",\"data\":{\"e\":\"depthUpdate\",\"E\":1704067200653,\"U\":652,\"u\":652,\"b\":[],\"a\":[[\"50001.00\",\"1.00000000\"]]}}"}
{"local_receipt_timestamp_ns":1704067200000006541,"raw_payload":"{\"stream\":\"btcusdt@depth@100ms\",\"data\":{\"e\":\"depthUpdate\",\"E\":1704067200654,\"U\":653,\"u\":653,\"b\":[[\"50000.00\",\"1.00000000\"]],\"a\":[]}}"}
{"local_receipt_timestamp_ns":1704067200000006551,"raw_payload":"{\"stream\":\"btcusdt@depth@100ms\",\"data\":{\"e\":\"depthUpdate\",\"E\":1704067200655,\"U\":654,\"u\":654,\"b\":[],\"a\":[[\"50001.00\",\"1.00000000\"]]}}"}
{"local_receipt_timestamp_ns":1704067200000006561,"raw_payload":"{\"stream\":\"btcusdt@depth@100ms\",\"data\":{\"e\":\"depthUpdate\",\"E\":1704067200656,\"U\":655,\"u\":655,\"b\":[[\"50000.00\",\"1.00000000\"]],\"a\":[]}}"}
{"local_receipt_timestamp_ns":1704067200000006571,"raw_payload":"{\"stream\":\"btcusdt@depth@100ms\",\"data\":{\"e\":\"depthUpdate\",\"E\":1704067200657,\"U\":656,\"u\":656,\"b\":[],\"a\":[[\"50001.00\",\"1.00000000\"]]}}"}
{"local_receipt_timestamp_ns":1704067200000006581,"raw_payload":"{\"stream\":\"btcusdt@depth@100ms\",\"data\":{\"e\":\"depthUpdate\",\"E\":1704067200658,\"U\":657,\"u\":657,\"b\":[[\"50000.00\",\"1.00000000\"]],\"a\":[]}}"}
{"local_receipt_timestamp_ns":1704067200000006591,"raw_payload":"{\"stream\":\"btcusdt@depth@100ms\",\"data\":{\"e\":\"depthUpdate\",\"E\":1704067200659,\"U\":658,\"u\":658,\"b\":[],\"a\":[[\"50001.00\",\"1.00000000\"]]}}"}
{"local_receipt_timestamp_ns":1704067200000006601,"raw_payload":"{\"stream\":\"btcusdt@depth@100ms\",\"data\":{\"e\":\"depthUpdate\",\"E\":1704067200660,\"U\":659,\"u\":659,\"b\":[[\"50000.00\",\"1.00000000\"]],\"a\":[]}}"}
{"local_receipt_timestamp_ns":1704067200000006611,"raw_payload":"{\"stream\":\"btcusdt@depth@100ms\",\"data\":{\"e\":\"depthUpdate\",\"E\":1704067200661,\"U\":660,\"u\":660,\"b\":[],\"a\":[[\"50001.00\",\"1.00000000\"]]}}"}
{"local_receipt_timestamp_ns":1704067200000006621,"raw_payload":"{\"stream\":\"btcusdt@depth@100ms\",\"data\":{\"e\":\"depthUpdate\",\"E\":1704067200662,\"U\":661,\"u\":661,\"b\":[[\"50000.00\",\"1.00000000\"]],\"a\":[]}}"}
{"local_receipt_timestamp_ns":1704067200000006631,"raw_payload":"{\"stream\":\"btcusdt@depth@100ms\",\"data\":{\"e\":\"depthUpdate\",\"E\":1704067200663,\"U\":662,\"u\":662,\"b\":[],\"a\":[[\"50001.00\",\"1.00000000\"]]}}"}
{"local_receipt_timestamp_ns":1704067200000006641,"raw_payload":"{\"stream\":\"btcusdt@depth@100ms\",\"data\":{\"e\":\"depthUpdate\",\"E\":1704067200664,\"U\":663,\"u\":663,\"b\":[[\"50000.00\",\"1.00000000\"]],\"a\":[]}}"}
{"local_receipt_timestamp_ns":1704067200000006651,"raw_payload":"{\"stream\":\"btcusdt@depth@100ms\",\"data\":{\"e\":\"depthUpdate\",\"E\":1704067200665,\"U\":664,\"u\":664,\"b\":[],\"a\":[[\"50001.00\",\"1.00000000\"]]}}"}
{"local_receipt_timestamp_ns":1704067200000006661,"raw_payload":"{\"stream\":\"btcusdt@depth@100ms\",\"data\":{\"e\":\"depthUpdate\",\"E\":1704067200666,\"U\":665,\"u\":665,\"b\":[[\"50000.00\",\"1.00000000\"]],\"a\":[]}}"}
{"local_receipt_timestamp_ns":1704067200000006671,"raw_payload":"{\"stream\":\"btcusdt@depth@100ms\",\"data\":{\"e\":\"depthUpdate\",\"E\":1704067200667,\"U\":666,\"u\":666,\"b\":[],\"a\":[[\"50001.00\",\"1.00000000\"]]}}"}
{"local_receipt_timestamp_ns":1704067200000006681,"raw_payload":"{\"stream\":\"btcusdt@depth@100ms\",\"data\":{\"e\":\"depthUpdate\",\"E\":1704067200668,\"U\":667,\"u\":667,\"b\":[[\"50000.00\",\"1.00000000\"]],\"a\":[]}}"}
{"local_receipt_timestamp_ns":1704067200000006691,"raw_payload":"{\"stream\":\"btcusdt@depth@100ms\",\"data\":{\"e\":\"depthUpdate\",\"E\":1704067200669,\"U\":668,\"u\":668,\"b\":[],\"a\":[[\"50001.00\",\"1.00000000\"]]}}"}
{"local_receipt_timestamp_ns":1704067200000006701,"raw_payload":"{\"stream\":\"btcusdt@depth@100ms\",\"data\":{\"e\":\"depthUpdate\",\"E\":1704067200670,\"U\":669,\"u\":669,\"b\":[[\"50000.00\",\"1.00000000\"]],\"a\":[]}}"}
{"local_receipt_timestamp_ns":1704067200000006711,"raw_payload":"{\"stream\":\"btcusdt@depth@100ms\",\"data\":{\"e\":\"depthUpdate\",\"E\":1704067200671,\"U\":670,\"u\":670,\"b\":[],\"a\":[[\"50001.00\",\"1.00000000\"]]}}"}
{"local_receipt_timestamp_ns":1704067200000006721,"raw_payload":"{\"stream\":\"btcusdt@depth@100ms\",\"data\":{\"e\":\"depthUpdate\",\"E\":1704067200672,\"U\":671,\"u\":671,\"b\":[[\"50000.00\",\"1.00000000\"]],\"a\":[]}}"}
{"local_receipt_timestamp_ns":1704067200000006731,"raw_payload":"{\"stream\":\"btcusdt@depth@100ms\",\"data\":{\"e\":\"depthUpdate\",\"E\":1704067200673,\"U\":672,\"u\":672,\"b\":[],\"a\":[[\"50001.00\",\"1.00000000\"]]}}"}
{"local_receipt_timestamp_ns":1704067200000006741,"raw_payload":"{\"stream\":\"btcusdt@depth@100ms\",\"data\":{\"e\":\"depthUpdate\",\"E\":1704067200674,\"U\":673,\"u\":673,\"b\":[[\"50000.00\",\"1.00000000\"]],\"a\":[]}}"}
{"local_receipt_timestamp_ns":1704067200000006751,"raw_payload":"{\"stream\":\"btcusdt@depth@100ms\",\"data\":{\"e\":\"depthUpdate\",\"E\":1704067200675,\"U\":674,\"u\":674,\"b\":[],\"a\":[[\"50001.00\",\"1.00000000\"]]}}"}
{"local_receipt_timestamp_ns":1704067200000006761,"raw_payload":"{\"stream\":\"btcusdt@depth@100ms\",\"data\":{\"e\":\"depthUpdate\",\"E\":1704067200676,\"U\":675,\"u\":675,\"b\":[[\"50000.00\",\"1.00000000\"]],\"a\":[]}}"}
{"local_receipt_timestamp_ns":1704067200000006771,"raw_payload":"{\"stream\":\"btcusdt@depth@100ms\",\"data\":{\"e\":\"depthUpdate\",\"E\":1704067200677,\"U\":676,\"u\":676,\"b\":[],\"a\":[[\"50001.00\",\"1.00000000\"]]}}"}
{"local_receipt_timestamp_ns":1704067200000006781,"raw_payload":"{\"stream\":\"btcusdt@depth@100ms\",\"data\":{\"e\":\"depthUpdate\",\"E\":1704067200678,\"U\":677,\"u\":677,\"b\":[[\"50000.00\",\"1.00000000\"]],\"a\":[]}}"}
{"local_receipt_timestamp_ns":1704067200000006791,"raw_payload":"{\"stream\":\"btcusdt@depth@100ms\",\"data\":{\"e\":\"depthUpdate\",\"E\":1704067200679,\"U\":678,\"u\":678,\"b\":[],\"a\":[[\"50001.00\",\"1.00000000\"]]}}"}
{"local_receipt_timestamp_ns":1704067200000006801,"raw_payload":"{\"stream\":\"btcusdt@depth@100ms\",\"data\":{\"e\":\"depthUpdate\",\"E\":1704067200680,\"U\":679,\"u\":679,\"b\":[[\"50000.00\",\"1.00000000\"]],\"a\":[]}}"}
{"local_receipt_timestamp_ns":1704067200000006811,"raw_payload":"{\"stream\":\"btcusdt@depth@100ms\",\"data\":{\"e\":\"depthUpdate\",\"E\":1704067200681,\"U\":680,\"u\":680,\"b\":[],\"a\":[[\"50001.00\",\"1.00000000\"]]}}"}
{"local_receipt_timestamp_ns":1704067200000006821,"raw_payload":"{\"stream\":\"btcusdt@depth@100ms\",\"data\":{\"e\":\"depthUpdate\",\"E\":1704067200682,\"U\":681,\"u\":681,\"b\":[[\"50000.00\",\"1.00000000\"]],\"a\":[]}}"}
{"local_receipt_timestamp_ns":1704067200000006831,"raw_payload":"{\"stream\":\"btcusdt@depth@100ms\",\"data\":{\"e\":\"depthUpdate\",\"E\":1704067200683,\"U\":682,\"u\":682,\"b\":[],\"a\":[[\"50001.00\",\"1.00000000\"]]}}"}
{"local_receipt_timestamp_ns":1704067200000006841,"raw_payload":"{\"stream\":\"btcusdt@depth@100ms\",\"data\":{\"e\":\"depthUpdate\",\"E\":1704067200684,\"U\":683,\"u\":683,\"b\":[[\"50000.00\",\"1.00000000\"]],\"a\":[]}}"}
{"local_receipt_timestamp_ns":1704067200000006851,"raw_payload":"{\"stream\":\"btcusdt@depth@100ms\",\"data\":{\"e\":\"depthUpdate\",\"E\":1704067200685,\"U\":684,\"u\":684,\"b\":[],\"a\":[[\"50001.00\",\"1.00000000\"]]}}"}
{"local_receipt_timestamp_ns":1704067200000006861,"raw_payload":"{\"stream\":\"btcusdt@depth@100ms\",\"data\":{\"e\":\"depthUpdate\",\"E\":1704067200686,\"U\":685,\"u\":685,\"b\":[[\"50000.00\",\"1.00000000\"]],\"a\":[]}}"}
{"local_receipt_timestamp_ns":1704067200000006871,"raw_payload":"{\"stream\":\"btcusdt@depth@100ms\",\"data\":{\"e\":\"depthUpdate\",\"E\":1704067200687,\"U\":686,\"u\":686,\"b\":[],\"a\":[[\"50001.00\",\"1.00000000\"]]}}"}
{"local_receipt_timestamp_ns":1704067200000006881,"raw_payload":"{\"stream\":\"btcusdt@depth@100ms\",\"data\":{\"e\":\"depthUpdate\",\"E\":1704067200688,\"U\":687,\"u\":687,\"b\":[[\"50000.00\",\"1.00000000\"]],\"a\":[]}}"}
{"local_receipt_timestamp_ns":1704067200000006891,"raw_payload":"{\"stream\":\"btcusdt@depth@100ms\",\"data\":{\"e\":\"depthUpdate\",\"E\":1704067200689,\"U\":688,\"u\":688,\"b\":[],\"a\":[[\"50001.00\",\"1.00000000\"]]}}"}
{"local_receipt_timestamp_ns":1704067200000006901,"raw_payload":"{\"stream\":\"btcusdt@depth@100ms\",\"data\":{\"e\":\"depthUpdate\",\"E\":1704067200690,\"U\":689,\"u\":689,\"b\":[[\"50000.00\",\"1.00000000\"]],\"a\":[]}}"}
{"local_receipt_timestamp_ns":1704067200000006911,"raw_payload":"{\"stream\":\"btcusdt@depth@100ms\",\"data\":{\"e\":\"depthUpdate\",\"E\":1704067200691,\"U\":690,\"u\":690,\"b\":[],\"a\":[[\"50001.00\",\"1.00000000\"]]}}"}
{"local_receipt_timestamp_ns":1704067200000006921,"raw_payload":"{\"stream\":\"btcusdt@depth@100ms\",\"data\":{\"e\":\"depthUpdate\",\"E\":1704067200692,\"U\":691,\"u\":691,\"b\":[[\"50000.00\",\"1.00000000\"]],\"a\":[]}}"}
{"local_receipt_timestamp_ns":1704067200000006931,"raw_payload":"{\"stream\":\"btcusdt@depth@100ms\",\"data\":{\"e\":\"depthUpdate\",\"E\":1704067200693,\"U\":692,\"u\":692,\"b\":[],\"a\":[[\"50001.00\",\"1.00000000\"]]}}"}
{"local_receipt_timestamp_ns":1704067200000006941,"raw_payload":"{\"stream\":\"btcusdt@depth@100ms\",\"data\":{\"e\":\"depthUpdate\",\"E\":1704067200694,\"U\":693,\"u\":693,\"b\":[[\"50000.00\",\"1.00000000\"]],\"a\":[]}}"}
{"local_receipt_timestamp_ns":1704067200000006951,"raw_payload":"{\"stream\":\"btcusdt@depth@100ms\",\"data\":{\"e\":\"depthUpdate\",\"E\":1704067200695,\"U\":694,\"u\":694,\"b\":[],\"a\":[[\"50001.00\",\"1.00000000\"]]}}"}
{"local_receipt_timestamp_ns":1704067200000006961,"raw_payload":"{\"stream\":\"btcusdt@depth@100ms\",\"data\":{\"e\":\"depthUpdate\",\"E\":1704067200696,\"U\":695,\"u\":695,\"b\":[[\"50000.00\",\"1.00000000\"]],\"a\":[]}}"}
{"local_receipt_timestamp_ns":1704067200000006971,"raw_payload":"{\"stream\":\"btcusdt@depth@100ms\",\"data\":{\"e\":\"depthUpdate\",\"E\":1704067200697,\"U\":696,\"u\":696,\"b\":[],\"a\":[[\"50001.00\",\"1.00000000\"]]}}"}
{"local_receipt_timestamp_ns":1704067200000006981,"raw_payload":"{\"stream\":\"btcusdt@depth@100ms\",\"data\":{\"e\":\"depthUpdate\",\"E\":1704067200698,\"U\":697,\"u\":697,\"b\":[[\"50000.00\",\"1.00000000\"]],\"a\":[]}}"}
{"local_receipt_timestamp_ns":1704067200000006991,"raw_payload":"{\"stream\":\"btcusdt@depth@100ms\",\"data\":{\"e\":\"depthUpdate\",\"E\":1704067200699,\"U\":698,\"u\":698,\"b\":[],\"a\":[[\"50001.00\",\"1.00000000\"]]}}"}
{"local_receipt_timestamp_ns":1704067200000007001,"raw_payload":"{\"stream\":\"btcusdt@depth@100ms\",\"data\":{\"e\":\"depthUpdate\",\"E\":1704067200700,\"U\":699,\"u\":699,\"b\":[[\"50000.00\",\"1.00000000\"]],\"a\":[]}}"}
{"local_receipt_timestamp_ns":1704067200000007011,"raw_payload":"{\"stream\":\"btcusdt@depth@100ms\",\"data\":{\"e\":\"depthUpdate\",\"E\":1704067200701,\"U\":700,\"u\":700,\"b\":[],\"a\":[[\"50001.00\",\"1.00000000\"]]}}"}
{"local_receipt_timestamp_ns":1704067200000007021,"raw_payload":"{\"stream\":\"btcusdt@depth@100ms\",\"data\":{\"e\":\"depthUpdate\",\"E\":1704067200702,\"U\":701,\"u\":701,\"b\":[[\"50000.00\",\"1.00000000\"]],\"a\":[]}}"}
{"local_receipt_timestamp_ns":1704067200000007031,"raw_payload":"{\"stream\":\"btcusdt@depth@100ms\",\"data\":{\"e\":\"depthUpdate\",\"E\":1704067200703,\"U\":702,\"u\":702,\"b\":[],\"a\":[[\"50001.00\",\"1.00000000\"]]}}"}
{"local_receipt_timestamp_ns":1704067200000007041,"raw_payload":"{\"stream\":\"btcusdt@depth@100ms\",\"data\":{\"e\":\"depthUpdate\",\"E\":1704067200704,\"U\":703,\"u\":703,\"b\":[[\"50000.00\",\"1.00000000\"]],\"a\":[]}}"}
{"local_receipt_timestamp_ns":1704067200000007051,"raw_payload":"{\"stream\":\"btcusdt@depth@100ms\",\"data\":{\"e\":\"depthUpdate\",\"E\":1704067200705,\"U\":704,\"u\":704,\"b\":[],\"a\":[[\"50001.00\",\"1.00000000\"]]}}"}
{"local_receipt_timestamp_ns":1704067200000007061,"raw_payload":"{\"stream\":\"btcusdt@depth@100ms\",\"data\":{\"e\":\"depthUpdate\",\"E\":1704067200706,\"U\":705,\"u\":705,\"b\":[[\"50000.00\",\"1.00000000\"]],\"a\":[]}}"}
{"local_receipt_timestamp_ns":1704067200000007071,"raw_payload":"{\"stream\":\"btcusdt@depth@100ms\",\"data\":{\"e\":\"depthUpdate\",\"E\":1704067200707,\"U\":706,\"u\":706,\"b\":[],\"a\":[[\"50001.00\",\"1.00000000\"]]}}"}
{"local_receipt_timestamp_ns":1704067200000007081,"raw_payload":"{\"stream\":\"btcusdt@depth@100ms\",\"data\":{\"e\":\"depthUpdate\",\"E\":1704067200708,\"U\":707,\"u\":707,\"b\":[[\"50000.00\",\"1.00000000\"]],\"a\":[]}}"}
{"local_receipt_timestamp_ns":1704067200000007091,"raw_payload":"{\"stream\":\"btcusdt@depth@100ms\",\"data\":{\"e\":\"depthUpdate\",\"E\":1704067200709,\"U\":708,\"u\":708,\"b\":[],\"a\":[[\"50001.00\",\"1.00000000\"]]}}"}
{"local_receipt_timestamp_ns":1704067200000007101,"raw_payload":"{\"stream\":\"btcusdt@depth@100ms\",\"data\":{\"e\":\"depthUpdate\",\"E\":1704067200710,\"U\":709,\"u\":709,\"b\":[[\"50000.00\",\"1.00000000\"]],\"a\":[]}}"}
{"local_receipt_timestamp_ns":1704067200000007111,"raw_payload":"{\"stream\":\"btcusdt@depth@100ms\",\"data\":{\"e\":\"depthUpdate\",\"E\":1704067200711,\"U\":710,\"u\":710,\"b\":[],\"a\":[[\"50001.00\",\"1.00000000\"]]}}"}
{"local_receipt_timestamp_ns":1704067200000007121,"raw_payload":"{\"stream\":\"btcusdt@depth@100ms\",\"data\":{\"e\":\"depthUpdate\",\"E\":1704067200712,\"U\":711,\"u\":711,\"b\":[[\"50000.00\",\"1.00000000\"]],\"a\":[]}}"}
{"local_receipt_timestamp_ns":1704067200000007131,"raw_payload":"{\"stream\":\"btcusdt@depth@100ms\",\"data\":{\"e\":\"depthUpdate\",\"E\":1704067200713,\"U\":712,\"u\":712,\"b\":[],\"a\":[[\"50001.00\",\"1.00000000\"]]}}"}
{"local_receipt_timestamp_ns":1704067200000007141,"raw_payload":"{\"stream\":\"btcusdt@depth@100ms\",\"data\":{\"e\":\"depthUpdate\",\"E\":1704067200714,\"U\":713,\"u\":713,\"b\":[[\"50000.00\",\"1.00000000\"]],\"a\":[]}}"}
{"local_receipt_timestamp_ns":1704067200000007151,"raw_payload":"{\"stream\":\"btcusdt@depth@100ms\",\"data\":{\"e\":\"depthUpdate\",\"E\":1704067200715,\"U\":714,\"u\":714,\"b\":[],\"a\":[[\"50001.00\",\"1.00000000\"]]}}"}
{"local_receipt_timestamp_ns":1704067200000007161,"raw_payload":"{\"stream\":\"btcusdt@depth@100ms\",\"data\":{\"e\":\"depthUpdate\",\"E\":1704067200716,\"U\":715,\"u\":715,\"b\":[[\"50000.00\",\"1.00000000\"]],\"a\":[]}}"}
{"local_receipt_timestamp_ns":1704067200000007171,"raw_payload":"{\"stream\":\"btcusdt@depth@100ms\",\"data\":{\"e\":\"depthUpdate\",\"E\":1704067200717,\"U\":716,\"u\":716,\"b\":[],\"a\":[[\"50001.00\",\"1.00000000\"]]}}"}
{"local_receipt_timestamp_ns":1704067200000007181,"raw_payload":"{\"stream\":\"btcusdt@depth@100ms\",\"data\":{\"e\":\"depthUpdate\",\"E\":1704067200718,\"U\":717,\"u\":717,\"b\":[[\"50000.00\",\"1.00000000\"]],\"a\":[]}}"}
{"local_receipt_timestamp_ns":1704067200000007191,"raw_payload":"{\"stream\":\"btcusdt@depth@100ms\",\"data\":{\"e\":\"depthUpdate\",\"E\":1704067200719,\"U\":718,\"u\":718,\"b\":[],\"a\":[[\"50001.00\",\"1.00000000\"]]}}"}
{"local_receipt_timestamp_ns":1704067200000007201,"raw_payload":"{\"stream\":\"btcusdt@depth@100ms\",\"data\":{\"e\":\"depthUpdate\",\"E\":1704067200720,\"U\":719,\"u\":719,\"b\":[[\"50000.00\",\"1.00000000\"]],\"a\":[]}}"}
{"local_receipt_timestamp_ns":1704067200000007211,"raw_payload":"{\"stream\":\"btcusdt@depth@100ms\",\"data\":{\"e\":\"depthUpdate\",\"E\":1704067200721,\"U\":720,\"u\":720,\"b\":[],\"a\":[[\"50001.00\",\"1.00000000\"]]}}"}
{"local_receipt_timestamp_ns":1704067200000007221,"raw_payload":"{\"stream\":\"btcusdt@depth@100ms\",\"data\":{\"e\":\"depthUpdate\",\"E\":1704067200722,\"U\":721,\"u\":721,\"b\":[[\"50000.00\",\"1.00000000\"]],\"a\":[]}}"}
{"local_receipt_timestamp_ns":1704067200000007231,"raw_payload":"{\"stream\":\"btcusdt@depth@100ms\",\"data\":{\"e\":\"depthUpdate\",\"E\":1704067200723,\"U\":722,\"u\":722,\"b\":[],\"a\":[[\"50001.00\",\"1.00000000\"]]}}"}
{"local_receipt_timestamp_ns":1704067200000007241,"raw_payload":"{\"stream\":\"btcusdt@depth@100ms\",\"data\":{\"e\":\"depthUpdate\",\"E\":1704067200724,\"U\":723,\"u\":723,\"b\":[[\"50000.00\",\"1.00000000\"]],\"a\":[]}}"}
{"local_receipt_timestamp_ns":1704067200000007251,"raw_payload":"{\"stream\":\"btcusdt@depth@100ms\",\"data\":{\"e\":\"depthUpdate\",\"E\":1704067200725,\"U\":724,\"u\":724,\"b\":[],\"a\":[[\"50001.00\",\"1.00000000\"]]}}"}
{"local_receipt_timestamp_ns":1704067200000007261,"raw_payload":"{\"stream\":\"btcusdt@depth@100ms\",\"data\":{\"e\":\"depthUpdate\",\"E\":1704067200726,\"U\":725,\"u\":725,\"b\":[[\"50000.00\",\"1.00000000\"]],\"a\":[]}}"}
{"local_receipt_timestamp_ns":1704067200000007271,"raw_payload":"{\"stream\":\"btcusdt@depth@100ms\",\"data\":{\"e\":\"depthUpdate\",\"E\":1704067200727,\"U\":726,\"u\":726,\"b\":[],\"a\":[[\"50001.00\",\"1.00000000\"]]}}"}
{"local_receipt_timestamp_ns":1704067200000007281,"raw_payload":"{\"stream\":\"btcusdt@depth@100ms\",\"data\":{\"e\":\"depthUpdate\",\"E\":1704067200728,\"U\":727,\"u\":727,\"b\":[[\"50000.00\",\"1.00000000\"]],\"a\":[]}}"}
{"local_receipt_timestamp_ns":1704067200000007291,"raw_payload":"{\"stream\":\"btcusdt@depth@100ms\",\"data\":{\"e\":\"depthUpdate\",\"E\":1704067200729,\"U\":728,\"u\":728,\"b\":[],\"a\":[[\"50001.00\",\"1.00000000\"]]}}"}
{"local_receipt_timestamp_ns":1704067200000007301,"raw_payload":"{\"stream\":\"btcusdt@depth@100ms\",\"data\":{\"e\":\"depthUpdate\",\"E\":1704067200730,\"U\":729,\"u\":729,\"b\":[[\"50000.00\",\"1.00000000\"]],\"a\":[]}}"}
{"local_receipt_timestamp_ns":1704067200000007311,"raw_payload":"{\"stream\":\"btcusdt@depth@100ms\",\"data\":{\"e\":\"depthUpdate\",\"E\":1704067200731,\"U\":730,\"u\":730,\"b\":[],\"a\":[[\"50001.00\",\"1.00000000\"]]}}"}
{"local_receipt_timestamp_ns":1704067200000007321,"raw_payload":"{\"stream\":\"btcusdt@depth@100ms\",\"data\":{\"e\":\"depthUpdate\",\"E\":1704067200732,\"U\":731,\"u\":731,\"b\":[[\"50000.00\",\"1.00000000\"]],\"a\":[]}}"}
{"local_receipt_timestamp_ns":1704067200000007331,"raw_payload":"{\"stream\":\"btcusdt@depth@100ms\",\"data\":{\"e\":\"depthUpdate\",\"E\":1704067200733,\"U\":732,\"u\":732,\"b\":[],\"a\":[[\"50001.00\",\"1.00000000\"]]}}"}
{"local_receipt_timestamp_ns":1704067200000007341,"raw_payload":"{\"stream\":\"btcusdt@depth@100ms\",\"data\":{\"e\":\"depthUpdate\",\"E\":1704067200734,\"U\":733,\"u\":733,\"b\":[[\"50000.00\",\"1.00000000\"]],\"a\":[]}}"}
{"local_receipt_timestamp_ns":1704067200000007351,"raw_payload":"{\"stream\":\"btcusdt@depth@100ms\",\"data\":{\"e\":\"depthUpdate\",\"E\":1704067200735,\"U\":734,\"u\":734,\"b\":[],\"a\":[[\"50001.00\",\"1.00000000\"]]}}"}
{"local_receipt_timestamp_ns":1704067200000007361,"raw_payload":"{\"stream\":\"btcusdt@depth@100ms\",\"data\":{\"e\":\"depthUpdate\",\"E\":1704067200736,\"U\":735,\"u\":735,\"b\":[[\"50000.00\",\"1.00000000\"]],\"a\":[]}}"}
{"local_receipt_timestamp_ns":1704067200000007371,"raw_payload":"{\"stream\":\"btcusdt@depth@100ms\",\"data\":{\"e\":\"depthUpdate\",\"E\":1704067200737,\"U\":736,\"u\":736,\"b\":[],\"a\":[[\"50001.00\",\"1.00000000\"]]}}"}
{"local_receipt_timestamp_ns":1704067200000007381,"raw_payload":"{\"stream\":\"btcusdt@depth@100ms\",\"data\":{\"e\":\"depthUpdate\",\"E\":1704067200738,\"U\":737,\"u\":737,\"b\":[[\"50000.00\",\"1.00000000\"]],\"a\":[]}}"}
{"local_receipt_timestamp_ns":1704067200000007391,"raw_payload":"{\"stream\":\"btcusdt@depth@100ms\",\"data\":{\"e\":\"depthUpdate\",\"E\":1704067200739,\"U\":738,\"u\":738,\"b\":[],\"a\":[[\"50001.00\",\"1.00000000\"]]}}"}
{"local_receipt_timestamp_ns":1704067200000007401,"raw_payload":"{\"stream\":\"btcusdt@depth@100ms\",\"data\":{\"e\":\"depthUpdate\",\"E\":1704067200740,\"U\":739,\"u\":739,\"b\":[[\"50000.00\",\"1.00000000\"]],\"a\":[]}}"}
{"local_receipt_timestamp_ns":1704067200000007411,"raw_payload":"{\"stream\":\"btcusdt@depth@100ms\",\"data\":{\"e\":\"depthUpdate\",\"E\":1704067200741,\"U\":740,\"u\":740,\"b\":[],\"a\":[[\"50001.00\",\"1.00000000\"]]}}"}
{"local_receipt_timestamp_ns":1704067200000007421,"raw_payload":"{\"stream\":\"btcusdt@depth@100ms\",\"data\":{\"e\":\"depthUpdate\",\"E\":1704067200742,\"U\":741,\"u\":741,\"b\":[[\"50000.00\",\"1.00000000\"]],\"a\":[]}}"}
{"local_receipt_timestamp_ns":1704067200000007431,"raw_payload":"{\"stream\":\"btcusdt@depth@100ms\",\"data\":{\"e\":\"depthUpdate\",\"E\":1704067200743,\"U\":742,\"u\":742,\"b\":[],\"a\":[[\"50001.00\",\"1.00000000\"]]}}"}
{"local_receipt_timestamp_ns":1704067200000007441,"raw_payload":"{\"stream\":\"btcusdt@depth@100ms\",\"data\":{\"e\":\"depthUpdate\",\"E\":1704067200744,\"U\":743,\"u\":743,\"b\":[[\"50000.00\",\"1.00000000\"]],\"a\":[]}}"}
{"local_receipt_timestamp_ns":1704067200000007451,"raw_payload":"{\"stream\":\"btcusdt@depth@100ms\",\"data\":{\"e\":\"depthUpdate\",\"E\":1704067200745,\"U\":744,\"u\":744,\"b\":[],\"a\":[[\"50001.00\",\"1.00000000\"]]}}"}
{"local_receipt_timestamp_ns":1704067200000007461,"raw_payload":"{\"stream\":\"btcusdt@depth@100ms\",\"data\":{\"e\":\"depthUpdate\",\"E\":1704067200746,\"U\":745,\"u\":745,\"b\":[[\"50000.00\",\"1.00000000\"]],\"a\":[]}}"}
{"local_receipt_timestamp_ns":1704067200000007471,"raw_payload":"{\"stream\":\"btcusdt@depth@100ms\",\"data\":{\"e\":\"depthUpdate\",\"E\":1704067200747,\"U\":746,\"u\":746,\"b\":[],\"a\":[[\"50001.00\",\"1.00000000\"]]}}"}
{"local_receipt_timestamp_ns":1704067200000007481,"raw_payload":"{\"stream\":\"btcusdt@depth@100ms\",\"data\":{\"e\":\"depthUpdate\",\"E\":1704067200748,\"U\":747,\"u\":747,\"b\":[[\"50000.00\",\"1.00000000\"]],\"a\":[]}}"}
{"local_receipt_timestamp_ns":1704067200000007491,"raw_payload":"{\"stream\":\"btcusdt@depth@100ms\",\"data\":{\"e\":\"depthUpdate\",\"E\":1704067200749,\"U\":748,\"u\":748,\"b\":[],\"a\":[[\"50001.00\",\"1.00000000\"]]}}"}
{"local_receipt_timestamp_ns":1704067200000007501,"raw_payload":"{\"stream\":\"btcusdt@depth@100ms\",\"data\":{\"e\":\"depthUpdate\",\"E\":1704067200750,\"U\":749,\"u\":749,\"b\":[[\"50000.00\",\"1.00000000\"]],\"a\":[]}}"}
{"local_receipt_timestamp_ns":1704067200000007511,"raw_payload":"{\"stream\":\"btcusdt@depth@100ms\",\"data\":{\"e\":\"depthUpdate\",\"E\":1704067200751,\"U\":750,\"u\":750,\"b\":[],\"a\":[[\"50001.00\",\"1.00000000\"]]}}"}
{"local_receipt_timestamp_ns":1704067200000007521,"raw_payload":"{\"stream\":\"btcusdt@depth@100ms\",\"data\":{\"e\":\"depthUpdate\",\"E\":1704067200752,\"U\":751,\"u\":751,\"b\":[[\"50000.00\",\"1.00000000\"]],\"a\":[]}}"}
{"local_receipt_timestamp_ns":1704067200000007531,"raw_payload":"{\"stream\":\"btcusdt@depth@100ms\",\"data\":{\"e\":\"depthUpdate\",\"E\":1704067200753,\"U\":752,\"u\":752,\"b\":[],\"a\":[[\"50001.00\",\"1.00000000\"]]}}"}
{"local_receipt_timestamp_ns":1704067200000007541,"raw_payload":"{\"stream\":\"btcusdt@trade\",\"data\":{\"e\":\"trade\"}}"}
{"local_receipt_timestamp_ns":1704067200000007551,"raw_payload":"{"}
