{"local_receipt_timestamp_ns":1704067200000007312,"raw_payload":"{\"channel\":\"l2_data\",\"sequence_num\":730,\"events\":[{\"updates\":[{\"side\":\"offer\",\"event_time\":\"2024-01-01T00:00:00.000000001Z\",\"price_level\":\"50001.00\",\"new_quantity\":\"1.00000000\"}]}]}"}
{"local_receipt_timestamp_ns":1704067200000007322,"raw_payload":"{\"channel\":\"l2_data\",\"sequence_num\":731,\"events\":[{\"updates\":[{\"side\":\"bid\",\"event_time\":\"2024-01-01T00:00:00.000000001Z\",\"price_level\":\"50000.00\",\"new_quantity\":\"1.00000000\"}]}]}"}
{"local_receipt_timestamp_ns":1704067200000007332,"raw_payload":"{\"channel\":\"l2_data\",\"sequence_num\":732,\"events\":[{\"updates\":[{\"side\":\"offer\",\"event_time\":\"2024-01-01T00:00:00.000000001Z\",\"price_level\":\"50001.00\",\"new_quantity\":\"1.00000000\"}]}]}"}
{"local_receipt_timestamp_ns":1704067200000007342,"raw_payload":"{\"channel\":\"l2_data\",\"sequence_num\":733,\"events\":[{\"updates\":[{\"side\":\"bid\",\"event_time\":\"2024-01-01T00:00:00.000000001Z\",\"price_level\":\"50000.00\",\"new_quantity\":\"1.00000000\"}]}]}"}
{"local_receipt_timestamp_ns":1704067200000007352,"raw_payload":"{\"channel\":\"l2_data\",\"sequence_num\":734,\"events\":[{\"updates\":[{\"side\":\"offer\",\"event_time\":\"2024-01-01T00:00:00.000000001Z\",\"price_level\":\"50001.00\",\"new_quantity\":\"1.00000000\"}]}]}"}
{"local_receipt_timestamp_ns":1704067200000007362,"raw_payload":"{\"channel\":\"l2_data\",\"sequence_num\":735,\"events\":[{\"updates\":[{\"side\":\"bid\",\"event_time\":\"2024-01-01T00:00:00.000000001Z\",\"price_level\":\"50000.00\",\"new_quantity\":\"1.00000000\"}]}]}"}
{"local_receipt_timestamp_ns":1704067200000007372,"raw_payload":"{\"channel\":\"l2_data\",\"sequence_num\":736,\"events\":[{\"updates\":[{\"side\":\"offer\",\"event_time\":\"2024-01-01T00:00:00.000000001Z\",\"price_level\":\"50001.00\",\"new_quantity\":\"1.00000000\"}]}]}"}
{"local_receipt_timestamp_ns":1704067200000007382,"raw_payload":"{\"channel\":\"l2_data\",\"sequence_num\":737,\"events\":[{\"updates\":[{\"side\":\"bid\",\"event_time\":\"2024-01-01T00:00:00.000000001Z\",\"price_level\":\"50000.00\",\"new_quantity\":\"1.00000000\"}]}]}"}
{"local_receipt_timestamp_ns":1704067200000007392,"raw_payload":"{\"channel\":\"l2_data\",\"sequence_num\":738,\"events\":[{\"updates\":[{\"side\":\"offer\",\"event_time\":\"2024-01-01T00:00:00.000000001Z\",\"price_level\":\"50001.00\",\"new_quantity\":\"1.00000000\"}]}]}"}
{"local_receipt_timestamp_ns":1704067200000007402,"raw_payload":"{\"channel\":\"l2_data\",\"sequence_num\":739,\"events\":[{\"updates\":[{\"side\":\"bid\",\"event_time\":\"2024-01-01T00:00:00.000000001Z\",\"price_level\":\"50000.00\",\"new_quantity\":\"1.00000000\"}]}]}"}
{"local_receipt_timestamp_ns":1704067200000007412,"raw_payload":"{\"channel\":\"l2_data\",\"sequence_num\":740,\"events\":[{\"updates\":[{\"side\":\"offer\",\"event_time\":\"2024-01-01T00:00:00.000000001Z\",\"price_level\":\"50001.00\",\"new_quantity\":\"1.00000000\"}]}]}"}
{"local_receipt_timestamp_ns":1704067200000007422,"raw_payload":"{\"channel\":\"l2_data\",\"sequence_num\":741,\"events\":[{\"updates\":[{\"side\":\"bid\",\"event_time\":\"2024-01-01T00:00:00.000000001Z\",\"price_level\":\"50000.00\",\"new_quantity\":\"1.00000000\"}]}]}"}
{"local_receipt_timestamp_ns":1704067200000007432,"raw_payload":"{\"channel\":\"l2_data\",\"sequence_num\":742,\"events\":[{\"updates\":[{\"side\":\"offer\",\"event_time\":\"2024-01-01T00:00:00.000000001Z\",\"price_level\":\"50001.00\",\"new_quantity\":\"1.00000000\"}]}]}"}
{"local_receipt_timestamp_ns":1704067200000007442,"raw_payload":"{\"channel\":\"l2_data\",\"sequence_num\":743,\"events\":[{\"updates\":[{\"side\":\"bid\",\"event_time\":\"2024-01-01T00:00:00.000000001Z\",\"price_level\":\"50000.00\",\"new_quantity\":\"1.00000000\"}]}]}"}
{"local_receipt_timestamp_ns":1704067200000007452,"raw_payload":"{\"channel\":\"l2_data\",\"sequence_num\":744,\"events\":[{\"updates\":[{\"side\":\"offer\",\"event_time\":\"2024-01-01T00:00:00.000000001Z\",\"price_level\":\"50001.00\",\"new_quantity\":\"1.00000000\"}]}]}"}
{"local_receipt_timestamp_ns":1704067200000007462,"raw_payload":"{\"channel\":\"l2_data\",\"sequence_num\":745,\"events\":[{\"updates\":[{\"side\":\"bid\",\"event_time\":\"2024-01-01T00:00:00.000000001Z\",\"price_level\":\"50000.00\",\"new_quantity\":\"1.00000000\"}]}]}"}
{"local_receipt_timestamp_ns":1704067200000007472,"raw_payload":"{\"channel\":\"l2_data\",\"sequence_num\":746,\"events\":[{\"updates\":[{\"side\":\"offer\",\"event_time\":\"2024-01-01T00:00:00.000000001Z\",\"price_level\":\"50001.00\",\"new_quantity\":\"1.00000000\"}]}]}"}
{"local_receipt_timestamp_ns":1704067200000007482,"raw_payload":"{\"channel\":\"l2_data\",\"sequence_num\":747,\"events\":[{\"updates\":[{\"side\":\"bid\",\"event_time\":\"2024-01-01T00:00:00.000000001Z\",\"price_level\":\"50000.00\",\"new_quantity\":\"1.00000000\"}]}]}"}
{"local_receipt_timestamp_ns":1704067200000007492,"raw_payload":"{\"channel\":\"l2_data\",\"sequence_num\":748,\"events\":[{\"updates\":[{\"side\":\"offer\",\"event_time\":\"2024-01-01T00:00:00.000000001Z\",\"price_level\":\"50001.00\",\"new_quantity\":\"1.00000000\"}]}]}"}
{"local_receipt_timestamp_ns":1704067200000007502,"raw_payload":"{\"channel\":\"l2_data\",\"sequence_num\":749,\"events\":[{\"updates\":[{\"side\":\"bid\",\"event_time\":\"2024-01-01T00:00:00.000000001Z\",\"price_level\":\"50000.00\",\"new_quantity\":\"1.00000000\"}]}]}"}
{"local_receipt_timestamp_ns":1704067200000007512,"raw_payload":"{\"channel\":\"l2_data\",\"sequence_num\":750,\"events\":[{\"updates\":[{\"side\":\"offer\",\"event_time\":\"2024-01-01T00:00:00.000000001Z\",\"price_level\":\"50001.00\",\"new_quantity\":\"1.00000000\"}]}]}"}
{"local_receipt_timestamp_ns":1704067200000007522,"raw_payload":"{\"channel\":\"l2_data\",\"sequence_num\":751,\"events\":[{\"updates\":[{\"side\":\"bid\",\"event_time\":\"2024-01-01T00:00:00.000000001Z\",\"price_level\":\"50000.00\",\"new_quantity\":\"1.00000000\"}]}]}"}
{"local_receipt_timestamp_ns":1704067200000007532,"raw_payload":"{\"channel\":\"l2_data\",\"sequence_num\":752,\"events\":[{\"updates\":[{\"side\":\"offer\",\"event_time\":\"2024-01-01T00:00:00.000000001Z\",\"price_level\":\"50001.00\",\"new_quantity\":\"1.00000000\"}]}]}"}
{"local_receipt_timestamp_ns":1704067200000007542,"raw_payload":"{\"channel\":\"market_trades\",\"events\":[]}"}
{"local_receipt_timestamp_ns":1704067200000007552,"raw_payload":"{"}
