{"local_receipt_timestamp_ns":1704067200000000012,"raw_payload":"{\"channel\":\"l2_data\",\"sequence_num\":1,\"events\":[{\"updates\":[{\"side\":\"bid\",\"event_time\":\"2024-01-01T00:00:00.000000001Z\",\"price_level\":\"50000.00\",\"new_quantity\":\"1.00000000\"}]}]}"}
{"local_receipt_timestamp_ns":1704067200000000022,"raw_payload":"{\"channel\":\"l2_data\",\"sequence_num\":2,\"events\":[{\"updates\":[{\"side\":\"offer\",\"event_time\":\"2024-01-01T00:00:00.000000001Z\",\"price_level\":\"50001.00\",\"new_quantity\":\"1.00000000\"}]}]}"}
{"local_receipt_timestamp_ns":1704067200000000032,"raw_payload":"{\"channel\":\"l2_data\",\"sequence_num\":3,\"events\":[{\"updates\":[{\"side\":\"bid\",\"event_time\":\"2024-01-01T00:00:00.000000001Z\",\"price_level\":\"50000.00\",\"new_quantity\":\"1.00000000\"}]}]}"}
{"local_receipt_timestamp_ns":1704067200000000042,"raw_payload":"{\"channel\":\"l2_data\",\"sequence_num\":4,\"events\":[{\"updates\":[{\"side\":\"offer\",\"event_time\":\"2024-01-01T00:00:00.000000001Z\",\"price_level\":\"50001.00\",\"new_quantity\":\"1.00000000\"}]}]}"}
{"local_receipt_timestamp_ns":1704067200000000052,"raw_payload":"{\"channel\":\"l2_data\",\"sequence_num\":5,\"events\":[{\"updates\":[{\"side\":\"bid\",\"event_time\":\"2024-01-01T00:00:00.000000001Z\",\"price_level\":\"50000.00\",\"new_quantity\":\"1.00000000\"}]}]}"}
{"local_receipt_timestamp_ns":1704067200000000062,"raw_payload":"{\"channel\":\"l2_data\",\"sequence_num\":6,\"events\":[{\"updates\":[{\"side\":\"offer\",\"event_time\":\"2024-01-01T00:00:00.000000001Z\",\"price_level\":\"50001.00\",\"new_quantity\":\"1.00000000\"}]}]}"}
{"local_receipt_timestamp_ns":1704067200000000072,"raw_payload":"{\"channel\":\"l2_data\",\"sequence_num\":7,\"events\":[{\"updates\":[{\"side\":\"bid\",\"event_time\":\"2024-01-01T00:00:00.000000001Z\",\"price_level\":\"50000.00\",\"new_quantity\":\"1.00000000\"}]}]}"}
{"local_receipt_timestamp_ns":1704067200000000082,"raw_payload":"{\"channel\":\"l2_data\",\"sequence_num\":8,\"events\":[{\"updates\":[{\"side\":\"offer\",\"event_time\":\"2024-01-01T00:00:00.000000001Z\",\"price_level\":\"50001.00\",\"new_quantity\":\"1.00000000\"}]}]}"}
{"local_receipt_timestamp_ns":1704067200000000092,"raw_payload":"{\"channel\":\"l2_data\",\"sequence_num\":9,\"events\":[{\"updates\":[{\"side\":\"bid\",\"event_time\":\"2024-01-01T00:00:00.000000001Z\",\"price_level\":\"50000.00\",\"new_quantity\":\"1.00000000\"}]}]}"}
{"local_receipt_timestamp_ns":1704067200000000102,"raw_payload":"{\"channel\":\"l2_data\",\"sequence_num\":10,\"events\":[{\"updates\":[{\"side\":\"offer\",\"event_time\":\"2024-01-01T00:00:00.000000001Z\",\"price_level\":\"50001.00\",\"new_quantity\":\"1.00000000\"}]}]}"}
{"local_receipt_timestamp_ns":1704067200000000112,"raw_payload":"{\"channel\":\"l2_data\",\"sequence_num\":11,\"events\":[{\"updates\":[{\"side\":\"bid\",\"event_time\":\"2024-01-01T00:00:00.000000001Z\",\"price_level\":\"50000.00\",\"new_quantity\":\"1.00000000\"}]}]}"}
{"local_receipt_timestamp_ns":1704067200000000122,"raw_payload":"{\"channel\":\"l2_data\",\"sequence_num\":12,\"events\":[{\"updates\":[{\"side\":\"offer\",\"event_time\":\"2024-01-01T00:00:00.000000001Z\",\"price_level\":\"50001.00\",\"new_quantity\":\"1.00000000\"}]}]}"}
{"local_receipt_timestamp_ns":1704067200000000132,"raw_payload":"{\"channel\":\"l2_data\",\"sequence_num\":13,\"events\":[{\"updates\":[{\"side\":\"bid\",\"event_time\":\"2024-01-01T00:00:00.000000001Z\",\"price_level\":\"50000.00\",\"new_quantity\":\"1.00000000\"}]}]}"}
{"local_receipt_timestamp_ns":1704067200000000142,"raw_payload":"{\"channel\":\"l2_data\",\"sequence_num\":14,\"events\":[{\"updates\":[{\"side\":\"offer\",\"event_time\":\"2024-01-01T00:00:00.000000001Z\",\"price_level\":\"50001.00\",\"new_quantity\":\"1.00000000\"}]}]}"}
{"local_receipt_timestamp_ns":1704067200000000152,"raw_payload":"{\"channel\":\"l2_data\",\"sequence_num\":15,\"events\":[{\"updates\":[{\"side\":\"bid\",\"event_time\":\"2024-01-01T00:00:00.000000001Z\",\"price_level\":\"50000.00\",\"new_quantity\":\"1.00000000\"}]}]}"}
{"local_receipt_timestamp_ns":1704067200000000162,"raw_payload":"{\"channel\":\"l2_data\",\"sequence_num\":16,\"events\":[{\"updates\":[{\"side\":\"offer\",\"event_time\":\"2024-01-01T00:00:00.000000001Z\",\"price_level\":\"50001.00\",\"new_quantity\":\"1.00000000\"}]}]}"}
{"local_receipt_timestamp_ns":1704067200000000172,"raw_payload":"{\"channel\":\"l2_data\",\"sequence_num\":17,\"events\":[{\"updates\":[{\"side\":\"bid\",\"event_time\":\"2024-01-01T00:00:00.000000001Z\",\"price_level\":\"50000.00\",\"new_quantity\":\"1.00000000\"}]}]}"}
{"local_receipt_timestamp_ns":1704067200000000182,"raw_payload":"{\"channel\":\"l2_data\",\"sequence_num\":18,\"events\":[{\"updates\":[{\"side\":\"offer\",\"event_time\":\"2024-01-01T00:00:00.000000001Z\",\"price_level\":\"50001.00\",\"new_quantity\":\"1.00000000\"}]}]}"}
{"local_receipt_timestamp_ns":1704067200000000192,"raw_payload":"{\"channel\":\"l2_data\",\"sequence_num\":19,\"events\":[{\"updates\":[{\"side\":\"bid\",\"event_time\":\"2024-01-01T00:00:00.000000001Z\",\"price_level\":\"50000.00\",\"new_quantity\":\"1.00000000\"}]}]}"}
{"local_receipt_timestamp_ns":1704067200000000202,"raw_payload":"{\"channel\":\"l2_data\",\"sequence_num\":20,\"events\":[{\"updates\":[{\"side\":\"offer\",\"event_time\":\"2024-01-01T00:00:00.000000001Z\",\"price_level\":\"50001.00\",\"new_quantity\":\"1.00000000\"}]}]}"}
{"local_receipt_timestamp_ns":1704067200000000212,"raw_payload":"{\"channel\":\"l2_data\",\"sequence_num\":21,\"events\":[{\"updates\":[{\"side\":\"bid\",\"event_time\":\"2024-01-01T00:00:00.000000001Z\",\"price_level\":\"50000.00\",\"new_quantity\":\"1.00000000\"}]}]}"}
{"local_receipt_timestamp_ns":1704067200000000222,"raw_payload":"{\"channel\":\"l2_data\",\"sequence_num\":22,\"events\":[{\"updates\":[{\"side\":\"offer\",\"event_time\":\"2024-01-01T00:00:00.000000001Z\",\"price_level\":\"50001.00\",\"new_quantity\":\"1.00000000\"}]}]}"}
{"local_receipt_timestamp_ns":1704067200000000232,"raw_payload":"{\"channel\":\"l2_data\",\"sequence_num\":23,\"events\":[{\"updates\":[{\"side\":\"bid\",\"event_time\":\"2024-01-01T00:00:00.000000001Z\",\"price_level\":\"50000.00\",\"new_quantity\":\"1.00000000\"}]}]}"}
{"local_receipt_timestamp_ns":1704067200000000242,"raw_payload":"{\"channel\":\"l2_data\",\"sequence_num\":24,\"events\":[{\"updates\":[{\"side\":\"offer\",\"event_time\":\"2024-01-01T00:00:00.000000001Z\",\"price_level\":\"50001.00\",\"new_quantity\":\"1.00000000\"}]}]}"}
{"local_receipt_timestamp_ns":1704067200000000252,"raw_payload":"{\"channel\":\"l2_data\",\"sequence_num\":25,\"events\":[{\"updates\":[{\"side\":\"bid\",\"event_time\":\"2024-01-01T00:00:00.000000001Z\",\"price_level\":\"50000.00\",\"new_quantity\":\"1.00000000\"}]}]}"}
{"local_receipt_timestamp_ns":1704067200000000262,"raw_payload":"{\"channel\":\"l2_data\",\"sequence_num\":26,\"events\":[{\"updates\":[{\"side\":\"offer\",\"event_time\":\"2024-01-01T00:00:00.000000001Z\",\"price_level\":\"50001.00\",\"new_quantity\":\"1.00000000\"}]}]}"}
{"local_receipt_timestamp_ns":1704067200000000272,"raw_payload":"{\"channel\":\"l2_data\",\"sequence_num\":27,\"events\":[{\"updates\":[{\"side\":\"bid\",\"event_time\":\"2024-01-01T00:00:00.000000001Z\",\"price_level\":\"50000.00\",\"new_quantity\":\"1.00000000\"}]}]}"}
{"local_receipt_timestamp_ns":1704067200000000282,"raw_payload":"{\"channel\":\"l2_data\",\"sequence_num\":28,\"events\":[{\"updates\":[{\"side\":\"offer\",\"event_time\":\"2024-01-01T00:00:00.000000001Z\",\"price_level\":\"50001.00\",\"new_quantity\":\"1.00000000\"}]}]}"}
{"local_receipt_timestamp_ns":1704067200000000292,"raw_payload":"{\"channel\":\"l2_data\",\"sequence_num\":29,\"events\":[{\"updates\":[{\"side\":\"bid\",\"event_time\":\"2024-01-01T00:00:00.000000001Z\",\"price_level\":\"50000.00\",\"new_quantity\":\"1.00000000\"}]}]}"}
{"local_receipt_timestamp_ns":1704067200000000302,"raw_payload":"{\"channel\":\"l2_data\",\"sequence_num\":30,\"events\":[{\"updates\":[{\"side\":\"offer\",\"event_time\":\"2024-01-01T00:00:00.000000001Z\",\"price_level\":\"50001.00\",\"new_quantity\":\"1.00000000\"}]}]}"}
{"local_receipt_timestamp_ns":1704067200000000312,"raw_payload":"{\"channel\":\"l2_data\",\"sequence_num\":31,\"events\":[{\"updates\":[{\"side\":\"bid\",\"event_time\":\"2024-01-01T00:00:00.000000001Z\",\"price_level\":\"50000.00\",\"new_quantity\":\"1.00000000\"}]}]}"}
{"local_receipt_timestamp_ns":1704067200000000322,"raw_payload":"{\"channel\":\"l2_data\",\"sequence_num\":32,\"events\":[{\"updates\":[{\"side\":\"offer\",\"event_time\":\"2024-01-01T00:00:00.000000001Z\",\"price_level\":\"50001.00\",\"new_quantity\":\"1.00000000\"}]}]}"}
{"local_receipt_timestamp_ns":1704067200000000332,"raw_payload":"{\"channel\":\"l2_data\",\"sequence_num\":33,\"events\":[{\"updates\":[{\"side\":\"bid\",\"event_time\":\"2024-01-01T00:00:00.000000001Z\",\"price_level\":\"50000.00\",\"new_quantity\":\"1.00000000\"}]}]}"}
{"local_receipt_timestamp_ns":1704067200000000342,"raw_payload":"{\"channel\":\"l2_data\",\"sequence_num\":34,\"events\":[{\"updates\":[{\"side\":\"offer\",\"event_time\":\"2024-01-01T00:00:00.000000001Z\",\"price_level\":\"50001.00\",\"new_quantity\":\"1.00000000\"}]}]}"}
{"local_receipt_timestamp_ns":1704067200000000352,"raw_payload":"{\"channel\":\"l2_data\",\"sequence_num\":35,\"events\":[{\"updates\":[{\"side\":\"bid\",\"event_time\":\"2024-01-01T00:00:00.000000001Z\",\"price_level\":\"50000.00\",\"new_quantity\":\"1.00000000\"}]}]}"}
{"local_receipt_timestamp_ns":1704067200000000362,"raw_payload":"{\"channel\":\"l2_data\",\"sequence_num\":36,\"events\":[{\"updates\":[{\"side\":\"offer\",\"event_time\":\"2024-01-01T00:00:00.000000001Z\",\"price_level\":\"50001.00\",\"new_quantity\":\"1.00000000\"}]}]}"}
{"local_receipt_timestamp_ns":1704067200000000372,"raw_payload":"{\"channel\":\"l2_data\",\"sequence_num\":37,\"events\":[{\"updates\":[{\"side\":\"bid\",\"event_time\":\"2024-01-01T00:00:00.000000001Z\",\"price_level\":\"50000.00\",\"new_quantity\":\"1.00000000\"}]}]}"}
{"local_receipt_timestamp_ns":1704067200000000382,"raw_payload":"{\"channel\":\"l2_data\",\"sequence_num\":38,\"events\":[{\"updates\":[{\"side\":\"offer\",\"event_time\":\"2024-01-01T00:00:00.000000001Z\",\"price_level\":\"50001.00\",\"new_quantity\":\"1.00000000\"}]}]}"}
{"local_receipt_timestamp_ns":1704067200000000392,"raw_payload":"{\"channel\":\"l2_data\",\"sequence_num\":39,\"events\":[{\"updates\":[{\"side\":\"bid\",\"event_time\":\"2024-01-01T00:00:00.000000001Z\",\"price_level\":\"50000.00\",\"new_quantity\":\"1.00000000\"}]}]}"}
{"local_receipt_timestamp_ns":1704067200000000402,"raw_payload":"{\"channel\":\"l2_data\",\"sequence_num\":40,\"events\":[{\"updates\":[{\"side\":\"offer\",\"event_time\":\"2024-01-01T00:00:00.000000001Z\",\"price_level\":\"50001.00\",\"new_quantity\":\"1.00000000\"}]}]}"}
{"local_receipt_timestamp_ns":1704067200000000412,"raw_payload":"{\"channel\":\"l2_data\",\"sequence_num\":41,\"events\":[{\"updates\":[{\"side\":\"bid\",\"event_time\":\"2024-01-01T00:00:00.000000001Z\",\"price_level\":\"50000.00\",\"new_quantity\":\"1.00000000\"}]}]}"}
{"local_receipt_timestamp_ns":1704067200000000422,"raw_payload":"{\"channel\":\"l2_data\",\"sequence_num\":42,\"events\":[{\"updates\":[{\"side\":\"offer\",\"event_time\":\"2024-01-01T00:00:00.000000001Z\",\"price_level\":\"50001.00\",\"new_quantity\":\"1.00000000\"}]}]}"}
{"local_receipt_timestamp_ns":1704067200000000432,"raw_payload":"{\"channel\":\"l2_data\",\"sequence_num\":43,\"events\":[{\"updates\":[{\"side\":\"bid\",\"event_time\":\"2024-01-01T00:00:00.000000001Z\",\"price_level\":\"50000.00\",\"new_quantity\":\"1.00000000\"}]}]}"}
{"local_receipt_timestamp_ns":1704067200000000442,"raw_payload":"{\"channel\":\"l2_data\",\"sequence_num\":44,\"events\":[{\"updates\":[{\"side\":\"offer\",\"event_time\":\"2024-01-01T00:00:00.000000001Z\",\"price_level\":\"50001.00\",\"new_quantity\":\"1.00000000\"}]}]}"}
{"local_receipt_timestamp_ns":1704067200000000452,"raw_payload":"{\"channel\":\"l2_data\",\"sequence_num\":45,\"events\":[{\"updates\":[{\"side\":\"bid\",\"event_time\":\"2024-01-01T00:00:00.000000001Z\",\"price_level\":\"50000.00\",\"new_quantity\":\"1.00000000\"}]}]}"}
{"local_receipt_timestamp_ns":1704067200000000462,"raw_payload":"{\"channel\":\"l2_data\",\"sequence_num\":46,\"events\":[{\"updates\":[{\"side\":\"offer\",\"event_time\":\"2024-01-01T00:00:00.000000001Z\",\"price_level\":\"50001.00\",\"new_quantity\":\"1.00000000\"}]}]}"}
{"local_receipt_timestamp_ns":1704067200000000472,"raw_payload":"{\"channel\":\"l2_data\",\"sequence_num\":47,\"events\":[{\"updates\":[{\"side\":\"bid\",\"event_time\":\"2024-01-01T00:00:00.000000001Z\",\"price_level\":\"50000.00\",\"new_quantity\":\"1.00000000\"}]}]}"}
{"local_receipt_timestamp_ns":1704067200000000482,"raw_payload":"{\"channel\":\"l2_data\",\"sequence_num\":48,\"events\":[{\"updates\":[{\"side\":\"offer\",\"event_time\":\"2024-01-01T00:00:00.000000001Z\",\"price_level\":\"50001.00\",\"new_quantity\":\"1.00000000\"}]}]}"}
{"local_receipt_timestamp_ns":1704067200000000492,"raw_payload":"{\"channel\":\"l2_data\",\"sequence_num\":49,\"events\":[{\"updates\":[{\"side\":\"bid\",\"event_time\":\"2024-01-01T00:00:00.000000001Z\",\"price_level\":\"50000.00\",\"new_quantity\":\"1.00000000\"}]}]}"}
{"local_receipt_timestamp_ns":1704067200000000502,"raw_payload":"{\"channel\":\"l2_data\",\"sequence_num\":50,\"events\":[{\"updates\":[{\"side\":\"offer\",\"event_time\":\"2024-01-01T00:00:00.000000001Z\",\"price_level\":\"50001.00\",\"new_quantity\":\"1.00000000\"}]}]}"}
{"local_receipt_timestamp_ns":1704067200000000512,"raw_payload":"{\"channel\":\"l2_data\",\"sequence_num\":51,\"events\":[{\"updates\":[{\"side\":\"bid\",\"event_time\":\"2024-01-01T00:00:00.000000001Z\",\"price_level\":\"50000.00\",\"new_quantity\":\"1.00000000\"}]}]}"}
{"local_receipt_timestamp_ns":1704067200000000522,"raw_payload":"{\"channel\":\"l2_data\",\"sequence_num\":52,\"events\":[{\"updates\":[{\"side\":\"offer\",\"event_time\":\"2024-01-01T00:00:00.000000001Z\",\"price_level\":\"50001.00\",\"new_quantity\":\"1.00000000\"}]}]}"}
{"local_receipt_timestamp_ns":1704067200000000532,"raw_payload":"{\"channel\":\"l2_data\",\"sequence_num\":53,\"events\":[{\"updates\":[{\"side\":\"bid\",\"event_time\":\"2024-01-01T00:00:00.000000001Z\",\"price_level\":\"50000.00\",\"new_quantity\":\"1.00000000\"}]}]}"}
{"local_receipt_timestamp_ns":1704067200000000542,"raw_payload":"{\"channel\":\"l2_data\",\"sequence_num\":54,\"events\":[{\"updates\":[{\"side\":\"offer\",\"event_time\":\"2024-01-01T00:00:00.000000001Z\",\"price_level\":\"50001.00\",\"new_quantity\":\"1.00000000\"}]}]}"}
{"local_receipt_timestamp_ns":1704067200000000552,"raw_payload":"{\"channel\":\"l2_data\",\"sequence_num\":55,\"events\":[{\"updates\":[{\"side\":\"bid\",\"event_time\":\"2024-01-01T00:00:00.000000001Z\",\"price_level\":\"50000.00\",\"new_quantity\":\"1.00000000\"}]}]}"}
{"local_receipt_timestamp_ns":1704067200000000562,"raw_payload":"{\"channel\":\"l2_data\",\"sequence_num\":56,\"events\":[{\"updates\":[{\"side\":\"offer\",\"event_time\":\"2024-01-01T00:00:00.000000001Z\",\"price_level\":\"50001.00\",\"new_quantity\":\"1.00000000\"}]}]}"}
{"local_receipt_timestamp_ns":1704067200000000572,"raw_payload":"{\"channel\":\"l2_data\",\"sequence_num\":57,\"events\":[{\"updates\":[{\"side\":\"bid\",\"event_time\":\"2024-01-01T00:00:00.000000001Z\",\"price_level\":\"50000.00\",\"new_quantity\":\"1.00000000\"}]}]}"}
{"local_receipt_timestamp_ns":1704067200000000582,"raw_payload":"{\"channel\":\"l2_data\",\"sequence_num\":58,\"events\":[{\"updates\":[{\"side\":\"offer\",\"event_time\":\"2024-01-01T00:00:00.000000001Z\",\"price_level\":\"50001.00\",\"new_quantity\":\"1.00000000\"}]}]}"}
{"local_receipt_timestamp_ns":1704067200000000592,"raw_payload":"{\"channel\":\"l2_data\",\"sequence_num\":59,\"events\":[{\"updates\":[{\"side\":\"bid\",\"event_time\":\"2024-01-01T00:00:00.000000001Z\",\"price_level\":\"50000.00\",\"new_quantity\":\"1.00000000\"}]}]}"}
{"local_receipt_timestamp_ns":1704067200000000602,"raw_payload":"{\"channel\":\"l2_data\",\"sequence_num\":60,\"events\":[{\"updates\":[{\"side\":\"offer\",\"event_time\":\"2024-01-01T00:00:00.000000001Z\",\"price_level\":\"50001.00\",\"new_quantity\":\"1.00000000\"}]}]}"}
{"local_receipt_timestamp_ns":1704067200000000612,"raw_payload":"{\"channel\":\"l2_data\",\"sequence_num\":61,\"events\":[{\"updates\":[{\"side\":\"bid\",\"event_time\":\"2024-01-01T00:00:00.000000001Z\",\"price_level\":\"50000.00\",\"new_quantity\":\"1.00000000\"}]}]}"}
{"local_receipt_timestamp_ns":1704067200000000622,"raw_payload":"{\"channel\":\"l2_data\",\"sequence_num\":62,\"events\":[{\"updates\":[{\"side\":\"offer\",\"event_time\":\"2024-01-01T00:00:00.000000001Z\",\"price_level\":\"50001.00\",\"new_quantity\":\"1.00000000\"}]}]}"}
{"local_receipt_timestamp_ns":1704067200000000632,"raw_payload":"{\"channel\":\"l2_data\",\"sequence_num\":63,\"events\":[{\"updates\":[{\"side\":\"bid\",\"event_time\":\"2024-01-01T00:00:00.000000001Z\",\"price_level\":\"50000.00\",\"new_quantity\":\"1.00000000\"}]}]}"}
{"local_receipt_timestamp_ns":1704067200000000642,"raw_payload":"{\"channel\":\"l2_data\",\"sequence_num\":64,\"events\":[{\"updates\":[{\"side\":\"offer\",\"event_time\":\"2024-01-01T00:00:00.000000001Z\",\"price_level\":\"50001.00\",\"new_quantity\":\"1.00000000\"}]}]}"}
{"local_receipt_timestamp_ns":1704067200000000652,"raw_payload":"{\"channel\":\"l2_data\",\"sequence_num\":65,\"events\":[{\"updates\":[{\"side\":\"bid\",\"event_time\":\"2024-01-01T00:00:00.000000001Z\",\"price_level\":\"50000.00\",\"new_quantity\":\"1.00000000\"}]}]}"}
{"local_receipt_timestamp_ns":1704067200000000662,"raw_payload":"{\"channel\":\"l2_data\",\"sequence_num\":66,\"events\":[{\"updates\":[{\"side\":\"offer\",\"event_time\":\"2024-01-01T00:00:00.000000001Z\",\"price_level\":\"50001.00\",\"new_quantity\":\"1.00000000\"}]}]}"}
{"local_receipt_timestamp_ns":1704067200000000672,"raw_payload":"{\"channel\":\"l2_data\",\"sequence_num\":67,\"events\":[{\"updates\":[{\"side\":\"bid\",\"event_time\":\"2024-01-01T00:00:00.000000001Z\",\"price_level\":\"50000.00\",\"new_quantity\":\"1.00000000\"}]}]}"}
{"local_receipt_timestamp_ns":1704067200000000682,"raw_payload":"{\"channel\":\"l2_data\",\"sequence_num\":68,\"events\":[{\"updates\":[{\"side\":\"offer\",\"event_time\":\"2024-01-01T00:00:00.000000001Z\",\"price_level\":\"50001.00\",\"new_quantity\":\"1.00000000\"}]}]}"}
{"local_receipt_timestamp_ns":1704067200000000692,"raw_payload":"{\"channel\":\"l2_data\",\"sequence_num\":69,\"events\":[{\"updates\":[{\"side\":\"bid\",\"event_time\":\"2024-01-01T00:00:00.000000001Z\",\"price_level\":\"50000.00\",\"new_quantity\":\"1.00000000\"}]}]}"}
{"local_receipt_timestamp_ns":1704067200000000702,"raw_payload":"{\"channel\":\"l2_data\",\"sequence_num\":70,\"events\":[{\"updates\":[{\"side\":\"offer\",\"event_time\":\"2024-01-01T00:00:00.000000001Z\",\"price_level\":\"50001.00\",\"new_quantity\":\"1.00000000\"}]}]}"}
{"local_receipt_timestamp_ns":1704067200000000712,"raw_payload":"{\"channel\":\"l2_data\",\"sequence_num\":71,\"events\":[{\"updates\":[{\"side\":\"bid\",\"event_time\":\"2024-01-01T00:00:00.000000001Z\",\"price_level\":\"50000.00\",\"new_quantity\":\"1.00000000\"}]}]}"}
{"local_receipt_timestamp_ns":1704067200000000722,"raw_payload":"{\"channel\":\"l2_data\",\"sequence_num\":72,\"events\":[{\"updates\":[{\"side\":\"offer\",\"event_time\":\"2024-01-01T00:00:00.000000001Z\",\"price_level\":\"50001.00\",\"new_quantity\":\"1.00000000\"}]}]}"}
{"local_receipt_timestamp_ns":1704067200000000732,"raw_payload":"{\"channel\":\"l2_data\",\"sequence_num\":73,\"events\":[{\"updates\":[{\"side\":\"bid\",\"event_time\":\"2024-01-01T00:00:00.000000001Z\",\"price_level\":\"50000.00\",\"new_quantity\":\"1.00000000\"}]}]}"}
{"local_receipt_timestamp_ns":1704067200000000742,"raw_payload":"{\"channel\":\"l2_data\",\"sequence_num\":74,\"events\":[{\"updates\":[{\"side\":\"offer\",\"event_time\":\"2024-01-01T00:00:00.000000001Z\",\"price_level\":\"50001.00\",\"new_quantity\":\"1.00000000\"}]}]}"}
{"local_receipt_timestamp_ns":1704067200000000752,"raw_payload":"{\"channel\":\"l2_data\",\"sequence_num\":75,\"events\":[{\"updates\":[{\"side\":\"bid\",\"event_time\":\"2024-01-01T00:00:00.000000001Z\",\"price_level\":\"50000.00\",\"new_quantity\":\"1.00000000\"}]}]}"}
{"local_receipt_timestamp_ns":1704067200000000762,"raw_payload":"{\"channel\":\"l2_data\",\"sequence_num\":76,\"events\":[{\"updates\":[{\"side\":\"offer\",\"event_time\":\"2024-01-01T00:00:00.000000001Z\",\"price_level\":\"50001.00\",\"new_quantity\":\"1.00000000\"}]}]}"}
{"local_receipt_timestamp_ns":1704067200000000772,"raw_payload":"{\"channel\":\"l2_data\",\"sequence_num\":77,\"events\":[{\"updates\":[{\"side\":\"bid\",\"event_time\":\"2024-01-01T00:00:00.000000001Z\",\"price_level\":\"50000.00\",\"new_quantity\":\"1.00000000\"}]}]}"}
{"local_receipt_timestamp_ns":1704067200000000782,"raw_payload":"{\"channel\":\"l2_data\",\"sequence_num\":78,\"events\":[{\"updates\":[{\"side\":\"offer\",\"event_time\":\"2024-01-01T00:00:00.000000001Z\",\"price_level\":\"50001.00\",\"new_quantity\":\"1.00000000\"}]}]}"}
{"local_receipt_timestamp_ns":1704067200000000792,"raw_payload":"{\"channel\":\"l2_data\",\"sequence_num\":79,\"events\":[{\"updates\":[{\"side\":\"bid\",\"event_time\":\"2024-01-01T00:00:00.000000001Z\",\"price_level\":\"50000.00\",\"new_quantity\":\"1.00000000\"}]}]}"}
{"local_receipt_timestamp_ns":1704067200000000802,"raw_payload":"{\"channel\":\"l2_data\",\"sequence_num\":80,\"events\":[{\"updates\":[{\"side\":\"offer\",\"event_time\":\"2024-01-01T00:00:00.000000001Z\",\"price_level\":\"50001.00\",\"new_quantity\":\"1.00000000\"}]}]}"}
{"local_receipt_timestamp_ns":1704067200000000812,"raw_payload":"{\"channel\":\"l2_data\",\"sequence_num\":81,\"events\":[{\"updates\":[{\"side\":\"bid\",\"event_time\":\"2024-01-01T00:00:00.000000001Z\",\"price_level\":\"50000.00\",\"new_quantity\":\"1.00000000\"}]}]}"}
{"local_receipt_timestamp_ns":1704067200000000822,"raw_payload":"{\"channel\":\"l2_data\",\"sequence_num\":82,\"events\":[{\"updates\":[{\"side\":\"offer\",\"event_time\":\"2024-01-01T00:00:00.000000001Z\",\"price_level\":\"50001.00\",\"new_quantity\":\"1.00000000\"}]}]}"}
{"local_receipt_timestamp_ns":1704067200000000832,"raw_payload":"{\"channel\":\"l2_data\",\"sequence_num\":83,\"events\":[{\"updates\":[{\"side\":\"bid\",\"event_time\":\"2024-01-01T00:00:00.000000001Z\",\"price_level\":\"50000.00\",\"new_quantity\":\"1.00000000\"}]}]}"}
{"local_receipt_timestamp_ns":1704067200000000842,"raw_payload":"{\"channel\":\"l2_data\",\"sequence_num\":84,\"events\":[{\"updates\":[{\"side\":\"offer\",\"event_time\":\"2024-01-01T00:00:00.000000001Z\",\"price_level\":\"50001.00\",\"new_quantity\":\"1.00000000\"}]}]}"}
{"local_receipt_timestamp_ns":1704067200000000852,"raw_payload":"{\"channel\":\"l2_data\",\"sequence_num\":85,\"events\":[{\"updates\":[{\"side\":\"bid\",\"event_time\":\"2024-01-01T00:00:00.000000001Z\",\"price_level\":\"50000.00\",\"new_quantity\":\"1.00000000\"}]}]}"}
{"local_receipt_timestamp_ns":1704067200000000862,"raw_payload":"{\"channel\":\"l2_data\",\"sequence_num\":86,\"events\":[{\"updates\":[{\"side\":\"offer\",\"event_time\":\"2024-01-01T00:00:00.000000001Z\",\"price_level\":\"50001.00\",\"new_quantity\":\"1.00000000\"}]}]}"}
{"local_receipt_timestamp_ns":1704067200000000872,"raw_payload":"{\"channel\":\"l2_data\",\"sequence_num\":87,\"events\":[{\"updates\":[{\"side\":\"bid\",\"event_time\":\"2024-01-01T00:00:00.000000001Z\",\"price_level\":\"50000.00\",\"new_quantity\":\"1.00000000\"}]}]}"}
{"local_receipt_timestamp_ns":1704067200000000882,"raw_payload":"{\"channel\":\"l2_data\",\"sequence_num\":88,\"events\":[{\"updates\":[{\"side\":\"offer\",\"event_time\":\"2024-01-01T00:00:00.000000001Z\",\"price_level\":\"50001.00\",\"new_quantity\":\"1.00000000\"}]}]}"}
{"local_receipt_timestamp_ns":1704067200000000892,"raw_payload":"{\"channel\":\"l2_data\",\"sequence_num\":89,\"events\":[{\"updates\":[{\"side\":\"bid\",\"event_time\":\"2024-01-01T00:00:00.000000001Z\",\"price_level\":\"50000.00\",\"new_quantity\":\"1.00000000\"}]}]}"}
{"local_receipt_timestamp_ns":1704067200000000902,"raw_payload":"{\"channel\":\"l2_data\",\"sequence_num\":90,\"events\":[{\"updates\":[{\"side\":\"offer\",\"event_time\":\"2024-01-01T00:00:00.000000001Z\",\"price_level\":\"50001.00\",\"new_quantity\":\"1.00000000\"}]}]}"}
{"local_receipt_timestamp_ns":1704067200000000912,"raw_payload":"{\"channel\":\"l2_data\",\"sequence_num\":91,\"events\":[{\"updates\":[{\"side\":\"bid\",\"event_time\":\"2024-01-01T00:00:00.000000001Z\",\"price_level\":\"50000.00\",\"new_quantity\":\"1.00000000\"}]}]}"}
{"local_receipt_timestamp_ns":1704067200000000922,"raw_payload":"{\"channel\":\"l2_data\",\"sequence_num\":92,\"events\":[{\"updates\":[{\"side\":\"offer\",\"event_time\":\"2024-01-01T00:00:00.000000001Z\",\"price_level\":\"50001.00\",\"new_quantity\":\"1.00000000\"}]}]}"}
{"local_receipt_timestamp_ns":1704067200000000932,"raw_payload":"{\"channel\":\"l2_data\",\"sequence_num\":93,\"events\":[{\"updates\":[{\"side\":\"bid\",\"event_time\":\"2024-01-01T00:00:00.000000001Z\",\"price_level\":\"50000.00\",\"new_quantity\":\"1.00000000\"}]}]}"}
{"local_receipt_timestamp_ns":1704067200000000942,"raw_payload":"{\"channel\":\"l2_data\",\"sequence_num\":94,\"events\":[{\"updates\":[{\"side\":\"offer\",\"event_time\":\"2024-01-01T00:00:00.000000001Z\",\"price_level\":\"50001.00\",\"new_quantity\":\"1.00000000\"}]}]}"}
{"local_receipt_timestamp_ns":1704067200000000952,"raw_payload":"{\"channel\":\"l2_data\",\"sequence_num\":95,\"events\":[{\"updates\":[{\"side\":\"bid\",\"event_time\":\"2024-01-01T00:00:00.000000001Z\",\"price_level\":\"50000.00\",\"new_quantity\":\"1.00000000\"}]}]}"}
{"local_receipt_timestamp_ns":1704067200000000962,"raw_payload":"{\"channel\":\"l2_data\",\"sequence_num\":96,\"events\":[{\"updates\":[{\"side\":\"offer\",\"event_time\":\"2024-01-01T00:00:00.000000001Z\",\"price_level\":\"50001.00\",\"new_quantity\":\"1.00000000\"}]}]}"}
{"local_receipt_timestamp_ns":1704067200000000972,"raw_payload":"{\"channel\":\"l2_data\",\"sequence_num\":97,\"events\":[{\"updates\":[{\"side\":\"bid\",\"event_time\":\"2024-01-01T00:00:00.000000001Z\",\"price_level\":\"50000.00\",\"new_quantity\":\"1.00000000\"}]}]}"}
{"local_receipt_timestamp_ns":1704067200000000982,"raw_payload":"{\"channel\":\"l2_data\",\"sequence_num\":98,\"events\":[{\"updates\":[{\"side\":\"offer\",\"event_time\":\"2024-01-01T00:00:00.000000001Z\",\"price_level\":\"50001.00\",\"new_quantity\":\"1.00000000\"}]}]}"}
{"local_receipt_timestamp_ns":1704067200000000992,"raw_payload":"{\"channel\":\"l2_data\",\"sequence_num\":99,\"events\":[{\"updates\":[{\"side\":\"bid\",\"event_time\":\"2024-01-01T00:00:00.000000001Z\",\"price_level\":\"50000.00\",\"new_quantity\":\"1.00000000\"}]}]}"}
{"local_receipt_timestamp_ns":1704067200000001002,"raw_payload":"{\"channel\":\"l2_data\",\"sequence_num\":100,\"events\":[{\"updates\":[{\"side\":\"offer\",\"event_time\":\"2024-01-01T00:00:00.000000001Z\",\"price_level\":\"50001.00\",\"new_quantity\":\"1.00000000\"}]}]}"}
{"local_receipt_timestamp_ns":1704067200000001012,"raw_payload":"{\"channel\":\"l2_data\",\"sequence_num\":101,\"events\":[{\"updates\":[{\"side\":\"bid\",\"event_time\":\"2024-01-01T00:00:00.000000001Z\",\"price_level\":\"50000.00\",\"new_quantity\":\"1.00000000\"}]}]}"}
{"local_receipt_timestamp_ns":1704067200000001022,"raw_payload":"{\"channel\":\"l2_data\",\"sequence_num\":102,\"events\":[{\"updates\":[{\"side\":\"offer\",\"event_time\":\"2024-01-01T00:00:00.000000001Z\",\"price_level\":\"50001.00\",\"new_quantity\":\"1.00000000\"}]}]}"}
{"local_receipt_timestamp_ns":1704067200000001032,"raw_payload":"{\"channel\":\"l2_data\",\"sequence_num\":103,\"events\":[{\"updates\":[{\"side\":\"bid\",\"event_time\":\"2024-01-01T00:00:00.000000001Z\",\"price_level\":\"50000.00\",\"new_quantity\":\"1.00000000\"}]}]}"}
{"local_receipt_timestamp_ns":1704067200000001042,"raw_payload":"{\"channel\":\"l2_data\",\"sequence_num\":104,\"events\":[{\"updates\":[{\"side\":\"offer\",\"event_time\":\"2024-01-01T00:00:00.000000001Z\",\"price_level\":\"50001.00\",\"new_quantity\":\"1.00000000\"}]}]}"}
{"local_receipt_timestamp_ns":1704067200000001052,"raw_payload":"{\"channel\":\"l2_data\",\"sequence_num\":105,\"events\":[{\"updates\":[{\"side\":\"bid\",\"event_time\":\"2024-01-01T00:00:00.000000001Z\",\"price_level\":\"50000.00\",\"new_quantity\":\"1.00000000\"}]}]}"}
{"local_receipt_timestamp_ns":1704067200000001062,"raw_payload":"{\"channel\":\"l2_data\",\"sequence_num\":106,\"events\":[{\"updates\":[{\"side\":\"offer\",\"event_time\":\"2024-01-01T00:00:00.000000001Z\",\"price_level\":\"50001.00\",\"new_quantity\":\"1.00000000\"}]}]}"}
{"local_receipt_timestamp_ns":1704067200000001072,"raw_payload":"{\"channel\":\"l2_data\",\"sequence_num\":107,\"events\":[{\"updates\":[{\"side\":\"bid\",\"event_time\":\"2024-01-01T00:00:00.000000001Z\",\"price_level\":\"50000.00\",\"new_quantity\":\"1.00000000\"}]}]}"}
{"local_receipt_timestamp_ns":1704067200000001082,"raw_payload":"{\"channel\":\"l2_data\",\"sequence_num\":108,\"events\":[{\"updates\":[{\"side\":\"offer\",\"event_time\":\"2024-01-01T00:00:00.000000001Z\",\"price_level\":\"50001.00\",\"new_quantity\":\"1.00000000\"}]}]}"}
{"local_receipt_timestamp_ns":1704067200000001092,"raw_payload":"{\"channel\":\"l2_data\",\"sequence_num\":109,\"events\":[{\"updates\":[{\"side\":\"bid\",\"event_time\":\"2024-01-01T00:00:00.000000001Z\",\"price_level\":\"50000.00\",\"new_quantity\":\"1.00000000\"}]}]}"}
{"local_receipt_timestamp_ns":1704067200000001102,"raw_payload":"{\"channel\":\"l2_data\",\"sequence_num\":110,\"events\":[{\"updates\":[{\"side\":\"offer\",\"event_time\":\"2024-01-01T00:00:00.000000001Z\",\"price_level\":\"50001.00\",\"new_quantity\":\"1.00000000\"}]}]}"}
{"local_receipt_timestamp_ns":1704067200000001112,"raw_payload":"{\"channel\":\"l2_data\",\"sequence_num\":111,\"events\":[{\"updates\":[{\"side\":\"bid\",\"event_time\":\"2024-01-01T00:00:00.000000001Z\",\"price_level\":\"50000.00\",\"new_quantity\":\"1.00000000\"}]}]}"}
{"local_receipt_timestamp_ns":1704067200000001122,"raw_payload":"{\"channel\":\"l2_data\",\"sequence_num\":112,\"events\":[{\"updates\":[{\"side\":\"offer\",\"event_time\":\"2024-01-01T00:00:00.000000001Z\",\"price_level\":\"50001.00\",\"new_quantity\":\"1.00000000\"}]}]}"}
{"local_receipt_timestamp_ns":1704067200000001132,"raw_payload":"{\"channel\":\"l2_data\",\"sequence_num\":113,\"events\":[{\"updates\":[{\"side\":\"bid\",\"event_time\":\"2024-01-01T00:00:00.000000001Z\",\"price_level\":\"50000.00\",\"new_quantity\":\"1.00000000\"}]}]}"}
{"local_receipt_timestamp_ns":1704067200000001142,"raw_payload":"{\"channel\":\"l2_data\",\"sequence_num\":114,\"events\":[{\"updates\":[{\"side\":\"offer\",\"event_time\":\"2024-01-01T00:00:00.000000001Z\",\"price_level\":\"50001.00\",\"new_quantity\":\"1.00000000\"}]}]}"}
{"local_receipt_timestamp_ns":1704067200000001152,"raw_payload":"{\"channel\":\"l2_data\",\"sequence_num\":115,\"events\":[{\"updates\":[{\"side\":\"bid\",\"event_time\":\"2024-01-01T00:00:00.000000001Z\",\"price_level\":\"50000.00\",\"new_quantity\":\"1.00000000\"}]}]}"}
{"local_receipt_timestamp_ns":1704067200000001162,"raw_payload":"{\"channel\":\"l2_data\",\"sequence_num\":116,\"events\":[{\"updates\":[{\"side\":\"offer\",\"event_time\":\"2024-01-01T00:00:00.000000001Z\",\"price_level\":\"50001.00\",\"new_quantity\":\"1.00000000\"}]}]}"}
{"local_receipt_timestamp_ns":1704067200000001172,"raw_payload":"{\"channel\":\"l2_data\",\"sequence_num\":117,\"events\":[{\"updates\":[{\"side\":\"bid\",\"event_time\":\"2024-01-01T00:00:00.000000001Z\",\"price_level\":\"50000.00\",\"new_quantity\":\"1.00000000\"}]}]}"}
{"local_receipt_timestamp_ns":1704067200000001182,"raw_payload":"{\"channel\":\"l2_data\",\"sequence_num\":118,\"events\":[{\"updates\":[{\"side\":\"offer\",\"event_time\":\"2024-01-01T00:00:00.000000001Z\",\"price_level\":\"50001.00\",\"new_quantity\":\"1.00000000\"}]}]}"}
{"local_receipt_timestamp_ns":1704067200000001192,"raw_payload":"{\"channel\":\"l2_data\",\"sequence_num\":119,\"events\":[{\"updates\":[{\"side\":\"bid\",\"event_time\":\"2024-01-01T00:00:00.000000001Z\",\"price_level\":\"50000.00\",\"new_quantity\":\"1.00000000\"}]}]}"}
{"local_receipt_timestamp_ns":1704067200000001202,"raw_payload":"{\"channel\":\"l2_data\",\"sequence_num\":120,\"events\":[{\"updates\":[{\"side\":\"offer\",\"event_time\":\"2024-01-01T00:00:00.000000001Z\",\"price_level\":\"50001.00\",\"new_quantity\":\"1.00000000\"}]}]}"}
{"local_receipt_timestamp_ns":1704067200000001212,"raw_payload":"{\"channel\":\"l2_data\",\"sequence_num\":121,\"events\":[{\"updates\":[{\"side\":\"bid\",\"event_time\":\"2024-01-01T00:00:00.000000001Z\",\"price_level\":\"50000.00\",\"new_quantity\":\"1.00000000\"}]}]}"}
{"local_receipt_timestamp_ns":1704067200000001222,"raw_payload":"{\"channel\":\"l2_data\",\"sequence_num\":122,\"events\":[{\"updates\":[{\"side\":\"offer\",\"event_time\":\"2024-01-01T00:00:00.000000001Z\",\"price_level\":\"50001.00\",\"new_quantity\":\"1.00000000\"}]}]}"}
{"local_receipt_timestamp_ns":1704067200000001232,"raw_payload":"{\"channel\":\"l2_data\",\"sequence_num\":123,\"events\":[{\"updates\":[{\"side\":\"bid\",\"event_time\":\"2024-01-01T00:00:00.000000001Z\",\"price_level\":\"50000.00\",\"new_quantity\":\"1.00000000\"}]}]}"}
{"local_receipt_timestamp_ns":1704067200000001242,"raw_payload":"{\"channel\":\"l2_data\",\"sequence_num\":124,\"events\":[{\"updates\":[{\"side\":\"offer\",\"event_time\":\"2024-01-01T00:00:00.000000001Z\",\"price_level\":\"50001.00\",\"new_quantity\":\"1.00000000\"}]}]}"}
{"local_receipt_timestamp_ns":1704067200000001252,"raw_payload":"{\"channel\":\"l2_data\",\"sequence_num\":125,\"events\":[{\"updates\":[{\"side\":\"bid\",\"event_time\":\"2024-01-01T00:00:00.000000001Z\",\"price_level\":\"50000.00\",\"new_quantity\":\"1.00000000\"}]}]}"}
{"local_receipt_timestamp_ns":1704067200000001262,"raw_payload":"{\"channel\":\"l2_data\",\"sequence_num\":126,\"events\":[{\"updates\":[{\"side\":\"offer\",\"event_time\":\"2024-01-01T00:00:00.000000001Z\",\"price_level\":\"50001.00\",\"new_quantity\":\"1.00000000\"}]}]}"}
{"local_receipt_timestamp_ns":1704067200000001272,"raw_payload":"{\"channel\":\"l2_data\",\"sequence_num\":127,\"events\":[{\"updates\":[{\"side\":\"bid\",\"event_time\":\"2024-01-01T00:00:00.000000001Z\",\"price_level\":\"50000.00\",\"new_quantity\":\"1.00000000\"}]}]}"}
{"local_receipt_timestamp_ns":1704067200000001282,"raw_payload":"{\"channel\":\"l2_data\",\"sequence_num\":128,\"events\":[{\"updates\":[{\"side\":\"offer\",\"event_time\":\"2024-01-01T00:00:00.000000001Z\",\"price_level\":\"50001.00\",\"new_quantity\":\"1.00000000\"}]}]}"}
{"local_receipt_timestamp_ns":1704067200000001292,"raw_payload":"{\"channel\":\"l2_data\",\"sequence_num\":129,\"events\":[{\"updates\":[{\"side\":\"bid\",\"event_time\":\"2024-01-01T00:00:00.000000001Z\",\"price_level\":\"50000.00\",\"new_quantity\":\"1.00000000\"}]}]}"}
{"local_receipt_timestamp_ns":1704067200000001302,"raw_payload":"{\"channel\":\"l2_data\",\"sequence_num\":130,\"events\":[{\"updates\":[{\"side\":\"offer\",\"event_time\":\"2024-01-01T00:00:00.000000001Z\",\"price_level\":\"50001.00\",\"new_quantity\":\"1.00000000\"}]}]}"}
{"local_receipt_timestamp_ns":1704067200000001312,"raw_payload":"{\"channel\":\"l2_data\",\"sequence_num\":131,\"events\":[{\"updates\":[{\"side\":\"bid\",\"event_time\":\"2024-01-01T00:00:00.000000001Z\",\"price_level\":\"50000.00\",\"new_quantity\":\"1.00000000\"}]}]}"}
{"local_receipt_timestamp_ns":1704067200000001322,"raw_payload":"{\"channel\":\"l2_data\",\"sequence_num\":132,\"events\":[{\"updates\":[{\"side\":\"offer\",\"event_time\":\"2024-01-01T00:00:00.000000001Z\",\"price_level\":\"50001.00\",\"new_quantity\":\"1.00000000\"}]}]}"}
{"local_receipt_timestamp_ns":1704067200000001332,"raw_payload":"{\"channel\":\"l2_data\",\"sequence_num\":133,\"events\":[{\"updates\":[{\"side\":\"bid\",\"event_time\":\"2024-01-01T00:00:00.000000001Z\",\"price_level\":\"50000.00\",\"new_quantity\":\"1.00000000\"}]}]}"}
{"local_receipt_timestamp_ns":1704067200000001342,"raw_payload":"{\"channel\":\"l2_data\",\"sequence_num\":134,\"events\":[{\"updates\":[{\"side\":\"offer\",\"event_time\":\"2024-01-01T00:00:00.000000001Z\",\"price_level\":\"50001.00\",\"new_quantity\":\"1.00000000\"}]}]}"}
{"local_receipt_timestamp_ns":1704067200000001352,"raw_payload":"{\"channel\":\"l2_data\",\"sequence_num\":135,\"events\":[{\"updates\":[{\"side\":\"bid\",\"event_time\":\"2024-01-01T00:00:00.000000001Z\",\"price_level\":\"50000.00\",\"new_quantity\":\"1.00000000\"}]}]}"}
{"local_receipt_timestamp_ns":1704067200000001362,"raw_payload":"{\"channel\":\"l2_data\",\"sequence_num\":136,\"events\":[{\"updates\":[{\"side\":\"offer\",\"event_time\":\"2024-01-01T00:00:00.000000001Z\",\"price_level\":\"50001.00\",\"new_quantity\":\"1.00000000\"}]}]}"}
{"local_receipt_timestamp_ns":1704067200000001372,"raw_payload":"{\"channel\":\"l2_data\",\"sequence_num\":137,\"events\":[{\"updates\":[{\"side\":\"bid\",\"event_time\":\"2024-01-01T00:00:00.000000001Z\",\"price_level\":\"50000.00\",\"new_quantity\":\"1.00000000\"}]}]}"}
{"local_receipt_timestamp_ns":1704067200000001382,"raw_payload":"{\"channel\":\"l2_data\",\"sequence_num\":138,\"events\":[{\"updates\":[{\"side\":\"offer\",\"event_time\":\"2024-01-01T00:00:00.000000001Z\",\"price_level\":\"50001.00\",\"new_quantity\":\"1.00000000\"}]}]}"}
{"local_receipt_timestamp_ns":1704067200000001392,"raw_payload":"{\"channel\":\"l2_data\",\"sequence_num\":139,\"events\":[{\"updates\":[{\"side\":\"bid\",\"event_time\":\"2024-01-01T00:00:00.000000001Z\",\"price_level\":\"50000.00\",\"new_quantity\":\"1.00000000\"}]}]}"}
{"local_receipt_timestamp_ns":1704067200000001402,"raw_payload":"{\"channel\":\"l2_data\",\"sequence_num\":140,\"events\":[{\"updates\":[{\"side\":\"offer\",\"event_time\":\"2024-01-01T00:00:00.000000001Z\",\"price_level\":\"50001.00\",\"new_quantity\":\"1.00000000\"}]}]}"}
{"local_receipt_timestamp_ns":1704067200000001412,"raw_payload":"{\"channel\":\"l2_data\",\"sequence_num\":141,\"events\":[{\"updates\":[{\"side\":\"bid\",\"event_time\":\"2024-01-01T00:00:00.000000001Z\",\"price_level\":\"50000.00\",\"new_quantity\":\"1.00000000\"}]}]}"}
{"local_receipt_timestamp_ns":1704067200000001422,"raw_payload":"{\"channel\":\"l2_data\",\"sequence_num\":142,\"events\":[{\"updates\":[{\"side\":\"offer\",\"event_time\":\"2024-01-01T00:00:00.000000001Z\",\"price_level\":\"50001.00\",\"new_quantity\":\"1.00000000\"}]}]}"}
{"local_receipt_timestamp_ns":1704067200000001432,"raw_payload":"{\"channel\":\"l2_data\",\"sequence_num\":143,\"events\":[{\"updates\":[{\"side\":\"bid\",\"event_time\":\"2024-01-01T00:00:00.000000001Z\",\"price_level\":\"50000.00\",\"new_quantity\":\"1.00000000\"}]}]}"}
{"local_receipt_timestamp_ns":1704067200000001442,"raw_payload":"{\"channel\":\"l2_data\",\"sequence_num\":144,\"events\":[{\"updates\":[{\"side\":\"offer\",\"event_time\":\"2024-01-01T00:00:00.000000001Z\",\"price_level\":\"50001.00\",\"new_quantity\":\"1.00000000\"}]}]}"}
{"local_receipt_timestamp_ns":1704067200000001452,"raw_payload":"{\"channel\":\"l2_data\",\"sequence_num\":145,\"events\":[{\"updates\":[{\"side\":\"bid\",\"event_time\":\"2024-01-01T00:00:00.000000001Z\",\"price_level\":\"50000.00\",\"new_quantity\":\"1.00000000\"}]}]}"}
{"local_receipt_timestamp_ns":1704067200000001462,"raw_payload":"{\"channel\":\"l2_data\",\"sequence_num\":146,\"events\":[{\"updates\":[{\"side\":\"offer\",\"event_time\":\"2024-01-01T00:00:00.000000001Z\",\"price_level\":\"50001.00\",\"new_quantity\":\"1.00000000\"}]}]}"}
{"local_receipt_timestamp_ns":1704067200000001472,"raw_payload":"{\"channel\":\"l2_data\",\"sequence_num\":147,\"events\":[{\"updates\":[{\"side\":\"bid\",\"event_time\":\"2024-01-01T00:00:00.000000001Z\",\"price_level\":\"50000.00\",\"new_quantity\":\"1.00000000\"}]}]}"}
{"local_receipt_timestamp_ns":1704067200000001482,"raw_payload":"{\"channel\":\"l2_data\",\"sequence_num\":148,\"events\":[{\"updates\":[{\"side\":\"offer\",\"event_time\":\"2024-01-01T00:00:00.000000001Z\",\"price_level\":\"50001.00\",\"new_quantity\":\"1.00000000\"}]}]}"}
{"local_receipt_timestamp_ns":1704067200000001492,"raw_payload":"{\"channel\":\"l2_data\",\"sequence_num\":149,\"events\":[{\"updates\":[{\"side\":\"bid\",\"event_time\":\"2024-01-01T00:00:00.000000001Z\",\"price_level\":\"50000.00\",\"new_quantity\":\"1.00000000\"}]}]}"}
{"local_receipt_timestamp_ns":1704067200000001502,"raw_payload":"{\"channel\":\"l2_data\",\"sequence_num\":150,\"events\":[{\"updates\":[{\"side\":\"offer\",\"event_time\":\"2024-01-01T00:00:00.000000001Z\",\"price_level\":\"50001.00\",\"new_quantity\":\"1.00000000\"}]}]}"}
{"local_receipt_timestamp_ns":1704067200000001512,"raw_payload":"{\"channel\":\"l2_data\",\"sequence_num\":151,\"events\":[{\"updates\":[{\"side\":\"bid\",\"event_time\":\"2024-01-01T00:00:00.000000001Z\",\"price_level\":\"50000.00\",\"new_quantity\":\"1.00000000\"}]}]}"}
{"local_receipt_timestamp_ns":1704067200000001522,"raw_payload":"{\"channel\":\"l2_data\",\"sequence_num\":152,\"events\":[{\"updates\":[{\"side\":\"offer\",\"event_time\":\"2024-01-01T00:00:00.000000001Z\",\"price_level\":\"50001.00\",\"new_quantity\":\"1.00000000\"}]}]}"}
{"local_receipt_timestamp_ns":1704067200000001532,"raw_payload":"{\"channel\":\"l2_data\",\"sequence_num\":153,\"events\":[{\"updates\":[{\"side\":\"bid\",\"event_time\":\"2024-01-01T00:00:00.000000001Z\",\"price_level\":\"50000.00\",\"new_quantity\":\"1.00000000\"}]}]}"}
{"local_receipt_timestamp_ns":1704067200000001542,"raw_payload":"{\"channel\":\"l2_data\",\"sequence_num\":154,\"events\":[{\"updates\":[{\"side\":\"offer\",\"event_time\":\"2024-01-01T00:00:00.000000001Z\",\"price_level\":\"50001.00\",\"new_quantity\":\"1.00000000\"}]}]}"}
{"local_receipt_timestamp_ns":1704067200000001552,"raw_payload":"{\"channel\":\"l2_data\",\"sequence_num\":155,\"events\":[{\"updates\":[{\"side\":\"bid\",\"event_time\":\"2024-01-01T00:00:00.000000001Z\",\"price_level\":\"50000.00\",\"new_quantity\":\"1.00000000\"}]}]}"}
{"local_receipt_timestamp_ns":1704067200000001562,"raw_payload":"{\"channel\":\"l2_data\",\"sequence_num\":156,\"events\":[{\"updates\":[{\"side\":\"offer\",\"event_time\":\"2024-01-01T00:00:00.000000001Z\",\"price_level\":\"50001.00\",\"new_quantity\":\"1.00000000\"}]}]}"}
{"local_receipt_timestamp_ns":1704067200000001572,"raw_payload":"{\"channel\":\"l2_data\",\"sequence_num\":157,\"events\":[{\"updates\":[{\"side\":\"bid\",\"event_time\":\"2024-01-01T00:00:00.000000001Z\",\"price_level\":\"50000.00\",\"new_quantity\":\"1.00000000\"}]}]}"}
{"local_receipt_timestamp_ns":1704067200000001582,"raw_payload":"{\"channel\":\"l2_data\",\"sequence_num\":158,\"events\":[{\"updates\":[{\"side\":\"offer\",\"event_time\":\"2024-01-01T00:00:00.000000001Z\",\"price_level\":\"50001.00\",\"new_quantity\":\"1.00000000\"}]}]}"}
{"local_receipt_timestamp_ns":1704067200000001592,"raw_payload":"{\"channel\":\"l2_data\",\"sequence_num\":159,\"events\":[{\"updates\":[{\"side\":\"bid\",\"event_time\":\"2024-01-01T00:00:00.000000001Z\",\"price_level\":\"50000.00\",\"new_quantity\":\"1.00000000\"}]}]}"}
{"local_receipt_timestamp_ns":1704067200000001602,"raw_payload":"{\"channel\":\"l2_data\",\"sequence_num\":160,\"events\":[{\"updates\":[{\"side\":\"offer\",\"event_time\":\"2024-01-01T00:00:00.000000001Z\",\"price_level\":\"50001.00\",\"new_quantity\":\"1.00000000\"}]}]}"}
{"local_receipt_timestamp_ns":1704067200000001612,"raw_payload":"{\"channel\":\"l2_data\",\"sequence_num\":161,\"events\":[{\"updates\":[{\"side\":\"bid\",\"event_time\":\"2024-01-01T00:00:00.000000001Z\",\"price_level\":\"50000.00\",\"new_quantity\":\"1.00000000\"}]}]}"}
{"local_receipt_timestamp_ns":1704067200000001622,"raw_payload":"{\"channel\":\"l2_data\",\"sequence_num\":162,\"events\":[{\"updates\":[{\"side\":\"offer\",\"event_time\":\"2024-01-01T00:00:00.000000001Z\",\"price_level\":\"50001.00\",\"new_quantity\":\"1.00000000\"}]}]}"}
{"local_receipt_timestamp_ns":1704067200000001632,"raw_payload":"{\"channel\":\"l2_data\",\"sequence_num\":163,\"events\":[{\"updates\":[{\"side\":\"bid\",\"event_time\":\"2024-01-01T00:00:00.000000001Z\",\"price_level\":\"50000.00\",\"new_quantity\":\"1.00000000\"}]}]}"}
{"local_receipt_timestamp_ns":1704067200000001642,"raw_payload":"{\"channel\":\"l2_data\",\"sequence_num\":164,\"events\":[{\"updates\":[{\"side\":\"offer\",\"event_time\":\"2024-01-01T00:00:00.000000001Z\",\"price_level\":\"50001.00\",\"new_quantity\":\"1.00000000\"}]}]}"}
{"local_receipt_timestamp_ns":1704067200000001652,"raw_payload":"{\"channel\":\"l2_data\",\"sequence_num\":165,\"events\":[{\"updates\":[{\"side\":\"bid\",\"event_time\":\"2024-01-01T00:00:00.000000001Z\",\"price_level\":\"50000.00\",\"new_quantity\":\"1.00000000\"}]}]}"}
{"local_receipt_timestamp_ns":1704067200000001662,"raw_payload":"{\"channel\":\"l2_data\",\"sequence_num\":166,\"events\":[{\"updates\":[{\"side\":\"offer\",\"event_time\":\"2024-01-01T00:00:00.000000001Z\",\"price_level\":\"50001.00\",\"new_quantity\":\"1.00000000\"}]}]}"}
{"local_receipt_timestamp_ns":1704067200000001672,"raw_payload":"{\"channel\":\"l2_data\",\"sequence_num\":167,\"events\":[{\"updates\":[{\"side\":\"bid\",\"event_time\":\"2024-01-01T00:00:00.000000001Z\",\"price_level\":\"50000.00\",\"new_quantity\":\"1.00000000\"}]}]}"}
{"local_receipt_timestamp_ns":1704067200000001682,"raw_payload":"{\"channel\":\"l2_data\",\"sequence_num\":168,\"events\":[{\"updates\":[{\"side\":\"offer\",\"event_time\":\"2024-01-01T00:00:00.000000001Z\",\"price_level\":\"50001.00\",\"new_quantity\":\"1.00000000\"}]}]}"}
{"local_receipt_timestamp_ns":1704067200000001692,"raw_payload":"{\"channel\":\"l2_data\",\"sequence_num\":169,\"events\":[{\"updates\":[{\"side\":\"bid\",\"event_time\":\"2024-01-01T00:00:00.000000001Z\",\"price_level\":\"50000.00\",\"new_quantity\":\"1.00000000\"}]}]}"}
{"local_receipt_timestamp_ns":1704067200000001702,"raw_payload":"{\"channel\":\"l2_data\",\"sequence_num\":170,\"events\":[{\"updates\":[{\"side\":\"offer\",\"event_time\":\"2024-01-01T00:00:00.000000001Z\",\"price_level\":\"50001.00\",\"new_quantity\":\"1.00000000\"}]}]}"}
{"local_receipt_timestamp_ns":1704067200000001712,"raw_payload":"{\"channel\":\"l2_data\",\"sequence_num\":171,\"events\":[{\"updates\":[{\"side\":\"bid\",\"event_time\":\"2024-01-01T00:00:00.000000001Z\",\"price_level\":\"50000.00\",\"new_quantity\":\"1.00000000\"}]}]}"}
{"local_receipt_timestamp_ns":1704067200000001722,"raw_payload":"{\"channel\":\"l2_data\",\"sequence_num\":172,\"events\":[{\"updates\":[{\"side\":\"offer\",\"event_time\":\"2024-01-01T00:00:00.000000001Z\",\"price_level\":\"50001.00\",\"new_quantity\":\"1.00000000\"}]}]}"}
{"local_receipt_timestamp_ns":1704067200000001732,"raw_payload":"{\"channel\":\"l2_data\",\"sequence_num\":173,\"events\":[{\"updates\":[{\"side\":\"bid\",\"event_time\":\"2024-01-01T00:00:00.000000001Z\",\"price_level\":\"50000.00\",\"new_quantity\":\"1.00000000\"}]}]}"}
{"local_receipt_timestamp_ns":1704067200000001742,"raw_payload":"{\"channel\":\"l2_data\",\"sequence_num\":174,\"events\":[{\"updates\":[{\"side\":\"offer\",\"event_time\":\"2024-01-01T00:00:00.000000001Z\",\"price_level\":\"50001.00\",\"new_quantity\":\"1.00000000\"}]}]}"}
{"local_receipt_timestamp_ns":1704067200000001752,"raw_payload":"{\"channel\":\"l2_data\",\"sequence_num\":175,\"events\":[{\"updates\":[{\"side\":\"bid\",\"event_time\":\"2024-01-01T00:00:00.000000001Z\",\"price_level\":\"50000.00\",\"new_quantity\":\"1.00000000\"}]}]}"}
{"local_receipt_timestamp_ns":1704067200000001762,"raw_payload":"{\"channel\":\"l2_data\",\"sequence_num\":176,\"events\":[{\"updates\":[{\"side\":\"offer\",\"event_time\":\"2024-01-01T00:00:00.000000001Z\",\"price_level\":\"50001.00\",\"new_quantity\":\"1.00000000\"}]}]}"}
{"local_receipt_timestamp_ns":1704067200000001772,"raw_payload":"{\"channel\":\"l2_data\",\"sequence_num\":177,\"events\":[{\"updates\":[{\"side\":\"bid\",\"event_time\":\"2024-01-01T00:00:00.000000001Z\",\"price_level\":\"50000.00\",\"new_quantity\":\"1.00000000\"}]}]}"}
{"local_receipt_timestamp_ns":1704067200000001782,"raw_payload":"{\"channel\":\"l2_data\",\"sequence_num\":178,\"events\":[{\"updates\":[{\"side\":\"offer\",\"event_time\":\"2024-01-01T00:00:00.000000001Z\",\"price_level\":\"50001.00\",\"new_quantity\":\"1.00000000\"}]}]}"}
{"local_receipt_timestamp_ns":1704067200000001792,"raw_payload":"{\"channel\":\"l2_data\",\"sequence_num\":179,\"events\":[{\"updates\":[{\"side\":\"bid\",\"event_time\":\"2024-01-01T00:00:00.000000001Z\",\"price_level\":\"50000.00\",\"new_quantity\":\"1.00000000\"}]}]}"}
{"local_receipt_timestamp_ns":1704067200000001802,"raw_payload":"{\"channel\":\"l2_data\",\"sequence_num\":180,\"events\":[{\"updates\":[{\"side\":\"offer\",\"event_time\":\"2024-01-01T00:00:00.000000001Z\",\"price_level\":\"50001.00\",\"new_quantity\":\"1.00000000\"}]}]}"}
{"local_receipt_timestamp_ns":1704067200000001812,"raw_payload":"{\"channel\":\"l2_data\",\"sequence_num\":181,\"events\":[{\"updates\":[{\"side\":\"bid\",\"event_time\":\"2024-01-01T00:00:00.000000001Z\",\"price_level\":\"50000.00\",\"new_quantity\":\"1.00000000\"}]}]}"}
{"local_receipt_timestamp_ns":1704067200000001822,"raw_payload":"{\"channel\":\"l2_data\",\"sequence_num\":182,\"events\":[{\"updates\":[{\"side\":\"offer\",\"event_time\":\"2024-01-01T00:00:00.000000001Z\",\"price_level\":\"50001.00\",\"new_quantity\":\"1.00000000\"}]}]}"}
{"local_receipt_timestamp_ns":1704067200000001832,"raw_payload":"{\"channel\":\"l2_data\",\"sequence_num\":183,\"events\":[{\"updates\":[{\"side\":\"bid\",\"event_time\":\"2024-01-01T00:00:00.000000001Z\",\"price_level\":\"50000.00\",\"new_quantity\":\"1.00000000\"}]}]}"}
{"local_receipt_timestamp_ns":1704067200000001842,"raw_payload":"{\"channel\":\"l2_data\",\"sequence_num\":184,\"events\":[{\"updates\":[{\"side\":\"offer\",\"event_time\":\"2024-01-01T00:00:00.000000001Z\",\"price_level\":\"50001.00\",\"new_quantity\":\"1.00000000\"}]}]}"}
{"local_receipt_timestamp_ns":1704067200000001852,"raw_payload":"{\"channel\":\"l2_data\",\"sequence_num\":185,\"events\":[{\"updates\":[{\"side\":\"bid\",\"event_time\":\"2024-01-01T00:00:00.000000001Z\",\"price_level\":\"50000.00\",\"new_quantity\":\"1.00000000\"}]}]}"}
{"local_receipt_timestamp_ns":1704067200000001862,"raw_payload":"{\"channel\":\"l2_data\",\"sequence_num\":186,\"events\":[{\"updates\":[{\"side\":\"offer\",\"event_time\":\"2024-01-01T00:00:00.000000001Z\",\"price_level\":\"50001.00\",\"new_quantity\":\"1.00000000\"}]}]}"}
{"local_receipt_timestamp_ns":1704067200000001872,"raw_payload":"{\"channel\":\"l2_data\",\"sequence_num\":187,\"events\":[{\"updates\":[{\"side\":\"bid\",\"event_time\":\"2024-01-01T00:00:00.000000001Z\",\"price_level\":\"50000.00\",\"new_quantity\":\"1.00000000\"}]}]}"}
{"local_receipt_timestamp_ns":1704067200000001882,"raw_payload":"{\"channel\":\"l2_data\",\"sequence_num\":188,\"events\":[{\"updates\":[{\"side\":\"offer\",\"event_time\":\"2024-01-01T00:00:00.000000001Z\",\"price_level\":\"50001.00\",\"new_quantity\":\"1.00000000\"}]}]}"}
{"local_receipt_timestamp_ns":1704067200000001892,"raw_payload":"{\"channel\":\"l2_data\",\"sequence_num\":189,\"events\":[{\"updates\":[{\"side\":\"bid\",\"event_time\":\"2024-01-01T00:00:00.000000001Z\",\"price_level\":\"50000.00\",\"new_quantity\":\"1.00000000\"}]}]}"}
{"local_receipt_timestamp_ns":1704067200000001902,"raw_payload":"{\"channel\":\"l2_data\",\"sequence_num\":190,\"events\":[{\"updates\":[{\"side\":\"offer\",\"event_time\":\"2024-01-01T00:00:00.000000001Z\",\"price_level\":\"50001.00\",\"new_quantity\":\"1.00000000\"}]}]}"}
{"local_receipt_timestamp_ns":1704067200000001912,"raw_payload":"{\"channel\":\"l2_data\",\"sequence_num\":191,\"events\":[{\"updates\":[{\"side\":\"bid\",\"event_time\":\"2024-01-01T00:00:00.000000001Z\",\"price_level\":\"50000.00\",\"new_quantity\":\"1.00000000\"}]}]}"}
{"local_receipt_timestamp_ns":1704067200000001922,"raw_payload":"{\"channel\":\"l2_data\",\"sequence_num\":192,\"events\":[{\"updates\":[{\"side\":\"offer\",\"event_time\":\"2024-01-01T00:00:00.000000001Z\",\"price_level\":\"50001.00\",\"new_quantity\":\"1.00000000\"}]}]}"}
{"local_receipt_timestamp_ns":1704067200000001932,"raw_payload":"{\"channel\":\"l2_data\",\"sequence_num\":193,\"events\":[{\"updates\":[{\"side\":\"bid\",\"event_time\":\"2024-01-01T00:00:00.000000001Z\",\"price_level\":\"50000.00\",\"new_quantity\":\"1.00000000\"}]}]}"}
{"local_receipt_timestamp_ns":1704067200000001942,"raw_payload":"{\"channel\":\"l2_data\",\"sequence_num\":194,\"events\":[{\"updates\":[{\"side\":\"offer\",\"event_time\":\"2024-01-01T00:00:00.000000001Z\",\"price_level\":\"50001.00\",\"new_quantity\":\"1.00000000\"}]}]}"}
{"local_receipt_timestamp_ns":1704067200000001952,"raw_payload":"{\"channel\":\"l2_data\",\"sequence_num\":195,\"events\":[{\"updates\":[{\"side\":\"bid\",\"event_time\":\"2024-01-01T00:00:00.000000001Z\",\"price_level\":\"50000.00\",\"new_quantity\":\"1.00000000\"}]}]}"}
{"local_receipt_timestamp_ns":1704067200000001962,"raw_payload":"{\"channel\":\"l2_data\",\"sequence_num\":196,\"events\":[{\"updates\":[{\"side\":\"offer\",\"event_time\":\"2024-01-01T00:00:00.000000001Z\",\"price_level\":\"50001.00\",\"new_quantity\":\"1.00000000\"}]}]}"}
{"local_receipt_timestamp_ns":1704067200000001972,"raw_payload":"{\"channel\":\"l2_data\",\"sequence_num\":197,\"events\":[{\"updates\":[{\"side\":\"bid\",\"event_time\":\"2024-01-01T00:00:00.000000001Z\",\"price_level\":\"50000.00\",\"new_quantity\":\"1.00000000\"}]}]}"}
{"local_receipt_timestamp_ns":1704067200000001982,"raw_payload":"{\"channel\":\"l2_data\",\"sequence_num\":198,\"events\":[{\"updates\":[{\"side\":\"offer\",\"event_time\":\"2024-01-01T00:00:00.000000001Z\",\"price_level\":\"50001.00\",\"new_quantity\":\"1.00000000\"}]}]}"}
{"local_receipt_timestamp_ns":1704067200000001992,"raw_payload":"{\"channel\":\"l2_data\",\"sequence_num\":199,\"events\":[{\"updates\":[{\"side\":\"bid\",\"event_time\":\"2024-01-01T00:00:00.000000001Z\",\"price_level\":\"50000.00\",\"new_quantity\":\"1.00000000\"}]}]}"}
{"local_receipt_timestamp_ns":1704067200000002002,"raw_payload":"{\"channel\":\"l2_data\",\"sequence_num\":200,\"events\":[{\"updates\":[{\"side\":\"offer\",\"event_time\":\"2024-01-01T00:00:00.000000001Z\",\"price_level\":\"50001.00\",\"new_quantity\":\"1.00000000\"}]}]}"}
{"local_receipt_timestamp_ns":1704067200000002012,"raw_payload":"{\"channel\":\"l2_data\",\"sequence_num\":201,\"events\":[{\"updates\":[{\"side\":\"bid\",\"event_time\":\"2024-01-01T00:00:00.000000001Z\",\"price_level\":\"50000.00\",\"new_quantity\":\"1.00000000\"}]}]}"}
{"local_receipt_timestamp_ns":1704067200000002022,"raw_payload":"{\"channel\":\"l2_data\",\"sequence_num\":202,\"events\":[{\"updates\":[{\"side\":\"offer\",\"event_time\":\"2024-01-01T00:00:00.000000001Z\",\"price_level\":\"50001.00\",\"new_quantity\":\"1.00000000\"}]}]}"}
{"local_receipt_timestamp_ns":1704067200000002032,"raw_payload":"{\"channel\":\"l2_data\",\"sequence_num\":203,\"events\":[{\"updates\":[{\"side\":\"bid\",\"event_time\":\"2024-01-01T00:00:00.000000001Z\",\"price_level\":\"50000.00\",\"new_quantity\":\"1.00000000\"}]}]}"}
{"local_receipt_timestamp_ns":1704067200000002042,"raw_payload":"{\"channel\":\"l2_data\",\"sequence_num\":204,\"events\":[{\"updates\":[{\"side\":\"offer\",\"event_time\":\"2024-01-01T00:00:00.000000001Z\",\"price_level\":\"50001.00\",\"new_quantity\":\"1.00000000\"}]}]}"}
{"local_receipt_timestamp_ns":1704067200000002052,"raw_payload":"{\"channel\":\"l2_data\",\"sequence_num\":205,\"events\":[{\"updates\":[{\"side\":\"bid\",\"event_time\":\"2024-01-01T00:00:00.000000001Z\",\"price_level\":\"50000.00\",\"new_quantity\":\"1.00000000\"}]}]}"}
{"local_receipt_timestamp_ns":1704067200000002062,"raw_payload":"{\"channel\":\"l2_data\",\"sequence_num\":206,\"events\":[{\"updates\":[{\"side\":\"offer\",\"event_time\":\"2024-01-01T00:00:00.000000001Z\",\"price_level\":\"50001.00\",\"new_quantity\":\"1.00000000\"}]}]}"}
{"local_receipt_timestamp_ns":1704067200000002072,"raw_payload":"{\"channel\":\"l2_data\",\"sequence_num\":207,\"events\":[{\"updates\":[{\"side\":\"bid\",\"event_time\":\"2024-01-01T00:00:00.000000001Z\",\"price_level\":\"50000.00\",\"new_quantity\":\"1.00000000\"}]}]}"}
{"local_receipt_timestamp_ns":1704067200000002082,"raw_payload":"{\"channel\":\"l2_data\",\"sequence_num\":208,\"events\":[{\"updates\":[{\"side\":\"offer\",\"event_time\":\"2024-01-01T00:00:00.000000001Z\",\"price_level\":\"50001.00\",\"new_quantity\":\"1.00000000\"}]}]}"}
{"local_receipt_timestamp_ns":1704067200000002092,"raw_payload":"{\"channel\":\"l2_data\",\"sequence_num\":209,\"events\":[{\"updates\":[{\"side\":\"bid\",\"event_time\":\"2024-01-01T00:00:00.000000001Z\",\"price_level\":\"50000.00\",\"new_quantity\":\"1.00000000\"}]}]}"}
{"local_receipt_timestamp_ns":1704067200000002102,"raw_payload":"{\"channel\":\"l2_data\",\"sequence_num\":210,\"events\":[{\"updates\":[{\"side\":\"offer\",\"event_time\":\"2024-01-01T00:00:00.000000001Z\",\"price_level\":\"50001.00\",\"new_quantity\":\"1.00000000\"}]}]}"}
{"local_receipt_timestamp_ns":1704067200000002112,"raw_payload":"{\"channel\":\"l2_data\",\"sequence_num\":211,\"events\":[{\"updates\":[{\"side\":\"bid\",\"event_time\":\"2024-01-01T00:00:00.000000001Z\",\"price_level\":\"50000.00\",\"new_quantity\":\"1.00000000\"}]}]}"}
{"local_receipt_timestamp_ns":1704067200000002122,"raw_payload":"{\"channel\":\"l2_data\",\"sequence_num\":212,\"events\":[{\"updates\":[{\"side\":\"offer\",\"event_time\":\"2024-01-01T00:00:00.000000001Z\",\"price_level\":\"50001.00\",\"new_quantity\":\"1.00000000\"}]}]}"}
{"local_receipt_timestamp_ns":1704067200000002132,"raw_payload":"{\"channel\":\"l2_data\",\"sequence_num\":213,\"events\":[{\"updates\":[{\"side\":\"bid\",\"event_time\":\"2024-01-01T00:00:00.000000001Z\",\"price_level\":\"50000.00\",\"new_quantity\":\"1.00000000\"}]}]}"}
{"local_receipt_timestamp_ns":1704067200000002142,"raw_payload":"{\"channel\":\"l2_data\",\"sequence_num\":214,\"events\":[{\"updates\":[{\"side\":\"offer\",\"event_time\":\"2024-01-01T00:00:00.000000001Z\",\"price_level\":\"50001.00\",\"new_quantity\":\"1.00000000\"}]}]}"}
{"local_receipt_timestamp_ns":1704067200000002152,"raw_payload":"{\"channel\":\"l2_data\",\"sequence_num\":215,\"events\":[{\"updates\":[{\"side\":\"bid\",\"event_time\":\"2024-01-01T00:00:00.000000001Z\",\"price_level\":\"50000.00\",\"new_quantity\":\"1.00000000\"}]}]}"}
{"local_receipt_timestamp_ns":1704067200000002162,"raw_payload":"{\"channel\":\"l2_data\",\"sequence_num\":216,\"events\":[{\"updates\":[{\"side\":\"offer\",\"event_time\":\"2024-01-01T00:00:00.000000001Z\",\"price_level\":\"50001.00\",\"new_quantity\":\"1.00000000\"}]}]}"}
{"local_receipt_timestamp_ns":1704067200000002172,"raw_payload":"{\"channel\":\"l2_data\",\"sequence_num\":217,\"events\":[{\"updates\":[{\"side\":\"bid\",\"event_time\":\"2024-01-01T00:00:00.000000001Z\",\"price_level\":\"50000.00\",\"new_quantity\":\"1.00000000\"}]}]}"}
{"local_receipt_timestamp_ns":1704067200000002182,"raw_payload":"{\"channel\":\"l2_data\",\"sequence_num\":218,\"events\":[{\"updates\":[{\"side\":\"offer\",\"event_time\":\"2024-01-01T00:00:00.000000001Z\",\"price_level\":\"50001.00\",\"new_quantity\":\"1.00000000\"}]}]}"}
{"local_receipt_timestamp_ns":1704067200000002192,"raw_payload":"{\"channel\":\"l2_data\",\"sequence_num\":219,\"events\":[{\"updates\":[{\"side\":\"bid\",\"event_time\":\"2024-01-01T00:00:00.000000001Z\",\"price_level\":\"50000.00\",\"new_quantity\":\"1.00000000\"}]}]}"}
{"local_receipt_timestamp_ns":1704067200000002202,"raw_payload":"{\"channel\":\"l2_data\",\"sequence_num\":220,\"events\":[{\"updates\":[{\"side\":\"offer\",\"event_time\":\"2024-01-01T00:00:00.000000001Z\",\"price_level\":\"50001.00\",\"new_quantity\":\"1.00000000\"}]}]}"}
{"local_receipt_timestamp_ns":1704067200000002212,"raw_payload":"{\"channel\":\"l2_data\",\"sequence_num\":221,\"events\":[{\"updates\":[{\"side\":\"bid\",\"event_time\":\"2024-01-01T00:00:00.000000001Z\",\"price_level\":\"50000.00\",\"new_quantity\":\"1.00000000\"}]}]}"}
{"local_receipt_timestamp_ns":1704067200000002222,"raw_payload":"{\"channel\":\"l2_data\",\"sequence_num\":222,\"events\":[{\"updates\":[{\"side\":\"offer\",\"event_time\":\"2024-01-01T00:00:00.000000001Z\",\"price_level\":\"50001.00\",\"new_quantity\":\"1.00000000\"}]}]}"}
{"local_receipt_timestamp_ns":1704067200000002232,"raw_payload":"{\"channel\":\"l2_data\",\"sequence_num\":223,\"events\":[{\"updates\":[{\"side\":\"bid\",\"event_time\":\"2024-01-01T00:00:00.000000001Z\",\"price_level\":\"50000.00\",\"new_quantity\":\"1.00000000\"}]}]}"}
{"local_receipt_timestamp_ns":1704067200000002242,"raw_payload":"{\"channel\":\"l2_data\",\"sequence_num\":224,\"events\":[{\"updates\":[{\"side\":\"offer\",\"event_time\":\"2024-01-01T00:00:00.000000001Z\",\"price_level\":\"50001.00\",\"new_quantity\":\"1.00000000\"}]}]}"}
{"local_receipt_timestamp_ns":1704067200000002252,"raw_payload":"{\"channel\":\"l2_data\",\"sequence_num\":225,\"events\":[{\"updates\":[{\"side\":\"bid\",\"event_time\":\"2024-01-01T00:00:00.000000001Z\",\"price_level\":\"50000.00\",\"new_quantity\":\"1.00000000\"}]}]}"}
{"local_receipt_timestamp_ns":1704067200000002262,"raw_payload":"{\"channel\":\"l2_data\",\"sequence_num\":226,\"events\":[{\"updates\":[{\"side\":\"offer\",\"event_time\":\"2024-01-01T00:00:00.000000001Z\",\"price_level\":\"50001.00\",\"new_quantity\":\"1.00000000\"}]}]}"}
{"local_receipt_timestamp_ns":1704067200000002272,"raw_payload":"{\"channel\":\"l2_data\",\"sequence_num\":227,\"events\":[{\"updates\":[{\"side\":\"bid\",\"event_time\":\"2024-01-01T00:00:00.000000001Z\",\"price_level\":\"50000.00\",\"new_quantity\":\"1.00000000\"}]}]}"}
{"local_receipt_timestamp_ns":1704067200000002282,"raw_payload":"{\"channel\":\"l2_data\",\"sequence_num\":228,\"events\":[{\"updates\":[{\"side\":\"offer\",\"event_time\":\"2024-01-01T00:00:00.000000001Z\",\"price_level\":\"50001.00\",\"new_quantity\":\"1.00000000\"}]}]}"}
{"local_receipt_timestamp_ns":1704067200000002292,"raw_payload":"{\"channel\":\"l2_data\",\"sequence_num\":229,\"events\":[{\"updates\":[{\"side\":\"bid\",\"event_time\":\"2024-01-01T00:00:00.000000001Z\",\"price_level\":\"50000.00\",\"new_quantity\":\"1.00000000\"}]}]}"}
{"local_receipt_timestamp_ns":1704067200000002302,"raw_payload":"{\"channel\":\"l2_data\",\"sequence_num\":230,\"events\":[{\"updates\":[{\"side\":\"offer\",\"event_time\":\"2024-01-01T00:00:00.000000001Z\",\"price_level\":\"50001.00\",\"new_quantity\":\"1.00000000\"}]}]}"}
{"local_receipt_timestamp_ns":1704067200000002312,"raw_payload":"{\"channel\":\"l2_data\",\"sequence_num\":231,\"events\":[{\"updates\":[{\"side\":\"bid\",\"event_time\":\"2024-01-01T00:00:00.000000001Z\",\"price_level\":\"50000.00\",\"new_quantity\":\"1.00000000\"}]}]}"}
{"local_receipt_timestamp_ns":1704067200000002322,"raw_payload":"{\"channel\":\"l2_data\",\"sequence_num\":232,\"events\":[{\"updates\":[{\"side\":\"offer\",\"event_time\":\"2024-01-01T00:00:00.000000001Z\",\"price_level\":\"50001.00\",\"new_quantity\":\"1.00000000\"}]}]}"}
{"local_receipt_timestamp_ns":1704067200000002332,"raw_payload":"{\"channel\":\"l2_data\",\"sequence_num\":233,\"events\":[{\"updates\":[{\"side\":\"bid\",\"event_time\":\"2024-01-01T00:00:00.000000001Z\",\"price_level\":\"50000.00\",\"new_quantity\":\"1.00000000\"}]}]}"}
{"local_receipt_timestamp_ns":1704067200000002342,"raw_payload":"{\"channel\":\"l2_data\",\"sequence_num\":234,\"events\":[{\"updates\":[{\"side\":\"offer\",\"event_time\":\"2024-01-01T00:00:00.000000001Z\",\"price_level\":\"50001.00\",\"new_quantity\":\"1.00000000\"}]}]}"}
{"local_receipt_timestamp_ns":1704067200000002352,"raw_payload":"{\"channel\":\"l2_data\",\"sequence_num\":235,\"events\":[{\"updates\":[{\"side\":\"bid\",\"event_time\":\"2024-01-01T00:00:00.000000001Z\",\"price_level\":\"50000.00\",\"new_quantity\":\"1.00000000\"}]}]}"}
{"local_receipt_timestamp_ns":1704067200000002362,"raw_payload":"{\"channel\":\"l2_data\",\"sequence_num\":236,\"events\":[{\"updates\":[{\"side\":\"offer\",\"event_time\":\"2024-01-01T00:00:00.000000001Z\",\"price_level\":\"50001.00\",\"new_quantity\":\"1.00000000\"}]}]}"}
{"local_receipt_timestamp_ns":1704067200000002372,"raw_payload":"{\"channel\":\"l2_data\",\"sequence_num\":237,\"events\":[{\"updates\":[{\"side\":\"bid\",\"event_time\":\"2024-01-01T00:00:00.000000001Z\",\"price_level\":\"50000.00\",\"new_quantity\":\"1.00000000\"}]}]}"}
{"local_receipt_timestamp_ns":1704067200000002382,"raw_payload":"{\"channel\":\"l2_data\",\"sequence_num\":238,\"events\":[{\"updates\":[{\"side\":\"offer\",\"event_time\":\"2024-01-01T00:00:00.000000001Z\",\"price_level\":\"50001.00\",\"new_quantity\":\"1.00000000\"}]}]}"}
{"local_receipt_timestamp_ns":1704067200000002392,"raw_payload":"{\"channel\":\"l2_data\",\"sequence_num\":239,\"events\":[{\"updates\":[{\"side\":\"bid\",\"event_time\":\"2024-01-01T00:00:00.000000001Z\",\"price_level\":\"50000.00\",\"new_quantity\":\"1.00000000\"}]}]}"}
{"local_receipt_timestamp_ns":1704067200000002402,"raw_payload":"{\"channel\":\"l2_data\",\"sequence_num\":240,\"events\":[{\"updates\":[{\"side\":\"offer\",\"event_time\":\"2024-01-01T00:00:00.000000001Z\",\"price_level\":\"50001.00\",\"new_quantity\":\"1.00000000\"}]}]}"}
{"local_receipt_timestamp_ns":1704067200000002412,"raw_payload":"{\"channel\":\"l2_data\",\"sequence_num\":241,\"events\":[{\"updates\":[{\"side\":\"bid\",\"event_time\":\"2024-01-01T00:00:00.000000001Z\",\"price_level\":\"50000.00\",\"new_quantity\":\"1.00000000\"}]}]}"}
{"local_receipt_timestamp_ns":1704067200000002422,"raw_payload":"{\"channel\":\"l2_data\",\"sequence_num\":242,\"events\":[{\"updates\":[{\"side\":\"offer\",\"event_time\":\"2024-01-01T00:00:00.000000001Z\",\"price_level\":\"50001.00\",\"new_quantity\":\"1.00000000\"}]}]}"}
{"local_receipt_timestamp_ns":1704067200000002432,"raw_payload":"{\"channel\":\"l2_data\",\"sequence_num\":243,\"events\":[{\"updates\":[{\"side\":\"bid\",\"event_time\":\"2024-01-01T00:00:00.000000001Z\",\"price_level\":\"50000.00\",\"new_quantity\":\"1.00000000\"}]}]}"}
{"local_receipt_timestamp_ns":1704067200000002442,"raw_payload":"{\"channel\":\"l2_data\",\"sequence_num\":244,\"events\":[{\"updates\":[{\"side\":\"offer\",\"event_time\":\"2024-01-01T00:00:00.000000001Z\",\"price_level\":\"50001.00\",\"new_quantity\":\"1.00000000\"}]}]}"}
{"local_receipt_timestamp_ns":1704067200000002452,"raw_payload":"{\"channel\":\"l2_data\",\"sequence_num\":245,\"events\":[{\"updates\":[{\"side\":\"bid\",\"event_time\":\"2024-01-01T00:00:00.000000001Z\",\"price_level\":\"50000.00\",\"new_quantity\":\"1.00000000\"}]}]}"}
{"local_receipt_timestamp_ns":1704067200000002462,"raw_payload":"{\"channel\":\"l2_data\",\"sequence_num\":246,\"events\":[{\"updates\":[{\"side\":\"offer\",\"event_time\":\"2024-01-01T00:00:00.000000001Z\",\"price_level\":\"50001.00\",\"new_quantity\":\"1.00000000\"}]}]}"}
{"local_receipt_timestamp_ns":1704067200000002472,"raw_payload":"{\"channel\":\"l2_data\",\"sequence_num\":247,\"events\":[{\"updates\":[{\"side\":\"bid\",\"event_time\":\"2024-01-01T00:00:00.000000001Z\",\"price_level\":\"50000.00\",\"new_quantity\":\"1.00000000\"}]}]}"}
{"local_receipt_timestamp_ns":1704067200000002482,"raw_payload":"{\"channel\":\"l2_data\",\"sequence_num\":248,\"events\":[{\"updates\":[{\"side\":\"offer\",\"event_time\":\"2024-01-01T00:00:00.000000001Z\",\"price_level\":\"50001.00\",\"new_quantity\":\"1.00000000\"}]}]}"}
{"local_receipt_timestamp_ns":1704067200000002492,"raw_payload":"{\"channel\":\"l2_data\",\"sequence_num\":249,\"events\":[{\"updates\":[{\"side\":\"bid\",\"event_time\":\"2024-01-01T00:00:00.000000001Z\",\"price_level\":\"50000.00\",\"new_quantity\":\"1.00000000\"}]}]}"}
{"local_receipt_timestamp_ns":1704067200000002502,"raw_payload":"{\"channel\":\"l2_data\",\"sequence_num\":250,\"events\":[{\"updates\":[{\"side\":\"offer\",\"event_time\":\"2024-01-01T00:00:00.000000001Z\",\"price_level\":\"50001.00\",\"new_quantity\":\"1.00000000\"}]}]}"}
{"local_receipt_timestamp_ns":1704067200000002512,"raw_payload":"{\"channel\":\"l2_data\",\"sequence_num\":250,\"events\":[{\"updates\":[{\"side\":\"offer\",\"event_time\":\"2024-01-01T00:00:00.000000001Z\",\"price_level\":\"50001.00\",\"new_quantity\":\"1.00000000\"}]}]}"}
{"local_receipt_timestamp_ns":1704067200000002522,"raw_payload":"{\"channel\":\"l2_data\",\"sequence_num\":249,\"events\":[{\"updates\":[{\"side\":\"bid\",\"event_time\":\"2024-01-01T00:00:00.000000001Z\",\"price_level\":\"50000.00\",\"new_quantity\":\"1.00000000\"}]}]}"}
{"local_receipt_timestamp_ns":1704067200000002532,"raw_payload":"{\"channel\":\"l2_data\",\"sequence_num\":252,\"events\":[{\"updates\":[{\"side\":\"offer\",\"event_time\":\"2024-01-01T00:00:00.000000001Z\",\"price_level\":\"50001.00\",\"new_quantity\":\"1.00000000\"}]}]}"}
{"local_receipt_timestamp_ns":1704067200000002542,"raw_payload":"{\"channel\":\"l2_data\",\"sequence_num\":253,\"events\":[{\"updates\":[{\"side\":\"bid\",\"event_time\":\"2024-01-01T00:00:00.000000001Z\",\"price_level\":\"50000.00\",\"new_quantity\":\"1.00000000\"}]}]}"}
{"local_receipt_timestamp_ns":1704067200000002552,"raw_payload":"{\"channel\":\"l2_data\",\"sequence_num\":254,\"events\":[{\"updates\":[{\"side\":\"offer\",\"event_time\":\"2024-01-01T00:00:00.000000001Z\",\"price_level\":\"50001.00\",\"new_quantity\":\"1.00000000\"}]}]}"}
{"local_receipt_timestamp_ns":1704067200000002562,"raw_payload":"{\"channel\":\"l2_data\",\"sequence_num\":255,\"events\":[{\"updates\":[{\"side\":\"bid\",\"event_time\":\"2024-01-01T00:00:00.000000001Z\",\"price_level\":\"50000.00\",\"new_quantity\":\"1.00000000\"}]}]}"}
{"local_receipt_timestamp_ns":1704067200000002572,"raw_payload":"{\"channel\":\"l2_data\",\"sequence_num\":256,\"events\":[{\"updates\":[{\"side\":\"offer\",\"event_time\":\"2024-01-01T00:00:00.000000001Z\",\"price_level\":\"50001.00\",\"new_quantity\":\"1.00000000\"}]}]}"}
{"local_receipt_timestamp_ns":1704067200000002582,"raw_payload":"{\"channel\":\"l2_data\",\"sequence_num\":257,\"events\":[{\"updates\":[{\"side\":\"bid\",\"event_time\":\"2024-01-01T00:00:00.000000001Z\",\"price_level\":\"50000.00\",\"new_quantity\":\"1.00000000\"}]}]}"}
{"local_receipt_timestamp_ns":1704067200000002592,"raw_payload":"{\"channel\":\"l2_data\",\"sequence_num\":258,\"events\":[{\"updates\":[{\"side\":\"offer\",\"event_time\":\"2024-01-01T00:00:00.000000001Z\",\"price_level\":\"50001.00\",\"new_quantity\":\"1.00000000\"}]}]}"}
{"local_receipt_timestamp_ns":1704067200000002602,"raw_payload":"{\"channel\":\"l2_data\",\"sequence_num\":259,\"events\":[{\"updates\":[{\"side\":\"bid\",\"event_time\":\"2024-01-01T00:00:00.000000001Z\",\"price_level\":\"50000.00\",\"new_quantity\":\"1.00000000\"}]}]}"}
{"local_receipt_timestamp_ns":1704067200000002612,"raw_payload":"{\"channel\":\"l2_data\",\"sequence_num\":260,\"events\":[{\"updates\":[{\"side\":\"offer\",\"event_time\":\"2024-01-01T00:00:00.000000001Z\",\"price_level\":\"50001.00\",\"new_quantity\":\"1.00000000\"}]}]}"}
{"local_receipt_timestamp_ns":1704067200000002622,"raw_payload":"{\"channel\":\"l2_data\",\"sequence_num\":261,\"events\":[{\"updates\":[{\"side\":\"bid\",\"event_time\":\"2024-01-01T00:00:00.000000001Z\",\"price_level\":\"50000.00\",\"new_quantity\":\"1.00000000\"}]}]}"}
{"local_receipt_timestamp_ns":1704067200000002632,"raw_payload":"{\"channel\":\"l2_data\",\"sequence_num\":262,\"events\":[{\"updates\":[{\"side\":\"offer\",\"event_time\":\"2024-01-01T00:00:00.000000001Z\",\"price_level\":\"50001.00\",\"new_quantity\":\"1.00000000\"}]}]}"}
{"local_receipt_timestamp_ns":1704067200000002642,"raw_payload":"{\"channel\":\"l2_data\",\"sequence_num\":263,\"events\":[{\"updates\":[{\"side\":\"bid\",\"event_time\":\"2024-01-01T00:00:00.000000001Z\",\"price_level\":\"50000.00\",\"new_quantity\":\"1.00000000\"}]}]}"}
{"local_receipt_timestamp_ns":1704067200000002652,"raw_payload":"{\"channel\":\"l2_data\",\"sequence_num\":264,\"events\":[{\"updates\":[{\"side\":\"offer\",\"event_time\":\"2024-01-01T00:00:00.000000001Z\",\"price_level\":\"50001.00\",\"new_quantity\":\"1.00000000\"}]}]}"}
{"local_receipt_timestamp_ns":1704067200000002662,"raw_payload":"{\"channel\":\"l2_data\",\"sequence_num\":265,\"events\":[{\"updates\":[{\"side\":\"bid\",\"event_time\":\"2024-01-01T00:00:00.000000001Z\",\"price_level\":\"50000.00\",\"new_quantity\":\"1.00000000\"}]}]}"}
{"local_receipt_timestamp_ns":1704067200000002672,"raw_payload":"{\"channel\":\"l2_data\",\"sequence_num\":266,\"events\":[{\"updates\":[{\"side\":\"offer\",\"event_time\":\"2024-01-01T00:00:00.000000001Z\",\"price_level\":\"50001.00\",\"new_quantity\":\"1.00000000\"}]}]}"}
{"local_receipt_timestamp_ns":1704067200000002682,"raw_payload":"{\"channel\":\"l2_data\",\"sequence_num\":267,\"events\":[{\"updates\":[{\"side\":\"bid\",\"event_time\":\"2024-01-01T00:00:00.000000001Z\",\"price_level\":\"50000.00\",\"new_quantity\":\"1.00000000\"}]}]}"}
{"local_receipt_timestamp_ns":1704067200000002692,"raw_payload":"{\"channel\":\"l2_data\",\"sequence_num\":268,\"events\":[{\"updates\":[{\"side\":\"offer\",\"event_time\":\"2024-01-01T00:00:00.000000001Z\",\"price_level\":\"50001.00\",\"new_quantity\":\"1.00000000\"}]}]}"}
{"local_receipt_timestamp_ns":1704067200000002702,"raw_payload":"{\"channel\":\"l2_data\",\"sequence_num\":269,\"events\":[{\"updates\":[{\"side\":\"bid\",\"event_time\":\"2024-01-01T00:00:00.000000001Z\",\"price_level\":\"50000.00\",\"new_quantity\":\"1.00000000\"}]}]}"}
{"local_receipt_timestamp_ns":1704067200000002712,"raw_payload":"{\"channel\":\"l2_data\",\"sequence_num\":270,\"events\":[{\"updates\":[{\"side\":\"offer\",\"event_time\":\"2024-01-01T00:00:00.000000001Z\",\"price_level\":\"50001.00\",\"new_quantity\":\"1.00000000\"}]}]}"}
{"local_receipt_timestamp_ns":1704067200000002722,"raw_payload":"{\"channel\":\"l2_data\",\"sequence_num\":271,\"events\":[{\"updates\":[{\"side\":\"bid\",\"event_time\":\"2024-01-01T00:00:00.000000001Z\",\"price_level\":\"50000.00\",\"new_quantity\":\"1.00000000\"}]}]}"}
{"local_receipt_timestamp_ns":1704067200000002732,"raw_payload":"{\"channel\":\"l2_data\",\"sequence_num\":272,\"events\":[{\"updates\":[{\"side\":\"offer\",\"event_time\":\"2024-01-01T00:00:00.000000001Z\",\"price_level\":\"50001.00\",\"new_quantity\":\"1.00000000\"}]}]}"}
{"local_receipt_timestamp_ns":1704067200000002742,"raw_payload":"{\"channel\":\"l2_data\",\"sequence_num\":273,\"events\":[{\"updates\":[{\"side\":\"bid\",\"event_time\":\"2024-01-01T00:00:00.000000001Z\",\"price_level\":\"50000.00\",\"new_quantity\":\"1.00000000\"}]}]}"}
{"local_receipt_timestamp_ns":1704067200000002752,"raw_payload":"{\"channel\":\"l2_data\",\"sequence_num\":274,\"events\":[{\"updates\":[{\"side\":\"offer\",\"event_time\":\"2024-01-01T00:00:00.000000001Z\",\"price_level\":\"50001.00\",\"new_quantity\":\"1.00000000\"}]}]}"}
{"local_receipt_timestamp_ns":1704067200000002762,"raw_payload":"{\"channel\":\"l2_data\",\"sequence_num\":275,\"events\":[{\"updates\":[{\"side\":\"bid\",\"event_time\":\"2024-01-01T00:00:00.000000001Z\",\"price_level\":\"50000.00\",\"new_quantity\":\"1.00000000\"}]}]}"}
{"local_receipt_timestamp_ns":1704067200000002772,"raw_payload":"{\"channel\":\"l2_data\",\"sequence_num\":276,\"events\":[{\"updates\":[{\"side\":\"offer\",\"event_time\":\"2024-01-01T00:00:00.000000001Z\",\"price_level\":\"50001.00\",\"new_quantity\":\"1.00000000\"}]}]}"}
{"local_receipt_timestamp_ns":1704067200000002782,"raw_payload":"{\"channel\":\"l2_data\",\"sequence_num\":277,\"events\":[{\"updates\":[{\"side\":\"bid\",\"event_time\":\"2024-01-01T00:00:00.000000001Z\",\"price_level\":\"50000.00\",\"new_quantity\":\"1.00000000\"}]}]}"}
{"local_receipt_timestamp_ns":1704067200000002792,"raw_payload":"{\"channel\":\"l2_data\",\"sequence_num\":278,\"events\":[{\"updates\":[{\"side\":\"offer\",\"event_time\":\"2024-01-01T00:00:00.000000001Z\",\"price_level\":\"50001.00\",\"new_quantity\":\"1.00000000\"}]}]}"}
{"local_receipt_timestamp_ns":1704067200000002802,"raw_payload":"{\"channel\":\"l2_data\",\"sequence_num\":279,\"events\":[{\"updates\":[{\"side\":\"bid\",\"event_time\":\"2024-01-01T00:00:00.000000001Z\",\"price_level\":\"50000.00\",\"new_quantity\":\"1.00000000\"}]}]}"}
{"local_receipt_timestamp_ns":1704067200000002812,"raw_payload":"{\"channel\":\"l2_data\",\"sequence_num\":280,\"events\":[{\"updates\":[{\"side\":\"offer\",\"event_time\":\"2024-01-01T00:00:00.000000001Z\",\"price_level\":\"50001.00\",\"new_quantity\":\"1.00000000\"}]}]}"}
{"local_receipt_timestamp_ns":1704067200000002822,"raw_payload":"{\"channel\":\"l2_data\",\"sequence_num\":281,\"events\":[{\"updates\":[{\"side\":\"bid\",\"event_time\":\"2024-01-01T00:00:00.000000001Z\",\"price_level\":\"50000.00\",\"new_quantity\":\"1.00000000\"}]}]}"}
{"local_receipt_timestamp_ns":1704067200000002832,"raw_payload":"{\"channel\":\"l2_data\",\"sequence_num\":282,\"events\":[{\"updates\":[{\"side\":\"offer\",\"event_time\":\"2024-01-01T00:00:00.000000001Z\",\"price_level\":\"50001.00\",\"new_quantity\":\"1.00000000\"}]}]}"}
{"local_receipt_timestamp_ns":1704067200000002842,"raw_payload":"{\"channel\":\"l2_data\",\"sequence_num\":283,\"events\":[{\"updates\":[{\"side\":\"bid\",\"event_time\":\"2024-01-01T00:00:00.000000001Z\",\"price_level\":\"50000.00\",\"new_quantity\":\"1.00000000\"}]}]}"}
{"local_receipt_timestamp_ns":1704067200000002852,"raw_payload":"{\"channel\":\"l2_data\",\"sequence_num\":284,\"events\":[{\"updates\":[{\"side\":\"offer\",\"event_time\":\"2024-01-01T00:00:00.000000001Z\",\"price_level\":\"50001.00\",\"new_quantity\":\"1.00000000\"}]}]}"}
{"local_receipt_timestamp_ns":1704067200000002862,"raw_payload":"{\"channel\":\"l2_data\",\"sequence_num\":285,\"events\":[{\"updates\":[{\"side\":\"bid\",\"event_time\":\"2024-01-01T00:00:00.000000001Z\",\"price_level\":\"50000.00\",\"new_quantity\":\"1.00000000\"}]}]}"}
{"local_receipt_timestamp_ns":1704067200000002872,"raw_payload":"{\"channel\":\"l2_data\",\"sequence_num\":286,\"events\":[{\"updates\":[{\"side\":\"offer\",\"event_time\":\"2024-01-01T00:00:00.000000001Z\",\"price_level\":\"50001.00\",\"new_quantity\":\"1.00000000\"}]}]}"}
{"local_receipt_timestamp_ns":1704067200000002882,"raw_payload":"{\"channel\":\"l2_data\",\"sequence_num\":287,\"events\":[{\"updates\":[{\"side\":\"bid\",\"event_time\":\"2024-01-01T00:00:00.000000001Z\",\"price_level\":\"50000.00\",\"new_quantity\":\"1.00000000\"}]}]}"}
{"local_receipt_timestamp_ns":1704067200000002892,"raw_payload":"{\"channel\":\"l2_data\",\"sequence_num\":288,\"events\":[{\"updates\":[{\"side\":\"offer\",\"event_time\":\"2024-01-01T00:00:00.000000001Z\",\"price_level\":\"50001.00\",\"new_quantity\":\"1.00000000\"}]}]}"}
{"local_receipt_timestamp_ns":1704067200000002902,"raw_payload":"{\"channel\":\"l2_data\",\"sequence_num\":289,\"events\":[{\"updates\":[{\"side\":\"bid\",\"event_time\":\"2024-01-01T00:00:00.000000001Z\",\"price_level\":\"50000.00\",\"new_quantity\":\"1.00000000\"}]}]}"}
{"local_receipt_timestamp_ns":1704067200000002912,"raw_payload":"{\"channel\":\"l2_data\",\"sequence_num\":290,\"events\":[{\"updates\":[{\"side\":\"offer\",\"event_time\":\"2024-01-01T00:00:00.000000001Z\",\"price_level\":\"50001.00\",\"new_quantity\":\"1.00000000\"}]}]}"}
{"local_receipt_timestamp_ns":1704067200000002922,"raw_payload":"{\"channel\":\"l2_data\",\"sequence_num\":291,\"events\":[{\"updates\":[{\"side\":\"bid\",\"event_time\":\"2024-01-01T00:00:00.000000001Z\",\"price_level\":\"50000.00\",\"new_quantity\":\"1.00000000\"}]}]}"}
{"local_receipt_timestamp_ns":1704067200000002932,"raw_payload":"{\"channel\":\"l2_data\",\"sequence_num\":292,\"events\":[{\"updates\":[{\"side\":\"offer\",\"event_time\":\"2024-01-01T00:00:00.000000001Z\",\"price_level\":\"50001.00\",\"new_quantity\":\"1.00000000\"}]}]}"}
{"local_receipt_timestamp_ns":1704067200000002942,"raw_payload":"{\"channel\":\"l2_data\",\"sequence_num\":293,\"events\":[{\"updates\":[{\"side\":\"bid\",\"event_time\":\"2024-01-01T00:00:00.000000001Z\",\"price_level\":\"50000.00\",\"new_quantity\":\"1.00000000\"}]}]}"}
{"local_receipt_timestamp_ns":1704067200000002952,"raw_payload":"{\"channel\":\"l2_data\",\"sequence_num\":294,\"events\":[{\"updates\":[{\"side\":\"offer\",\"event_time\":\"2024-01-01T00:00:00.000000001Z\",\"price_level\":\"50001.00\",\"new_quantity\":\"1.00000000\"}]}]}"}
{"local_receipt_timestamp_ns":1704067200000002962,"raw_payload":"{\"channel\":\"l2_data\",\"sequence_num\":295,\"events\":[{\"updates\":[{\"side\":\"bid\",\"event_time\":\"2024-01-01T00:00:00.000000001Z\",\"price_level\":\"50000.00\",\"new_quantity\":\"1.00000000\"}]}]}"}
{"local_receipt_timestamp_ns":1704067200000002972,"raw_payload":"{\"channel\":\"l2_data\",\"sequence_num\":296,\"events\":[{\"updates\":[{\"side\":\"offer\",\"event_time\":\"2024-01-01T00:00:00.000000001Z\",\"price_level\":\"50001.00\",\"new_quantity\":\"1.00000000\"}]}]}"}
{"local_receipt_timestamp_ns":1704067200000002982,"raw_payload":"{\"channel\":\"l2_data\",\"sequence_num\":297,\"events\":[{\"updates\":[{\"side\":\"bid\",\"event_time\":\"2024-01-01T00:00:00.000000001Z\",\"price_level\":\"50000.00\",\"new_quantity\":\"1.00000000\"}]}]}"}
{"local_receipt_timestamp_ns":1704067200000002992,"raw_payload":"{\"channel\":\"l2_data\",\"sequence_num\":298,\"events\":[{\"updates\":[{\"side\":\"offer\",\"event_time\":\"2024-01-01T00:00:00.000000001Z\",\"price_level\":\"50001.00\",\"new_quantity\":\"1.00000000\"}]}]}"}
{"local_receipt_timestamp_ns":1704067200000003002,"raw_payload":"{\"channel\":\"l2_data\",\"sequence_num\":299,\"events\":[{\"updates\":[{\"side\":\"bid\",\"event_time\":\"2024-01-01T00:00:00.000000001Z\",\"price_level\":\"50000.00\",\"new_quantity\":\"1.00000000\"}]}]}"}
{"local_receipt_timestamp_ns":1704067200000003012,"raw_payload":"{\"channel\":\"l2_data\",\"sequence_num\":300,\"events\":[{\"updates\":[{\"side\":\"offer\",\"event_time\":\"2024-01-01T00:00:00.000000001Z\",\"price_level\":\"50001.00\",\"new_quantity\":\"1.00000000\"}]}]}"}
{"local_receipt_timestamp_ns":1704067200000003022,"raw_payload":"{\"channel\":\"l2_data\",\"sequence_num\":301,\"events\":[{\"updates\":[{\"side\":\"bid\",\"event_time\":\"2024-01-01T00:00:00.000000001Z\",\"price_level\":\"50000.00\",\"new_quantity\":\"1.00000000\"}]}]}"}
{"local_receipt_timestamp_ns":1704067200000003032,"raw_payload":"{\"channel\":\"l2_data\",\"sequence_num\":302,\"events\":[{\"updates\":[{\"side\":\"offer\",\"event_time\":\"2024-01-01T00:00:00.000000001Z\",\"price_level\":\"50001.00\",\"new_quantity\":\"1.00000000\"}]}]}"}
{"local_receipt_timestamp_ns":1704067200000003042,"raw_payload":"{\"channel\":\"l2_data\",\"sequence_num\":303,\"events\":[{\"updates\":[{\"side\":\"bid\",\"event_time\":\"2024-01-01T00:00:00.000000001Z\",\"price_level\":\"50000.00\",\"new_quantity\":\"1.00000000\"}]}]}"}
{"local_receipt_timestamp_ns":1704067200000003052,"raw_payload":"{\"channel\":\"l2_data\",\"sequence_num\":304,\"events\":[{\"updates\":[{\"side\":\"offer\",\"event_time\":\"2024-01-01T00:00:00.000000001Z\",\"price_level\":\"50001.00\",\"new_quantity\":\"1.00000000\"}]}]}"}
{"local_receipt_timestamp_ns":1704067200000003062,"raw_payload":"{\"channel\":\"l2_data\",\"sequence_num\":305,\"events\":[{\"updates\":[{\"side\":\"bid\",\"event_time\":\"2024-01-01T00:00:00.000000001Z\",\"price_level\":\"50000.00\",\"new_quantity\":\"1.00000000\"}]}]}"}
{"local_receipt_timestamp_ns":1704067200000003072,"raw_payload":"{\"channel\":\"l2_data\",\"sequence_num\":306,\"events\":[{\"updates\":[{\"side\":\"offer\",\"event_time\":\"2024-01-01T00:00:00.000000001Z\",\"price_level\":\"50001.00\",\"new_quantity\":\"1.00000000\"}]}]}"}
{"local_receipt_timestamp_ns":1704067200000003082,"raw_payload":"{\"channel\":\"l2_data\",\"sequence_num\":307,\"events\":[{\"updates\":[{\"side\":\"bid\",\"event_time\":\"2024-01-01T00:00:00.000000001Z\",\"price_level\":\"50000.00\",\"new_quantity\":\"1.00000000\"}]}]}"}
{"local_receipt_timestamp_ns":1704067200000003092,"raw_payload":"{\"channel\":\"l2_data\",\"sequence_num\":308,\"events\":[{\"updates\":[{\"side\":\"offer\",\"event_time\":\"2024-01-01T00:00:00.000000001Z\",\"price_level\":\"50001.00\",\"new_quantity\":\"1.00000000\"}]}]}"}
{"local_receipt_timestamp_ns":1704067200000003102,"raw_payload":"{\"channel\":\"l2_data\",\"sequence_num\":309,\"events\":[{\"updates\":[{\"side\":\"bid\",\"event_time\":\"2024-01-01T00:00:00.000000001Z\",\"price_level\":\"50000.00\",\"new_quantity\":\"1.00000000\"}]}]}"}
{"local_receipt_timestamp_ns":1704067200000003112,"raw_payload":"{\"channel\":\"l2_data\",\"sequence_num\":310,\"events\":[{\"updates\":[{\"side\":\"offer\",\"event_time\":\"2024-01-01T00:00:00.000000001Z\",\"price_level\":\"50001.00\",\"new_quantity\":\"1.00000000\"}]}]}"}
{"local_receipt_timestamp_ns":1704067200000003122,"raw_payload":"{\"channel\":\"l2_data\",\"sequence_num\":311,\"events\":[{\"updates\":[{\"side\":\"bid\",\"event_time\":\"2024-01-01T00:00:00.000000001Z\",\"price_level\":\"50000.00\",\"new_quantity\":\"1.00000000\"}]}]}"}
{"local_receipt_timestamp_ns":1704067200000003132,"raw_payload":"{\"channel\":\"l2_data\",\"sequence_num\":312,\"events\":[{\"updates\":[{\"side\":\"offer\",\"event_time\":\"2024-01-01T00:00:00.000000001Z\",\"price_level\":\"50001.00\",\"new_quantity\":\"1.00000000\"}]}]}"}
{"local_receipt_timestamp_ns":1704067200000003142,"raw_payload":"{\"channel\":\"l2_data\",\"sequence_num\":313,\"events\":[{\"updates\":[{\"side\":\"bid\",\"event_time\":\"2024-01-01T00:00:00.000000001Z\",\"price_level\":\"50000.00\",\"new_quantity\":\"1.00000000\"}]}]}"}
{"local_receipt_timestamp_ns":1704067200000003152,"raw_payload":"{\"channel\":\"l2_data\",\"sequence_num\":314,\"events\":[{\"updates\":[{\"side\":\"offer\",\"event_time\":\"2024-01-01T00:00:00.000000001Z\",\"price_level\":\"50001.00\",\"new_quantity\":\"1.00000000\"}]}]}"}
{"local_receipt_timestamp_ns":1704067200000003162,"raw_payload":"{\"channel\":\"l2_data\",\"sequence_num\":315,\"events\":[{\"updates\":[{\"side\":\"bid\",\"event_time\":\"2024-01-01T00:00:00.000000001Z\",\"price_level\":\"50000.00\",\"new_quantity\":\"1.00000000\"}]}]}"}
{"local_receipt_timestamp_ns":1704067200000003172,"raw_payload":"{\"channel\":\"l2_data\",\"sequence_num\":316,\"events\":[{\"updates\":[{\"side\":\"offer\",\"event_time\":\"2024-01-01T00:00:00.000000001Z\",\"price_level\":\"50001.00\",\"new_quantity\":\"1.00000000\"}]}]}"}
{"local_receipt_timestamp_ns":1704067200000003182,"raw_payload":"{\"channel\":\"l2_data\",\"sequence_num\":317,\"events\":[{\"updates\":[{\"side\":\"bid\",\"event_time\":\"2024-01-01T00:00:00.000000001Z\",\"price_level\":\"50000.00\",\"new_quantity\":\"1.00000000\"}]}]}"}
{"local_receipt_timestamp_ns":1704067200000003192,"raw_payload":"{\"channel\":\"l2_data\",\"sequence_num\":318,\"events\":[{\"updates\":[{\"side\":\"offer\",\"event_time\":\"2024-01-01T00:00:00.000000001Z\",\"price_level\":\"50001.00\",\"new_quantity\":\"1.00000000\"}]}]}"}
{"local_receipt_timestamp_ns":1704067200000003202,"raw_payload":"{\"channel\":\"l2_data\",\"sequence_num\":319,\"events\":[{\"updates\":[{\"side\":\"bid\",\"event_time\":\"2024-01-01T00:00:00.000000001Z\",\"price_level\":\"50000.00\",\"new_quantity\":\"1.00000000\"}]}]}"}
{"local_receipt_timestamp_ns":1704067200000003212,"raw_payload":"{\"channel\":\"l2_data\",\"sequence_num\":320,\"events\":[{\"updates\":[{\"side\":\"offer\",\"event_time\":\"2024-01-01T00:00:00.000000001Z\",\"price_level\":\"50001.00\",\"new_quantity\":\"1.00000000\"}]}]}"}
{"local_receipt_timestamp_ns":1704067200000003222,"raw_payload":"{\"channel\":\"l2_data\",\"sequence_num\":321,\"events\":[{\"updates\":[{\"side\":\"bid\",\"event_time\":\"2024-01-01T00:00:00.000000001Z\",\"price_level\":\"50000.00\",\"new_quantity\":\"1.00000000\"}]}]}"}
{"local_receipt_timestamp_ns":1704067200000003232,"raw_payload":"{\"channel\":\"l2_data\",\"sequence_num\":322,\"events\":[{\"updates\":[{\"side\":\"offer\",\"event_time\":\"2024-01-01T00:00:00.000000001Z\",\"price_level\":\"50001.00\",\"new_quantity\":\"1.00000000\"}]}]}"}
{"local_receipt_timestamp_ns":1704067200000003242,"raw_payload":"{\"channel\":\"l2_data\",\"sequence_num\":323,\"events\":[{\"updates\":[{\"side\":\"bid\",\"event_time\":\"2024-01-01T00:00:00.000000001Z\",\"price_level\":\"50000.00\",\"new_quantity\":\"1.00000000\"}]}]}"}
{"local_receipt_timestamp_ns":1704067200000003252,"raw_payload":"{\"channel\":\"l2_data\",\"sequence_num\":324,\"events\":[{\"updates\":[{\"side\":\"offer\",\"event_time\":\"2024-01-01T00:00:00.000000001Z\",\"price_level\":\"50001.00\",\"new_quantity\":\"1.00000000\"}]}]}"}
{"local_receipt_timestamp_ns":1704067200000003262,"raw_payload":"{\"channel\":\"l2_data\",\"sequence_num\":325,\"events\":[{\"updates\":[{\"side\":\"bid\",\"event_time\":\"2024-01-01T00:00:00.000000001Z\",\"price_level\":\"50000.00\",\"new_quantity\":\"1.00000000\"}]}]}"}
{"local_receipt_timestamp_ns":1704067200000003272,"raw_payload":"{\"channel\":\"l2_data\",\"sequence_num\":326,\"events\":[{\"updates\":[{\"side\":\"offer\",\"event_time\":\"2024-01-01T00:00:00.000000001Z\",\"price_level\":\"50001.00\",\"new_quantity\":\"1.00000000\"}]}]}"}
{"local_receipt_timestamp_ns":1704067200000003282,"raw_payload":"{\"channel\":\"l2_data\",\"sequence_num\":327,\"events\":[{\"updates\":[{\"side\":\"bid\",\"event_time\":\"2024-01-01T00:00:00.000000001Z\",\"price_level\":\"50000.00\",\"new_quantity\":\"1.00000000\"}]}]}"}
{"local_receipt_timestamp_ns":1704067200000003292,"raw_payload":"{\"channel\":\"l2_data\",\"sequence_num\":328,\"events\":[{\"updates\":[{\"side\":\"offer\",\"event_time\":\"2024-01-01T00:00:00.000000001Z\",\"price_level\":\"50001.00\",\"new_quantity\":\"1.00000000\"}]}]}"}
{"local_receipt_timestamp_ns":1704067200000003302,"raw_payload":"{\"channel\":\"l2_data\",\"sequence_num\":329,\"events\":[{\"updates\":[{\"side\":\"bid\",\"event_time\":\"2024-01-01T00:00:00.000000001Z\",\"price_level\":\"50000.00\",\"new_quantity\":\"1.00000000\"}]}]}"}
{"local_receipt_timestamp_ns":1704067200000003312,"raw_payload":"{\"channel\":\"l2_data\",\"sequence_num\":330,\"events\":[{\"updates\":[{\"side\":\"offer\",\"event_time\":\"2024-01-01T00:00:00.000000001Z\",\"price_level\":\"50001.00\",\"new_quantity\":\"1.00000000\"}]}]}"}
{"local_receipt_timestamp_ns":1704067200000003322,"raw_payload":"{\"channel\":\"l2_data\",\"sequence_num\":331,\"events\":[{\"updates\":[{\"side\":\"bid\",\"event_time\":\"2024-01-01T00:00:00.000000001Z\",\"price_level\":\"50000.00\",\"new_quantity\":\"1.00000000\"}]}]}"}
{"local_receipt_timestamp_ns":1704067200000003332,"raw_payload":"{\"channel\":\"l2_data\",\"sequence_num\":332,\"events\":[{\"updates\":[{\"side\":\"offer\",\"event_time\":\"2024-01-01T00:00:00.000000001Z\",\"price_level\":\"50001.00\",\"new_quantity\":\"1.00000000\"}]}]}"}
{"local_receipt_timestamp_ns":1704067200000003342,"raw_payload":"{\"channel\":\"l2_data\",\"sequence_num\":333,\"events\":[{\"updates\":[{\"side\":\"bid\",\"event_time\":\"2024-01-01T00:00:00.000000001Z\",\"price_level\":\"50000.00\",\"new_quantity\":\"1.00000000\"}]}]}"}
{"local_receipt_timestamp_ns":1704067200000003352,"raw_payload":"{\"channel\":\"l2_data\",\"sequence_num\":334,\"events\":[{\"updates\":[{\"side\":\"offer\",\"event_time\":\"2024-01-01T00:00:00.000000001Z\",\"price_level\":\"50001.00\",\"new_quantity\":\"1.00000000\"}]}]}"}
{"local_receipt_timestamp_ns":1704067200000003362,"raw_payload":"{\"channel\":\"l2_data\",\"sequence_num\":335,\"events\":[{\"updates\":[{\"side\":\"bid\",\"event_time\":\"2024-01-01T00:00:00.000000001Z\",\"price_level\":\"50000.00\",\"new_quantity\":\"1.00000000\"}]}]}"}
{"local_receipt_timestamp_ns":1704067200000003372,"raw_payload":"{\"channel\":\"l2_data\",\"sequence_num\":336,\"events\":[{\"updates\":[{\"side\":\"offer\",\"event_time\":\"2024-01-01T00:00:00.000000001Z\",\"price_level\":\"50001.00\",\"new_quantity\":\"1.00000000\"}]}]}"}
{"local_receipt_timestamp_ns":1704067200000003382,"raw_payload":"{\"channel\":\"l2_data\",\"sequence_num\":337,\"events\":[{\"updates\":[{\"side\":\"bid\",\"event_time\":\"2024-01-01T00:00:00.000000001Z\",\"price_level\":\"50000.00\",\"new_quantity\":\"1.00000000\"}]}]}"}
{"local_receipt_timestamp_ns":1704067200000003392,"raw_payload":"{\"channel\":\"l2_data\",\"sequence_num\":338,\"events\":[{\"updates\":[{\"side\":\"offer\",\"event_time\":\"2024-01-01T00:00:00.000000001Z\",\"price_level\":\"50001.00\",\"new_quantity\":\"1.00000000\"}]}]}"}
{"local_receipt_timestamp_ns":1704067200000003402,"raw_payload":"{\"channel\":\"l2_data\",\"sequence_num\":339,\"events\":[{\"updates\":[{\"side\":\"bid\",\"event_time\":\"2024-01-01T00:00:00.000000001Z\",\"price_level\":\"50000.00\",\"new_quantity\":\"1.00000000\"}]}]}"}
{"local_receipt_timestamp_ns":1704067200000003412,"raw_payload":"{\"channel\":\"l2_data\",\"sequence_num\":340,\"events\":[{\"updates\":[{\"side\":\"offer\",\"event_time\":\"2024-01-01T00:00:00.000000001Z\",\"price_level\":\"50001.00\",\"new_quantity\":\"1.00000000\"}]}]}"}
{"local_receipt_timestamp_ns":1704067200000003422,"raw_payload":"{\"channel\":\"l2_data\",\"sequence_num\":341,\"events\":[{\"updates\":[{\"side\":\"bid\",\"event_time\":\"2024-01-01T00:00:00.000000001Z\",\"price_level\":\"50000.00\",\"new_quantity\":\"1.00000000\"}]}]}"}
{"local_receipt_timestamp_ns":1704067200000003432,"raw_payload":"{\"channel\":\"l2_data\",\"sequence_num\":342,\"events\":[{\"updates\":[{\"side\":\"offer\",\"event_time\":\"2024-01-01T00:00:00.000000001Z\",\"price_level\":\"50001.00\",\"new_quantity\":\"1.00000000\"}]}]}"}
{"local_receipt_timestamp_ns":1704067200000003442,"raw_payload":"{\"channel\":\"l2_data\",\"sequence_num\":343,\"events\":[{\"updates\":[{\"side\":\"bid\",\"event_time\":\"2024-01-01T00:00:00.000000001Z\",\"price_level\":\"50000.00\",\"new_quantity\":\"1.00000000\"}]}]}"}
{"local_receipt_timestamp_ns":1704067200000003452,"raw_payload":"{\"channel\":\"l2_data\",\"sequence_num\":344,\"events\":[{\"updates\":[{\"side\":\"offer\",\"event_time\":\"2024-01-01T00:00:00.000000001Z\",\"price_level\":\"50001.00\",\"new_quantity\":\"1.00000000\"}]}]}"}
{"local_receipt_timestamp_ns":1704067200000003462,"raw_payload":"{\"channel\":\"l2_data\",\"sequence_num\":345,\"events\":[{\"updates\":[{\"side\":\"bid\",\"event_time\":\"2024-01-01T00:00:00.000000001Z\",\"price_level\":\"50000.00\",\"new_quantity\":\"1.00000000\"}]}]}"}
{"local_receipt_timestamp_ns":1704067200000003472,"raw_payload":"{\"channel\":\"l2_data\",\"sequence_num\":346,\"events\":[{\"updates\":[{\"side\":\"offer\",\"event_time\":\"2024-01-01T00:00:00.000000001Z\",\"price_level\":\"50001.00\",\"new_quantity\":\"1.00000000\"}]}]}"}
{"local_receipt_timestamp_ns":1704067200000003482,"raw_payload":"{\"channel\":\"l2_data\",\"sequence_num\":347,\"events\":[{\"updates\":[{\"side\":\"bid\",\"event_time\":\"2024-01-01T00:00:00.000000001Z\",\"price_level\":\"50000.00\",\"new_quantity\":\"1.00000000\"}]}]}"}
{"local_receipt_timestamp_ns":1704067200000003492,"raw_payload":"{\"channel\":\"l2_data\",\"sequence_num\":348,\"events\":[{\"updates\":[{\"side\":\"offer\",\"event_time\":\"2024-01-01T00:00:00.000000001Z\",\"price_level\":\"50001.00\",\"new_quantity\":\"1.00000000\"}]}]}"}
{"local_receipt_timestamp_ns":1704067200000003502,"raw_payload":"{\"channel\":\"l2_data\",\"sequence_num\":349,\"events\":[{\"updates\":[{\"side\":\"bid\",\"event_time\":\"2024-01-01T00:00:00.000000001Z\",\"price_level\":\"50000.00\",\"new_quantity\":\"1.00000000\"}]}]}"}
{"local_receipt_timestamp_ns":1704067200000003512,"raw_payload":"{\"channel\":\"l2_data\",\"sequence_num\":350,\"events\":[{\"updates\":[{\"side\":\"offer\",\"event_time\":\"2024-01-01T00:00:00.000000001Z\",\"price_level\":\"50001.00\",\"new_quantity\":\"1.00000000\"}]}]}"}
{"local_receipt_timestamp_ns":1704067200000003522,"raw_payload":"{\"channel\":\"l2_data\",\"sequence_num\":351,\"events\":[{\"updates\":[{\"side\":\"bid\",\"event_time\":\"2024-01-01T00:00:00.000000001Z\",\"price_level\":\"50000.00\",\"new_quantity\":\"1.00000000\"}]}]}"}
{"local_receipt_timestamp_ns":1704067200000003532,"raw_payload":"{\"channel\":\"l2_data\",\"sequence_num\":352,\"events\":[{\"updates\":[{\"side\":\"offer\",\"event_time\":\"2024-01-01T00:00:00.000000001Z\",\"price_level\":\"50001.00\",\"new_quantity\":\"1.00000000\"}]}]}"}
{"local_receipt_timestamp_ns":1704067200000003542,"raw_payload":"{\"channel\":\"l2_data\",\"sequence_num\":353,\"events\":[{\"updates\":[{\"side\":\"bid\",\"event_time\":\"2024-01-01T00:00:00.000000001Z\",\"price_level\":\"50000.00\",\"new_quantity\":\"1.00000000\"}]}]}"}
{"local_receipt_timestamp_ns":1704067200000003552,"raw_payload":"{\"channel\":\"l2_data\",\"sequence_num\":354,\"events\":[{\"updates\":[{\"side\":\"offer\",\"event_time\":\"2024-01-01T00:00:00.000000001Z\",\"price_level\":\"50001.00\",\"new_quantity\":\"1.00000000\"}]}]}"}
{"local_receipt_timestamp_ns":1704067200000003562,"raw_payload":"{\"channel\":\"l2_data\",\"sequence_num\":355,\"events\":[{\"updates\":[{\"side\":\"bid\",\"event_time\":\"2024-01-01T00:00:00.000000001Z\",\"price_level\":\"50000.00\",\"new_quantity\":\"1.00000000\"}]}]}"}
{"local_receipt_timestamp_ns":1704067200000003572,"raw_payload":"{\"channel\":\"l2_data\",\"sequence_num\":356,\"events\":[{\"updates\":[{\"side\":\"offer\",\"event_time\":\"2024-01-01T00:00:00.000000001Z\",\"price_level\":\"50001.00\",\"new_quantity\":\"1.00000000\"}]}]}"}
{"local_receipt_timestamp_ns":1704067200000003582,"raw_payload":"{\"channel\":\"l2_data\",\"sequence_num\":357,\"events\":[{\"updates\":[{\"side\":\"bid\",\"event_time\":\"2024-01-01T00:00:00.000000001Z\",\"price_level\":\"50000.00\",\"new_quantity\":\"1.00000000\"}]}]}"}
{"local_receipt_timestamp_ns":1704067200000003592,"raw_payload":"{\"channel\":\"l2_data\",\"sequence_num\":358,\"events\":[{\"updates\":[{\"side\":\"offer\",\"event_time\":\"2024-01-01T00:00:00.000000001Z\",\"price_level\":\"50001.00\",\"new_quantity\":\"1.00000000\"}]}]}"}
{"local_receipt_timestamp_ns":1704067200000003602,"raw_payload":"{\"channel\":\"l2_data\",\"sequence_num\":359,\"events\":[{\"updates\":[{\"side\":\"bid\",\"event_time\":\"2024-01-01T00:00:00.000000001Z\",\"price_level\":\"50000.00\",\"new_quantity\":\"1.00000000\"}]}]}"}
{"local_receipt_timestamp_ns":1704067200000003612,"raw_payload":"{\"channel\":\"l2_data\",\"sequence_num\":360,\"events\":[{\"updates\":[{\"side\":\"offer\",\"event_time\":\"2024-01-01T00:00:00.000000001Z\",\"price_level\":\"50001.00\",\"new_quantity\":\"1.00000000\"}]}]}"}
{"local_receipt_timestamp_ns":1704067200000003622,"raw_payload":"{\"channel\":\"l2_data\",\"sequence_num\":361,\"events\":[{\"updates\":[{\"side\":\"bid\",\"event_time\":\"2024-01-01T00:00:00.000000001Z\",\"price_level\":\"50000.00\",\"new_quantity\":\"1.00000000\"}]}]}"}
{"local_receipt_timestamp_ns":1704067200000003632,"raw_payload":"{\"channel\":\"l2_data\",\"sequence_num\":362,\"events\":[{\"updates\":[{\"side\":\"offer\",\"event_time\":\"2024-01-01T00:00:00.000000001Z\",\"price_level\":\"50001.00\",\"new_quantity\":\"1.00000000\"}]}]}"}
{"local_receipt_timestamp_ns":1704067200000003642,"raw_payload":"{\"channel\":\"l2_data\",\"sequence_num\":363,\"events\":[{\"updates\":[{\"side\":\"bid\",\"event_time\":\"2024-01-01T00:00:00.000000001Z\",\"price_level\":\"50000.00\",\"new_quantity\":\"1.00000000\"}]}]}"}
{"local_receipt_timestamp_ns":1704067200000003652,"raw_payload":"{\"channel\":\"l2_data\",\"sequence_num\":364,\"events\":[{\"updates\":[{\"side\":\"offer\",\"event_time\":\"2024-01-01T00:00:00.000000001Z\",\"price_level\":\"50001.00\",\"new_quantity\":\"1.00000000\"}]}]}"}
{"local_receipt_timestamp_ns":1704067200000003662,"raw_payload":"{\"channel\":\"l2_data\",\"sequence_num\":365,\"events\":[{\"updates\":[{\"side\":\"bid\",\"event_time\":\"2024-01-01T00:00:00.000000001Z\",\"price_level\":\"50000.00\",\"new_quantity\":\"1.00000000\"}]}]}"}
{"local_receipt_timestamp_ns":1704067200000003672,"raw_payload":"{\"channel\":\"l2_data\",\"sequence_num\":366,\"events\":[{\"updates\":[{\"side\":\"offer\",\"event_time\":\"2024-01-01T00:00:00.000000001Z\",\"price_level\":\"50001.00\",\"new_quantity\":\"1.00000000\"}]}]}"}
{"local_receipt_timestamp_ns":1704067200000003682,"raw_payload":"{\"channel\":\"l2_data\",\"sequence_num\":367,\"events\":[{\"updates\":[{\"side\":\"bid\",\"event_time\":\"2024-01-01T00:00:00.000000001Z\",\"price_level\":\"50000.00\",\"new_quantity\":\"1.00000000\"}]}]}"}
{"local_receipt_timestamp_ns":1704067200000003692,"raw_payload":"{\"channel\":\"l2_data\",\"sequence_num\":368,\"events\":[{\"updates\":[{\"side\":\"offer\",\"event_time\":\"2024-01-01T00:00:00.000000001Z\",\"price_level\":\"50001.00\",\"new_quantity\":\"1.00000000\"}]}]}"}
{"local_receipt_timestamp_ns":1704067200000003702,"raw_payload":"{\"channel\":\"l2_data\",\"sequence_num\":369,\"events\":[{\"updates\":[{\"side\":\"bid\",\"event_time\":\"2024-01-01T00:00:00.000000001Z\",\"price_level\":\"50000.00\",\"new_quantity\":\"1.00000000\"}]}]}"}
{"local_receipt_timestamp_ns":1704067200000003712,"raw_payload":"{\"channel\":\"l2_data\",\"sequence_num\":370,\"events\":[{\"updates\":[{\"side\":\"offer\",\"event_time\":\"2024-01-01T00:00:00.000000001Z\",\"price_level\":\"50001.00\",\"new_quantity\":\"1.00000000\"}]}]}"}
{"local_receipt_timestamp_ns":1704067200000003722,"raw_payload":"{\"channel\":\"l2_data\",\"sequence_num\":371,\"events\":[{\"updates\":[{\"side\":\"bid\",\"event_time\":\"2024-01-01T00:00:00.000000001Z\",\"price_level\":\"50000.00\",\"new_quantity\":\"1.00000000\"}]}]}"}
{"local_receipt_timestamp_ns":1704067200000003732,"raw_payload":"{\"channel\":\"l2_data\",\"sequence_num\":372,\"events\":[{\"updates\":[{\"side\":\"offer\",\"event_time\":\"2024-01-01T00:00:00.000000001Z\",\"price_level\":\"50001.00\",\"new_quantity\":\"1.00000000\"}]}]}"}
{"local_receipt_timestamp_ns":1704067200000003742,"raw_payload":"{\"channel\":\"l2_data\",\"sequence_num\":373,\"events\":[{\"updates\":[{\"side\":\"bid\",\"event_time\":\"2024-01-01T00:00:00.000000001Z\",\"price_level\":\"50000.00\",\"new_quantity\":\"1.00000000\"}]}]}"}
{"local_receipt_timestamp_ns":1704067200000003752,"raw_payload":"{\"channel\":\"l2_data\",\"sequence_num\":374,\"events\":[{\"updates\":[{\"side\":\"offer\",\"event_time\":\"2024-01-01T00:00:00.000000001Z\",\"price_level\":\"50001.00\",\"new_quantity\":\"1.00000000\"}]}]}"}
{"local_receipt_timestamp_ns":1704067200000003762,"raw_payload":"{\"channel\":\"l2_data\",\"sequence_num\":375,\"events\":[{\"updates\":[{\"side\":\"bid\",\"event_time\":\"2024-01-01T00:00:00.000000001Z\",\"price_level\":\"50000.00\",\"new_quantity\":\"1.00000000\"}]}]}"}
{"local_receipt_timestamp_ns":1704067200000003772,"raw_payload":"{\"channel\":\"l2_data\",\"sequence_num\":376,\"events\":[{\"updates\":[{\"side\":\"offer\",\"event_time\":\"2024-01-01T00:00:00.000000001Z\",\"price_level\":\"50001.00\",\"new_quantity\":\"1.00000000\"}]}]}"}
{"local_receipt_timestamp_ns":1704067200000003782,"raw_payload":"{\"channel\":\"l2_data\",\"sequence_num\":377,\"events\":[{\"updates\":[{\"side\":\"bid\",\"event_time\":\"2024-01-01T00:00:00.000000001Z\",\"price_level\":\"50000.00\",\"new_quantity\":\"1.00000000\"}]}]}"}
{"local_receipt_timestamp_ns":1704067200000003792,"raw_payload":"{\"channel\":\"l2_data\",\"sequence_num\":378,\"events\":[{\"updates\":[{\"side\":\"offer\",\"event_time\":\"2024-01-01T00:00:00.000000001Z\",\"price_level\":\"50001.00\",\"new_quantity\":\"1.00000000\"}]}]}"}
{"local_receipt_timestamp_ns":1704067200000003802,"raw_payload":"{\"channel\":\"l2_data\",\"sequence_num\":379,\"events\":[{\"updates\":[{\"side\":\"bid\",\"event_time\":\"2024-01-01T00:00:00.000000001Z\",\"price_level\":\"50000.00\",\"new_quantity\":\"1.00000000\"}]}]}"}
{"local_receipt_timestamp_ns":1704067200000003812,"raw_payload":"{\"channel\":\"l2_data\",\"sequence_num\":380,\"events\":[{\"updates\":[{\"side\":\"offer\",\"event_time\":\"2024-01-01T00:00:00.000000001Z\",\"price_level\":\"50001.00\",\"new_quantity\":\"1.00000000\"}]}]}"}
{"local_receipt_timestamp_ns":1704067200000003822,"raw_payload":"{\"channel\":\"l2_data\",\"sequence_num\":381,\"events\":[{\"updates\":[{\"side\":\"bid\",\"event_time\":\"2024-01-01T00:00:00.000000001Z\",\"price_level\":\"50000.00\",\"new_quantity\":\"1.00000000\"}]}]}"}
{"local_receipt_timestamp_ns":1704067200000003832,"raw_payload":"{\"channel\":\"l2_data\",\"sequence_num\":382,\"events\":[{\"updates\":[{\"side\":\"offer\",\"event_time\":\"2024-01-01T00:00:00.000000001Z\",\"price_level\":\"50001.00\",\"new_quantity\":\"1.00000000\"}]}]}"}
{"local_receipt_timestamp_ns":1704067200000003842,"raw_payload":"{\"channel\":\"l2_data\",\"sequence_num\":383,\"events\":[{\"updates\":[{\"side\":\"bid\",\"event_time\":\"2024-01-01T00:00:00.000000001Z\",\"price_level\":\"50000.00\",\"new_quantity\":\"1.00000000\"}]}]}"}
{"local_receipt_timestamp_ns":1704067200000003852,"raw_payload":"{\"channel\":\"l2_data\",\"sequence_num\":384,\"events\":[{\"updates\":[{\"side\":\"offer\",\"event_time\":\"2024-01-01T00:00:00.000000001Z\",\"price_level\":\"50001.00\",\"new_quantity\":\"1.00000000\"}]}]}"}
{"local_receipt_timestamp_ns":1704067200000003862,"raw_payload":"{\"channel\":\"l2_data\",\"sequence_num\":385,\"events\":[{\"updates\":[{\"side\":\"bid\",\"event_time\":\"2024-01-01T00:00:00.000000001Z\",\"price_level\":\"50000.00\",\"new_quantity\":\"1.00000000\"}]}]}"}
{"local_receipt_timestamp_ns":1704067200000003872,"raw_payload":"{\"channel\":\"l2_data\",\"sequence_num\":386,\"events\":[{\"updates\":[{\"side\":\"offer\",\"event_time\":\"2024-01-01T00:00:00.000000001Z\",\"price_level\":\"50001.00\",\"new_quantity\":\"1.00000000\"}]}]}"}
{"local_receipt_timestamp_ns":1704067200000003882,"raw_payload":"{\"channel\":\"l2_data\",\"sequence_num\":387,\"events\":[{\"updates\":[{\"side\":\"bid\",\"event_time\":\"2024-01-01T00:00:00.000000001Z\",\"price_level\":\"50000.00\",\"new_quantity\":\"1.00000000\"}]}]}"}
{"local_receipt_timestamp_ns":1704067200000003892,"raw_payload":"{\"channel\":\"l2_data\",\"sequence_num\":388,\"events\":[{\"updates\":[{\"side\":\"offer\",\"event_time\":\"2024-01-01T00:00:00.000000001Z\",\"price_level\":\"50001.00\",\"new_quantity\":\"1.00000000\"}]}]}"}
{"local_receipt_timestamp_ns":1704067200000003902,"raw_payload":"{\"channel\":\"l2_data\",\"sequence_num\":389,\"events\":[{\"updates\":[{\"side\":\"bid\",\"event_time\":\"2024-01-01T00:00:00.000000001Z\",\"price_level\":\"50000.00\",\"new_quantity\":\"1.00000000\"}]}]}"}
{"local_receipt_timestamp_ns":1704067200000003912,"raw_payload":"{\"channel\":\"l2_data\",\"sequence_num\":390,\"events\":[{\"updates\":[{\"side\":\"offer\",\"event_time\":\"2024-01-01T00:00:00.000000001Z\",\"price_level\":\"50001.00\",\"new_quantity\":\"1.00000000\"}]}]}"}
{"local_receipt_timestamp_ns":1704067200000003922,"raw_payload":"{\"channel\":\"l2_data\",\"sequence_num\":391,\"events\":[{\"updates\":[{\"side\":\"bid\",\"event_time\":\"2024-01-01T00:00:00.000000001Z\",\"price_level\":\"50000.00\",\"new_quantity\":\"1.00000000\"}]}]}"}
{"local_receipt_timestamp_ns":1704067200000003932,"raw_payload":"{\"channel\":\"l2_data\",\"sequence_num\":392,\"events\":[{\"updates\":[{\"side\":\"offer\",\"event_time\":\"2024-01-01T00:00:00.000000001Z\",\"price_level\":\"50001.00\",\"new_quantity\":\"1.00000000\"}]}]}"}
{"local_receipt_timestamp_ns":1704067200000003942,"raw_payload":"{\"channel\":\"l2_data\",\"sequence_num\":393,\"events\":[{\"updates\":[{\"side\":\"bid\",\"event_time\":\"2024-01-01T00:00:00.000000001Z\",\"price_level\":\"50000.00\",\"new_quantity\":\"1.00000000\"}]}]}"}
{"local_receipt_timestamp_ns":1704067200000003952,"raw_payload":"{\"channel\":\"l2_data\",\"sequence_num\":394,\"events\":[{\"updates\":[{\"side\":\"offer\",\"event_time\":\"2024-01-01T00:00:00.000000001Z\",\"price_level\":\"50001.00\",\"new_quantity\":\"1.00000000\"}]}]}"}
{"local_receipt_timestamp_ns":1704067200000003962,"raw_payload":"{\"channel\":\"l2_data\",\"sequence_num\":395,\"events\":[{\"updates\":[{\"side\":\"bid\",\"event_time\":\"2024-01-01T00:00:00.000000001Z\",\"price_level\":\"50000.00\",\"new_quantity\":\"1.00000000\"}]}]}"}
{"local_receipt_timestamp_ns":1704067200000003972,"raw_payload":"{\"channel\":\"l2_data\",\"sequence_num\":396,\"events\":[{\"updates\":[{\"side\":\"offer\",\"event_time\":\"2024-01-01T00:00:00.000000001Z\",\"price_level\":\"50001.00\",\"new_quantity\":\"1.00000000\"}]}]}"}
{"local_receipt_timestamp_ns":1704067200000003982,"raw_payload":"{\"channel\":\"l2_data\",\"sequence_num\":397,\"events\":[{\"updates\":[{\"side\":\"bid\",\"event_time\":\"2024-01-01T00:00:00.000000001Z\",\"price_level\":\"50000.00\",\"new_quantity\":\"1.00000000\"}]}]}"}
{"local_receipt_timestamp_ns":1704067200000003992,"raw_payload":"{\"channel\":\"l2_data\",\"sequence_num\":398,\"events\":[{\"updates\":[{\"side\":\"offer\",\"event_time\":\"2024-01-01T00:00:00.000000001Z\",\"price_level\":\"50001.00\",\"new_quantity\":\"1.00000000\"}]}]}"}
{"local_receipt_timestamp_ns":1704067200000004002,"raw_payload":"{\"channel\":\"l2_data\",\"sequence_num\":399,\"events\":[{\"updates\":[{\"side\":\"bid\",\"event_time\":\"2024-01-01T00:00:00.000000001Z\",\"price_level\":\"50000.00\",\"new_quantity\":\"1.00000000\"}]}]}"}
{"local_receipt_timestamp_ns":1704067200000004012,"raw_payload":"{\"channel\":\"l2_data\",\"sequence_num\":400,\"events\":[{\"updates\":[{\"side\":\"offer\",\"event_time\":\"2024-01-01T00:00:00.000000001Z\",\"price_level\":\"50001.00\",\"new_quantity\":\"1.00000000\"}]}]}"}
{"local_receipt_timestamp_ns":1704067200000004022,"raw_payload":"{\"channel\":\"l2_data\",\"sequence_num\":401,\"events\":[{\"updates\":[{\"side\":\"bid\",\"event_time\":\"2024-01-01T00:00:00.000000001Z\",\"price_level\":\"50000.00\",\"new_quantity\":\"1.00000000\"}]}]}"}
{"local_receipt_timestamp_ns":1704067200000004032,"raw_payload":"{\"channel\":\"l2_data\",\"sequence_num\":402,\"events\":[{\"updates\":[{\"side\":\"offer\",\"event_time\":\"2024-01-01T00:00:00.000000001Z\",\"price_level\":\"50001.00\",\"new_quantity\":\"1.00000000\"}]}]}"}
{"local_receipt_timestamp_ns":1704067200000004042,"raw_payload":"{\"channel\":\"l2_data\",\"sequence_num\":403,\"events\":[{\"updates\":[{\"side\":\"bid\",\"event_time\":\"2024-01-01T00:00:00.000000001Z\",\"price_level\":\"50000.00\",\"new_quantity\":\"1.00000000\"}]}]}"}
{"local_receipt_timestamp_ns":1704067200000004052,"raw_payload":"{\"channel\":\"l2_data\",\"sequence_num\":404,\"events\":[{\"updates\":[{\"side\":\"offer\",\"event_time\":\"2024-01-01T00:00:00.000000001Z\",\"price_level\":\"50001.00\",\"new_quantity\":\"1.00000000\"}]}]}"}
{"local_receipt_timestamp_ns":1704067200000004062,"raw_payload":"{\"channel\":\"l2_data\",\"sequence_num\":405,\"events\":[{\"updates\":[{\"side\":\"bid\",\"event_time\":\"2024-01-01T00:00:00.000000001Z\",\"price_level\":\"50000.00\",\"new_quantity\":\"1.00000000\"}]}]}"}
{"local_receipt_timestamp_ns":1704067200000004072,"raw_payload":"{\"channel\":\"l2_data\",\"sequence_num\":406,\"events\":[{\"updates\":[{\"side\":\"offer\",\"event_time\":\"2024-01-01T00:00:00.000000001Z\",\"price_level\":\"50001.00\",\"new_quantity\":\"1.00000000\"}]}]}"}
{"local_receipt_timestamp_ns":1704067200000004082,"raw_payload":"{\"channel\":\"l2_data\",\"sequence_num\":407,\"events\":[{\"updates\":[{\"side\":\"bid\",\"event_time\":\"2024-01-01T00:00:00.000000001Z\",\"price_level\":\"50000.00\",\"new_quantity\":\"1.00000000\"}]}]}"}
{"local_receipt_timestamp_ns":1704067200000004092,"raw_payload":"{\"channel\":\"l2_data\",\"sequence_num\":408,\"events\":[{\"updates\":[{\"side\":\"offer\",\"event_time\":\"2024-01-01T00:00:00.000000001Z\",\"price_level\":\"50001.00\",\"new_quantity\":\"1.00000000\"}]}]}"}
{"local_receipt_timestamp_ns":1704067200000004102,"raw_payload":"{\"channel\":\"l2_data\",\"sequence_num\":409,\"events\":[{\"updates\":[{\"side\":\"bid\",\"event_time\":\"2024-01-01T00:00:00.000000001Z\",\"price_level\":\"50000.00\",\"new_quantity\":\"1.00000000\"}]}]}"}
{"local_receipt_timestamp_ns":1704067200000004112,"raw_payload":"{\"channel\":\"l2_data\",\"sequence_num\":410,\"events\":[{\"updates\":[{\"side\":\"offer\",\"event_time\":\"2024-01-01T00:00:00.000000001Z\",\"price_level\":\"50001.00\",\"new_quantity\":\"1.00000000\"}]}]}"}
{"local_receipt_timestamp_ns":1704067200000004122,"raw_payload":"{\"channel\":\"l2_data\",\"sequence_num\":411,\"events\":[{\"updates\":[{\"side\":\"bid\",\"event_time\":\"2024-01-01T00:00:00.000000001Z\",\"price_level\":\"50000.00\",\"new_quantity\":\"1.00000000\"}]}]}"}
{"local_receipt_timestamp_ns":1704067200000004132,"raw_payload":"{\"channel\":\"l2_data\",\"sequence_num\":412,\"events\":[{\"updates\":[{\"side\":\"offer\",\"event_time\":\"2024-01-01T00:00:00.000000001Z\",\"price_level\":\"50001.00\",\"new_quantity\":\"1.00000000\"}]}]}"}
{"local_receipt_timestamp_ns":1704067200000004142,"raw_payload":"{\"channel\":\"l2_data\",\"sequence_num\":413,\"events\":[{\"updates\":[{\"side\":\"bid\",\"event_time\":\"2024-01-01T00:00:00.000000001Z\",\"price_level\":\"50000.00\",\"new_quantity\":\"1.00000000\"}]}]}"}
{"local_receipt_timestamp_ns":1704067200000004152,"raw_payload":"{\"channel\":\"l2_data\",\"sequence_num\":414,\"events\":[{\"updates\":[{\"side\":\"offer\",\"event_time\":\"2024-01-01T00:00:00.000000001Z\",\"price_level\":\"50001.00\",\"new_quantity\":\"1.00000000\"}]}]}"}
{"local_receipt_timestamp_ns":1704067200000004162,"raw_payload":"{\"channel\":\"l2_data\",\"sequence_num\":415,\"events\":[{\"updates\":[{\"side\":\"bid\",\"event_time\":\"2024-01-01T00:00:00.000000001Z\",\"price_level\":\"50000.00\",\"new_quantity\":\"1.00000000\"}]}]}"}
{"local_receipt_timestamp_ns":1704067200000004172,"raw_payload":"{\"channel\":\"l2_data\",\"sequence_num\":416,\"events\":[{\"updates\":[{\"side\":\"offer\",\"event_time\":\"2024-01-01T00:00:00.000000001Z\",\"price_level\":\"50001.00\",\"new_quantity\":\"1.00000000\"}]}]}"}
{"local_receipt_timestamp_ns":1704067200000004182,"raw_payload":"{\"channel\":\"l2_data\",\"sequence_num\":417,\"events\":[{\"updates\":[{\"side\":\"bid\",\"event_time\":\"2024-01-01T00:00:00.000000001Z\",\"price_level\":\"50000.00\",\"new_quantity\":\"1.00000000\"}]}]}"}
{"local_receipt_timestamp_ns":1704067200000004192,"raw_payload":"{\"channel\":\"l2_data\",\"sequence_num\":418,\"events\":[{\"updates\":[{\"side\":\"offer\",\"event_time\":\"2024-01-01T00:00:00.000000001Z\",\"price_level\":\"50001.00\",\"new_quantity\":\"1.00000000\"}]}]}"}
{"local_receipt_timestamp_ns":1704067200000004202,"raw_payload":"{\"channel\":\"l2_data\",\"sequence_num\":419,\"events\":[{\"updates\":[{\"side\":\"bid\",\"event_time\":\"2024-01-01T00:00:00.000000001Z\",\"price_level\":\"50000.00\",\"new_quantity\":\"1.00000000\"}]}]}"}
{"local_receipt_timestamp_ns":1704067200000004212,"raw_payload":"{\"channel\":\"l2_data\",\"sequence_num\":420,\"events\":[{\"updates\":[{\"side\":\"offer\",\"event_time\":\"2024-01-01T00:00:00.000000001Z\",\"price_level\":\"50001.00\",\"new_quantity\":\"1.00000000\"}]}]}"}
{"local_receipt_timestamp_ns":1704067200000004222,"raw_payload":"{\"channel\":\"l2_data\",\"sequence_num\":421,\"events\":[{\"updates\":[{\"side\":\"bid\",\"event_time\":\"2024-01-01T00:00:00.000000001Z\",\"price_level\":\"50000.00\",\"new_quantity\":\"1.00000000\"}]}]}"}
{"local_receipt_timestamp_ns":1704067200000004232,"raw_payload":"{\"channel\":\"l2_data\",\"sequence_num\":422,\"events\":[{\"updates\":[{\"side\":\"offer\",\"event_time\":\"2024-01-01T00:00:00.000000001Z\",\"price_level\":\"50001.00\",\"new_quantity\":\"1.00000000\"}]}]}"}
{"local_receipt_timestamp_ns":1704067200000004242,"raw_payload":"{\"channel\":\"l2_data\",\"sequence_num\":423,\"events\":[{\"updates\":[{\"side\":\"bid\",\"event_time\":\"2024-01-01T00:00:00.000000001Z\",\"price_level\":\"50000.00\",\"new_quantity\":\"1.00000000\"}]}]}"}
{"local_receipt_timestamp_ns":1704067200000004252,"raw_payload":"{\"channel\":\"l2_data\",\"sequence_num\":424,\"events\":[{\"updates\":[{\"side\":\"offer\",\"event_time\":\"2024-01-01T00:00:00.000000001Z\",\"price_level\":\"50001.00\",\"new_quantity\":\"1.00000000\"}]}]}"}
{"local_receipt_timestamp_ns":1704067200000004262,"raw_payload":"{\"channel\":\"l2_data\",\"sequence_num\":425,\"events\":[{\"updates\":[{\"side\":\"bid\",\"event_time\":\"2024-01-01T00:00:00.000000001Z\",\"price_level\":\"50000.00\",\"new_quantity\":\"1.00000000\"}]}]}"}
{"local_receipt_timestamp_ns":1704067200000004272,"raw_payload":"{\"channel\":\"l2_data\",\"sequence_num\":426,\"events\":[{\"updates\":[{\"side\":\"offer\",\"event_time\":\"2024-01-01T00:00:00.000000001Z\",\"price_level\":\"50001.00\",\"new_quantity\":\"1.00000000\"}]}]}"}
{"local_receipt_timestamp_ns":1704067200000004282,"raw_payload":"{\"channel\":\"l2_data\",\"sequence_num\":427,\"events\":[{\"updates\":[{\"side\":\"bid\",\"event_time\":\"2024-01-01T00:00:00.000000001Z\",\"price_level\":\"50000.00\",\"new_quantity\":\"1.00000000\"}]}]}"}
{"local_receipt_timestamp_ns":1704067200000004292,"raw_payload":"{\"channel\":\"l2_data\",\"sequence_num\":428,\"events\":[{\"updates\":[{\"side\":\"offer\",\"event_time\":\"2024-01-01T00:00:00.000000001Z\",\"price_level\":\"50001.00\",\"new_quantity\":\"1.00000000\"}]}]}"}
{"local_receipt_timestamp_ns":1704067200000004302,"raw_payload":"{\"channel\":\"l2_data\",\"sequence_num\":429,\"events\":[{\"updates\":[{\"side\":\"bid\",\"event_time\":\"2024-01-01T00:00:00.000000001Z\",\"price_level\":\"50000.00\",\"new_quantity\":\"1.00000000\"}]}]}"}
{"local_receipt_timestamp_ns":1704067200000004312,"raw_payload":"{\"channel\":\"l2_data\",\"sequence_num\":430,\"events\":[{\"updates\":[{\"side\":\"offer\",\"event_time\":\"2024-01-01T00:00:00.000000001Z\",\"price_level\":\"50001.00\",\"new_quantity\":\"1.00000000\"}]}]}"}
{"local_receipt_timestamp_ns":1704067200000004322,"raw_payload":"{\"channel\":\"l2_data\",\"sequence_num\":431,\"events\":[{\"updates\":[{\"side\":\"bid\",\"event_time\":\"2024-01-01T00:00:00.000000001Z\",\"price_level\":\"50000.00\",\"new_quantity\":\"1.00000000\"}]}]}"}
{"local_receipt_timestamp_ns":1704067200000004332,"raw_payload":"{\"channel\":\"l2_data\",\"sequence_num\":432,\"events\":[{\"updates\":[{\"side\":\"offer\",\"event_time\":\"2024-01-01T00:00:00.000000001Z\",\"price_level\":\"50001.00\",\"new_quantity\":\"1.00000000\"}]}]}"}
{"local_receipt_timestamp_ns":1704067200000004342,"raw_payload":"{\"channel\":\"l2_data\",\"sequence_num\":433,\"events\":[{\"updates\":[{\"side\":\"bid\",\"event_time\":\"2024-01-01T00:00:00.000000001Z\",\"price_level\":\"50000.00\",\"new_quantity\":\"1.00000000\"}]}]}"}
{"local_receipt_timestamp_ns":1704067200000004352,"raw_payload":"{\"channel\":\"l2_data\",\"sequence_num\":434,\"events\":[{\"updates\":[{\"side\":\"offer\",\"event_time\":\"2024-01-01T00:00:00.000000001Z\",\"price_level\":\"50001.00\",\"new_quantity\":\"1.00000000\"}]}]}"}
{"local_receipt_timestamp_ns":1704067200000004362,"raw_payload":"{\"channel\":\"l2_data\",\"sequence_num\":435,\"events\":[{\"updates\":[{\"side\":\"bid\",\"event_time\":\"2024-01-01T00:00:00.000000001Z\",\"price_level\":\"50000.00\",\"new_quantity\":\"1.00000000\"}]}]}"}
{"local_receipt_timestamp_ns":1704067200000004372,"raw_payload":"{\"channel\":\"l2_data\",\"sequence_num\":436,\"events\":[{\"updates\":[{\"side\":\"offer\",\"event_time\":\"2024-01-01T00:00:00.000000001Z\",\"price_level\":\"50001.00\",\"new_quantity\":\"1.00000000\"}]}]}"}
{"local_receipt_timestamp_ns":1704067200000004382,"raw_payload":"{\"channel\":\"l2_data\",\"sequence_num\":437,\"events\":[{\"updates\":[{\"side\":\"bid\",\"event_time\":\"2024-01-01T00:00:00.000000001Z\",\"price_level\":\"50000.00\",\"new_quantity\":\"1.00000000\"}]}]}"}
{"local_receipt_timestamp_ns":1704067200000004392,"raw_payload":"{\"channel\":\"l2_data\",\"sequence_num\":438,\"events\":[{\"updates\":[{\"side\":\"offer\",\"event_time\":\"2024-01-01T00:00:00.000000001Z\",\"price_level\":\"50001.00\",\"new_quantity\":\"1.00000000\"}]}]}"}
{"local_receipt_timestamp_ns":1704067200000004402,"raw_payload":"{\"channel\":\"l2_data\",\"sequence_num\":439,\"events\":[{\"updates\":[{\"side\":\"bid\",\"event_time\":\"2024-01-01T00:00:00.000000001Z\",\"price_level\":\"50000.00\",\"new_quantity\":\"1.00000000\"}]}]}"}
{"local_receipt_timestamp_ns":1704067200000004412,"raw_payload":"{\"channel\":\"l2_data\",\"sequence_num\":440,\"events\":[{\"updates\":[{\"side\":\"offer\",\"event_time\":\"2024-01-01T00:00:00.000000001Z\",\"price_level\":\"50001.00\",\"new_quantity\":\"1.00000000\"}]}]}"}
{"local_receipt_timestamp_ns":1704067200000004422,"raw_payload":"{\"channel\":\"l2_data\",\"sequence_num\":441,\"events\":[{\"updates\":[{\"side\":\"bid\",\"event_time\":\"2024-01-01T00:00:00.000000001Z\",\"price_level\":\"50000.00\",\"new_quantity\":\"1.00000000\"}]}]}"}
{"local_receipt_timestamp_ns":1704067200000004432,"raw_payload":"{\"channel\":\"l2_data\",\"sequence_num\":442,\"events\":[{\"updates\":[{\"side\":\"offer\",\"event_time\":\"2024-01-01T00:00:00.000000001Z\",\"price_level\":\"50001.00\",\"new_quantity\":\"1.00000000\"}]}]}"}
{"local_receipt_timestamp_ns":1704067200000004442,"raw_payload":"{\"channel\":\"l2_data\",\"sequence_num\":443,\"events\":[{\"updates\":[{\"side\":\"bid\",\"event_time\":\"2024-01-01T00:00:00.000000001Z\",\"price_level\":\"50000.00\",\"new_quantity\":\"1.00000000\"}]}]}"}
{"local_receipt_timestamp_ns":1704067200000004452,"raw_payload":"{\"channel\":\"l2_data\",\"sequence_num\":444,\"events\":[{\"updates\":[{\"side\":\"offer\",\"event_time\":\"2024-01-01T00:00:00.000000001Z\",\"price_level\":\"50001.00\",\"new_quantity\":\"1.00000000\"}]}]}"}
{"local_receipt_timestamp_ns":1704067200000004462,"raw_payload":"{\"channel\":\"l2_data\",\"sequence_num\":445,\"events\":[{\"updates\":[{\"side\":\"bid\",\"event_time\":\"2024-01-01T00:00:00.000000001Z\",\"price_level\":\"50000.00\",\"new_quantity\":\"1.00000000\"}]}]}"}
{"local_receipt_timestamp_ns":1704067200000004472,"raw_payload":"{\"channel\":\"l2_data\",\"sequence_num\":446,\"events\":[{\"updates\":[{\"side\":\"offer\",\"event_time\":\"2024-01-01T00:00:00.000000001Z\",\"price_level\":\"50001.00\",\"new_quantity\":\"1.00000000\"}]}]}"}
{"local_receipt_timestamp_ns":1704067200000004482,"raw_payload":"{\"channel\":\"l2_data\",\"sequence_num\":447,\"events\":[{\"updates\":[{\"side\":\"bid\",\"event_time\":\"2024-01-01T00:00:00.000000001Z\",\"price_level\":\"50000.00\",\"new_quantity\":\"1.00000000\"}]}]}"}
{"local_receipt_timestamp_ns":1704067200000004492,"raw_payload":"{\"channel\":\"l2_data\",\"sequence_num\":448,\"events\":[{\"updates\":[{\"side\":\"offer\",\"event_time\":\"2024-01-01T00:00:00.000000001Z\",\"price_level\":\"50001.00\",\"new_quantity\":\"1.00000000\"}]}]}"}
{"local_receipt_timestamp_ns":1704067200000004502,"raw_payload":"{\"channel\":\"l2_data\",\"sequence_num\":449,\"events\":[{\"updates\":[{\"side\":\"bid\",\"event_time\":\"2024-01-01T00:00:00.000000001Z\",\"price_level\":\"50000.00\",\"new_quantity\":\"1.00000000\"}]}]}"}
{"local_receipt_timestamp_ns":1704067200000004512,"raw_payload":"{\"channel\":\"l2_data\",\"sequence_num\":450,\"events\":[{\"updates\":[{\"side\":\"offer\",\"event_time\":\"2024-01-01T00:00:00.000000001Z\",\"price_level\":\"50001.00\",\"new_quantity\":\"1.00000000\"}]}]}"}
{"local_receipt_timestamp_ns":1704067200000004522,"raw_payload":"{\"channel\":\"l2_data\",\"sequence_num\":451,\"events\":[{\"updates\":[{\"side\":\"bid\",\"event_time\":\"2024-01-01T00:00:00.000000001Z\",\"price_level\":\"50000.00\",\"new_quantity\":\"1.00000000\"}]}]}"}
{"local_receipt_timestamp_ns":1704067200000004532,"raw_payload":"{\"channel\":\"l2_data\",\"sequence_num\":452,\"events\":[{\"updates\":[{\"side\":\"offer\",\"event_time\":\"2024-01-01T00:00:00.000000001Z\",\"price_level\":\"50001.00\",\"new_quantity\":\"1.00000000\"}]}]}"}
{"local_receipt_timestamp_ns":1704067200000004542,"raw_payload":"{\"channel\":\"l2_data\",\"sequence_num\":453,\"events\":[{\"updates\":[{\"side\":\"bid\",\"event_time\":\"2024-01-01T00:00:00.000000001Z\",\"price_level\":\"50000.00\",\"new_quantity\":\"1.00000000\"}]}]}"}
{"local_receipt_timestamp_ns":1704067200000004552,"raw_payload":"{\"channel\":\"l2_data\",\"sequence_num\":454,\"events\":[{\"updates\":[{\"side\":\"offer\",\"event_time\":\"2024-01-01T00:00:00.000000001Z\",\"price_level\":\"50001.00\",\"new_quantity\":\"1.00000000\"}]}]}"}
{"local_receipt_timestamp_ns":1704067200000004562,"raw_payload":"{\"channel\":\"l2_data\",\"sequence_num\":455,\"events\":[{\"updates\":[{\"side\":\"bid\",\"event_time\":\"2024-01-01T00:00:00.000000001Z\",\"price_level\":\"50000.00\",\"new_quantity\":\"1.00000000\"}]}]}"}
{"local_receipt_timestamp_ns":1704067200000004572,"raw_payload":"{\"channel\":\"l2_data\",\"sequence_num\":456,\"events\":[{\"updates\":[{\"side\":\"offer\",\"event_time\":\"2024-01-01T00:00:00.000000001Z\",\"price_level\":\"50001.00\",\"new_quantity\":\"1.00000000\"}]}]}"}
{"local_receipt_timestamp_ns":1704067200000004582,"raw_payload":"{\"channel\":\"l2_data\",\"sequence_num\":457,\"events\":[{\"updates\":[{\"side\":\"bid\",\"event_time\":\"2024-01-01T00:00:00.000000001Z\",\"price_level\":\"50000.00\",\"new_quantity\":\"1.00000000\"}]}]}"}
{"local_receipt_timestamp_ns":1704067200000004592,"raw_payload":"{\"channel\":\"l2_data\",\"sequence_num\":458,\"events\":[{\"updates\":[{\"side\":\"offer\",\"event_time\":\"2024-01-01T00:00:00.000000001Z\",\"price_level\":\"50001.00\",\"new_quantity\":\"1.00000000\"}]}]}"}
{"local_receipt_timestamp_ns":1704067200000004602,"raw_payload":"{\"channel\":\"l2_data\",\"sequence_num\":459,\"events\":[{\"updates\":[{\"side\":\"bid\",\"event_time\":\"2024-01-01T00:00:00.000000001Z\",\"price_level\":\"50000.00\",\"new_quantity\":\"1.00000000\"}]}]}"}
{"local_receipt_timestamp_ns":1704067200000004612,"raw_payload":"{\"channel\":\"l2_data\",\"sequence_num\":460,\"events\":[{\"updates\":[{\"side\":\"offer\",\"event_time\":\"2024-01-01T00:00:00.000000001Z\",\"price_level\":\"50001.00\",\"new_quantity\":\"1.00000000\"}]}]}"}
{"local_receipt_timestamp_ns":1704067200000004622,"raw_payload":"{\"channel\":\"l2_data\",\"sequence_num\":461,\"events\":[{\"updates\":[{\"side\":\"bid\",\"event_time\":\"2024-01-01T00:00:00.000000001Z\",\"price_level\":\"50000.00\",\"new_quantity\":\"1.00000000\"}]}]}"}
{"local_receipt_timestamp_ns":1704067200000004632,"raw_payload":"{\"channel\":\"l2_data\",\"sequence_num\":462,\"events\":[{\"updates\":[{\"side\":\"offer\",\"event_time\":\"2024-01-01T00:00:00.000000001Z\",\"price_level\":\"50001.00\",\"new_quantity\":\"1.00000000\"}]}]}"}
{"local_receipt_timestamp_ns":1704067200000004642,"raw_payload":"{\"channel\":\"l2_data\",\"sequence_num\":463,\"events\":[{\"updates\":[{\"side\":\"bid\",\"event_time\":\"2024-01-01T00:00:00.000000001Z\",\"price_level\":\"50000.00\",\"new_quantity\":\"1.00000000\"}]}]}"}
{"local_receipt_timestamp_ns":1704067200000004652,"raw_payload":"{\"channel\":\"l2_data\",\"sequence_num\":464,\"events\":[{\"updates\":[{\"side\":\"offer\",\"event_time\":\"2024-01-01T00:00:00.000000001Z\",\"price_level\":\"50001.00\",\"new_quantity\":\"1.00000000\"}]}]}"}
{"local_receipt_timestamp_ns":1704067200000004662,"raw_payload":"{\"channel\":\"l2_data\",\"sequence_num\":465,\"events\":[{\"updates\":[{\"side\":\"bid\",\"event_time\":\"2024-01-01T00:00:00.000000001Z\",\"price_level\":\"50000.00\",\"new_quantity\":\"1.00000000\"}]}]}"}
{"local_receipt_timestamp_ns":1704067200000004672,"raw_payload":"{\"channel\":\"l2_data\",\"sequence_num\":466,\"events\":[{\"updates\":[{\"side\":\"offer\",\"event_time\":\"2024-01-01T00:00:00.000000001Z\",\"price_level\":\"50001.00\",\"new_quantity\":\"1.00000000\"}]}]}"}
{"local_receipt_timestamp_ns":1704067200000004682,"raw_payload":"{\"channel\":\"l2_data\",\"sequence_num\":467,\"events\":[{\"updates\":[{\"side\":\"bid\",\"event_time\":\"2024-01-01T00:00:00.000000001Z\",\"price_level\":\"50000.00\",\"new_quantity\":\"1.00000000\"}]}]}"}
{"local_receipt_timestamp_ns":1704067200000004692,"raw_payload":"{\"channel\":\"l2_data\",\"sequence_num\":468,\"events\":[{\"updates\":[{\"side\":\"offer\",\"event_time\":\"2024-01-01T00:00:00.000000001Z\",\"price_level\":\"50001.00\",\"new_quantity\":\"1.00000000\"}]}]}"}
{"local_receipt_timestamp_ns":1704067200000004702,"raw_payload":"{\"channel\":\"l2_data\",\"sequence_num\":469,\"events\":[{\"updates\":[{\"side\":\"bid\",\"event_time\":\"2024-01-01T00:00:00.000000001Z\",\"price_level\":\"50000.00\",\"new_quantity\":\"1.00000000\"}]}]}"}
{"local_receipt_timestamp_ns":1704067200000004712,"raw_payload":"{\"channel\":\"l2_data\",\"sequence_num\":470,\"events\":[{\"updates\":[{\"side\":\"offer\",\"event_time\":\"2024-01-01T00:00:00.000000001Z\",\"price_level\":\"50001.00\",\"new_quantity\":\"1.00000000\"}]}]}"}
{"local_receipt_timestamp_ns":1704067200000004722,"raw_payload":"{\"channel\":\"l2_data\",\"sequence_num\":471,\"events\":[{\"updates\":[{\"side\":\"bid\",\"event_time\":\"2024-01-01T00:00:00.000000001Z\",\"price_level\":\"50000.00\",\"new_quantity\":\"1.00000000\"}]}]}"}
{"local_receipt_timestamp_ns":1704067200000004732,"raw_payload":"{\"channel\":\"l2_data\",\"sequence_num\":472,\"events\":[{\"updates\":[{\"side\":\"offer\",\"event_time\":\"2024-01-01T00:00:00.000000001Z\",\"price_level\":\"50001.00\",\"new_quantity\":\"1.00000000\"}]}]}"}
{"local_receipt_timestamp_ns":1704067200000004742,"raw_payload":"{\"channel\":\"l2_data\",\"sequence_num\":473,\"events\":[{\"updates\":[{\"side\":\"bid\",\"event_time\":\"2024-01-01T00:00:00.000000001Z\",\"price_level\":\"50000.00\",\"new_quantity\":\"1.00000000\"}]}]}"}
{"local_receipt_timestamp_ns":1704067200000004752,"raw_payload":"{\"channel\":\"l2_data\",\"sequence_num\":474,\"events\":[{\"updates\":[{\"side\":\"offer\",\"event_time\":\"2024-01-01T00:00:00.000000001Z\",\"price_level\":\"50001.00\",\"new_quantity\":\"1.00000000\"}]}]}"}
{"local_receipt_timestamp_ns":1704067200000004762,"raw_payload":"{\"channel\":\"l2_data\",\"sequence_num\":475,\"events\":[{\"updates\":[{\"side\":\"bid\",\"event_time\":\"2024-01-01T00:00:00.000000001Z\",\"price_level\":\"50000.00\",\"new_quantity\":\"1.00000000\"}]}]}"}
{"local_receipt_timestamp_ns":1704067200000004772,"raw_payload":"{\"channel\":\"l2_data\",\"sequence_num\":476,\"events\":[{\"updates\":[{\"side\":\"offer\",\"event_time\":\"2024-01-01T00:00:00.000000001Z\",\"price_level\":\"50001.00\",\"new_quantity\":\"1.00000000\"}]}]}"}
{"local_receipt_timestamp_ns":1704067200000004782,"raw_payload":"{\"channel\":\"l2_data\",\"sequence_num\":477,\"events\":[{\"updates\":[{\"side\":\"bid\",\"event_time\":\"2024-01-01T00:00:00.000000001Z\",\"price_level\":\"50000.00\",\"new_quantity\":\"1.00000000\"}]}]}"}
{"local_receipt_timestamp_ns":1704067200000004792,"raw_payload":"{\"channel\":\"l2_data\",\"sequence_num\":478,\"events\":[{\"updates\":[{\"side\":\"offer\",\"event_time\":\"2024-01-01T00:00:00.000000001Z\",\"price_level\":\"50001.00\",\"new_quantity\":\"1.00000000\"}]}]}"}
{"local_receipt_timestamp_ns":1704067200000004802,"raw_payload":"{\"channel\":\"l2_data\",\"sequence_num\":479,\"events\":[{\"updates\":[{\"side\":\"bid\",\"event_time\":\"2024-01-01T00:00:00.000000001Z\",\"price_level\":\"50000.00\",\"new_quantity\":\"1.00000000\"}]}]}"}
{"local_receipt_timestamp_ns":1704067200000004812,"raw_payload":"{\"channel\":\"l2_data\",\"sequence_num\":480,\"events\":[{\"updates\":[{\"side\":\"offer\",\"event_time\":\"2024-01-01T00:00:00.000000001Z\",\"price_level\":\"50001.00\",\"new_quantity\":\"1.00000000\"}]}]}"}
{"local_receipt_timestamp_ns":1704067200000004822,"raw_payload":"{\"channel\":\"l2_data\",\"sequence_num\":481,\"events\":[{\"updates\":[{\"side\":\"bid\",\"event_time\":\"2024-01-01T00:00:00.000000001Z\",\"price_level\":\"50000.00\",\"new_quantity\":\"1.00000000\"}]}]}"}
{"local_receipt_timestamp_ns":1704067200000004832,"raw_payload":"{\"channel\":\"l2_data\",\"sequence_num\":482,\"events\":[{\"updates\":[{\"side\":\"offer\",\"event_time\":\"2024-01-01T00:00:00.000000001Z\",\"price_level\":\"50001.00\",\"new_quantity\":\"1.00000000\"}]}]}"}
{"local_receipt_timestamp_ns":1704067200000004842,"raw_payload":"{\"channel\":\"l2_data\",\"sequence_num\":483,\"events\":[{\"updates\":[{\"side\":\"bid\",\"event_time\":\"2024-01-01T00:00:00.000000001Z\",\"price_level\":\"50000.00\",\"new_quantity\":\"1.00000000\"}]}]}"}
{"local_receipt_timestamp_ns":1704067200000004852,"raw_payload":"{\"channel\":\"l2_data\",\"sequence_num\":484,\"events\":[{\"updates\":[{\"side\":\"offer\",\"event_time\":\"2024-01-01T00:00:00.000000001Z\",\"price_level\":\"50001.00\",\"new_quantity\":\"1.00000000\"}]}]}"}
{"local_receipt_timestamp_ns":1704067200000004862,"raw_payload":"{\"channel\":\"l2_data\",\"sequence_num\":485,\"events\":[{\"updates\":[{\"side\":\"bid\",\"event_time\":\"2024-01-01T00:00:00.000000001Z\",\"price_level\":\"50000.00\",\"new_quantity\":\"1.00000000\"}]}]}"}
{"local_receipt_timestamp_ns":1704067200000004872,"raw_payload":"{\"channel\":\"l2_data\",\"sequence_num\":486,\"events\":[{\"updates\":[{\"side\":\"offer\",\"event_time\":\"2024-01-01T00:00:00.000000001Z\",\"price_level\":\"50001.00\",\"new_quantity\":\"1.00000000\"}]}]}"}
{"local_receipt_timestamp_ns":1704067200000004882,"raw_payload":"{\"channel\":\"l2_data\",\"sequence_num\":487,\"events\":[{\"updates\":[{\"side\":\"bid\",\"event_time\":\"2024-01-01T00:00:00.000000001Z\",\"price_level\":\"50000.00\",\"new_quantity\":\"1.00000000\"}]}]}"}
{"local_receipt_timestamp_ns":1704067200000004892,"raw_payload":"{\"channel\":\"l2_data\",\"sequence_num\":488,\"events\":[{\"updates\":[{\"side\":\"offer\",\"event_time\":\"2024-01-01T00:00:00.000000001Z\",\"price_level\":\"50001.00\",\"new_quantity\":\"1.00000000\"}]}]}"}
{"local_receipt_timestamp_ns":1704067200000004902,"raw_payload":"{\"channel\":\"l2_data\",\"sequence_num\":489,\"events\":[{\"updates\":[{\"side\":\"bid\",\"event_time\":\"2024-01-01T00:00:00.000000001Z\",\"price_level\":\"50000.00\",\"new_quantity\":\"1.00000000\"}]}]}"}
{"local_receipt_timestamp_ns":1704067200000004912,"raw_payload":"{\"channel\":\"l2_data\",\"sequence_num\":490,\"events\":[{\"updates\":[{\"side\":\"offer\",\"event_time\":\"2024-01-01T00:00:00.000000001Z\",\"price_level\":\"50001.00\",\"new_quantity\":\"1.00000000\"}]}]}"}
{"local_receipt_timestamp_ns":1704067200000004922,"raw_payload":"{\"channel\":\"l2_data\",\"sequence_num\":491,\"events\":[{\"updates\":[{\"side\":\"bid\",\"event_time\":\"2024-01-01T00:00:00.000000001Z\",\"price_level\":\"50000.00\",\"new_quantity\":\"1.00000000\"}]}]}"}
{"local_receipt_timestamp_ns":1704067200000004932,"raw_payload":"{\"channel\":\"l2_data\",\"sequence_num\":492,\"events\":[{\"updates\":[{\"side\":\"offer\",\"event_time\":\"2024-01-01T00:00:00.000000001Z\",\"price_level\":\"50001.00\",\"new_quantity\":\"1.00000000\"}]}]}"}
{"local_receipt_timestamp_ns":1704067200000004942,"raw_payload":"{\"channel\":\"l2_data\",\"sequence_num\":493,\"events\":[{\"updates\":[{\"side\":\"bid\",\"event_time\":\"2024-01-01T00:00:00.000000001Z\",\"price_level\":\"50000.00\",\"new_quantity\":\"1.00000000\"}]}]}"}
{"local_receipt_timestamp_ns":1704067200000004952,"raw_payload":"{\"channel\":\"l2_data\",\"sequence_num\":494,\"events\":[{\"updates\":[{\"side\":\"offer\",\"event_time\":\"2024-01-01T00:00:00.000000001Z\",\"price_level\":\"50001.00\",\"new_quantity\":\"1.00000000\"}]}]}"}
{"local_receipt_timestamp_ns":1704067200000004962,"raw_payload":"{\"channel\":\"l2_data\",\"sequence_num\":495,\"events\":[{\"updates\":[{\"side\":\"bid\",\"event_time\":\"2024-01-01T00:00:00.000000001Z\",\"price_level\":\"50000.00\",\"new_quantity\":\"1.00000000\"}]}]}"}
{"local_receipt_timestamp_ns":1704067200000004972,"raw_payload":"{\"channel\":\"l2_data\",\"sequence_num\":496,\"events\":[{\"updates\":[{\"side\":\"offer\",\"event_time\":\"2024-01-01T00:00:00.000000001Z\",\"price_level\":\"50001.00\",\"new_quantity\":\"1.00000000\"}]}]}"}
{"local_receipt_timestamp_ns":1704067200000004982,"raw_payload":"{\"channel\":\"l2_data\",\"sequence_num\":497,\"events\":[{\"updates\":[{\"side\":\"bid\",\"event_time\":\"2024-01-01T00:00:00.000000001Z\",\"price_level\":\"50000.00\",\"new_quantity\":\"1.00000000\"}]}]}"}
{"local_receipt_timestamp_ns":1704067200000004992,"raw_payload":"{\"channel\":\"l2_data\",\"sequence_num\":498,\"events\":[{\"updates\":[{\"side\":\"offer\",\"event_time\":\"2024-01-01T00:00:00.000000001Z\",\"price_level\":\"50001.00\",\"new_quantity\":\"1.00000000\"}]}]}"}
{"local_receipt_timestamp_ns":1704067200000005002,"raw_payload":"{\"channel\":\"l2_data\",\"sequence_num\":499,\"events\":[{\"updates\":[{\"side\":\"bid\",\"event_time\":\"2024-01-01T00:00:00.000000001Z\",\"price_level\":\"50000.00\",\"new_quantity\":\"1.00000000\"}]}]}"}
{"local_receipt_timestamp_ns":1704067200000005012,"raw_payload":"{\"channel\":\"l2_data\",\"sequence_num\":500,\"events\":[{\"updates\":[{\"side\":\"offer\",\"event_time\":\"2024-01-01T00:00:00.000000001Z\",\"price_level\":\"50001.00\",\"new_quantity\":\"1.00000000\"}]}]}"}
{"local_receipt_timestamp_ns":1704067200000005022,"raw_payload":"{\"channel\":\"l2_data\",\"sequence_num\":501,\"events\":[{\"updates\":[{\"side\":\"bid\",\"event_time\":\"2024-01-01T00:00:00.000000001Z\",\"price_level\":\"50000.00\",\"new_quantity\":\"1.00000000\"}]}]}"}
{"local_receipt_timestamp_ns":1704067200000005032,"raw_payload":"{\"channel\":\"l2_data\",\"sequence_num\":502,\"events\":[{\"updates\":[{\"side\":\"offer\",\"event_time\":\"2024-01-01T00:00:00.000000001Z\",\"price_level\":\"50001.00\",\"new_quantity\":\"1.00000000\"}]}]}"}
{"local_receipt_timestamp_ns":1704067200000005042,"raw_payload":"{\"channel\":\"l2_data\",\"sequence_num\":503,\"events\":[{\"updates\":[{\"side\":\"bid\",\"event_time\":\"2024-01-01T00:00:00.000000001Z\",\"price_level\":\"50000.00\",\"new_quantity\":\"1.00000000\"}]}]}"}
{"local_receipt_timestamp_ns":1704067200000005052,"raw_payload":"{\"channel\":\"l2_data\",\"sequence_num\":504,\"events\":[{\"updates\":[{\"side\":\"offer\",\"event_time\":\"2024-01-01T00:00:00.000000001Z\",\"price_level\":\"50001.00\",\"new_quantity\":\"1.00000000\"}]}]}"}
{"local_receipt_timestamp_ns":1704067200000005062,"raw_payload":"{\"channel\":\"l2_data\",\"sequence_num\":505,\"events\":[{\"updates\":[{\"side\":\"bid\",\"event_time\":\"2024-01-01T00:00:00.000000001Z\",\"price_level\":\"50000.00\",\"new_quantity\":\"1.00000000\"}]}]}"}
{"local_receipt_timestamp_ns":1704067200000005072,"raw_payload":"{\"channel\":\"l2_data\",\"sequence_num\":506,\"events\":[{\"updates\":[{\"side\":\"offer\",\"event_time\":\"2024-01-01T00:00:00.000000001Z\",\"price_level\":\"50001.00\",\"new_quantity\":\"1.00000000\"}]}]}"}
{"local_receipt_timestamp_ns":1704067200000005082,"raw_payload":"{\"channel\":\"l2_data\",\"sequence_num\":507,\"events\":[{\"updates\":[{\"side\":\"bid\",\"event_time\":\"2024-01-01T00:00:00.000000001Z\",\"price_level\":\"50000.00\",\"new_quantity\":\"1.00000000\"}]}]}"}
{"local_receipt_timestamp_ns":1704067200000005092,"raw_payload":"{\"channel\":\"l2_data\",\"sequence_num\":508,\"events\":[{\"updates\":[{\"side\":\"offer\",\"event_time\":\"2024-01-01T00:00:00.000000001Z\",\"price_level\":\"50001.00\",\"new_quantity\":\"1.00000000\"}]}]}"}
{"local_receipt_timestamp_ns":1704067200000005102,"raw_payload":"{\"channel\":\"l2_data\",\"sequence_num\":509,\"events\":[{\"updates\":[{\"side\":\"bid\",\"event_time\":\"2024-01-01T00:00:00.000000001Z\",\"price_level\":\"50000.00\",\"new_quantity\":\"1.00000000\"}]}]}"}
{"local_receipt_timestamp_ns":1704067200000005112,"raw_payload":"{\"channel\":\"l2_data\",\"sequence_num\":510,\"events\":[{\"updates\":[{\"side\":\"offer\",\"event_time\":\"2024-01-01T00:00:00.000000001Z\",\"price_level\":\"50001.00\",\"new_quantity\":\"1.00000000\"}]}]}"}
{"local_receipt_timestamp_ns":1704067200000005122,"raw_payload":"{\"channel\":\"l2_data\",\"sequence_num\":511,\"events\":[{\"updates\":[{\"side\":\"bid\",\"event_time\":\"2024-01-01T00:00:00.000000001Z\",\"price_level\":\"50000.00\",\"new_quantity\":\"1.00000000\"}]}]}"}
{"local_receipt_timestamp_ns":1704067200000005132,"raw_payload":"{\"channel\":\"l2_data\",\"sequence_num\":512,\"events\":[{\"updates\":[{\"side\":\"offer\",\"event_time\":\"2024-01-01T00:00:00.000000001Z\",\"price_level\":\"50001.00\",\"new_quantity\":\"1.00000000\"}]}]}"}
{"local_receipt_timestamp_ns":1704067200000005142,"raw_payload":"{\"channel\":\"l2_data\",\"sequence_num\":513,\"events\":[{\"updates\":[{\"side\":\"bid\",\"event_time\":\"2024-01-01T00:00:00.000000001Z\",\"price_level\":\"50000.00\",\"new_quantity\":\"1.00000000\"}]}]}"}
{"local_receipt_timestamp_ns":1704067200000005152,"raw_payload":"{\"channel\":\"l2_data\",\"sequence_num\":514,\"events\":[{\"updates\":[{\"side\":\"offer\",\"event_time\":\"2024-01-01T00:00:00.000000001Z\",\"price_level\":\"50001.00\",\"new_quantity\":\"1.00000000\"}]}]}"}
{"local_receipt_timestamp_ns":1704067200000005162,"raw_payload":"{\"channel\":\"l2_data\",\"sequence_num\":515,\"events\":[{\"updates\":[{\"side\":\"bid\",\"event_time\":\"2024-01-01T00:00:00.000000001Z\",\"price_level\":\"50000.00\",\"new_quantity\":\"1.00000000\"}]}]}"}
{"local_receipt_timestamp_ns":1704067200000005172,"raw_payload":"{\"channel\":\"l2_data\",\"sequence_num\":516,\"events\":[{\"updates\":[{\"side\":\"offer\",\"event_time\":\"2024-01-01T00:00:00.000000001Z\",\"price_level\":\"50001.00\",\"new_quantity\":\"1.00000000\"}]}]}"}
{"local_receipt_timestamp_ns":1704067200000005182,"raw_payload":"{\"channel\":\"l2_data\",\"sequence_num\":517,\"events\":[{\"updates\":[{\"side\":\"bid\",\"event_time\":\"2024-01-01T00:00:00.000000001Z\",\"price_level\":\"50000.00\",\"new_quantity\":\"1.00000000\"}]}]}"}
{"local_receipt_timestamp_ns":1704067200000005192,"raw_payload":"{\"channel\":\"l2_data\",\"sequence_num\":518,\"events\":[{\"updates\":[{\"side\":\"offer\",\"event_time\":\"2024-01-01T00:00:00.000000001Z\",\"price_level\":\"50001.00\",\"new_quantity\":\"1.00000000\"}]}]}"}
{"local_receipt_timestamp_ns":1704067200000005202,"raw_payload":"{\"channel\":\"l2_data\",\"sequence_num\":519,\"events\":[{\"updates\":[{\"side\":\"bid\",\"event_time\":\"2024-01-01T00:00:00.000000001Z\",\"price_level\":\"50000.00\",\"new_quantity\":\"1.00000000\"}]}]}"}
{"local_receipt_timestamp_ns":1704067200000005212,"raw_payload":"{\"channel\":\"l2_data\",\"sequence_num\":520,\"events\":[{\"updates\":[{\"side\":\"offer\",\"event_time\":\"2024-01-01T00:00:00.000000001Z\",\"price_level\":\"50001.00\",\"new_quantity\":\"1.00000000\"}]}]}"}
{"local_receipt_timestamp_ns":1704067200000005222,"raw_payload":"{\"channel\":\"l2_data\",\"sequence_num\":521,\"events\":[{\"updates\":[{\"side\":\"bid\",\"event_time\":\"2024-01-01T00:00:00.000000001Z\",\"price_level\":\"50000.00\",\"new_quantity\":\"1.00000000\"}]}]}"}
{"local_receipt_timestamp_ns":1704067200000005232,"raw_payload":"{\"channel\":\"l2_data\",\"sequence_num\":522,\"events\":[{\"updates\":[{\"side\":\"offer\",\"event_time\":\"2024-01-01T00:00:00.000000001Z\",\"price_level\":\"50001.00\",\"new_quantity\":\"1.00000000\"}]}]}"}
{"local_receipt_timestamp_ns":1704067200000005242,"raw_payload":"{\"channel\":\"l2_data\",\"sequence_num\":523,\"events\":[{\"updates\":[{\"side\":\"bid\",\"event_time\":\"2024-01-01T00:00:00.000000001Z\",\"price_level\":\"50000.00\",\"new_quantity\":\"1.00000000\"}]}]}"}
{"local_receipt_timestamp_ns":1704067200000005252,"raw_payload":"{\"channel\":\"l2_data\",\"sequence_num\":524,\"events\":[{\"updates\":[{\"side\":\"offer\",\"event_time\":\"2024-01-01T00:00:00.000000001Z\",\"price_level\":\"50001.00\",\"new_quantity\":\"1.00000000\"}]}]}"}
{"local_receipt_timestamp_ns":1704067200000005262,"raw_payload":"{\"channel\":\"l2_data\",\"sequence_num\":525,\"events\":[{\"updates\":[{\"side\":\"bid\",\"event_time\":\"2024-01-01T00:00:00.000000001Z\",\"price_level\":\"50000.00\",\"new_quantity\":\"1.00000000\"}]}]}"}
{"local_receipt_timestamp_ns":1704067200000005272,"raw_payload":"{\"channel\":\"l2_data\",\"sequence_num\":526,\"events\":[{\"updates\":[{\"side\":\"offer\",\"event_time\":\"2024-01-01T00:00:00.000000001Z\",\"price_level\":\"50001.00\",\"new_quantity\":\"1.00000000\"}]}]}"}
{"local_receipt_timestamp_ns":1704067200000005282,"raw_payload":"{\"channel\":\"l2_data\",\"sequence_num\":527,\"events\":[{\"updates\":[{\"side\":\"bid\",\"event_time\":\"2024-01-01T00:00:00.000000001Z\",\"price_level\":\"50000.00\",\"new_quantity\":\"1.00000000\"}]}]}"}
{"local_receipt_timestamp_ns":1704067200000005292,"raw_payload":"{\"channel\":\"l2_data\",\"sequence_num\":528,\"events\":[{\"updates\":[{\"side\":\"offer\",\"event_time\":\"2024-01-01T00:00:00.000000001Z\",\"price_level\":\"50001.00\",\"new_quantity\":\"1.00000000\"}]}]}"}
{"local_receipt_timestamp_ns":1704067200000005302,"raw_payload":"{\"channel\":\"l2_data\",\"sequence_num\":529,\"events\":[{\"updates\":[{\"side\":\"bid\",\"event_time\":\"2024-01-01T00:00:00.000000001Z\",\"price_level\":\"50000.00\",\"new_quantity\":\"1.00000000\"}]}]}"}
{"local_receipt_timestamp_ns":1704067200000005312,"raw_payload":"{\"channel\":\"l2_data\",\"sequence_num\":530,\"events\":[{\"updates\":[{\"side\":\"offer\",\"event_time\":\"2024-01-01T00:00:00.000000001Z\",\"price_level\":\"50001.00\",\"new_quantity\":\"1.00000000\"}]}]}"}
{"local_receipt_timestamp_ns":1704067200000005322,"raw_payload":"{\"channel\":\"l2_data\",\"sequence_num\":531,\"events\":[{\"updates\":[{\"side\":\"bid\",\"event_time\":\"2024-01-01T00:00:00.000000001Z\",\"price_level\":\"50000.00\",\"new_quantity\":\"1.00000000\"}]}]}"}
{"local_receipt_timestamp_ns":1704067200000005332,"raw_payload":"{\"channel\":\"l2_data\",\"sequence_num\":532,\"events\":[{\"updates\":[{\"side\":\"offer\",\"event_time\":\"2024-01-01T00:00:00.000000001Z\",\"price_level\":\"50001.00\",\"new_quantity\":\"1.00000000\"}]}]}"}
{"local_receipt_timestamp_ns":1704067200000005342,"raw_payload":"{\"channel\":\"l2_data\",\"sequence_num\":533,\"events\":[{\"updates\":[{\"side\":\"bid\",\"event_time\":\"2024-01-01T00:00:00.000000001Z\",\"price_level\":\"50000.00\",\"new_quantity\":\"1.00000000\"}]}]}"}
{"local_receipt_timestamp_ns":1704067200000005352,"raw_payload":"{\"channel\":\"l2_data\",\"sequence_num\":534,\"events\":[{\"updates\":[{\"side\":\"offer\",\"event_time\":\"2024-01-01T00:00:00.000000001Z\",\"price_level\":\"50001.00\",\"new_quantity\":\"1.00000000\"}]}]}"}
{"local_receipt_timestamp_ns":1704067200000005362,"raw_payload":"{\"channel\":\"l2_data\",\"sequence_num\":535,\"events\":[{\"updates\":[{\"side\":\"bid\",\"event_time\":\"2024-01-01T00:00:00.000000001Z\",\"price_level\":\"50000.00\",\"new_quantity\":\"1.00000000\"}]}]}"}
{"local_receipt_timestamp_ns":1704067200000005372,"raw_payload":"{\"channel\":\"l2_data\",\"sequence_num\":536,\"events\":[{\"updates\":[{\"side\":\"offer\",\"event_time\":\"2024-01-01T00:00:00.000000001Z\",\"price_level\":\"50001.00\",\"new_quantity\":\"1.00000000\"}]}]}"}
{"local_receipt_timestamp_ns":1704067200000005382,"raw_payload":"{\"channel\":\"l2_data\",\"sequence_num\":537,\"events\":[{\"updates\":[{\"side\":\"bid\",\"event_time\":\"2024-01-01T00:00:00.000000001Z\",\"price_level\":\"50000.00\",\"new_quantity\":\"1.00000000\"}]}]}"}
{"local_receipt_timestamp_ns":1704067200000005392,"raw_payload":"{\"channel\":\"l2_data\",\"sequence_num\":538,\"events\":[{\"updates\":[{\"side\":\"offer\",\"event_time\":\"2024-01-01T00:00:00.000000001Z\",\"price_level\":\"50001.00\",\"new_quantity\":\"1.00000000\"}]}]}"}
{"local_receipt_timestamp_ns":1704067200000005402,"raw_payload":"{\"channel\":\"l2_data\",\"sequence_num\":539,\"events\":[{\"updates\":[{\"side\":\"bid\",\"event_time\":\"2024-01-01T00:00:00.000000001Z\",\"price_level\":\"50000.00\",\"new_quantity\":\"1.00000000\"}]}]}"}
{"local_receipt_timestamp_ns":1704067200000005412,"raw_payload":"{\"channel\":\"l2_data\",\"sequence_num\":540,\"events\":[{\"updates\":[{\"side\":\"offer\",\"event_time\":\"2024-01-01T00:00:00.000000001Z\",\"price_level\":\"50001.00\",\"new_quantity\":\"1.00000000\"}]}]}"}
{"local_receipt_timestamp_ns":1704067200000005422,"raw_payload":"{\"channel\":\"l2_data\",\"sequence_num\":541,\"events\":[{\"updates\":[{\"side\":\"bid\",\"event_time\":\"2024-01-01T00:00:00.000000001Z\",\"price_level\":\"50000.00\",\"new_quantity\":\"1.00000000\"}]}]}"}
{"local_receipt_timestamp_ns":1704067200000005432,"raw_payload":"{\"channel\":\"l2_data\",\"sequence_num\":542,\"events\":[{\"updates\":[{\"side\":\"offer\",\"event_time\":\"2024-01-01T00:00:00.000000001Z\",\"price_level\":\"50001.00\",\"new_quantity\":\"1.00000000\"}]}]}"}
{"local_receipt_timestamp_ns":1704067200000005442,"raw_payload":"{\"channel\":\"l2_data\",\"sequence_num\":543,\"events\":[{\"updates\":[{\"side\":\"bid\",\"event_time\":\"2024-01-01T00:00:00.000000001Z\",\"price_level\":\"50000.00\",\"new_quantity\":\"1.00000000\"}]}]}"}
{"local_receipt_timestamp_ns":1704067200000005452,"raw_payload":"{\"channel\":\"l2_data\",\"sequence_num\":544,\"events\":[{\"updates\":[{\"side\":\"offer\",\"event_time\":\"2024-01-01T00:00:00.000000001Z\",\"price_level\":\"50001.00\",\"new_quantity\":\"1.00000000\"}]}]}"}
{"local_receipt_timestamp_ns":1704067200000005462,"raw_payload":"{\"channel\":\"l2_data\",\"sequence_num\":545,\"events\":[{\"updates\":[{\"side\":\"bid\",\"event_time\":\"2024-01-01T00:00:00.000000001Z\",\"price_level\":\"50000.00\",\"new_quantity\":\"1.00000000\"}]}]}"}
{"local_receipt_timestamp_ns":1704067200000005472,"raw_payload":"{\"channel\":\"l2_data\",\"sequence_num\":546,\"events\":[{\"updates\":[{\"side\":\"offer\",\"event_time\":\"2024-01-01T00:00:00.000000001Z\",\"price_level\":\"50001.00\",\"new_quantity\":\"1.00000000\"}]}]}"}
{"local_receipt_timestamp_ns":1704067200000005482,"raw_payload":"{\"channel\":\"l2_data\",\"sequence_num\":547,\"events\":[{\"updates\":[{\"side\":\"bid\",\"event_time\":\"2024-01-01T00:00:00.000000001Z\",\"price_level\":\"50000.00\",\"new_quantity\":\"1.00000000\"}]}]}"}
{"local_receipt_timestamp_ns":1704067200000005492,"raw_payload":"{\"channel\":\"l2_data\",\"sequence_num\":548,\"events\":[{\"updates\":[{\"side\":\"offer\",\"event_time\":\"2024-01-01T00:00:00.000000001Z\",\"price_level\":\"50001.00\",\"new_quantity\":\"1.00000000\"}]}]}"}
{"local_receipt_timestamp_ns":1704067200000005502,"raw_payload":"{\"channel\":\"l2_data\",\"sequence_num\":549,\"events\":[{\"updates\":[{\"side\":\"bid\",\"event_time\":\"2024-01-01T00:00:00.000000001Z\",\"price_level\":\"50000.00\",\"new_quantity\":\"1.00000000\"}]}]}"}
{"local_receipt_timestamp_ns":1704067200000005512,"raw_payload":"{\"channel\":\"l2_data\",\"sequence_num\":550,\"events\":[{\"updates\":[{\"side\":\"offer\",\"event_time\":\"2024-01-01T00:00:00.000000001Z\",\"price_level\":\"50001.00\",\"new_quantity\":\"1.00000000\"}]}]}"}
{"local_receipt_timestamp_ns":1704067200000005522,"raw_payload":"{\"channel\":\"l2_data\",\"sequence_num\":551,\"events\":[{\"updates\":[{\"side\":\"bid\",\"event_time\":\"2024-01-01T00:00:00.000000001Z\",\"price_level\":\"50000.00\",\"new_quantity\":\"1.00000000\"}]}]}"}
{"local_receipt_timestamp_ns":1704067200000005532,"raw_payload":"{\"channel\":\"l2_data\",\"sequence_num\":552,\"events\":[{\"updates\":[{\"side\":\"offer\",\"event_time\":\"2024-01-01T00:00:00.000000001Z\",\"price_level\":\"50001.00\",\"new_quantity\":\"1.00000000\"}]}]}"}
{"local_receipt_timestamp_ns":1704067200000005542,"raw_payload":"{\"channel\":\"l2_data\",\"sequence_num\":553,\"events\":[{\"updates\":[{\"side\":\"bid\",\"event_time\":\"2024-01-01T00:00:00.000000001Z\",\"price_level\":\"50000.00\",\"new_quantity\":\"1.00000000\"}]}]}"}
{"local_receipt_timestamp_ns":1704067200000005552,"raw_payload":"{\"channel\":\"l2_data\",\"sequence_num\":554,\"events\":[{\"updates\":[{\"side\":\"offer\",\"event_time\":\"2024-01-01T00:00:00.000000001Z\",\"price_level\":\"50001.00\",\"new_quantity\":\"1.00000000\"}]}]}"}
{"local_receipt_timestamp_ns":1704067200000005562,"raw_payload":"{\"channel\":\"l2_data\",\"sequence_num\":555,\"events\":[{\"updates\":[{\"side\":\"bid\",\"event_time\":\"2024-01-01T00:00:00.000000001Z\",\"price_level\":\"50000.00\",\"new_quantity\":\"1.00000000\"}]}]}"}
{"local_receipt_timestamp_ns":1704067200000005572,"raw_payload":"{\"channel\":\"l2_data\",\"sequence_num\":556,\"events\":[{\"updates\":[{\"side\":\"offer\",\"event_time\":\"2024-01-01T00:00:00.000000001Z\",\"price_level\":\"50001.00\",\"new_quantity\":\"1.00000000\"}]}]}"}
{"local_receipt_timestamp_ns":1704067200000005582,"raw_payload":"{\"channel\":\"l2_data\",\"sequence_num\":557,\"events\":[{\"updates\":[{\"side\":\"bid\",\"event_time\":\"2024-01-01T00:00:00.000000001Z\",\"price_level\":\"50000.00\",\"new_quantity\":\"1.00000000\"}]}]}"}
{"local_receipt_timestamp_ns":1704067200000005592,"raw_payload":"{\"channel\":\"l2_data\",\"sequence_num\":558,\"events\":[{\"updates\":[{\"side\":\"offer\",\"event_time\":\"2024-01-01T00:00:00.000000001Z\",\"price_level\":\"50001.00\",\"new_quantity\":\"1.00000000\"}]}]}"}
{"local_receipt_timestamp_ns":1704067200000005602,"raw_payload":"{\"channel\":\"l2_data\",\"sequence_num\":559,\"events\":[{\"updates\":[{\"side\":\"bid\",\"event_time\":\"2024-01-01T00:00:00.000000001Z\",\"price_level\":\"50000.00\",\"new_quantity\":\"1.00000000\"}]}]}"}
{"local_receipt_timestamp_ns":1704067200000005612,"raw_payload":"{\"channel\":\"l2_data\",\"sequence_num\":560,\"events\":[{\"updates\":[{\"side\":\"offer\",\"event_time\":\"2024-01-01T00:00:00.000000001Z\",\"price_level\":\"50001.00\",\"new_quantity\":\"1.00000000\"}]}]}"}
{"local_receipt_timestamp_ns":1704067200000005622,"raw_payload":"{\"channel\":\"l2_data\",\"sequence_num\":561,\"events\":[{\"updates\":[{\"side\":\"bid\",\"event_time\":\"2024-01-01T00:00:00.000000001Z\",\"price_level\":\"50000.00\",\"new_quantity\":\"1.00000000\"}]}]}"}
{"local_receipt_timestamp_ns":1704067200000005632,"raw_payload":"{\"channel\":\"l2_data\",\"sequence_num\":562,\"events\":[{\"updates\":[{\"side\":\"offer\",\"event_time\":\"2024-01-01T00:00:00.000000001Z\",\"price_level\":\"50001.00\",\"new_quantity\":\"1.00000000\"}]}]}"}
{"local_receipt_timestamp_ns":1704067200000005642,"raw_payload":"{\"channel\":\"l2_data\",\"sequence_num\":563,\"events\":[{\"updates\":[{\"side\":\"bid\",\"event_time\":\"2024-01-01T00:00:00.000000001Z\",\"price_level\":\"50000.00\",\"new_quantity\":\"1.00000000\"}]}]}"}
{"local_receipt_timestamp_ns":1704067200000005652,"raw_payload":"{\"channel\":\"l2_data\",\"sequence_num\":564,\"events\":[{\"updates\":[{\"side\":\"offer\",\"event_time\":\"2024-01-01T00:00:00.000000001Z\",\"price_level\":\"50001.00\",\"new_quantity\":\"1.00000000\"}]}]}"}
{"local_receipt_timestamp_ns":1704067200000005662,"raw_payload":"{\"channel\":\"l2_data\",\"sequence_num\":565,\"events\":[{\"updates\":[{\"side\":\"bid\",\"event_time\":\"2024-01-01T00:00:00.000000001Z\",\"price_level\":\"50000.00\",\"new_quantity\":\"1.00000000\"}]}]}"}
{"local_receipt_timestamp_ns":1704067200000005672,"raw_payload":"{\"channel\":\"l2_data\",\"sequence_num\":566,\"events\":[{\"updates\":[{\"side\":\"offer\",\"event_time\":\"2024-01-01T00:00:00.000000001Z\",\"price_level\":\"50001.00\",\"new_quantity\":\"1.00000000\"}]}]}"}
{"local_receipt_timestamp_ns":1704067200000005682,"raw_payload":"{\"channel\":\"l2_data\",\"sequence_num\":567,\"events\":[{\"updates\":[{\"side\":\"bid\",\"event_time\":\"2024-01-01T00:00:00.000000001Z\",\"price_level\":\"50000.00\",\"new_quantity\":\"1.00000000\"}]}]}"}
{"local_receipt_timestamp_ns":1704067200000005692,"raw_payload":"{\"channel\":\"l2_data\",\"sequence_num\":568,\"events\":[{\"updates\":[{\"side\":\"offer\",\"event_time\":\"2024-01-01T00:00:00.000000001Z\",\"price_level\":\"50001.00\",\"new_quantity\":\"1.00000000\"}]}]}"}
{"local_receipt_timestamp_ns":1704067200000005702,"raw_payload":"{\"channel\":\"l2_data\",\"sequence_num\":569,\"events\":[{\"updates\":[{\"side\":\"bid\",\"event_time\":\"2024-01-01T00:00:00.000000001Z\",\"price_level\":\"50000.00\",\"new_quantity\":\"1.00000000\"}]}]}"}
{"local_receipt_timestamp_ns":1704067200000005712,"raw_payload":"{\"channel\":\"l2_data\",\"sequence_num\":570,\"events\":[{\"updates\":[{\"side\":\"offer\",\"event_time\":\"2024-01-01T00:00:00.000000001Z\",\"price_level\":\"50001.00\",\"new_quantity\":\"1.00000000\"}]}]}"}
{"local_receipt_timestamp_ns":1704067200000005722,"raw_payload":"{\"channel\":\"l2_data\",\"sequence_num\":571,\"events\":[{\"updates\":[{\"side\":\"bid\",\"event_time\":\"2024-01-01T00:00:00.000000001Z\",\"price_level\":\"50000.00\",\"new_quantity\":\"1.00000000\"}]}]}"}
{"local_receipt_timestamp_ns":1704067200000005732,"raw_payload":"{\"channel\":\"l2_data\",\"sequence_num\":572,\"events\":[{\"updates\":[{\"side\":\"offer\",\"event_time\":\"2024-01-01T00:00:00.000000001Z\",\"price_level\":\"50001.00\",\"new_quantity\":\"1.00000000\"}]}]}"}
{"local_receipt_timestamp_ns":1704067200000005742,"raw_payload":"{\"channel\":\"l2_data\",\"sequence_num\":573,\"events\":[{\"updates\":[{\"side\":\"bid\",\"event_time\":\"2024-01-01T00:00:00.000000001Z\",\"price_level\":\"50000.00\",\"new_quantity\":\"1.00000000\"}]}]}"}
{"local_receipt_timestamp_ns":1704067200000005752,"raw_payload":"{\"channel\":\"l2_data\",\"sequence_num\":574,\"events\":[{\"updates\":[{\"side\":\"offer\",\"event_time\":\"2024-01-01T00:00:00.000000001Z\",\"price_level\":\"50001.00\",\"new_quantity\":\"1.00000000\"}]}]}"}
{"local_receipt_timestamp_ns":1704067200000005762,"raw_payload":"{\"channel\":\"l2_data\",\"sequence_num\":575,\"events\":[{\"updates\":[{\"side\":\"bid\",\"event_time\":\"2024-01-01T00:00:00.000000001Z\",\"price_level\":\"50000.00\",\"new_quantity\":\"1.00000000\"}]}]}"}
{"local_receipt_timestamp_ns":1704067200000005772,"raw_payload":"{\"channel\":\"l2_data\",\"sequence_num\":576,\"events\":[{\"updates\":[{\"side\":\"offer\",\"event_time\":\"2024-01-01T00:00:00.000000001Z\",\"price_level\":\"50001.00\",\"new_quantity\":\"1.00000000\"}]}]}"}
{"local_receipt_timestamp_ns":1704067200000005782,"raw_payload":"{\"channel\":\"l2_data\",\"sequence_num\":577,\"events\":[{\"updates\":[{\"side\":\"bid\",\"event_time\":\"2024-01-01T00:00:00.000000001Z\",\"price_level\":\"50000.00\",\"new_quantity\":\"1.00000000\"}]}]}"}
{"local_receipt_timestamp_ns":1704067200000005792,"raw_payload":"{\"channel\":\"l2_data\",\"sequence_num\":578,\"events\":[{\"updates\":[{\"side\":\"offer\",\"event_time\":\"2024-01-01T00:00:00.000000001Z\",\"price_level\":\"50001.00\",\"new_quantity\":\"1.00000000\"}]}]}"}
{"local_receipt_timestamp_ns":1704067200000005802,"raw_payload":"{\"channel\":\"l2_data\",\"sequence_num\":579,\"events\":[{\"updates\":[{\"side\":\"bid\",\"event_time\":\"2024-01-01T00:00:00.000000001Z\",\"price_level\":\"50000.00\",\"new_quantity\":\"1.00000000\"}]}]}"}
{"local_receipt_timestamp_ns":1704067200000005812,"raw_payload":"{\"channel\":\"l2_data\",\"sequence_num\":580,\"events\":[{\"updates\":[{\"side\":\"offer\",\"event_time\":\"2024-01-01T00:00:00.000000001Z\",\"price_level\":\"50001.00\",\"new_quantity\":\"1.00000000\"}]}]}"}
{"local_receipt_timestamp_ns":1704067200000005822,"raw_payload":"{\"channel\":\"l2_data\",\"sequence_num\":581,\"events\":[{\"updates\":[{\"side\":\"bid\",\"event_time\":\"2024-01-01T00:00:00.000000001Z\",\"price_level\":\"50000.00\",\"new_quantity\":\"1.00000000\"}]}]}"}
{"local_receipt_timestamp_ns":1704067200000005832,"raw_payload":"{\"channel\":\"l2_data\",\"sequence_num\":582,\"events\":[{\"updates\":[{\"side\":\"offer\",\"event_time\":\"2024-01-01T00:00:00.000000001Z\",\"price_level\":\"50001.00\",\"new_quantity\":\"1.00000000\"}]}]}"}
{"local_receipt_timestamp_ns":1704067200000005842,"raw_payload":"{\"channel\":\"l2_data\",\"sequence_num\":583,\"events\":[{\"updates\":[{\"side\":\"bid\",\"event_time\":\"2024-01-01T00:00:00.000000001Z\",\"price_level\":\"50000.00\",\"new_quantity\":\"1.00000000\"}]}]}"}
{"local_receipt_timestamp_ns":1704067200000005852,"raw_payload":"{\"channel\":\"l2_data\",\"sequence_num\":584,\"events\":[{\"updates\":[{\"side\":\"offer\",\"event_time\":\"2024-01-01T00:00:00.000000001Z\",\"price_level\":\"50001.00\",\"new_quantity\":\"1.00000000\"}]}]}"}
{"local_receipt_timestamp_ns":1704067200000005862,"raw_payload":"{\"channel\":\"l2_data\",\"sequence_num\":585,\"events\":[{\"updates\":[{\"side\":\"bid\",\"event_time\":\"2024-01-01T00:00:00.000000001Z\",\"price_level\":\"50000.00\",\"new_quantity\":\"1.00000000\"}]}]}"}
{"local_receipt_timestamp_ns":1704067200000005872,"raw_payload":"{\"channel\":\"l2_data\",\"sequence_num\":586,\"events\":[{\"updates\":[{\"side\":\"offer\",\"event_time\":\"2024-01-01T00:00:00.000000001Z\",\"price_level\":\"50001.00\",\"new_quantity\":\"1.00000000\"}]}]}"}
{"local_receipt_timestamp_ns":1704067200000005882,"raw_payload":"{\"channel\":\"l2_data\",\"sequence_num\":587,\"events\":[{\"updates\":[{\"side\":\"bid\",\"event_time\":\"2024-01-01T00:00:00.000000001Z\",\"price_level\":\"50000.00\",\"new_quantity\":\"1.00000000\"}]}]}"}
{"local_receipt_timestamp_ns":1704067200000005892,"raw_payload":"{\"channel\":\"l2_data\",\"sequence_num\":588,\"events\":[{\"updates\":[{\"side\":\"offer\",\"event_time\":\"2024-01-01T00:00:00.000000001Z\",\"price_level\":\"50001.00\",\"new_quantity\":\"1.00000000\"}]}]}"}
{"local_receipt_timestamp_ns":1704067200000005902,"raw_payload":"{\"channel\":\"l2_data\",\"sequence_num\":589,\"events\":[{\"updates\":[{\"side\":\"bid\",\"event_time\":\"2024-01-01T00:00:00.000000001Z\",\"price_level\":\"50000.00\",\"new_quantity\":\"1.00000000\"}]}]}"}
{"local_receipt_timestamp_ns":1704067200000005912,"raw_payload":"{\"channel\":\"l2_data\",\"sequence_num\":590,\"events\":[{\"updates\":[{\"side\":\"offer\",\"event_time\":\"2024-01-01T00:00:00.000000001Z\",\"price_level\":\"50001.00\",\"new_quantity\":\"1.00000000\"}]}]}"}
{"local_receipt_timestamp_ns":1704067200000005922,"raw_payload":"{\"channel\":\"l2_data\",\"sequence_num\":591,\"events\":[{\"updates\":[{\"side\":\"bid\",\"event_time\":\"2024-01-01T00:00:00.000000001Z\",\"price_level\":\"50000.00\",\"new_quantity\":\"1.00000000\"}]}]}"}
{"local_receipt_timestamp_ns":1704067200000005932,"raw_payload":"{\"channel\":\"l2_data\",\"sequence_num\":592,\"events\":[{\"updates\":[{\"side\":\"offer\",\"event_time\":\"2024-01-01T00:00:00.000000001Z\",\"price_level\":\"50001.00\",\"new_quantity\":\"1.00000000\"}]}]}"}
{"local_receipt_timestamp_ns":1704067200000005942,"raw_payload":"{\"channel\":\"l2_data\",\"sequence_num\":593,\"events\":[{\"updates\":[{\"side\":\"bid\",\"event_time\":\"2024-01-01T00:00:00.000000001Z\",\"price_level\":\"50000.00\",\"new_quantity\":\"1.00000000\"}]}]}"}
{"local_receipt_timestamp_ns":1704067200000005952,"raw_payload":"{\"channel\":\"l2_data\",\"sequence_num\":594,\"events\":[{\"updates\":[{\"side\":\"offer\",\"event_time\":\"2024-01-01T00:00:00.000000001Z\",\"price_level\":\"50001.00\",\"new_quantity\":\"1.00000000\"}]}]}"}
{"local_receipt_timestamp_ns":1704067200000005962,"raw_payload":"{\"channel\":\"l2_data\",\"sequence_num\":595,\"events\":[{\"updates\":[{\"side\":\"bid\",\"event_time\":\"2024-01-01T00:00:00.000000001Z\",\"price_level\":\"50000.00\",\"new_quantity\":\"1.00000000\"}]}]}"}
{"local_receipt_timestamp_ns":1704067200000005972,"raw_payload":"{\"channel\":\"l2_data\",\"sequence_num\":596,\"events\":[{\"updates\":[{\"side\":\"offer\",\"event_time\":\"2024-01-01T00:00:00.000000001Z\",\"price_level\":\"50001.00\",\"new_quantity\":\"1.00000000\"}]}]}"}
{"local_receipt_timestamp_ns":1704067200000005982,"raw_payload":"{\"channel\":\"l2_data\",\"sequence_num\":597,\"events\":[{\"updates\":[{\"side\":\"bid\",\"event_time\":\"2024-01-01T00:00:00.000000001Z\",\"price_level\":\"50000.00\",\"new_quantity\":\"1.00000000\"}]}]}"}
{"local_receipt_timestamp_ns":1704067200000005992,"raw_payload":"{\"channel\":\"l2_data\",\"sequence_num\":598,\"events\":[{\"updates\":[{\"side\":\"offer\",\"event_time\":\"2024-01-01T00:00:00.000000001Z\",\"price_level\":\"50001.00\",\"new_quantity\":\"1.00000000\"}]}]}"}
{"local_receipt_timestamp_ns":1704067200000006002,"raw_payload":"{\"channel\":\"l2_data\",\"sequence_num\":599,\"events\":[{\"updates\":[{\"side\":\"bid\",\"event_time\":\"2024-01-01T00:00:00.000000001Z\",\"price_level\":\"50000.00\",\"new_quantity\":\"1.00000000\"}]}]}"}
{"local_receipt_timestamp_ns":1704067200000006012,"raw_payload":"{\"channel\":\"l2_data\",\"sequence_num\":600,\"events\":[{\"updates\":[{\"side\":\"offer\",\"event_time\":\"2024-01-01T00:00:00.000000001Z\",\"price_level\":\"50001.00\",\"new_quantity\":\"1.00000000\"}]}]}"}
{"local_receipt_timestamp_ns":1704067200000006022,"raw_payload":"{\"channel\":\"l2_data\",\"sequence_num\":601,\"events\":[{\"updates\":[{\"side\":\"bid\",\"event_time\":\"2024-01-01T00:00:00.000000001Z\",\"price_level\":\"50000.00\",\"new_quantity\":\"1.00000000\"}]}]}"}
{"local_receipt_timestamp_ns":1704067200000006032,"raw_payload":"{\"channel\":\"l2_data\",\"sequence_num\":602,\"events\":[{\"updates\":[{\"side\":\"offer\",\"event_time\":\"2024-01-01T00:00:00.000000001Z\",\"price_level\":\"50001.00\",\"new_quantity\":\"1.00000000\"}]}]}"}
{"local_receipt_timestamp_ns":1704067200000006042,"raw_payload":"{\"channel\":\"l2_data\",\"sequence_num\":603,\"events\":[{\"updates\":[{\"side\":\"bid\",\"event_time\":\"2024-01-01T00:00:00.000000001Z\",\"price_level\":\"50000.00\",\"new_quantity\":\"1.00000000\"}]}]}"}
{"local_receipt_timestamp_ns":1704067200000006052,"raw_payload":"{\"channel\":\"l2_data\",\"sequence_num\":604,\"events\":[{\"updates\":[{\"side\":\"offer\",\"event_time\":\"2024-01-01T00:00:00.000000001Z\",\"price_level\":\"50001.00\",\"new_quantity\":\"1.00000000\"}]}]}"}
{"local_receipt_timestamp_ns":1704067200000006062,"raw_payload":"{\"channel\":\"l2_data\",\"sequence_num\":605,\"events\":[{\"updates\":[{\"side\":\"bid\",\"event_time\":\"2024-01-01T00:00:00.000000001Z\",\"price_level\":\"50000.00\",\"new_quantity\":\"1.00000000\"}]}]}"}
{"local_receipt_timestamp_ns":1704067200000006072,"raw_payload":"{\"channel\":\"l2_data\",\"sequence_num\":606,\"events\":[{\"updates\":[{\"side\":\"offer\",\"event_time\":\"2024-01-01T00:00:00.000000001Z\",\"price_level\":\"50001.00\",\"new_quantity\":\"1.00000000\"}]}]}"}
{"local_receipt_timestamp_ns":1704067200000006082,"raw_payload":"{\"channel\":\"l2_data\",\"sequence_num\":607,\"events\":[{\"updates\":[{\"side\":\"bid\",\"event_time\":\"2024-01-01T00:00:00.000000001Z\",\"price_level\":\"50000.00\",\"new_quantity\":\"1.00000000\"}]}]}"}
{"local_receipt_timestamp_ns":1704067200000006092,"raw_payload":"{\"channel\":\"l2_data\",\"sequence_num\":608,\"events\":[{\"updates\":[{\"side\":\"offer\",\"event_time\":\"2024-01-01T00:00:00.000000001Z\",\"price_level\":\"50001.00\",\"new_quantity\":\"1.00000000\"}]}]}"}
{"local_receipt_timestamp_ns":1704067200000006102,"raw_payload":"{\"channel\":\"l2_data\",\"sequence_num\":609,\"events\":[{\"updates\":[{\"side\":\"bid\",\"event_time\":\"2024-01-01T00:00:00.000000001Z\",\"price_level\":\"50000.00\",\"new_quantity\":\"1.00000000\"}]}]}"}
{"local_receipt_timestamp_ns":1704067200000006112,"raw_payload":"{\"channel\":\"l2_data\",\"sequence_num\":610,\"events\":[{\"updates\":[{\"side\":\"offer\",\"event_time\":\"2024-01-01T00:00:00.000000001Z\",\"price_level\":\"50001.00\",\"new_quantity\":\"1.00000000\"}]}]}"}
{"local_receipt_timestamp_ns":1704067200000006122,"raw_payload":"{\"channel\":\"l2_data\",\"sequence_num\":611,\"events\":[{\"updates\":[{\"side\":\"bid\",\"event_time\":\"2024-01-01T00:00:00.000000001Z\",\"price_level\":\"50000.00\",\"new_quantity\":\"1.00000000\"}]}]}"}
{"local_receipt_timestamp_ns":1704067200000006132,"raw_payload":"{\"channel\":\"l2_data\",\"sequence_num\":612,\"events\":[{\"updates\":[{\"side\":\"offer\",\"event_time\":\"2024-01-01T00:00:00.000000001Z\",\"price_level\":\"50001.00\",\"new_quantity\":\"1.00000000\"}]}]}"}
{"local_receipt_timestamp_ns":1704067200000006142,"raw_payload":"{\"channel\":\"l2_data\",\"sequence_num\":613,\"events\":[{\"updates\":[{\"side\":\"bid\",\"event_time\":\"2024-01-01T00:00:00.000000001Z\",\"price_level\":\"50000.00\",\"new_quantity\":\"1.00000000\"}]}]}"}
{"local_receipt_timestamp_ns":1704067200000006152,"raw_payload":"{\"channel\":\"l2_data\",\"sequence_num\":614,\"events\":[{\"updates\":[{\"side\":\"offer\",\"event_time\":\"2024-01-01T00:00:00.000000001Z\",\"price_level\":\"50001.00\",\"new_quantity\":\"1.00000000\"}]}]}"}
{"local_receipt_timestamp_ns":1704067200000006162,"raw_payload":"{\"channel\":\"l2_data\",\"sequence_num\":615,\"events\":[{\"updates\":[{\"side\":\"bid\",\"event_time\":\"2024-01-01T00:00:00.000000001Z\",\"price_level\":\"50000.00\",\"new_quantity\":\"1.00000000\"}]}]}"}
{"local_receipt_timestamp_ns":1704067200000006172,"raw_payload":"{\"channel\":\"l2_data\",\"sequence_num\":616,\"events\":[{\"updates\":[{\"side\":\"offer\",\"event_time\":\"2024-01-01T00:00:00.000000001Z\",\"price_level\":\"50001.00\",\"new_quantity\":\"1.00000000\"}]}]}"}
{"local_receipt_timestamp_ns":1704067200000006182,"raw_payload":"{\"channel\":\"l2_data\",\"sequence_num\":617,\"events\":[{\"updates\":[{\"side\":\"bid\",\"event_time\":\"2024-01-01T00:00:00.000000001Z\",\"price_level\":\"50000.00\",\"new_quantity\":\"1.00000000\"}]}]}"}
{"local_receipt_timestamp_ns":1704067200000006192,"raw_payload":"{\"channel\":\"l2_data\",\"sequence_num\":618,\"events\":[{\"updates\":[{\"side\":\"offer\",\"event_time\":\"2024-01-01T00:00:00.000000001Z\",\"price_level\":\"50001.00\",\"new_quantity\":\"1.00000000\"}]}]}"}
{"local_receipt_timestamp_ns":1704067200000006202,"raw_payload":"{\"channel\":\"l2_data\",\"sequence_num\":619,\"events\":[{\"updates\":[{\"side\":\"bid\",\"event_time\":\"2024-01-01T00:00:00.000000001Z\",\"price_level\":\"50000.00\",\"new_quantity\":\"1.00000000\"}]}]}"}
{"local_receipt_timestamp_ns":1704067200000006212,"raw_payload":"{\"channel\":\"l2_data\",\"sequence_num\":620,\"events\":[{\"updates\":[{\"side\":\"offer\",\"event_time\":\"2024-01-01T00:00:00.000000001Z\",\"price_level\":\"50001.00\",\"new_quantity\":\"1.00000000\"}]}]}"}
{"local_receipt_timestamp_ns":1704067200000006222,"raw_payload":"{\"channel\":\"l2_data\",\"sequence_num\":621,\"events\":[{\"updates\":[{\"side\":\"bid\",\"event_time\":\"2024-01-01T00:00:00.000000001Z\",\"price_level\":\"50000.00\",\"new_quantity\":\"1.00000000\"}]}]}"}
{"local_receipt_timestamp_ns":1704067200000006232,"raw_payload":"{\"channel\":\"l2_data\",\"sequence_num\":622,\"events\":[{\"updates\":[{\"side\":\"offer\",\"event_time\":\"2024-01-01T00:00:00.000000001Z\",\"price_level\":\"50001.00\",\"new_quantity\":\"1.00000000\"}]}]}"}
{"local_receipt_timestamp_ns":1704067200000006242,"raw_payload":"{\"channel\":\"l2_data\",\"sequence_num\":623,\"events\":[{\"updates\":[{\"side\":\"bid\",\"event_time\":\"2024-01-01T00:00:00.000000001Z\",\"price_level\":\"50000.00\",\"new_quantity\":\"1.00000000\"}]}]}"}
{"local_receipt_timestamp_ns":1704067200000006252,"raw_payload":"{\"channel\":\"l2_data\",\"sequence_num\":624,\"events\":[{\"updates\":[{\"side\":\"offer\",\"event_time\":\"2024-01-01T00:00:00.000000001Z\",\"price_level\":\"50001.00\",\"new_quantity\":\"1.00000000\"}]}]}"}
{"local_receipt_timestamp_ns":1704067200000006262,"raw_payload":"{\"channel\":\"l2_data\",\"sequence_num\":625,\"events\":[{\"updates\":[{\"side\":\"bid\",\"event_time\":\"2024-01-01T00:00:00.000000001Z\",\"price_level\":\"50000.00\",\"new_quantity\":\"1.00000000\"}]}]}"}
{"local_receipt_timestamp_ns":1704067200000006272,"raw_payload":"{\"channel\":\"l2_data\",\"sequence_num\":626,\"events\":[{\"updates\":[{\"side\":\"offer\",\"event_time\":\"2024-01-01T00:00:00.000000001Z\",\"price_level\":\"50001.00\",\"new_quantity\":\"1.00000000\"}]}]}"}
{"local_receipt_timestamp_ns":1704067200000006282,"raw_payload":"{\"channel\":\"l2_data\",\"sequence_num\":627,\"events\":[{\"updates\":[{\"side\":\"bid\",\"event_time\":\"2024-01-01T00:00:00.000000001Z\",\"price_level\":\"50000.00\",\"new_quantity\":\"1.00000000\"}]}]}"}
{"local_receipt_timestamp_ns":1704067200000006292,"raw_payload":"{\"channel\":\"l2_data\",\"sequence_num\":628,\"events\":[{\"updates\":[{\"side\":\"offer\",\"event_time\":\"2024-01-01T00:00:00.000000001Z\",\"price_level\":\"50001.00\",\"new_quantity\":\"1.00000000\"}]}]}"}
{"local_receipt_timestamp_ns":1704067200000006302,"raw_payload":"{\"channel\":\"l2_data\",\"sequence_num\":629,\"events\":[{\"updates\":[{\"side\":\"bid\",\"event_time\":\"2024-01-01T00:00:00.000000001Z\",\"price_level\":\"50000.00\",\"new_quantity\":\"1.00000000\"}]}]}"}
{"local_receipt_timestamp_ns":1704067200000006312,"raw_payload":"{\"channel\":\"l2_data\",\"sequence_num\":630,\"events\":[{\"updates\":[{\"side\":\"offer\",\"event_time\":\"2024-01-01T00:00:00.000000001Z\",\"price_level\":\"50001.00\",\"new_quantity\":\"1.00000000\"}]}]}"}
{"local_receipt_timestamp_ns":1704067200000006322,"raw_payload":"{\"channel\":\"l2_data\",\"sequence_num\":631,\"events\":[{\"updates\":[{\"side\":\"bid\",\"event_time\":\"2024-01-01T00:00:00.000000001Z\",\"price_level\":\"50000.00\",\"new_quantity\":\"1.00000000\"}]}]}"}
{"local_receipt_timestamp_ns":1704067200000006332,"raw_payload":"{\"channel\":\"l2_data\",\"sequence_num\":632,\"events\":[{\"updates\":[{\"side\":\"offer\",\"event_time\":\"2024-01-01T00:00:00.000000001Z\",\"price_level\":\"50001.00\",\"new_quantity\":\"1.00000000\"}]}]}"}
{"local_receipt_timestamp_ns":1704067200000006342,"raw_payload":"{\"channel\":\"l2_data\",\"sequence_num\":633,\"events\":[{\"updates\":[{\"side\":\"bid\",\"event_time\":\"2024-01-01T00:00:00.000000001Z\",\"price_level\":\"50000.00\",\"new_quantity\":\"1.00000000\"}]}]}"}
{"local_receipt_timestamp_ns":1704067200000006352,"raw_payload":"{\"channel\":\"l2_data\",\"sequence_num\":634,\"events\":[{\"updates\":[{\"side\":\"offer\",\"event_time\":\"2024-01-01T00:00:00.000000001Z\",\"price_level\":\"50001.00\",\"new_quantity\":\"1.00000000\"}]}]}"}
{"local_receipt_timestamp_ns":1704067200000006362,"raw_payload":"{\"channel\":\"l2_data\",\"sequence_num\":635,\"events\":[{\"updates\":[{\"side\":\"bid\",\"event_time\":\"2024-01-01T00:00:00.000000001Z\",\"price_level\":\"50000.00\",\"new_quantity\":\"1.00000000\"}]}]}"}
{"local_receipt_timestamp_ns":1704067200000006372,"raw_payload":"{\"channel\":\"l2_data\",\"sequence_num\":636,\"events\":[{\"updates\":[{\"side\":\"offer\",\"event_time\":\"2024-01-01T00:00:00.000000001Z\",\"price_level\":\"50001.00\",\"new_quantity\":\"1.00000000\"}]}]}"}
{"local_receipt_timestamp_ns":1704067200000006382,"raw_payload":"{\"channel\":\"l2_data\",\"sequence_num\":637,\"events\":[{\"updates\":[{\"side\":\"bid\",\"event_time\":\"2024-01-01T00:00:00.000000001Z\",\"price_level\":\"50000.00\",\"new_quantity\":\"1.00000000\"}]}]}"}
{"local_receipt_timestamp_ns":1704067200000006392,"raw_payload":"{\"channel\":\"l2_data\",\"sequence_num\":638,\"events\":[{\"updates\":[{\"side\":\"offer\",\"event_time\":\"2024-01-01T00:00:00.000000001Z\",\"price_level\":\"50001.00\",\"new_quantity\":\"1.00000000\"}]}]}"}
{"local_receipt_timestamp_ns":1704067200000006402,"raw_payload":"{\"channel\":\"l2_data\",\"sequence_num\":639,\"events\":[{\"updates\":[{\"side\":\"bid\",\"event_time\":\"2024-01-01T00:00:00.000000001Z\",\"price_level\":\"50000.00\",\"new_quantity\":\"1.00000000\"}]}]}"}
{"local_receipt_timestamp_ns":1704067200000006412,"raw_payload":"{\"channel\":\"l2_data\",\"sequence_num\":640,\"events\":[{\"updates\":[{\"side\":\"offer\",\"event_time\":\"2024-01-01T00:00:00.000000001Z\",\"price_level\":\"50001.00\",\"new_quantity\":\"1.00000000\"}]}]}"}
{"local_receipt_timestamp_ns":1704067200000006422,"raw_payload":"{\"channel\":\"l2_data\",\"sequence_num\":641,\"events\":[{\"updates\":[{\"side\":\"bid\",\"event_time\":\"2024-01-01T00:00:00.000000001Z\",\"price_level\":\"50000.00\",\"new_quantity\":\"1.00000000\"}]}]}"}
{"local_receipt_timestamp_ns":1704067200000006432,"raw_payload":"{\"channel\":\"l2_data\",\"sequence_num\":642,\"events\":[{\"updates\":[{\"side\":\"offer\",\"event_time\":\"2024-01-01T00:00:00.000000001Z\",\"price_level\":\"50001.00\",\"new_quantity\":\"1.00000000\"}]}]}"}
{"local_receipt_timestamp_ns":1704067200000006442,"raw_payload":"{\"channel\":\"l2_data\",\"sequence_num\":643,\"events\":[{\"updates\":[{\"side\":\"bid\",\"event_time\":\"2024-01-01T00:00:00.000000001Z\",\"price_level\":\"50000.00\",\"new_quantity\":\"1.00000000\"}]}]}"}
{"local_receipt_timestamp_ns":1704067200000006452,"raw_payload":"{\"channel\":\"l2_data\",\"sequence_num\":644,\"events\":[{\"updates\":[{\"side\":\"offer\",\"event_time\":\"2024-01-01T00:00:00.000000001Z\",\"price_level\":\"50001.00\",\"new_quantity\":\"1.00000000\"}]}]}"}
{"local_receipt_timestamp_ns":1704067200000006462,"raw_payload":"{\"channel\":\"l2_data\",\"sequence_num\":645,\"events\":[{\"updates\":[{\"side\":\"bid\",\"event_time\":\"2024-01-01T00:00:00.000000001Z\",\"price_level\":\"50000.00\",\"new_quantity\":\"1.00000000\"}]}]}"}
{"local_receipt_timestamp_ns":1704067200000006472,"raw_payload":"{\"channel\":\"l2_data\",\"sequence_num\":646,\"events\":[{\"updates\":[{\"side\":\"offer\",\"event_time\":\"2024-01-01T00:00:00.000000001Z\",\"price_level\":\"50001.00\",\"new_quantity\":\"1.00000000\"}]}]}"}
{"local_receipt_timestamp_ns":1704067200000006482,"raw_payload":"{\"channel\":\"l2_data\",\"sequence_num\":647,\"events\":[{\"updates\":[{\"side\":\"bid\",\"event_time\":\"2024-01-01T00:00:00.000000001Z\",\"price_level\":\"50000.00\",\"new_quantity\":\"1.00000000\"}]}]}"}
{"local_receipt_timestamp_ns":1704067200000006492,"raw_payload":"{\"channel\":\"l2_data\",\"sequence_num\":648,\"events\":[{\"updates\":[{\"side\":\"offer\",\"event_time\":\"2024-01-01T00:00:00.000000001Z\",\"price_level\":\"50001.00\",\"new_quantity\":\"1.00000000\"}]}]}"}
{"local_receipt_timestamp_ns":1704067200000006502,"raw_payload":"{\"channel\":\"l2_data\",\"sequence_num\":649,\"events\":[{\"updates\":[{\"side\":\"bid\",\"event_time\":\"2024-01-01T00:00:00.000000001Z\",\"price_level\":\"50000.00\",\"new_quantity\":\"1.00000000\"}]}]}"}
{"local_receipt_timestamp_ns":1704067200000006512,"raw_payload":"{\"channel\":\"l2_data\",\"sequence_num\":650,\"events\":[{\"updates\":[{\"side\":\"offer\",\"event_time\":\"2024-01-01T00:00:00.000000001Z\",\"price_level\":\"50001.00\",\"new_quantity\":\"1.00000000\"}]}]}"}
{"local_receipt_timestamp_ns":1704067200000006522,"raw_payload":"{\"channel\":\"l2_data\",\"sequence_num\":651,\"events\":[{\"updates\":[{\"side\":\"bid\",\"event_time\":\"2024-01-01T00:00:00.000000001Z\",\"price_level\":\"50000.00\",\"new_quantity\":\"1.00000000\"}]}]}"}
{"local_receipt_timestamp_ns":1704067200000006532,"raw_payload":"{\"channel\":\"l2_data\",\"sequence_num\":652,\"events\":[{\"updates\":[{\"side\":\"offer\",\"event_time\":\"2024-01-01T00:00:00.000000001Z\",\"price_level\":\"50001.00\",\"new_quantity\":\"1.00000000\"}]}]}"}
{"local_receipt_timestamp_ns":1704067200000006542,"raw_payload":"{\"channel\":\"l2_data\",\"sequence_num\":653,\"events\":[{\"updates\":[{\"side\":\"bid\",\"event_time\":\"2024-01-01T00:00:00.000000001Z\",\"price_level\":\"50000.00\",\"new_quantity\":\"1.00000000\"}]}]}"}
{"local_receipt_timestamp_ns":1704067200000006552,"raw_payload":"{\"channel\":\"l2_data\",\"sequence_num\":654,\"events\":[{\"updates\":[{\"side\":\"offer\",\"event_time\":\"2024-01-01T00:00:00.000000001Z\",\"price_level\":\"50001.00\",\"new_quantity\":\"1.00000000\"}]}]}"}
{"local_receipt_timestamp_ns":1704067200000006562,"raw_payload":"{\"channel\":\"l2_data\",\"sequence_num\":655,\"events\":[{\"updates\":[{\"side\":\"bid\",\"event_time\":\"2024-01-01T00:00:00.000000001Z\",\"price_level\":\"50000.00\",\"new_quantity\":\"1.00000000\"}]}]}"}
{"local_receipt_timestamp_ns":1704067200000006572,"raw_payload":"{\"channel\":\"l2_data\",\"sequence_num\":656,\"events\":[{\"updates\":[{\"side\":\"offer\",\"event_time\":\"2024-01-01T00:00:00.000000001Z\",\"price_level\":\"50001.00\",\"new_quantity\":\"1.00000000\"}]}]}"}
{"local_receipt_timestamp_ns":1704067200000006582,"raw_payload":"{\"channel\":\"l2_data\",\"sequence_num\":657,\"events\":[{\"updates\":[{\"side\":\"bid\",\"event_time\":\"2024-01-01T00:00:00.000000001Z\",\"price_level\":\"50000.00\",\"new_quantity\":\"1.00000000\"}]}]}"}
{"local_receipt_timestamp_ns":1704067200000006592,"raw_payload":"{\"channel\":\"l2_data\",\"sequence_num\":658,\"events\":[{\"updates\":[{\"side\":\"offer\",\"event_time\":\"2024-01-01T00:00:00.000000001Z\",\"price_level\":\"50001.00\",\"new_quantity\":\"1.00000000\"}]}]}"}
{"local_receipt_timestamp_ns":1704067200000006602,"raw_payload":"{\"channel\":\"l2_data\",\"sequence_num\":659,\"events\":[{\"updates\":[{\"side\":\"bid\",\"event_time\":\"2024-01-01T00:00:00.000000001Z\",\"price_level\":\"50000.00\",\"new_quantity\":\"1.00000000\"}]}]}"}
{"local_receipt_timestamp_ns":1704067200000006612,"raw_payload":"{\"channel\":\"l2_data\",\"sequence_num\":660,\"events\":[{\"updates\":[{\"side\":\"offer\",\"event_time\":\"2024-01-01T00:00:00.000000001Z\",\"price_level\":\"50001.00\",\"new_quantity\":\"1.00000000\"}]}]}"}
{"local_receipt_timestamp_ns":1704067200000006622,"raw_payload":"{\"channel\":\"l2_data\",\"sequence_num\":661,\"events\":[{\"updates\":[{\"side\":\"bid\",\"event_time\":\"2024-01-01T00:00:00.000000001Z\",\"price_level\":\"50000.00\",\"new_quantity\":\"1.00000000\"}]}]}"}
{"local_receipt_timestamp_ns":1704067200000006632,"raw_payload":"{\"channel\":\"l2_data\",\"sequence_num\":662,\"events\":[{\"updates\":[{\"side\":\"offer\",\"event_time\":\"2024-01-01T00:00:00.000000001Z\",\"price_level\":\"50001.00\",\"new_quantity\":\"1.00000000\"}]}]}"}
{"local_receipt_timestamp_ns":1704067200000006642,"raw_payload":"{\"channel\":\"l2_data\",\"sequence_num\":663,\"events\":[{\"updates\":[{\"side\":\"bid\",\"event_time\":\"2024-01-01T00:00:00.000000001Z\",\"price_level\":\"50000.00\",\"new_quantity\":\"1.00000000\"}]}]}"}
{"local_receipt_timestamp_ns":1704067200000006652,"raw_payload":"{\"channel\":\"l2_data\",\"sequence_num\":664,\"events\":[{\"updates\":[{\"side\":\"offer\",\"event_time\":\"2024-01-01T00:00:00.000000001Z\",\"price_level\":\"50001.00\",\"new_quantity\":\"1.00000000\"}]}]}"}
{"local_receipt_timestamp_ns":1704067200000006662,"raw_payload":"{\"channel\":\"l2_data\",\"sequence_num\":665,\"events\":[{\"updates\":[{\"side\":\"bid\",\"event_time\":\"2024-01-01T00:00:00.000000001Z\",\"price_level\":\"50000.00\",\"new_quantity\":\"1.00000000\"}]}]}"}
{"local_receipt_timestamp_ns":1704067200000006672,"raw_payload":"{\"channel\":\"l2_data\",\"sequence_num\":666,\"events\":[{\"updates\":[{\"side\":\"offer\",\"event_time\":\"2024-01-01T00:00:00.000000001Z\",\"price_level\":\"50001.00\",\"new_quantity\":\"1.00000000\"}]}]}"}
{"local_receipt_timestamp_ns":1704067200000006682,"raw_payload":"{\"channel\":\"l2_data\",\"sequence_num\":667,\"events\":[{\"updates\":[{\"side\":\"bid\",\"event_time\":\"2024-01-01T00:00:00.000000001Z\",\"price_level\":\"50000.00\",\"new_quantity\":\"1.00000000\"}]}]}"}
{"local_receipt_timestamp_ns":1704067200000006692,"raw_payload":"{\"channel\":\"l2_data\",\"sequence_num\":668,\"events\":[{\"updates\":[{\"side\":\"offer\",\"event_time\":\"2024-01-01T00:00:00.000000001Z\",\"price_level\":\"50001.00\",\"new_quantity\":\"1.00000000\"}]}]}"}
{"local_receipt_timestamp_ns":1704067200000006702,"raw_payload":"{\"channel\":\"l2_data\",\"sequence_num\":669,\"events\":[{\"updates\":[{\"side\":\"bid\",\"event_time\":\"2024-01-01T00:00:00.000000001Z\",\"price_level\":\"50000.00\",\"new_quantity\":\"1.00000000\"}]}]}"}
{"local_receipt_timestamp_ns":1704067200000006712,"raw_payload":"{\"channel\":\"l2_data\",\"sequence_num\":670,\"events\":[{\"updates\":[{\"side\":\"offer\",\"event_time\":\"2024-01-01T00:00:00.000000001Z\",\"price_level\":\"50001.00\",\"new_quantity\":\"1.00000000\"}]}]}"}
{"local_receipt_timestamp_ns":1704067200000006722,"raw_payload":"{\"channel\":\"l2_data\",\"sequence_num\":671,\"events\":[{\"updates\":[{\"side\":\"bid\",\"event_time\":\"2024-01-01T00:00:00.000000001Z\",\"price_level\":\"50000.00\",\"new_quantity\":\"1.00000000\"}]}]}"}
{"local_receipt_timestamp_ns":1704067200000006732,"raw_payload":"{\"channel\":\"l2_data\",\"sequence_num\":672,\"events\":[{\"updates\":[{\"side\":\"offer\",\"event_time\":\"2024-01-01T00:00:00.000000001Z\",\"price_level\":\"50001.00\",\"new_quantity\":\"1.00000000\"}]}]}"}
{"local_receipt_timestamp_ns":1704067200000006742,"raw_payload":"{\"channel\":\"l2_data\",\"sequence_num\":673,\"events\":[{\"updates\":[{\"side\":\"bid\",\"event_time\":\"2024-01-01T00:00:00.000000001Z\",\"price_level\":\"50000.00\",\"new_quantity\":\"1.00000000\"}]}]}"}
{"local_receipt_timestamp_ns":1704067200000006752,"raw_payload":"{\"channel\":\"l2_data\",\"sequence_num\":674,\"events\":[{\"updates\":[{\"side\":\"offer\",\"event_time\":\"2024-01-01T00:00:00.000000001Z\",\"price_level\":\"50001.00\",\"new_quantity\":\"1.00000000\"}]}]}"}
{"local_receipt_timestamp_ns":1704067200000006762,"raw_payload":"{\"channel\":\"l2_data\",\"sequence_num\":675,\"events\":[{\"updates\":[{\"side\":\"bid\",\"event_time\":\"2024-01-01T00:00:00.000000001Z\",\"price_level\":\"50000.00\",\"new_quantity\":\"1.00000000\"}]}]}"}
{"local_receipt_timestamp_ns":1704067200000006772,"raw_payload":"{\"channel\":\"l2_data\",\"sequence_num\":676,\"events\":[{\"updates\":[{\"side\":\"offer\",\"event_time\":\"2024-01-01T00:00:00.000000001Z\",\"price_level\":\"50001.00\",\"new_quantity\":\"1.00000000\"}]}]}"}
{"local_receipt_timestamp_ns":1704067200000006782,"raw_payload":"{\"channel\":\"l2_data\",\"sequence_num\":677,\"events\":[{\"updates\":[{\"side\":\"bid\",\"event_time\":\"2024-01-01T00:00:00.000000001Z\",\"price_level\":\"50000.00\",\"new_quantity\":\"1.00000000\"}]}]}"}
{"local_receipt_timestamp_ns":1704067200000006792,"raw_payload":"{\"channel\":\"l2_data\",\"sequence_num\":678,\"events\":[{\"updates\":[{\"side\":\"offer\",\"event_time\":\"2024-01-01T00:00:00.000000001Z\",\"price_level\":\"50001.00\",\"new_quantity\":\"1.00000000\"}]}]}"}
{"local_receipt_timestamp_ns":1704067200000006802,"raw_payload":"{\"channel\":\"l2_data\",\"sequence_num\":679,\"events\":[{\"updates\":[{\"side\":\"bid\",\"event_time\":\"2024-01-01T00:00:00.000000001Z\",\"price_level\":\"50000.00\",\"new_quantity\":\"1.00000000\"}]}]}"}
{"local_receipt_timestamp_ns":1704067200000006812,"raw_payload":"{\"channel\":\"l2_data\",\"sequence_num\":680,\"events\":[{\"updates\":[{\"side\":\"offer\",\"event_time\":\"2024-01-01T00:00:00.000000001Z\",\"price_level\":\"50001.00\",\"new_quantity\":\"1.00000000\"}]}]}"}
{"local_receipt_timestamp_ns":1704067200000006822,"raw_payload":"{\"channel\":\"l2_data\",\"sequence_num\":681,\"events\":[{\"updates\":[{\"side\":\"bid\",\"event_time\":\"2024-01-01T00:00:00.000000001Z\",\"price_level\":\"50000.00\",\"new_quantity\":\"1.00000000\"}]}]}"}
{"local_receipt_timestamp_ns":1704067200000006832,"raw_payload":"{\"channel\":\"l2_data\",\"sequence_num\":682,\"events\":[{\"updates\":[{\"side\":\"offer\",\"event_time\":\"2024-01-01T00:00:00.000000001Z\",\"price_level\":\"50001.00\",\"new_quantity\":\"1.00000000\"}]}]}"}
{"local_receipt_timestamp_ns":1704067200000006842,"raw_payload":"{\"channel\":\"l2_data\",\"sequence_num\":683,\"events\":[{\"updates\":[{\"side\":\"bid\",\"event_time\":\"2024-01-01T00:00:00.000000001Z\",\"price_level\":\"50000.00\",\"new_quantity\":\"1.00000000\"}]}]}"}
{"local_receipt_timestamp_ns":1704067200000006852,"raw_payload":"{\"channel\":\"l2_data\",\"sequence_num\":684,\"events\":[{\"updates\":[{\"side\":\"offer\",\"event_time\":\"2024-01-01T00:00:00.000000001Z\",\"price_level\":\"50001.00\",\"new_quantity\":\"1.00000000\"}]}]}"}
{"local_receipt_timestamp_ns":1704067200000006862,"raw_payload":"{\"channel\":\"l2_data\",\"sequence_num\":685,\"events\":[{\"updates\":[{\"side\":\"bid\",\"event_time\":\"2024-01-01T00:00:00.000000001Z\",\"price_level\":\"50000.00\",\"new_quantity\":\"1.00000000\"}]}]}"}
{"local_receipt_timestamp_ns":1704067200000006872,"raw_payload":"{\"channel\":\"l2_data\",\"sequence_num\":686,\"events\":[{\"updates\":[{\"side\":\"offer\",\"event_time\":\"2024-01-01T00:00:00.000000001Z\",\"price_level\":\"50001.00\",\"new_quantity\":\"1.00000000\"}]}]}"}
{"local_receipt_timestamp_ns":1704067200000006882,"raw_payload":"{\"channel\":\"l2_data\",\"sequence_num\":687,\"events\":[{\"updates\":[{\"side\":\"bid\",\"event_time\":\"2024-01-01T00:00:00.000000001Z\",\"price_level\":\"50000.00\",\"new_quantity\":\"1.00000000\"}]}]}"}
{"local_receipt_timestamp_ns":1704067200000006892,"raw_payload":"{\"channel\":\"l2_data\",\"sequence_num\":688,\"events\":[{\"updates\":[{\"side\":\"offer\",\"event_time\":\"2024-01-01T00:00:00.000000001Z\",\"price_level\":\"50001.00\",\"new_quantity\":\"1.00000000\"}]}]}"}
{"local_receipt_timestamp_ns":1704067200000006902,"raw_payload":"{\"channel\":\"l2_data\",\"sequence_num\":689,\"events\":[{\"updates\":[{\"side\":\"bid\",\"event_time\":\"2024-01-01T00:00:00.000000001Z\",\"price_level\":\"50000.00\",\"new_quantity\":\"1.00000000\"}]}]}"}
{"local_receipt_timestamp_ns":1704067200000006912,"raw_payload":"{\"channel\":\"l2_data\",\"sequence_num\":690,\"events\":[{\"updates\":[{\"side\":\"offer\",\"event_time\":\"2024-01-01T00:00:00.000000001Z\",\"price_level\":\"50001.00\",\"new_quantity\":\"1.00000000\"}]}]}"}
{"local_receipt_timestamp_ns":1704067200000006922,"raw_payload":"{\"channel\":\"l2_data\",\"sequence_num\":691,\"events\":[{\"updates\":[{\"side\":\"bid\",\"event_time\":\"2024-01-01T00:00:00.000000001Z\",\"price_level\":\"50000.00\",\"new_quantity\":\"1.00000000\"}]}]}"}
{"local_receipt_timestamp_ns":1704067200000006932,"raw_payload":"{\"channel\":\"l2_data\",\"sequence_num\":692,\"events\":[{\"updates\":[{\"side\":\"offer\",\"event_time\":\"2024-01-01T00:00:00.000000001Z\",\"price_level\":\"50001.00\",\"new_quantity\":\"1.00000000\"}]}]}"}
{"local_receipt_timestamp_ns":1704067200000006942,"raw_payload":"{\"channel\":\"l2_data\",\"sequence_num\":693,\"events\":[{\"updates\":[{\"side\":\"bid\",\"event_time\":\"2024-01-01T00:00:00.000000001Z\",\"price_level\":\"50000.00\",\"new_quantity\":\"1.00000000\"}]}]}"}
{"local_receipt_timestamp_ns":1704067200000006952,"raw_payload":"{\"channel\":\"l2_data\",\"sequence_num\":694,\"events\":[{\"updates\":[{\"side\":\"offer\",\"event_time\":\"2024-01-01T00:00:00.000000001Z\",\"price_level\":\"50001.00\",\"new_quantity\":\"1.00000000\"}]}]}"}
{"local_receipt_timestamp_ns":1704067200000006962,"raw_payload":"{\"channel\":\"l2_data\",\"sequence_num\":695,\"events\":[{\"updates\":[{\"side\":\"bid\",\"event_time\":\"2024-01-01T00:00:00.000000001Z\",\"price_level\":\"50000.00\",\"new_quantity\":\"1.00000000\"}]}]}"}
{"local_receipt_timestamp_ns":1704067200000006972,"raw_payload":"{\"channel\":\"l2_data\",\"sequence_num\":696,\"events\":[{\"updates\":[{\"side\":\"offer\",\"event_time\":\"2024-01-01T00:00:00.000000001Z\",\"price_level\":\"50001.00\",\"new_quantity\":\"1.00000000\"}]}]}"}
{"local_receipt_timestamp_ns":1704067200000006982,"raw_payload":"{\"channel\":\"l2_data\",\"sequence_num\":697,\"events\":[{\"updates\":[{\"side\":\"bid\",\"event_time\":\"2024-01-01T00:00:00.000000001Z\",\"price_level\":\"50000.00\",\"new_quantity\":\"1.00000000\"}]}]}"}
{"local_receipt_timestamp_ns":1704067200000006992,"raw_payload":"{\"channel\":\"l2_data\",\"sequence_num\":698,\"events\":[{\"updates\":[{\"side\":\"offer\",\"event_time\":\"2024-01-01T00:00:00.000000001Z\",\"price_level\":\"50001.00\",\"new_quantity\":\"1.00000000\"}]}]}"}
{"local_receipt_timestamp_ns":1704067200000007002,"raw_payload":"{\"channel\":\"l2_data\",\"sequence_num\":699,\"events\":[{\"updates\":[{\"side\":\"bid\",\"event_time\":\"2024-01-01T00:00:00.000000001Z\",\"price_level\":\"50000.00\",\"new_quantity\":\"1.00000000\"}]}]}"}
{"local_receipt_timestamp_ns":1704067200000007012,"raw_payload":"{\"channel\":\"l2_data\",\"sequence_num\":700,\"events\":[{\"updates\":[{\"side\":\"offer\",\"event_time\":\"2024-01-01T00:00:00.000000001Z\",\"price_level\":\"50001.00\",\"new_quantity\":\"1.00000000\"}]}]}"}
{"local_receipt_timestamp_ns":1704067200000007022,"raw_payload":"{\"channel\":\"l2_data\",\"sequence_num\":701,\"events\":[{\"updates\":[{\"side\":\"bid\",\"event_time\":\"2024-01-01T00:00:00.000000001Z\",\"price_level\":\"50000.00\",\"new_quantity\":\"1.00000000\"}]}]}"}
{"local_receipt_timestamp_ns":1704067200000007032,"raw_payload":"{\"channel\":\"l2_data\",\"sequence_num\":702,\"events\":[{\"updates\":[{\"side\":\"offer\",\"event_time\":\"2024-01-01T00:00:00.000000001Z\",\"price_level\":\"50001.00\",\"new_quantity\":\"1.00000000\"}]}]}"}
{"local_receipt_timestamp_ns":1704067200000007042,"raw_payload":"{\"channel\":\"l2_data\",\"sequence_num\":703,\"events\":[{\"updates\":[{\"side\":\"bid\",\"event_time\":\"2024-01-01T00:00:00.000000001Z\",\"price_level\":\"50000.00\",\"new_quantity\":\"1.00000000\"}]}]}"}
{"local_receipt_timestamp_ns":1704067200000007052,"raw_payload":"{\"channel\":\"l2_data\",\"sequence_num\":704,\"events\":[{\"updates\":[{\"side\":\"offer\",\"event_time\":\"2024-01-01T00:00:00.000000001Z\",\"price_level\":\"50001.00\",\"new_quantity\":\"1.00000000\"}]}]}"}
{"local_receipt_timestamp_ns":1704067200000007062,"raw_payload":"{\"channel\":\"l2_data\",\"sequence_num\":705,\"events\":[{\"updates\":[{\"side\":\"bid\",\"event_time\":\"2024-01-01T00:00:00.000000001Z\",\"price_level\":\"50000.00\",\"new_quantity\":\"1.00000000\"}]}]}"}
{"local_receipt_timestamp_ns":1704067200000007072,"raw_payload":"{\"channel\":\"l2_data\",\"sequence_num\":706,\"events\":[{\"updates\":[{\"side\":\"offer\",\"event_time\":\"2024-01-01T00:00:00.000000001Z\",\"price_level\":\"50001.00\",\"new_quantity\":\"1.00000000\"}]}]}"}
{"local_receipt_timestamp_ns":1704067200000007082,"raw_payload":"{\"channel\":\"l2_data\",\"sequence_num\":707,\"events\":[{\"updates\":[{\"side\":\"bid\",\"event_time\":\"2024-01-01T00:00:00.000000001Z\",\"price_level\":\"50000.00\",\"new_quantity\":\"1.00000000\"}]}]}"}
{"local_receipt_timestamp_ns":1704067200000007092,"raw_payload":"{\"channel\":\"l2_data\",\"sequence_num\":708,\"events\":[{\"updates\":[{\"side\":\"offer\",\"event_time\":\"2024-01-01T00:00:00.000000001Z\",\"price_level\":\"50001.00\",\"new_quantity\":\"1.00000000\"}]}]}"}
{"local_receipt_timestamp_ns":1704067200000007102,"raw_payload":"{\"channel\":\"l2_data\",\"sequence_num\":709,\"events\":[{\"updates\":[{\"side\":\"bid\",\"event_time\":\"2024-01-01T00:00:00.000000001Z\",\"price_level\":\"50000.00\",\"new_quantity\":\"1.00000000\"}]}]}"}
{"local_receipt_timestamp_ns":1704067200000007112,"raw_payload":"{\"channel\":\"l2_data\",\"sequence_num\":710,\"events\":[{\"updates\":[{\"side\":\"offer\",\"event_time\":\"2024-01-01T00:00:00.000000001Z\",\"price_level\":\"50001.00\",\"new_quantity\":\"1.00000000\"}]}]}"}
{"local_receipt_timestamp_ns":1704067200000007122,"raw_payload":"{\"channel\":\"l2_data\",\"sequence_num\":711,\"events\":[{\"updates\":[{\"side\":\"bid\",\"event_time\":\"2024-01-01T00:00:00.000000001Z\",\"price_level\":\"50000.00\",\"new_quantity\":\"1.00000000\"}]}]}"}
{"local_receipt_timestamp_ns":1704067200000007132,"raw_payload":"{\"channel\":\"l2_data\",\"sequence_num\":712,\"events\":[{\"updates\":[{\"side\":\"offer\",\"event_time\":\"2024-01-01T00:00:00.000000001Z\",\"price_level\":\"50001.00\",\"new_quantity\":\"1.00000000\"}]}]}"}
{"local_receipt_timestamp_ns":1704067200000007142,"raw_payload":"{\"channel\":\"l2_data\",\"sequence_num\":713,\"events\":[{\"updates\":[{\"side\":\"bid\",\"event_time\":\"2024-01-01T00:00:00.000000001Z\",\"price_level\":\"50000.00\",\"new_quantity\":\"1.00000000\"}]}]}"}
{"local_receipt_timestamp_ns":1704067200000007152,"raw_payload":"{\"channel\":\"l2_data\",\"sequence_num\":714,\"events\":[{\"updates\":[{\"side\":\"offer\",\"event_time\":\"2024-01-01T00:00:00.000000001Z\",\"price_level\":\"50001.00\",\"new_quantity\":\"1.00000000\"}]}]}"}
{"local_receipt_timestamp_ns":1704067200000007162,"raw_payload":"{\"channel\":\"l2_data\",\"sequence_num\":715,\"events\":[{\"updates\":[{\"side\":\"bid\",\"event_time\":\"2024-01-01T00:00:00.000000001Z\",\"price_level\":\"50000.00\",\"new_quantity\":\"1.00000000\"}]}]}"}
{"local_receipt_timestamp_ns":1704067200000007172,"raw_payload":"{\"channel\":\"l2_data\",\"sequence_num\":716,\"events\":[{\"updates\":[{\"side\":\"offer\",\"event_time\":\"2024-01-01T00:00:00.000000001Z\",\"price_level\":\"50001.00\",\"new_quantity\":\"1.00000000\"}]}]}"}
{"local_receipt_timestamp_ns":1704067200000007182,"raw_payload":"{\"channel\":\"l2_data\",\"sequence_num\":717,\"events\":[{\"updates\":[{\"side\":\"bid\",\"event_time\":\"2024-01-01T00:00:00.000000001Z\",\"price_level\":\"50000.00\",\"new_quantity\":\"1.00000000\"}]}]}"}
{"local_receipt_timestamp_ns":1704067200000007192,"raw_payload":"{\"channel\":\"l2_data\",\"sequence_num\":718,\"events\":[{\"updates\":[{\"side\":\"offer\",\"event_time\":\"2024-01-01T00:00:00.000000001Z\",\"price_level\":\"50001.00\",\"new_quantity\":\"1.00000000\"}]}]}"}
{"local_receipt_timestamp_ns":1704067200000007202,"raw_payload":"{\"channel\":\"l2_data\",\"sequence_num\":719,\"events\":[{\"updates\":[{\"side\":\"bid\",\"event_time\":\"2024-01-01T00:00:00.000000001Z\",\"price_level\":\"50000.00\",\"new_quantity\":\"1.00000000\"}]}]}"}
{"local_receipt_timestamp_ns":1704067200000007212,"raw_payload":"{\"channel\":\"l2_data\",\"sequence_num\":720,\"events\":[{\"updates\":[{\"side\":\"offer\",\"event_time\":\"2024-01-01T00:00:00.000000001Z\",\"price_level\":\"50001.00\",\"new_quantity\":\"1.00000000\"}]}]}"}
{"local_receipt_timestamp_ns":1704067200000007222,"raw_payload":"{\"channel\":\"l2_data\",\"sequence_num\":721,\"events\":[{\"updates\":[{\"side\":\"bid\",\"event_time\":\"2024-01-01T00:00:00.000000001Z\",\"price_level\":\"50000.00\",\"new_quantity\":\"1.00000000\"}]}]}"}
{"local_receipt_timestamp_ns":1704067200000007232,"raw_payload":"{\"channel\":\"l2_data\",\"sequence_num\":722,\"events\":[{\"updates\":[{\"side\":\"offer\",\"event_time\":\"2024-01-01T00:00:00.000000001Z\",\"price_level\":\"50001.00\",\"new_quantity\":\"1.00000000\"}]}]}"}
{"local_receipt_timestamp_ns":1704067200000007242,"raw_payload":"{\"channel\":\"l2_data\",\"sequence_num\":723,\"events\":[{\"updates\":[{\"side\":\"bid\",\"event_time\":\"2024-01-01T00:00:00.000000001Z\",\"price_level\":\"50000.00\",\"new_quantity\":\"1.00000000\"}]}]}"}
{"local_receipt_timestamp_ns":1704067200000007252,"raw_payload":"{\"channel\":\"l2_data\",\"sequence_num\":724,\"events\":[{\"updates\":[{\"side\":\"offer\",\"event_time\":\"2024-01-01T00:00:00.000000001Z\",\"price_level\":\"50001.00\",\"new_quantity\":\"1.00000000\"}]}]}"}
{"local_receipt_timestamp_ns":1704067200000007262,"raw_payload":"{\"channel\":\"l2_data\",\"sequence_num\":725,\"events\":[{\"updates\":[{\"side\":\"bid\",\"event_time\":\"2024-01-01T00:00:00.000000001Z\",\"price_level\":\"50000.00\",\"new_quantity\":\"1.00000000\"}]}]}"}
{"local_receipt_timestamp_ns":1704067200000007272,"raw_payload":"{\"channel\":\"l2_data\",\"sequence_num\":726,\"events\":[{\"updates\":[{\"side\":\"offer\",\"event_time\":\"2024-01-01T00:00:00.000000001Z\",\"price_level\":\"50001.00\",\"new_quantity\":\"1.00000000\"}]}]}"}
{"local_receipt_timestamp_ns":1704067200000007282,"raw_payload":"{\"channel\":\"l2_data\",\"sequence_num\":727,\"events\":[{\"updates\":[{\"side\":\"bid\",\"event_time\":\"2024-01-01T00:00:00.000000001Z\",\"price_level\":\"50000.00\",\"new_quantity\":\"1.00000000\"}]}]}"}
{"local_receipt_timestamp_ns":1704067200000007292,"raw_payload":"{\"channel\":\"l2_data\",\"sequence_num\":728,\"events\":[{\"updates\":[{\"side\":\"offer\",\"event_time\":\"2024-01-01T00:00:00.000000001Z\",\"price_level\":\"50001.00\",\"new_quantity\":\"1.00000000\"}]}]}"}
{"local_receipt_timestamp_ns":1704067200000007302,"raw_payload":"{\"channel\":\"l2_data\",\"sequence_num\":729,\"events\":[{\"updates\":[{\"side\":\"bid\",\"event_time\":\"2024-01-01T00:00:00.000000001Z\",\"price_level\":\"50000.00\",\"new_quantity\":\"1.00000000\"}]}]}"}
