{"local_receipt_timestamp_ns":1704067200000000013,"raw_payload":"{\"arg\":{\"channel\":\"books\",\"instId\":\"BTC-USDT\"},\"data\":[{\"ts\":\"1704067200001\",\"seqId\":1,\"prevSeqId\":0,\"bids\":[[\"50000.0\",\"1.00000000\",\"0\",\"1\"]],\"asks\":[]}]}"}
{"local_receipt_timestamp_ns":1704067200000000023,"raw_payload":"{\"arg\":{\"channel\":\"books\",\"instId\":\"BTC-USDT\"},\"data\":[{\"ts\":\"1704067200002\",\"seqId\":2,\"prevSeqId\":1,\"bids\":[],\"asks\":[[\"50001.0\",\"1.00000000\",\"0\",\"1\"]]}]}"}
{"local_receipt_timestamp_ns":1704067200000000033,"raw_payload":"{\"arg\":{\"channel\":\"books\",\"instId\":\"BTC-USDT\"},\"data\":[{\"ts\":\"1704067200003\",\"seqId\":3,\"prevSeqId\":2,\"bids\":[[\"50000.0\",\"1.00000000\",\"0\",\"1\"]],\"asks\":[]}]}"}
{"local_receipt_timestamp_ns":1704067200000000043,"raw_payload":"{\"arg\":{\"channel\":\"books\",\"instId\":\"BTC-USDT\"},\"data\":[{\"ts\":\"1704067200004\",\"seqId\":4,\"prevSeqId\":3,\"bids\":[],\"asks\":[[\"50001.0\",\"1.00000000\",\"0\",\"1\"]]}]}"}
{"local_receipt_timestamp_ns":1704067200000000053,"raw_payload":"{\"arg\":{\"channel\":\"books\",\"instId\":\"BTC-USDT\"},\"data\":[{\"ts\":\"1704067200005\",\"seqId\":5,\"prevSeqId\":4,\"bids\":[[\"50000.0\",\"1.00000000\",\"0\",\"1\"]],\"asks\":[]}]}"}
{"local_receipt_timestamp_ns":1704067200000000063,"raw_payload":"{\"arg\":{\"channel\":\"books\",\"instId\":\"BTC-USDT\"},\"data\":[{\"ts\":\"1704067200006\",\"seqId\":6,\"prevSeqId\":5,\"bids\":[],\"asks\":[[\"50001.0\",\"1.00000000\",\"0\",\"1\"]]}]}"}
{"local_receipt_timestamp_ns":1704067200000000073,"raw_payload":"{\"arg\":{\"channel\":\"books\",\"instId\":\"BTC-USDT\"},\"data\":[{\"ts\":\"1704067200007\",\"seqId\":7,\"prevSeqId\":6,\"bids\":[[\"50000.0\",\"1.00000000\",\"0\",\"1\"]],\"asks\":[]}]}"}
{"local_receipt_timestamp_ns":1704067200000000083,"raw_payload":"{\"arg\":{\"channel\":\"books\",\"instId\":\"BTC-USDT\"},\"data\":[{\"ts\":\"1704067200008\",\"seqId\":8,\"prevSeqId\":7,\"bids\":[],\"asks\":[[\"50001.0\",\"1.00000000\",\"0\",\"1\"]]}]}"}
{"local_receipt_timestamp_ns":1704067200000000093,"raw_payload":"{\"arg\":{\"channel\":\"books\",\"instId\":\"BTC-USDT\"},\"data\":[{\"ts\":\"1704067200009\",\"seqId\":9,\"prevSeqId\":8,\"bids\":[[\"50000.0\",\"1.00000000\",\"0\",\"1\"]],\"asks\":[]}]}"}
{"local_receipt_timestamp_ns":1704067200000000103,"raw_payload":"{\"arg\":{\"channel\":\"books\",\"instId\":\"BTC-USDT\"},\"data\":[{\"ts\":\"1704067200010\",\"seqId\":10,\"prevSeqId\":9,\"bids\":[],\"asks\":[[\"50001.0\",\"1.00000000\",\"0\",\"1\"]]}]}"}
{"local_receipt_timestamp_ns":1704067200000000113,"raw_payload":"{\"arg\":{\"channel\":\"books\",\"instId\":\"BTC-USDT\"},\"data\":[{\"ts\":\"1704067200011\",\"seqId\":11,\"prevSeqId\":10,\"bids\":[[\"50000.0\",\"1.00000000\",\"0\",\"1\"]],\"asks\":[]}]}"}
{"local_receipt_timestamp_ns":1704067200000000123,"raw_payload":"{\"arg\":{\"channel\":\"books\",\"instId\":\"BTC-USDT\"},\"data\":[{\"ts\":\"1704067200012\",\"seqId\":12,\"prevSeqId\":11,\"bids\":[],\"asks\":[[\"50001.0\",\"1.00000000\",\"0\",\"1\"]]}]}"}
{"local_receipt_timestamp_ns":1704067200000000133,"raw_payload":"{\"arg\":{\"channel\":\"books\",\"instId\":\"BTC-USDT\"},\"data\":[{\"ts\":\"1704067200013\",\"seqId\":13,\"prevSeqId\":12,\"bids\":[[\"50000.0\",\"1.00000000\",\"0\",\"1\"]],\"asks\":[]}]}"}
{"local_receipt_timestamp_ns":1704067200000000143,"raw_payload":"{\"arg\":{\"channel\":\"books\",\"instId\":\"BTC-USDT\"},\"data\":[{\"ts\":\"1704067200014\",\"seqId\":14,\"prevSeqId\":13,\"bids\":[],\"asks\":[[\"50001.0\",\"1.00000000\",\"0\",\"1\"]]}]}"}
{"local_receipt_timestamp_ns":1704067200000000153,"raw_payload":"{\"arg\":{\"channel\":\"books\",\"instId\":\"BTC-USDT\"},\"data\":[{\"ts\":\"1704067200015\",\"seqId\":15,\"prevSeqId\":14,\"bids\":[[\"50000.0\",\"1.00000000\",\"0\",\"1\"]],\"asks\":[]}]}"}
{"local_receipt_timestamp_ns":1704067200000000163,"raw_payload":"{\"arg\":{\"channel\":\"books\",\"instId\":\"BTC-USDT\"},\"data\":[{\"ts\":\"1704067200016\",\"seqId\":16,\"prevSeqId\":15,\"bids\":[],\"asks\":[[\"50001.0\",\"1.00000000\",\"0\",\"1\"]]}]}"}
{"local_receipt_timestamp_ns":1704067200000000173,"raw_payload":"{\"arg\":{\"channel\":\"books\",\"instId\":\"BTC-USDT\"},\"data\":[{\"ts\":\"1704067200017\",\"seqId\":17,\"prevSeqId\":16,\"bids\":[[\"50000.0\",\"1.00000000\",\"0\",\"1\"]],\"asks\":[]}]}"}
{"local_receipt_timestamp_ns":1704067200000000183,"raw_payload":"{\"arg\":{\"channel\":\"books\",\"instId\":\"BTC-USDT\"},\"data\":[{\"ts\":\"1704067200018\",\"seqId\":18,\"prevSeqId\":17,\"bids\":[],\"asks\":[[\"50001.0\",\"1.00000000\",\"0\",\"1\"]]}]}"}
{"local_receipt_timestamp_ns":1704067200000000193,"raw_payload":"{\"arg\":{\"channel\":\"books\",\"instId\":\"BTC-USDT\"},\"data\":[{\"ts\":\"1704067200019\",\"seqId\":19,\"prevSeqId\":18,\"bids\":[[\"50000.0\",\"1.00000000\",\"0\",\"1\"]],\"asks\":[]}]}"}
{"local_receipt_timestamp_ns":1704067200000000203,"raw_payload":"{\"arg\":{\"channel\":\"books\",\"instId\":\"BTC-USDT\"},\"data\":[{\"ts\":\"1704067200020\",\"seqId\":20,\"prevSeqId\":19,\"bids\":[],\"asks\":[[\"50001.0\",\"1.00000000\",\"0\",\"1\"]]}]}"}
{"local_receipt_timestamp_ns":1704067200000000213,"raw_payload":"{\"arg\":{\"channel\":\"books\",\"instId\":\"BTC-USDT\"},\"data\":[{\"ts\":\"1704067200021\",\"seqId\":21,\"prevSeqId\":20,\"bids\":[[\"50000.0\",\"1.00000000\",\"0\",\"1\"]],\"asks\":[]}]}"}
{"local_receipt_timestamp_ns":1704067200000000223,"raw_payload":"{\"arg\":{\"channel\":\"books\",\"instId\":\"BTC-USDT\"},\"data\":[{\"ts\":\"1704067200022\",\"seqId\":22,\"prevSeqId\":21,\"bids\":[],\"asks\":[[\"50001.0\",\"1.00000000\",\"0\",\"1\"]]}]}"}
{"local_receipt_timestamp_ns":1704067200000000233,"raw_payload":"{\"arg\":{\"channel\":\"books\",\"instId\":\"BTC-USDT\"},\"data\":[{\"ts\":\"1704067200023\",\"seqId\":23,\"prevSeqId\":22,\"bids\":[[\"50000.0\",\"1.00000000\",\"0\",\"1\"]],\"asks\":[]}]}"}
{"local_receipt_timestamp_ns":1704067200000000243,"raw_payload":"{\"arg\":{\"channel\":\"books\",\"instId\":\"BTC-USDT\"},\"data\":[{\"ts\":\"1704067200024\",\"seqId\":24,\"prevSeqId\":23,\"bids\":[],\"asks\":[[\"50001.0\",\"1.00000000\",\"0\",\"1\"]]}]}"}
{"local_receipt_timestamp_ns":1704067200000000253,"raw_payload":"{\"arg\":{\"channel\":\"books\",\"instId\":\"BTC-USDT\"},\"data\":[{\"ts\":\"1704067200025\",\"seqId\":25,\"prevSeqId\":24,\"bids\":[[\"50000.0\",\"1.00000000\",\"0\",\"1\"]],\"asks\":[]}]}"}
{"local_receipt_timestamp_ns":1704067200000000263,"raw_payload":"{\"arg\":{\"channel\":\"books\",\"instId\":\"BTC-USDT\"},\"data\":[{\"ts\":\"1704067200026\",\"seqId\":26,\"prevSeqId\":25,\"bids\":[],\"asks\":[[\"50001.0\",\"1.00000000\",\"0\",\"1\"]]}]}"}
{"local_receipt_timestamp_ns":1704067200000000273,"raw_payload":"{\"arg\":{\"channel\":\"books\",\"instId\":\"BTC-USDT\"},\"data\":[{\"ts\":\"1704067200027\",\"seqId\":27,\"prevSeqId\":26,\"bids\":[[\"50000.0\",\"1.00000000\",\"0\",\"1\"]],\"asks\":[]}]}"}
{"local_receipt_timestamp_ns":1704067200000000283,"raw_payload":"{\"arg\":{\"channel\":\"books\",\"instId\":\"BTC-USDT\"},\"data\":[{\"ts\":\"1704067200028\",\"seqId\":28,\"prevSeqId\":27,\"bids\":[],\"asks\":[[\"50001.0\",\"1.00000000\",\"0\",\"1\"]]}]}"}
{"local_receipt_timestamp_ns":1704067200000000293,"raw_payload":"{\"arg\":{\"channel\":\"books\",\"instId\":\"BTC-USDT\"},\"data\":[{\"ts\":\"1704067200029\",\"seqId\":29,\"prevSeqId\":28,\"bids\":[[\"50000.0\",\"1.00000000\",\"0\",\"1\"]],\"asks\":[]}]}"}
{"local_receipt_timestamp_ns":1704067200000000303,"raw_payload":"{\"arg\":{\"channel\":\"books\",\"instId\":\"BTC-USDT\"},\"data\":[{\"ts\":\"1704067200030\",\"seqId\":30,\"prevSeqId\":29,\"bids\":[],\"asks\":[[\"50001.0\",\"1.00000000\",\"0\",\"1\"]]}]}"}
{"local_receipt_timestamp_ns":1704067200000000313,"raw_payload":"{\"arg\":{\"channel\":\"books\",\"instId\":\"BTC-USDT\"},\"data\":[{\"ts\":\"1704067200031\",\"seqId\":31,\"prevSeqId\":30,\"bids\":[[\"50000.0\",\"1.00000000\",\"0\",\"1\"]],\"asks\":[]}]}"}
{"local_receipt_timestamp_ns":1704067200000000323,"raw_payload":"{\"arg\":{\"channel\":\"books\",\"instId\":\"BTC-USDT\"},\"data\":[{\"ts\":\"1704067200032\",\"seqId\":32,\"prevSeqId\":31,\"bids\":[],\"asks\":[[\"50001.0\",\"1.00000000\",\"0\",\"1\"]]}]}"}
{"local_receipt_timestamp_ns":1704067200000000333,"raw_payload":"{\"arg\":{\"channel\":\"books\",\"instId\":\"BTC-USDT\"},\"data\":[{\"ts\":\"1704067200033\",\"seqId\":33,\"prevSeqId\":32,\"bids\":[[\"50000.0\",\"1.00000000\",\"0\",\"1\"]],\"asks\":[]}]}"}
{"local_receipt_timestamp_ns":1704067200000000343,"raw_payload":"{\"arg\":{\"channel\":\"books\",\"instId\":\"BTC-USDT\"},\"data\":[{\"ts\":\"1704067200034\",\"seqId\":34,\"prevSeqId\":33,\"bids\":[],\"asks\":[[\"50001.0\",\"1.00000000\",\"0\",\"1\"]]}]}"}
{"local_receipt_timestamp_ns":1704067200000000353,"raw_payload":"{\"arg\":{\"channel\":\"books\",\"instId\":\"BTC-USDT\"},\"data\":[{\"ts\":\"1704067200035\",\"seqId\":35,\"prevSeqId\":34,\"bids\":[[\"50000.0\",\"1.00000000\",\"0\",\"1\"]],\"asks\":[]}]}"}
{"local_receipt_timestamp_ns":1704067200000000363,"raw_payload":"{\"arg\":{\"channel\":\"books\",\"instId\":\"BTC-USDT\"},\"data\":[{\"ts\":\"1704067200036\",\"seqId\":36,\"prevSeqId\":35,\"bids\":[],\"asks\":[[\"50001.0\",\"1.00000000\",\"0\",\"1\"]]}]}"}
{"local_receipt_timestamp_ns":1704067200000000373,"raw_payload":"{\"arg\":{\"channel\":\"books\",\"instId\":\"BTC-USDT\"},\"data\":[{\"ts\":\"1704067200037\",\"seqId\":37,\"prevSeqId\":36,\"bids\":[[\"50000.0\",\"1.00000000\",\"0\",\"1\"]],\"asks\":[]}]}"}
{"local_receipt_timestamp_ns":1704067200000000383,"raw_payload":"{\"arg\":{\"channel\":\"books\",\"instId\":\"BTC-USDT\"},\"data\":[{\"ts\":\"1704067200038\",\"seqId\":38,\"prevSeqId\":37,\"bids\":[],\"asks\":[[\"50001.0\",\"1.00000000\",\"0\",\"1\"]]}]}"}
{"local_receipt_timestamp_ns":1704067200000000393,"raw_payload":"{\"arg\":{\"channel\":\"books\",\"instId\":\"BTC-USDT\"},\"data\":[{\"ts\":\"1704067200039\",\"seqId\":39,\"prevSeqId\":38,\"bids\":[[\"50000.0\",\"1.00000000\",\"0\",\"1\"]],\"asks\":[]}]}"}
{"local_receipt_timestamp_ns":1704067200000000403,"raw_payload":"{\"arg\":{\"channel\":\"books\",\"instId\":\"BTC-USDT\"},\"data\":[{\"ts\":\"1704067200040\",\"seqId\":40,\"prevSeqId\":39,\"bids\":[],\"asks\":[[\"50001.0\",\"1.00000000\",\"0\",\"1\"]]}]}"}
{"local_receipt_timestamp_ns":1704067200000000413,"raw_payload":"{\"arg\":{\"channel\":\"books\",\"instId\":\"BTC-USDT\"},\"data\":[{\"ts\":\"1704067200041\",\"seqId\":41,\"prevSeqId\":40,\"bids\":[[\"50000.0\",\"1.00000000\",\"0\",\"1\"]],\"asks\":[]}]}"}
{"local_receipt_timestamp_ns":1704067200000000423,"raw_payload":"{\"arg\":{\"channel\":\"books\",\"instId\":\"BTC-USDT\"},\"data\":[{\"ts\":\"1704067200042\",\"seqId\":42,\"prevSeqId\":41,\"bids\":[],\"asks\":[[\"50001.0\",\"1.00000000\",\"0\",\"1\"]]}]}"}
{"local_receipt_timestamp_ns":1704067200000000433,"raw_payload":"{\"arg\":{\"channel\":\"books\",\"instId\":\"BTC-USDT\"},\"data\":[{\"ts\":\"1704067200043\",\"seqId\":43,\"prevSeqId\":42,\"bids\":[[\"50000.0\",\"1.00000000\",\"0\",\"1\"]],\"asks\":[]}]}"}
{"local_receipt_timestamp_ns":1704067200000000443,"raw_payload":"{\"arg\":{\"channel\":\"books\",\"instId\":\"BTC-USDT\"},\"data\":[{\"ts\":\"1704067200044\",\"seqId\":44,\"prevSeqId\":43,\"bids\":[],\"asks\":[[\"50001.0\",\"1.00000000\",\"0\",\"1\"]]}]}"}
{"local_receipt_timestamp_ns":1704067200000000453,"raw_payload":"{\"arg\":{\"channel\":\"books\",\"instId\":\"BTC-USDT\"},\"data\":[{\"ts\":\"1704067200045\",\"seqId\":45,\"prevSeqId\":44,\"bids\":[[\"50000.0\",\"1.00000000\",\"0\",\"1\"]],\"asks\":[]}]}"}
{"local_receipt_timestamp_ns":1704067200000000463,"raw_payload":"{\"arg\":{\"channel\":\"books\",\"instId\":\"BTC-USDT\"},\"data\":[{\"ts\":\"1704067200046\",\"seqId\":46,\"prevSeqId\":45,\"bids\":[],\"asks\":[[\"50001.0\",\"1.00000000\",\"0\",\"1\"]]}]}"}
{"local_receipt_timestamp_ns":1704067200000000473,"raw_payload":"{\"arg\":{\"channel\":\"books\",\"instId\":\"BTC-USDT\"},\"data\":[{\"ts\":\"1704067200047\",\"seqId\":47,\"prevSeqId\":46,\"bids\":[[\"50000.0\",\"1.00000000\",\"0\",\"1\"]],\"asks\":[]}]}"}
{"local_receipt_timestamp_ns":1704067200000000483,"raw_payload":"{\"arg\":{\"channel\":\"books\",\"instId\":\"BTC-USDT\"},\"data\":[{\"ts\":\"1704067200048\",\"seqId\":48,\"prevSeqId\":47,\"bids\":[],\"asks\":[[\"50001.0\",\"1.00000000\",\"0\",\"1\"]]}]}"}
{"local_receipt_timestamp_ns":1704067200000000493,"raw_payload":"{\"arg\":{\"channel\":\"books\",\"instId\":\"BTC-USDT\"},\"data\":[{\"ts\":\"1704067200049\",\"seqId\":49,\"prevSeqId\":48,\"bids\":[[\"50000.0\",\"1.00000000\",\"0\",\"1\"]],\"asks\":[]}]}"}
{"local_receipt_timestamp_ns":1704067200000000503,"raw_payload":"{\"arg\":{\"channel\":\"books\",\"instId\":\"BTC-USDT\"},\"data\":[{\"ts\":\"1704067200050\",\"seqId\":50,\"prevSeqId\":49,\"bids\":[],\"asks\":[[\"50001.0\",\"1.00000000\",\"0\",\"1\"]]}]}"}
{"local_receipt_timestamp_ns":1704067200000000513,"raw_payload":"{\"arg\":{\"channel\":\"books\",\"instId\":\"BTC-USDT\"},\"data\":[{\"ts\":\"1704067200051\",\"seqId\":51,\"prevSeqId\":50,\"bids\":[[\"50000.0\",\"1.00000000\",\"0\",\"1\"]],\"asks\":[]}]}"}
{"local_receipt_timestamp_ns":1704067200000000523,"raw_payload":"{\"arg\":{\"channel\":\"books\",\"instId\":\"BTC-USDT\"},\"data\":[{\"ts\":\"1704067200052\",\"seqId\":52,\"prevSeqId\":51,\"bids\":[],\"asks\":[[\"50001.0\",\"1.00000000\",\"0\",\"1\"]]}]}"}
{"local_receipt_timestamp_ns":1704067200000000533,"raw_payload":"{\"arg\":{\"channel\":\"books\",\"instId\":\"BTC-USDT\"},\"data\":[{\"ts\":\"1704067200053\",\"seqId\":53,\"prevSeqId\":52,\"bids\":[[\"50000.0\",\"1.00000000\",\"0\",\"1\"]],\"asks\":[]}]}"}
{"local_receipt_timestamp_ns":1704067200000000543,"raw_payload":"{\"arg\":{\"channel\":\"books\",\"instId\":\"BTC-USDT\"},\"data\":[{\"ts\":\"1704067200054\",\"seqId\":54,\"prevSeqId\":53,\"bids\":[],\"asks\":[[\"50001.0\",\"1.00000000\",\"0\",\"1\"]]}]}"}
{"local_receipt_timestamp_ns":1704067200000000553,"raw_payload":"{\"arg\":{\"channel\":\"books\",\"instId\":\"BTC-USDT\"},\"data\":[{\"ts\":\"1704067200055\",\"seqId\":55,\"prevSeqId\":54,\"bids\":[[\"50000.0\",\"1.00000000\",\"0\",\"1\"]],\"asks\":[]}]}"}
{"local_receipt_timestamp_ns":1704067200000000563,"raw_payload":"{\"arg\":{\"channel\":\"books\",\"instId\":\"BTC-USDT\"},\"data\":[{\"ts\":\"1704067200056\",\"seqId\":56,\"prevSeqId\":55,\"bids\":[],\"asks\":[[\"50001.0\",\"1.00000000\",\"0\",\"1\"]]}]}"}
{"local_receipt_timestamp_ns":1704067200000000573,"raw_payload":"{\"arg\":{\"channel\":\"books\",\"instId\":\"BTC-USDT\"},\"data\":[{\"ts\":\"1704067200057\",\"seqId\":57,\"prevSeqId\":56,\"bids\":[[\"50000.0\",\"1.00000000\",\"0\",\"1\"]],\"asks\":[]}]}"}
{"local_receipt_timestamp_ns":1704067200000000583,"raw_payload":"{\"arg\":{\"channel\":\"books\",\"instId\":\"BTC-USDT\"},\"data\":[{\"ts\":\"1704067200058\",\"seqId\":58,\"prevSeqId\":57,\"bids\":[],\"asks\":[[\"50001.0\",\"1.00000000\",\"0\",\"1\"]]}]}"}
{"local_receipt_timestamp_ns":1704067200000000593,"raw_payload":"{\"arg\":{\"channel\":\"books\",\"instId\":\"BTC-USDT\"},\"data\":[{\"ts\":\"1704067200059\",\"seqId\":59,\"prevSeqId\":58,\"bids\":[[\"50000.0\",\"1.00000000\",\"0\",\"1\"]],\"asks\":[]}]}"}
{"local_receipt_timestamp_ns":1704067200000000603,"raw_payload":"{\"arg\":{\"channel\":\"books\",\"instId\":\"BTC-USDT\"},\"data\":[{\"ts\":\"1704067200060\",\"seqId\":60,\"prevSeqId\":59,\"bids\":[],\"asks\":[[\"50001.0\",\"1.00000000\",\"0\",\"1\"]]}]}"}
{"local_receipt_timestamp_ns":1704067200000000613,"raw_payload":"{\"arg\":{\"channel\":\"books\",\"instId\":\"BTC-USDT\"},\"data\":[{\"ts\":\"1704067200061\",\"seqId\":61,\"prevSeqId\":60,\"bids\":[[\"50000.0\",\"1.00000000\",\"0\",\"1\"]],\"asks\":[]}]}"}
{"local_receipt_timestamp_ns":1704067200000000623,"raw_payload":"{\"arg\":{\"channel\":\"books\",\"instId\":\"BTC-USDT\"},\"data\":[{\"ts\":\"1704067200062\",\"seqId\":62,\"prevSeqId\":61,\"bids\":[],\"asks\":[[\"50001.0\",\"1.00000000\",\"0\",\"1\"]]}]}"}
{"local_receipt_timestamp_ns":1704067200000000633,"raw_payload":"{\"arg\":{\"channel\":\"books\",\"instId\":\"BTC-USDT\"},\"data\":[{\"ts\":\"1704067200063\",\"seqId\":63,\"prevSeqId\":62,\"bids\":[[\"50000.0\",\"1.00000000\",\"0\",\"1\"]],\"asks\":[]}]}"}
{"local_receipt_timestamp_ns":1704067200000000643,"raw_payload":"{\"arg\":{\"channel\":\"books\",\"instId\":\"BTC-USDT\"},\"data\":[{\"ts\":\"1704067200064\",\"seqId\":64,\"prevSeqId\":63,\"bids\":[],\"asks\":[[\"50001.0\",\"1.00000000\",\"0\",\"1\"]]}]}"}
{"local_receipt_timestamp_ns":1704067200000000653,"raw_payload":"{\"arg\":{\"channel\":\"books\",\"instId\":\"BTC-USDT\"},\"data\":[{\"ts\":\"1704067200065\",\"seqId\":65,\"prevSeqId\":64,\"bids\":[[\"50000.0\",\"1.00000000\",\"0\",\"1\"]],\"asks\":[]}]}"}
{"local_receipt_timestamp_ns":1704067200000000663,"raw_payload":"{\"arg\":{\"channel\":\"books\",\"instId\":\"BTC-USDT\"},\"data\":[{\"ts\":\"1704067200066\",\"seqId\":66,\"prevSeqId\":65,\"bids\":[],\"asks\":[[\"50001.0\",\"1.00000000\",\"0\",\"1\"]]}]}"}
{"local_receipt_timestamp_ns":1704067200000000673,"raw_payload":"{\"arg\":{\"channel\":\"books\",\"instId\":\"BTC-USDT\"},\"data\":[{\"ts\":\"1704067200067\",\"seqId\":67,\"prevSeqId\":66,\"bids\":[[\"50000.0\",\"1.00000000\",\"0\",\"1\"]],\"asks\":[]}]}"}
{"local_receipt_timestamp_ns":1704067200000000683,"raw_payload":"{\"arg\":{\"channel\":\"books\",\"instId\":\"BTC-USDT\"},\"data\":[{\"ts\":\"1704067200068\",\"seqId\":68,\"prevSeqId\":67,\"bids\":[],\"asks\":[[\"50001.0\",\"1.00000000\",\"0\",\"1\"]]}]}"}
{"local_receipt_timestamp_ns":1704067200000000693,"raw_payload":"{\"arg\":{\"channel\":\"books\",\"instId\":\"BTC-USDT\"},\"data\":[{\"ts\":\"1704067200069\",\"seqId\":69,\"prevSeqId\":68,\"bids\":[[\"50000.0\",\"1.00000000\",\"0\",\"1\"]],\"asks\":[]}]}"}
{"local_receipt_timestamp_ns":1704067200000000703,"raw_payload":"{\"arg\":{\"channel\":\"books\",\"instId\":\"BTC-USDT\"},\"data\":[{\"ts\":\"1704067200070\",\"seqId\":70,\"prevSeqId\":69,\"bids\":[],\"asks\":[[\"50001.0\",\"1.00000000\",\"0\",\"1\"]]}]}"}
{"local_receipt_timestamp_ns":1704067200000000713,"raw_payload":"{\"arg\":{\"channel\":\"books\",\"instId\":\"BTC-USDT\"},\"data\":[{\"ts\":\"1704067200071\",\"seqId\":71,\"prevSeqId\":70,\"bids\":[[\"50000.0\",\"1.00000000\",\"0\",\"1\"]],\"asks\":[]}]}"}
{"local_receipt_timestamp_ns":1704067200000000723,"raw_payload":"{\"arg\":{\"channel\":\"books\",\"instId\":\"BTC-USDT\"},\"data\":[{\"ts\":\"1704067200072\",\"seqId\":72,\"prevSeqId\":71,\"bids\":[],\"asks\":[[\"50001.0\",\"1.00000000\",\"0\",\"1\"]]}]}"}
{"local_receipt_timestamp_ns":1704067200000000733,"raw_payload":"{\"arg\":{\"channel\":\"books\",\"instId\":\"BTC-USDT\"},\"data\":[{\"ts\":\"1704067200073\",\"seqId\":73,\"prevSeqId\":72,\"bids\":[[\"50000.0\",\"1.00000000\",\"0\",\"1\"]],\"asks\":[]}]}"}
{"local_receipt_timestamp_ns":1704067200000000743,"raw_payload":"{\"arg\":{\"channel\":\"books\",\"instId\":\"BTC-USDT\"},\"data\":[{\"ts\":\"1704067200074\",\"seqId\":74,\"prevSeqId\":73,\"bids\":[],\"asks\":[[\"50001.0\",\"1.00000000\",\"0\",\"1\"]]}]}"}
{"local_receipt_timestamp_ns":1704067200000000753,"raw_payload":"{\"arg\":{\"channel\":\"books\",\"instId\":\"BTC-USDT\"},\"data\":[{\"ts\":\"1704067200075\",\"seqId\":75,\"prevSeqId\":74,\"bids\":[[\"50000.0\",\"1.00000000\",\"0\",\"1\"]],\"asks\":[]}]}"}
{"local_receipt_timestamp_ns":1704067200000000763,"raw_payload":"{\"arg\":{\"channel\":\"books\",\"instId\":\"BTC-USDT\"},\"data\":[{\"ts\":\"1704067200076\",\"seqId\":76,\"prevSeqId\":75,\"bids\":[],\"asks\":[[\"50001.0\",\"1.00000000\",\"0\",\"1\"]]}]}"}
{"local_receipt_timestamp_ns":1704067200000000773,"raw_payload":"{\"arg\":{\"channel\":\"books\",\"instId\":\"BTC-USDT\"},\"data\":[{\"ts\":\"1704067200077\",\"seqId\":77,\"prevSeqId\":76,\"bids\":[[\"50000.0\",\"1.00000000\",\"0\",\"1\"]],\"asks\":[]}]}"}
{"local_receipt_timestamp_ns":1704067200000000783,"raw_payload":"{\"arg\":{\"channel\":\"books\",\"instId\":\"BTC-USDT\"},\"data\":[{\"ts\":\"1704067200078\",\"seqId\":78,\"prevSeqId\":77,\"bids\":[],\"asks\":[[\"50001.0\",\"1.00000000\",\"0\",\"1\"]]}]}"}
{"local_receipt_timestamp_ns":1704067200000000793,"raw_payload":"{\"arg\":{\"channel\":\"books\",\"instId\":\"BTC-USDT\"},\"data\":[{\"ts\":\"1704067200079\",\"seqId\":79,\"prevSeqId\":78,\"bids\":[[\"50000.0\",\"1.00000000\",\"0\",\"1\"]],\"asks\":[]}]}"}
{"local_receipt_timestamp_ns":1704067200000000803,"raw_payload":"{\"arg\":{\"channel\":\"books\",\"instId\":\"BTC-USDT\"},\"data\":[{\"ts\":\"1704067200080\",\"seqId\":80,\"prevSeqId\":79,\"bids\":[],\"asks\":[[\"50001.0\",\"1.00000000\",\"0\",\"1\"]]}]}"}
{"local_receipt_timestamp_ns":1704067200000000813,"raw_payload":"{\"arg\":{\"channel\":\"books\",\"instId\":\"BTC-USDT\"},\"data\":[{\"ts\":\"1704067200081\",\"seqId\":81,\"prevSeqId\":80,\"bids\":[[\"50000.0\",\"1.00000000\",\"0\",\"1\"]],\"asks\":[]}]}"}
{"local_receipt_timestamp_ns":1704067200000000823,"raw_payload":"{\"arg\":{\"channel\":\"books\",\"instId\":\"BTC-USDT\"},\"data\":[{\"ts\":\"1704067200082\",\"seqId\":82,\"prevSeqId\":81,\"bids\":[],\"asks\":[[\"50001.0\",\"1.00000000\",\"0\",\"1\"]]}]}"}
{"local_receipt_timestamp_ns":1704067200000000833,"raw_payload":"{\"arg\":{\"channel\":\"books\",\"instId\":\"BTC-USDT\"},\"data\":[{\"ts\":\"1704067200083\",\"seqId\":83,\"prevSeqId\":82,\"bids\":[[\"50000.0\",\"1.00000000\",\"0\",\"1\"]],\"asks\":[]}]}"}
{"local_receipt_timestamp_ns":1704067200000000843,"raw_payload":"{\"arg\":{\"channel\":\"books\",\"instId\":\"BTC-USDT\"},\"data\":[{\"ts\":\"1704067200084\",\"seqId\":84,\"prevSeqId\":83,\"bids\":[],\"asks\":[[\"50001.0\",\"1.00000000\",\"0\",\"1\"]]}]}"}
{"local_receipt_timestamp_ns":1704067200000000853,"raw_payload":"{\"arg\":{\"channel\":\"books\",\"instId\":\"BTC-USDT\"},\"data\":[{\"ts\":\"1704067200085\",\"seqId\":85,\"prevSeqId\":84,\"bids\":[[\"50000.0\",\"1.00000000\",\"0\",\"1\"]],\"asks\":[]}]}"}
{"local_receipt_timestamp_ns":1704067200000000863,"raw_payload":"{\"arg\":{\"channel\":\"books\",\"instId\":\"BTC-USDT\"},\"data\":[{\"ts\":\"1704067200086\",\"seqId\":86,\"prevSeqId\":85,\"bids\":[],\"asks\":[[\"50001.0\",\"1.00000000\",\"0\",\"1\"]]}]}"}
{"local_receipt_timestamp_ns":1704067200000000873,"raw_payload":"{\"arg\":{\"channel\":\"books\",\"instId\":\"BTC-USDT\"},\"data\":[{\"ts\":\"1704067200087\",\"seqId\":87,\"prevSeqId\":86,\"bids\":[[\"50000.0\",\"1.00000000\",\"0\",\"1\"]],\"asks\":[]}]}"}
{"local_receipt_timestamp_ns":1704067200000000883,"raw_payload":"{\"arg\":{\"channel\":\"books\",\"instId\":\"BTC-USDT\"},\"data\":[{\"ts\":\"1704067200088\",\"seqId\":88,\"prevSeqId\":87,\"bids\":[],\"asks\":[[\"50001.0\",\"1.00000000\",\"0\",\"1\"]]}]}"}
{"local_receipt_timestamp_ns":1704067200000000893,"raw_payload":"{\"arg\":{\"channel\":\"books\",\"instId\":\"BTC-USDT\"},\"data\":[{\"ts\":\"1704067200089\",\"seqId\":89,\"prevSeqId\":88,\"bids\":[[\"50000.0\",\"1.00000000\",\"0\",\"1\"]],\"asks\":[]}]}"}
{"local_receipt_timestamp_ns":1704067200000000903,"raw_payload":"{\"arg\":{\"channel\":\"books\",\"instId\":\"BTC-USDT\"},\"data\":[{\"ts\":\"1704067200090\",\"seqId\":90,\"prevSeqId\":89,\"bids\":[],\"asks\":[[\"50001.0\",\"1.00000000\",\"0\",\"1\"]]}]}"}
{"local_receipt_timestamp_ns":1704067200000000913,"raw_payload":"{\"arg\":{\"channel\":\"books\",\"instId\":\"BTC-USDT\"},\"data\":[{\"ts\":\"1704067200091\",\"seqId\":91,\"prevSeqId\":90,\"bids\":[[\"50000.0\",\"1.00000000\",\"0\",\"1\"]],\"asks\":[]}]}"}
{"local_receipt_timestamp_ns":1704067200000000923,"raw_payload":"{\"arg\":{\"channel\":\"books\",\"instId\":\"BTC-USDT\"},\"data\":[{\"ts\":\"1704067200092\",\"seqId\":92,\"prevSeqId\":91,\"bids\":[],\"asks\":[[\"50001.0\",\"1.00000000\",\"0\",\"1\"]]}]}"}
{"local_receipt_timestamp_ns":1704067200000000933,"raw_payload":"{\"arg\":{\"channel\":\"books\",\"instId\":\"BTC-USDT\"},\"data\":[{\"ts\":\"1704067200093\",\"seqId\":93,\"prevSeqId\":92,\"bids\":[[\"50000.0\",\"1.00000000\",\"0\",\"1\"]],\"asks\":[]}]}"}
{"local_receipt_timestamp_ns":1704067200000000943,"raw_payload":"{\"arg\":{\"channel\":\"books\",\"instId\":\"BTC-USDT\"},\"data\":[{\"ts\":\"1704067200094\",\"seqId\":94,\"prevSeqId\":93,\"bids\":[],\"asks\":[[\"50001.0\",\"1.00000000\",\"0\",\"1\"]]}]}"}
{"local_receipt_timestamp_ns":1704067200000000953,"raw_payload":"{\"arg\":{\"channel\":\"books\",\"instId\":\"BTC-USDT\"},\"data\":[{\"ts\":\"1704067200095\",\"seqId\":95,\"prevSeqId\":94,\"bids\":[[\"50000.0\",\"1.00000000\",\"0\",\"1\"]],\"asks\":[]}]}"}
{"local_receipt_timestamp_ns":1704067200000000963,"raw_payload":"{\"arg\":{\"channel\":\"books\",\"instId\":\"BTC-USDT\"},\"data\":[{\"ts\":\"1704067200096\",\"seqId\":96,\"prevSeqId\":95,\"bids\":[],\"asks\":[[\"50001.0\",\"1.00000000\",\"0\",\"1\"]]}]}"}
{"local_receipt_timestamp_ns":1704067200000000973,"raw_payload":"{\"arg\":{\"channel\":\"books\",\"instId\":\"BTC-USDT\"},\"data\":[{\"ts\":\"1704067200097\",\"seqId\":97,\"prevSeqId\":96,\"bids\":[[\"50000.0\",\"1.00000000\",\"0\",\"1\"]],\"asks\":[]}]}"}
{"local_receipt_timestamp_ns":1704067200000000983,"raw_payload":"{\"arg\":{\"channel\":\"books\",\"instId\":\"BTC-USDT\"},\"data\":[{\"ts\":\"1704067200098\",\"seqId\":98,\"prevSeqId\":97,\"bids\":[],\"asks\":[[\"50001.0\",\"1.00000000\",\"0\",\"1\"]]}]}"}
{"local_receipt_timestamp_ns":1704067200000000993,"raw_payload":"{\"arg\":{\"channel\":\"books\",\"instId\":\"BTC-USDT\"},\"data\":[{\"ts\":\"1704067200099\",\"seqId\":99,\"prevSeqId\":98,\"bids\":[[\"50000.0\",\"1.00000000\",\"0\",\"1\"]],\"asks\":[]}]}"}
{"local_receipt_timestamp_ns":1704067200000001003,"raw_payload":"{\"arg\":{\"channel\":\"books\",\"instId\":\"BTC-USDT\"},\"data\":[{\"ts\":\"1704067200100\",\"seqId\":100,\"prevSeqId\":99,\"bids\":[],\"asks\":[[\"50001.0\",\"1.00000000\",\"0\",\"1\"]]}]}"}
{"local_receipt_timestamp_ns":1704067200000001013,"raw_payload":"{\"arg\":{\"channel\":\"books\",\"instId\":\"BTC-USDT\"},\"data\":[{\"ts\":\"1704067200101\",\"seqId\":101,\"prevSeqId\":100,\"bids\":[[\"50000.0\",\"1.00000000\",\"0\",\"1\"]],\"asks\":[]}]}"}
{"local_receipt_timestamp_ns":1704067200000001023,"raw_payload":"{\"arg\":{\"channel\":\"books\",\"instId\":\"BTC-USDT\"},\"data\":[{\"ts\":\"1704067200102\",\"seqId\":102,\"prevSeqId\":101,\"bids\":[],\"asks\":[[\"50001.0\",\"1.00000000\",\"0\",\"1\"]]}]}"}
{"local_receipt_timestamp_ns":1704067200000001033,"raw_payload":"{\"arg\":{\"channel\":\"books\",\"instId\":\"BTC-USDT\"},\"data\":[{\"ts\":\"1704067200103\",\"seqId\":103,\"prevSeqId\":102,\"bids\":[[\"50000.0\",\"1.00000000\",\"0\",\"1\"]],\"asks\":[]}]}"}
{"local_receipt_timestamp_ns":1704067200000001043,"raw_payload":"{\"arg\":{\"channel\":\"books\",\"instId\":\"BTC-USDT\"},\"data\":[{\"ts\":\"1704067200104\",\"seqId\":104,\"prevSeqId\":103,\"bids\":[],\"asks\":[[\"50001.0\",\"1.00000000\",\"0\",\"1\"]]}]}"}
{"local_receipt_timestamp_ns":1704067200000001053,"raw_payload":"{\"arg\":{\"channel\":\"books\",\"instId\":\"BTC-USDT\"},\"data\":[{\"ts\":\"1704067200105\",\"seqId\":105,\"prevSeqId\":104,\"bids\":[[\"50000.0\",\"1.00000000\",\"0\",\"1\"]],\"asks\":[]}]}"}
{"local_receipt_timestamp_ns":1704067200000001063,"raw_payload":"{\"arg\":{\"channel\":\"books\",\"instId\":\"BTC-USDT\"},\"data\":[{\"ts\":\"1704067200106\",\"seqId\":106,\"prevSeqId\":105,\"bids\":[],\"asks\":[[\"50001.0\",\"1.00000000\",\"0\",\"1\"]]}]}"}
{"local_receipt_timestamp_ns":1704067200000001073,"raw_payload":"{\"arg\":{\"channel\":\"books\",\"instId\":\"BTC-USDT\"},\"data\":[{\"ts\":\"1704067200107\",\"seqId\":107,\"prevSeqId\":106,\"bids\":[[\"50000.0\",\"1.00000000\",\"0\",\"1\"]],\"asks\":[]}]}"}
{"local_receipt_timestamp_ns":1704067200000001083,"raw_payload":"{\"arg\":{\"channel\":\"books\",\"instId\":\"BTC-USDT\"},\"data\":[{\"ts\":\"1704067200108\",\"seqId\":108,\"prevSeqId\":107,\"bids\":[],\"asks\":[[\"50001.0\",\"1.00000000\",\"0\",\"1\"]]}]}"}
{"local_receipt_timestamp_ns":1704067200000001093,"raw_payload":"{\"arg\":{\"channel\":\"books\",\"instId\":\"BTC-USDT\"},\"data\":[{\"ts\":\"1704067200109\",\"seqId\":109,\"prevSeqId\":108,\"bids\":[[\"50000.0\",\"1.00000000\",\"0\",\"1\"]],\"asks\":[]}]}"}
{"local_receipt_timestamp_ns":1704067200000001103,"raw_payload":"{\"arg\":{\"channel\":\"books\",\"instId\":\"BTC-USDT\"},\"data\":[{\"ts\":\"1704067200110\",\"seqId\":110,\"prevSeqId\":109,\"bids\":[],\"asks\":[[\"50001.0\",\"1.00000000\",\"0\",\"1\"]]}]}"}
{"local_receipt_timestamp_ns":1704067200000001113,"raw_payload":"{\"arg\":{\"channel\":\"books\",\"instId\":\"BTC-USDT\"},\"data\":[{\"ts\":\"1704067200111\",\"seqId\":111,\"prevSeqId\":110,\"bids\":[[\"50000.0\",\"1.00000000\",\"0\",\"1\"]],\"asks\":[]}]}"}
{"local_receipt_timestamp_ns":1704067200000001123,"raw_payload":"{\"arg\":{\"channel\":\"books\",\"instId\":\"BTC-USDT\"},\"data\":[{\"ts\":\"1704067200112\",\"seqId\":112,\"prevSeqId\":111,\"bids\":[],\"asks\":[[\"50001.0\",\"1.00000000\",\"0\",\"1\"]]}]}"}
{"local_receipt_timestamp_ns":1704067200000001133,"raw_payload":"{\"arg\":{\"channel\":\"books\",\"instId\":\"BTC-USDT\"},\"data\":[{\"ts\":\"1704067200113\",\"seqId\":113,\"prevSeqId\":112,\"bids\":[[\"50000.0\",\"1.00000000\",\"0\",\"1\"]],\"asks\":[]}]}"}
{"local_receipt_timestamp_ns":1704067200000001143,"raw_payload":"{\"arg\":{\"channel\":\"books\",\"instId\":\"BTC-USDT\"},\"data\":[{\"ts\":\"1704067200114\",\"seqId\":114,\"prevSeqId\":113,\"bids\":[],\"asks\":[[\"50001.0\",\"1.00000000\",\"0\",\"1\"]]}]}"}
{"local_receipt_timestamp_ns":1704067200000001153,"raw_payload":"{\"arg\":{\"channel\":\"books\",\"instId\":\"BTC-USDT\"},\"data\":[{\"ts\":\"1704067200115\",\"seqId\":115,\"prevSeqId\":114,\"bids\":[[\"50000.0\",\"1.00000000\",\"0\",\"1\"]],\"asks\":[]}]}"}
{"local_receipt_timestamp_ns":1704067200000001163,"raw_payload":"{\"arg\":{\"channel\":\"books\",\"instId\":\"BTC-USDT\"},\"data\":[{\"ts\":\"1704067200116\",\"seqId\":116,\"prevSeqId\":115,\"bids\":[],\"asks\":[[\"50001.0\",\"1.00000000\",\"0\",\"1\"]]}]}"}
{"local_receipt_timestamp_ns":1704067200000001173,"raw_payload":"{\"arg\":{\"channel\":\"books\",\"instId\":\"BTC-USDT\"},\"data\":[{\"ts\":\"1704067200117\",\"seqId\":117,\"prevSeqId\":116,\"bids\":[[\"50000.0\",\"1.00000000\",\"0\",\"1\"]],\"asks\":[]}]}"}
{"local_receipt_timestamp_ns":1704067200000001183,"raw_payload":"{\"arg\":{\"channel\":\"books\",\"instId\":\"BTC-USDT\"},\"data\":[{\"ts\":\"1704067200118\",\"seqId\":118,\"prevSeqId\":117,\"bids\":[],\"asks\":[[\"50001.0\",\"1.00000000\",\"0\",\"1\"]]}]}"}
{"local_receipt_timestamp_ns":1704067200000001193,"raw_payload":"{\"arg\":{\"channel\":\"books\",\"instId\":\"BTC-USDT\"},\"data\":[{\"ts\":\"1704067200119\",\"seqId\":119,\"prevSeqId\":118,\"bids\":[[\"50000.0\",\"1.00000000\",\"0\",\"1\"]],\"asks\":[]}]}"}
{"local_receipt_timestamp_ns":1704067200000001203,"raw_payload":"{\"arg\":{\"channel\":\"books\",\"instId\":\"BTC-USDT\"},\"data\":[{\"ts\":\"1704067200120\",\"seqId\":120,\"prevSeqId\":119,\"bids\":[],\"asks\":[[\"50001.0\",\"1.00000000\",\"0\",\"1\"]]}]}"}
{"local_receipt_timestamp_ns":1704067200000001213,"raw_payload":"{\"arg\":{\"channel\":\"books\",\"instId\":\"BTC-USDT\"},\"data\":[{\"ts\":\"1704067200121\",\"seqId\":121,\"prevSeqId\":120,\"bids\":[[\"50000.0\",\"1.00000000\",\"0\",\"1\"]],\"asks\":[]}]}"}
{"local_receipt_timestamp_ns":1704067200000001223,"raw_payload":"{\"arg\":{\"channel\":\"books\",\"instId\":\"BTC-USDT\"},\"data\":[{\"ts\":\"1704067200122\",\"seqId\":122,\"prevSeqId\":121,\"bids\":[],\"asks\":[[\"50001.0\",\"1.00000000\",\"0\",\"1\"]]}]}"}
{"local_receipt_timestamp_ns":1704067200000001233,"raw_payload":"{\"arg\":{\"channel\":\"books\",\"instId\":\"BTC-USDT\"},\"data\":[{\"ts\":\"1704067200123\",\"seqId\":123,\"prevSeqId\":122,\"bids\":[[\"50000.0\",\"1.00000000\",\"0\",\"1\"]],\"asks\":[]}]}"}
{"local_receipt_timestamp_ns":1704067200000001243,"raw_payload":"{\"arg\":{\"channel\":\"books\",\"instId\":\"BTC-USDT\"},\"data\":[{\"ts\":\"1704067200124\",\"seqId\":124,\"prevSeqId\":123,\"bids\":[],\"asks\":[[\"50001.0\",\"1.00000000\",\"0\",\"1\"]]}]}"}
{"local_receipt_timestamp_ns":1704067200000001253,"raw_payload":"{\"arg\":{\"channel\":\"books\",\"instId\":\"BTC-USDT\"},\"data\":[{\"ts\":\"1704067200125\",\"seqId\":125,\"prevSeqId\":124,\"bids\":[[\"50000.0\",\"1.00000000\",\"0\",\"1\"]],\"asks\":[]}]}"}
{"local_receipt_timestamp_ns":1704067200000001263,"raw_payload":"{\"arg\":{\"channel\":\"books\",\"instId\":\"BTC-USDT\"},\"data\":[{\"ts\":\"1704067200126\",\"seqId\":126,\"prevSeqId\":125,\"bids\":[],\"asks\":[[\"50001.0\",\"1.00000000\",\"0\",\"1\"]]}]}"}
{"local_receipt_timestamp_ns":1704067200000001273,"raw_payload":"{\"arg\":{\"channel\":\"books\",\"instId\":\"BTC-USDT\"},\"data\":[{\"ts\":\"1704067200127\",\"seqId\":127,\"prevSeqId\":126,\"bids\":[[\"50000.0\",\"1.00000000\",\"0\",\"1\"]],\"asks\":[]}]}"}
{"local_receipt_timestamp_ns":1704067200000001283,"raw_payload":"{\"arg\":{\"channel\":\"books\",\"instId\":\"BTC-USDT\"},\"data\":[{\"ts\":\"1704067200128\",\"seqId\":128,\"prevSeqId\":127,\"bids\":[],\"asks\":[[\"50001.0\",\"1.00000000\",\"0\",\"1\"]]}]}"}
{"local_receipt_timestamp_ns":1704067200000001293,"raw_payload":"{\"arg\":{\"channel\":\"books\",\"instId\":\"BTC-USDT\"},\"data\":[{\"ts\":\"1704067200129\",\"seqId\":129,\"prevSeqId\":128,\"bids\":[[\"50000.0\",\"1.00000000\",\"0\",\"1\"]],\"asks\":[]}]}"}
{"local_receipt_timestamp_ns":1704067200000001303,"raw_payload":"{\"arg\":{\"channel\":\"books\",\"instId\":\"BTC-USDT\"},\"data\":[{\"ts\":\"1704067200130\",\"seqId\":130,\"prevSeqId\":129,\"bids\":[],\"asks\":[[\"50001.0\",\"1.00000000\",\"0\",\"1\"]]}]}"}
{"local_receipt_timestamp_ns":1704067200000001313,"raw_payload":"{\"arg\":{\"channel\":\"books\",\"instId\":\"BTC-USDT\"},\"data\":[{\"ts\":\"1704067200131\",\"seqId\":131,\"prevSeqId\":130,\"bids\":[[\"50000.0\",\"1.00000000\",\"0\",\"1\"]],\"asks\":[]}]}"}
{"local_receipt_timestamp_ns":1704067200000001323,"raw_payload":"{\"arg\":{\"channel\":\"books\",\"instId\":\"BTC-USDT\"},\"data\":[{\"ts\":\"1704067200132\",\"seqId\":132,\"prevSeqId\":131,\"bids\":[],\"asks\":[[\"50001.0\",\"1.00000000\",\"0\",\"1\"]]}]}"}
{"local_receipt_timestamp_ns":1704067200000001333,"raw_payload":"{\"arg\":{\"channel\":\"books\",\"instId\":\"BTC-USDT\"},\"data\":[{\"ts\":\"1704067200133\",\"seqId\":133,\"prevSeqId\":132,\"bids\":[[\"50000.0\",\"1.00000000\",\"0\",\"1\"]],\"asks\":[]}]}"}
{"local_receipt_timestamp_ns":1704067200000001343,"raw_payload":"{\"arg\":{\"channel\":\"books\",\"instId\":\"BTC-USDT\"},\"data\":[{\"ts\":\"1704067200134\",\"seqId\":134,\"prevSeqId\":133,\"bids\":[],\"asks\":[[\"50001.0\",\"1.00000000\",\"0\",\"1\"]]}]}"}
{"local_receipt_timestamp_ns":1704067200000001353,"raw_payload":"{\"arg\":{\"channel\":\"books\",\"instId\":\"BTC-USDT\"},\"data\":[{\"ts\":\"1704067200135\",\"seqId\":135,\"prevSeqId\":134,\"bids\":[[\"50000.0\",\"1.00000000\",\"0\",\"1\"]],\"asks\":[]}]}"}
{"local_receipt_timestamp_ns":1704067200000001363,"raw_payload":"{\"arg\":{\"channel\":\"books\",\"instId\":\"BTC-USDT\"},\"data\":[{\"ts\":\"1704067200136\",\"seqId\":136,\"prevSeqId\":135,\"bids\":[],\"asks\":[[\"50001.0\",\"1.00000000\",\"0\",\"1\"]]}]}"}
{"local_receipt_timestamp_ns":1704067200000001373,"raw_payload":"{\"arg\":{\"channel\":\"books\",\"instId\":\"BTC-USDT\"},\"data\":[{\"ts\":\"1704067200137\",\"seqId\":137,\"prevSeqId\":136,\"bids\":[[\"50000.0\",\"1.00000000\",\"0\",\"1\"]],\"asks\":[]}]}"}
{"local_receipt_timestamp_ns":1704067200000001383,"raw_payload":"{\"arg\":{\"channel\":\"books\",\"instId\":\"BTC-USDT\"},\"data\":[{\"ts\":\"1704067200138\",\"seqId\":138,\"prevSeqId\":137,\"bids\":[],\"asks\":[[\"50001.0\",\"1.00000000\",\"0\",\"1\"]]}]}"}
{"local_receipt_timestamp_ns":1704067200000001393,"raw_payload":"{\"arg\":{\"channel\":\"books\",\"instId\":\"BTC-USDT\"},\"data\":[{\"ts\":\"1704067200139\",\"seqId\":139,\"prevSeqId\":138,\"bids\":[[\"50000.0\",\"1.00000000\",\"0\",\"1\"]],\"asks\":[]}]}"}
{"local_receipt_timestamp_ns":1704067200000001403,"raw_payload":"{\"arg\":{\"channel\":\"books\",\"instId\":\"BTC-USDT\"},\"data\":[{\"ts\":\"1704067200140\",\"seqId\":140,\"prevSeqId\":139,\"bids\":[],\"asks\":[[\"50001.0\",\"1.00000000\",\"0\",\"1\"]]}]}"}
{"local_receipt_timestamp_ns":1704067200000001413,"raw_payload":"{\"arg\":{\"channel\":\"books\",\"instId\":\"BTC-USDT\"},\"data\":[{\"ts\":\"1704067200141\",\"seqId\":141,\"prevSeqId\":140,\"bids\":[[\"50000.0\",\"1.00000000\",\"0\",\"1\"]],\"asks\":[]}]}"}
{"local_receipt_timestamp_ns":1704067200000001423,"raw_payload":"{\"arg\":{\"channel\":\"books\",\"instId\":\"BTC-USDT\"},\"data\":[{\"ts\":\"1704067200142\",\"seqId\":142,\"prevSeqId\":141,\"bids\":[],\"asks\":[[\"50001.0\",\"1.00000000\",\"0\",\"1\"]]}]}"}
{"local_receipt_timestamp_ns":1704067200000001433,"raw_payload":"{\"arg\":{\"channel\":\"books\",\"instId\":\"BTC-USDT\"},\"data\":[{\"ts\":\"1704067200143\",\"seqId\":143,\"prevSeqId\":142,\"bids\":[[\"50000.0\",\"1.00000000\",\"0\",\"1\"]],\"asks\":[]}]}"}
{"local_receipt_timestamp_ns":1704067200000001443,"raw_payload":"{\"arg\":{\"channel\":\"books\",\"instId\":\"BTC-USDT\"},\"data\":[{\"ts\":\"1704067200144\",\"seqId\":144,\"prevSeqId\":143,\"bids\":[],\"asks\":[[\"50001.0\",\"1.00000000\",\"0\",\"1\"]]}]}"}
{"local_receipt_timestamp_ns":1704067200000001453,"raw_payload":"{\"arg\":{\"channel\":\"books\",\"instId\":\"BTC-USDT\"},\"data\":[{\"ts\":\"1704067200145\",\"seqId\":145,\"prevSeqId\":144,\"bids\":[[\"50000.0\",\"1.00000000\",\"0\",\"1\"]],\"asks\":[]}]}"}
{"local_receipt_timestamp_ns":1704067200000001463,"raw_payload":"{\"arg\":{\"channel\":\"books\",\"instId\":\"BTC-USDT\"},\"data\":[{\"ts\":\"1704067200146\",\"seqId\":146,\"prevSeqId\":145,\"bids\":[],\"asks\":[[\"50001.0\",\"1.00000000\",\"0\",\"1\"]]}]}"}
{"local_receipt_timestamp_ns":1704067200000001473,"raw_payload":"{\"arg\":{\"channel\":\"books\",\"instId\":\"BTC-USDT\"},\"data\":[{\"ts\":\"1704067200147\",\"seqId\":147,\"prevSeqId\":146,\"bids\":[[\"50000.0\",\"1.00000000\",\"0\",\"1\"]],\"asks\":[]}]}"}
{"local_receipt_timestamp_ns":1704067200000001483,"raw_payload":"{\"arg\":{\"channel\":\"books\",\"instId\":\"BTC-USDT\"},\"data\":[{\"ts\":\"1704067200148\",\"seqId\":148,\"prevSeqId\":147,\"bids\":[],\"asks\":[[\"50001.0\",\"1.00000000\",\"0\",\"1\"]]}]}"}
{"local_receipt_timestamp_ns":1704067200000001493,"raw_payload":"{\"arg\":{\"channel\":\"books\",\"instId\":\"BTC-USDT\"},\"data\":[{\"ts\":\"1704067200149\",\"seqId\":149,\"prevSeqId\":148,\"bids\":[[\"50000.0\",\"1.00000000\",\"0\",\"1\"]],\"asks\":[]}]}"}
{"local_receipt_timestamp_ns":1704067200000001503,"raw_payload":"{\"arg\":{\"channel\":\"books\",\"instId\":\"BTC-USDT\"},\"data\":[{\"ts\":\"1704067200150\",\"seqId\":150,\"prevSeqId\":149,\"bids\":[],\"asks\":[[\"50001.0\",\"1.00000000\",\"0\",\"1\"]]}]}"}
{"local_receipt_timestamp_ns":1704067200000001513,"raw_payload":"{\"arg\":{\"channel\":\"books\",\"instId\":\"BTC-USDT\"},\"data\":[{\"ts\":\"1704067200151\",\"seqId\":151,\"prevSeqId\":150,\"bids\":[[\"50000.0\",\"1.00000000\",\"0\",\"1\"]],\"asks\":[]}]}"}
{"local_receipt_timestamp_ns":1704067200000001523,"raw_payload":"{\"arg\":{\"channel\":\"books\",\"instId\":\"BTC-USDT\"},\"data\":[{\"ts\":\"1704067200152\",\"seqId\":152,\"prevSeqId\":151,\"bids\":[],\"asks\":[[\"50001.0\",\"1.00000000\",\"0\",\"1\"]]}]}"}
{"local_receipt_timestamp_ns":1704067200000001533,"raw_payload":"{\"arg\":{\"channel\":\"books\",\"instId\":\"BTC-USDT\"},\"data\":[{\"ts\":\"1704067200153\",\"seqId\":153,\"prevSeqId\":152,\"bids\":[[\"50000.0\",\"1.00000000\",\"0\",\"1\"]],\"asks\":[]}]}"}
{"local_receipt_timestamp_ns":1704067200000001543,"raw_payload":"{\"arg\":{\"channel\":\"books\",\"instId\":\"BTC-USDT\"},\"data\":[{\"ts\":\"1704067200154\",\"seqId\":154,\"prevSeqId\":153,\"bids\":[],\"asks\":[[\"50001.0\",\"1.00000000\",\"0\",\"1\"]]}]}"}
{"local_receipt_timestamp_ns":1704067200000001553,"raw_payload":"{\"arg\":{\"channel\":\"books\",\"instId\":\"BTC-USDT\"},\"data\":[{\"ts\":\"1704067200155\",\"seqId\":155,\"prevSeqId\":154,\"bids\":[[\"50000.0\",\"1.00000000\",\"0\",\"1\"]],\"asks\":[]}]}"}
{"local_receipt_timestamp_ns":1704067200000001563,"raw_payload":"{\"arg\":{\"channel\":\"books\",\"instId\":\"BTC-USDT\"},\"data\":[{\"ts\":\"1704067200156\",\"seqId\":156,\"prevSeqId\":155,\"bids\":[],\"asks\":[[\"50001.0\",\"1.00000000\",\"0\",\"1\"]]}]}"}
{"local_receipt_timestamp_ns":1704067200000001573,"raw_payload":"{\"arg\":{\"channel\":\"books\",\"instId\":\"BTC-USDT\"},\"data\":[{\"ts\":\"1704067200157\",\"seqId\":157,\"prevSeqId\":156,\"bids\":[[\"50000.0\",\"1.00000000\",\"0\",\"1\"]],\"asks\":[]}]}"}
{"local_receipt_timestamp_ns":1704067200000001583,"raw_payload":"{\"arg\":{\"channel\":\"books\",\"instId\":\"BTC-USDT\"},\"data\":[{\"ts\":\"1704067200158\",\"seqId\":158,\"prevSeqId\":157,\"bids\":[],\"asks\":[[\"50001.0\",\"1.00000000\",\"0\",\"1\"]]}]}"}
{"local_receipt_timestamp_ns":1704067200000001593,"raw_payload":"{\"arg\":{\"channel\":\"books\",\"instId\":\"BTC-USDT\"},\"data\":[{\"ts\":\"1704067200159\",\"seqId\":159,\"prevSeqId\":158,\"bids\":[[\"50000.0\",\"1.00000000\",\"0\",\"1\"]],\"asks\":[]}]}"}
{"local_receipt_timestamp_ns":1704067200000001603,"raw_payload":"{\"arg\":{\"channel\":\"books\",\"instId\":\"BTC-USDT\"},\"data\":[{\"ts\":\"1704067200160\",\"seqId\":160,\"prevSeqId\":159,\"bids\":[],\"asks\":[[\"50001.0\",\"1.00000000\",\"0\",\"1\"]]}]}"}
{"local_receipt_timestamp_ns":1704067200000001613,"raw_payload":"{\"arg\":{\"channel\":\"books\",\"instId\":\"BTC-USDT\"},\"data\":[{\"ts\":\"1704067200161\",\"seqId\":161,\"prevSeqId\":160,\"bids\":[[\"50000.0\",\"1.00000000\",\"0\",\"1\"]],\"asks\":[]}]}"}
{"local_receipt_timestamp_ns":1704067200000001623,"raw_payload":"{\"arg\":{\"channel\":\"books\",\"instId\":\"BTC-USDT\"},\"data\":[{\"ts\":\"1704067200162\",\"seqId\":162,\"prevSeqId\":161,\"bids\":[],\"asks\":[[\"50001.0\",\"1.00000000\",\"0\",\"1\"]]}]}"}
{"local_receipt_timestamp_ns":1704067200000001633,"raw_payload":"{\"arg\":{\"channel\":\"books\",\"instId\":\"BTC-USDT\"},\"data\":[{\"ts\":\"1704067200163\",\"seqId\":163,\"prevSeqId\":162,\"bids\":[[\"50000.0\",\"1.00000000\",\"0\",\"1\"]],\"asks\":[]}]}"}
{"local_receipt_timestamp_ns":1704067200000001643,"raw_payload":"{\"arg\":{\"channel\":\"books\",\"instId\":\"BTC-USDT\"},\"data\":[{\"ts\":\"1704067200164\",\"seqId\":164,\"prevSeqId\":163,\"bids\":[],\"asks\":[[\"50001.0\",\"1.00000000\",\"0\",\"1\"]]}]}"}
{"local_receipt_timestamp_ns":1704067200000001653,"raw_payload":"{\"arg\":{\"channel\":\"books\",\"instId\":\"BTC-USDT\"},\"data\":[{\"ts\":\"1704067200165\",\"seqId\":165,\"prevSeqId\":164,\"bids\":[[\"50000.0\",\"1.00000000\",\"0\",\"1\"]],\"asks\":[]}]}"}
{"local_receipt_timestamp_ns":1704067200000001663,"raw_payload":"{\"arg\":{\"channel\":\"books\",\"instId\":\"BTC-USDT\"},\"data\":[{\"ts\":\"1704067200166\",\"seqId\":166,\"prevSeqId\":165,\"bids\":[],\"asks\":[[\"50001.0\",\"1.00000000\",\"0\",\"1\"]]}]}"}
{"local_receipt_timestamp_ns":1704067200000001673,"raw_payload":"{\"arg\":{\"channel\":\"books\",\"instId\":\"BTC-USDT\"},\"data\":[{\"ts\":\"1704067200167\",\"seqId\":167,\"prevSeqId\":166,\"bids\":[[\"50000.0\",\"1.00000000\",\"0\",\"1\"]],\"asks\":[]}]}"}
{"local_receipt_timestamp_ns":1704067200000001683,"raw_payload":"{\"arg\":{\"channel\":\"books\",\"instId\":\"BTC-USDT\"},\"data\":[{\"ts\":\"1704067200168\",\"seqId\":168,\"prevSeqId\":167,\"bids\":[],\"asks\":[[\"50001.0\",\"1.00000000\",\"0\",\"1\"]]}]}"}
{"local_receipt_timestamp_ns":1704067200000001693,"raw_payload":"{\"arg\":{\"channel\":\"books\",\"instId\":\"BTC-USDT\"},\"data\":[{\"ts\":\"1704067200169\",\"seqId\":169,\"prevSeqId\":168,\"bids\":[[\"50000.0\",\"1.00000000\",\"0\",\"1\"]],\"asks\":[]}]}"}
{"local_receipt_timestamp_ns":1704067200000001703,"raw_payload":"{\"arg\":{\"channel\":\"books\",\"instId\":\"BTC-USDT\"},\"data\":[{\"ts\":\"1704067200170\",\"seqId\":170,\"prevSeqId\":169,\"bids\":[],\"asks\":[[\"50001.0\",\"1.00000000\",\"0\",\"1\"]]}]}"}
{"local_receipt_timestamp_ns":1704067200000001713,"raw_payload":"{\"arg\":{\"channel\":\"books\",\"instId\":\"BTC-USDT\"},\"data\":[{\"ts\":\"1704067200171\",\"seqId\":171,\"prevSeqId\":170,\"bids\":[[\"50000.0\",\"1.00000000\",\"0\",\"1\"]],\"asks\":[]}]}"}
{"local_receipt_timestamp_ns":1704067200000001723,"raw_payload":"{\"arg\":{\"channel\":\"books\",\"instId\":\"BTC-USDT\"},\"data\":[{\"ts\":\"1704067200172\",\"seqId\":172,\"prevSeqId\":171,\"bids\":[],\"asks\":[[\"50001.0\",\"1.00000000\",\"0\",\"1\"]]}]}"}
{"local_receipt_timestamp_ns":1704067200000001733,"raw_payload":"{\"arg\":{\"channel\":\"books\",\"instId\":\"BTC-USDT\"},\"data\":[{\"ts\":\"1704067200173\",\"seqId\":173,\"prevSeqId\":172,\"bids\":[[\"50000.0\",\"1.00000000\",\"0\",\"1\"]],\"asks\":[]}]}"}
{"local_receipt_timestamp_ns":1704067200000001743,"raw_payload":"{\"arg\":{\"channel\":\"books\",\"instId\":\"BTC-USDT\"},\"data\":[{\"ts\":\"1704067200174\",\"seqId\":174,\"prevSeqId\":173,\"bids\":[],\"asks\":[[\"50001.0\",\"1.00000000\",\"0\",\"1\"]]}]}"}
{"local_receipt_timestamp_ns":1704067200000001753,"raw_payload":"{\"arg\":{\"channel\":\"books\",\"instId\":\"BTC-USDT\"},\"data\":[{\"ts\":\"1704067200175\",\"seqId\":175,\"prevSeqId\":174,\"bids\":[[\"50000.0\",\"1.00000000\",\"0\",\"1\"]],\"asks\":[]}]}"}
{"local_receipt_timestamp_ns":1704067200000001763,"raw_payload":"{\"arg\":{\"channel\":\"books\",\"instId\":\"BTC-USDT\"},\"data\":[{\"ts\":\"1704067200176\",\"seqId\":176,\"prevSeqId\":175,\"bids\":[],\"asks\":[[\"50001.0\",\"1.00000000\",\"0\",\"1\"]]}]}"}
{"local_receipt_timestamp_ns":1704067200000001773,"raw_payload":"{\"arg\":{\"channel\":\"books\",\"instId\":\"BTC-USDT\"},\"data\":[{\"ts\":\"1704067200177\",\"seqId\":177,\"prevSeqId\":176,\"bids\":[[\"50000.0\",\"1.00000000\",\"0\",\"1\"]],\"asks\":[]}]}"}
{"local_receipt_timestamp_ns":1704067200000001783,"raw_payload":"{\"arg\":{\"channel\":\"books\",\"instId\":\"BTC-USDT\"},\"data\":[{\"ts\":\"1704067200178\",\"seqId\":178,\"prevSeqId\":177,\"bids\":[],\"asks\":[[\"50001.0\",\"1.00000000\",\"0\",\"1\"]]}]}"}
{"local_receipt_timestamp_ns":1704067200000001793,"raw_payload":"{\"arg\":{\"channel\":\"books\",\"instId\":\"BTC-USDT\"},\"data\":[{\"ts\":\"1704067200179\",\"seqId\":179,\"prevSeqId\":178,\"bids\":[[\"50000.0\",\"1.00000000\",\"0\",\"1\"]],\"asks\":[]}]}"}
{"local_receipt_timestamp_ns":1704067200000001803,"raw_payload":"{\"arg\":{\"channel\":\"books\",\"instId\":\"BTC-USDT\"},\"data\":[{\"ts\":\"1704067200180\",\"seqId\":180,\"prevSeqId\":179,\"bids\":[],\"asks\":[[\"50001.0\",\"1.00000000\",\"0\",\"1\"]]}]}"}
{"local_receipt_timestamp_ns":1704067200000001813,"raw_payload":"{\"arg\":{\"channel\":\"books\",\"instId\":\"BTC-USDT\"},\"data\":[{\"ts\":\"1704067200181\",\"seqId\":181,\"prevSeqId\":180,\"bids\":[[\"50000.0\",\"1.00000000\",\"0\",\"1\"]],\"asks\":[]}]}"}
{"local_receipt_timestamp_ns":1704067200000001823,"raw_payload":"{\"arg\":{\"channel\":\"books\",\"instId\":\"BTC-USDT\"},\"data\":[{\"ts\":\"1704067200182\",\"seqId\":182,\"prevSeqId\":181,\"bids\":[],\"asks\":[[\"50001.0\",\"1.00000000\",\"0\",\"1\"]]}]}"}
{"local_receipt_timestamp_ns":1704067200000001833,"raw_payload":"{\"arg\":{\"channel\":\"books\",\"instId\":\"BTC-USDT\"},\"data\":[{\"ts\":\"1704067200183\",\"seqId\":183,\"prevSeqId\":182,\"bids\":[[\"50000.0\",\"1.00000000\",\"0\",\"1\"]],\"asks\":[]}]}"}
{"local_receipt_timestamp_ns":1704067200000001843,"raw_payload":"{\"arg\":{\"channel\":\"books\",\"instId\":\"BTC-USDT\"},\"data\":[{\"ts\":\"1704067200184\",\"seqId\":184,\"prevSeqId\":183,\"bids\":[],\"asks\":[[\"50001.0\",\"1.00000000\",\"0\",\"1\"]]}]}"}
{"local_receipt_timestamp_ns":1704067200000001853,"raw_payload":"{\"arg\":{\"channel\":\"books\",\"instId\":\"BTC-USDT\"},\"data\":[{\"ts\":\"1704067200185\",\"seqId\":185,\"prevSeqId\":184,\"bids\":[[\"50000.0\",\"1.00000000\",\"0\",\"1\"]],\"asks\":[]}]}"}
{"local_receipt_timestamp_ns":1704067200000001863,"raw_payload":"{\"arg\":{\"channel\":\"books\",\"instId\":\"BTC-USDT\"},\"data\":[{\"ts\":\"1704067200186\",\"seqId\":186,\"prevSeqId\":185,\"bids\":[],\"asks\":[[\"50001.0\",\"1.00000000\",\"0\",\"1\"]]}]}"}
{"local_receipt_timestamp_ns":1704067200000001873,"raw_payload":"{\"arg\":{\"channel\":\"books\",\"instId\":\"BTC-USDT\"},\"data\":[{\"ts\":\"1704067200187\",\"seqId\":187,\"prevSeqId\":186,\"bids\":[[\"50000.0\",\"1.00000000\",\"0\",\"1\"]],\"asks\":[]}]}"}
{"local_receipt_timestamp_ns":1704067200000001883,"raw_payload":"{\"arg\":{\"channel\":\"books\",\"instId\":\"BTC-USDT\"},\"data\":[{\"ts\":\"1704067200188\",\"seqId\":188,\"prevSeqId\":187,\"bids\":[],\"asks\":[[\"50001.0\",\"1.00000000\",\"0\",\"1\"]]}]}"}
{"local_receipt_timestamp_ns":1704067200000001893,"raw_payload":"{\"arg\":{\"channel\":\"books\",\"instId\":\"BTC-USDT\"},\"data\":[{\"ts\":\"1704067200189\",\"seqId\":189,\"prevSeqId\":188,\"bids\":[[\"50000.0\",\"1.00000000\",\"0\",\"1\"]],\"asks\":[]}]}"}
{"local_receipt_timestamp_ns":1704067200000001903,"raw_payload":"{\"arg\":{\"channel\":\"books\",\"instId\":\"BTC-USDT\"},\"data\":[{\"ts\":\"1704067200190\",\"seqId\":190,\"prevSeqId\":189,\"bids\":[],\"asks\":[[\"50001.0\",\"1.00000000\",\"0\",\"1\"]]}]}"}
{"local_receipt_timestamp_ns":1704067200000001913,"raw_payload":"{\"arg\":{\"channel\":\"books\",\"instId\":\"BTC-USDT\"},\"data\":[{\"ts\":\"1704067200191\",\"seqId\":191,\"prevSeqId\":190,\"bids\":[[\"50000.0\",\"1.00000000\",\"0\",\"1\"]],\"asks\":[]}]}"}
{"local_receipt_timestamp_ns":1704067200000001923,"raw_payload":"{\"arg\":{\"channel\":\"books\",\"instId\":\"BTC-USDT\"},\"data\":[{\"ts\":\"1704067200192\",\"seqId\":192,\"prevSeqId\":191,\"bids\":[],\"asks\":[[\"50001.0\",\"1.00000000\",\"0\",\"1\"]]}]}"}
{"local_receipt_timestamp_ns":1704067200000001933,"raw_payload":"{\"arg\":{\"channel\":\"books\",\"instId\":\"BTC-USDT\"},\"data\":[{\"ts\":\"1704067200193\",\"seqId\":193,\"prevSeqId\":192,\"bids\":[[\"50000.0\",\"1.00000000\",\"0\",\"1\"]],\"asks\":[]}]}"}
{"local_receipt_timestamp_ns":1704067200000001943,"raw_payload":"{\"arg\":{\"channel\":\"books\",\"instId\":\"BTC-USDT\"},\"data\":[{\"ts\":\"1704067200194\",\"seqId\":194,\"prevSeqId\":193,\"bids\":[],\"asks\":[[\"50001.0\",\"1.00000000\",\"0\",\"1\"]]}]}"}
{"local_receipt_timestamp_ns":1704067200000001953,"raw_payload":"{\"arg\":{\"channel\":\"books\",\"instId\":\"BTC-USDT\"},\"data\":[{\"ts\":\"1704067200195\",\"seqId\":195,\"prevSeqId\":194,\"bids\":[[\"50000.0\",\"1.00000000\",\"0\",\"1\"]],\"asks\":[]}]}"}
{"local_receipt_timestamp_ns":1704067200000001963,"raw_payload":"{\"arg\":{\"channel\":\"books\",\"instId\":\"BTC-USDT\"},\"data\":[{\"ts\":\"1704067200196\",\"seqId\":196,\"prevSeqId\":195,\"bids\":[],\"asks\":[[\"50001.0\",\"1.00000000\",\"0\",\"1\"]]}]}"}
{"local_receipt_timestamp_ns":1704067200000001973,"raw_payload":"{\"arg\":{\"channel\":\"books\",\"instId\":\"BTC-USDT\"},\"data\":[{\"ts\":\"1704067200197\",\"seqId\":197,\"prevSeqId\":196,\"bids\":[[\"50000.0\",\"1.00000000\",\"0\",\"1\"]],\"asks\":[]}]}"}
{"local_receipt_timestamp_ns":1704067200000001983,"raw_payload":"{\"arg\":{\"channel\":\"books\",\"instId\":\"BTC-USDT\"},\"data\":[{\"ts\":\"1704067200198\",\"seqId\":198,\"prevSeqId\":197,\"bids\":[],\"asks\":[[\"50001.0\",\"1.00000000\",\"0\",\"1\"]]}]}"}
{"local_receipt_timestamp_ns":1704067200000001993,"raw_payload":"{\"arg\":{\"channel\":\"books\",\"instId\":\"BTC-USDT\"},\"data\":[{\"ts\":\"1704067200199\",\"seqId\":199,\"prevSeqId\":198,\"bids\":[[\"50000.0\",\"1.00000000\",\"0\",\"1\"]],\"asks\":[]}]}"}
{"local_receipt_timestamp_ns":1704067200000002003,"raw_payload":"{\"arg\":{\"channel\":\"books\",\"instId\":\"BTC-USDT\"},\"data\":[{\"ts\":\"1704067200200\",\"seqId\":200,\"prevSeqId\":199,\"bids\":[],\"asks\":[[\"50001.0\",\"1.00000000\",\"0\",\"1\"]]}]}"}
{"local_receipt_timestamp_ns":1704067200000002013,"raw_payload":"{\"arg\":{\"channel\":\"books\",\"instId\":\"BTC-USDT\"},\"data\":[{\"ts\":\"1704067200201\",\"seqId\":201,\"prevSeqId\":200,\"bids\":[[\"50000.0\",\"1.00000000\",\"0\",\"1\"]],\"asks\":[]}]}"}
{"local_receipt_timestamp_ns":1704067200000002023,"raw_payload":"{\"arg\":{\"channel\":\"books\",\"instId\":\"BTC-USDT\"},\"data\":[{\"ts\":\"1704067200202\",\"seqId\":202,\"prevSeqId\":201,\"bids\":[],\"asks\":[[\"50001.0\",\"1.00000000\",\"0\",\"1\"]]}]}"}
{"local_receipt_timestamp_ns":1704067200000002033,"raw_payload":"{\"arg\":{\"channel\":\"books\",\"instId\":\"BTC-USDT\"},\"data\":[{\"ts\":\"1704067200203\",\"seqId\":203,\"prevSeqId\":202,\"bids\":[[\"50000.0\",\"1.00000000\",\"0\",\"1\"]],\"asks\":[]}]}"}
{"local_receipt_timestamp_ns":1704067200000002043,"raw_payload":"{\"arg\":{\"channel\":\"books\",\"instId\":\"BTC-USDT\"},\"data\":[{\"ts\":\"1704067200204\",\"seqId\":204,\"prevSeqId\":203,\"bids\":[],\"asks\":[[\"50001.0\",\"1.00000000\",\"0\",\"1\"]]}]}"}
{"local_receipt_timestamp_ns":1704067200000002053,"raw_payload":"{\"arg\":{\"channel\":\"books\",\"instId\":\"BTC-USDT\"},\"data\":[{\"ts\":\"1704067200205\",\"seqId\":205,\"prevSeqId\":204,\"bids\":[[\"50000.0\",\"1.00000000\",\"0\",\"1\"]],\"asks\":[]}]}"}
{"local_receipt_timestamp_ns":1704067200000002063,"raw_payload":"{\"arg\":{\"channel\":\"books\",\"instId\":\"BTC-USDT\"},\"data\":[{\"ts\":\"1704067200206\",\"seqId\":206,\"prevSeqId\":205,\"bids\":[],\"asks\":[[\"50001.0\",\"1.00000000\",\"0\",\"1\"]]}]}"}
{"local_receipt_timestamp_ns":1704067200000002073,"raw_payload":"{\"arg\":{\"channel\":\"books\",\"instId\":\"BTC-USDT\"},\"data\":[{\"ts\":\"1704067200207\",\"seqId\":207,\"prevSeqId\":206,\"bids\":[[\"50000.0\",\"1.00000000\",\"0\",\"1\"]],\"asks\":[]}]}"}
{"local_receipt_timestamp_ns":1704067200000002083,"raw_payload":"{\"arg\":{\"channel\":\"books\",\"instId\":\"BTC-USDT\"},\"data\":[{\"ts\":\"1704067200208\",\"seqId\":208,\"prevSeqId\":207,\"bids\":[],\"asks\":[[\"50001.0\",\"1.00000000\",\"0\",\"1\"]]}]}"}
{"local_receipt_timestamp_ns":1704067200000002093,"raw_payload":"{\"arg\":{\"channel\":\"books\",\"instId\":\"BTC-USDT\"},\"data\":[{\"ts\":\"1704067200209\",\"seqId\":209,\"prevSeqId\":208,\"bids\":[[\"50000.0\",\"1.00000000\",\"0\",\"1\"]],\"asks\":[]}]}"}
{"local_receipt_timestamp_ns":1704067200000002103,"raw_payload":"{\"arg\":{\"channel\":\"books\",\"instId\":\"BTC-USDT\"},\"data\":[{\"ts\":\"1704067200210\",\"seqId\":210,\"prevSeqId\":209,\"bids\":[],\"asks\":[[\"50001.0\",\"1.00000000\",\"0\",\"1\"]]}]}"}
{"local_receipt_timestamp_ns":1704067200000002113,"raw_payload":"{\"arg\":{\"channel\":\"books\",\"instId\":\"BTC-USDT\"},\"data\":[{\"ts\":\"1704067200211\",\"seqId\":211,\"prevSeqId\":210,\"bids\":[[\"50000.0\",\"1.00000000\",\"0\",\"1\"]],\"asks\":[]}]}"}
{"local_receipt_timestamp_ns":1704067200000002123,"raw_payload":"{\"arg\":{\"channel\":\"books\",\"instId\":\"BTC-USDT\"},\"data\":[{\"ts\":\"1704067200212\",\"seqId\":212,\"prevSeqId\":211,\"bids\":[],\"asks\":[[\"50001.0\",\"1.00000000\",\"0\",\"1\"]]}]}"}
{"local_receipt_timestamp_ns":1704067200000002133,"raw_payload":"{\"arg\":{\"channel\":\"books\",\"instId\":\"BTC-USDT\"},\"data\":[{\"ts\":\"1704067200213\",\"seqId\":213,\"prevSeqId\":212,\"bids\":[[\"50000.0\",\"1.00000000\",\"0\",\"1\"]],\"asks\":[]}]}"}
{"local_receipt_timestamp_ns":1704067200000002143,"raw_payload":"{\"arg\":{\"channel\":\"books\",\"instId\":\"BTC-USDT\"},\"data\":[{\"ts\":\"1704067200214\",\"seqId\":214,\"prevSeqId\":213,\"bids\":[],\"asks\":[[\"50001.0\",\"1.00000000\",\"0\",\"1\"]]}]}"}
{"local_receipt_timestamp_ns":1704067200000002153,"raw_payload":"{\"arg\":{\"channel\":\"books\",\"instId\":\"BTC-USDT\"},\"data\":[{\"ts\":\"1704067200215\",\"seqId\":215,\"prevSeqId\":214,\"bids\":[[\"50000.0\",\"1.00000000\",\"0\",\"1\"]],\"asks\":[]}]}"}
{"local_receipt_timestamp_ns":1704067200000002163,"raw_payload":"{\"arg\":{\"channel\":\"books\",\"instId\":\"BTC-USDT\"},\"data\":[{\"ts\":\"1704067200216\",\"seqId\":216,\"prevSeqId\":215,\"bids\":[],\"asks\":[[\"50001.0\",\"1.00000000\",\"0\",\"1\"]]}]}"}
{"local_receipt_timestamp_ns":1704067200000002173,"raw_payload":"{\"arg\":{\"channel\":\"books\",\"instId\":\"BTC-USDT\"},\"data\":[{\"ts\":\"1704067200217\",\"seqId\":217,\"prevSeqId\":216,\"bids\":[[\"50000.0\",\"1.00000000\",\"0\",\"1\"]],\"asks\":[]}]}"}
{"local_receipt_timestamp_ns":1704067200000002183,"raw_payload":"{\"arg\":{\"channel\":\"books\",\"instId\":\"BTC-USDT\"},\"data\":[{\"ts\":\"1704067200218\",\"seqId\":218,\"prevSeqId\":217,\"bids\":[],\"asks\":[[\"50001.0\",\"1.00000000\",\"0\",\"1\"]]}]}"}
{"local_receipt_timestamp_ns":1704067200000002193,"raw_payload":"{\"arg\":{\"channel\":\"books\",\"instId\":\"BTC-USDT\"},\"data\":[{\"ts\":\"1704067200219\",\"seqId\":219,\"prevSeqId\":218,\"bids\":[[\"50000.0\",\"1.00000000\",\"0\",\"1\"]],\"asks\":[]}]}"}
{"local_receipt_timestamp_ns":1704067200000002203,"raw_payload":"{\"arg\":{\"channel\":\"books\",\"instId\":\"BTC-USDT\"},\"data\":[{\"ts\":\"1704067200220\",\"seqId\":220,\"prevSeqId\":219,\"bids\":[],\"asks\":[[\"50001.0\",\"1.00000000\",\"0\",\"1\"]]}]}"}
{"local_receipt_timestamp_ns":1704067200000002213,"raw_payload":"{\"arg\":{\"channel\":\"books\",\"instId\":\"BTC-USDT\"},\"data\":[{\"ts\":\"1704067200221\",\"seqId\":221,\"prevSeqId\":220,\"bids\":[[\"50000.0\",\"1.00000000\",\"0\",\"1\"]],\"asks\":[]}]}"}
{"local_receipt_timestamp_ns":1704067200000002223,"raw_payload":"{\"arg\":{\"channel\":\"books\",\"instId\":\"BTC-USDT\"},\"data\":[{\"ts\":\"1704067200222\",\"seqId\":222,\"prevSeqId\":221,\"bids\":[],\"asks\":[[\"50001.0\",\"1.00000000\",\"0\",\"1\"]]}]}"}
{"local_receipt_timestamp_ns":1704067200000002233,"raw_payload":"{\"arg\":{\"channel\":\"books\",\"instId\":\"BTC-USDT\"},\"data\":[{\"ts\":\"1704067200223\",\"seqId\":223,\"prevSeqId\":222,\"bids\":[[\"50000.0\",\"1.00000000\",\"0\",\"1\"]],\"asks\":[]}]}"}
{"local_receipt_timestamp_ns":1704067200000002243,"raw_payload":"{\"arg\":{\"channel\":\"books\",\"instId\":\"BTC-USDT\"},\"data\":[{\"ts\":\"1704067200224\",\"seqId\":224,\"prevSeqId\":223,\"bids\":[],\"asks\":[[\"50001.0\",\"1.00000000\",\"0\",\"1\"]]}]}"}
{"local_receipt_timestamp_ns":1704067200000002253,"raw_payload":"{\"arg\":{\"channel\":\"books\",\"instId\":\"BTC-USDT\"},\"data\":[{\"ts\":\"1704067200225\",\"seqId\":225,\"prevSeqId\":224,\"bids\":[[\"50000.0\",\"1.00000000\",\"0\",\"1\"]],\"asks\":[]}]}"}
{"local_receipt_timestamp_ns":1704067200000002263,"raw_payload":"{\"arg\":{\"channel\":\"books\",\"instId\":\"BTC-USDT\"},\"data\":[{\"ts\":\"1704067200226\",\"seqId\":226,\"prevSeqId\":225,\"bids\":[],\"asks\":[[\"50001.0\",\"1.00000000\",\"0\",\"1\"]]}]}"}
{"local_receipt_timestamp_ns":1704067200000002273,"raw_payload":"{\"arg\":{\"channel\":\"books\",\"instId\":\"BTC-USDT\"},\"data\":[{\"ts\":\"1704067200227\",\"seqId\":227,\"prevSeqId\":226,\"bids\":[[\"50000.0\",\"1.00000000\",\"0\",\"1\"]],\"asks\":[]}]}"}
{"local_receipt_timestamp_ns":1704067200000002283,"raw_payload":"{\"arg\":{\"channel\":\"books\",\"instId\":\"BTC-USDT\"},\"data\":[{\"ts\":\"1704067200228\",\"seqId\":228,\"prevSeqId\":227,\"bids\":[],\"asks\":[[\"50001.0\",\"1.00000000\",\"0\",\"1\"]]}]}"}
{"local_receipt_timestamp_ns":1704067200000002293,"raw_payload":"{\"arg\":{\"channel\":\"books\",\"instId\":\"BTC-USDT\"},\"data\":[{\"ts\":\"1704067200229\",\"seqId\":229,\"prevSeqId\":228,\"bids\":[[\"50000.0\",\"1.00000000\",\"0\",\"1\"]],\"asks\":[]}]}"}
{"local_receipt_timestamp_ns":1704067200000002303,"raw_payload":"{\"arg\":{\"channel\":\"books\",\"instId\":\"BTC-USDT\"},\"data\":[{\"ts\":\"1704067200230\",\"seqId\":230,\"prevSeqId\":229,\"bids\":[],\"asks\":[[\"50001.0\",\"1.00000000\",\"0\",\"1\"]]}]}"}
{"local_receipt_timestamp_ns":1704067200000002313,"raw_payload":"{\"arg\":{\"channel\":\"books\",\"instId\":\"BTC-USDT\"},\"data\":[{\"ts\":\"1704067200231\",\"seqId\":231,\"prevSeqId\":230,\"bids\":[[\"50000.0\",\"1.00000000\",\"0\",\"1\"]],\"asks\":[]}]}"}
{"local_receipt_timestamp_ns":1704067200000002323,"raw_payload":"{\"arg\":{\"channel\":\"books\",\"instId\":\"BTC-USDT\"},\"data\":[{\"ts\":\"1704067200232\",\"seqId\":232,\"prevSeqId\":231,\"bids\":[],\"asks\":[[\"50001.0\",\"1.00000000\",\"0\",\"1\"]]}]}"}
{"local_receipt_timestamp_ns":1704067200000002333,"raw_payload":"{\"arg\":{\"channel\":\"books\",\"instId\":\"BTC-USDT\"},\"data\":[{\"ts\":\"1704067200233\",\"seqId\":233,\"prevSeqId\":232,\"bids\":[[\"50000.0\",\"1.00000000\",\"0\",\"1\"]],\"asks\":[]}]}"}
{"local_receipt_timestamp_ns":1704067200000002343,"raw_payload":"{\"arg\":{\"channel\":\"books\",\"instId\":\"BTC-USDT\"},\"data\":[{\"ts\":\"1704067200234\",\"seqId\":234,\"prevSeqId\":233,\"bids\":[],\"asks\":[[\"50001.0\",\"1.00000000\",\"0\",\"1\"]]}]}"}
{"local_receipt_timestamp_ns":1704067200000002353,"raw_payload":"{\"arg\":{\"channel\":\"books\",\"instId\":\"BTC-USDT\"},\"data\":[{\"ts\":\"1704067200235\",\"seqId\":235,\"prevSeqId\":234,\"bids\":[[\"50000.0\",\"1.00000000\",\"0\",\"1\"]],\"asks\":[]}]}"}
{"local_receipt_timestamp_ns":1704067200000002363,"raw_payload":"{\"arg\":{\"channel\":\"books\",\"instId\":\"BTC-USDT\"},\"data\":[{\"ts\":\"1704067200236\",\"seqId\":236,\"prevSeqId\":235,\"bids\":[],\"asks\":[[\"50001.0\",\"1.00000000\",\"0\",\"1\"]]}]}"}
{"local_receipt_timestamp_ns":1704067200000002373,"raw_payload":"{\"arg\":{\"channel\":\"books\",\"instId\":\"BTC-USDT\"},\"data\":[{\"ts\":\"1704067200237\",\"seqId\":237,\"prevSeqId\":236,\"bids\":[[\"50000.0\",\"1.00000000\",\"0\",\"1\"]],\"asks\":[]}]}"}
{"local_receipt_timestamp_ns":1704067200000002383,"raw_payload":"{\"arg\":{\"channel\":\"books\",\"instId\":\"BTC-USDT\"},\"data\":[{\"ts\":\"1704067200238\",\"seqId\":238,\"prevSeqId\":237,\"bids\":[],\"asks\":[[\"50001.0\",\"1.00000000\",\"0\",\"1\"]]}]}"}
{"local_receipt_timestamp_ns":1704067200000002393,"raw_payload":"{\"arg\":{\"channel\":\"books\",\"instId\":\"BTC-USDT\"},\"data\":[{\"ts\":\"1704067200239\",\"seqId\":239,\"prevSeqId\":238,\"bids\":[[\"50000.0\",\"1.00000000\",\"0\",\"1\"]],\"asks\":[]}]}"}
{"local_receipt_timestamp_ns":1704067200000002403,"raw_payload":"{\"arg\":{\"channel\":\"books\",\"instId\":\"BTC-USDT\"},\"data\":[{\"ts\":\"1704067200240\",\"seqId\":240,\"prevSeqId\":239,\"bids\":[],\"asks\":[[\"50001.0\",\"1.00000000\",\"0\",\"1\"]]}]}"}
{"local_receipt_timestamp_ns":1704067200000002413,"raw_payload":"{\"arg\":{\"channel\":\"books\",\"instId\":\"BTC-USDT\"},\"data\":[{\"ts\":\"1704067200241\",\"seqId\":241,\"prevSeqId\":240,\"bids\":[[\"50000.0\",\"1.00000000\",\"0\",\"1\"]],\"asks\":[]}]}"}
{"local_receipt_timestamp_ns":1704067200000002423,"raw_payload":"{\"arg\":{\"channel\":\"books\",\"instId\":\"BTC-USDT\"},\"data\":[{\"ts\":\"1704067200242\",\"seqId\":242,\"prevSeqId\":241,\"bids\":[],\"asks\":[[\"50001.0\",\"1.00000000\",\"0\",\"1\"]]}]}"}
{"local_receipt_timestamp_ns":1704067200000002433,"raw_payload":"{\"arg\":{\"channel\":\"books\",\"instId\":\"BTC-USDT\"},\"data\":[{\"ts\":\"1704067200243\",\"seqId\":243,\"prevSeqId\":242,\"bids\":[[\"50000.0\",\"1.00000000\",\"0\",\"1\"]],\"asks\":[]}]}"}
{"local_receipt_timestamp_ns":1704067200000002443,"raw_payload":"{\"arg\":{\"channel\":\"books\",\"instId\":\"BTC-USDT\"},\"data\":[{\"ts\":\"1704067200244\",\"seqId\":244,\"prevSeqId\":243,\"bids\":[],\"asks\":[[\"50001.0\",\"1.00000000\",\"0\",\"1\"]]}]}"}
{"local_receipt_timestamp_ns":1704067200000002453,"raw_payload":"{\"arg\":{\"channel\":\"books\",\"instId\":\"BTC-USDT\"},\"data\":[{\"ts\":\"1704067200245\",\"seqId\":245,\"prevSeqId\":244,\"bids\":[[\"50000.0\",\"1.00000000\",\"0\",\"1\"]],\"asks\":[]}]}"}
{"local_receipt_timestamp_ns":1704067200000002463,"raw_payload":"{\"arg\":{\"channel\":\"books\",\"instId\":\"BTC-USDT\"},\"data\":[{\"ts\":\"1704067200246\",\"seqId\":246,\"prevSeqId\":245,\"bids\":[],\"asks\":[[\"50001.0\",\"1.00000000\",\"0\",\"1\"]]}]}"}
{"local_receipt_timestamp_ns":1704067200000002473,"raw_payload":"{\"arg\":{\"channel\":\"books\",\"instId\":\"BTC-USDT\"},\"data\":[{\"ts\":\"1704067200247\",\"seqId\":247,\"prevSeqId\":246,\"bids\":[[\"50000.0\",\"1.00000000\",\"0\",\"1\"]],\"asks\":[]}]}"}
{"local_receipt_timestamp_ns":1704067200000002483,"raw_payload":"{\"arg\":{\"channel\":\"books\",\"instId\":\"BTC-USDT\"},\"data\":[{\"ts\":\"1704067200248\",\"seqId\":248,\"prevSeqId\":247,\"bids\":[],\"asks\":[[\"50001.0\",\"1.00000000\",\"0\",\"1\"]]}]}"}
{"local_receipt_timestamp_ns":1704067200000002493,"raw_payload":"{\"arg\":{\"channel\":\"books\",\"instId\":\"BTC-USDT\"},\"data\":[{\"ts\":\"1704067200249\",\"seqId\":249,\"prevSeqId\":248,\"bids\":[[\"50000.0\",\"1.00000000\",\"0\",\"1\"]],\"asks\":[]}]}"}
{"local_receipt_timestamp_ns":1704067200000002503,"raw_payload":"{\"arg\":{\"channel\":\"books\",\"instId\":\"BTC-USDT\"},\"data\":[{\"ts\":\"1704067200250\",\"seqId\":250,\"prevSeqId\":249,\"bids\":[],\"asks\":[[\"50001.0\",\"1.00000000\",\"0\",\"1\"]]}]}"}
{"local_receipt_timestamp_ns":1704067200000002513,"raw_payload":"{\"arg\":{\"channel\":\"books\",\"instId\":\"BTC-USDT\"},\"data\":[{\"ts\":\"1704067200251\",\"seqId\":250,\"prevSeqId\":249,\"bids\":[],\"asks\":[[\"50001.0\",\"1.00000000\",\"0\",\"1\"]]}]}"}
{"local_receipt_timestamp_ns":1704067200000002523,"raw_payload":"{\"arg\":{\"channel\":\"books\",\"instId\":\"BTC-USDT\"},\"data\":[{\"ts\":\"1704067200252\",\"seqId\":249,\"prevSeqId\":248,\"bids\":[[\"50000.0\",\"1.00000000\",\"0\",\"1\"]],\"asks\":[]}]}"}
{"local_receipt_timestamp_ns":1704067200000002533,"raw_payload":"{\"arg\":{\"channel\":\"books\",\"instId\":\"BTC-USDT\"},\"data\":[{\"ts\":\"1704067200253\",\"seqId\":252,\"prevSeqId\":251,\"bids\":[],\"asks\":[[\"50001.0\",\"1.00000000\",\"0\",\"1\"]]}]}"}
{"local_receipt_timestamp_ns":1704067200000002543,"raw_payload":"{\"arg\":{\"channel\":\"books\",\"instId\":\"BTC-USDT\"},\"data\":[{\"ts\":\"1704067200254\",\"seqId\":253,\"prevSeqId\":252,\"bids\":[[\"50000.0\",\"1.00000000\",\"0\",\"1\"]],\"asks\":[]}]}"}
{"local_receipt_timestamp_ns":1704067200000002553,"raw_payload":"{\"arg\":{\"channel\":\"books\",\"instId\":\"BTC-USDT\"},\"data\":[{\"ts\":\"1704067200255\",\"seqId\":254,\"prevSeqId\":253,\"bids\":[],\"asks\":[[\"50001.0\",\"1.00000000\",\"0\",\"1\"]]}]}"}
{"local_receipt_timestamp_ns":1704067200000002563,"raw_payload":"{\"arg\":{\"channel\":\"books\",\"instId\":\"BTC-USDT\"},\"data\":[{\"ts\":\"1704067200256\",\"seqId\":255,\"prevSeqId\":254,\"bids\":[[\"50000.0\",\"1.00000000\",\"0\",\"1\"]],\"asks\":[]}]}"}
{"local_receipt_timestamp_ns":1704067200000002573,"raw_payload":"{\"arg\":{\"channel\":\"books\",\"instId\":\"BTC-USDT\"},\"data\":[{\"ts\":\"1704067200257\",\"seqId\":256,\"prevSeqId\":255,\"bids\":[],\"asks\":[[\"50001.0\",\"1.00000000\",\"0\",\"1\"]]}]}"}
{"local_receipt_timestamp_ns":1704067200000002583,"raw_payload":"{\"arg\":{\"channel\":\"books\",\"instId\":\"BTC-USDT\"},\"data\":[{\"ts\":\"1704067200258\",\"seqId\":257,\"prevSeqId\":256,\"bids\":[[\"50000.0\",\"1.00000000\",\"0\",\"1\"]],\"asks\":[]}]}"}
{"local_receipt_timestamp_ns":1704067200000002593,"raw_payload":"{\"arg\":{\"channel\":\"books\",\"instId\":\"BTC-USDT\"},\"data\":[{\"ts\":\"1704067200259\",\"seqId\":258,\"prevSeqId\":257,\"bids\":[],\"asks\":[[\"50001.0\",\"1.00000000\",\"0\",\"1\"]]}]}"}
{"local_receipt_timestamp_ns":1704067200000002603,"raw_payload":"{\"arg\":{\"channel\":\"books\",\"instId\":\"BTC-USDT\"},\"data\":[{\"ts\":\"1704067200260\",\"seqId\":259,\"prevSeqId\":258,\"bids\":[[\"50000.0\",\"1.00000000\",\"0\",\"1\"]],\"asks\":[]}]}"}
{"local_receipt_timestamp_ns":1704067200000002613,"raw_payload":"{\"arg\":{\"channel\":\"books\",\"instId\":\"BTC-USDT\"},\"data\":[{\"ts\":\"1704067200261\",\"seqId\":260,\"prevSeqId\":259,\"bids\":[],\"asks\":[[\"50001.0\",\"1.00000000\",\"0\",\"1\"]]}]}"}
{"local_receipt_timestamp_ns":1704067200000002623,"raw_payload":"{\"arg\":{\"channel\":\"books\",\"instId\":\"BTC-USDT\"},\"data\":[{\"ts\":\"1704067200262\",\"seqId\":261,\"prevSeqId\":260,\"bids\":[[\"50000.0\",\"1.00000000\",\"0\",\"1\"]],\"asks\":[]}]}"}
{"local_receipt_timestamp_ns":1704067200000002633,"raw_payload":"{\"arg\":{\"channel\":\"books\",\"instId\":\"BTC-USDT\"},\"data\":[{\"ts\":\"1704067200263\",\"seqId\":262,\"prevSeqId\":261,\"bids\":[],\"asks\":[[\"50001.0\",\"1.00000000\",\"0\",\"1\"]]}]}"}
{"local_receipt_timestamp_ns":1704067200000002643,"raw_payload":"{\"arg\":{\"channel\":\"books\",\"instId\":\"BTC-USDT\"},\"data\":[{\"ts\":\"1704067200264\",\"seqId\":263,\"prevSeqId\":262,\"bids\":[[\"50000.0\",\"1.00000000\",\"0\",\"1\"]],\"asks\":[]}]}"}
{"local_receipt_timestamp_ns":1704067200000002653,"raw_payload":"{\"arg\":{\"channel\":\"books\",\"instId\":\"BTC-USDT\"},\"data\":[{\"ts\":\"1704067200265\",\"seqId\":264,\"prevSeqId\":263,\"bids\":[],\"asks\":[[\"50001.0\",\"1.00000000\",\"0\",\"1\"]]}]}"}
{"local_receipt_timestamp_ns":1704067200000002663,"raw_payload":"{\"arg\":{\"channel\":\"books\",\"instId\":\"BTC-USDT\"},\"data\":[{\"ts\":\"1704067200266\",\"seqId\":265,\"prevSeqId\":264,\"bids\":[[\"50000.0\",\"1.00000000\",\"0\",\"1\"]],\"asks\":[]}]}"}
{"local_receipt_timestamp_ns":1704067200000002673,"raw_payload":"{\"arg\":{\"channel\":\"books\",\"instId\":\"BTC-USDT\"},\"data\":[{\"ts\":\"1704067200267\",\"seqId\":266,\"prevSeqId\":265,\"bids\":[],\"asks\":[[\"50001.0\",\"1.00000000\",\"0\",\"1\"]]}]}"}
{"local_receipt_timestamp_ns":1704067200000002683,"raw_payload":"{\"arg\":{\"channel\":\"books\",\"instId\":\"BTC-USDT\"},\"data\":[{\"ts\":\"1704067200268\",\"seqId\":267,\"prevSeqId\":266,\"bids\":[[\"50000.0\",\"1.00000000\",\"0\",\"1\"]],\"asks\":[]}]}"}
{"local_receipt_timestamp_ns":1704067200000002693,"raw_payload":"{\"arg\":{\"channel\":\"books\",\"instId\":\"BTC-USDT\"},\"data\":[{\"ts\":\"1704067200269\",\"seqId\":268,\"prevSeqId\":267,\"bids\":[],\"asks\":[[\"50001.0\",\"1.00000000\",\"0\",\"1\"]]}]}"}
{"local_receipt_timestamp_ns":1704067200000002703,"raw_payload":"{\"arg\":{\"channel\":\"books\",\"instId\":\"BTC-USDT\"},\"data\":[{\"ts\":\"1704067200270\",\"seqId\":269,\"prevSeqId\":268,\"bids\":[[\"50000.0\",\"1.00000000\",\"0\",\"1\"]],\"asks\":[]}]}"}
{"local_receipt_timestamp_ns":1704067200000002713,"raw_payload":"{\"arg\":{\"channel\":\"books\",\"instId\":\"BTC-USDT\"},\"data\":[{\"ts\":\"1704067200271\",\"seqId\":270,\"prevSeqId\":269,\"bids\":[],\"asks\":[[\"50001.0\",\"1.00000000\",\"0\",\"1\"]]}]}"}
{"local_receipt_timestamp_ns":1704067200000002723,"raw_payload":"{\"arg\":{\"channel\":\"books\",\"instId\":\"BTC-USDT\"},\"data\":[{\"ts\":\"1704067200272\",\"seqId\":271,\"prevSeqId\":270,\"bids\":[[\"50000.0\",\"1.00000000\",\"0\",\"1\"]],\"asks\":[]}]}"}
{"local_receipt_timestamp_ns":1704067200000002733,"raw_payload":"{\"arg\":{\"channel\":\"books\",\"instId\":\"BTC-USDT\"},\"data\":[{\"ts\":\"1704067200273\",\"seqId\":272,\"prevSeqId\":271,\"bids\":[],\"asks\":[[\"50001.0\",\"1.00000000\",\"0\",\"1\"]]}]}"}
{"local_receipt_timestamp_ns":1704067200000002743,"raw_payload":"{\"arg\":{\"channel\":\"books\",\"instId\":\"BTC-USDT\"},\"data\":[{\"ts\":\"1704067200274\",\"seqId\":273,\"prevSeqId\":272,\"bids\":[[\"50000.0\",\"1.00000000\",\"0\",\"1\"]],\"asks\":[]}]}"}
{"local_receipt_timestamp_ns":1704067200000002753,"raw_payload":"{\"arg\":{\"channel\":\"books\",\"instId\":\"BTC-USDT\"},\"data\":[{\"ts\":\"1704067200275\",\"seqId\":274,\"prevSeqId\":273,\"bids\":[],\"asks\":[[\"50001.0\",\"1.00000000\",\"0\",\"1\"]]}]}"}
{"local_receipt_timestamp_ns":1704067200000002763,"raw_payload":"{\"arg\":{\"channel\":\"books\",\"instId\":\"BTC-USDT\"},\"data\":[{\"ts\":\"1704067200276\",\"seqId\":275,\"prevSeqId\":274,\"bids\":[[\"50000.0\",\"1.00000000\",\"0\",\"1\"]],\"asks\":[]}]}"}
{"local_receipt_timestamp_ns":1704067200000002773,"raw_payload":"{\"arg\":{\"channel\":\"books\",\"instId\":\"BTC-USDT\"},\"data\":[{\"ts\":\"1704067200277\",\"seqId\":276,\"prevSeqId\":275,\"bids\":[],\"asks\":[[\"50001.0\",\"1.00000000\",\"0\",\"1\"]]}]}"}
{"local_receipt_timestamp_ns":1704067200000002783,"raw_payload":"{\"arg\":{\"channel\":\"books\",\"instId\":\"BTC-USDT\"},\"data\":[{\"ts\":\"1704067200278\",\"seqId\":277,\"prevSeqId\":276,\"bids\":[[\"50000.0\",\"1.00000000\",\"0\",\"1\"]],\"asks\":[]}]}"}
{"local_receipt_timestamp_ns":1704067200000002793,"raw_payload":"{\"arg\":{\"channel\":\"books\",\"instId\":\"BTC-USDT\"},\"data\":[{\"ts\":\"1704067200279\",\"seqId\":278,\"prevSeqId\":277,\"bids\":[],\"asks\":[[\"50001.0\",\"1.00000000\",\"0\",\"1\"]]}]}"}
{"local_receipt_timestamp_ns":1704067200000002803,"raw_payload":"{\"arg\":{\"channel\":\"books\",\"instId\":\"BTC-USDT\"},\"data\":[{\"ts\":\"1704067200280\",\"seqId\":279,\"prevSeqId\":278,\"bids\":[[\"50000.0\",\"1.00000000\",\"0\",\"1\"]],\"asks\":[]}]}"}
{"local_receipt_timestamp_ns":1704067200000002813,"raw_payload":"{\"arg\":{\"channel\":\"books\",\"instId\":\"BTC-USDT\"},\"data\":[{\"ts\":\"1704067200281\",\"seqId\":280,\"prevSeqId\":279,\"bids\":[],\"asks\":[[\"50001.0\",\"1.00000000\",\"0\",\"1\"]]}]}"}
{"local_receipt_timestamp_ns":1704067200000002823,"raw_payload":"{\"arg\":{\"channel\":\"books\",\"instId\":\"BTC-USDT\"},\"data\":[{\"ts\":\"1704067200282\",\"seqId\":281,\"prevSeqId\":280,\"bids\":[[\"50000.0\",\"1.00000000\",\"0\",\"1\"]],\"asks\":[]}]}"}
{"local_receipt_timestamp_ns":1704067200000002833,"raw_payload":"{\"arg\":{\"channel\":\"books\",\"instId\":\"BTC-USDT\"},\"data\":[{\"ts\":\"1704067200283\",\"seqId\":282,\"prevSeqId\":281,\"bids\":[],\"asks\":[[\"50001.0\",\"1.00000000\",\"0\",\"1\"]]}]}"}
{"local_receipt_timestamp_ns":1704067200000002843,"raw_payload":"{\"arg\":{\"channel\":\"books\",\"instId\":\"BTC-USDT\"},\"data\":[{\"ts\":\"1704067200284\",\"seqId\":283,\"prevSeqId\":282,\"bids\":[[\"50000.0\",\"1.00000000\",\"0\",\"1\"]],\"asks\":[]}]}"}
{"local_receipt_timestamp_ns":1704067200000002853,"raw_payload":"{\"arg\":{\"channel\":\"books\",\"instId\":\"BTC-USDT\"},\"data\":[{\"ts\":\"1704067200285\",\"seqId\":284,\"prevSeqId\":283,\"bids\":[],\"asks\":[[\"50001.0\",\"1.00000000\",\"0\",\"1\"]]}]}"}
{"local_receipt_timestamp_ns":1704067200000002863,"raw_payload":"{\"arg\":{\"channel\":\"books\",\"instId\":\"BTC-USDT\"},\"data\":[{\"ts\":\"1704067200286\",\"seqId\":285,\"prevSeqId\":284,\"bids\":[[\"50000.0\",\"1.00000000\",\"0\",\"1\"]],\"asks\":[]}]}"}
{"local_receipt_timestamp_ns":1704067200000002873,"raw_payload":"{\"arg\":{\"channel\":\"books\",\"instId\":\"BTC-USDT\"},\"data\":[{\"ts\":\"1704067200287\",\"seqId\":286,\"prevSeqId\":285,\"bids\":[],\"asks\":[[\"50001.0\",\"1.00000000\",\"0\",\"1\"]]}]}"}
{"local_receipt_timestamp_ns":1704067200000002883,"raw_payload":"{\"arg\":{\"channel\":\"books\",\"instId\":\"BTC-USDT\"},\"data\":[{\"ts\":\"1704067200288\",\"seqId\":287,\"prevSeqId\":286,\"bids\":[[\"50000.0\",\"1.00000000\",\"0\",\"1\"]],\"asks\":[]}]}"}
{"local_receipt_timestamp_ns":1704067200000002893,"raw_payload":"{\"arg\":{\"channel\":\"books\",\"instId\":\"BTC-USDT\"},\"data\":[{\"ts\":\"1704067200289\",\"seqId\":288,\"prevSeqId\":287,\"bids\":[],\"asks\":[[\"50001.0\",\"1.00000000\",\"0\",\"1\"]]}]}"}
{"local_receipt_timestamp_ns":1704067200000002903,"raw_payload":"{\"arg\":{\"channel\":\"books\",\"instId\":\"BTC-USDT\"},\"data\":[{\"ts\":\"1704067200290\",\"seqId\":289,\"prevSeqId\":288,\"bids\":[[\"50000.0\",\"1.00000000\",\"0\",\"1\"]],\"asks\":[]}]}"}
{"local_receipt_timestamp_ns":1704067200000002913,"raw_payload":"{\"arg\":{\"channel\":\"books\",\"instId\":\"BTC-USDT\"},\"data\":[{\"ts\":\"1704067200291\",\"seqId\":290,\"prevSeqId\":289,\"bids\":[],\"asks\":[[\"50001.0\",\"1.00000000\",\"0\",\"1\"]]}]}"}
{"local_receipt_timestamp_ns":1704067200000002923,"raw_payload":"{\"arg\":{\"channel\":\"books\",\"instId\":\"BTC-USDT\"},\"data\":[{\"ts\":\"1704067200292\",\"seqId\":291,\"prevSeqId\":290,\"bids\":[[\"50000.0\",\"1.00000000\",\"0\",\"1\"]],\"asks\":[]}]}"}
{"local_receipt_timestamp_ns":1704067200000002933,"raw_payload":"{\"arg\":{\"channel\":\"books\",\"instId\":\"BTC-USDT\"},\"data\":[{\"ts\":\"1704067200293\",\"seqId\":292,\"prevSeqId\":291,\"bids\":[],\"asks\":[[\"50001.0\",\"1.00000000\",\"0\",\"1\"]]}]}"}
{"local_receipt_timestamp_ns":1704067200000002943,"raw_payload":"{\"arg\":{\"channel\":\"books\",\"instId\":\"BTC-USDT\"},\"data\":[{\"ts\":\"1704067200294\",\"seqId\":293,\"prevSeqId\":292,\"bids\":[[\"50000.0\",\"1.00000000\",\"0\",\"1\"]],\"asks\":[]}]}"}
{"local_receipt_timestamp_ns":1704067200000002953,"raw_payload":"{\"arg\":{\"channel\":\"books\",\"instId\":\"BTC-USDT\"},\"data\":[{\"ts\":\"1704067200295\",\"seqId\":294,\"prevSeqId\":293,\"bids\":[],\"asks\":[[\"50001.0\",\"1.00000000\",\"0\",\"1\"]]}]}"}
{"local_receipt_timestamp_ns":1704067200000002963,"raw_payload":"{\"arg\":{\"channel\":\"books\",\"instId\":\"BTC-USDT\"},\"data\":[{\"ts\":\"1704067200296\",\"seqId\":295,\"prevSeqId\":294,\"bids\":[[\"50000.0\",\"1.00000000\",\"0\",\"1\"]],\"asks\":[]}]}"}
{"local_receipt_timestamp_ns":1704067200000002973,"raw_payload":"{\"arg\":{\"channel\":\"books\",\"instId\":\"BTC-USDT\"},\"data\":[{\"ts\":\"1704067200297\",\"seqId\":296,\"prevSeqId\":295,\"bids\":[],\"asks\":[[\"50001.0\",\"1.00000000\",\"0\",\"1\"]]}]}"}
{"local_receipt_timestamp_ns":1704067200000002983,"raw_payload":"{\"arg\":{\"channel\":\"books\",\"instId\":\"BTC-USDT\"},\"data\":[{\"ts\":\"1704067200298\",\"seqId\":297,\"prevSeqId\":296,\"bids\":[[\"50000.0\",\"1.00000000\",\"0\",\"1\"]],\"asks\":[]}]}"}
{"local_receipt_timestamp_ns":1704067200000002993,"raw_payload":"{\"arg\":{\"channel\":\"books\",\"instId\":\"BTC-USDT\"},\"data\":[{\"ts\":\"1704067200299\",\"seqId\":298,\"prevSeqId\":297,\"bids\":[],\"asks\":[[\"50001.0\",\"1.00000000\",\"0\",\"1\"]]}]}"}
{"local_receipt_timestamp_ns":1704067200000003003,"raw_payload":"{\"arg\":{\"channel\":\"books\",\"instId\":\"BTC-USDT\"},\"data\":[{\"ts\":\"1704067200300\",\"seqId\":299,\"prevSeqId\":298,\"bids\":[[\"50000.0\",\"1.00000000\",\"0\",\"1\"]],\"asks\":[]}]}"}
{"local_receipt_timestamp_ns":1704067200000003013,"raw_payload":"{\"arg\":{\"channel\":\"books\",\"instId\":\"BTC-USDT\"},\"data\":[{\"ts\":\"1704067200301\",\"seqId\":300,\"prevSeqId\":299,\"bids\":[],\"asks\":[[\"50001.0\",\"1.00000000\",\"0\",\"1\"]]}]}"}
{"local_receipt_timestamp_ns":1704067200000003023,"raw_payload":"{\"arg\":{\"channel\":\"books\",\"instId\":\"BTC-USDT\"},\"data\":[{\"ts\":\"1704067200302\",\"seqId\":301,\"prevSeqId\":300,\"bids\":[[\"50000.0\",\"1.00000000\",\"0\",\"1\"]],\"asks\":[]}]}"}
{"local_receipt_timestamp_ns":1704067200000003033,"raw_payload":"{\"arg\":{\"channel\":\"books\",\"instId\":\"BTC-USDT\"},\"data\":[{\"ts\":\"1704067200303\",\"seqId\":302,\"prevSeqId\":301,\"bids\":[],\"asks\":[[\"50001.0\",\"1.00000000\",\"0\",\"1\"]]}]}"}
{"local_receipt_timestamp_ns":1704067200000003043,"raw_payload":"{\"arg\":{\"channel\":\"books\",\"instId\":\"BTC-USDT\"},\"data\":[{\"ts\":\"1704067200304\",\"seqId\":303,\"prevSeqId\":302,\"bids\":[[\"50000.0\",\"1.00000000\",\"0\",\"1\"]],\"asks\":[]}]}"}
{"local_receipt_timestamp_ns":1704067200000003053,"raw_payload":"{\"arg\":{\"channel\":\"books\",\"instId\":\"BTC-USDT\"},\"data\":[{\"ts\":\"1704067200305\",\"seqId\":304,\"prevSeqId\":303,\"bids\":[],\"asks\":[[\"50001.0\",\"1.00000000\",\"0\",\"1\"]]}]}"}
{"local_receipt_timestamp_ns":1704067200000003063,"raw_payload":"{\"arg\":{\"channel\":\"books\",\"instId\":\"BTC-USDT\"},\"data\":[{\"ts\":\"1704067200306\",\"seqId\":305,\"prevSeqId\":304,\"bids\":[[\"50000.0\",\"1.00000000\",\"0\",\"1\"]],\"asks\":[]}]}"}
{"local_receipt_timestamp_ns":1704067200000003073,"raw_payload":"{\"arg\":{\"channel\":\"books\",\"instId\":\"BTC-USDT\"},\"data\":[{\"ts\":\"1704067200307\",\"seqId\":306,\"prevSeqId\":305,\"bids\":[],\"asks\":[[\"50001.0\",\"1.00000000\",\"0\",\"1\"]]}]}"}
{"local_receipt_timestamp_ns":1704067200000003083,"raw_payload":"{\"arg\":{\"channel\":\"books\",\"instId\":\"BTC-USDT\"},\"data\":[{\"ts\":\"1704067200308\",\"seqId\":307,\"prevSeqId\":306,\"bids\":[[\"50000.0\",\"1.00000000\",\"0\",\"1\"]],\"asks\":[]}]}"}
{"local_receipt_timestamp_ns":1704067200000003093,"raw_payload":"{\"arg\":{\"channel\":\"books\",\"instId\":\"BTC-USDT\"},\"data\":[{\"ts\":\"1704067200309\",\"seqId\":308,\"prevSeqId\":307,\"bids\":[],\"asks\":[[\"50001.0\",\"1.00000000\",\"0\",\"1\"]]}]}"}
{"local_receipt_timestamp_ns":1704067200000003103,"raw_payload":"{\"arg\":{\"channel\":\"books\",\"instId\":\"BTC-USDT\"},\"data\":[{\"ts\":\"1704067200310\",\"seqId\":309,\"prevSeqId\":308,\"bids\":[[\"50000.0\",\"1.00000000\",\"0\",\"1\"]],\"asks\":[]}]}"}
{"local_receipt_timestamp_ns":1704067200000003113,"raw_payload":"{\"arg\":{\"channel\":\"books\",\"instId\":\"BTC-USDT\"},\"data\":[{\"ts\":\"1704067200311\",\"seqId\":310,\"prevSeqId\":309,\"bids\":[],\"asks\":[[\"50001.0\",\"1.00000000\",\"0\",\"1\"]]}]}"}
{"local_receipt_timestamp_ns":1704067200000003123,"raw_payload":"{\"arg\":{\"channel\":\"books\",\"instId\":\"BTC-USDT\"},\"data\":[{\"ts\":\"1704067200312\",\"seqId\":311,\"prevSeqId\":310,\"bids\":[[\"50000.0\",\"1.00000000\",\"0\",\"1\"]],\"asks\":[]}]}"}
{"local_receipt_timestamp_ns":1704067200000003133,"raw_payload":"{\"arg\":{\"channel\":\"books\",\"instId\":\"BTC-USDT\"},\"data\":[{\"ts\":\"1704067200313\",\"seqId\":312,\"prevSeqId\":311,\"bids\":[],\"asks\":[[\"50001.0\",\"1.00000000\",\"0\",\"1\"]]}]}"}
{"local_receipt_timestamp_ns":1704067200000003143,"raw_payload":"{\"arg\":{\"channel\":\"books\",\"instId\":\"BTC-USDT\"},\"data\":[{\"ts\":\"1704067200314\",\"seqId\":313,\"prevSeqId\":312,\"bids\":[[\"50000.0\",\"1.00000000\",\"0\",\"1\"]],\"asks\":[]}]}"}
{"local_receipt_timestamp_ns":1704067200000003153,"raw_payload":"{\"arg\":{\"channel\":\"books\",\"instId\":\"BTC-USDT\"},\"data\":[{\"ts\":\"1704067200315\",\"seqId\":314,\"prevSeqId\":313,\"bids\":[],\"asks\":[[\"50001.0\",\"1.00000000\",\"0\",\"1\"]]}]}"}
{"local_receipt_timestamp_ns":1704067200000003163,"raw_payload":"{\"arg\":{\"channel\":\"books\",\"instId\":\"BTC-USDT\"},\"data\":[{\"ts\":\"1704067200316\",\"seqId\":315,\"prevSeqId\":314,\"bids\":[[\"50000.0\",\"1.00000000\",\"0\",\"1\"]],\"asks\":[]}]}"}
{"local_receipt_timestamp_ns":1704067200000003173,"raw_payload":"{\"arg\":{\"channel\":\"books\",\"instId\":\"BTC-USDT\"},\"data\":[{\"ts\":\"1704067200317\",\"seqId\":316,\"prevSeqId\":315,\"bids\":[],\"asks\":[[\"50001.0\",\"1.00000000\",\"0\",\"1\"]]}]}"}
{"local_receipt_timestamp_ns":1704067200000003183,"raw_payload":"{\"arg\":{\"channel\":\"books\",\"instId\":\"BTC-USDT\"},\"data\":[{\"ts\":\"1704067200318\",\"seqId\":317,\"prevSeqId\":316,\"bids\":[[\"50000.0\",\"1.00000000\",\"0\",\"1\"]],\"asks\":[]}]}"}
{"local_receipt_timestamp_ns":1704067200000003193,"raw_payload":"{\"arg\":{\"channel\":\"books\",\"instId\":\"BTC-USDT\"},\"data\":[{\"ts\":\"1704067200319\",\"seqId\":318,\"prevSeqId\":317,\"bids\":[],\"asks\":[[\"50001.0\",\"1.00000000\",\"0\",\"1\"]]}]}"}
{"local_receipt_timestamp_ns":1704067200000003203,"raw_payload":"{\"arg\":{\"channel\":\"books\",\"instId\":\"BTC-USDT\"},\"data\":[{\"ts\":\"1704067200320\",\"seqId\":319,\"prevSeqId\":318,\"bids\":[[\"50000.0\",\"1.00000000\",\"0\",\"1\"]],\"asks\":[]}]}"}
{"local_receipt_timestamp_ns":1704067200000003213,"raw_payload":"{\"arg\":{\"channel\":\"books\",\"instId\":\"BTC-USDT\"},\"data\":[{\"ts\":\"1704067200321\",\"seqId\":320,\"prevSeqId\":319,\"bids\":[],\"asks\":[[\"50001.0\",\"1.00000000\",\"0\",\"1\"]]}]}"}
{"local_receipt_timestamp_ns":1704067200000003223,"raw_payload":"{\"arg\":{\"channel\":\"books\",\"instId\":\"BTC-USDT\"},\"data\":[{\"ts\":\"1704067200322\",\"seqId\":321,\"prevSeqId\":320,\"bids\":[[\"50000.0\",\"1.00000000\",\"0\",\"1\"]],\"asks\":[]}]}"}
{"local_receipt_timestamp_ns":1704067200000003233,"raw_payload":"{\"arg\":{\"channel\":\"books\",\"instId\":\"BTC-USDT\"},\"data\":[{\"ts\":\"1704067200323\",\"seqId\":322,\"prevSeqId\":321,\"bids\":[],\"asks\":[[\"50001.0\",\"1.00000000\",\"0\",\"1\"]]}]}"}
{"local_receipt_timestamp_ns":1704067200000003243,"raw_payload":"{\"arg\":{\"channel\":\"books\",\"instId\":\"BTC-USDT\"},\"data\":[{\"ts\":\"1704067200324\",\"seqId\":323,\"prevSeqId\":322,\"bids\":[[\"50000.0\",\"1.00000000\",\"0\",\"1\"]],\"asks\":[]}]}"}
{"local_receipt_timestamp_ns":1704067200000003253,"raw_payload":"{\"arg\":{\"channel\":\"books\",\"instId\":\"BTC-USDT\"},\"data\":[{\"ts\":\"1704067200325\",\"seqId\":324,\"prevSeqId\":323,\"bids\":[],\"asks\":[[\"50001.0\",\"1.00000000\",\"0\",\"1\"]]}]}"}
{"local_receipt_timestamp_ns":1704067200000003263,"raw_payload":"{\"arg\":{\"channel\":\"books\",\"instId\":\"BTC-USDT\"},\"data\":[{\"ts\":\"1704067200326\",\"seqId\":325,\"prevSeqId\":324,\"bids\":[[\"50000.0\",\"1.00000000\",\"0\",\"1\"]],\"asks\":[]}]}"}
{"local_receipt_timestamp_ns":1704067200000003273,"raw_payload":"{\"arg\":{\"channel\":\"books\",\"instId\":\"BTC-USDT\"},\"data\":[{\"ts\":\"1704067200327\",\"seqId\":326,\"prevSeqId\":325,\"bids\":[],\"asks\":[[\"50001.0\",\"1.00000000\",\"0\",\"1\"]]}]}"}
{"local_receipt_timestamp_ns":1704067200000003283,"raw_payload":"{\"arg\":{\"channel\":\"books\",\"instId\":\"BTC-USDT\"},\"data\":[{\"ts\":\"1704067200328\",\"seqId\":327,\"prevSeqId\":326,\"bids\":[[\"50000.0\",\"1.00000000\",\"0\",\"1\"]],\"asks\":[]}]}"}
{"local_receipt_timestamp_ns":1704067200000003293,"raw_payload":"{\"arg\":{\"channel\":\"books\",\"instId\":\"BTC-USDT\"},\"data\":[{\"ts\":\"1704067200329\",\"seqId\":328,\"prevSeqId\":327,\"bids\":[],\"asks\":[[\"50001.0\",\"1.00000000\",\"0\",\"1\"]]}]}"}
{"local_receipt_timestamp_ns":1704067200000003303,"raw_payload":"{\"arg\":{\"channel\":\"books\",\"instId\":\"BTC-USDT\"},\"data\":[{\"ts\":\"1704067200330\",\"seqId\":329,\"prevSeqId\":328,\"bids\":[[\"50000.0\",\"1.00000000\",\"0\",\"1\"]],\"asks\":[]}]}"}
{"local_receipt_timestamp_ns":1704067200000003313,"raw_payload":"{\"arg\":{\"channel\":\"books\",\"instId\":\"BTC-USDT\"},\"data\":[{\"ts\":\"1704067200331\",\"seqId\":330,\"prevSeqId\":329,\"bids\":[],\"asks\":[[\"50001.0\",\"1.00000000\",\"0\",\"1\"]]}]}"}
{"local_receipt_timestamp_ns":1704067200000003323,"raw_payload":"{\"arg\":{\"channel\":\"books\",\"instId\":\"BTC-USDT\"},\"data\":[{\"ts\":\"1704067200332\",\"seqId\":331,\"prevSeqId\":330,\"bids\":[[\"50000.0\",\"1.00000000\",\"0\",\"1\"]],\"asks\":[]}]}"}
{"local_receipt_timestamp_ns":1704067200000003333,"raw_payload":"{\"arg\":{\"channel\":\"books\",\"instId\":\"BTC-USDT\"},\"data\":[{\"ts\":\"1704067200333\",\"seqId\":332,\"prevSeqId\":331,\"bids\":[],\"asks\":[[\"50001.0\",\"1.00000000\",\"0\",\"1\"]]}]}"}
{"local_receipt_timestamp_ns":1704067200000003343,"raw_payload":"{\"arg\":{\"channel\":\"books\",\"instId\":\"BTC-USDT\"},\"data\":[{\"ts\":\"1704067200334\",\"seqId\":333,\"prevSeqId\":332,\"bids\":[[\"50000.0\",\"1.00000000\",\"0\",\"1\"]],\"asks\":[]}]}"}
{"local_receipt_timestamp_ns":1704067200000003353,"raw_payload":"{\"arg\":{\"channel\":\"books\",\"instId\":\"BTC-USDT\"},\"data\":[{\"ts\":\"1704067200335\",\"seqId\":334,\"prevSeqId\":333,\"bids\":[],\"asks\":[[\"50001.0\",\"1.00000000\",\"0\",\"1\"]]}]}"}
{"local_receipt_timestamp_ns":1704067200000003363,"raw_payload":"{\"arg\":{\"channel\":\"books\",\"instId\":\"BTC-USDT\"},\"data\":[{\"ts\":\"1704067200336\",\"seqId\":335,\"prevSeqId\":334,\"bids\":[[\"50000.0\",\"1.00000000\",\"0\",\"1\"]],\"asks\":[]}]}"}
{"local_receipt_timestamp_ns":1704067200000003373,"raw_payload":"{\"arg\":{\"channel\":\"books\",\"instId\":\"BTC-USDT\"},\"data\":[{\"ts\":\"1704067200337\",\"seqId\":336,\"prevSeqId\":335,\"bids\":[],\"asks\":[[\"50001.0\",\"1.00000000\",\"0\",\"1\"]]}]}"}
{"local_receipt_timestamp_ns":1704067200000003383,"raw_payload":"{\"arg\":{\"channel\":\"books\",\"instId\":\"BTC-USDT\"},\"data\":[{\"ts\":\"1704067200338\",\"seqId\":337,\"prevSeqId\":336,\"bids\":[[\"50000.0\",\"1.00000000\",\"0\",\"1\"]],\"asks\":[]}]}"}
{"local_receipt_timestamp_ns":1704067200000003393,"raw_payload":"{\"arg\":{\"channel\":\"books\",\"instId\":\"BTC-USDT\"},\"data\":[{\"ts\":\"1704067200339\",\"seqId\":338,\"prevSeqId\":337,\"bids\":[],\"asks\":[[\"50001.0\",\"1.00000000\",\"0\",\"1\"]]}]}"}
{"local_receipt_timestamp_ns":1704067200000003403,"raw_payload":"{\"arg\":{\"channel\":\"books\",\"instId\":\"BTC-USDT\"},\"data\":[{\"ts\":\"1704067200340\",\"seqId\":339,\"prevSeqId\":338,\"bids\":[[\"50000.0\",\"1.00000000\",\"0\",\"1\"]],\"asks\":[]}]}"}
{"local_receipt_timestamp_ns":1704067200000003413,"raw_payload":"{\"arg\":{\"channel\":\"books\",\"instId\":\"BTC-USDT\"},\"data\":[{\"ts\":\"1704067200341\",\"seqId\":340,\"prevSeqId\":339,\"bids\":[],\"asks\":[[\"50001.0\",\"1.00000000\",\"0\",\"1\"]]}]}"}
{"local_receipt_timestamp_ns":1704067200000003423,"raw_payload":"{\"arg\":{\"channel\":\"books\",\"instId\":\"BTC-USDT\"},\"data\":[{\"ts\":\"1704067200342\",\"seqId\":341,\"prevSeqId\":340,\"bids\":[[\"50000.0\",\"1.00000000\",\"0\",\"1\"]],\"asks\":[]}]}"}
{"local_receipt_timestamp_ns":1704067200000003433,"raw_payload":"{\"arg\":{\"channel\":\"books\",\"instId\":\"BTC-USDT\"},\"data\":[{\"ts\":\"1704067200343\",\"seqId\":342,\"prevSeqId\":341,\"bids\":[],\"asks\":[[\"50001.0\",\"1.00000000\",\"0\",\"1\"]]}]}"}
{"local_receipt_timestamp_ns":1704067200000003443,"raw_payload":"{\"arg\":{\"channel\":\"books\",\"instId\":\"BTC-USDT\"},\"data\":[{\"ts\":\"1704067200344\",\"seqId\":343,\"prevSeqId\":342,\"bids\":[[\"50000.0\",\"1.00000000\",\"0\",\"1\"]],\"asks\":[]}]}"}
{"local_receipt_timestamp_ns":1704067200000003453,"raw_payload":"{\"arg\":{\"channel\":\"books\",\"instId\":\"BTC-USDT\"},\"data\":[{\"ts\":\"1704067200345\",\"seqId\":344,\"prevSeqId\":343,\"bids\":[],\"asks\":[[\"50001.0\",\"1.00000000\",\"0\",\"1\"]]}]}"}
{"local_receipt_timestamp_ns":1704067200000003463,"raw_payload":"{\"arg\":{\"channel\":\"books\",\"instId\":\"BTC-USDT\"},\"data\":[{\"ts\":\"1704067200346\",\"seqId\":345,\"prevSeqId\":344,\"bids\":[[\"50000.0\",\"1.00000000\",\"0\",\"1\"]],\"asks\":[]}]}"}
{"local_receipt_timestamp_ns":1704067200000003473,"raw_payload":"{\"arg\":{\"channel\":\"books\",\"instId\":\"BTC-USDT\"},\"data\":[{\"ts\":\"1704067200347\",\"seqId\":346,\"prevSeqId\":345,\"bids\":[],\"asks\":[[\"50001.0\",\"1.00000000\",\"0\",\"1\"]]}]}"}
{"local_receipt_timestamp_ns":1704067200000003483,"raw_payload":"{\"arg\":{\"channel\":\"books\",\"instId\":\"BTC-USDT\"},\"data\":[{\"ts\":\"1704067200348\",\"seqId\":347,\"prevSeqId\":346,\"bids\":[[\"50000.0\",\"1.00000000\",\"0\",\"1\"]],\"asks\":[]}]}"}
{"local_receipt_timestamp_ns":1704067200000003493,"raw_payload":"{\"arg\":{\"channel\":\"books\",\"instId\":\"BTC-USDT\"},\"data\":[{\"ts\":\"1704067200349\",\"seqId\":348,\"prevSeqId\":347,\"bids\":[],\"asks\":[[\"50001.0\",\"1.00000000\",\"0\",\"1\"]]}]}"}
{"local_receipt_timestamp_ns":1704067200000003503,"raw_payload":"{\"arg\":{\"channel\":\"books\",\"instId\":\"BTC-USDT\"},\"data\":[{\"ts\":\"1704067200350\",\"seqId\":349,\"prevSeqId\":348,\"bids\":[[\"50000.0\",\"1.00000000\",\"0\",\"1\"]],\"asks\":[]}]}"}
{"local_receipt_timestamp_ns":1704067200000003513,"raw_payload":"{\"arg\":{\"channel\":\"books\",\"instId\":\"BTC-USDT\"},\"data\":[{\"ts\":\"1704067200351\",\"seqId\":350,\"prevSeqId\":349,\"bids\":[],\"asks\":[[\"50001.0\",\"1.00000000\",\"0\",\"1\"]]}]}"}
{"local_receipt_timestamp_ns":1704067200000003523,"raw_payload":"{\"arg\":{\"channel\":\"books\",\"instId\":\"BTC-USDT\"},\"data\":[{\"ts\":\"1704067200352\",\"seqId\":351,\"prevSeqId\":350,\"bids\":[[\"50000.0\",\"1.00000000\",\"0\",\"1\"]],\"asks\":[]}]}"}
{"local_receipt_timestamp_ns":1704067200000003533,"raw_payload":"{\"arg\":{\"channel\":\"books\",\"instId\":\"BTC-USDT\"},\"data\":[{\"ts\":\"1704067200353\",\"seqId\":352,\"prevSeqId\":351,\"bids\":[],\"asks\":[[\"50001.0\",\"1.00000000\",\"0\",\"1\"]]}]}"}
{"local_receipt_timestamp_ns":1704067200000003543,"raw_payload":"{\"arg\":{\"channel\":\"books\",\"instId\":\"BTC-USDT\"},\"data\":[{\"ts\":\"1704067200354\",\"seqId\":353,\"prevSeqId\":352,\"bids\":[[\"50000.0\",\"1.00000000\",\"0\",\"1\"]],\"asks\":[]}]}"}
{"local_receipt_timestamp_ns":1704067200000003553,"raw_payload":"{\"arg\":{\"channel\":\"books\",\"instId\":\"BTC-USDT\"},\"data\":[{\"ts\":\"1704067200355\",\"seqId\":354,\"prevSeqId\":353,\"bids\":[],\"asks\":[[\"50001.0\",\"1.00000000\",\"0\",\"1\"]]}]}"}
{"local_receipt_timestamp_ns":1704067200000003563,"raw_payload":"{\"arg\":{\"channel\":\"books\",\"instId\":\"BTC-USDT\"},\"data\":[{\"ts\":\"1704067200356\",\"seqId\":355,\"prevSeqId\":354,\"bids\":[[\"50000.0\",\"1.00000000\",\"0\",\"1\"]],\"asks\":[]}]}"}
{"local_receipt_timestamp_ns":1704067200000003573,"raw_payload":"{\"arg\":{\"channel\":\"books\",\"instId\":\"BTC-USDT\"},\"data\":[{\"ts\":\"1704067200357\",\"seqId\":356,\"prevSeqId\":355,\"bids\":[],\"asks\":[[\"50001.0\",\"1.00000000\",\"0\",\"1\"]]}]}"}
{"local_receipt_timestamp_ns":1704067200000003583,"raw_payload":"{\"arg\":{\"channel\":\"books\",\"instId\":\"BTC-USDT\"},\"data\":[{\"ts\":\"1704067200358\",\"seqId\":357,\"prevSeqId\":356,\"bids\":[[\"50000.0\",\"1.00000000\",\"0\",\"1\"]],\"asks\":[]}]}"}
{"local_receipt_timestamp_ns":1704067200000003593,"raw_payload":"{\"arg\":{\"channel\":\"books\",\"instId\":\"BTC-USDT\"},\"data\":[{\"ts\":\"1704067200359\",\"seqId\":358,\"prevSeqId\":357,\"bids\":[],\"asks\":[[\"50001.0\",\"1.00000000\",\"0\",\"1\"]]}]}"}
{"local_receipt_timestamp_ns":1704067200000003603,"raw_payload":"{\"arg\":{\"channel\":\"books\",\"instId\":\"BTC-USDT\"},\"data\":[{\"ts\":\"1704067200360\",\"seqId\":359,\"prevSeqId\":358,\"bids\":[[\"50000.0\",\"1.00000000\",\"0\",\"1\"]],\"asks\":[]}]}"}
{"local_receipt_timestamp_ns":1704067200000003613,"raw_payload":"{\"arg\":{\"channel\":\"books\",\"instId\":\"BTC-USDT\"},\"data\":[{\"ts\":\"1704067200361\",\"seqId\":360,\"prevSeqId\":359,\"bids\":[],\"asks\":[[\"50001.0\",\"1.00000000\",\"0\",\"1\"]]}]}"}
{"local_receipt_timestamp_ns":1704067200000003623,"raw_payload":"{\"arg\":{\"channel\":\"books\",\"instId\":\"BTC-USDT\"},\"data\":[{\"ts\":\"1704067200362\",\"seqId\":361,\"prevSeqId\":360,\"bids\":[[\"50000.0\",\"1.00000000\",\"0\",\"1\"]],\"asks\":[]}]}"}
{"local_receipt_timestamp_ns":1704067200000003633,"raw_payload":"{\"arg\":{\"channel\":\"books\",\"instId\":\"BTC-USDT\"},\"data\":[{\"ts\":\"1704067200363\",\"seqId\":362,\"prevSeqId\":361,\"bids\":[],\"asks\":[[\"50001.0\",\"1.00000000\",\"0\",\"1\"]]}]}"}
{"local_receipt_timestamp_ns":1704067200000003643,"raw_payload":"{\"arg\":{\"channel\":\"books\",\"instId\":\"BTC-USDT\"},\"data\":[{\"ts\":\"1704067200364\",\"seqId\":363,\"prevSeqId\":362,\"bids\":[[\"50000.0\",\"1.00000000\",\"0\",\"1\"]],\"asks\":[]}]}"}
{"local_receipt_timestamp_ns":1704067200000003653,"raw_payload":"{\"arg\":{\"channel\":\"books\",\"instId\":\"BTC-USDT\"},\"data\":[{\"ts\":\"1704067200365\",\"seqId\":364,\"prevSeqId\":363,\"bids\":[],\"asks\":[[\"50001.0\",\"1.00000000\",\"0\",\"1\"]]}]}"}
{"local_receipt_timestamp_ns":1704067200000003663,"raw_payload":"{\"arg\":{\"channel\":\"books\",\"instId\":\"BTC-USDT\"},\"data\":[{\"ts\":\"1704067200366\",\"seqId\":365,\"prevSeqId\":364,\"bids\":[[\"50000.0\",\"1.00000000\",\"0\",\"1\"]],\"asks\":[]}]}"}
{"local_receipt_timestamp_ns":1704067200000003673,"raw_payload":"{\"arg\":{\"channel\":\"books\",\"instId\":\"BTC-USDT\"},\"data\":[{\"ts\":\"1704067200367\",\"seqId\":366,\"prevSeqId\":365,\"bids\":[],\"asks\":[[\"50001.0\",\"1.00000000\",\"0\",\"1\"]]}]}"}
{"local_receipt_timestamp_ns":1704067200000003683,"raw_payload":"{\"arg\":{\"channel\":\"books\",\"instId\":\"BTC-USDT\"},\"data\":[{\"ts\":\"1704067200368\",\"seqId\":367,\"prevSeqId\":366,\"bids\":[[\"50000.0\",\"1.00000000\",\"0\",\"1\"]],\"asks\":[]}]}"}
{"local_receipt_timestamp_ns":1704067200000003693,"raw_payload":"{\"arg\":{\"channel\":\"books\",\"instId\":\"BTC-USDT\"},\"data\":[{\"ts\":\"1704067200369\",\"seqId\":368,\"prevSeqId\":367,\"bids\":[],\"asks\":[[\"50001.0\",\"1.00000000\",\"0\",\"1\"]]}]}"}
{"local_receipt_timestamp_ns":1704067200000003703,"raw_payload":"{\"arg\":{\"channel\":\"books\",\"instId\":\"BTC-USDT\"},\"data\":[{\"ts\":\"1704067200370\",\"seqId\":369,\"prevSeqId\":368,\"bids\":[[\"50000.0\",\"1.00000000\",\"0\",\"1\"]],\"asks\":[]}]}"}
{"local_receipt_timestamp_ns":1704067200000003713,"raw_payload":"{\"arg\":{\"channel\":\"books\",\"instId\":\"BTC-USDT\"},\"data\":[{\"ts\":\"1704067200371\",\"seqId\":370,\"prevSeqId\":369,\"bids\":[],\"asks\":[[\"50001.0\",\"1.00000000\",\"0\",\"1\"]]}]}"}
{"local_receipt_timestamp_ns":1704067200000003723,"raw_payload":"{\"arg\":{\"channel\":\"books\",\"instId\":\"BTC-USDT\"},\"data\":[{\"ts\":\"1704067200372\",\"seqId\":371,\"prevSeqId\":370,\"bids\":[[\"50000.0\",\"1.00000000\",\"0\",\"1\"]],\"asks\":[]}]}"}
{"local_receipt_timestamp_ns":1704067200000003733,"raw_payload":"{\"arg\":{\"channel\":\"books\",\"instId\":\"BTC-USDT\"},\"data\":[{\"ts\":\"1704067200373\",\"seqId\":372,\"prevSeqId\":371,\"bids\":[],\"asks\":[[\"50001.0\",\"1.00000000\",\"0\",\"1\"]]}]}"}
{"local_receipt_timestamp_ns":1704067200000003743,"raw_payload":"{\"arg\":{\"channel\":\"books\",\"instId\":\"BTC-USDT\"},\"data\":[{\"ts\":\"1704067200374\",\"seqId\":373,\"prevSeqId\":372,\"bids\":[[\"50000.0\",\"1.00000000\",\"0\",\"1\"]],\"asks\":[]}]}"}
{"local_receipt_timestamp_ns":1704067200000003753,"raw_payload":"{\"arg\":{\"channel\":\"books\",\"instId\":\"BTC-USDT\"},\"data\":[{\"ts\":\"1704067200375\",\"seqId\":374,\"prevSeqId\":373,\"bids\":[],\"asks\":[[\"50001.0\",\"1.00000000\",\"0\",\"1\"]]}]}"}
{"local_receipt_timestamp_ns":1704067200000003763,"raw_payload":"{\"arg\":{\"channel\":\"books\",\"instId\":\"BTC-USDT\"},\"data\":[{\"ts\":\"1704067200376\",\"seqId\":375,\"prevSeqId\":374,\"bids\":[[\"50000.0\",\"1.00000000\",\"0\",\"1\"]],\"asks\":[]}]}"}
{"local_receipt_timestamp_ns":1704067200000003773,"raw_payload":"{\"arg\":{\"channel\":\"books\",\"instId\":\"BTC-USDT\"},\"data\":[{\"ts\":\"1704067200377\",\"seqId\":376,\"prevSeqId\":375,\"bids\":[],\"asks\":[[\"50001.0\",\"1.00000000\",\"0\",\"1\"]]}]}"}
{"local_receipt_timestamp_ns":1704067200000003783,"raw_payload":"{\"arg\":{\"channel\":\"books\",\"instId\":\"BTC-USDT\"},\"data\":[{\"ts\":\"1704067200378\",\"seqId\":377,\"prevSeqId\":376,\"bids\":[[\"50000.0\",\"1.00000000\",\"0\",\"1\"]],\"asks\":[]}]}"}
{"local_receipt_timestamp_ns":1704067200000003793,"raw_payload":"{\"arg\":{\"channel\":\"books\",\"instId\":\"BTC-USDT\"},\"data\":[{\"ts\":\"1704067200379\",\"seqId\":378,\"prevSeqId\":377,\"bids\":[],\"asks\":[[\"50001.0\",\"1.00000000\",\"0\",\"1\"]]}]}"}
{"local_receipt_timestamp_ns":1704067200000003803,"raw_payload":"{\"arg\":{\"channel\":\"books\",\"instId\":\"BTC-USDT\"},\"data\":[{\"ts\":\"1704067200380\",\"seqId\":379,\"prevSeqId\":378,\"bids\":[[\"50000.0\",\"1.00000000\",\"0\",\"1\"]],\"asks\":[]}]}"}
{"local_receipt_timestamp_ns":1704067200000003813,"raw_payload":"{\"arg\":{\"channel\":\"books\",\"instId\":\"BTC-USDT\"},\"data\":[{\"ts\":\"1704067200381\",\"seqId\":380,\"prevSeqId\":379,\"bids\":[],\"asks\":[[\"50001.0\",\"1.00000000\",\"0\",\"1\"]]}]}"}
{"local_receipt_timestamp_ns":1704067200000003823,"raw_payload":"{\"arg\":{\"channel\":\"books\",\"instId\":\"BTC-USDT\"},\"data\":[{\"ts\":\"1704067200382\",\"seqId\":381,\"prevSeqId\":380,\"bids\":[[\"50000.0\",\"1.00000000\",\"0\",\"1\"]],\"asks\":[]}]}"}
{"local_receipt_timestamp_ns":1704067200000003833,"raw_payload":"{\"arg\":{\"channel\":\"books\",\"instId\":\"BTC-USDT\"},\"data\":[{\"ts\":\"1704067200383\",\"seqId\":382,\"prevSeqId\":381,\"bids\":[],\"asks\":[[\"50001.0\",\"1.00000000\",\"0\",\"1\"]]}]}"}
{"local_receipt_timestamp_ns":1704067200000003843,"raw_payload":"{\"arg\":{\"channel\":\"books\",\"instId\":\"BTC-USDT\"},\"data\":[{\"ts\":\"1704067200384\",\"seqId\":383,\"prevSeqId\":382,\"bids\":[[\"50000.0\",\"1.00000000\",\"0\",\"1\"]],\"asks\":[]}]}"}
{"local_receipt_timestamp_ns":1704067200000003853,"raw_payload":"{\"arg\":{\"channel\":\"books\",\"instId\":\"BTC-USDT\"},\"data\":[{\"ts\":\"1704067200385\",\"seqId\":384,\"prevSeqId\":383,\"bids\":[],\"asks\":[[\"50001.0\",\"1.00000000\",\"0\",\"1\"]]}]}"}
{"local_receipt_timestamp_ns":1704067200000003863,"raw_payload":"{\"arg\":{\"channel\":\"books\",\"instId\":\"BTC-USDT\"},\"data\":[{\"ts\":\"1704067200386\",\"seqId\":385,\"prevSeqId\":384,\"bids\":[[\"50000.0\",\"1.00000000\",\"0\",\"1\"]],\"asks\":[]}]}"}
{"local_receipt_timestamp_ns":1704067200000003873,"raw_payload":"{\"arg\":{\"channel\":\"books\",\"instId\":\"BTC-USDT\"},\"data\":[{\"ts\":\"1704067200387\",\"seqId\":386,\"prevSeqId\":385,\"bids\":[],\"asks\":[[\"50001.0\",\"1.00000000\",\"0\",\"1\"]]}]}"}
{"local_receipt_timestamp_ns":1704067200000003883,"raw_payload":"{\"arg\":{\"channel\":\"books\",\"instId\":\"BTC-USDT\"},\"data\":[{\"ts\":\"1704067200388\",\"seqId\":387,\"prevSeqId\":386,\"bids\":[[\"50000.0\",\"1.00000000\",\"0\",\"1\"]],\"asks\":[]}]}"}
{"local_receipt_timestamp_ns":1704067200000003893,"raw_payload":"{\"arg\":{\"channel\":\"books\",\"instId\":\"BTC-USDT\"},\"data\":[{\"ts\":\"1704067200389\",\"seqId\":388,\"prevSeqId\":387,\"bids\":[],\"asks\":[[\"50001.0\",\"1.00000000\",\"0\",\"1\"]]}]}"}
{"local_receipt_timestamp_ns":1704067200000003903,"raw_payload":"{\"arg\":{\"channel\":\"books\",\"instId\":\"BTC-USDT\"},\"data\":[{\"ts\":\"1704067200390\",\"seqId\":389,\"prevSeqId\":388,\"bids\":[[\"50000.0\",\"1.00000000\",\"0\",\"1\"]],\"asks\":[]}]}"}
{"local_receipt_timestamp_ns":1704067200000003913,"raw_payload":"{\"arg\":{\"channel\":\"books\",\"instId\":\"BTC-USDT\"},\"data\":[{\"ts\":\"1704067200391\",\"seqId\":390,\"prevSeqId\":389,\"bids\":[],\"asks\":[[\"50001.0\",\"1.00000000\",\"0\",\"1\"]]}]}"}
{"local_receipt_timestamp_ns":1704067200000003923,"raw_payload":"{\"arg\":{\"channel\":\"books\",\"instId\":\"BTC-USDT\"},\"data\":[{\"ts\":\"1704067200392\",\"seqId\":391,\"prevSeqId\":390,\"bids\":[[\"50000.0\",\"1.00000000\",\"0\",\"1\"]],\"asks\":[]}]}"}
{"local_receipt_timestamp_ns":1704067200000003933,"raw_payload":"{\"arg\":{\"channel\":\"books\",\"instId\":\"BTC-USDT\"},\"data\":[{\"ts\":\"1704067200393\",\"seqId\":392,\"prevSeqId\":391,\"bids\":[],\"asks\":[[\"50001.0\",\"1.00000000\",\"0\",\"1\"]]}]}"}
{"local_receipt_timestamp_ns":1704067200000003943,"raw_payload":"{\"arg\":{\"channel\":\"books\",\"instId\":\"BTC-USDT\"},\"data\":[{\"ts\":\"1704067200394\",\"seqId\":393,\"prevSeqId\":392,\"bids\":[[\"50000.0\",\"1.00000000\",\"0\",\"1\"]],\"asks\":[]}]}"}
{"local_receipt_timestamp_ns":1704067200000003953,"raw_payload":"{\"arg\":{\"channel\":\"books\",\"instId\":\"BTC-USDT\"},\"data\":[{\"ts\":\"1704067200395\",\"seqId\":394,\"prevSeqId\":393,\"bids\":[],\"asks\":[[\"50001.0\",\"1.00000000\",\"0\",\"1\"]]}]}"}
{"local_receipt_timestamp_ns":1704067200000003963,"raw_payload":"{\"arg\":{\"channel\":\"books\",\"instId\":\"BTC-USDT\"},\"data\":[{\"ts\":\"1704067200396\",\"seqId\":395,\"prevSeqId\":394,\"bids\":[[\"50000.0\",\"1.00000000\",\"0\",\"1\"]],\"asks\":[]}]}"}
{"local_receipt_timestamp_ns":1704067200000003973,"raw_payload":"{\"arg\":{\"channel\":\"books\",\"instId\":\"BTC-USDT\"},\"data\":[{\"ts\":\"1704067200397\",\"seqId\":396,\"prevSeqId\":395,\"bids\":[],\"asks\":[[\"50001.0\",\"1.00000000\",\"0\",\"1\"]]}]}"}
{"local_receipt_timestamp_ns":1704067200000003983,"raw_payload":"{\"arg\":{\"channel\":\"books\",\"instId\":\"BTC-USDT\"},\"data\":[{\"ts\":\"1704067200398\",\"seqId\":397,\"prevSeqId\":396,\"bids\":[[\"50000.0\",\"1.00000000\",\"0\",\"1\"]],\"asks\":[]}]}"}
{"local_receipt_timestamp_ns":1704067200000003993,"raw_payload":"{\"arg\":{\"channel\":\"books\",\"instId\":\"BTC-USDT\"},\"data\":[{\"ts\":\"1704067200399\",\"seqId\":398,\"prevSeqId\":397,\"bids\":[],\"asks\":[[\"50001.0\",\"1.00000000\",\"0\",\"1\"]]}]}"}
{"local_receipt_timestamp_ns":1704067200000004003,"raw_payload":"{\"arg\":{\"channel\":\"books\",\"instId\":\"BTC-USDT\"},\"data\":[{\"ts\":\"1704067200400\",\"seqId\":399,\"prevSeqId\":398,\"bids\":[[\"50000.0\",\"1.00000000\",\"0\",\"1\"]],\"asks\":[]}]}"}
{"local_receipt_timestamp_ns":1704067200000004013,"raw_payload":"{\"arg\":{\"channel\":\"books\",\"instId\":\"BTC-USDT\"},\"data\":[{\"ts\":\"1704067200401\",\"seqId\":400,\"prevSeqId\":399,\"bids\":[],\"asks\":[[\"50001.0\",\"1.00000000\",\"0\",\"1\"]]}]}"}
{"local_receipt_timestamp_ns":1704067200000004023,"raw_payload":"{\"arg\":{\"channel\":\"books\",\"instId\":\"BTC-USDT\"},\"data\":[{\"ts\":\"1704067200402\",\"seqId\":401,\"prevSeqId\":400,\"bids\":[[\"50000.0\",\"1.00000000\",\"0\",\"1\"]],\"asks\":[]}]}"}
{"local_receipt_timestamp_ns":1704067200000004033,"raw_payload":"{\"arg\":{\"channel\":\"books\",\"instId\":\"BTC-USDT\"},\"data\":[{\"ts\":\"1704067200403\",\"seqId\":402,\"prevSeqId\":401,\"bids\":[],\"asks\":[[\"50001.0\",\"1.00000000\",\"0\",\"1\"]]}]}"}
{"local_receipt_timestamp_ns":1704067200000004043,"raw_payload":"{\"arg\":{\"channel\":\"books\",\"instId\":\"BTC-USDT\"},\"data\":[{\"ts\":\"1704067200404\",\"seqId\":403,\"prevSeqId\":402,\"bids\":[[\"50000.0\",\"1.00000000\",\"0\",\"1\"]],\"asks\":[]}]}"}
{"local_receipt_timestamp_ns":1704067200000004053,"raw_payload":"{\"arg\":{\"channel\":\"books\",\"instId\":\"BTC-USDT\"},\"data\":[{\"ts\":\"1704067200405\",\"seqId\":404,\"prevSeqId\":403,\"bids\":[],\"asks\":[[\"50001.0\",\"1.00000000\",\"0\",\"1\"]]}]}"}
{"local_receipt_timestamp_ns":1704067200000004063,"raw_payload":"{\"arg\":{\"channel\":\"books\",\"instId\":\"BTC-USDT\"},\"data\":[{\"ts\":\"1704067200406\",\"seqId\":405,\"prevSeqId\":404,\"bids\":[[\"50000.0\",\"1.00000000\",\"0\",\"1\"]],\"asks\":[]}]}"}
{"local_receipt_timestamp_ns":1704067200000004073,"raw_payload":"{\"arg\":{\"channel\":\"books\",\"instId\":\"BTC-USDT\"},\"data\":[{\"ts\":\"1704067200407\",\"seqId\":406,\"prevSeqId\":405,\"bids\":[],\"asks\":[[\"50001.0\",\"1.00000000\",\"0\",\"1\"]]}]}"}
{"local_receipt_timestamp_ns":1704067200000004083,"raw_payload":"{\"arg\":{\"channel\":\"books\",\"instId\":\"BTC-USDT\"},\"data\":[{\"ts\":\"1704067200408\",\"seqId\":407,\"prevSeqId\":406,\"bids\":[[\"50000.0\",\"1.00000000\",\"0\",\"1\"]],\"asks\":[]}]}"}
{"local_receipt_timestamp_ns":1704067200000004093,"raw_payload":"{\"arg\":{\"channel\":\"books\",\"instId\":\"BTC-USDT\"},\"data\":[{\"ts\":\"1704067200409\",\"seqId\":408,\"prevSeqId\":407,\"bids\":[],\"asks\":[[\"50001.0\",\"1.00000000\",\"0\",\"1\"]]}]}"}
{"local_receipt_timestamp_ns":1704067200000004103,"raw_payload":"{\"arg\":{\"channel\":\"books\",\"instId\":\"BTC-USDT\"},\"data\":[{\"ts\":\"1704067200410\",\"seqId\":409,\"prevSeqId\":408,\"bids\":[[\"50000.0\",\"1.00000000\",\"0\",\"1\"]],\"asks\":[]}]}"}
{"local_receipt_timestamp_ns":1704067200000004113,"raw_payload":"{\"arg\":{\"channel\":\"books\",\"instId\":\"BTC-USDT\"},\"data\":[{\"ts\":\"1704067200411\",\"seqId\":410,\"prevSeqId\":409,\"bids\":[],\"asks\":[[\"50001.0\",\"1.00000000\",\"0\",\"1\"]]}]}"}
{"local_receipt_timestamp_ns":1704067200000004123,"raw_payload":"{\"arg\":{\"channel\":\"books\",\"instId\":\"BTC-USDT\"},\"data\":[{\"ts\":\"1704067200412\",\"seqId\":411,\"prevSeqId\":410,\"bids\":[[\"50000.0\",\"1.00000000\",\"0\",\"1\"]],\"asks\":[]}]}"}
{"local_receipt_timestamp_ns":1704067200000004133,"raw_payload":"{\"arg\":{\"channel\":\"books\",\"instId\":\"BTC-USDT\"},\"data\":[{\"ts\":\"1704067200413\",\"seqId\":412,\"prevSeqId\":411,\"bids\":[],\"asks\":[[\"50001.0\",\"1.00000000\",\"0\",\"1\"]]}]}"}
{"local_receipt_timestamp_ns":1704067200000004143,"raw_payload":"{\"arg\":{\"channel\":\"books\",\"instId\":\"BTC-USDT\"},\"data\":[{\"ts\":\"1704067200414\",\"seqId\":413,\"prevSeqId\":412,\"bids\":[[\"50000.0\",\"1.00000000\",\"0\",\"1\"]],\"asks\":[]}]}"}
{"local_receipt_timestamp_ns":1704067200000004153,"raw_payload":"{\"arg\":{\"channel\":\"books\",\"instId\":\"BTC-USDT\"},\"data\":[{\"ts\":\"1704067200415\",\"seqId\":414,\"prevSeqId\":413,\"bids\":[],\"asks\":[[\"50001.0\",\"1.00000000\",\"0\",\"1\"]]}]}"}
{"local_receipt_timestamp_ns":1704067200000004163,"raw_payload":"{\"arg\":{\"channel\":\"books\",\"instId\":\"BTC-USDT\"},\"data\":[{\"ts\":\"1704067200416\",\"seqId\":415,\"prevSeqId\":414,\"bids\":[[\"50000.0\",\"1.00000000\",\"0\",\"1\"]],\"asks\":[]}]}"}
{"local_receipt_timestamp_ns":1704067200000004173,"raw_payload":"{\"arg\":{\"channel\":\"books\",\"instId\":\"BTC-USDT\"},\"data\":[{\"ts\":\"1704067200417\",\"seqId\":416,\"prevSeqId\":415,\"bids\":[],\"asks\":[[\"50001.0\",\"1.00000000\",\"0\",\"1\"]]}]}"}
{"local_receipt_timestamp_ns":1704067200000004183,"raw_payload":"{\"arg\":{\"channel\":\"books\",\"instId\":\"BTC-USDT\"},\"data\":[{\"ts\":\"1704067200418\",\"seqId\":417,\"prevSeqId\":416,\"bids\":[[\"50000.0\",\"1.00000000\",\"0\",\"1\"]],\"asks\":[]}]}"}
{"local_receipt_timestamp_ns":1704067200000004193,"raw_payload":"{\"arg\":{\"channel\":\"books\",\"instId\":\"BTC-USDT\"},\"data\":[{\"ts\":\"1704067200419\",\"seqId\":418,\"prevSeqId\":417,\"bids\":[],\"asks\":[[\"50001.0\",\"1.00000000\",\"0\",\"1\"]]}]}"}
{"local_receipt_timestamp_ns":1704067200000004203,"raw_payload":"{\"arg\":{\"channel\":\"books\",\"instId\":\"BTC-USDT\"},\"data\":[{\"ts\":\"1704067200420\",\"seqId\":419,\"prevSeqId\":418,\"bids\":[[\"50000.0\",\"1.00000000\",\"0\",\"1\"]],\"asks\":[]}]}"}
{"local_receipt_timestamp_ns":1704067200000004213,"raw_payload":"{\"arg\":{\"channel\":\"books\",\"instId\":\"BTC-USDT\"},\"data\":[{\"ts\":\"1704067200421\",\"seqId\":420,\"prevSeqId\":419,\"bids\":[],\"asks\":[[\"50001.0\",\"1.00000000\",\"0\",\"1\"]]}]}"}
{"local_receipt_timestamp_ns":1704067200000004223,"raw_payload":"{\"arg\":{\"channel\":\"books\",\"instId\":\"BTC-USDT\"},\"data\":[{\"ts\":\"1704067200422\",\"seqId\":421,\"prevSeqId\":420,\"bids\":[[\"50000.0\",\"1.00000000\",\"0\",\"1\"]],\"asks\":[]}]}"}
{"local_receipt_timestamp_ns":1704067200000004233,"raw_payload":"{\"arg\":{\"channel\":\"books\",\"instId\":\"BTC-USDT\"},\"data\":[{\"ts\":\"1704067200423\",\"seqId\":422,\"prevSeqId\":421,\"bids\":[],\"asks\":[[\"50001.0\",\"1.00000000\",\"0\",\"1\"]]}]}"}
{"local_receipt_timestamp_ns":1704067200000004243,"raw_payload":"{\"arg\":{\"channel\":\"books\",\"instId\":\"BTC-USDT\"},\"data\":[{\"ts\":\"1704067200424\",\"seqId\":423,\"prevSeqId\":422,\"bids\":[[\"50000.0\",\"1.00000000\",\"0\",\"1\"]],\"asks\":[]}]}"}
{"local_receipt_timestamp_ns":1704067200000004253,"raw_payload":"{\"arg\":{\"channel\":\"books\",\"instId\":\"BTC-USDT\"},\"data\":[{\"ts\":\"1704067200425\",\"seqId\":424,\"prevSeqId\":423,\"bids\":[],\"asks\":[[\"50001.0\",\"1.00000000\",\"0\",\"1\"]]}]}"}
{"local_receipt_timestamp_ns":1704067200000004263,"raw_payload":"{\"arg\":{\"channel\":\"books\",\"instId\":\"BTC-USDT\"},\"data\":[{\"ts\":\"1704067200426\",\"seqId\":425,\"prevSeqId\":424,\"bids\":[[\"50000.0\",\"1.00000000\",\"0\",\"1\"]],\"asks\":[]}]}"}
{"local_receipt_timestamp_ns":1704067200000004273,"raw_payload":"{\"arg\":{\"channel\":\"books\",\"instId\":\"BTC-USDT\"},\"data\":[{\"ts\":\"1704067200427\",\"seqId\":426,\"prevSeqId\":425,\"bids\":[],\"asks\":[[\"50001.0\",\"1.00000000\",\"0\",\"1\"]]}]}"}
{"local_receipt_timestamp_ns":1704067200000004283,"raw_payload":"{\"arg\":{\"channel\":\"books\",\"instId\":\"BTC-USDT\"},\"data\":[{\"ts\":\"1704067200428\",\"seqId\":427,\"prevSeqId\":426,\"bids\":[[\"50000.0\",\"1.00000000\",\"0\",\"1\"]],\"asks\":[]}]}"}
{"local_receipt_timestamp_ns":1704067200000004293,"raw_payload":"{\"arg\":{\"channel\":\"books\",\"instId\":\"BTC-USDT\"},\"data\":[{\"ts\":\"1704067200429\",\"seqId\":428,\"prevSeqId\":427,\"bids\":[],\"asks\":[[\"50001.0\",\"1.00000000\",\"0\",\"1\"]]}]}"}
{"local_receipt_timestamp_ns":1704067200000004303,"raw_payload":"{\"arg\":{\"channel\":\"books\",\"instId\":\"BTC-USDT\"},\"data\":[{\"ts\":\"1704067200430\",\"seqId\":429,\"prevSeqId\":428,\"bids\":[[\"50000.0\",\"1.00000000\",\"0\",\"1\"]],\"asks\":[]}]}"}
{"local_receipt_timestamp_ns":1704067200000004313,"raw_payload":"{\"arg\":{\"channel\":\"books\",\"instId\":\"BTC-USDT\"},\"data\":[{\"ts\":\"1704067200431\",\"seqId\":430,\"prevSeqId\":429,\"bids\":[],\"asks\":[[\"50001.0\",\"1.00000000\",\"0\",\"1\"]]}]}"}
{"local_receipt_timestamp_ns":1704067200000004323,"raw_payload":"{\"arg\":{\"channel\":\"books\",\"instId\":\"BTC-USDT\"},\"data\":[{\"ts\":\"1704067200432\",\"seqId\":431,\"prevSeqId\":430,\"bids\":[[\"50000.0\",\"1.00000000\",\"0\",\"1\"]],\"asks\":[]}]}"}
{"local_receipt_timestamp_ns":1704067200000004333,"raw_payload":"{\"arg\":{\"channel\":\"books\",\"instId\":\"BTC-USDT\"},\"data\":[{\"ts\":\"1704067200433\",\"seqId\":432,\"prevSeqId\":431,\"bids\":[],\"asks\":[[\"50001.0\",\"1.00000000\",\"0\",\"1\"]]}]}"}
{"local_receipt_timestamp_ns":1704067200000004343,"raw_payload":"{\"arg\":{\"channel\":\"books\",\"instId\":\"BTC-USDT\"},\"data\":[{\"ts\":\"1704067200434\",\"seqId\":433,\"prevSeqId\":432,\"bids\":[[\"50000.0\",\"1.00000000\",\"0\",\"1\"]],\"asks\":[]}]}"}
{"local_receipt_timestamp_ns":1704067200000004353,"raw_payload":"{\"arg\":{\"channel\":\"books\",\"instId\":\"BTC-USDT\"},\"data\":[{\"ts\":\"1704067200435\",\"seqId\":434,\"prevSeqId\":433,\"bids\":[],\"asks\":[[\"50001.0\",\"1.00000000\",\"0\",\"1\"]]}]}"}
{"local_receipt_timestamp_ns":1704067200000004363,"raw_payload":"{\"arg\":{\"channel\":\"books\",\"instId\":\"BTC-USDT\"},\"data\":[{\"ts\":\"1704067200436\",\"seqId\":435,\"prevSeqId\":434,\"bids\":[[\"50000.0\",\"1.00000000\",\"0\",\"1\"]],\"asks\":[]}]}"}
{"local_receipt_timestamp_ns":1704067200000004373,"raw_payload":"{\"arg\":{\"channel\":\"books\",\"instId\":\"BTC-USDT\"},\"data\":[{\"ts\":\"1704067200437\",\"seqId\":436,\"prevSeqId\":435,\"bids\":[],\"asks\":[[\"50001.0\",\"1.00000000\",\"0\",\"1\"]]}]}"}
{"local_receipt_timestamp_ns":1704067200000004383,"raw_payload":"{\"arg\":{\"channel\":\"books\",\"instId\":\"BTC-USDT\"},\"data\":[{\"ts\":\"1704067200438\",\"seqId\":437,\"prevSeqId\":436,\"bids\":[[\"50000.0\",\"1.00000000\",\"0\",\"1\"]],\"asks\":[]}]}"}
{"local_receipt_timestamp_ns":1704067200000004393,"raw_payload":"{\"arg\":{\"channel\":\"books\",\"instId\":\"BTC-USDT\"},\"data\":[{\"ts\":\"1704067200439\",\"seqId\":438,\"prevSeqId\":437,\"bids\":[],\"asks\":[[\"50001.0\",\"1.00000000\",\"0\",\"1\"]]}]}"}
{"local_receipt_timestamp_ns":1704067200000004403,"raw_payload":"{\"arg\":{\"channel\":\"books\",\"instId\":\"BTC-USDT\"},\"data\":[{\"ts\":\"1704067200440\",\"seqId\":439,\"prevSeqId\":438,\"bids\":[[\"50000.0\",\"1.00000000\",\"0\",\"1\"]],\"asks\":[]}]}"}
{"local_receipt_timestamp_ns":1704067200000004413,"raw_payload":"{\"arg\":{\"channel\":\"books\",\"instId\":\"BTC-USDT\"},\"data\":[{\"ts\":\"1704067200441\",\"seqId\":440,\"prevSeqId\":439,\"bids\":[],\"asks\":[[\"50001.0\",\"1.00000000\",\"0\",\"1\"]]}]}"}
{"local_receipt_timestamp_ns":1704067200000004423,"raw_payload":"{\"arg\":{\"channel\":\"books\",\"instId\":\"BTC-USDT\"},\"data\":[{\"ts\":\"1704067200442\",\"seqId\":441,\"prevSeqId\":440,\"bids\":[[\"50000.0\",\"1.00000000\",\"0\",\"1\"]],\"asks\":[]}]}"}
{"local_receipt_timestamp_ns":1704067200000004433,"raw_payload":"{\"arg\":{\"channel\":\"books\",\"instId\":\"BTC-USDT\"},\"data\":[{\"ts\":\"1704067200443\",\"seqId\":442,\"prevSeqId\":441,\"bids\":[],\"asks\":[[\"50001.0\",\"1.00000000\",\"0\",\"1\"]]}]}"}
{"local_receipt_timestamp_ns":1704067200000004443,"raw_payload":"{\"arg\":{\"channel\":\"books\",\"instId\":\"BTC-USDT\"},\"data\":[{\"ts\":\"1704067200444\",\"seqId\":443,\"prevSeqId\":442,\"bids\":[[\"50000.0\",\"1.00000000\",\"0\",\"1\"]],\"asks\":[]}]}"}
{"local_receipt_timestamp_ns":1704067200000004453,"raw_payload":"{\"arg\":{\"channel\":\"books\",\"instId\":\"BTC-USDT\"},\"data\":[{\"ts\":\"1704067200445\",\"seqId\":444,\"prevSeqId\":443,\"bids\":[],\"asks\":[[\"50001.0\",\"1.00000000\",\"0\",\"1\"]]}]}"}
{"local_receipt_timestamp_ns":1704067200000004463,"raw_payload":"{\"arg\":{\"channel\":\"books\",\"instId\":\"BTC-USDT\"},\"data\":[{\"ts\":\"1704067200446\",\"seqId\":445,\"prevSeqId\":444,\"bids\":[[\"50000.0\",\"1.00000000\",\"0\",\"1\"]],\"asks\":[]}]}"}
{"local_receipt_timestamp_ns":1704067200000004473,"raw_payload":"{\"arg\":{\"channel\":\"books\",\"instId\":\"BTC-USDT\"},\"data\":[{\"ts\":\"1704067200447\",\"seqId\":446,\"prevSeqId\":445,\"bids\":[],\"asks\":[[\"50001.0\",\"1.00000000\",\"0\",\"1\"]]}]}"}
{"local_receipt_timestamp_ns":1704067200000004483,"raw_payload":"{\"arg\":{\"channel\":\"books\",\"instId\":\"BTC-USDT\"},\"data\":[{\"ts\":\"1704067200448\",\"seqId\":447,\"prevSeqId\":446,\"bids\":[[\"50000.0\",\"1.00000000\",\"0\",\"1\"]],\"asks\":[]}]}"}
{"local_receipt_timestamp_ns":1704067200000004493,"raw_payload":"{\"arg\":{\"channel\":\"books\",\"instId\":\"BTC-USDT\"},\"data\":[{\"ts\":\"1704067200449\",\"seqId\":448,\"prevSeqId\":447,\"bids\":[],\"asks\":[[\"50001.0\",\"1.00000000\",\"0\",\"1\"]]}]}"}
{"local_receipt_timestamp_ns":1704067200000004503,"raw_payload":"{\"arg\":{\"channel\":\"books\",\"instId\":\"BTC-USDT\"},\"data\":[{\"ts\":\"1704067200450\",\"seqId\":449,\"prevSeqId\":448,\"bids\":[[\"50000.0\",\"1.00000000\",\"0\",\"1\"]],\"asks\":[]}]}"}
{"local_receipt_timestamp_ns":1704067200000004513,"raw_payload":"{\"arg\":{\"channel\":\"books\",\"instId\":\"BTC-USDT\"},\"data\":[{\"ts\":\"1704067200451\",\"seqId\":450,\"prevSeqId\":449,\"bids\":[],\"asks\":[[\"50001.0\",\"1.00000000\",\"0\",\"1\"]]}]}"}
{"local_receipt_timestamp_ns":1704067200000004523,"raw_payload":"{\"arg\":{\"channel\":\"books\",\"instId\":\"BTC-USDT\"},\"data\":[{\"ts\":\"1704067200452\",\"seqId\":451,\"prevSeqId\":450,\"bids\":[[\"50000.0\",\"1.00000000\",\"0\",\"1\"]],\"asks\":[]}]}"}
{"local_receipt_timestamp_ns":1704067200000004533,"raw_payload":"{\"arg\":{\"channel\":\"books\",\"instId\":\"BTC-USDT\"},\"data\":[{\"ts\":\"1704067200453\",\"seqId\":452,\"prevSeqId\":451,\"bids\":[],\"asks\":[[\"50001.0\",\"1.00000000\",\"0\",\"1\"]]}]}"}
{"local_receipt_timestamp_ns":1704067200000004543,"raw_payload":"{\"arg\":{\"channel\":\"books\",\"instId\":\"BTC-USDT\"},\"data\":[{\"ts\":\"1704067200454\",\"seqId\":453,\"prevSeqId\":452,\"bids\":[[\"50000.0\",\"1.00000000\",\"0\",\"1\"]],\"asks\":[]}]}"}
{"local_receipt_timestamp_ns":1704067200000004553,"raw_payload":"{\"arg\":{\"channel\":\"books\",\"instId\":\"BTC-USDT\"},\"data\":[{\"ts\":\"1704067200455\",\"seqId\":454,\"prevSeqId\":453,\"bids\":[],\"asks\":[[\"50001.0\",\"1.00000000\",\"0\",\"1\"]]}]}"}
{"local_receipt_timestamp_ns":1704067200000004563,"raw_payload":"{\"arg\":{\"channel\":\"books\",\"instId\":\"BTC-USDT\"},\"data\":[{\"ts\":\"1704067200456\",\"seqId\":455,\"prevSeqId\":454,\"bids\":[[\"50000.0\",\"1.00000000\",\"0\",\"1\"]],\"asks\":[]}]}"}
{"local_receipt_timestamp_ns":1704067200000004573,"raw_payload":"{\"arg\":{\"channel\":\"books\",\"instId\":\"BTC-USDT\"},\"data\":[{\"ts\":\"1704067200457\",\"seqId\":456,\"prevSeqId\":455,\"bids\":[],\"asks\":[[\"50001.0\",\"1.00000000\",\"0\",\"1\"]]}]}"}
{"local_receipt_timestamp_ns":1704067200000004583,"raw_payload":"{\"arg\":{\"channel\":\"books\",\"instId\":\"BTC-USDT\"},\"data\":[{\"ts\":\"1704067200458\",\"seqId\":457,\"prevSeqId\":456,\"bids\":[[\"50000.0\",\"1.00000000\",\"0\",\"1\"]],\"asks\":[]}]}"}
{"local_receipt_timestamp_ns":1704067200000004593,"raw_payload":"{\"arg\":{\"channel\":\"books\",\"instId\":\"BTC-USDT\"},\"data\":[{\"ts\":\"1704067200459\",\"seqId\":458,\"prevSeqId\":457,\"bids\":[],\"asks\":[[\"50001.0\",\"1.00000000\",\"0\",\"1\"]]}]}"}
{"local_receipt_timestamp_ns":1704067200000004603,"raw_payload":"{\"arg\":{\"channel\":\"books\",\"instId\":\"BTC-USDT\"},\"data\":[{\"ts\":\"1704067200460\",\"seqId\":459,\"prevSeqId\":458,\"bids\":[[\"50000.0\",\"1.00000000\",\"0\",\"1\"]],\"asks\":[]}]}"}
{"local_receipt_timestamp_ns":1704067200000004613,"raw_payload":"{\"arg\":{\"channel\":\"books\",\"instId\":\"BTC-USDT\"},\"data\":[{\"ts\":\"1704067200461\",\"seqId\":460,\"prevSeqId\":459,\"bids\":[],\"asks\":[[\"50001.0\",\"1.00000000\",\"0\",\"1\"]]}]}"}
{"local_receipt_timestamp_ns":1704067200000004623,"raw_payload":"{\"arg\":{\"channel\":\"books\",\"instId\":\"BTC-USDT\"},\"data\":[{\"ts\":\"1704067200462\",\"seqId\":461,\"prevSeqId\":460,\"bids\":[[\"50000.0\",\"1.00000000\",\"0\",\"1\"]],\"asks\":[]}]}"}
{"local_receipt_timestamp_ns":1704067200000004633,"raw_payload":"{\"arg\":{\"channel\":\"books\",\"instId\":\"BTC-USDT\"},\"data\":[{\"ts\":\"1704067200463\",\"seqId\":462,\"prevSeqId\":461,\"bids\":[],\"asks\":[[\"50001.0\",\"1.00000000\",\"0\",\"1\"]]}]}"}
{"local_receipt_timestamp_ns":1704067200000004643,"raw_payload":"{\"arg\":{\"channel\":\"books\",\"instId\":\"BTC-USDT\"},\"data\":[{\"ts\":\"1704067200464\",\"seqId\":463,\"prevSeqId\":462,\"bids\":[[\"50000.0\",\"1.00000000\",\"0\",\"1\"]],\"asks\":[]}]}"}
{"local_receipt_timestamp_ns":1704067200000004653,"raw_payload":"{\"arg\":{\"channel\":\"books\",\"instId\":\"BTC-USDT\"},\"data\":[{\"ts\":\"1704067200465\",\"seqId\":464,\"prevSeqId\":463,\"bids\":[],\"asks\":[[\"50001.0\",\"1.00000000\",\"0\",\"1\"]]}]}"}
{"local_receipt_timestamp_ns":1704067200000004663,"raw_payload":"{\"arg\":{\"channel\":\"books\",\"instId\":\"BTC-USDT\"},\"data\":[{\"ts\":\"1704067200466\",\"seqId\":465,\"prevSeqId\":464,\"bids\":[[\"50000.0\",\"1.00000000\",\"0\",\"1\"]],\"asks\":[]}]}"}
{"local_receipt_timestamp_ns":1704067200000004673,"raw_payload":"{\"arg\":{\"channel\":\"books\",\"instId\":\"BTC-USDT\"},\"data\":[{\"ts\":\"1704067200467\",\"seqId\":466,\"prevSeqId\":465,\"bids\":[],\"asks\":[[\"50001.0\",\"1.00000000\",\"0\",\"1\"]]}]}"}
{"local_receipt_timestamp_ns":1704067200000004683,"raw_payload":"{\"arg\":{\"channel\":\"books\",\"instId\":\"BTC-USDT\"},\"data\":[{\"ts\":\"1704067200468\",\"seqId\":467,\"prevSeqId\":466,\"bids\":[[\"50000.0\",\"1.00000000\",\"0\",\"1\"]],\"asks\":[]}]}"}
{"local_receipt_timestamp_ns":1704067200000004693,"raw_payload":"{\"arg\":{\"channel\":\"books\",\"instId\":\"BTC-USDT\"},\"data\":[{\"ts\":\"1704067200469\",\"seqId\":468,\"prevSeqId\":467,\"bids\":[],\"asks\":[[\"50001.0\",\"1.00000000\",\"0\",\"1\"]]}]}"}
{"local_receipt_timestamp_ns":1704067200000004703,"raw_payload":"{\"arg\":{\"channel\":\"books\",\"instId\":\"BTC-USDT\"},\"data\":[{\"ts\":\"1704067200470\",\"seqId\":469,\"prevSeqId\":468,\"bids\":[[\"50000.0\",\"1.00000000\",\"0\",\"1\"]],\"asks\":[]}]}"}
{"local_receipt_timestamp_ns":1704067200000004713,"raw_payload":"{\"arg\":{\"channel\":\"books\",\"instId\":\"BTC-USDT\"},\"data\":[{\"ts\":\"1704067200471\",\"seqId\":470,\"prevSeqId\":469,\"bids\":[],\"asks\":[[\"50001.0\",\"1.00000000\",\"0\",\"1\"]]}]}"}
{"local_receipt_timestamp_ns":1704067200000004723,"raw_payload":"{\"arg\":{\"channel\":\"books\",\"instId\":\"BTC-USDT\"},\"data\":[{\"ts\":\"1704067200472\",\"seqId\":471,\"prevSeqId\":470,\"bids\":[[\"50000.0\",\"1.00000000\",\"0\",\"1\"]],\"asks\":[]}]}"}
{"local_receipt_timestamp_ns":1704067200000004733,"raw_payload":"{\"arg\":{\"channel\":\"books\",\"instId\":\"BTC-USDT\"},\"data\":[{\"ts\":\"1704067200473\",\"seqId\":472,\"prevSeqId\":471,\"bids\":[],\"asks\":[[\"50001.0\",\"1.00000000\",\"0\",\"1\"]]}]}"}
{"local_receipt_timestamp_ns":1704067200000004743,"raw_payload":"{\"arg\":{\"channel\":\"books\",\"instId\":\"BTC-USDT\"},\"data\":[{\"ts\":\"1704067200474\",\"seqId\":473,\"prevSeqId\":472,\"bids\":[[\"50000.0\",\"1.00000000\",\"0\",\"1\"]],\"asks\":[]}]}"}
{"local_receipt_timestamp_ns":1704067200000004753,"raw_payload":"{\"arg\":{\"channel\":\"books\",\"instId\":\"BTC-USDT\"},\"data\":[{\"ts\":\"1704067200475\",\"seqId\":474,\"prevSeqId\":473,\"bids\":[],\"asks\":[[\"50001.0\",\"1.00000000\",\"0\",\"1\"]]}]}"}
{"local_receipt_timestamp_ns":1704067200000004763,"raw_payload":"{\"arg\":{\"channel\":\"books\",\"instId\":\"BTC-USDT\"},\"data\":[{\"ts\":\"1704067200476\",\"seqId\":475,\"prevSeqId\":474,\"bids\":[[\"50000.0\",\"1.00000000\",\"0\",\"1\"]],\"asks\":[]}]}"}
{"local_receipt_timestamp_ns":1704067200000004773,"raw_payload":"{\"arg\":{\"channel\":\"books\",\"instId\":\"BTC-USDT\"},\"data\":[{\"ts\":\"1704067200477\",\"seqId\":476,\"prevSeqId\":475,\"bids\":[],\"asks\":[[\"50001.0\",\"1.00000000\",\"0\",\"1\"]]}]}"}
{"local_receipt_timestamp_ns":1704067200000004783,"raw_payload":"{\"arg\":{\"channel\":\"books\",\"instId\":\"BTC-USDT\"},\"data\":[{\"ts\":\"1704067200478\",\"seqId\":477,\"prevSeqId\":476,\"bids\":[[\"50000.0\",\"1.00000000\",\"0\",\"1\"]],\"asks\":[]}]}"}
{"local_receipt_timestamp_ns":1704067200000004793,"raw_payload":"{\"arg\":{\"channel\":\"books\",\"instId\":\"BTC-USDT\"},\"data\":[{\"ts\":\"1704067200479\",\"seqId\":478,\"prevSeqId\":477,\"bids\":[],\"asks\":[[\"50001.0\",\"1.00000000\",\"0\",\"1\"]]}]}"}
{"local_receipt_timestamp_ns":1704067200000004803,"raw_payload":"{\"arg\":{\"channel\":\"books\",\"instId\":\"BTC-USDT\"},\"data\":[{\"ts\":\"1704067200480\",\"seqId\":479,\"prevSeqId\":478,\"bids\":[[\"50000.0\",\"1.00000000\",\"0\",\"1\"]],\"asks\":[]}]}"}
{"local_receipt_timestamp_ns":1704067200000004813,"raw_payload":"{\"arg\":{\"channel\":\"books\",\"instId\":\"BTC-USDT\"},\"data\":[{\"ts\":\"1704067200481\",\"seqId\":480,\"prevSeqId\":479,\"bids\":[],\"asks\":[[\"50001.0\",\"1.00000000\",\"0\",\"1\"]]}]}"}
{"local_receipt_timestamp_ns":1704067200000004823,"raw_payload":"{\"arg\":{\"channel\":\"books\",\"instId\":\"BTC-USDT\"},\"data\":[{\"ts\":\"1704067200482\",\"seqId\":481,\"prevSeqId\":480,\"bids\":[[\"50000.0\",\"1.00000000\",\"0\",\"1\"]],\"asks\":[]}]}"}
{"local_receipt_timestamp_ns":1704067200000004833,"raw_payload":"{\"arg\":{\"channel\":\"books\",\"instId\":\"BTC-USDT\"},\"data\":[{\"ts\":\"1704067200483\",\"seqId\":482,\"prevSeqId\":481,\"bids\":[],\"asks\":[[\"50001.0\",\"1.00000000\",\"0\",\"1\"]]}]}"}
{"local_receipt_timestamp_ns":1704067200000004843,"raw_payload":"{\"arg\":{\"channel\":\"books\",\"instId\":\"BTC-USDT\"},\"data\":[{\"ts\":\"1704067200484\",\"seqId\":483,\"prevSeqId\":482,\"bids\":[[\"50000.0\",\"1.00000000\",\"0\",\"1\"]],\"asks\":[]}]}"}
{"local_receipt_timestamp_ns":1704067200000004853,"raw_payload":"{\"arg\":{\"channel\":\"books\",\"instId\":\"BTC-USDT\"},\"data\":[{\"ts\":\"1704067200485\",\"seqId\":484,\"prevSeqId\":483,\"bids\":[],\"asks\":[[\"50001.0\",\"1.00000000\",\"0\",\"1\"]]}]}"}
{"local_receipt_timestamp_ns":1704067200000004863,"raw_payload":"{\"arg\":{\"channel\":\"books\",\"instId\":\"BTC-USDT\"},\"data\":[{\"ts\":\"1704067200486\",\"seqId\":485,\"prevSeqId\":484,\"bids\":[[\"50000.0\",\"1.00000000\",\"0\",\"1\"]],\"asks\":[]}]}"}
{"local_receipt_timestamp_ns":1704067200000004873,"raw_payload":"{\"arg\":{\"channel\":\"books\",\"instId\":\"BTC-USDT\"},\"data\":[{\"ts\":\"1704067200487\",\"seqId\":486,\"prevSeqId\":485,\"bids\":[],\"asks\":[[\"50001.0\",\"1.00000000\",\"0\",\"1\"]]}]}"}
{"local_receipt_timestamp_ns":1704067200000004883,"raw_payload":"{\"arg\":{\"channel\":\"books\",\"instId\":\"BTC-USDT\"},\"data\":[{\"ts\":\"1704067200488\",\"seqId\":487,\"prevSeqId\":486,\"bids\":[[\"50000.0\",\"1.00000000\",\"0\",\"1\"]],\"asks\":[]}]}"}
{"local_receipt_timestamp_ns":1704067200000004893,"raw_payload":"{\"arg\":{\"channel\":\"books\",\"instId\":\"BTC-USDT\"},\"data\":[{\"ts\":\"1704067200489\",\"seqId\":488,\"prevSeqId\":487,\"bids\":[],\"asks\":[[\"50001.0\",\"1.00000000\",\"0\",\"1\"]]}]}"}
{"local_receipt_timestamp_ns":1704067200000004903,"raw_payload":"{\"arg\":{\"channel\":\"books\",\"instId\":\"BTC-USDT\"},\"data\":[{\"ts\":\"1704067200490\",\"seqId\":489,\"prevSeqId\":488,\"bids\":[[\"50000.0\",\"1.00000000\",\"0\",\"1\"]],\"asks\":[]}]}"}
{"local_receipt_timestamp_ns":1704067200000004913,"raw_payload":"{\"arg\":{\"channel\":\"books\",\"instId\":\"BTC-USDT\"},\"data\":[{\"ts\":\"1704067200491\",\"seqId\":490,\"prevSeqId\":489,\"bids\":[],\"asks\":[[\"50001.0\",\"1.00000000\",\"0\",\"1\"]]}]}"}
{"local_receipt_timestamp_ns":1704067200000004923,"raw_payload":"{\"arg\":{\"channel\":\"books\",\"instId\":\"BTC-USDT\"},\"data\":[{\"ts\":\"1704067200492\",\"seqId\":491,\"prevSeqId\":490,\"bids\":[[\"50000.0\",\"1.00000000\",\"0\",\"1\"]],\"asks\":[]}]}"}
{"local_receipt_timestamp_ns":1704067200000004933,"raw_payload":"{\"arg\":{\"channel\":\"books\",\"instId\":\"BTC-USDT\"},\"data\":[{\"ts\":\"1704067200493\",\"seqId\":492,\"prevSeqId\":491,\"bids\":[],\"asks\":[[\"50001.0\",\"1.00000000\",\"0\",\"1\"]]}]}"}
{"local_receipt_timestamp_ns":1704067200000004943,"raw_payload":"{\"arg\":{\"channel\":\"books\",\"instId\":\"BTC-USDT\"},\"data\":[{\"ts\":\"1704067200494\",\"seqId\":493,\"prevSeqId\":492,\"bids\":[[\"50000.0\",\"1.00000000\",\"0\",\"1\"]],\"asks\":[]}]}"}
{"local_receipt_timestamp_ns":1704067200000004953,"raw_payload":"{\"arg\":{\"channel\":\"books\",\"instId\":\"BTC-USDT\"},\"data\":[{\"ts\":\"1704067200495\",\"seqId\":494,\"prevSeqId\":493,\"bids\":[],\"asks\":[[\"50001.0\",\"1.00000000\",\"0\",\"1\"]]}]}"}
{"local_receipt_timestamp_ns":1704067200000004963,"raw_payload":"{\"arg\":{\"channel\":\"books\",\"instId\":\"BTC-USDT\"},\"data\":[{\"ts\":\"1704067200496\",\"seqId\":495,\"prevSeqId\":494,\"bids\":[[\"50000.0\",\"1.00000000\",\"0\",\"1\"]],\"asks\":[]}]}"}
{"local_receipt_timestamp_ns":1704067200000004973,"raw_payload":"{\"arg\":{\"channel\":\"books\",\"instId\":\"BTC-USDT\"},\"data\":[{\"ts\":\"1704067200497\",\"seqId\":496,\"prevSeqId\":495,\"bids\":[],\"asks\":[[\"50001.0\",\"1.00000000\",\"0\",\"1\"]]}]}"}
{"local_receipt_timestamp_ns":1704067200000004983,"raw_payload":"{\"arg\":{\"channel\":\"books\",\"instId\":\"BTC-USDT\"},\"data\":[{\"ts\":\"1704067200498\",\"seqId\":497,\"prevSeqId\":496,\"bids\":[[\"50000.0\",\"1.00000000\",\"0\",\"1\"]],\"asks\":[]}]}"}
{"local_receipt_timestamp_ns":1704067200000004993,"raw_payload":"{\"arg\":{\"channel\":\"books\",\"instId\":\"BTC-USDT\"},\"data\":[{\"ts\":\"1704067200499\",\"seqId\":498,\"prevSeqId\":497,\"bids\":[],\"asks\":[[\"50001.0\",\"1.00000000\",\"0\",\"1\"]]}]}"}
{"local_receipt_timestamp_ns":1704067200000005003,"raw_payload":"{\"arg\":{\"channel\":\"books\",\"instId\":\"BTC-USDT\"},\"data\":[{\"ts\":\"1704067200500\",\"seqId\":499,\"prevSeqId\":498,\"bids\":[[\"50000.0\",\"1.00000000\",\"0\",\"1\"]],\"asks\":[]}]}"}
{"local_receipt_timestamp_ns":1704067200000005013,"raw_payload":"{\"arg\":{\"channel\":\"books\",\"instId\":\"BTC-USDT\"},\"data\":[{\"ts\":\"1704067200501\",\"seqId\":500,\"prevSeqId\":499,\"bids\":[],\"asks\":[[\"50001.0\",\"1.00000000\",\"0\",\"1\"]]}]}"}
{"local_receipt_timestamp_ns":1704067200000005023,"raw_payload":"{\"arg\":{\"channel\":\"books\",\"instId\":\"BTC-USDT\"},\"data\":[{\"ts\":\"1704067200502\",\"seqId\":501,\"prevSeqId\":500,\"bids\":[[\"50000.0\",\"1.00000000\",\"0\",\"1\"]],\"asks\":[]}]}"}
{"local_receipt_timestamp_ns":1704067200000005033,"raw_payload":"{\"arg\":{\"channel\":\"books\",\"instId\":\"BTC-USDT\"},\"data\":[{\"ts\":\"1704067200503\",\"seqId\":502,\"prevSeqId\":501,\"bids\":[],\"asks\":[[\"50001.0\",\"1.00000000\",\"0\",\"1\"]]}]}"}
{"local_receipt_timestamp_ns":1704067200000005043,"raw_payload":"{\"arg\":{\"channel\":\"books\",\"instId\":\"BTC-USDT\"},\"data\":[{\"ts\":\"1704067200504\",\"seqId\":503,\"prevSeqId\":502,\"bids\":[[\"50000.0\",\"1.00000000\",\"0\",\"1\"]],\"asks\":[]}]}"}
{"local_receipt_timestamp_ns":1704067200000005053,"raw_payload":"{\"arg\":{\"channel\":\"books\",\"instId\":\"BTC-USDT\"},\"data\":[{\"ts\":\"1704067200505\",\"seqId\":504,\"prevSeqId\":503,\"bids\":[],\"asks\":[[\"50001.0\",\"1.00000000\",\"0\",\"1\"]]}]}"}
{"local_receipt_timestamp_ns":1704067200000005063,"raw_payload":"{\"arg\":{\"channel\":\"books\",\"instId\":\"BTC-USDT\"},\"data\":[{\"ts\":\"1704067200506\",\"seqId\":505,\"prevSeqId\":504,\"bids\":[[\"50000.0\",\"1.00000000\",\"0\",\"1\"]],\"asks\":[]}]}"}
{"local_receipt_timestamp_ns":1704067200000005073,"raw_payload":"{\"arg\":{\"channel\":\"books\",\"instId\":\"BTC-USDT\"},\"data\":[{\"ts\":\"1704067200507\",\"seqId\":506,\"prevSeqId\":505,\"bids\":[],\"asks\":[[\"50001.0\",\"1.00000000\",\"0\",\"1\"]]}]}"}
{"local_receipt_timestamp_ns":1704067200000005083,"raw_payload":"{\"arg\":{\"channel\":\"books\",\"instId\":\"BTC-USDT\"},\"data\":[{\"ts\":\"1704067200508\",\"seqId\":507,\"prevSeqId\":506,\"bids\":[[\"50000.0\",\"1.00000000\",\"0\",\"1\"]],\"asks\":[]}]}"}
{"local_receipt_timestamp_ns":1704067200000005093,"raw_payload":"{\"arg\":{\"channel\":\"books\",\"instId\":\"BTC-USDT\"},\"data\":[{\"ts\":\"1704067200509\",\"seqId\":508,\"prevSeqId\":507,\"bids\":[],\"asks\":[[\"50001.0\",\"1.00000000\",\"0\",\"1\"]]}]}"}
{"local_receipt_timestamp_ns":1704067200000005103,"raw_payload":"{\"arg\":{\"channel\":\"books\",\"instId\":\"BTC-USDT\"},\"data\":[{\"ts\":\"1704067200510\",\"seqId\":509,\"prevSeqId\":508,\"bids\":[[\"50000.0\",\"1.00000000\",\"0\",\"1\"]],\"asks\":[]}]}"}
{"local_receipt_timestamp_ns":1704067200000005113,"raw_payload":"{\"arg\":{\"channel\":\"books\",\"instId\":\"BTC-USDT\"},\"data\":[{\"ts\":\"1704067200511\",\"seqId\":510,\"prevSeqId\":509,\"bids\":[],\"asks\":[[\"50001.0\",\"1.00000000\",\"0\",\"1\"]]}]}"}
{"local_receipt_timestamp_ns":1704067200000005123,"raw_payload":"{\"arg\":{\"channel\":\"books\",\"instId\":\"BTC-USDT\"},\"data\":[{\"ts\":\"1704067200512\",\"seqId\":511,\"prevSeqId\":510,\"bids\":[[\"50000.0\",\"1.00000000\",\"0\",\"1\"]],\"asks\":[]}]}"}
{"local_receipt_timestamp_ns":1704067200000005133,"raw_payload":"{\"arg\":{\"channel\":\"books\",\"instId\":\"BTC-USDT\"},\"data\":[{\"ts\":\"1704067200513\",\"seqId\":512,\"prevSeqId\":511,\"bids\":[],\"asks\":[[\"50001.0\",\"1.00000000\",\"0\",\"1\"]]}]}"}
{"local_receipt_timestamp_ns":1704067200000005143,"raw_payload":"{\"arg\":{\"channel\":\"books\",\"instId\":\"BTC-USDT\"},\"data\":[{\"ts\":\"1704067200514\",\"seqId\":513,\"prevSeqId\":512,\"bids\":[[\"50000.0\",\"1.00000000\",\"0\",\"1\"]],\"asks\":[]}]}"}
{"local_receipt_timestamp_ns":1704067200000005153,"raw_payload":"{\"arg\":{\"channel\":\"books\",\"instId\":\"BTC-USDT\"},\"data\":[{\"ts\":\"1704067200515\",\"seqId\":514,\"prevSeqId\":513,\"bids\":[],\"asks\":[[\"50001.0\",\"1.00000000\",\"0\",\"1\"]]}]}"}
{"local_receipt_timestamp_ns":1704067200000005163,"raw_payload":"{\"arg\":{\"channel\":\"books\",\"instId\":\"BTC-USDT\"},\"data\":[{\"ts\":\"1704067200516\",\"seqId\":515,\"prevSeqId\":514,\"bids\":[[\"50000.0\",\"1.00000000\",\"0\",\"1\"]],\"asks\":[]}]}"}
{"local_receipt_timestamp_ns":1704067200000005173,"raw_payload":"{\"arg\":{\"channel\":\"books\",\"instId\":\"BTC-USDT\"},\"data\":[{\"ts\":\"1704067200517\",\"seqId\":516,\"prevSeqId\":515,\"bids\":[],\"asks\":[[\"50001.0\",\"1.00000000\",\"0\",\"1\"]]}]}"}
{"local_receipt_timestamp_ns":1704067200000005183,"raw_payload":"{\"arg\":{\"channel\":\"books\",\"instId\":\"BTC-USDT\"},\"data\":[{\"ts\":\"1704067200518\",\"seqId\":517,\"prevSeqId\":516,\"bids\":[[\"50000.0\",\"1.00000000\",\"0\",\"1\"]],\"asks\":[]}]}"}
{"local_receipt_timestamp_ns":1704067200000005193,"raw_payload":"{\"arg\":{\"channel\":\"books\",\"instId\":\"BTC-USDT\"},\"data\":[{\"ts\":\"1704067200519\",\"seqId\":518,\"prevSeqId\":517,\"bids\":[],\"asks\":[[\"50001.0\",\"1.00000000\",\"0\",\"1\"]]}]}"}
{"local_receipt_timestamp_ns":1704067200000005203,"raw_payload":"{\"arg\":{\"channel\":\"books\",\"instId\":\"BTC-USDT\"},\"data\":[{\"ts\":\"1704067200520\",\"seqId\":519,\"prevSeqId\":518,\"bids\":[[\"50000.0\",\"1.00000000\",\"0\",\"1\"]],\"asks\":[]}]}"}
{"local_receipt_timestamp_ns":1704067200000005213,"raw_payload":"{\"arg\":{\"channel\":\"books\",\"instId\":\"BTC-USDT\"},\"data\":[{\"ts\":\"1704067200521\",\"seqId\":520,\"prevSeqId\":519,\"bids\":[],\"asks\":[[\"50001.0\",\"1.00000000\",\"0\",\"1\"]]}]}"}
{"local_receipt_timestamp_ns":1704067200000005223,"raw_payload":"{\"arg\":{\"channel\":\"books\",\"instId\":\"BTC-USDT\"},\"data\":[{\"ts\":\"1704067200522\",\"seqId\":521,\"prevSeqId\":520,\"bids\":[[\"50000.0\",\"1.00000000\",\"0\",\"1\"]],\"asks\":[]}]}"}
{"local_receipt_timestamp_ns":1704067200000005233,"raw_payload":"{\"arg\":{\"channel\":\"books\",\"instId\":\"BTC-USDT\"},\"data\":[{\"ts\":\"1704067200523\",\"seqId\":522,\"prevSeqId\":521,\"bids\":[],\"asks\":[[\"50001.0\",\"1.00000000\",\"0\",\"1\"]]}]}"}
{"local_receipt_timestamp_ns":1704067200000005243,"raw_payload":"{\"arg\":{\"channel\":\"books\",\"instId\":\"BTC-USDT\"},\"data\":[{\"ts\":\"1704067200524\",\"seqId\":523,\"prevSeqId\":522,\"bids\":[[\"50000.0\",\"1.00000000\",\"0\",\"1\"]],\"asks\":[]}]}"}
{"local_receipt_timestamp_ns":1704067200000005253,"raw_payload":"{\"arg\":{\"channel\":\"books\",\"instId\":\"BTC-USDT\"},\"data\":[{\"ts\":\"1704067200525\",\"seqId\":524,\"prevSeqId\":523,\"bids\":[],\"asks\":[[\"50001.0\",\"1.00000000\",\"0\",\"1\"]]}]}"}
{"local_receipt_timestamp_ns":1704067200000005263,"raw_payload":"{\"arg\":{\"channel\":\"books\",\"instId\":\"BTC-USDT\"},\"data\":[{\"ts\":\"1704067200526\",\"seqId\":525,\"prevSeqId\":524,\"bids\":[[\"50000.0\",\"1.00000000\",\"0\",\"1\"]],\"asks\":[]}]}"}
{"local_receipt_timestamp_ns":1704067200000005273,"raw_payload":"{\"arg\":{\"channel\":\"books\",\"instId\":\"BTC-USDT\"},\"data\":[{\"ts\":\"1704067200527\",\"seqId\":526,\"prevSeqId\":525,\"bids\":[],\"asks\":[[\"50001.0\",\"1.00000000\",\"0\",\"1\"]]}]}"}
{"local_receipt_timestamp_ns":1704067200000005283,"raw_payload":"{\"arg\":{\"channel\":\"books\",\"instId\":\"BTC-USDT\"},\"data\":[{\"ts\":\"1704067200528\",\"seqId\":527,\"prevSeqId\":526,\"bids\":[[\"50000.0\",\"1.00000000\",\"0\",\"1\"]],\"asks\":[]}]}"}
{"local_receipt_timestamp_ns":1704067200000005293,"raw_payload":"{\"arg\":{\"channel\":\"books\",\"instId\":\"BTC-USDT\"},\"data\":[{\"ts\":\"1704067200529\",\"seqId\":528,\"prevSeqId\":527,\"bids\":[],\"asks\":[[\"50001.0\",\"1.00000000\",\"0\",\"1\"]]}]}"}
{"local_receipt_timestamp_ns":1704067200000005303,"raw_payload":"{\"arg\":{\"channel\":\"books\",\"instId\":\"BTC-USDT\"},\"data\":[{\"ts\":\"1704067200530\",\"seqId\":529,\"prevSeqId\":528,\"bids\":[[\"50000.0\",\"1.00000000\",\"0\",\"1\"]],\"asks\":[]}]}"}
{"local_receipt_timestamp_ns":1704067200000005313,"raw_payload":"{\"arg\":{\"channel\":\"books\",\"instId\":\"BTC-USDT\"},\"data\":[{\"ts\":\"1704067200531\",\"seqId\":530,\"prevSeqId\":529,\"bids\":[],\"asks\":[[\"50001.0\",\"1.00000000\",\"0\",\"1\"]]}]}"}
{"local_receipt_timestamp_ns":1704067200000005323,"raw_payload":"{\"arg\":{\"channel\":\"books\",\"instId\":\"BTC-USDT\"},\"data\":[{\"ts\":\"1704067200532\",\"seqId\":531,\"prevSeqId\":530,\"bids\":[[\"50000.0\",\"1.00000000\",\"0\",\"1\"]],\"asks\":[]}]}"}
{"local_receipt_timestamp_ns":1704067200000005333,"raw_payload":"{\"arg\":{\"channel\":\"books\",\"instId\":\"BTC-USDT\"},\"data\":[{\"ts\":\"1704067200533\",\"seqId\":532,\"prevSeqId\":531,\"bids\":[],\"asks\":[[\"50001.0\",\"1.00000000\",\"0\",\"1\"]]}]}"}
{"local_receipt_timestamp_ns":1704067200000005343,"raw_payload":"{\"arg\":{\"channel\":\"books\",\"instId\":\"BTC-USDT\"},\"data\":[{\"ts\":\"1704067200534\",\"seqId\":533,\"prevSeqId\":532,\"bids\":[[\"50000.0\",\"1.00000000\",\"0\",\"1\"]],\"asks\":[]}]}"}
{"local_receipt_timestamp_ns":1704067200000005353,"raw_payload":"{\"arg\":{\"channel\":\"books\",\"instId\":\"BTC-USDT\"},\"data\":[{\"ts\":\"1704067200535\",\"seqId\":534,\"prevSeqId\":533,\"bids\":[],\"asks\":[[\"50001.0\",\"1.00000000\",\"0\",\"1\"]]}]}"}
{"local_receipt_timestamp_ns":1704067200000005363,"raw_payload":"{\"arg\":{\"channel\":\"books\",\"instId\":\"BTC-USDT\"},\"data\":[{\"ts\":\"1704067200536\",\"seqId\":535,\"prevSeqId\":534,\"bids\":[[\"50000.0\",\"1.00000000\",\"0\",\"1\"]],\"asks\":[]}]}"}
{"local_receipt_timestamp_ns":1704067200000005373,"raw_payload":"{\"arg\":{\"channel\":\"books\",\"instId\":\"BTC-USDT\"},\"data\":[{\"ts\":\"1704067200537\",\"seqId\":536,\"prevSeqId\":535,\"bids\":[],\"asks\":[[\"50001.0\",\"1.00000000\",\"0\",\"1\"]]}]}"}
{"local_receipt_timestamp_ns":1704067200000005383,"raw_payload":"{\"arg\":{\"channel\":\"books\",\"instId\":\"BTC-USDT\"},\"data\":[{\"ts\":\"1704067200538\",\"seqId\":537,\"prevSeqId\":536,\"bids\":[[\"50000.0\",\"1.00000000\",\"0\",\"1\"]],\"asks\":[]}]}"}
{"local_receipt_timestamp_ns":1704067200000005393,"raw_payload":"{\"arg\":{\"channel\":\"books\",\"instId\":\"BTC-USDT\"},\"data\":[{\"ts\":\"1704067200539\",\"seqId\":538,\"prevSeqId\":537,\"bids\":[],\"asks\":[[\"50001.0\",\"1.00000000\",\"0\",\"1\"]]}]}"}
{"local_receipt_timestamp_ns":1704067200000005403,"raw_payload":"{\"arg\":{\"channel\":\"books\",\"instId\":\"BTC-USDT\"},\"data\":[{\"ts\":\"1704067200540\",\"seqId\":539,\"prevSeqId\":538,\"bids\":[[\"50000.0\",\"1.00000000\",\"0\",\"1\"]],\"asks\":[]}]}"}
{"local_receipt_timestamp_ns":1704067200000005413,"raw_payload":"{\"arg\":{\"channel\":\"books\",\"instId\":\"BTC-USDT\"},\"data\":[{\"ts\":\"1704067200541\",\"seqId\":540,\"prevSeqId\":539,\"bids\":[],\"asks\":[[\"50001.0\",\"1.00000000\",\"0\",\"1\"]]}]}"}
{"local_receipt_timestamp_ns":1704067200000005423,"raw_payload":"{\"arg\":{\"channel\":\"books\",\"instId\":\"BTC-USDT\"},\"data\":[{\"ts\":\"1704067200542\",\"seqId\":541,\"prevSeqId\":540,\"bids\":[[\"50000.0\",\"1.00000000\",\"0\",\"1\"]],\"asks\":[]}]}"}
{"local_receipt_timestamp_ns":1704067200000005433,"raw_payload":"{\"arg\":{\"channel\":\"books\",\"instId\":\"BTC-USDT\"},\"data\":[{\"ts\":\"1704067200543\",\"seqId\":542,\"prevSeqId\":541,\"bids\":[],\"asks\":[[\"50001.0\",\"1.00000000\",\"0\",\"1\"]]}]}"}
{"local_receipt_timestamp_ns":1704067200000005443,"raw_payload":"{\"arg\":{\"channel\":\"books\",\"instId\":\"BTC-USDT\"},\"data\":[{\"ts\":\"1704067200544\",\"seqId\":543,\"prevSeqId\":542,\"bids\":[[\"50000.0\",\"1.00000000\",\"0\",\"1\"]],\"asks\":[]}]}"}
{"local_receipt_timestamp_ns":1704067200000005453,"raw_payload":"{\"arg\":{\"channel\":\"books\",\"instId\":\"BTC-USDT\"},\"data\":[{\"ts\":\"1704067200545\",\"seqId\":544,\"prevSeqId\":543,\"bids\":[],\"asks\":[[\"50001.0\",\"1.00000000\",\"0\",\"1\"]]}]}"}
{"local_receipt_timestamp_ns":1704067200000005463,"raw_payload":"{\"arg\":{\"channel\":\"books\",\"instId\":\"BTC-USDT\"},\"data\":[{\"ts\":\"1704067200546\",\"seqId\":545,\"prevSeqId\":544,\"bids\":[[\"50000.0\",\"1.00000000\",\"0\",\"1\"]],\"asks\":[]}]}"}
{"local_receipt_timestamp_ns":1704067200000005473,"raw_payload":"{\"arg\":{\"channel\":\"books\",\"instId\":\"BTC-USDT\"},\"data\":[{\"ts\":\"1704067200547\",\"seqId\":546,\"prevSeqId\":545,\"bids\":[],\"asks\":[[\"50001.0\",\"1.00000000\",\"0\",\"1\"]]}]}"}
{"local_receipt_timestamp_ns":1704067200000005483,"raw_payload":"{\"arg\":{\"channel\":\"books\",\"instId\":\"BTC-USDT\"},\"data\":[{\"ts\":\"1704067200548\",\"seqId\":547,\"prevSeqId\":546,\"bids\":[[\"50000.0\",\"1.00000000\",\"0\",\"1\"]],\"asks\":[]}]}"}
{"local_receipt_timestamp_ns":1704067200000005493,"raw_payload":"{\"arg\":{\"channel\":\"books\",\"instId\":\"BTC-USDT\"},\"data\":[{\"ts\":\"1704067200549\",\"seqId\":548,\"prevSeqId\":547,\"bids\":[],\"asks\":[[\"50001.0\",\"1.00000000\",\"0\",\"1\"]]}]}"}
{"local_receipt_timestamp_ns":1704067200000005503,"raw_payload":"{\"arg\":{\"channel\":\"books\",\"instId\":\"BTC-USDT\"},\"data\":[{\"ts\":\"1704067200550\",\"seqId\":549,\"prevSeqId\":548,\"bids\":[[\"50000.0\",\"1.00000000\",\"0\",\"1\"]],\"asks\":[]}]}"}
{"local_receipt_timestamp_ns":1704067200000005513,"raw_payload":"{\"arg\":{\"channel\":\"books\",\"instId\":\"BTC-USDT\"},\"data\":[{\"ts\":\"1704067200551\",\"seqId\":550,\"prevSeqId\":549,\"bids\":[],\"asks\":[[\"50001.0\",\"1.00000000\",\"0\",\"1\"]]}]}"}
{"local_receipt_timestamp_ns":1704067200000005523,"raw_payload":"{\"arg\":{\"channel\":\"books\",\"instId\":\"BTC-USDT\"},\"data\":[{\"ts\":\"1704067200552\",\"seqId\":551,\"prevSeqId\":550,\"bids\":[[\"50000.0\",\"1.00000000\",\"0\",\"1\"]],\"asks\":[]}]}"}
{"local_receipt_timestamp_ns":1704067200000005533,"raw_payload":"{\"arg\":{\"channel\":\"books\",\"instId\":\"BTC-USDT\"},\"data\":[{\"ts\":\"1704067200553\",\"seqId\":552,\"prevSeqId\":551,\"bids\":[],\"asks\":[[\"50001.0\",\"1.00000000\",\"0\",\"1\"]]}]}"}
{"local_receipt_timestamp_ns":1704067200000005543,"raw_payload":"{\"arg\":{\"channel\":\"books\",\"instId\":\"BTC-USDT\"},\"data\":[{\"ts\":\"1704067200554\",\"seqId\":553,\"prevSeqId\":552,\"bids\":[[\"50000.0\",\"1.00000000\",\"0\",\"1\"]],\"asks\":[]}]}"}
{"local_receipt_timestamp_ns":1704067200000005553,"raw_payload":"{\"arg\":{\"channel\":\"books\",\"instId\":\"BTC-USDT\"},\"data\":[{\"ts\":\"1704067200555\",\"seqId\":554,\"prevSeqId\":553,\"bids\":[],\"asks\":[[\"50001.0\",\"1.00000000\",\"0\",\"1\"]]}]}"}
{"local_receipt_timestamp_ns":1704067200000005563,"raw_payload":"{\"arg\":{\"channel\":\"books\",\"instId\":\"BTC-USDT\"},\"data\":[{\"ts\":\"1704067200556\",\"seqId\":555,\"prevSeqId\":554,\"bids\":[[\"50000.0\",\"1.00000000\",\"0\",\"1\"]],\"asks\":[]}]}"}
{"local_receipt_timestamp_ns":1704067200000005573,"raw_payload":"{\"arg\":{\"channel\":\"books\",\"instId\":\"BTC-USDT\"},\"data\":[{\"ts\":\"1704067200557\",\"seqId\":556,\"prevSeqId\":555,\"bids\":[],\"asks\":[[\"50001.0\",\"1.00000000\",\"0\",\"1\"]]}]}"}
{"local_receipt_timestamp_ns":1704067200000005583,"raw_payload":"{\"arg\":{\"channel\":\"books\",\"instId\":\"BTC-USDT\"},\"data\":[{\"ts\":\"1704067200558\",\"seqId\":557,\"prevSeqId\":556,\"bids\":[[\"50000.0\",\"1.00000000\",\"0\",\"1\"]],\"asks\":[]}]}"}
{"local_receipt_timestamp_ns":1704067200000005593,"raw_payload":"{\"arg\":{\"channel\":\"books\",\"instId\":\"BTC-USDT\"},\"data\":[{\"ts\":\"1704067200559\",\"seqId\":558,\"prevSeqId\":557,\"bids\":[],\"asks\":[[\"50001.0\",\"1.00000000\",\"0\",\"1\"]]}]}"}
{"local_receipt_timestamp_ns":1704067200000005603,"raw_payload":"{\"arg\":{\"channel\":\"books\",\"instId\":\"BTC-USDT\"},\"data\":[{\"ts\":\"1704067200560\",\"seqId\":559,\"prevSeqId\":558,\"bids\":[[\"50000.0\",\"1.00000000\",\"0\",\"1\"]],\"asks\":[]}]}"}
{"local_receipt_timestamp_ns":1704067200000005613,"raw_payload":"{\"arg\":{\"channel\":\"books\",\"instId\":\"BTC-USDT\"},\"data\":[{\"ts\":\"1704067200561\",\"seqId\":560,\"prevSeqId\":559,\"bids\":[],\"asks\":[[\"50001.0\",\"1.00000000\",\"0\",\"1\"]]}]}"}
{"local_receipt_timestamp_ns":1704067200000005623,"raw_payload":"{\"arg\":{\"channel\":\"books\",\"instId\":\"BTC-USDT\"},\"data\":[{\"ts\":\"1704067200562\",\"seqId\":561,\"prevSeqId\":560,\"bids\":[[\"50000.0\",\"1.00000000\",\"0\",\"1\"]],\"asks\":[]}]}"}
{"local_receipt_timestamp_ns":1704067200000005633,"raw_payload":"{\"arg\":{\"channel\":\"books\",\"instId\":\"BTC-USDT\"},\"data\":[{\"ts\":\"1704067200563\",\"seqId\":562,\"prevSeqId\":561,\"bids\":[],\"asks\":[[\"50001.0\",\"1.00000000\",\"0\",\"1\"]]}]}"}
{"local_receipt_timestamp_ns":1704067200000005643,"raw_payload":"{\"arg\":{\"channel\":\"books\",\"instId\":\"BTC-USDT\"},\"data\":[{\"ts\":\"1704067200564\",\"seqId\":563,\"prevSeqId\":562,\"bids\":[[\"50000.0\",\"1.00000000\",\"0\",\"1\"]],\"asks\":[]}]}"}
{"local_receipt_timestamp_ns":1704067200000005653,"raw_payload":"{\"arg\":{\"channel\":\"books\",\"instId\":\"BTC-USDT\"},\"data\":[{\"ts\":\"1704067200565\",\"seqId\":564,\"prevSeqId\":563,\"bids\":[],\"asks\":[[\"50001.0\",\"1.00000000\",\"0\",\"1\"]]}]}"}
{"local_receipt_timestamp_ns":1704067200000005663,"raw_payload":"{\"arg\":{\"channel\":\"books\",\"instId\":\"BTC-USDT\"},\"data\":[{\"ts\":\"1704067200566\",\"seqId\":565,\"prevSeqId\":564,\"bids\":[[\"50000.0\",\"1.00000000\",\"0\",\"1\"]],\"asks\":[]}]}"}
{"local_receipt_timestamp_ns":1704067200000005673,"raw_payload":"{\"arg\":{\"channel\":\"books\",\"instId\":\"BTC-USDT\"},\"data\":[{\"ts\":\"1704067200567\",\"seqId\":566,\"prevSeqId\":565,\"bids\":[],\"asks\":[[\"50001.0\",\"1.00000000\",\"0\",\"1\"]]}]}"}
{"local_receipt_timestamp_ns":1704067200000005683,"raw_payload":"{\"arg\":{\"channel\":\"books\",\"instId\":\"BTC-USDT\"},\"data\":[{\"ts\":\"1704067200568\",\"seqId\":567,\"prevSeqId\":566,\"bids\":[[\"50000.0\",\"1.00000000\",\"0\",\"1\"]],\"asks\":[]}]}"}
{"local_receipt_timestamp_ns":1704067200000005693,"raw_payload":"{\"arg\":{\"channel\":\"books\",\"instId\":\"BTC-USDT\"},\"data\":[{\"ts\":\"1704067200569\",\"seqId\":568,\"prevSeqId\":567,\"bids\":[],\"asks\":[[\"50001.0\",\"1.00000000\",\"0\",\"1\"]]}]}"}
{"local_receipt_timestamp_ns":1704067200000005703,"raw_payload":"{\"arg\":{\"channel\":\"books\",\"instId\":\"BTC-USDT\"},\"data\":[{\"ts\":\"1704067200570\",\"seqId\":569,\"prevSeqId\":568,\"bids\":[[\"50000.0\",\"1.00000000\",\"0\",\"1\"]],\"asks\":[]}]}"}
{"local_receipt_timestamp_ns":1704067200000005713,"raw_payload":"{\"arg\":{\"channel\":\"books\",\"instId\":\"BTC-USDT\"},\"data\":[{\"ts\":\"1704067200571\",\"seqId\":570,\"prevSeqId\":569,\"bids\":[],\"asks\":[[\"50001.0\",\"1.00000000\",\"0\",\"1\"]]}]}"}
{"local_receipt_timestamp_ns":1704067200000005723,"raw_payload":"{\"arg\":{\"channel\":\"books\",\"instId\":\"BTC-USDT\"},\"data\":[{\"ts\":\"1704067200572\",\"seqId\":571,\"prevSeqId\":570,\"bids\":[[\"50000.0\",\"1.00000000\",\"0\",\"1\"]],\"asks\":[]}]}"}
{"local_receipt_timestamp_ns":1704067200000005733,"raw_payload":"{\"arg\":{\"channel\":\"books\",\"instId\":\"BTC-USDT\"},\"data\":[{\"ts\":\"1704067200573\",\"seqId\":572,\"prevSeqId\":571,\"bids\":[],\"asks\":[[\"50001.0\",\"1.00000000\",\"0\",\"1\"]]}]}"}
{"local_receipt_timestamp_ns":1704067200000005743,"raw_payload":"{\"arg\":{\"channel\":\"books\",\"instId\":\"BTC-USDT\"},\"data\":[{\"ts\":\"1704067200574\",\"seqId\":573,\"prevSeqId\":572,\"bids\":[[\"50000.0\",\"1.00000000\",\"0\",\"1\"]],\"asks\":[]}]}"}
{"local_receipt_timestamp_ns":1704067200000005753,"raw_payload":"{\"arg\":{\"channel\":\"books\",\"instId\":\"BTC-USDT\"},\"data\":[{\"ts\":\"1704067200575\",\"seqId\":574,\"prevSeqId\":573,\"bids\":[],\"asks\":[[\"50001.0\",\"1.00000000\",\"0\",\"1\"]]}]}"}
{"local_receipt_timestamp_ns":1704067200000005763,"raw_payload":"{\"arg\":{\"channel\":\"books\",\"instId\":\"BTC-USDT\"},\"data\":[{\"ts\":\"1704067200576\",\"seqId\":575,\"prevSeqId\":574,\"bids\":[[\"50000.0\",\"1.00000000\",\"0\",\"1\"]],\"asks\":[]}]}"}
{"local_receipt_timestamp_ns":1704067200000005773,"raw_payload":"{\"arg\":{\"channel\":\"books\",\"instId\":\"BTC-USDT\"},\"data\":[{\"ts\":\"1704067200577\",\"seqId\":576,\"prevSeqId\":575,\"bids\":[],\"asks\":[[\"50001.0\",\"1.00000000\",\"0\",\"1\"]]}]}"}
{"local_receipt_timestamp_ns":1704067200000005783,"raw_payload":"{\"arg\":{\"channel\":\"books\",\"instId\":\"BTC-USDT\"},\"data\":[{\"ts\":\"1704067200578\",\"seqId\":577,\"prevSeqId\":576,\"bids\":[[\"50000.0\",\"1.00000000\",\"0\",\"1\"]],\"asks\":[]}]}"}
{"local_receipt_timestamp_ns":1704067200000005793,"raw_payload":"{\"arg\":{\"channel\":\"books\",\"instId\":\"BTC-USDT\"},\"data\":[{\"ts\":\"1704067200579\",\"seqId\":578,\"prevSeqId\":577,\"bids\":[],\"asks\":[[\"50001.0\",\"1.00000000\",\"0\",\"1\"]]}]}"}
{"local_receipt_timestamp_ns":1704067200000005803,"raw_payload":"{\"arg\":{\"channel\":\"books\",\"instId\":\"BTC-USDT\"},\"data\":[{\"ts\":\"1704067200580\",\"seqId\":579,\"prevSeqId\":578,\"bids\":[[\"50000.0\",\"1.00000000\",\"0\",\"1\"]],\"asks\":[]}]}"}
{"local_receipt_timestamp_ns":1704067200000005813,"raw_payload":"{\"arg\":{\"channel\":\"books\",\"instId\":\"BTC-USDT\"},\"data\":[{\"ts\":\"1704067200581\",\"seqId\":580,\"prevSeqId\":579,\"bids\":[],\"asks\":[[\"50001.0\",\"1.00000000\",\"0\",\"1\"]]}]}"}
{"local_receipt_timestamp_ns":1704067200000005823,"raw_payload":"{\"arg\":{\"channel\":\"books\",\"instId\":\"BTC-USDT\"},\"data\":[{\"ts\":\"1704067200582\",\"seqId\":581,\"prevSeqId\":580,\"bids\":[[\"50000.0\",\"1.00000000\",\"0\",\"1\"]],\"asks\":[]}]}"}
{"local_receipt_timestamp_ns":1704067200000005833,"raw_payload":"{\"arg\":{\"channel\":\"books\",\"instId\":\"BTC-USDT\"},\"data\":[{\"ts\":\"1704067200583\",\"seqId\":582,\"prevSeqId\":581,\"bids\":[],\"asks\":[[\"50001.0\",\"1.00000000\",\"0\",\"1\"]]}]}"}
{"local_receipt_timestamp_ns":1704067200000005843,"raw_payload":"{\"arg\":{\"channel\":\"books\",\"instId\":\"BTC-USDT\"},\"data\":[{\"ts\":\"1704067200584\",\"seqId\":583,\"prevSeqId\":582,\"bids\":[[\"50000.0\",\"1.00000000\",\"0\",\"1\"]],\"asks\":[]}]}"}
{"local_receipt_timestamp_ns":1704067200000005853,"raw_payload":"{\"arg\":{\"channel\":\"books\",\"instId\":\"BTC-USDT\"},\"data\":[{\"ts\":\"1704067200585\",\"seqId\":584,\"prevSeqId\":583,\"bids\":[],\"asks\":[[\"50001.0\",\"1.00000000\",\"0\",\"1\"]]}]}"}
{"local_receipt_timestamp_ns":1704067200000005863,"raw_payload":"{\"arg\":{\"channel\":\"books\",\"instId\":\"BTC-USDT\"},\"data\":[{\"ts\":\"1704067200586\",\"seqId\":585,\"prevSeqId\":584,\"bids\":[[\"50000.0\",\"1.00000000\",\"0\",\"1\"]],\"asks\":[]}]}"}
{"local_receipt_timestamp_ns":1704067200000005873,"raw_payload":"{\"arg\":{\"channel\":\"books\",\"instId\":\"BTC-USDT\"},\"data\":[{\"ts\":\"1704067200587\",\"seqId\":586,\"prevSeqId\":585,\"bids\":[],\"asks\":[[\"50001.0\",\"1.00000000\",\"0\",\"1\"]]}]}"}
{"local_receipt_timestamp_ns":1704067200000005883,"raw_payload":"{\"arg\":{\"channel\":\"books\",\"instId\":\"BTC-USDT\"},\"data\":[{\"ts\":\"1704067200588\",\"seqId\":587,\"prevSeqId\":586,\"bids\":[[\"50000.0\",\"1.00000000\",\"0\",\"1\"]],\"asks\":[]}]}"}
{"local_receipt_timestamp_ns":1704067200000005893,"raw_payload":"{\"arg\":{\"channel\":\"books\",\"instId\":\"BTC-USDT\"},\"data\":[{\"ts\":\"1704067200589\",\"seqId\":588,\"prevSeqId\":587,\"bids\":[],\"asks\":[[\"50001.0\",\"1.00000000\",\"0\",\"1\"]]}]}"}
{"local_receipt_timestamp_ns":1704067200000005903,"raw_payload":"{\"arg\":{\"channel\":\"books\",\"instId\":\"BTC-USDT\"},\"data\":[{\"ts\":\"1704067200590\",\"seqId\":589,\"prevSeqId\":588,\"bids\":[[\"50000.0\",\"1.00000000\",\"0\",\"1\"]],\"asks\":[]}]}"}
{"local_receipt_timestamp_ns":1704067200000005913,"raw_payload":"{\"arg\":{\"channel\":\"books\",\"instId\":\"BTC-USDT\"},\"data\":[{\"ts\":\"1704067200591\",\"seqId\":590,\"prevSeqId\":589,\"bids\":[],\"asks\":[[\"50001.0\",\"1.00000000\",\"0\",\"1\"]]}]}"}
{"local_receipt_timestamp_ns":1704067200000005923,"raw_payload":"{\"arg\":{\"channel\":\"books\",\"instId\":\"BTC-USDT\"},\"data\":[{\"ts\":\"1704067200592\",\"seqId\":591,\"prevSeqId\":590,\"bids\":[[\"50000.0\",\"1.00000000\",\"0\",\"1\"]],\"asks\":[]}]}"}
{"local_receipt_timestamp_ns":1704067200000005933,"raw_payload":"{\"arg\":{\"channel\":\"books\",\"instId\":\"BTC-USDT\"},\"data\":[{\"ts\":\"1704067200593\",\"seqId\":592,\"prevSeqId\":591,\"bids\":[],\"asks\":[[\"50001.0\",\"1.00000000\",\"0\",\"1\"]]}]}"}
{"local_receipt_timestamp_ns":1704067200000005943,"raw_payload":"{\"arg\":{\"channel\":\"books\",\"instId\":\"BTC-USDT\"},\"data\":[{\"ts\":\"1704067200594\",\"seqId\":593,\"prevSeqId\":592,\"bids\":[[\"50000.0\",\"1.00000000\",\"0\",\"1\"]],\"asks\":[]}]}"}
{"local_receipt_timestamp_ns":1704067200000005953,"raw_payload":"{\"arg\":{\"channel\":\"books\",\"instId\":\"BTC-USDT\"},\"data\":[{\"ts\":\"1704067200595\",\"seqId\":594,\"prevSeqId\":593,\"bids\":[],\"asks\":[[\"50001.0\",\"1.00000000\",\"0\",\"1\"]]}]}"}
{"local_receipt_timestamp_ns":1704067200000005963,"raw_payload":"{\"arg\":{\"channel\":\"books\",\"instId\":\"BTC-USDT\"},\"data\":[{\"ts\":\"1704067200596\",\"seqId\":595,\"prevSeqId\":594,\"bids\":[[\"50000.0\",\"1.00000000\",\"0\",\"1\"]],\"asks\":[]}]}"}
{"local_receipt_timestamp_ns":1704067200000005973,"raw_payload":"{\"arg\":{\"channel\":\"books\",\"instId\":\"BTC-USDT\"},\"data\":[{\"ts\":\"1704067200597\",\"seqId\":596,\"prevSeqId\":595,\"bids\":[],\"asks\":[[\"50001.0\",\"1.00000000\",\"0\",\"1\"]]}]}"}
{"local_receipt_timestamp_ns":1704067200000005983,"raw_payload":"{\"arg\":{\"channel\":\"books\",\"instId\":\"BTC-USDT\"},\"data\":[{\"ts\":\"1704067200598\",\"seqId\":597,\"prevSeqId\":596,\"bids\":[[\"50000.0\",\"1.00000000\",\"0\",\"1\"]],\"asks\":[]}]}"}
{"local_receipt_timestamp_ns":1704067200000005993,"raw_payload":"{\"arg\":{\"channel\":\"books\",\"instId\":\"BTC-USDT\"},\"data\":[{\"ts\":\"1704067200599\",\"seqId\":598,\"prevSeqId\":597,\"bids\":[],\"asks\":[[\"50001.0\",\"1.00000000\",\"0\",\"1\"]]}]}"}
{"local_receipt_timestamp_ns":1704067200000006003,"raw_payload":"{\"arg\":{\"channel\":\"books\",\"instId\":\"BTC-USDT\"},\"data\":[{\"ts\":\"1704067200600\",\"seqId\":599,\"prevSeqId\":598,\"bids\":[[\"50000.0\",\"1.00000000\",\"0\",\"1\"]],\"asks\":[]}]}"}
{"local_receipt_timestamp_ns":1704067200000006013,"raw_payload":"{\"arg\":{\"channel\":\"books\",\"instId\":\"BTC-USDT\"},\"data\":[{\"ts\":\"1704067200601\",\"seqId\":600,\"prevSeqId\":599,\"bids\":[],\"asks\":[[\"50001.0\",\"1.00000000\",\"0\",\"1\"]]}]}"}
{"local_receipt_timestamp_ns":1704067200000006023,"raw_payload":"{\"arg\":{\"channel\":\"books\",\"instId\":\"BTC-USDT\"},\"data\":[{\"ts\":\"1704067200602\",\"seqId\":601,\"prevSeqId\":600,\"bids\":[[\"50000.0\",\"1.00000000\",\"0\",\"1\"]],\"asks\":[]}]}"}
{"local_receipt_timestamp_ns":1704067200000006033,"raw_payload":"{\"arg\":{\"channel\":\"books\",\"instId\":\"BTC-USDT\"},\"data\":[{\"ts\":\"1704067200603\",\"seqId\":602,\"prevSeqId\":601,\"bids\":[],\"asks\":[[\"50001.0\",\"1.00000000\",\"0\",\"1\"]]}]}"}
{"local_receipt_timestamp_ns":1704067200000006043,"raw_payload":"{\"arg\":{\"channel\":\"books\",\"instId\":\"BTC-USDT\"},\"data\":[{\"ts\":\"1704067200604\",\"seqId\":603,\"prevSeqId\":602,\"bids\":[[\"50000.0\",\"1.00000000\",\"0\",\"1\"]],\"asks\":[]}]}"}
{"local_receipt_timestamp_ns":1704067200000006053,"raw_payload":"{\"arg\":{\"channel\":\"books\",\"instId\":\"BTC-USDT\"},\"data\":[{\"ts\":\"1704067200605\",\"seqId\":604,\"prevSeqId\":603,\"bids\":[],\"asks\":[[\"50001.0\",\"1.00000000\",\"0\",\"1\"]]}]}"}
{"local_receipt_timestamp_ns":1704067200000006063,"raw_payload":"{\"arg\":{\"channel\":\"books\",\"instId\":\"BTC-USDT\"},\"data\":[{\"ts\":\"1704067200606\",\"seqId\":605,\"prevSeqId\":604,\"bids\":[[\"50000.0\",\"1.00000000\",\"0\",\"1\"]],\"asks\":[]}]}"}
{"local_receipt_timestamp_ns":1704067200000006073,"raw_payload":"{\"arg\":{\"channel\":\"books\",\"instId\":\"BTC-USDT\"},\"data\":[{\"ts\":\"1704067200607\",\"seqId\":606,\"prevSeqId\":605,\"bids\":[],\"asks\":[[\"50001.0\",\"1.00000000\",\"0\",\"1\"]]}]}"}
{"local_receipt_timestamp_ns":1704067200000006083,"raw_payload":"{\"arg\":{\"channel\":\"books\",\"instId\":\"BTC-USDT\"},\"data\":[{\"ts\":\"1704067200608\",\"seqId\":607,\"prevSeqId\":606,\"bids\":[[\"50000.0\",\"1.00000000\",\"0\",\"1\"]],\"asks\":[]}]}"}
{"local_receipt_timestamp_ns":1704067200000006093,"raw_payload":"{\"arg\":{\"channel\":\"books\",\"instId\":\"BTC-USDT\"},\"data\":[{\"ts\":\"1704067200609\",\"seqId\":608,\"prevSeqId\":607,\"bids\":[],\"asks\":[[\"50001.0\",\"1.00000000\",\"0\",\"1\"]]}]}"}
{"local_receipt_timestamp_ns":1704067200000006103,"raw_payload":"{\"arg\":{\"channel\":\"books\",\"instId\":\"BTC-USDT\"},\"data\":[{\"ts\":\"1704067200610\",\"seqId\":609,\"prevSeqId\":608,\"bids\":[[\"50000.0\",\"1.00000000\",\"0\",\"1\"]],\"asks\":[]}]}"}
{"local_receipt_timestamp_ns":1704067200000006113,"raw_payload":"{\"arg\":{\"channel\":\"books\",\"instId\":\"BTC-USDT\"},\"data\":[{\"ts\":\"1704067200611\",\"seqId\":610,\"prevSeqId\":609,\"bids\":[],\"asks\":[[\"50001.0\",\"1.00000000\",\"0\",\"1\"]]}]}"}
{"local_receipt_timestamp_ns":1704067200000006123,"raw_payload":"{\"arg\":{\"channel\":\"books\",\"instId\":\"BTC-USDT\"},\"data\":[{\"ts\":\"1704067200612\",\"seqId\":611,\"prevSeqId\":610,\"bids\":[[\"50000.0\",\"1.00000000\",\"0\",\"1\"]],\"asks\":[]}]}"}
{"local_receipt_timestamp_ns":1704067200000006133,"raw_payload":"{\"arg\":{\"channel\":\"books\",\"instId\":\"BTC-USDT\"},\"data\":[{\"ts\":\"1704067200613\",\"seqId\":612,\"prevSeqId\":611,\"bids\":[],\"asks\":[[\"50001.0\",\"1.00000000\",\"0\",\"1\"]]}]}"}
{"local_receipt_timestamp_ns":1704067200000006143,"raw_payload":"{\"arg\":{\"channel\":\"books\",\"instId\":\"BTC-USDT\"},\"data\":[{\"ts\":\"1704067200614\",\"seqId\":613,\"prevSeqId\":612,\"bids\":[[\"50000.0\",\"1.00000000\",\"0\",\"1\"]],\"asks\":[]}]}"}
{"local_receipt_timestamp_ns":1704067200000006153,"raw_payload":"{\"arg\":{\"channel\":\"books\",\"instId\":\"BTC-USDT\"},\"data\":[{\"ts\":\"1704067200615\",\"seqId\":614,\"prevSeqId\":613,\"bids\":[],\"asks\":[[\"50001.0\",\"1.00000000\",\"0\",\"1\"]]}]}"}
{"local_receipt_timestamp_ns":1704067200000006163,"raw_payload":"{\"arg\":{\"channel\":\"books\",\"instId\":\"BTC-USDT\"},\"data\":[{\"ts\":\"1704067200616\",\"seqId\":615,\"prevSeqId\":614,\"bids\":[[\"50000.0\",\"1.00000000\",\"0\",\"1\"]],\"asks\":[]}]}"}
{"local_receipt_timestamp_ns":1704067200000006173,"raw_payload":"{\"arg\":{\"channel\":\"books\",\"instId\":\"BTC-USDT\"},\"data\":[{\"ts\":\"1704067200617\",\"seqId\":616,\"prevSeqId\":615,\"bids\":[],\"asks\":[[\"50001.0\",\"1.00000000\",\"0\",\"1\"]]}]}"}
{"local_receipt_timestamp_ns":1704067200000006183,"raw_payload":"{\"arg\":{\"channel\":\"books\",\"instId\":\"BTC-USDT\"},\"data\":[{\"ts\":\"1704067200618\",\"seqId\":617,\"prevSeqId\":616,\"bids\":[[\"50000.0\",\"1.00000000\",\"0\",\"1\"]],\"asks\":[]}]}"}
{"local_receipt_timestamp_ns":1704067200000006193,"raw_payload":"{\"arg\":{\"channel\":\"books\",\"instId\":\"BTC-USDT\"},\"data\":[{\"ts\":\"1704067200619\",\"seqId\":618,\"prevSeqId\":617,\"bids\":[],\"asks\":[[\"50001.0\",\"1.00000000\",\"0\",\"1\"]]}]}"}
{"local_receipt_timestamp_ns":1704067200000006203,"raw_payload":"{\"arg\":{\"channel\":\"books\",\"instId\":\"BTC-USDT\"},\"data\":[{\"ts\":\"1704067200620\",\"seqId\":619,\"prevSeqId\":618,\"bids\":[[\"50000.0\",\"1.00000000\",\"0\",\"1\"]],\"asks\":[]}]}"}
{"local_receipt_timestamp_ns":1704067200000006213,"raw_payload":"{\"arg\":{\"channel\":\"books\",\"instId\":\"BTC-USDT\"},\"data\":[{\"ts\":\"1704067200621\",\"seqId\":620,\"prevSeqId\":619,\"bids\":[],\"asks\":[[\"50001.0\",\"1.00000000\",\"0\",\"1\"]]}]}"}
{"local_receipt_timestamp_ns":1704067200000006223,"raw_payload":"{\"arg\":{\"channel\":\"books\",\"instId\":\"BTC-USDT\"},\"data\":[{\"ts\":\"1704067200622\",\"seqId\":621,\"prevSeqId\":620,\"bids\":[[\"50000.0\",\"1.00000000\",\"0\",\"1\"]],\"asks\":[]}]}"}
{"local_receipt_timestamp_ns":1704067200000006233,"raw_payload":"{\"arg\":{\"channel\":\"books\",\"instId\":\"BTC-USDT\"},\"data\":[{\"ts\":\"1704067200623\",\"seqId\":622,\"prevSeqId\":621,\"bids\":[],\"asks\":[[\"50001.0\",\"1.00000000\",\"0\",\"1\"]]}]}"}
{"local_receipt_timestamp_ns":1704067200000006243,"raw_payload":"{\"arg\":{\"channel\":\"books\",\"instId\":\"BTC-USDT\"},\"data\":[{\"ts\":\"1704067200624\",\"seqId\":623,\"prevSeqId\":622,\"bids\":[[\"50000.0\",\"1.00000000\",\"0\",\"1\"]],\"asks\":[]}]}"}
{"local_receipt_timestamp_ns":1704067200000006253,"raw_payload":"{\"arg\":{\"channel\":\"books\",\"instId\":\"BTC-USDT\"},\"data\":[{\"ts\":\"1704067200625\",\"seqId\":624,\"prevSeqId\":623,\"bids\":[],\"asks\":[[\"50001.0\",\"1.00000000\",\"0\",\"1\"]]}]}"}
{"local_receipt_timestamp_ns":1704067200000006263,"raw_payload":"{\"arg\":{\"channel\":\"books\",\"instId\":\"BTC-USDT\"},\"data\":[{\"ts\":\"1704067200626\",\"seqId\":625,\"prevSeqId\":624,\"bids\":[[\"50000.0\",\"1.00000000\",\"0\",\"1\"]],\"asks\":[]}]}"}
{"local_receipt_timestamp_ns":1704067200000006273,"raw_payload":"{\"arg\":{\"channel\":\"books\",\"instId\":\"BTC-USDT\"},\"data\":[{\"ts\":\"1704067200627\",\"seqId\":626,\"prevSeqId\":625,\"bids\":[],\"asks\":[[\"50001.0\",\"1.00000000\",\"0\",\"1\"]]}]}"}
{"local_receipt_timestamp_ns":1704067200000006283,"raw_payload":"{\"arg\":{\"channel\":\"books\",\"instId\":\"BTC-USDT\"},\"data\":[{\"ts\":\"1704067200628\",\"seqId\":627,\"prevSeqId\":626,\"bids\":[[\"50000.0\",\"1.00000000\",\"0\",\"1\"]],\"asks\":[]}]}"}
{"local_receipt_timestamp_ns":1704067200000006293,"raw_payload":"{\"arg\":{\"channel\":\"books\",\"instId\":\"BTC-USDT\"},\"data\":[{\"ts\":\"1704067200629\",\"seqId\":628,\"prevSeqId\":627,\"bids\":[],\"asks\":[[\"50001.0\",\"1.00000000\",\"0\",\"1\"]]}]}"}
{"local_receipt_timestamp_ns":1704067200000006303,"raw_payload":"{\"arg\":{\"channel\":\"books\",\"instId\":\"BTC-USDT\"},\"data\":[{\"ts\":\"1704067200630\",\"seqId\":629,\"prevSeqId\":628,\"bids\":[[\"50000.0\",\"1.00000000\",\"0\",\"1\"]],\"asks\":[]}]}"}
{"local_receipt_timestamp_ns":1704067200000006313,"raw_payload":"{\"arg\":{\"channel\":\"books\",\"instId\":\"BTC-USDT\"},\"data\":[{\"ts\":\"1704067200631\",\"seqId\":630,\"prevSeqId\":629,\"bids\":[],\"asks\":[[\"50001.0\",\"1.00000000\",\"0\",\"1\"]]}]}"}
{"local_receipt_timestamp_ns":1704067200000006323,"raw_payload":"{\"arg\":{\"channel\":\"books\",\"instId\":\"BTC-USDT\"},\"data\":[{\"ts\":\"1704067200632\",\"seqId\":631,\"prevSeqId\":630,\"bids\":[[\"50000.0\",\"1.00000000\",\"0\",\"1\"]],\"asks\":[]}]}"}
{"local_receipt_timestamp_ns":1704067200000006333,"raw_payload":"{\"arg\":{\"channel\":\"books\",\"instId\":\"BTC-USDT\"},\"data\":[{\"ts\":\"1704067200633\",\"seqId\":632,\"prevSeqId\":631,\"bids\":[],\"asks\":[[\"50001.0\",\"1.00000000\",\"0\",\"1\"]]}]}"}
{"local_receipt_timestamp_ns":1704067200000006343,"raw_payload":"{\"arg\":{\"channel\":\"books\",\"instId\":\"BTC-USDT\"},\"data\":[{\"ts\":\"1704067200634\",\"seqId\":633,\"prevSeqId\":632,\"bids\":[[\"50000.0\",\"1.00000000\",\"0\",\"1\"]],\"asks\":[]}]}"}
{"local_receipt_timestamp_ns":1704067200000006353,"raw_payload":"{\"arg\":{\"channel\":\"books\",\"instId\":\"BTC-USDT\"},\"data\":[{\"ts\":\"1704067200635\",\"seqId\":634,\"prevSeqId\":633,\"bids\":[],\"asks\":[[\"50001.0\",\"1.00000000\",\"0\",\"1\"]]}]}"}
{"local_receipt_timestamp_ns":1704067200000006363,"raw_payload":"{\"arg\":{\"channel\":\"books\",\"instId\":\"BTC-USDT\"},\"data\":[{\"ts\":\"1704067200636\",\"seqId\":635,\"prevSeqId\":634,\"bids\":[[\"50000.0\",\"1.00000000\",\"0\",\"1\"]],\"asks\":[]}]}"}
{"local_receipt_timestamp_ns":1704067200000006373,"raw_payload":"{\"arg\":{\"channel\":\"books\",\"instId\":\"BTC-USDT\"},\"data\":[{\"ts\":\"1704067200637\",\"seqId\":636,\"prevSeqId\":635,\"bids\":[],\"asks\":[[\"50001.0\",\"1.00000000\",\"0\",\"1\"]]}]}"}
{"local_receipt_timestamp_ns":1704067200000006383,"raw_payload":"{\"arg\":{\"channel\":\"books\",\"instId\":\"BTC-USDT\"},\"data\":[{\"ts\":\"1704067200638\",\"seqId\":637,\"prevSeqId\":636,\"bids\":[[\"50000.0\",\"1.00000000\",\"0\",\"1\"]],\"asks\":[]}]}"}
{"local_receipt_timestamp_ns":1704067200000006393,"raw_payload":"{\"arg\":{\"channel\":\"books\",\"instId\":\"BTC-USDT\"},\"data\":[{\"ts\":\"1704067200639\",\"seqId\":638,\"prevSeqId\":637,\"bids\":[],\"asks\":[[\"50001.0\",\"1.00000000\",\"0\",\"1\"]]}]}"}
{"local_receipt_timestamp_ns":1704067200000006403,"raw_payload":"{\"arg\":{\"channel\":\"books\",\"instId\":\"BTC-USDT\"},\"data\":[{\"ts\":\"1704067200640\",\"seqId\":639,\"prevSeqId\":638,\"bids\":[[\"50000.0\",\"1.00000000\",\"0\",\"1\"]],\"asks\":[]}]}"}
{"local_receipt_timestamp_ns":1704067200000006413,"raw_payload":"{\"arg\":{\"channel\":\"books\",\"instId\":\"BTC-USDT\"},\"data\":[{\"ts\":\"1704067200641\",\"seqId\":640,\"prevSeqId\":639,\"bids\":[],\"asks\":[[\"50001.0\",\"1.00000000\",\"0\",\"1\"]]}]}"}
{"local_receipt_timestamp_ns":1704067200000006423,"raw_payload":"{\"arg\":{\"channel\":\"books\",\"instId\":\"BTC-USDT\"},\"data\":[{\"ts\":\"1704067200642\",\"seqId\":641,\"prevSeqId\":640,\"bids\":[[\"50000.0\",\"1.00000000\",\"0\",\"1\"]],\"asks\":[]}]}"}
{"local_receipt_timestamp_ns":1704067200000006433,"raw_payload":"{\"arg\":{\"channel\":\"books\",\"instId\":\"BTC-USDT\"},\"data\":[{\"ts\":\"1704067200643\",\"seqId\":642,\"prevSeqId\":641,\"bids\":[],\"asks\":[[\"50001.0\",\"1.00000000\",\"0\",\"1\"]]}]}"}
{"local_receipt_timestamp_ns":1704067200000006443,"raw_payload":"{\"arg\":{\"channel\":\"books\",\"instId\":\"BTC-USDT\"},\"data\":[{\"ts\":\"1704067200644\",\"seqId\":643,\"prevSeqId\":642,\"bids\":[[\"50000.0\",\"1.00000000\",\"0\",\"1\"]],\"asks\":[]}]}"}
{"local_receipt_timestamp_ns":1704067200000006453,"raw_payload":"{\"arg\":{\"channel\":\"books\",\"instId\":\"BTC-USDT\"},\"data\":[{\"ts\":\"1704067200645\",\"seqId\":644,\"prevSeqId\":643,\"bids\":[],\"asks\":[[\"50001.0\",\"1.00000000\",\"0\",\"1\"]]}]}"}
{"local_receipt_timestamp_ns":1704067200000006463,"raw_payload":"{\"arg\":{\"channel\":\"books\",\"instId\":\"BTC-USDT\"},\"data\":[{\"ts\":\"1704067200646\",\"seqId\":645,\"prevSeqId\":644,\"bids\":[[\"50000.0\",\"1.00000000\",\"0\",\"1\"]],\"asks\":[]}]}"}
{"local_receipt_timestamp_ns":1704067200000006473,"raw_payload":"{\"arg\":{\"channel\":\"books\",\"instId\":\"BTC-USDT\"},\"data\":[{\"ts\":\"1704067200647\",\"seqId\":646,\"prevSeqId\":645,\"bids\":[],\"asks\":[[\"50001.0\",\"1.00000000\",\"0\",\"1\"]]}]}"}
{"local_receipt_timestamp_ns":1704067200000006483,"raw_payload":"{\"arg\":{\"channel\":\"books\",\"instId\":\"BTC-USDT\"},\"data\":[{\"ts\":\"1704067200648\",\"seqId\":647,\"prevSeqId\":646,\"bids\":[[\"50000.0\",\"1.00000000\",\"0\",\"1\"]],\"asks\":[]}]}"}
{"local_receipt_timestamp_ns":1704067200000006493,"raw_payload":"{\"arg\":{\"channel\":\"books\",\"instId\":\"BTC-USDT\"},\"data\":[{\"ts\":\"1704067200649\",\"seqId\":648,\"prevSeqId\":647,\"bids\":[],\"asks\":[[\"50001.0\",\"1.00000000\",\"0\",\"1\"]]}]}"}
{"local_receipt_timestamp_ns":1704067200000006503,"raw_payload":"{\"arg\":{\"channel\":\"books\",\"instId\":\"BTC-USDT\"},\"data\":[{\"ts\":\"1704067200650\",\"seqId\":649,\"prevSeqId\":648,\"bids\":[[\"50000.0\",\"1.00000000\",\"0\",\"1\"]],\"asks\":[]}]}"}
{"local_receipt_timestamp_ns":1704067200000006513,"raw_payload":"{\"arg\":{\"channel\":\"books\",\"instId\":\"BTC-USDT\"},\"data\":[{\"ts\":\"1704067200651\",\"seqId\":650,\"prevSeqId\":649,\"bids\":[],\"asks\":[[\"50001.0\",\"1.00000000\",\"0\",\"1\"]]}]}"}
{"local_receipt_timestamp_ns":1704067200000006523,"raw_payload":"{\"arg\":{\"channel\":\"books\",\"instId\":\"BTC-USDT\"},\"data\":[{\"ts\":\"1704067200652\",\"seqId\":651,\"prevSeqId\":650,\"bids\":[[\"50000.0\",\"1.00000000\",\"0\",\"1\"]],\"asks\":[]}]}"}
{"local_receipt_timestamp_ns":1704067200000006533,"raw_payload":"{\"arg\":{\"channel\":\"books\",\"instId\":\"BTC-USDT\"},\"data\":[{\"ts\":\"1704067200653\",\"seqId\":652,\"prevSeqId\":651,\"bids\":[],\"asks\":[[\"50001.0\",\"1.00000000\",\"0\",\"1\"]]}]}"}
{"local_receipt_timestamp_ns":1704067200000006543,"raw_payload":"{\"arg\":{\"channel\":\"books\",\"instId\":\"BTC-USDT\"},\"data\":[{\"ts\":\"1704067200654\",\"seqId\":653,\"prevSeqId\":652,\"bids\":[[\"50000.0\",\"1.00000000\",\"0\",\"1\"]],\"asks\":[]}]}"}
{"local_receipt_timestamp_ns":1704067200000006553,"raw_payload":"{\"arg\":{\"channel\":\"books\",\"instId\":\"BTC-USDT\"},\"data\":[{\"ts\":\"1704067200655\",\"seqId\":654,\"prevSeqId\":653,\"bids\":[],\"asks\":[[\"50001.0\",\"1.00000000\",\"0\",\"1\"]]}]}"}
{"local_receipt_timestamp_ns":1704067200000006563,"raw_payload":"{\"arg\":{\"channel\":\"books\",\"instId\":\"BTC-USDT\"},\"data\":[{\"ts\":\"1704067200656\",\"seqId\":655,\"prevSeqId\":654,\"bids\":[[\"50000.0\",\"1.00000000\",\"0\",\"1\"]],\"asks\":[]}]}"}
{"local_receipt_timestamp_ns":1704067200000006573,"raw_payload":"{\"arg\":{\"channel\":\"books\",\"instId\":\"BTC-USDT\"},\"data\":[{\"ts\":\"1704067200657\",\"seqId\":656,\"prevSeqId\":655,\"bids\":[],\"asks\":[[\"50001.0\",\"1.00000000\",\"0\",\"1\"]]}]}"}
{"local_receipt_timestamp_ns":1704067200000006583,"raw_payload":"{\"arg\":{\"channel\":\"books\",\"instId\":\"BTC-USDT\"},\"data\":[{\"ts\":\"1704067200658\",\"seqId\":657,\"prevSeqId\":656,\"bids\":[[\"50000.0\",\"1.00000000\",\"0\",\"1\"]],\"asks\":[]}]}"}
{"local_receipt_timestamp_ns":1704067200000006593,"raw_payload":"{\"arg\":{\"channel\":\"books\",\"instId\":\"BTC-USDT\"},\"data\":[{\"ts\":\"1704067200659\",\"seqId\":658,\"prevSeqId\":657,\"bids\":[],\"asks\":[[\"50001.0\",\"1.00000000\",\"0\",\"1\"]]}]}"}
{"local_receipt_timestamp_ns":1704067200000006603,"raw_payload":"{\"arg\":{\"channel\":\"books\",\"instId\":\"BTC-USDT\"},\"data\":[{\"ts\":\"1704067200660\",\"seqId\":659,\"prevSeqId\":658,\"bids\":[[\"50000.0\",\"1.00000000\",\"0\",\"1\"]],\"asks\":[]}]}"}
{"local_receipt_timestamp_ns":1704067200000006613,"raw_payload":"{\"arg\":{\"channel\":\"books\",\"instId\":\"BTC-USDT\"},\"data\":[{\"ts\":\"1704067200661\",\"seqId\":660,\"prevSeqId\":659,\"bids\":[],\"asks\":[[\"50001.0\",\"1.00000000\",\"0\",\"1\"]]}]}"}
{"local_receipt_timestamp_ns":1704067200000006623,"raw_payload":"{\"arg\":{\"channel\":\"books\",\"instId\":\"BTC-USDT\"},\"data\":[{\"ts\":\"1704067200662\",\"seqId\":661,\"prevSeqId\":660,\"bids\":[[\"50000.0\",\"1.00000000\",\"0\",\"1\"]],\"asks\":[]}]}"}
{"local_receipt_timestamp_ns":1704067200000006633,"raw_payload":"{\"arg\":{\"channel\":\"books\",\"instId\":\"BTC-USDT\"},\"data\":[{\"ts\":\"1704067200663\",\"seqId\":662,\"prevSeqId\":661,\"bids\":[],\"asks\":[[\"50001.0\",\"1.00000000\",\"0\",\"1\"]]}]}"}
{"local_receipt_timestamp_ns":1704067200000006643,"raw_payload":"{\"arg\":{\"channel\":\"books\",\"instId\":\"BTC-USDT\"},\"data\":[{\"ts\":\"1704067200664\",\"seqId\":663,\"prevSeqId\":662,\"bids\":[[\"50000.0\",\"1.00000000\",\"0\",\"1\"]],\"asks\":[]}]}"}
{"local_receipt_timestamp_ns":1704067200000006653,"raw_payload":"{\"arg\":{\"channel\":\"books\",\"instId\":\"BTC-USDT\"},\"data\":[{\"ts\":\"1704067200665\",\"seqId\":664,\"prevSeqId\":663,\"bids\":[],\"asks\":[[\"50001.0\",\"1.00000000\",\"0\",\"1\"]]}]}"}
{"local_receipt_timestamp_ns":1704067200000006663,"raw_payload":"{\"arg\":{\"channel\":\"books\",\"instId\":\"BTC-USDT\"},\"data\":[{\"ts\":\"1704067200666\",\"seqId\":665,\"prevSeqId\":664,\"bids\":[[\"50000.0\",\"1.00000000\",\"0\",\"1\"]],\"asks\":[]}]}"}
{"local_receipt_timestamp_ns":1704067200000006673,"raw_payload":"{\"arg\":{\"channel\":\"books\",\"instId\":\"BTC-USDT\"},\"data\":[{\"ts\":\"1704067200667\",\"seqId\":666,\"prevSeqId\":665,\"bids\":[],\"asks\":[[\"50001.0\",\"1.00000000\",\"0\",\"1\"]]}]}"}
{"local_receipt_timestamp_ns":1704067200000006683,"raw_payload":"{\"arg\":{\"channel\":\"books\",\"instId\":\"BTC-USDT\"},\"data\":[{\"ts\":\"1704067200668\",\"seqId\":667,\"prevSeqId\":666,\"bids\":[[\"50000.0\",\"1.00000000\",\"0\",\"1\"]],\"asks\":[]}]}"}
{"local_receipt_timestamp_ns":1704067200000006693,"raw_payload":"{\"arg\":{\"channel\":\"books\",\"instId\":\"BTC-USDT\"},\"data\":[{\"ts\":\"1704067200669\",\"seqId\":668,\"prevSeqId\":667,\"bids\":[],\"asks\":[[\"50001.0\",\"1.00000000\",\"0\",\"1\"]]}]}"}
{"local_receipt_timestamp_ns":1704067200000006703,"raw_payload":"{\"arg\":{\"channel\":\"books\",\"instId\":\"BTC-USDT\"},\"data\":[{\"ts\":\"1704067200670\",\"seqId\":669,\"prevSeqId\":668,\"bids\":[[\"50000.0\",\"1.00000000\",\"0\",\"1\"]],\"asks\":[]}]}"}
{"local_receipt_timestamp_ns":1704067200000006713,"raw_payload":"{\"arg\":{\"channel\":\"books\",\"instId\":\"BTC-USDT\"},\"data\":[{\"ts\":\"1704067200671\",\"seqId\":670,\"prevSeqId\":669,\"bids\":[],\"asks\":[[\"50001.0\",\"1.00000000\",\"0\",\"1\"]]}]}"}
{"local_receipt_timestamp_ns":1704067200000006723,"raw_payload":"{\"arg\":{\"channel\":\"books\",\"instId\":\"BTC-USDT\"},\"data\":[{\"ts\":\"1704067200672\",\"seqId\":671,\"prevSeqId\":670,\"bids\":[[\"50000.0\",\"1.00000000\",\"0\",\"1\"]],\"asks\":[]}]}"}
{"local_receipt_timestamp_ns":1704067200000006733,"raw_payload":"{\"arg\":{\"channel\":\"books\",\"instId\":\"BTC-USDT\"},\"data\":[{\"ts\":\"1704067200673\",\"seqId\":672,\"prevSeqId\":671,\"bids\":[],\"asks\":[[\"50001.0\",\"1.00000000\",\"0\",\"1\"]]}]}"}
{"local_receipt_timestamp_ns":1704067200000006743,"raw_payload":"{\"arg\":{\"channel\":\"books\",\"instId\":\"BTC-USDT\"},\"data\":[{\"ts\":\"1704067200674\",\"seqId\":673,\"prevSeqId\":672,\"bids\":[[\"50000.0\",\"1.00000000\",\"0\",\"1\"]],\"asks\":[]}]}"}
{"local_receipt_timestamp_ns":1704067200000006753,"raw_payload":"{\"arg\":{\"channel\":\"books\",\"instId\":\"BTC-USDT\"},\"data\":[{\"ts\":\"1704067200675\",\"seqId\":674,\"prevSeqId\":673,\"bids\":[],\"asks\":[[\"50001.0\",\"1.00000000\",\"0\",\"1\"]]}]}"}
{"local_receipt_timestamp_ns":1704067200000006763,"raw_payload":"{\"arg\":{\"channel\":\"books\",\"instId\":\"BTC-USDT\"},\"data\":[{\"ts\":\"1704067200676\",\"seqId\":675,\"prevSeqId\":674,\"bids\":[[\"50000.0\",\"1.00000000\",\"0\",\"1\"]],\"asks\":[]}]}"}
{"local_receipt_timestamp_ns":1704067200000006773,"raw_payload":"{\"arg\":{\"channel\":\"books\",\"instId\":\"BTC-USDT\"},\"data\":[{\"ts\":\"1704067200677\",\"seqId\":676,\"prevSeqId\":675,\"bids\":[],\"asks\":[[\"50001.0\",\"1.00000000\",\"0\",\"1\"]]}]}"}
{"local_receipt_timestamp_ns":1704067200000006783,"raw_payload":"{\"arg\":{\"channel\":\"books\",\"instId\":\"BTC-USDT\"},\"data\":[{\"ts\":\"1704067200678\",\"seqId\":677,\"prevSeqId\":676,\"bids\":[[\"50000.0\",\"1.00000000\",\"0\",\"1\"]],\"asks\":[]}]}"}
{"local_receipt_timestamp_ns":1704067200000006793,"raw_payload":"{\"arg\":{\"channel\":\"books\",\"instId\":\"BTC-USDT\"},\"data\":[{\"ts\":\"1704067200679\",\"seqId\":678,\"prevSeqId\":677,\"bids\":[],\"asks\":[[\"50001.0\",\"1.00000000\",\"0\",\"1\"]]}]}"}
{"local_receipt_timestamp_ns":1704067200000006803,"raw_payload":"{\"arg\":{\"channel\":\"books\",\"instId\":\"BTC-USDT\"},\"data\":[{\"ts\":\"1704067200680\",\"seqId\":679,\"prevSeqId\":678,\"bids\":[[\"50000.0\",\"1.00000000\",\"0\",\"1\"]],\"asks\":[]}]}"}
{"local_receipt_timestamp_ns":1704067200000006813,"raw_payload":"{\"arg\":{\"channel\":\"books\",\"instId\":\"BTC-USDT\"},\"data\":[{\"ts\":\"1704067200681\",\"seqId\":680,\"prevSeqId\":679,\"bids\":[],\"asks\":[[\"50001.0\",\"1.00000000\",\"0\",\"1\"]]}]}"}
{"local_receipt_timestamp_ns":1704067200000006823,"raw_payload":"{\"arg\":{\"channel\":\"books\",\"instId\":\"BTC-USDT\"},\"data\":[{\"ts\":\"1704067200682\",\"seqId\":681,\"prevSeqId\":680,\"bids\":[[\"50000.0\",\"1.00000000\",\"0\",\"1\"]],\"asks\":[]}]}"}
{"local_receipt_timestamp_ns":1704067200000006833,"raw_payload":"{\"arg\":{\"channel\":\"books\",\"instId\":\"BTC-USDT\"},\"data\":[{\"ts\":\"1704067200683\",\"seqId\":682,\"prevSeqId\":681,\"bids\":[],\"asks\":[[\"50001.0\",\"1.00000000\",\"0\",\"1\"]]}]}"}
{"local_receipt_timestamp_ns":1704067200000006843,"raw_payload":"{\"arg\":{\"channel\":\"books\",\"instId\":\"BTC-USDT\"},\"data\":[{\"ts\":\"1704067200684\",\"seqId\":683,\"prevSeqId\":682,\"bids\":[[\"50000.0\",\"1.00000000\",\"0\",\"1\"]],\"asks\":[]}]}"}
{"local_receipt_timestamp_ns":1704067200000006853,"raw_payload":"{\"arg\":{\"channel\":\"books\",\"instId\":\"BTC-USDT\"},\"data\":[{\"ts\":\"1704067200685\",\"seqId\":684,\"prevSeqId\":683,\"bids\":[],\"asks\":[[\"50001.0\",\"1.00000000\",\"0\",\"1\"]]}]}"}
{"local_receipt_timestamp_ns":1704067200000006863,"raw_payload":"{\"arg\":{\"channel\":\"books\",\"instId\":\"BTC-USDT\"},\"data\":[{\"ts\":\"1704067200686\",\"seqId\":685,\"prevSeqId\":684,\"bids\":[[\"50000.0\",\"1.00000000\",\"0\",\"1\"]],\"asks\":[]}]}"}
{"local_receipt_timestamp_ns":1704067200000006873,"raw_payload":"{\"arg\":{\"channel\":\"books\",\"instId\":\"BTC-USDT\"},\"data\":[{\"ts\":\"1704067200687\",\"seqId\":686,\"prevSeqId\":685,\"bids\":[],\"asks\":[[\"50001.0\",\"1.00000000\",\"0\",\"1\"]]}]}"}
{"local_receipt_timestamp_ns":1704067200000006883,"raw_payload":"{\"arg\":{\"channel\":\"books\",\"instId\":\"BTC-USDT\"},\"data\":[{\"ts\":\"1704067200688\",\"seqId\":687,\"prevSeqId\":686,\"bids\":[[\"50000.0\",\"1.00000000\",\"0\",\"1\"]],\"asks\":[]}]}"}
{"local_receipt_timestamp_ns":1704067200000006893,"raw_payload":"{\"arg\":{\"channel\":\"books\",\"instId\":\"BTC-USDT\"},\"data\":[{\"ts\":\"1704067200689\",\"seqId\":688,\"prevSeqId\":687,\"bids\":[],\"asks\":[[\"50001.0\",\"1.00000000\",\"0\",\"1\"]]}]}"}
{"local_receipt_timestamp_ns":1704067200000006903,"raw_payload":"{\"arg\":{\"channel\":\"books\",\"instId\":\"BTC-USDT\"},\"data\":[{\"ts\":\"1704067200690\",\"seqId\":689,\"prevSeqId\":688,\"bids\":[[\"50000.0\",\"1.00000000\",\"0\",\"1\"]],\"asks\":[]}]}"}
{"local_receipt_timestamp_ns":1704067200000006913,"raw_payload":"{\"arg\":{\"channel\":\"books\",\"instId\":\"BTC-USDT\"},\"data\":[{\"ts\":\"1704067200691\",\"seqId\":690,\"prevSeqId\":689,\"bids\":[],\"asks\":[[\"50001.0\",\"1.00000000\",\"0\",\"1\"]]}]}"}
{"local_receipt_timestamp_ns":1704067200000006923,"raw_payload":"{\"arg\":{\"channel\":\"books\",\"instId\":\"BTC-USDT\"},\"data\":[{\"ts\":\"1704067200692\",\"seqId\":691,\"prevSeqId\":690,\"bids\":[[\"50000.0\",\"1.00000000\",\"0\",\"1\"]],\"asks\":[]}]}"}
{"local_receipt_timestamp_ns":1704067200000006933,"raw_payload":"{\"arg\":{\"channel\":\"books\",\"instId\":\"BTC-USDT\"},\"data\":[{\"ts\":\"1704067200693\",\"seqId\":692,\"prevSeqId\":691,\"bids\":[],\"asks\":[[\"50001.0\",\"1.00000000\",\"0\",\"1\"]]}]}"}
{"local_receipt_timestamp_ns":1704067200000006943,"raw_payload":"{\"arg\":{\"channel\":\"books\",\"instId\":\"BTC-USDT\"},\"data\":[{\"ts\":\"1704067200694\",\"seqId\":693,\"prevSeqId\":692,\"bids\":[[\"50000.0\",\"1.00000000\",\"0\",\"1\"]],\"asks\":[]}]}"}
{"local_receipt_timestamp_ns":1704067200000006953,"raw_payload":"{\"arg\":{\"channel\":\"books\",\"instId\":\"BTC-USDT\"},\"data\":[{\"ts\":\"1704067200695\",\"seqId\":694,\"prevSeqId\":693,\"bids\":[],\"asks\":[[\"50001.0\",\"1.00000000\",\"0\",\"1\"]]}]}"}
{"local_receipt_timestamp_ns":1704067200000006963,"raw_payload":"{\"arg\":{\"channel\":\"books\",\"instId\":\"BTC-USDT\"},\"data\":[{\"ts\":\"1704067200696\",\"seqId\":695,\"prevSeqId\":694,\"bids\":[[\"50000.0\",\"1.00000000\",\"0\",\"1\"]],\"asks\":[]}]}"}
{"local_receipt_timestamp_ns":1704067200000006973,"raw_payload":"{\"arg\":{\"channel\":\"books\",\"instId\":\"BTC-USDT\"},\"data\":[{\"ts\":\"1704067200697\",\"seqId\":696,\"prevSeqId\":695,\"bids\":[],\"asks\":[[\"50001.0\",\"1.00000000\",\"0\",\"1\"]]}]}"}
{"local_receipt_timestamp_ns":1704067200000006983,"raw_payload":"{\"arg\":{\"channel\":\"books\",\"instId\":\"BTC-USDT\"},\"data\":[{\"ts\":\"1704067200698\",\"seqId\":697,\"prevSeqId\":696,\"bids\":[[\"50000.0\",\"1.00000000\",\"0\",\"1\"]],\"asks\":[]}]}"}
{"local_receipt_timestamp_ns":1704067200000006993,"raw_payload":"{\"arg\":{\"channel\":\"books\",\"instId\":\"BTC-USDT\"},\"data\":[{\"ts\":\"1704067200699\",\"seqId\":698,\"prevSeqId\":697,\"bids\":[],\"asks\":[[\"50001.0\",\"1.00000000\",\"0\",\"1\"]]}]}"}
{"local_receipt_timestamp_ns":1704067200000007003,"raw_payload":"{\"arg\":{\"channel\":\"books\",\"instId\":\"BTC-USDT\"},\"data\":[{\"ts\":\"1704067200700\",\"seqId\":699,\"prevSeqId\":698,\"bids\":[[\"50000.0\",\"1.00000000\",\"0\",\"1\"]],\"asks\":[]}]}"}
{"local_receipt_timestamp_ns":1704067200000007013,"raw_payload":"{\"arg\":{\"channel\":\"books\",\"instId\":\"BTC-USDT\"},\"data\":[{\"ts\":\"1704067200701\",\"seqId\":700,\"prevSeqId\":699,\"bids\":[],\"asks\":[[\"50001.0\",\"1.00000000\",\"0\",\"1\"]]}]}"}
{"local_receipt_timestamp_ns":1704067200000007023,"raw_payload":"{\"arg\":{\"channel\":\"books\",\"instId\":\"BTC-USDT\"},\"data\":[{\"ts\":\"1704067200702\",\"seqId\":701,\"prevSeqId\":700,\"bids\":[[\"50000.0\",\"1.00000000\",\"0\",\"1\"]],\"asks\":[]}]}"}
{"local_receipt_timestamp_ns":1704067200000007033,"raw_payload":"{\"arg\":{\"channel\":\"books\",\"instId\":\"BTC-USDT\"},\"data\":[{\"ts\":\"1704067200703\",\"seqId\":702,\"prevSeqId\":701,\"bids\":[],\"asks\":[[\"50001.0\",\"1.00000000\",\"0\",\"1\"]]}]}"}
{"local_receipt_timestamp_ns":1704067200000007043,"raw_payload":"{\"arg\":{\"channel\":\"books\",\"instId\":\"BTC-USDT\"},\"data\":[{\"ts\":\"1704067200704\",\"seqId\":703,\"prevSeqId\":702,\"bids\":[[\"50000.0\",\"1.00000000\",\"0\",\"1\"]],\"asks\":[]}]}"}
{"local_receipt_timestamp_ns":1704067200000007053,"raw_payload":"{\"arg\":{\"channel\":\"books\",\"instId\":\"BTC-USDT\"},\"data\":[{\"ts\":\"1704067200705\",\"seqId\":704,\"prevSeqId\":703,\"bids\":[],\"asks\":[[\"50001.0\",\"1.00000000\",\"0\",\"1\"]]}]}"}
{"local_receipt_timestamp_ns":1704067200000007063,"raw_payload":"{\"arg\":{\"channel\":\"books\",\"instId\":\"BTC-USDT\"},\"data\":[{\"ts\":\"1704067200706\",\"seqId\":705,\"prevSeqId\":704,\"bids\":[[\"50000.0\",\"1.00000000\",\"0\",\"1\"]],\"asks\":[]}]}"}
{"local_receipt_timestamp_ns":1704067200000007073,"raw_payload":"{\"arg\":{\"channel\":\"books\",\"instId\":\"BTC-USDT\"},\"data\":[{\"ts\":\"1704067200707\",\"seqId\":706,\"prevSeqId\":705,\"bids\":[],\"asks\":[[\"50001.0\",\"1.00000000\",\"0\",\"1\"]]}]}"}
{"local_receipt_timestamp_ns":1704067200000007083,"raw_payload":"{\"arg\":{\"channel\":\"books\",\"instId\":\"BTC-USDT\"},\"data\":[{\"ts\":\"1704067200708\",\"seqId\":707,\"prevSeqId\":706,\"bids\":[[\"50000.0\",\"1.00000000\",\"0\",\"1\"]],\"asks\":[]}]}"}
{"local_receipt_timestamp_ns":1704067200000007093,"raw_payload":"{\"arg\":{\"channel\":\"books\",\"instId\":\"BTC-USDT\"},\"data\":[{\"ts\":\"1704067200709\",\"seqId\":708,\"prevSeqId\":707,\"bids\":[],\"asks\":[[\"50001.0\",\"1.00000000\",\"0\",\"1\"]]}]}"}
{"local_receipt_timestamp_ns":1704067200000007103,"raw_payload":"{\"arg\":{\"channel\":\"books\",\"instId\":\"BTC-USDT\"},\"data\":[{\"ts\":\"1704067200710\",\"seqId\":709,\"prevSeqId\":708,\"bids\":[[\"50000.0\",\"1.00000000\",\"0\",\"1\"]],\"asks\":[]}]}"}
{"local_receipt_timestamp_ns":1704067200000007113,"raw_payload":"{\"arg\":{\"channel\":\"books\",\"instId\":\"BTC-USDT\"},\"data\":[{\"ts\":\"1704067200711\",\"seqId\":710,\"prevSeqId\":709,\"bids\":[],\"asks\":[[\"50001.0\",\"1.00000000\",\"0\",\"1\"]]}]}"}
{"local_receipt_timestamp_ns":1704067200000007123,"raw_payload":"{\"arg\":{\"channel\":\"books\",\"instId\":\"BTC-USDT\"},\"data\":[{\"ts\":\"1704067200712\",\"seqId\":711,\"prevSeqId\":710,\"bids\":[[\"50000.0\",\"1.00000000\",\"0\",\"1\"]],\"asks\":[]}]}"}
{"local_receipt_timestamp_ns":1704067200000007133,"raw_payload":"{\"arg\":{\"channel\":\"books\",\"instId\":\"BTC-USDT\"},\"data\":[{\"ts\":\"1704067200713\",\"seqId\":712,\"prevSeqId\":711,\"bids\":[],\"asks\":[[\"50001.0\",\"1.00000000\",\"0\",\"1\"]]}]}"}
{"local_receipt_timestamp_ns":1704067200000007143,"raw_payload":"{\"arg\":{\"channel\":\"books\",\"instId\":\"BTC-USDT\"},\"data\":[{\"ts\":\"1704067200714\",\"seqId\":713,\"prevSeqId\":712,\"bids\":[[\"50000.0\",\"1.00000000\",\"0\",\"1\"]],\"asks\":[]}]}"}
{"local_receipt_timestamp_ns":1704067200000007153,"raw_payload":"{\"arg\":{\"channel\":\"books\",\"instId\":\"BTC-USDT\"},\"data\":[{\"ts\":\"1704067200715\",\"seqId\":714,\"prevSeqId\":713,\"bids\":[],\"asks\":[[\"50001.0\",\"1.00000000\",\"0\",\"1\"]]}]}"}
{"local_receipt_timestamp_ns":1704067200000007163,"raw_payload":"{\"arg\":{\"channel\":\"books\",\"instId\":\"BTC-USDT\"},\"data\":[{\"ts\":\"1704067200716\",\"seqId\":715,\"prevSeqId\":714,\"bids\":[[\"50000.0\",\"1.00000000\",\"0\",\"1\"]],\"asks\":[]}]}"}
{"local_receipt_timestamp_ns":1704067200000007173,"raw_payload":"{\"arg\":{\"channel\":\"books\",\"instId\":\"BTC-USDT\"},\"data\":[{\"ts\":\"1704067200717\",\"seqId\":716,\"prevSeqId\":715,\"bids\":[],\"asks\":[[\"50001.0\",\"1.00000000\",\"0\",\"1\"]]}]}"}
{"local_receipt_timestamp_ns":1704067200000007183,"raw_payload":"{\"arg\":{\"channel\":\"books\",\"instId\":\"BTC-USDT\"},\"data\":[{\"ts\":\"1704067200718\",\"seqId\":717,\"prevSeqId\":716,\"bids\":[[\"50000.0\",\"1.00000000\",\"0\",\"1\"]],\"asks\":[]}]}"}
{"local_receipt_timestamp_ns":1704067200000007193,"raw_payload":"{\"arg\":{\"channel\":\"books\",\"instId\":\"BTC-USDT\"},\"data\":[{\"ts\":\"1704067200719\",\"seqId\":718,\"prevSeqId\":717,\"bids\":[],\"asks\":[[\"50001.0\",\"1.00000000\",\"0\",\"1\"]]}]}"}
{"local_receipt_timestamp_ns":1704067200000007203,"raw_payload":"{\"arg\":{\"channel\":\"books\",\"instId\":\"BTC-USDT\"},\"data\":[{\"ts\":\"1704067200720\",\"seqId\":719,\"prevSeqId\":718,\"bids\":[[\"50000.0\",\"1.00000000\",\"0\",\"1\"]],\"asks\":[]}]}"}
{"local_receipt_timestamp_ns":1704067200000007213,"raw_payload":"{\"arg\":{\"channel\":\"books\",\"instId\":\"BTC-USDT\"},\"data\":[{\"ts\":\"1704067200721\",\"seqId\":720,\"prevSeqId\":719,\"bids\":[],\"asks\":[[\"50001.0\",\"1.00000000\",\"0\",\"1\"]]}]}"}
{"local_receipt_timestamp_ns":1704067200000007223,"raw_payload":"{\"arg\":{\"channel\":\"books\",\"instId\":\"BTC-USDT\"},\"data\":[{\"ts\":\"1704067200722\",\"seqId\":721,\"prevSeqId\":720,\"bids\":[[\"50000.0\",\"1.00000000\",\"0\",\"1\"]],\"asks\":[]}]}"}
{"local_receipt_timestamp_ns":1704067200000007233,"raw_payload":"{\"arg\":{\"channel\":\"books\",\"instId\":\"BTC-USDT\"},\"data\":[{\"ts\":\"1704067200723\",\"seqId\":722,\"prevSeqId\":721,\"bids\":[],\"asks\":[[\"50001.0\",\"1.00000000\",\"0\",\"1\"]]}]}"}
{"local_receipt_timestamp_ns":1704067200000007243,"raw_payload":"{\"arg\":{\"channel\":\"books\",\"instId\":\"BTC-USDT\"},\"data\":[{\"ts\":\"1704067200724\",\"seqId\":723,\"prevSeqId\":722,\"bids\":[[\"50000.0\",\"1.00000000\",\"0\",\"1\"]],\"asks\":[]}]}"}
{"local_receipt_timestamp_ns":1704067200000007253,"raw_payload":"{\"arg\":{\"channel\":\"books\",\"instId\":\"BTC-USDT\"},\"data\":[{\"ts\":\"1704067200725\",\"seqId\":724,\"prevSeqId\":723,\"bids\":[],\"asks\":[[\"50001.0\",\"1.00000000\",\"0\",\"1\"]]}]}"}
{"local_receipt_timestamp_ns":1704067200000007263,"raw_payload":"{\"arg\":{\"channel\":\"books\",\"instId\":\"BTC-USDT\"},\"data\":[{\"ts\":\"1704067200726\",\"seqId\":725,\"prevSeqId\":724,\"bids\":[[\"50000.0\",\"1.00000000\",\"0\",\"1\"]],\"asks\":[]}]}"}
{"local_receipt_timestamp_ns":1704067200000007273,"raw_payload":"{\"arg\":{\"channel\":\"books\",\"instId\":\"BTC-USDT\"},\"data\":[{\"ts\":\"1704067200727\",\"seqId\":726,\"prevSeqId\":725,\"bids\":[],\"asks\":[[\"50001.0\",\"1.00000000\",\"0\",\"1\"]]}]}"}
{"local_receipt_timestamp_ns":1704067200000007283,"raw_payload":"{\"arg\":{\"channel\":\"books\",\"instId\":\"BTC-USDT\"},\"data\":[{\"ts\":\"1704067200728\",\"seqId\":727,\"prevSeqId\":726,\"bids\":[[\"50000.0\",\"1.00000000\",\"0\",\"1\"]],\"asks\":[]}]}"}
{"local_receipt_timestamp_ns":1704067200000007293,"raw_payload":"{\"arg\":{\"channel\":\"books\",\"instId\":\"BTC-USDT\"},\"data\":[{\"ts\":\"1704067200729\",\"seqId\":728,\"prevSeqId\":727,\"bids\":[],\"asks\":[[\"50001.0\",\"1.00000000\",\"0\",\"1\"]]}]}"}
{"local_receipt_timestamp_ns":1704067200000007303,"raw_payload":"{\"arg\":{\"channel\":\"books\",\"instId\":\"BTC-USDT\"},\"data\":[{\"ts\":\"1704067200730\",\"seqId\":729,\"prevSeqId\":728,\"bids\":[[\"50000.0\",\"1.00000000\",\"0\",\"1\"]],\"asks\":[]}]}"}
{"local_receipt_timestamp_ns":1704067200000007313,"raw_payload":"{\"arg\":{\"channel\":\"books\",\"instId\":\"BTC-USDT\"},\"data\":[{\"ts\":\"1704067200731\",\"seqId\":730,\"prevSeqId\":729,\"bids\":[],\"asks\":[[\"50001.0\",\"1.00000000\",\"0\",\"1\"]]}]}"}
{"local_receipt_timestamp_ns":1704067200000007323,"raw_payload":"{\"arg\":{\"channel\":\"books\",\"instId\":\"BTC-USDT\"},\"data\":[{\"ts\":\"1704067200732\",\"seqId\":731,\"prevSeqId\":730,\"bids\":[[\"50000.0\",\"1.00000000\",\"0\",\"1\"]],\"asks\":[]}]}"}
{"local_receipt_timestamp_ns":1704067200000007333,"raw_payload":"{\"arg\":{\"channel\":\"books\",\"instId\":\"BTC-USDT\"},\"data\":[{\"ts\":\"1704067200733\",\"seqId\":732,\"prevSeqId\":731,\"bids\":[],\"asks\":[[\"50001.0\",\"1.00000000\",\"0\",\"1\"]]}]}"}
{"local_receipt_timestamp_ns":1704067200000007343,"raw_payload":"{\"arg\":{\"channel\":\"books\",\"instId\":\"BTC-USDT\"},\"data\":[{\"ts\":\"1704067200734\",\"seqId\":733,\"prevSeqId\":732,\"bids\":[[\"50000.0\",\"1.00000000\",\"0\",\"1\"]],\"asks\":[]}]}"}
{"local_receipt_timestamp_ns":1704067200000007353,"raw_payload":"{\"arg\":{\"channel\":\"books\",\"instId\":\"BTC-USDT\"},\"data\":[{\"ts\":\"1704067200735\",\"seqId\":734,\"prevSeqId\":733,\"bids\":[],\"asks\":[[\"50001.0\",\"1.00000000\",\"0\",\"1\"]]}]}"}
{"local_receipt_timestamp_ns":1704067200000007363,"raw_payload":"{\"arg\":{\"channel\":\"books\",\"instId\":\"BTC-USDT\"},\"data\":[{\"ts\":\"1704067200736\",\"seqId\":735,\"prevSeqId\":734,\"bids\":[[\"50000.0\",\"1.00000000\",\"0\",\"1\"]],\"asks\":[]}]}"}
{"local_receipt_timestamp_ns":1704067200000007373,"raw_payload":"{\"arg\":{\"channel\":\"books\",\"instId\":\"BTC-USDT\"},\"data\":[{\"ts\":\"1704067200737\",\"seqId\":736,\"prevSeqId\":735,\"bids\":[],\"asks\":[[\"50001.0\",\"1.00000000\",\"0\",\"1\"]]}]}"}
{"local_receipt_timestamp_ns":1704067200000007383,"raw_payload":"{\"arg\":{\"channel\":\"books\",\"instId\":\"BTC-USDT\"},\"data\":[{\"ts\":\"1704067200738\",\"seqId\":737,\"prevSeqId\":736,\"bids\":[[\"50000.0\",\"1.00000000\",\"0\",\"1\"]],\"asks\":[]}]}"}
{"local_receipt_timestamp_ns":1704067200000007393,"raw_payload":"{\"arg\":{\"channel\":\"books\",\"instId\":\"BTC-USDT\"},\"data\":[{\"ts\":\"1704067200739\",\"seqId\":738,\"prevSeqId\":737,\"bids\":[],\"asks\":[[\"50001.0\",\"1.00000000\",\"0\",\"1\"]]}]}"}
{"local_receipt_timestamp_ns":1704067200000007403,"raw_payload":"{\"arg\":{\"channel\":\"books\",\"instId\":\"BTC-USDT\"},\"data\":[{\"ts\":\"1704067200740\",\"seqId\":739,\"prevSeqId\":738,\"bids\":[[\"50000.0\",\"1.00000000\",\"0\",\"1\"]],\"asks\":[]}]}"}
{"local_receipt_timestamp_ns":1704067200000007413,"raw_payload":"{\"arg\":{\"channel\":\"books\",\"instId\":\"BTC-USDT\"},\"data\":[{\"ts\":\"1704067200741\",\"seqId\":740,\"prevSeqId\":739,\"bids\":[],\"asks\":[[\"50001.0\",\"1.00000000\",\"0\",\"1\"]]}]}"}
{"local_receipt_timestamp_ns":1704067200000007423,"raw_payload":"{\"arg\":{\"channel\":\"books\",\"instId\":\"BTC-USDT\"},\"data\":[{\"ts\":\"1704067200742\",\"seqId\":741,\"prevSeqId\":740,\"bids\":[[\"50000.0\",\"1.00000000\",\"0\",\"1\"]],\"asks\":[]}]}"}
{"local_receipt_timestamp_ns":1704067200000007433,"raw_payload":"{\"arg\":{\"channel\":\"books\",\"instId\":\"BTC-USDT\"},\"data\":[{\"ts\":\"1704067200743\",\"seqId\":742,\"prevSeqId\":741,\"bids\":[],\"asks\":[[\"50001.0\",\"1.00000000\",\"0\",\"1\"]]}]}"}
{"local_receipt_timestamp_ns":1704067200000007443,"raw_payload":"{\"arg\":{\"channel\":\"books\",\"instId\":\"BTC-USDT\"},\"data\":[{\"ts\":\"1704067200744\",\"seqId\":743,\"prevSeqId\":742,\"bids\":[[\"50000.0\",\"1.00000000\",\"0\",\"1\"]],\"asks\":[]}]}"}
{"local_receipt_timestamp_ns":1704067200000007453,"raw_payload":"{\"arg\":{\"channel\":\"books\",\"instId\":\"BTC-USDT\"},\"data\":[{\"ts\":\"1704067200745\",\"seqId\":744,\"prevSeqId\":743,\"bids\":[],\"asks\":[[\"50001.0\",\"1.00000000\",\"0\",\"1\"]]}]}"}
{"local_receipt_timestamp_ns":1704067200000007463,"raw_payload":"{\"arg\":{\"channel\":\"books\",\"instId\":\"BTC-USDT\"},\"data\":[{\"ts\":\"1704067200746\",\"seqId\":745,\"prevSeqId\":744,\"bids\":[[\"50000.0\",\"1.00000000\",\"0\",\"1\"]],\"asks\":[]}]}"}
{"local_receipt_timestamp_ns":1704067200000007473,"raw_payload":"{\"arg\":{\"channel\":\"books\",\"instId\":\"BTC-USDT\"},\"data\":[{\"ts\":\"1704067200747\",\"seqId\":746,\"prevSeqId\":745,\"bids\":[],\"asks\":[[\"50001.0\",\"1.00000000\",\"0\",\"1\"]]}]}"}
{"local_receipt_timestamp_ns":1704067200000007483,"raw_payload":"{\"arg\":{\"channel\":\"books\",\"instId\":\"BTC-USDT\"},\"data\":[{\"ts\":\"1704067200748\",\"seqId\":747,\"prevSeqId\":746,\"bids\":[[\"50000.0\",\"1.00000000\",\"0\",\"1\"]],\"asks\":[]}]}"}
{"local_receipt_timestamp_ns":1704067200000007493,"raw_payload":"{\"arg\":{\"channel\":\"books\",\"instId\":\"BTC-USDT\"},\"data\":[{\"ts\":\"1704067200749\",\"seqId\":748,\"prevSeqId\":747,\"bids\":[],\"asks\":[[\"50001.0\",\"1.00000000\",\"0\",\"1\"]]}]}"}
{"local_receipt_timestamp_ns":1704067200000007503,"raw_payload":"{\"arg\":{\"channel\":\"books\",\"instId\":\"BTC-USDT\"},\"data\":[{\"ts\":\"1704067200750\",\"seqId\":749,\"prevSeqId\":748,\"bids\":[[\"50000.0\",\"1.00000000\",\"0\",\"1\"]],\"asks\":[]}]}"}
{"local_receipt_timestamp_ns":1704067200000007513,"raw_payload":"{\"arg\":{\"channel\":\"books\",\"instId\":\"BTC-USDT\"},\"data\":[{\"ts\":\"1704067200751\",\"seqId\":750,\"prevSeqId\":749,\"bids\":[],\"asks\":[[\"50001.0\",\"1.00000000\",\"0\",\"1\"]]}]}"}
{"local_receipt_timestamp_ns":1704067200000007523,"raw_payload":"{\"arg\":{\"channel\":\"books\",\"instId\":\"BTC-USDT\"},\"data\":[{\"ts\":\"1704067200752\",\"seqId\":751,\"prevSeqId\":750,\"bids\":[[\"50000.0\",\"1.00000000\",\"0\",\"1\"]],\"asks\":[]}]}"}
{"local_receipt_timestamp_ns":1704067200000007533,"raw_payload":"{\"arg\":{\"channel\":\"books\",\"instId\":\"BTC-USDT\"},\"data\":[{\"ts\":\"1704067200753\",\"seqId\":752,\"prevSeqId\":751,\"bids\":[],\"asks\":[[\"50001.0\",\"1.00000000\",\"0\",\"1\"]]}]}"}
{"local_receipt_timestamp_ns":1704067200000007543,"raw_payload":"{\"arg\":{\"channel\":\"trades\",\"instId\":\"BTC-USDT\"},\"data\":[]}"}
{"local_receipt_timestamp_ns":1704067200000007553,"raw_payload":"{"}
